fill ~384 ~60 ~48 ~386 ~64 ~48 stone
fill ~384 ~65 ~48 ~386 ~67 ~48 dirt
fill ~384 ~68 ~48 ~386 ~68 ~48 grass_block
fill ~387 ~60 ~48 ~394 ~65 ~48 stone
fill ~387 ~66 ~48 ~394 ~68 ~48 dirt
fill ~387 ~69 ~48 ~394 ~69 ~48 grass_block
fill ~395 ~60 ~48 ~395 ~66 ~48 stone
fill ~395 ~67 ~48 ~395 ~69 ~48 dirt
fill ~395 ~70 ~48 ~395 ~70 ~48 grass_block
fill ~396 ~60 ~48 ~399 ~65 ~48 stone
fill ~396 ~66 ~48 ~399 ~68 ~48 dirt
fill ~396 ~69 ~48 ~399 ~69 ~48 grass_block
fill ~384 ~60 ~49 ~387 ~64 ~49 stone
fill ~384 ~65 ~49 ~387 ~67 ~49 dirt
fill ~384 ~68 ~49 ~387 ~68 ~49 grass_block
fill ~388 ~60 ~49 ~390 ~65 ~49 stone
fill ~388 ~66 ~49 ~390 ~68 ~49 dirt
fill ~388 ~69 ~49 ~390 ~69 ~49 grass_block
fill ~391 ~60 ~49 ~392 ~64 ~49 stone
fill ~391 ~65 ~49 ~392 ~67 ~49 dirt
fill ~391 ~68 ~49 ~392 ~68 ~49 grass_block
fill ~393 ~60 ~49 ~394 ~65 ~49 stone
fill ~393 ~66 ~49 ~394 ~68 ~49 dirt
fill ~393 ~69 ~49 ~394 ~69 ~49 grass_block
fill ~395 ~60 ~49 ~395 ~66 ~49 stone
fill ~395 ~67 ~49 ~395 ~69 ~49 dirt
fill ~395 ~70 ~49 ~395 ~70 ~49 grass_block
fill ~396 ~60 ~49 ~398 ~65 ~49 stone
fill ~396 ~66 ~49 ~398 ~68 ~49 dirt
fill ~396 ~69 ~49 ~398 ~69 ~49 grass_block
fill ~399 ~60 ~49 ~399 ~64 ~49 stone
fill ~399 ~65 ~49 ~399 ~67 ~49 dirt
fill ~399 ~68 ~49 ~399 ~68 ~49 grass_block
fill ~384 ~60 ~50 ~392 ~64 ~50 stone
fill ~384 ~65 ~50 ~392 ~67 ~50 dirt
fill ~384 ~68 ~50 ~392 ~68 ~50 grass_block
fill ~393 ~60 ~50 ~394 ~65 ~50 stone
fill ~393 ~66 ~50 ~394 ~68 ~50 dirt
fill ~393 ~69 ~50 ~394 ~69 ~50 grass_block
fill ~395 ~60 ~50 ~395 ~66 ~50 stone
fill ~395 ~67 ~50 ~395 ~69 ~50 dirt
fill ~395 ~70 ~50 ~395 ~70 ~50 grass_block
fill ~396 ~60 ~50 ~398 ~65 ~50 stone
fill ~396 ~66 ~50 ~398 ~68 ~50 dirt
fill ~396 ~69 ~50 ~398 ~69 ~50 grass_block
fill ~399 ~60 ~50 ~399 ~64 ~50 stone
fill ~399 ~65 ~50 ~399 ~67 ~50 dirt
fill ~399 ~68 ~50 ~399 ~68 ~50 grass_block
fill ~384 ~60 ~51 ~384 ~63 ~51 stone
fill ~384 ~64 ~51 ~384 ~66 ~51 dirt
fill ~384 ~67 ~51 ~384 ~67 ~51 grass_block
fill ~385 ~60 ~51 ~385 ~64 ~51 stone
fill ~385 ~65 ~51 ~385 ~67 ~51 dirt
fill ~385 ~68 ~51 ~385 ~68 ~51 grass_block
fill ~386 ~60 ~51 ~389 ~63 ~51 stone
fill ~386 ~64 ~51 ~389 ~66 ~51 dirt
fill ~386 ~67 ~51 ~389 ~67 ~51 grass_block
fill ~390 ~60 ~51 ~392 ~64 ~51 stone
fill ~390 ~65 ~51 ~392 ~67 ~51 dirt
fill ~390 ~68 ~51 ~392 ~68 ~51 grass_block
fill ~393 ~60 ~51 ~393 ~65 ~51 stone
fill ~393 ~66 ~51 ~393 ~68 ~51 dirt
fill ~393 ~69 ~51 ~393 ~69 ~51 grass_block
fill ~394 ~60 ~51 ~397 ~66 ~51 stone
fill ~394 ~67 ~51 ~397 ~69 ~51 dirt
fill ~394 ~70 ~51 ~397 ~70 ~51 grass_block
fill ~398 ~60 ~51 ~399 ~65 ~51 stone
fill ~398 ~66 ~51 ~399 ~68 ~51 dirt
fill ~398 ~69 ~51 ~399 ~69 ~51 grass_block
fill ~384 ~60 ~52 ~389 ~63 ~52 stone
fill ~384 ~64 ~52 ~389 ~66 ~52 dirt
fill ~384 ~67 ~52 ~389 ~67 ~52 grass_block
fill ~390 ~60 ~52 ~391 ~64 ~52 stone
fill ~390 ~65 ~52 ~391 ~67 ~52 dirt
fill ~390 ~68 ~52 ~391 ~68 ~52 grass_block
fill ~392 ~60 ~52 ~394 ~65 ~52 stone
fill ~392 ~66 ~52 ~394 ~68 ~52 dirt
fill ~392 ~69 ~52 ~394 ~69 ~52 grass_block
fill ~395 ~60 ~52 ~397 ~66 ~52 stone
fill ~395 ~67 ~52 ~397 ~69 ~52 dirt
fill ~395 ~70 ~52 ~397 ~70 ~52 grass_block
fill ~398 ~60 ~52 ~399 ~65 ~52 stone
fill ~398 ~66 ~52 ~399 ~68 ~52 dirt
fill ~398 ~69 ~52 ~399 ~69 ~52 grass_block
fill ~384 ~60 ~53 ~388 ~63 ~53 stone
fill ~384 ~64 ~53 ~388 ~66 ~53 dirt
fill ~384 ~67 ~53 ~388 ~67 ~53 grass_block
fill ~389 ~60 ~53 ~390 ~64 ~53 stone
fill ~389 ~65 ~53 ~390 ~67 ~53 dirt
fill ~389 ~68 ~53 ~390 ~68 ~53 grass_block
fill ~391 ~60 ~53 ~394 ~65 ~53 stone
fill ~391 ~66 ~53 ~394 ~68 ~53 dirt
fill ~391 ~69 ~53 ~394 ~69 ~53 grass_block
fill ~395 ~60 ~53 ~397 ~66 ~53 stone
fill ~395 ~67 ~53 ~397 ~69 ~53 dirt
fill ~395 ~70 ~53 ~397 ~70 ~53 grass_block
fill ~398 ~60 ~53 ~399 ~65 ~53 stone
fill ~398 ~66 ~53 ~399 ~68 ~53 dirt
fill ~398 ~69 ~53 ~399 ~69 ~53 grass_block
fill ~384 ~60 ~54 ~385 ~62 ~54 stone
fill ~384 ~63 ~54 ~385 ~65 ~54 dirt
fill ~384 ~66 ~54 ~385 ~66 ~54 grass_block
fill ~386 ~60 ~54 ~387 ~63 ~54 stone
fill ~386 ~64 ~54 ~387 ~66 ~54 dirt
fill ~386 ~67 ~54 ~387 ~67 ~54 grass_block
fill ~388 ~60 ~54 ~391 ~64 ~54 stone
fill ~388 ~65 ~54 ~391 ~67 ~54 dirt
fill ~388 ~68 ~54 ~391 ~68 ~54 grass_block
fill ~392 ~60 ~54 ~395 ~65 ~54 stone
fill ~392 ~66 ~54 ~395 ~68 ~54 dirt
fill ~392 ~69 ~54 ~395 ~69 ~54 grass_block
fill ~396 ~60 ~54 ~398 ~66 ~54 stone
fill ~396 ~67 ~54 ~398 ~69 ~54 dirt
fill ~396 ~70 ~54 ~398 ~70 ~54 grass_block
fill ~399 ~60 ~54 ~399 ~65 ~54 stone
fill ~399 ~66 ~54 ~399 ~68 ~54 dirt
fill ~399 ~69 ~54 ~399 ~69 ~54 grass_block
fill ~384 ~60 ~55 ~386 ~62 ~55 stone
fill ~384 ~63 ~55 ~386 ~65 ~55 dirt
fill ~384 ~66 ~55 ~386 ~66 ~55 grass_block
fill ~387 ~60 ~55 ~389 ~63 ~55 stone
fill ~387 ~64 ~55 ~389 ~66 ~55 dirt
fill ~387 ~67 ~55 ~389 ~67 ~55 grass_block
fill ~390 ~60 ~55 ~392 ~64 ~55 stone
fill ~390 ~65 ~55 ~392 ~67 ~55 dirt
fill ~390 ~68 ~55 ~392 ~68 ~55 grass_block
fill ~393 ~60 ~55 ~399 ~65 ~55 stone
fill ~393 ~66 ~55 ~399 ~68 ~55 dirt
fill ~393 ~69 ~55 ~399 ~69 ~55 grass_block
fill ~384 ~60 ~56 ~385 ~63 ~56 stone
fill ~384 ~64 ~56 ~385 ~66 ~56 dirt
fill ~384 ~67 ~56 ~385 ~67 ~56 grass_block
fill ~386 ~60 ~56 ~387 ~62 ~56 stone
fill ~386 ~63 ~56 ~387 ~65 ~56 dirt
fill ~386 ~66 ~56 ~387 ~66 ~56 grass_block
fill ~388 ~60 ~56 ~390 ~63 ~56 stone
fill ~388 ~64 ~56 ~390 ~66 ~56 dirt
fill ~388 ~67 ~56 ~390 ~67 ~56 grass_block
fill ~391 ~60 ~56 ~393 ~64 ~56 stone
fill ~391 ~65 ~56 ~393 ~67 ~56 dirt
fill ~391 ~68 ~56 ~393 ~68 ~56 grass_block
fill ~394 ~60 ~56 ~399 ~65 ~56 stone
fill ~394 ~66 ~56 ~399 ~68 ~56 dirt
fill ~394 ~69 ~56 ~399 ~69 ~56 grass_block
fill ~384 ~60 ~57 ~385 ~63 ~57 stone
fill ~384 ~64 ~57 ~385 ~66 ~57 dirt
fill ~384 ~67 ~57 ~385 ~67 ~57 grass_block
fill ~386 ~60 ~57 ~388 ~62 ~57 stone
fill ~386 ~63 ~57 ~388 ~65 ~57 dirt
fill ~386 ~66 ~57 ~388 ~66 ~57 grass_block
fill ~389 ~60 ~57 ~391 ~63 ~57 stone
fill ~389 ~64 ~57 ~391 ~66 ~57 dirt
fill ~389 ~67 ~57 ~391 ~67 ~57 grass_block
fill ~392 ~60 ~57 ~394 ~64 ~57 stone
fill ~392 ~65 ~57 ~394 ~67 ~57 dirt
fill ~392 ~68 ~57 ~394 ~68 ~57 grass_block
fill ~395 ~60 ~57 ~399 ~65 ~57 stone
fill ~395 ~66 ~57 ~399 ~68 ~57 dirt
fill ~395 ~69 ~57 ~399 ~69 ~57 grass_block
fill ~384 ~60 ~58 ~386 ~63 ~58 stone
fill ~384 ~64 ~58 ~386 ~66 ~58 dirt
fill ~384 ~67 ~58 ~386 ~67 ~58 grass_block
fill ~387 ~60 ~58 ~388 ~62 ~58 stone
fill ~387 ~63 ~58 ~388 ~65 ~58 dirt
fill ~387 ~66 ~58 ~388 ~66 ~58 grass_block
fill ~389 ~60 ~58 ~392 ~63 ~58 stone
fill ~389 ~64 ~58 ~392 ~66 ~58 dirt
fill ~389 ~67 ~58 ~392 ~67 ~58 grass_block
fill ~393 ~60 ~58 ~395 ~64 ~58 stone
fill ~393 ~65 ~58 ~395 ~67 ~58 dirt
fill ~393 ~68 ~58 ~395 ~68 ~58 grass_block
fill ~396 ~60 ~58 ~396 ~65 ~58 stone
fill ~396 ~66 ~58 ~396 ~68 ~58 dirt
fill ~396 ~69 ~58 ~396 ~69 ~58 grass_block
fill ~397 ~60 ~58 ~399 ~64 ~58 stone
fill ~397 ~65 ~58 ~399 ~67 ~58 dirt
fill ~397 ~68 ~58 ~399 ~68 ~58 grass_block
fill ~384 ~60 ~59 ~384 ~64 ~59 stone
fill ~384 ~65 ~59 ~384 ~67 ~59 dirt
fill ~384 ~68 ~59 ~384 ~68 ~59 grass_block
fill ~385 ~60 ~59 ~387 ~63 ~59 stone
fill ~385 ~64 ~59 ~387 ~66 ~59 dirt
fill ~385 ~67 ~59 ~387 ~67 ~59 grass_block
fill ~388 ~60 ~59 ~389 ~62 ~59 stone
fill ~388 ~63 ~59 ~389 ~65 ~59 dirt
fill ~388 ~66 ~59 ~389 ~66 ~59 grass_block
fill ~390 ~60 ~59 ~392 ~63 ~59 stone
fill ~390 ~64 ~59 ~392 ~66 ~59 dirt
fill ~390 ~67 ~59 ~392 ~67 ~59 grass_block
fill ~393 ~60 ~59 ~399 ~64 ~59 stone
fill ~393 ~65 ~59 ~399 ~67 ~59 dirt
fill ~393 ~68 ~59 ~399 ~68 ~59 grass_block
fill ~384 ~60 ~60 ~385 ~64 ~60 stone
fill ~384 ~65 ~60 ~385 ~67 ~60 dirt
fill ~384 ~68 ~60 ~385 ~68 ~60 grass_block
fill ~386 ~60 ~60 ~388 ~63 ~60 stone
fill ~386 ~64 ~60 ~388 ~66 ~60 dirt
fill ~386 ~67 ~60 ~388 ~67 ~60 grass_block
fill ~389 ~60 ~60 ~391 ~62 ~60 stone
fill ~389 ~63 ~60 ~391 ~65 ~60 dirt
fill ~389 ~66 ~60 ~391 ~66 ~60 grass_block
fill ~392 ~60 ~60 ~393 ~63 ~60 stone
fill ~392 ~64 ~60 ~393 ~66 ~60 dirt
fill ~392 ~67 ~60 ~393 ~67 ~60 grass_block
fill ~394 ~60 ~60 ~398 ~64 ~60 stone
fill ~394 ~65 ~60 ~398 ~67 ~60 dirt
fill ~394 ~68 ~60 ~398 ~68 ~60 grass_block
fill ~399 ~60 ~60 ~399 ~63 ~60 stone
fill ~399 ~64 ~60 ~399 ~66 ~60 dirt
fill ~399 ~67 ~60 ~399 ~67 ~60 grass_block
fill ~384 ~60 ~61 ~385 ~64 ~61 stone
fill ~384 ~65 ~61 ~385 ~67 ~61 dirt
fill ~384 ~68 ~61 ~385 ~68 ~61 grass_block
fill ~386 ~60 ~61 ~388 ~63 ~61 stone
fill ~386 ~64 ~61 ~388 ~66 ~61 dirt
fill ~386 ~67 ~61 ~388 ~67 ~61 grass_block
fill ~389 ~60 ~61 ~392 ~62 ~61 stone
fill ~389 ~63 ~61 ~392 ~65 ~61 dirt
fill ~389 ~66 ~61 ~392 ~66 ~61 grass_block
fill ~393 ~60 ~61 ~394 ~63 ~61 stone
fill ~393 ~64 ~61 ~394 ~66 ~61 dirt
fill ~393 ~67 ~61 ~394 ~67 ~61 grass_block
fill ~395 ~60 ~61 ~399 ~64 ~61 stone
fill ~395 ~65 ~61 ~399 ~67 ~61 dirt
fill ~395 ~68 ~61 ~399 ~68 ~61 grass_block
fill ~384 ~60 ~62 ~386 ~64 ~62 stone
fill ~384 ~65 ~62 ~386 ~67 ~62 dirt
fill ~384 ~68 ~62 ~386 ~68 ~62 grass_block
fill ~387 ~60 ~62 ~389 ~63 ~62 stone
fill ~387 ~64 ~62 ~389 ~66 ~62 dirt
fill ~387 ~67 ~62 ~389 ~67 ~62 grass_block
fill ~390 ~60 ~62 ~392 ~62 ~62 stone
fill ~390 ~63 ~62 ~392 ~65 ~62 dirt
fill ~390 ~66 ~62 ~392 ~66 ~62 grass_block
fill ~393 ~60 ~62 ~394 ~63 ~62 stone
fill ~393 ~64 ~62 ~394 ~66 ~62 dirt
fill ~393 ~67 ~62 ~394 ~67 ~62 grass_block
fill ~395 ~60 ~62 ~398 ~64 ~62 stone
fill ~395 ~65 ~62 ~398 ~67 ~62 dirt
fill ~395 ~68 ~62 ~398 ~68 ~62 grass_block
fill ~399 ~60 ~62 ~399 ~63 ~62 stone
fill ~399 ~64 ~62 ~399 ~66 ~62 dirt
fill ~399 ~67 ~62 ~399 ~67 ~62 grass_block
fill ~384 ~60 ~63 ~384 ~65 ~63 stone
fill ~384 ~66 ~63 ~384 ~68 ~63 dirt
fill ~384 ~69 ~63 ~384 ~69 ~63 grass_block
fill ~385 ~60 ~63 ~387 ~64 ~63 stone
fill ~385 ~65 ~63 ~387 ~67 ~63 dirt
fill ~385 ~68 ~63 ~387 ~68 ~63 grass_block
fill ~388 ~60 ~63 ~390 ~63 ~63 stone
fill ~388 ~64 ~63 ~390 ~66 ~63 dirt
fill ~388 ~67 ~63 ~390 ~67 ~63 grass_block
fill ~391 ~60 ~63 ~393 ~62 ~63 stone
fill ~391 ~63 ~63 ~393 ~65 ~63 dirt
fill ~391 ~66 ~63 ~393 ~66 ~63 grass_block
fill ~394 ~60 ~63 ~395 ~63 ~63 stone
fill ~394 ~64 ~63 ~395 ~66 ~63 dirt
fill ~394 ~67 ~63 ~395 ~67 ~63 grass_block
fill ~396 ~60 ~63 ~398 ~64 ~63 stone
fill ~396 ~65 ~63 ~398 ~67 ~63 dirt
fill ~396 ~68 ~63 ~398 ~68 ~63 grass_block
fill ~399 ~60 ~63 ~399 ~63 ~63 stone
fill ~399 ~64 ~63 ~399 ~66 ~63 dirt
fill ~399 ~67 ~63 ~399 ~67 ~63 grass_block