fill ~240 ~60 ~48 ~242 ~61 ~48 stone
fill ~240 ~62 ~48 ~242 ~64 ~48 dirt
fill ~240 ~65 ~48 ~242 ~65 ~48 grass_block
fill ~243 ~60 ~48 ~253 ~62 ~48 stone
fill ~243 ~63 ~48 ~253 ~65 ~48 dirt
fill ~243 ~66 ~48 ~253 ~66 ~48 grass_block
fill ~254 ~60 ~48 ~255 ~61 ~48 stone
fill ~254 ~62 ~48 ~255 ~64 ~48 dirt
fill ~254 ~65 ~48 ~255 ~65 ~48 grass_block
fill ~240 ~60 ~49 ~242 ~61 ~49 stone
fill ~240 ~62 ~49 ~242 ~64 ~49 dirt
fill ~240 ~65 ~49 ~242 ~65 ~49 grass_block
fill ~243 ~60 ~49 ~255 ~62 ~49 stone
fill ~243 ~63 ~49 ~255 ~65 ~49 dirt
fill ~243 ~66 ~49 ~255 ~66 ~49 grass_block
fill ~240 ~60 ~50 ~241 ~61 ~50 stone
fill ~240 ~62 ~50 ~241 ~64 ~50 dirt
fill ~240 ~65 ~50 ~241 ~65 ~50 grass_block
fill ~242 ~60 ~50 ~255 ~62 ~50 stone
fill ~242 ~63 ~50 ~255 ~65 ~50 dirt
fill ~242 ~66 ~50 ~255 ~66 ~50 grass_block
fill ~240 ~60 ~51 ~241 ~61 ~51 stone
fill ~240 ~62 ~51 ~241 ~64 ~51 dirt
fill ~240 ~65 ~51 ~241 ~65 ~51 grass_block
fill ~242 ~60 ~51 ~255 ~62 ~51 stone
fill ~242 ~63 ~51 ~255 ~65 ~51 dirt
fill ~242 ~66 ~51 ~255 ~66 ~51 grass_block
fill ~240 ~60 ~52 ~241 ~61 ~52 stone
fill ~240 ~62 ~52 ~241 ~64 ~52 dirt
fill ~240 ~65 ~52 ~241 ~65 ~52 grass_block
fill ~242 ~60 ~52 ~255 ~62 ~52 stone
fill ~242 ~63 ~52 ~255 ~65 ~52 dirt
fill ~242 ~66 ~52 ~255 ~66 ~52 grass_block
fill ~240 ~60 ~53 ~242 ~61 ~53 stone
fill ~240 ~62 ~53 ~242 ~64 ~53 dirt
fill ~240 ~65 ~53 ~242 ~65 ~53 grass_block
fill ~243 ~60 ~53 ~248 ~62 ~53 stone
fill ~243 ~63 ~53 ~248 ~65 ~53 dirt
fill ~243 ~66 ~53 ~248 ~66 ~53 grass_block
fill ~249 ~60 ~53 ~249 ~63 ~53 stone
fill ~249 ~64 ~53 ~249 ~66 ~53 dirt
fill ~249 ~67 ~53 ~249 ~67 ~53 grass_block
fill ~250 ~60 ~53 ~250 ~62 ~53 stone
fill ~250 ~63 ~53 ~250 ~65 ~53 dirt
fill ~250 ~66 ~53 ~250 ~66 ~53 grass_block
fill ~251 ~60 ~53 ~252 ~63 ~53 stone
fill ~251 ~64 ~53 ~252 ~66 ~53 dirt
fill ~251 ~67 ~53 ~252 ~67 ~53 grass_block
fill ~253 ~60 ~53 ~255 ~62 ~53 stone
fill ~253 ~63 ~53 ~255 ~65 ~53 dirt
fill ~253 ~66 ~53 ~255 ~66 ~53 grass_block
fill ~240 ~60 ~54 ~241 ~61 ~54 stone
fill ~240 ~62 ~54 ~241 ~64 ~54 dirt
fill ~240 ~65 ~54 ~241 ~65 ~54 grass_block
fill ~242 ~60 ~54 ~255 ~62 ~54 stone
fill ~242 ~63 ~54 ~255 ~65 ~54 dirt
fill ~242 ~66 ~54 ~255 ~66 ~54 grass_block
fill ~240 ~60 ~55 ~243 ~62 ~55 stone
fill ~240 ~63 ~55 ~243 ~65 ~55 dirt
fill ~240 ~66 ~55 ~243 ~66 ~55 grass_block
fill ~244 ~60 ~55 ~246 ~63 ~55 stone
fill ~244 ~64 ~55 ~246 ~66 ~55 dirt
fill ~244 ~67 ~55 ~246 ~67 ~55 grass_block
fill ~247 ~60 ~55 ~249 ~62 ~55 stone
fill ~247 ~63 ~55 ~249 ~65 ~55 dirt
fill ~247 ~66 ~55 ~249 ~66 ~55 grass_block
fill ~250 ~60 ~55 ~250 ~63 ~55 stone
fill ~250 ~64 ~55 ~250 ~66 ~55 dirt
fill ~250 ~67 ~55 ~250 ~67 ~55 grass_block
fill ~251 ~60 ~55 ~255 ~62 ~55 stone
fill ~251 ~63 ~55 ~255 ~65 ~55 dirt
fill ~251 ~66 ~55 ~255 ~66 ~55 grass_block
fill ~240 ~60 ~56 ~242 ~62 ~56 stone
fill ~240 ~63 ~56 ~242 ~65 ~56 dirt
fill ~240 ~66 ~56 ~242 ~66 ~56 grass_block
fill ~243 ~60 ~56 ~251 ~63 ~56 stone
fill ~243 ~64 ~56 ~251 ~66 ~56 dirt
fill ~243 ~67 ~56 ~251 ~67 ~56 grass_block
fill ~252 ~60 ~56 ~255 ~62 ~56 stone
fill ~252 ~63 ~56 ~255 ~65 ~56 dirt
fill ~252 ~66 ~56 ~255 ~66 ~56 grass_block
fill ~240 ~60 ~57 ~242 ~62 ~57 stone
fill ~240 ~63 ~57 ~242 ~65 ~57 dirt
fill ~240 ~66 ~57 ~242 ~66 ~57 grass_block
fill ~243 ~60 ~57 ~250 ~63 ~57 stone
fill ~243 ~64 ~57 ~250 ~66 ~57 dirt
fill ~243 ~67 ~57 ~250 ~67 ~57 grass_block
fill ~251 ~60 ~57 ~253 ~62 ~57 stone
fill ~251 ~63 ~57 ~253 ~65 ~57 dirt
fill ~251 ~66 ~57 ~253 ~66 ~57 grass_block
fill ~254 ~60 ~57 ~254 ~63 ~57 stone
fill ~254 ~64 ~57 ~254 ~66 ~57 dirt
fill ~254 ~67 ~57 ~254 ~67 ~57 grass_block
fill ~255 ~60 ~57 ~255 ~62 ~57 stone
fill ~255 ~63 ~57 ~255 ~65 ~57 dirt
fill ~255 ~66 ~57 ~255 ~66 ~57 grass_block
fill ~240 ~60 ~58 ~242 ~62 ~58 stone
fill ~240 ~63 ~58 ~242 ~65 ~58 dirt
fill ~240 ~66 ~58 ~242 ~66 ~58 grass_block
fill ~243 ~60 ~58 ~251 ~63 ~58 stone
fill ~243 ~64 ~58 ~251 ~66 ~58 dirt
fill ~243 ~67 ~58 ~251 ~67 ~58 grass_block
fill ~252 ~60 ~58 ~255 ~62 ~58 stone
fill ~252 ~63 ~58 ~255 ~65 ~58 dirt
fill ~252 ~66 ~58 ~255 ~66 ~58 grass_block
fill ~240 ~60 ~59 ~243 ~62 ~59 stone
fill ~240 ~63 ~59 ~243 ~65 ~59 dirt
fill ~240 ~66 ~59 ~243 ~66 ~59 grass_block
fill ~244 ~60 ~59 ~252 ~63 ~59 stone
fill ~244 ~64 ~59 ~252 ~66 ~59 dirt
fill ~244 ~67 ~59 ~252 ~67 ~59 grass_block
fill ~253 ~60 ~59 ~255 ~62 ~59 stone
fill ~253 ~63 ~59 ~255 ~65 ~59 dirt
fill ~253 ~66 ~59 ~255 ~66 ~59 grass_block
fill ~240 ~60 ~60 ~245 ~62 ~60 stone
fill ~240 ~63 ~60 ~245 ~65 ~60 dirt
fill ~240 ~66 ~60 ~245 ~66 ~60 grass_block
fill ~246 ~60 ~60 ~254 ~63 ~60 stone
fill ~246 ~64 ~60 ~254 ~66 ~60 dirt
fill ~246 ~67 ~60 ~254 ~67 ~60 grass_block
fill ~255 ~60 ~60 ~255 ~62 ~60 stone
fill ~255 ~63 ~60 ~255 ~65 ~60 dirt
fill ~255 ~66 ~60 ~255 ~66 ~60 grass_block
fill ~240 ~60 ~61 ~246 ~62 ~61 stone
fill ~240 ~63 ~61 ~246 ~65 ~61 dirt
fill ~240 ~66 ~61 ~246 ~66 ~61 grass_block
fill ~247 ~60 ~61 ~255 ~63 ~61 stone
fill ~247 ~64 ~61 ~255 ~66 ~61 dirt
fill ~247 ~67 ~61 ~255 ~67 ~61 grass_block
fill ~240 ~60 ~62 ~247 ~62 ~62 stone
fill ~240 ~63 ~62 ~247 ~65 ~62 dirt
fill ~240 ~66 ~62 ~247 ~66 ~62 grass_block
fill ~248 ~60 ~62 ~255 ~63 ~62 stone
fill ~248 ~64 ~62 ~255 ~66 ~62 dirt
fill ~248 ~67 ~62 ~255 ~67 ~62 grass_block
fill ~240 ~60 ~63 ~242 ~62 ~63 stone
fill ~240 ~63 ~63 ~242 ~65 ~63 dirt
fill ~240 ~66 ~63 ~242 ~66 ~63 grass_block
fill ~243 ~60 ~63 ~245 ~63 ~63 stone
fill ~243 ~64 ~63 ~245 ~66 ~63 dirt
fill ~243 ~67 ~63 ~245 ~67 ~63 grass_block
fill ~246 ~60 ~63 ~248 ~62 ~63 stone
fill ~246 ~63 ~63 ~248 ~65 ~63 dirt
fill ~246 ~66 ~63 ~248 ~66 ~63 grass_block
fill ~249 ~60 ~63 ~255 ~63 ~63 stone
fill ~249 ~64 ~63 ~255 ~66 ~63 dirt
fill ~249 ~67 ~63 ~255 ~67 ~63 grass_block