fill ~432 ~60 ~0 ~443 ~65 ~0 stone
fill ~432 ~66 ~0 ~443 ~68 ~0 dirt
fill ~432 ~69 ~0 ~443 ~69 ~0 grass_block
fill ~444 ~60 ~0 ~447 ~64 ~0 stone
fill ~444 ~65 ~0 ~447 ~67 ~0 dirt
fill ~444 ~68 ~0 ~447 ~68 ~0 grass_block
fill ~432 ~60 ~1 ~441 ~65 ~1 stone
fill ~432 ~66 ~1 ~441 ~68 ~1 dirt
fill ~432 ~69 ~1 ~441 ~69 ~1 grass_block
fill ~442 ~60 ~1 ~447 ~64 ~1 stone
fill ~442 ~65 ~1 ~447 ~67 ~1 dirt
fill ~442 ~68 ~1 ~447 ~68 ~1 grass_block
fill ~432 ~60 ~2 ~437 ~65 ~2 stone
fill ~432 ~66 ~2 ~437 ~68 ~2 dirt
fill ~432 ~69 ~2 ~437 ~69 ~2 grass_block
fill ~438 ~60 ~2 ~445 ~64 ~2 stone
fill ~438 ~65 ~2 ~445 ~67 ~2 dirt
fill ~438 ~68 ~2 ~445 ~68 ~2 grass_block
fill ~446 ~60 ~2 ~447 ~63 ~2 stone
fill ~446 ~64 ~2 ~447 ~66 ~2 dirt
fill ~446 ~67 ~2 ~447 ~67 ~2 grass_block
fill ~432 ~60 ~3 ~436 ~65 ~3 stone
fill ~432 ~66 ~3 ~436 ~68 ~3 dirt
fill ~432 ~69 ~3 ~436 ~69 ~3 grass_block
fill ~437 ~60 ~3 ~444 ~64 ~3 stone
fill ~437 ~65 ~3 ~444 ~67 ~3 dirt
fill ~437 ~68 ~3 ~444 ~68 ~3 grass_block
fill ~445 ~60 ~3 ~447 ~63 ~3 stone
fill ~445 ~64 ~3 ~447 ~66 ~3 dirt
fill ~445 ~67 ~3 ~447 ~67 ~3 grass_block
fill ~432 ~60 ~4 ~436 ~65 ~4 stone
fill ~432 ~66 ~4 ~436 ~68 ~4 dirt
fill ~432 ~69 ~4 ~436 ~69 ~4 grass_block
fill ~437 ~60 ~4 ~441 ~64 ~4 stone
fill ~437 ~65 ~4 ~441 ~67 ~4 dirt
fill ~437 ~68 ~4 ~441 ~68 ~4 grass_block
fill ~442 ~60 ~4 ~447 ~63 ~4 stone
fill ~442 ~64 ~4 ~447 ~66 ~4 dirt
fill ~442 ~67 ~4 ~447 ~67 ~4 grass_block
fill ~432 ~60 ~5 ~436 ~65 ~5 stone
fill ~432 ~66 ~5 ~436 ~68 ~5 dirt
fill ~432 ~69 ~5 ~436 ~69 ~5 grass_block
fill ~437 ~60 ~5 ~440 ~64 ~5 stone
fill ~437 ~65 ~5 ~440 ~67 ~5 dirt
fill ~437 ~68 ~5 ~440 ~68 ~5 grass_block
fill ~441 ~60 ~5 ~447 ~63 ~5 stone
fill ~441 ~64 ~5 ~447 ~66 ~5 dirt
fill ~441 ~67 ~5 ~447 ~67 ~5 grass_block
fill ~432 ~60 ~6 ~435 ~65 ~6 stone
fill ~432 ~66 ~6 ~435 ~68 ~6 dirt
fill ~432 ~69 ~6 ~435 ~69 ~6 grass_block
fill ~436 ~60 ~6 ~439 ~64 ~6 stone
fill ~436 ~65 ~6 ~439 ~67 ~6 dirt
fill ~436 ~68 ~6 ~439 ~68 ~6 grass_block
fill ~440 ~60 ~6 ~446 ~63 ~6 stone
fill ~440 ~64 ~6 ~446 ~66 ~6 dirt
fill ~440 ~67 ~6 ~446 ~67 ~6 grass_block
fill ~447 ~60 ~6 ~447 ~64 ~6 stone
fill ~447 ~65 ~6 ~447 ~67 ~6 dirt
fill ~447 ~68 ~6 ~447 ~68 ~6 grass_block
fill ~432 ~60 ~7 ~439 ~64 ~7 stone
fill ~432 ~65 ~7 ~439 ~67 ~7 dirt
fill ~432 ~68 ~7 ~439 ~68 ~7 grass_block
fill ~440 ~60 ~7 ~446 ~63 ~7 stone
fill ~440 ~64 ~7 ~446 ~66 ~7 dirt
fill ~440 ~67 ~7 ~446 ~67 ~7 grass_block
fill ~447 ~60 ~7 ~447 ~64 ~7 stone
fill ~447 ~65 ~7 ~447 ~67 ~7 dirt
fill ~447 ~68 ~7 ~447 ~68 ~7 grass_block
fill ~432 ~60 ~8 ~439 ~64 ~8 stone
fill ~432 ~65 ~8 ~439 ~67 ~8 dirt
fill ~432 ~68 ~8 ~439 ~68 ~8 grass_block
fill ~440 ~60 ~8 ~446 ~63 ~8 stone
fill ~440 ~64 ~8 ~446 ~66 ~8 dirt
fill ~440 ~67 ~8 ~446 ~67 ~8 grass_block
fill ~447 ~60 ~8 ~447 ~64 ~8 stone
fill ~447 ~65 ~8 ~447 ~67 ~8 dirt
fill ~447 ~68 ~8 ~447 ~68 ~8 grass_block
fill ~432 ~60 ~9 ~438 ~64 ~9 stone
fill ~432 ~65 ~9 ~438 ~67 ~9 dirt
fill ~432 ~68 ~9 ~438 ~68 ~9 grass_block
fill ~439 ~60 ~9 ~446 ~63 ~9 stone
fill ~439 ~64 ~9 ~446 ~66 ~9 dirt
fill ~439 ~67 ~9 ~446 ~67 ~9 grass_block
fill ~447 ~60 ~9 ~447 ~64 ~9 stone
fill ~447 ~65 ~9 ~447 ~67 ~9 dirt
fill ~447 ~68 ~9 ~447 ~68 ~9 grass_block
fill ~432 ~60 ~10 ~435 ~64 ~10 stone
fill ~432 ~65 ~10 ~435 ~67 ~10 dirt
fill ~432 ~68 ~10 ~435 ~68 ~10 grass_block
fill ~436 ~60 ~10 ~442 ~63 ~10 stone
fill ~436 ~64 ~10 ~442 ~66 ~10 dirt
fill ~436 ~67 ~10 ~442 ~67 ~10 grass_block
fill ~443 ~60 ~10 ~444 ~62 ~10 stone
fill ~443 ~63 ~10 ~444 ~65 ~10 dirt
fill ~443 ~66 ~10 ~444 ~66 ~10 grass_block
fill ~445 ~60 ~10 ~447 ~63 ~10 stone
fill ~445 ~64 ~10 ~447 ~66 ~10 dirt
fill ~445 ~67 ~10 ~447 ~67 ~10 grass_block
fill ~432 ~60 ~11 ~433 ~64 ~11 stone
fill ~432 ~65 ~11 ~433 ~67 ~11 dirt
fill ~432 ~68 ~11 ~433 ~68 ~11 grass_block
fill ~434 ~60 ~11 ~442 ~63 ~11 stone
fill ~434 ~64 ~11 ~442 ~66 ~11 dirt
fill ~434 ~67 ~11 ~442 ~67 ~11 grass_block
fill ~443 ~60 ~11 ~444 ~62 ~11 stone
fill ~443 ~63 ~11 ~444 ~65 ~11 dirt
fill ~443 ~66 ~11 ~444 ~66 ~11 grass_block
fill ~445 ~60 ~11 ~447 ~63 ~11 stone
fill ~445 ~64 ~11 ~447 ~66 ~11 dirt
fill ~445 ~67 ~11 ~447 ~67 ~11 grass_block
fill ~432 ~60 ~12 ~432 ~64 ~12 stone
fill ~432 ~65 ~12 ~432 ~67 ~12 dirt
fill ~432 ~68 ~12 ~432 ~68 ~12 grass_block
fill ~433 ~60 ~12 ~443 ~63 ~12 stone
fill ~433 ~64 ~12 ~443 ~66 ~12 dirt
fill ~433 ~67 ~12 ~443 ~67 ~12 grass_block
fill ~444 ~60 ~12 ~444 ~62 ~12 stone
fill ~444 ~63 ~12 ~444 ~65 ~12 dirt
fill ~444 ~66 ~12 ~444 ~66 ~12 grass_block
fill ~445 ~60 ~12 ~447 ~63 ~12 stone
fill ~445 ~64 ~12 ~447 ~66 ~12 dirt
fill ~445 ~67 ~12 ~447 ~67 ~12 grass_block
fill ~432 ~60 ~13 ~432 ~64 ~13 stone
fill ~432 ~65 ~13 ~432 ~67 ~13 dirt
fill ~432 ~68 ~13 ~432 ~68 ~13 grass_block
fill ~433 ~60 ~13 ~441 ~63 ~13 stone
fill ~433 ~64 ~13 ~441 ~66 ~13 dirt
fill ~433 ~67 ~13 ~441 ~67 ~13 grass_block
fill ~442 ~60 ~13 ~444 ~62 ~13 stone
fill ~442 ~63 ~13 ~444 ~65 ~13 dirt
fill ~442 ~66 ~13 ~444 ~66 ~13 grass_block
fill ~445 ~60 ~13 ~447 ~63 ~13 stone
fill ~445 ~64 ~13 ~447 ~66 ~13 dirt
fill ~445 ~67 ~13 ~447 ~67 ~13 grass_block
fill ~432 ~60 ~14 ~436 ~63 ~14 stone
fill ~432 ~64 ~14 ~436 ~66 ~14 dirt
fill ~432 ~67 ~14 ~436 ~67 ~14 grass_block
fill ~437 ~60 ~14 ~443 ~62 ~14 stone
fill ~437 ~63 ~14 ~443 ~65 ~14 dirt
fill ~437 ~66 ~14 ~443 ~66 ~14 grass_block
fill ~444 ~60 ~14 ~446 ~63 ~14 stone
fill ~444 ~64 ~14 ~446 ~66 ~14 dirt
fill ~444 ~67 ~14 ~446 ~67 ~14 grass_block
fill ~447 ~60 ~14 ~447 ~64 ~14 stone
fill ~447 ~65 ~14 ~447 ~67 ~14 dirt
fill ~447 ~68 ~14 ~447 ~68 ~14 grass_block
fill ~432 ~60 ~15 ~432 ~64 ~15 stone
fill ~432 ~65 ~15 ~432 ~67 ~15 dirt
fill ~432 ~68 ~15 ~432 ~68 ~15 grass_block
fill ~433 ~60 ~15 ~437 ~63 ~15 stone
fill ~433 ~64 ~15 ~437 ~66 ~15 dirt
fill ~433 ~67 ~15 ~437 ~67 ~15 grass_block
fill ~438 ~60 ~15 ~442 ~62 ~15 stone
fill ~438 ~63 ~15 ~442 ~65 ~15 dirt
fill ~438 ~66 ~15 ~442 ~66 ~15 grass_block
fill ~443 ~60 ~15 ~446 ~63 ~15 stone
fill ~443 ~64 ~15 ~446 ~66 ~15 dirt
fill ~443 ~67 ~15 ~446 ~67 ~15 grass_block
fill ~447 ~60 ~15 ~447 ~64 ~15 stone
fill ~447 ~65 ~15 ~447 ~67 ~15 dirt
fill ~447 ~68 ~15 ~447 ~68 ~15 grass_block