fill ~432 ~60 ~16 ~437 ~63 ~16 stone
fill ~432 ~64 ~16 ~437 ~66 ~16 dirt
fill ~432 ~67 ~16 ~437 ~67 ~16 grass_block
fill ~438 ~60 ~16 ~441 ~62 ~16 stone
fill ~438 ~63 ~16 ~441 ~65 ~16 dirt
fill ~438 ~66 ~16 ~441 ~66 ~16 grass_block
fill ~442 ~60 ~16 ~446 ~63 ~16 stone
fill ~442 ~64 ~16 ~446 ~66 ~16 dirt
fill ~442 ~67 ~16 ~446 ~67 ~16 grass_block
fill ~447 ~60 ~16 ~447 ~64 ~16 stone
fill ~447 ~65 ~16 ~447 ~67 ~16 dirt
fill ~447 ~68 ~16 ~447 ~68 ~16 grass_block
fill ~432 ~60 ~17 ~437 ~63 ~17 stone
fill ~432 ~64 ~17 ~437 ~66 ~17 dirt
fill ~432 ~67 ~17 ~437 ~67 ~17 grass_block
fill ~438 ~60 ~17 ~441 ~62 ~17 stone
fill ~438 ~63 ~17 ~441 ~65 ~17 dirt
fill ~438 ~66 ~17 ~441 ~66 ~17 grass_block
fill ~442 ~60 ~17 ~446 ~63 ~17 stone
fill ~442 ~64 ~17 ~446 ~66 ~17 dirt
fill ~442 ~67 ~17 ~446 ~67 ~17 grass_block
fill ~447 ~60 ~17 ~447 ~64 ~17 stone
fill ~447 ~65 ~17 ~447 ~67 ~17 dirt
fill ~447 ~68 ~17 ~447 ~68 ~17 grass_block
fill ~432 ~60 ~18 ~437 ~63 ~18 stone
fill ~432 ~64 ~18 ~437 ~66 ~18 dirt
fill ~432 ~67 ~18 ~437 ~67 ~18 grass_block
fill ~438 ~60 ~18 ~441 ~62 ~18 stone
fill ~438 ~63 ~18 ~441 ~65 ~18 dirt
fill ~438 ~66 ~18 ~441 ~66 ~18 grass_block
fill ~442 ~60 ~18 ~446 ~63 ~18 stone
fill ~442 ~64 ~18 ~446 ~66 ~18 dirt
fill ~442 ~67 ~18 ~446 ~67 ~18 grass_block
fill ~447 ~60 ~18 ~447 ~64 ~18 stone
fill ~447 ~65 ~18 ~447 ~67 ~18 dirt
fill ~447 ~68 ~18 ~447 ~68 ~18 grass_block
fill ~432 ~60 ~19 ~436 ~63 ~19 stone
fill ~432 ~64 ~19 ~436 ~66 ~19 dirt
fill ~432 ~67 ~19 ~436 ~67 ~19 grass_block
fill ~437 ~60 ~19 ~441 ~62 ~19 stone
fill ~437 ~63 ~19 ~441 ~65 ~19 dirt
fill ~437 ~66 ~19 ~441 ~66 ~19 grass_block
fill ~442 ~60 ~19 ~445 ~63 ~19 stone
fill ~442 ~64 ~19 ~445 ~66 ~19 dirt
fill ~442 ~67 ~19 ~445 ~67 ~19 grass_block
fill ~446 ~60 ~19 ~447 ~64 ~19 stone
fill ~446 ~65 ~19 ~447 ~67 ~19 dirt
fill ~446 ~68 ~19 ~447 ~68 ~19 grass_block
fill ~432 ~60 ~20 ~436 ~63 ~20 stone
fill ~432 ~64 ~20 ~436 ~66 ~20 dirt
fill ~432 ~67 ~20 ~436 ~67 ~20 grass_block
fill ~437 ~60 ~20 ~441 ~62 ~20 stone
fill ~437 ~63 ~20 ~441 ~65 ~20 dirt
fill ~437 ~66 ~20 ~441 ~66 ~20 grass_block
fill ~442 ~60 ~20 ~445 ~63 ~20 stone
fill ~442 ~64 ~20 ~445 ~66 ~20 dirt
fill ~442 ~67 ~20 ~445 ~67 ~20 grass_block
fill ~446 ~60 ~20 ~447 ~64 ~20 stone
fill ~446 ~65 ~20 ~447 ~67 ~20 dirt
fill ~446 ~68 ~20 ~447 ~68 ~20 grass_block
fill ~432 ~60 ~21 ~436 ~63 ~21 stone
fill ~432 ~64 ~21 ~436 ~66 ~21 dirt
fill ~432 ~67 ~21 ~436 ~67 ~21 grass_block
fill ~437 ~60 ~21 ~441 ~62 ~21 stone
fill ~437 ~63 ~21 ~441 ~65 ~21 dirt
fill ~437 ~66 ~21 ~441 ~66 ~21 grass_block
fill ~442 ~60 ~21 ~445 ~63 ~21 stone
fill ~442 ~64 ~21 ~445 ~66 ~21 dirt
fill ~442 ~67 ~21 ~445 ~67 ~21 grass_block
fill ~446 ~60 ~21 ~447 ~64 ~21 stone
fill ~446 ~65 ~21 ~447 ~67 ~21 dirt
fill ~446 ~68 ~21 ~447 ~68 ~21 grass_block
fill ~432 ~60 ~22 ~436 ~63 ~22 stone
fill ~432 ~64 ~22 ~436 ~66 ~22 dirt
fill ~432 ~67 ~22 ~436 ~67 ~22 grass_block
fill ~437 ~60 ~22 ~441 ~62 ~22 stone
fill ~437 ~63 ~22 ~441 ~65 ~22 dirt
fill ~437 ~66 ~22 ~441 ~66 ~22 grass_block
fill ~442 ~60 ~22 ~445 ~63 ~22 stone
fill ~442 ~64 ~22 ~445 ~66 ~22 dirt
fill ~442 ~67 ~22 ~445 ~67 ~22 grass_block
fill ~446 ~60 ~22 ~447 ~64 ~22 stone
fill ~446 ~65 ~22 ~447 ~67 ~22 dirt
fill ~446 ~68 ~22 ~447 ~68 ~22 grass_block
fill ~432 ~60 ~23 ~433 ~62 ~23 stone
fill ~432 ~63 ~23 ~433 ~65 ~23 dirt
fill ~432 ~66 ~23 ~433 ~66 ~23 grass_block
fill ~434 ~60 ~23 ~435 ~63 ~23 stone
fill ~434 ~64 ~23 ~435 ~66 ~23 dirt
fill ~434 ~67 ~23 ~435 ~67 ~23 grass_block
fill ~436 ~60 ~23 ~442 ~62 ~23 stone
fill ~436 ~63 ~23 ~442 ~65 ~23 dirt
fill ~436 ~66 ~23 ~442 ~66 ~23 grass_block
fill ~443 ~60 ~23 ~447 ~63 ~23 stone
fill ~443 ~64 ~23 ~447 ~66 ~23 dirt
fill ~443 ~67 ~23 ~447 ~67 ~23 grass_block
fill ~432 ~60 ~24 ~443 ~62 ~24 stone
fill ~432 ~63 ~24 ~443 ~65 ~24 dirt
fill ~432 ~66 ~24 ~443 ~66 ~24 grass_block
fill ~444 ~60 ~24 ~447 ~63 ~24 stone
fill ~444 ~64 ~24 ~447 ~66 ~24 dirt
fill ~444 ~67 ~24 ~447 ~67 ~24 grass_block
fill ~432 ~60 ~25 ~444 ~62 ~25 stone
fill ~432 ~63 ~25 ~444 ~65 ~25 dirt
fill ~432 ~66 ~25 ~444 ~66 ~25 grass_block
fill ~445 ~60 ~25 ~447 ~63 ~25 stone
fill ~445 ~64 ~25 ~447 ~66 ~25 dirt
fill ~445 ~67 ~25 ~447 ~67 ~25 grass_block
fill ~432 ~60 ~26 ~435 ~61 ~26 stone
fill ~432 ~62 ~26 ~435 ~64 ~26 dirt
fill ~432 ~65 ~26 ~435 ~65 ~26 grass_block
fill ~436 ~60 ~26 ~446 ~62 ~26 stone
fill ~436 ~63 ~26 ~446 ~65 ~26 dirt
fill ~436 ~66 ~26 ~446 ~66 ~26 grass_block
fill ~447 ~60 ~26 ~447 ~63 ~26 stone
fill ~447 ~64 ~26 ~447 ~66 ~26 dirt
fill ~447 ~67 ~26 ~447 ~67 ~26 grass_block
fill ~432 ~60 ~27 ~437 ~61 ~27 stone
fill ~432 ~62 ~27 ~437 ~64 ~27 dirt
fill ~432 ~65 ~27 ~437 ~65 ~27 grass_block
fill ~438 ~60 ~27 ~447 ~62 ~27 stone
fill ~438 ~63 ~27 ~447 ~65 ~27 dirt
fill ~438 ~66 ~27 ~447 ~66 ~27 grass_block
fill ~432 ~60 ~28 ~433 ~62 ~28 stone
fill ~432 ~63 ~28 ~433 ~65 ~28 dirt
fill ~432 ~66 ~28 ~433 ~66 ~28 grass_block
fill ~434 ~60 ~28 ~438 ~61 ~28 stone
fill ~434 ~62 ~28 ~438 ~64 ~28 dirt
fill ~434 ~65 ~28 ~438 ~65 ~28 grass_block
fill ~439 ~60 ~28 ~447 ~62 ~28 stone
fill ~439 ~63 ~28 ~447 ~65 ~28 dirt
fill ~439 ~66 ~28 ~447 ~66 ~28 grass_block
fill ~432 ~60 ~29 ~435 ~62 ~29 stone
fill ~432 ~63 ~29 ~435 ~65 ~29 dirt
fill ~432 ~66 ~29 ~435 ~66 ~29 grass_block
fill ~436 ~60 ~29 ~440 ~61 ~29 stone
fill ~436 ~62 ~29 ~440 ~64 ~29 dirt
fill ~436 ~65 ~29 ~440 ~65 ~29 grass_block
fill ~441 ~60 ~29 ~443 ~62 ~29 stone
fill ~441 ~63 ~29 ~443 ~65 ~29 dirt
fill ~441 ~66 ~29 ~443 ~66 ~29 grass_block
fill ~444 ~60 ~29 ~444 ~61 ~29 stone
fill ~444 ~62 ~29 ~444 ~64 ~29 dirt
fill ~444 ~65 ~29 ~444 ~65 ~29 grass_block
fill ~445 ~60 ~29 ~447 ~62 ~29 stone
fill ~445 ~63 ~29 ~447 ~65 ~29 dirt
fill ~445 ~66 ~29 ~447 ~66 ~29 grass_block
fill ~432 ~60 ~30 ~433 ~63 ~30 stone
fill ~432 ~64 ~30 ~433 ~66 ~30 dirt
fill ~432 ~67 ~30 ~433 ~67 ~30 grass_block
fill ~434 ~60 ~30 ~436 ~62 ~30 stone
fill ~434 ~63 ~30 ~436 ~65 ~30 dirt
fill ~434 ~66 ~30 ~436 ~66 ~30 grass_block
fill ~437 ~60 ~30 ~442 ~61 ~30 stone
fill ~437 ~62 ~30 ~442 ~64 ~30 dirt
fill ~437 ~65 ~30 ~442 ~65 ~30 grass_block
fill ~443 ~60 ~30 ~444 ~62 ~30 stone
fill ~443 ~63 ~30 ~444 ~65 ~30 dirt
fill ~443 ~66 ~30 ~444 ~66 ~30 grass_block
fill ~445 ~60 ~30 ~446 ~61 ~30 stone
fill ~445 ~62 ~30 ~446 ~64 ~30 dirt
fill ~445 ~65 ~30 ~446 ~65 ~30 grass_block
fill ~447 ~60 ~30 ~447 ~62 ~30 stone
fill ~447 ~63 ~30 ~447 ~65 ~30 dirt
fill ~447 ~66 ~30 ~447 ~66 ~30 grass_block
fill ~432 ~60 ~31 ~432 ~63 ~31 stone
fill ~432 ~64 ~31 ~432 ~66 ~31 dirt
fill ~432 ~67 ~31 ~432 ~67 ~31 grass_block
fill ~433 ~60 ~31 ~437 ~62 ~31 stone
fill ~433 ~63 ~31 ~437 ~65 ~31 dirt
fill ~433 ~66 ~31 ~437 ~66 ~31 grass_block
fill ~438 ~60 ~31 ~447 ~61 ~31 stone
fill ~438 ~62 ~31 ~447 ~64 ~31 dirt
fill ~438 ~65 ~31 ~447 ~65 ~31 grass_block