fill ~80 ~60 ~96 ~81 ~67 ~96 stone
fill ~80 ~68 ~96 ~81 ~70 ~96 dirt
fill ~80 ~71 ~96 ~81 ~71 ~96 grass_block
fill ~82 ~60 ~96 ~83 ~66 ~96 stone
fill ~82 ~67 ~96 ~83 ~69 ~96 dirt
fill ~82 ~70 ~96 ~83 ~70 ~96 grass_block
fill ~84 ~60 ~96 ~88 ~65 ~96 stone
fill ~84 ~66 ~96 ~88 ~68 ~96 dirt
fill ~84 ~69 ~96 ~88 ~69 ~96 grass_block
fill ~89 ~60 ~96 ~95 ~66 ~96 stone
fill ~89 ~67 ~96 ~95 ~69 ~96 dirt
fill ~89 ~70 ~96 ~95 ~70 ~96 grass_block
fill ~80 ~60 ~97 ~80 ~68 ~97 stone
fill ~80 ~69 ~97 ~80 ~71 ~97 dirt
fill ~80 ~72 ~97 ~80 ~72 ~97 grass_block
fill ~81 ~60 ~97 ~81 ~67 ~97 stone
fill ~81 ~68 ~97 ~81 ~70 ~97 dirt
fill ~81 ~71 ~97 ~81 ~71 ~97 grass_block
fill ~82 ~60 ~97 ~85 ~66 ~97 stone
fill ~82 ~67 ~97 ~85 ~69 ~97 dirt
fill ~82 ~70 ~97 ~85 ~70 ~97 grass_block
fill ~86 ~60 ~97 ~86 ~65 ~97 stone
fill ~86 ~66 ~97 ~86 ~68 ~97 dirt
fill ~86 ~69 ~97 ~86 ~69 ~97 grass_block
fill ~87 ~60 ~97 ~95 ~66 ~97 stone
fill ~87 ~67 ~97 ~95 ~69 ~97 dirt
fill ~87 ~70 ~97 ~95 ~70 ~97 grass_block
fill ~80 ~60 ~98 ~81 ~68 ~98 stone
fill ~80 ~69 ~98 ~81 ~71 ~98 dirt
fill ~80 ~72 ~98 ~81 ~72 ~98 grass_block
fill ~82 ~60 ~98 ~83 ~67 ~98 stone
fill ~82 ~68 ~98 ~83 ~70 ~98 dirt
fill ~82 ~71 ~98 ~83 ~71 ~98 grass_block
fill ~84 ~60 ~98 ~88 ~66 ~98 stone
fill ~84 ~67 ~98 ~88 ~69 ~98 dirt
fill ~84 ~70 ~98 ~88 ~70 ~98 grass_block
fill ~89 ~60 ~98 ~93 ~67 ~98 stone
fill ~89 ~68 ~98 ~93 ~70 ~98 dirt
fill ~89 ~71 ~98 ~93 ~71 ~98 grass_block
fill ~94 ~60 ~98 ~95 ~66 ~98 stone
fill ~94 ~67 ~98 ~95 ~69 ~98 dirt
fill ~94 ~70 ~98 ~95 ~70 ~98 grass_block
fill ~80 ~60 ~99 ~82 ~68 ~99 stone
fill ~80 ~69 ~99 ~82 ~71 ~99 dirt
fill ~80 ~72 ~99 ~82 ~72 ~99 grass_block
fill ~83 ~60 ~99 ~86 ~67 ~99 stone
fill ~83 ~68 ~99 ~86 ~70 ~99 dirt
fill ~83 ~71 ~99 ~86 ~71 ~99 grass_block
fill ~87 ~60 ~99 ~87 ~66 ~99 stone
fill ~87 ~67 ~99 ~87 ~69 ~99 dirt
fill ~87 ~70 ~99 ~87 ~70 ~99 grass_block
fill ~88 ~60 ~99 ~93 ~67 ~99 stone
fill ~88 ~68 ~99 ~93 ~70 ~99 dirt
fill ~88 ~71 ~99 ~93 ~71 ~99 grass_block
fill ~94 ~60 ~99 ~95 ~66 ~99 stone
fill ~94 ~67 ~99 ~95 ~69 ~99 dirt
fill ~94 ~70 ~99 ~95 ~70 ~99 grass_block
fill ~80 ~60 ~100 ~83 ~68 ~100 stone
fill ~80 ~69 ~100 ~83 ~71 ~100 dirt
fill ~80 ~72 ~100 ~83 ~72 ~100 grass_block
fill ~84 ~60 ~100 ~93 ~67 ~100 stone
fill ~84 ~68 ~100 ~93 ~70 ~100 dirt
fill ~84 ~71 ~100 ~93 ~71 ~100 grass_block
fill ~94 ~60 ~100 ~95 ~66 ~100 stone
fill ~94 ~67 ~100 ~95 ~69 ~100 dirt
fill ~94 ~70 ~100 ~95 ~70 ~100 grass_block
fill ~80 ~60 ~101 ~81 ~68 ~101 stone
fill ~80 ~69 ~101 ~81 ~71 ~101 dirt
fill ~80 ~72 ~101 ~81 ~72 ~101 grass_block
fill ~82 ~60 ~101 ~93 ~67 ~101 stone
fill ~82 ~68 ~101 ~93 ~70 ~101 dirt
fill ~82 ~71 ~101 ~93 ~71 ~101 grass_block
fill ~94 ~60 ~101 ~95 ~66 ~101 stone
fill ~94 ~67 ~101 ~95 ~69 ~101 dirt
fill ~94 ~70 ~101 ~95 ~70 ~101 grass_block
fill ~80 ~60 ~102 ~81 ~68 ~102 stone
fill ~80 ~69 ~102 ~81 ~71 ~102 dirt
fill ~80 ~72 ~102 ~81 ~72 ~102 grass_block
fill ~82 ~60 ~102 ~89 ~67 ~102 stone
fill ~82 ~68 ~102 ~89 ~70 ~102 dirt
fill ~82 ~71 ~102 ~89 ~71 ~102 grass_block
fill ~90 ~60 ~102 ~91 ~68 ~102 stone
fill ~90 ~69 ~102 ~91 ~71 ~102 dirt
fill ~90 ~72 ~102 ~91 ~72 ~102 grass_block
fill ~92 ~60 ~102 ~93 ~67 ~102 stone
fill ~92 ~68 ~102 ~93 ~70 ~102 dirt
fill ~92 ~71 ~102 ~93 ~71 ~102 grass_block
fill ~94 ~60 ~102 ~95 ~66 ~102 stone
fill ~94 ~67 ~102 ~95 ~69 ~102 dirt
fill ~94 ~70 ~102 ~95 ~70 ~102 grass_block
fill ~80 ~60 ~103 ~81 ~68 ~103 stone
fill ~80 ~69 ~103 ~81 ~71 ~103 dirt
fill ~80 ~72 ~103 ~81 ~72 ~103 grass_block
fill ~82 ~60 ~103 ~89 ~67 ~103 stone
fill ~82 ~68 ~103 ~89 ~70 ~103 dirt
fill ~82 ~71 ~103 ~89 ~71 ~103 grass_block
fill ~90 ~60 ~103 ~92 ~68 ~103 stone
fill ~90 ~69 ~103 ~92 ~71 ~103 dirt
fill ~90 ~72 ~103 ~92 ~72 ~103 grass_block
fill ~93 ~60 ~103 ~93 ~67 ~103 stone
fill ~93 ~68 ~103 ~93 ~70 ~103 dirt
fill ~93 ~71 ~103 ~93 ~71 ~103 grass_block
fill ~94 ~60 ~103 ~95 ~66 ~103 stone
fill ~94 ~67 ~103 ~95 ~69 ~103 dirt
fill ~94 ~70 ~103 ~95 ~70 ~103 grass_block
fill ~80 ~60 ~104 ~81 ~68 ~104 stone
fill ~80 ~69 ~104 ~81 ~71 ~104 dirt
fill ~80 ~72 ~104 ~81 ~72 ~104 grass_block
fill ~82 ~60 ~104 ~89 ~67 ~104 stone
fill ~82 ~68 ~104 ~89 ~70 ~104 dirt
fill ~82 ~71 ~104 ~89 ~71 ~104 grass_block
fill ~90 ~60 ~104 ~93 ~68 ~104 stone
fill ~90 ~69 ~104 ~93 ~71 ~104 dirt
fill ~90 ~72 ~104 ~93 ~72 ~104 grass_block
fill ~94 ~60 ~104 ~94 ~67 ~104 stone
fill ~94 ~68 ~104 ~94 ~70 ~104 dirt
fill ~94 ~71 ~104 ~94 ~71 ~104 grass_block
fill ~95 ~60 ~104 ~95 ~66 ~104 stone
fill ~95 ~67 ~104 ~95 ~69 ~104 dirt
fill ~95 ~70 ~104 ~95 ~70 ~104 grass_block
fill ~80 ~60 ~105 ~82 ~68 ~105 stone
fill ~80 ~69 ~105 ~82 ~71 ~105 dirt
fill ~80 ~72 ~105 ~82 ~72 ~105 grass_block
fill ~83 ~60 ~105 ~84 ~67 ~105 stone
fill ~83 ~68 ~105 ~84 ~70 ~105 dirt
fill ~83 ~71 ~105 ~84 ~71 ~105 grass_block
fill ~85 ~60 ~105 ~85 ~66 ~105 stone
fill ~85 ~67 ~105 ~85 ~69 ~105 dirt
fill ~85 ~70 ~105 ~85 ~70 ~105 grass_block
fill ~86 ~60 ~105 ~90 ~67 ~105 stone
fill ~86 ~68 ~105 ~90 ~70 ~105 dirt
fill ~86 ~71 ~105 ~90 ~71 ~105 grass_block
fill ~91 ~60 ~105 ~94 ~68 ~105 stone
fill ~91 ~69 ~105 ~94 ~71 ~105 dirt
fill ~91 ~72 ~105 ~94 ~72 ~105 grass_block
fill ~95 ~60 ~105 ~95 ~67 ~105 stone
fill ~95 ~68 ~105 ~95 ~70 ~105 dirt
fill ~95 ~71 ~105 ~95 ~71 ~105 grass_block
fill ~80 ~60 ~106 ~82 ~68 ~106 stone
fill ~80 ~69 ~106 ~82 ~71 ~106 dirt
fill ~80 ~72 ~106 ~82 ~72 ~106 grass_block
fill ~83 ~60 ~106 ~84 ~67 ~106 stone
fill ~83 ~68 ~106 ~84 ~70 ~106 dirt
fill ~83 ~71 ~106 ~84 ~71 ~106 grass_block
fill ~85 ~60 ~106 ~86 ~66 ~106 stone
fill ~85 ~67 ~106 ~86 ~69 ~106 dirt
fill ~85 ~70 ~106 ~86 ~70 ~106 grass_block
fill ~87 ~60 ~106 ~91 ~67 ~106 stone
fill ~87 ~68 ~106 ~91 ~70 ~106 dirt
fill ~87 ~71 ~106 ~91 ~71 ~106 grass_block
fill ~92 ~60 ~106 ~95 ~68 ~106 stone
fill ~92 ~69 ~106 ~95 ~71 ~106 dirt
fill ~92 ~72 ~106 ~95 ~72 ~106 grass_block
fill ~80 ~60 ~107 ~83 ~68 ~107 stone
fill ~80 ~69 ~107 ~83 ~71 ~107 dirt
fill ~80 ~72 ~107 ~83 ~72 ~107 grass_block
fill ~84 ~60 ~107 ~85 ~67 ~107 stone
fill ~84 ~68 ~107 ~85 ~70 ~107 dirt
fill ~84 ~71 ~107 ~85 ~71 ~107 grass_block
fill ~86 ~60 ~107 ~87 ~66 ~107 stone
fill ~86 ~67 ~107 ~87 ~69 ~107 dirt
fill ~86 ~70 ~107 ~87 ~70 ~107 grass_block
fill ~88 ~60 ~107 ~92 ~67 ~107 stone
fill ~88 ~68 ~107 ~92 ~70 ~107 dirt
fill ~88 ~71 ~107 ~92 ~71 ~107 grass_block
fill ~93 ~60 ~107 ~95 ~68 ~107 stone
fill ~93 ~69 ~107 ~95 ~71 ~107 dirt
fill ~93 ~72 ~107 ~95 ~72 ~107 grass_block
fill ~80 ~60 ~108 ~82 ~68 ~108 stone
fill ~80 ~69 ~108 ~82 ~71 ~108 dirt
fill ~80 ~72 ~108 ~82 ~72 ~108 grass_block
fill ~83 ~60 ~108 ~86 ~67 ~108 stone
fill ~83 ~68 ~108 ~86 ~70 ~108 dirt
fill ~83 ~71 ~108 ~86 ~71 ~108 grass_block
fill ~87 ~60 ~108 ~89 ~66 ~108 stone
fill ~87 ~67 ~108 ~89 ~69 ~108 dirt
fill ~87 ~70 ~108 ~89 ~70 ~108 grass_block
fill ~90 ~60 ~108 ~93 ~67 ~108 stone
fill ~90 ~68 ~108 ~93 ~70 ~108 dirt
fill ~90 ~71 ~108 ~93 ~71 ~108 grass_block
fill ~94 ~60 ~108 ~95 ~68 ~108 stone
fill ~94 ~69 ~108 ~95 ~71 ~108 dirt
fill ~94 ~72 ~108 ~95 ~72 ~108 grass_block
fill ~80 ~60 ~109 ~82 ~68 ~109 stone
fill ~80 ~69 ~109 ~82 ~71 ~109 dirt
fill ~80 ~72 ~109 ~82 ~72 ~109 grass_block
fill ~83 ~60 ~109 ~86 ~67 ~109 stone
fill ~83 ~68 ~109 ~86 ~70 ~109 dirt
fill ~83 ~71 ~109 ~86 ~71 ~109 grass_block
fill ~87 ~60 ~109 ~90 ~66 ~109 stone
fill ~87 ~67 ~109 ~90 ~69 ~109 dirt
fill ~87 ~70 ~109 ~90 ~70 ~109 grass_block
fill ~91 ~60 ~109 ~93 ~67 ~109 stone
fill ~91 ~68 ~109 ~93 ~70 ~109 dirt
fill ~91 ~71 ~109 ~93 ~71 ~109 grass_block
fill ~94 ~60 ~109 ~95 ~68 ~109 stone
fill ~94 ~69 ~109 ~95 ~71 ~109 dirt
fill ~94 ~72 ~109 ~95 ~72 ~109 grass_block
fill ~80 ~60 ~110 ~82 ~68 ~110 stone
fill ~80 ~69 ~110 ~82 ~71 ~110 dirt
fill ~80 ~72 ~110 ~82 ~72 ~110 grass_block
fill ~83 ~60 ~110 ~86 ~67 ~110 stone
fill ~83 ~68 ~110 ~86 ~70 ~110 dirt
fill ~83 ~71 ~110 ~86 ~71 ~110 grass_block
fill ~87 ~60 ~110 ~91 ~66 ~110 stone
fill ~87 ~67 ~110 ~91 ~69 ~110 dirt
fill ~87 ~70 ~110 ~91 ~70 ~110 grass_block
fill ~92 ~60 ~110 ~94 ~67 ~110 stone
fill ~92 ~68 ~110 ~94 ~70 ~110 dirt
fill ~92 ~71 ~110 ~94 ~71 ~110 grass_block
fill ~95 ~60 ~110 ~95 ~68 ~110 stone
fill ~95 ~69 ~110 ~95 ~71 ~110 dirt
fill ~95 ~72 ~110 ~95 ~72 ~110 grass_block
fill ~80 ~60 ~111 ~86 ~67 ~111 stone
fill ~80 ~68 ~111 ~86 ~70 ~111 dirt
fill ~80 ~71 ~111 ~86 ~71 ~111 grass_block
fill ~87 ~60 ~111 ~91 ~66 ~111 stone
fill ~87 ~67 ~111 ~91 ~69 ~111 dirt
fill ~87 ~70 ~111 ~91 ~70 ~111 grass_block
fill ~92 ~60 ~111 ~94 ~67 ~111 stone
fill ~92 ~68 ~111 ~94 ~70 ~111 dirt
fill ~92 ~71 ~111 ~94 ~71 ~111 grass_block
fill ~95 ~60 ~111 ~95 ~68 ~111 stone
fill ~95 ~69 ~111 ~95 ~71 ~111 dirt
fill ~95 ~72 ~111 ~95 ~72 ~111 grass_block