fill ~368 ~60 ~96 ~371 ~65 ~96 stone
fill ~368 ~66 ~96 ~371 ~68 ~96 dirt
fill ~368 ~69 ~96 ~371 ~69 ~96 grass_block
fill ~372 ~60 ~96 ~375 ~64 ~96 stone
fill ~372 ~65 ~96 ~375 ~67 ~96 dirt
fill ~372 ~68 ~96 ~375 ~68 ~96 grass_block
fill ~376 ~60 ~96 ~377 ~63 ~96 stone
fill ~376 ~64 ~96 ~377 ~66 ~96 dirt
fill ~376 ~67 ~96 ~377 ~67 ~96 grass_block
fill ~378 ~60 ~96 ~383 ~64 ~96 stone
fill ~378 ~65 ~96 ~383 ~67 ~96 dirt
fill ~378 ~68 ~96 ~383 ~68 ~96 grass_block
fill ~368 ~60 ~97 ~371 ~65 ~97 stone
fill ~368 ~66 ~97 ~371 ~68 ~97 dirt
fill ~368 ~69 ~97 ~371 ~69 ~97 grass_block
fill ~372 ~60 ~97 ~375 ~64 ~97 stone
fill ~372 ~65 ~97 ~375 ~67 ~97 dirt
fill ~372 ~68 ~97 ~375 ~68 ~97 grass_block
fill ~376 ~60 ~97 ~378 ~63 ~97 stone
fill ~376 ~64 ~97 ~378 ~66 ~97 dirt
fill ~376 ~67 ~97 ~378 ~67 ~97 grass_block
fill ~379 ~60 ~97 ~383 ~64 ~97 stone
fill ~379 ~65 ~97 ~383 ~67 ~97 dirt
fill ~379 ~68 ~97 ~383 ~68 ~97 grass_block
fill ~368 ~60 ~98 ~371 ~65 ~98 stone
fill ~368 ~66 ~98 ~371 ~68 ~98 dirt
fill ~368 ~69 ~98 ~371 ~69 ~98 grass_block
fill ~372 ~60 ~98 ~375 ~64 ~98 stone
fill ~372 ~65 ~98 ~375 ~67 ~98 dirt
fill ~372 ~68 ~98 ~375 ~68 ~98 grass_block
fill ~376 ~60 ~98 ~379 ~63 ~98 stone
fill ~376 ~64 ~98 ~379 ~66 ~98 dirt
fill ~376 ~67 ~98 ~379 ~67 ~98 grass_block
fill ~380 ~60 ~98 ~383 ~64 ~98 stone
fill ~380 ~65 ~98 ~383 ~67 ~98 dirt
fill ~380 ~68 ~98 ~383 ~68 ~98 grass_block
fill ~368 ~60 ~99 ~371 ~65 ~99 stone
fill ~368 ~66 ~99 ~371 ~68 ~99 dirt
fill ~368 ~69 ~99 ~371 ~69 ~99 grass_block
fill ~372 ~60 ~99 ~375 ~64 ~99 stone
fill ~372 ~65 ~99 ~375 ~67 ~99 dirt
fill ~372 ~68 ~99 ~375 ~68 ~99 grass_block
fill ~376 ~60 ~99 ~380 ~63 ~99 stone
fill ~376 ~64 ~99 ~380 ~66 ~99 dirt
fill ~376 ~67 ~99 ~380 ~67 ~99 grass_block
fill ~381 ~60 ~99 ~383 ~64 ~99 stone
fill ~381 ~65 ~99 ~383 ~67 ~99 dirt
fill ~381 ~68 ~99 ~383 ~68 ~99 grass_block
fill ~368 ~60 ~100 ~371 ~65 ~100 stone
fill ~368 ~66 ~100 ~371 ~68 ~100 dirt
fill ~368 ~69 ~100 ~371 ~69 ~100 grass_block
fill ~372 ~60 ~100 ~376 ~64 ~100 stone
fill ~372 ~65 ~100 ~376 ~67 ~100 dirt
fill ~372 ~68 ~100 ~376 ~68 ~100 grass_block
fill ~377 ~60 ~100 ~381 ~63 ~100 stone
fill ~377 ~64 ~100 ~381 ~66 ~100 dirt
fill ~377 ~67 ~100 ~381 ~67 ~100 grass_block
fill ~382 ~60 ~100 ~383 ~64 ~100 stone
fill ~382 ~65 ~100 ~383 ~67 ~100 dirt
fill ~382 ~68 ~100 ~383 ~68 ~100 grass_block
fill ~368 ~60 ~101 ~371 ~65 ~101 stone
fill ~368 ~66 ~101 ~371 ~68 ~101 dirt
fill ~368 ~69 ~101 ~371 ~69 ~101 grass_block
fill ~372 ~60 ~101 ~376 ~64 ~101 stone
fill ~372 ~65 ~101 ~376 ~67 ~101 dirt
fill ~372 ~68 ~101 ~376 ~68 ~101 grass_block
fill ~377 ~60 ~101 ~382 ~63 ~101 stone
fill ~377 ~64 ~101 ~382 ~66 ~101 dirt
fill ~377 ~67 ~101 ~382 ~67 ~101 grass_block
fill ~383 ~60 ~101 ~383 ~64 ~101 stone
fill ~383 ~65 ~101 ~383 ~67 ~101 dirt
fill ~383 ~68 ~101 ~383 ~68 ~101 grass_block
fill ~368 ~60 ~102 ~371 ~65 ~102 stone
fill ~368 ~66 ~102 ~371 ~68 ~102 dirt
fill ~368 ~69 ~102 ~371 ~69 ~102 grass_block
fill ~372 ~60 ~102 ~376 ~64 ~102 stone
fill ~372 ~65 ~102 ~376 ~67 ~102 dirt
fill ~372 ~68 ~102 ~376 ~68 ~102 grass_block
fill ~377 ~60 ~102 ~383 ~63 ~102 stone
fill ~377 ~64 ~102 ~383 ~66 ~102 dirt
fill ~377 ~67 ~102 ~383 ~67 ~102 grass_block
fill ~368 ~60 ~103 ~372 ~65 ~103 stone
fill ~368 ~66 ~103 ~372 ~68 ~103 dirt
fill ~368 ~69 ~103 ~372 ~69 ~103 grass_block
fill ~373 ~60 ~103 ~377 ~64 ~103 stone
fill ~373 ~65 ~103 ~377 ~67 ~103 dirt
fill ~373 ~68 ~103 ~377 ~68 ~103 grass_block
fill ~378 ~60 ~103 ~383 ~63 ~103 stone
fill ~378 ~64 ~103 ~383 ~66 ~103 dirt
fill ~378 ~67 ~103 ~383 ~67 ~103 grass_block
fill ~368 ~60 ~104 ~371 ~65 ~104 stone
fill ~368 ~66 ~104 ~371 ~68 ~104 dirt
fill ~368 ~69 ~104 ~371 ~69 ~104 grass_block
fill ~372 ~60 ~104 ~377 ~64 ~104 stone
fill ~372 ~65 ~104 ~377 ~67 ~104 dirt
fill ~372 ~68 ~104 ~377 ~68 ~104 grass_block
fill ~378 ~60 ~104 ~383 ~63 ~104 stone
fill ~378 ~64 ~104 ~383 ~66 ~104 dirt
fill ~378 ~67 ~104 ~383 ~67 ~104 grass_block
fill ~368 ~60 ~105 ~372 ~65 ~105 stone
fill ~368 ~66 ~105 ~372 ~68 ~105 dirt
fill ~368 ~69 ~105 ~372 ~69 ~105 grass_block
fill ~373 ~60 ~105 ~377 ~64 ~105 stone
fill ~373 ~65 ~105 ~377 ~67 ~105 dirt
fill ~373 ~68 ~105 ~377 ~68 ~105 grass_block
fill ~378 ~60 ~105 ~383 ~63 ~105 stone
fill ~378 ~64 ~105 ~383 ~66 ~105 dirt
fill ~378 ~67 ~105 ~383 ~67 ~105 grass_block
fill ~368 ~60 ~106 ~372 ~65 ~106 stone
fill ~368 ~66 ~106 ~372 ~68 ~106 dirt
fill ~368 ~69 ~106 ~372 ~69 ~106 grass_block
fill ~373 ~60 ~106 ~376 ~64 ~106 stone
fill ~373 ~65 ~106 ~376 ~67 ~106 dirt
fill ~373 ~68 ~106 ~376 ~68 ~106 grass_block
fill ~377 ~60 ~106 ~383 ~63 ~106 stone
fill ~377 ~64 ~106 ~383 ~66 ~106 dirt
fill ~377 ~67 ~106 ~383 ~67 ~106 grass_block
fill ~368 ~60 ~107 ~368 ~64 ~107 stone
fill ~368 ~65 ~107 ~368 ~67 ~107 dirt
fill ~368 ~68 ~107 ~368 ~68 ~107 grass_block
fill ~369 ~60 ~107 ~371 ~65 ~107 stone
fill ~369 ~66 ~107 ~371 ~68 ~107 dirt
fill ~369 ~69 ~107 ~371 ~69 ~107 grass_block
fill ~372 ~60 ~107 ~376 ~64 ~107 stone
fill ~372 ~65 ~107 ~376 ~67 ~107 dirt
fill ~372 ~68 ~107 ~376 ~68 ~107 grass_block
fill ~377 ~60 ~107 ~383 ~63 ~107 stone
fill ~377 ~64 ~107 ~383 ~66 ~107 dirt
fill ~377 ~67 ~107 ~383 ~67 ~107 grass_block
fill ~368 ~60 ~108 ~369 ~64 ~108 stone
fill ~368 ~65 ~108 ~369 ~67 ~108 dirt
fill ~368 ~68 ~108 ~369 ~68 ~108 grass_block
fill ~370 ~60 ~108 ~371 ~65 ~108 stone
fill ~370 ~66 ~108 ~371 ~68 ~108 dirt
fill ~370 ~69 ~108 ~371 ~69 ~108 grass_block
fill ~372 ~60 ~108 ~376 ~64 ~108 stone
fill ~372 ~65 ~108 ~376 ~67 ~108 dirt
fill ~372 ~68 ~108 ~376 ~68 ~108 grass_block
fill ~377 ~60 ~108 ~383 ~63 ~108 stone
fill ~377 ~64 ~108 ~383 ~66 ~108 dirt
fill ~377 ~67 ~108 ~383 ~67 ~108 grass_block
fill ~368 ~60 ~109 ~375 ~64 ~109 stone
fill ~368 ~65 ~109 ~375 ~67 ~109 dirt
fill ~368 ~68 ~109 ~375 ~68 ~109 grass_block
fill ~376 ~60 ~109 ~381 ~63 ~109 stone
fill ~376 ~64 ~109 ~381 ~66 ~109 dirt
fill ~376 ~67 ~109 ~381 ~67 ~109 grass_block
fill ~382 ~60 ~109 ~382 ~62 ~109 stone
fill ~382 ~63 ~109 ~382 ~65 ~109 dirt
fill ~382 ~66 ~109 ~382 ~66 ~109 grass_block
fill ~383 ~60 ~109 ~383 ~63 ~109 stone
fill ~383 ~64 ~109 ~383 ~66 ~109 dirt
fill ~383 ~67 ~109 ~383 ~67 ~109 grass_block
fill ~368 ~60 ~110 ~375 ~64 ~110 stone
fill ~368 ~65 ~110 ~375 ~67 ~110 dirt
fill ~368 ~68 ~110 ~375 ~68 ~110 grass_block
fill ~376 ~60 ~110 ~381 ~63 ~110 stone
fill ~376 ~64 ~110 ~381 ~66 ~110 dirt
fill ~376 ~67 ~110 ~381 ~67 ~110 grass_block
fill ~382 ~60 ~110 ~382 ~62 ~110 stone
fill ~382 ~63 ~110 ~382 ~65 ~110 dirt
fill ~382 ~66 ~110 ~382 ~66 ~110 grass_block
fill ~383 ~60 ~110 ~383 ~63 ~110 stone
fill ~383 ~64 ~110 ~383 ~66 ~110 dirt
fill ~383 ~67 ~110 ~383 ~67 ~110 grass_block
fill ~368 ~60 ~111 ~375 ~64 ~111 stone
fill ~368 ~65 ~111 ~375 ~67 ~111 dirt
fill ~368 ~68 ~111 ~375 ~68 ~111 grass_block
fill ~376 ~60 ~111 ~381 ~63 ~111 stone
fill ~376 ~64 ~111 ~381 ~66 ~111 dirt
fill ~376 ~67 ~111 ~381 ~67 ~111 grass_block
fill ~382 ~60 ~111 ~383 ~62 ~111 stone
fill ~382 ~63 ~111 ~383 ~65 ~111 dirt
fill ~382 ~66 ~111 ~383 ~66 ~111 grass_block