fill ~160 ~60 ~80 ~161 ~64 ~80 stone
fill ~160 ~65 ~80 ~161 ~67 ~80 dirt
fill ~160 ~68 ~80 ~161 ~68 ~80 grass_block
fill ~162 ~60 ~80 ~166 ~63 ~80 stone
fill ~162 ~64 ~80 ~166 ~66 ~80 dirt
fill ~162 ~67 ~80 ~166 ~67 ~80 grass_block
fill ~167 ~60 ~80 ~173 ~64 ~80 stone
fill ~167 ~65 ~80 ~173 ~67 ~80 dirt
fill ~167 ~68 ~80 ~173 ~68 ~80 grass_block
fill ~174 ~60 ~80 ~175 ~63 ~80 stone
fill ~174 ~64 ~80 ~175 ~66 ~80 dirt
fill ~174 ~67 ~80 ~175 ~67 ~80 grass_block
fill ~160 ~60 ~81 ~162 ~64 ~81 stone
fill ~160 ~65 ~81 ~162 ~67 ~81 dirt
fill ~160 ~68 ~81 ~162 ~68 ~81 grass_block
fill ~163 ~60 ~81 ~167 ~63 ~81 stone
fill ~163 ~64 ~81 ~167 ~66 ~81 dirt
fill ~163 ~67 ~81 ~167 ~67 ~81 grass_block
fill ~168 ~60 ~81 ~174 ~64 ~81 stone
fill ~168 ~65 ~81 ~174 ~67 ~81 dirt
fill ~168 ~68 ~81 ~174 ~68 ~81 grass_block
fill ~175 ~60 ~81 ~175 ~63 ~81 stone
fill ~175 ~64 ~81 ~175 ~66 ~81 dirt
fill ~175 ~67 ~81 ~175 ~67 ~81 grass_block
fill ~160 ~60 ~82 ~163 ~64 ~82 stone
fill ~160 ~65 ~82 ~163 ~67 ~82 dirt
fill ~160 ~68 ~82 ~163 ~68 ~82 grass_block
fill ~164 ~60 ~82 ~168 ~63 ~82 stone
fill ~164 ~64 ~82 ~168 ~66 ~82 dirt
fill ~164 ~67 ~82 ~168 ~67 ~82 grass_block
fill ~169 ~60 ~82 ~174 ~64 ~82 stone
fill ~169 ~65 ~82 ~174 ~67 ~82 dirt
fill ~169 ~68 ~82 ~174 ~68 ~82 grass_block
fill ~175 ~60 ~82 ~175 ~63 ~82 stone
fill ~175 ~64 ~82 ~175 ~66 ~82 dirt
fill ~175 ~67 ~82 ~175 ~67 ~82 grass_block
fill ~160 ~60 ~83 ~160 ~65 ~83 stone
fill ~160 ~66 ~83 ~160 ~68 ~83 dirt
fill ~160 ~69 ~83 ~160 ~69 ~83 grass_block
fill ~161 ~60 ~83 ~164 ~64 ~83 stone
fill ~161 ~65 ~83 ~164 ~67 ~83 dirt
fill ~161 ~68 ~83 ~164 ~68 ~83 grass_block
fill ~165 ~60 ~83 ~169 ~63 ~83 stone
fill ~165 ~64 ~83 ~169 ~66 ~83 dirt
fill ~165 ~67 ~83 ~169 ~67 ~83 grass_block
fill ~170 ~60 ~83 ~175 ~64 ~83 stone
fill ~170 ~65 ~83 ~175 ~67 ~83 dirt
fill ~170 ~68 ~83 ~175 ~68 ~83 grass_block
fill ~160 ~60 ~84 ~161 ~65 ~84 stone
fill ~160 ~66 ~84 ~161 ~68 ~84 dirt
fill ~160 ~69 ~84 ~161 ~69 ~84 grass_block
fill ~162 ~60 ~84 ~165 ~64 ~84 stone
fill ~162 ~65 ~84 ~165 ~67 ~84 dirt
fill ~162 ~68 ~84 ~165 ~68 ~84 grass_block
fill ~166 ~60 ~84 ~170 ~63 ~84 stone
fill ~166 ~64 ~84 ~170 ~66 ~84 dirt
fill ~166 ~67 ~84 ~170 ~67 ~84 grass_block
fill ~171 ~60 ~84 ~175 ~64 ~84 stone
fill ~171 ~65 ~84 ~175 ~67 ~84 dirt
fill ~171 ~68 ~84 ~175 ~68 ~84 grass_block
fill ~160 ~60 ~85 ~163 ~65 ~85 stone
fill ~160 ~66 ~85 ~163 ~68 ~85 dirt
fill ~160 ~69 ~85 ~163 ~69 ~85 grass_block
fill ~164 ~60 ~85 ~166 ~64 ~85 stone
fill ~164 ~65 ~85 ~166 ~67 ~85 dirt
fill ~164 ~68 ~85 ~166 ~68 ~85 grass_block
fill ~167 ~60 ~85 ~171 ~63 ~85 stone
fill ~167 ~64 ~85 ~171 ~66 ~85 dirt
fill ~167 ~67 ~85 ~171 ~67 ~85 grass_block
fill ~172 ~60 ~85 ~175 ~64 ~85 stone
fill ~172 ~65 ~85 ~175 ~67 ~85 dirt
fill ~172 ~68 ~85 ~175 ~68 ~85 grass_block
fill ~160 ~60 ~86 ~163 ~65 ~86 stone
fill ~160 ~66 ~86 ~163 ~68 ~86 dirt
fill ~160 ~69 ~86 ~163 ~69 ~86 grass_block
fill ~164 ~60 ~86 ~167 ~64 ~86 stone
fill ~164 ~65 ~86 ~167 ~67 ~86 dirt
fill ~164 ~68 ~86 ~167 ~68 ~86 grass_block
fill ~168 ~60 ~86 ~173 ~63 ~86 stone
fill ~168 ~64 ~86 ~173 ~66 ~86 dirt
fill ~168 ~67 ~86 ~173 ~67 ~86 grass_block
fill ~174 ~60 ~86 ~175 ~64 ~86 stone
fill ~174 ~65 ~86 ~175 ~67 ~86 dirt
fill ~174 ~68 ~86 ~175 ~68 ~86 grass_block
fill ~160 ~60 ~87 ~164 ~65 ~87 stone
fill ~160 ~66 ~87 ~164 ~68 ~87 dirt
fill ~160 ~69 ~87 ~164 ~69 ~87 grass_block
fill ~165 ~60 ~87 ~168 ~64 ~87 stone
fill ~165 ~65 ~87 ~168 ~67 ~87 dirt
fill ~165 ~68 ~87 ~168 ~68 ~87 grass_block
fill ~169 ~60 ~87 ~174 ~63 ~87 stone
fill ~169 ~64 ~87 ~174 ~66 ~87 dirt
fill ~169 ~67 ~87 ~174 ~67 ~87 grass_block
fill ~175 ~60 ~87 ~175 ~64 ~87 stone
fill ~175 ~65 ~87 ~175 ~67 ~87 dirt
fill ~175 ~68 ~87 ~175 ~68 ~87 grass_block
fill ~160 ~60 ~88 ~165 ~65 ~88 stone
fill ~160 ~66 ~88 ~165 ~68 ~88 dirt
fill ~160 ~69 ~88 ~165 ~69 ~88 grass_block
fill ~166 ~60 ~88 ~168 ~64 ~88 stone
fill ~166 ~65 ~88 ~168 ~67 ~88 dirt
fill ~166 ~68 ~88 ~168 ~68 ~88 grass_block
fill ~169 ~60 ~88 ~175 ~63 ~88 stone
fill ~169 ~64 ~88 ~175 ~66 ~88 dirt
fill ~169 ~67 ~88 ~175 ~67 ~88 grass_block
fill ~160 ~60 ~89 ~165 ~65 ~89 stone
fill ~160 ~66 ~89 ~165 ~68 ~89 dirt
fill ~160 ~69 ~89 ~165 ~69 ~89 grass_block
fill ~166 ~60 ~89 ~170 ~64 ~89 stone
fill ~166 ~65 ~89 ~170 ~67 ~89 dirt
fill ~166 ~68 ~89 ~170 ~68 ~89 grass_block
fill ~171 ~60 ~89 ~175 ~63 ~89 stone
fill ~171 ~64 ~89 ~175 ~66 ~89 dirt
fill ~171 ~67 ~89 ~175 ~67 ~89 grass_block
fill ~160 ~60 ~90 ~160 ~66 ~90 stone
fill ~160 ~67 ~90 ~160 ~69 ~90 dirt
fill ~160 ~70 ~90 ~160 ~70 ~90 grass_block
fill ~161 ~60 ~90 ~165 ~65 ~90 stone
fill ~161 ~66 ~90 ~165 ~68 ~90 dirt
fill ~161 ~69 ~90 ~165 ~69 ~90 grass_block
fill ~166 ~60 ~90 ~170 ~64 ~90 stone
fill ~166 ~65 ~90 ~170 ~67 ~90 dirt
fill ~166 ~68 ~90 ~170 ~68 ~90 grass_block
fill ~171 ~60 ~90 ~175 ~63 ~90 stone
fill ~171 ~64 ~90 ~175 ~66 ~90 dirt
fill ~171 ~67 ~90 ~175 ~67 ~90 grass_block
fill ~160 ~60 ~91 ~161 ~66 ~91 stone
fill ~160 ~67 ~91 ~161 ~69 ~91 dirt
fill ~160 ~70 ~91 ~161 ~70 ~91 grass_block
fill ~162 ~60 ~91 ~165 ~65 ~91 stone
fill ~162 ~66 ~91 ~165 ~68 ~91 dirt
fill ~162 ~69 ~91 ~165 ~69 ~91 grass_block
fill ~166 ~60 ~91 ~171 ~64 ~91 stone
fill ~166 ~65 ~91 ~171 ~67 ~91 dirt
fill ~166 ~68 ~91 ~171 ~68 ~91 grass_block
fill ~172 ~60 ~91 ~175 ~63 ~91 stone
fill ~172 ~64 ~91 ~175 ~66 ~91 dirt
fill ~172 ~67 ~91 ~175 ~67 ~91 grass_block
fill ~160 ~60 ~92 ~161 ~66 ~92 stone
fill ~160 ~67 ~92 ~161 ~69 ~92 dirt
fill ~160 ~70 ~92 ~161 ~70 ~92 grass_block
fill ~162 ~60 ~92 ~166 ~65 ~92 stone
fill ~162 ~66 ~92 ~166 ~68 ~92 dirt
fill ~162 ~69 ~92 ~166 ~69 ~92 grass_block
fill ~167 ~60 ~92 ~171 ~64 ~92 stone
fill ~167 ~65 ~92 ~171 ~67 ~92 dirt
fill ~167 ~68 ~92 ~171 ~68 ~92 grass_block
fill ~172 ~60 ~92 ~175 ~63 ~92 stone
fill ~172 ~64 ~92 ~175 ~66 ~92 dirt
fill ~172 ~67 ~92 ~175 ~67 ~92 grass_block
fill ~160 ~60 ~93 ~161 ~66 ~93 stone
fill ~160 ~67 ~93 ~161 ~69 ~93 dirt
fill ~160 ~70 ~93 ~161 ~70 ~93 grass_block
fill ~162 ~60 ~93 ~167 ~65 ~93 stone
fill ~162 ~66 ~93 ~167 ~68 ~93 dirt
fill ~162 ~69 ~93 ~167 ~69 ~93 grass_block
fill ~168 ~60 ~93 ~170 ~64 ~93 stone
fill ~168 ~65 ~93 ~170 ~67 ~93 dirt
fill ~168 ~68 ~93 ~170 ~68 ~93 grass_block
fill ~171 ~60 ~93 ~175 ~63 ~93 stone
fill ~171 ~64 ~93 ~175 ~66 ~93 dirt
fill ~171 ~67 ~93 ~175 ~67 ~93 grass_block
fill ~160 ~60 ~94 ~168 ~65 ~94 stone
fill ~160 ~66 ~94 ~168 ~68 ~94 dirt
fill ~160 ~69 ~94 ~168 ~69 ~94 grass_block
fill ~169 ~60 ~94 ~170 ~64 ~94 stone
fill ~169 ~65 ~94 ~170 ~67 ~94 dirt
fill ~169 ~68 ~94 ~170 ~68 ~94 grass_block
fill ~171 ~60 ~94 ~175 ~63 ~94 stone
fill ~171 ~64 ~94 ~175 ~66 ~94 dirt
fill ~171 ~67 ~94 ~175 ~67 ~94 grass_block
fill ~160 ~60 ~95 ~169 ~65 ~95 stone
fill ~160 ~66 ~95 ~169 ~68 ~95 dirt
fill ~160 ~69 ~95 ~169 ~69 ~95 grass_block
fill ~170 ~60 ~95 ~172 ~64 ~95 stone
fill ~170 ~65 ~95 ~172 ~67 ~95 dirt
fill ~170 ~68 ~95 ~172 ~68 ~95 grass_block
fill ~173 ~60 ~95 ~175 ~63 ~95 stone
fill ~173 ~64 ~95 ~175 ~66 ~95 dirt
fill ~173 ~67 ~95 ~175 ~67 ~95 grass_block