fill ~240 ~60 ~0 ~244 ~66 ~0 stone
fill ~240 ~67 ~0 ~244 ~69 ~0 dirt
fill ~240 ~70 ~0 ~244 ~70 ~0 grass_block
fill ~245 ~60 ~0 ~247 ~65 ~0 stone
fill ~245 ~66 ~0 ~247 ~68 ~0 dirt
fill ~245 ~69 ~0 ~247 ~69 ~0 grass_block
fill ~248 ~60 ~0 ~249 ~64 ~0 stone
fill ~248 ~65 ~0 ~249 ~67 ~0 dirt
fill ~248 ~68 ~0 ~249 ~68 ~0 grass_block
fill ~250 ~60 ~0 ~253 ~63 ~0 stone
fill ~250 ~64 ~0 ~253 ~66 ~0 dirt
fill ~250 ~67 ~0 ~253 ~67 ~0 grass_block
fill ~254 ~60 ~0 ~255 ~62 ~0 stone
fill ~254 ~63 ~0 ~255 ~65 ~0 dirt
fill ~254 ~66 ~0 ~255 ~66 ~0 grass_block
fill ~240 ~60 ~1 ~242 ~66 ~1 stone
fill ~240 ~67 ~1 ~242 ~69 ~1 dirt
fill ~240 ~70 ~1 ~242 ~70 ~1 grass_block
fill ~243 ~60 ~1 ~247 ~65 ~1 stone
fill ~243 ~66 ~1 ~247 ~68 ~1 dirt
fill ~243 ~69 ~1 ~247 ~69 ~1 grass_block
fill ~248 ~60 ~1 ~250 ~64 ~1 stone
fill ~248 ~65 ~1 ~250 ~67 ~1 dirt
fill ~248 ~68 ~1 ~250 ~68 ~1 grass_block
fill ~251 ~60 ~1 ~254 ~63 ~1 stone
fill ~251 ~64 ~1 ~254 ~66 ~1 dirt
fill ~251 ~67 ~1 ~254 ~67 ~1 grass_block
fill ~255 ~60 ~1 ~255 ~62 ~1 stone
fill ~255 ~63 ~1 ~255 ~65 ~1 dirt
fill ~255 ~66 ~1 ~255 ~66 ~1 grass_block
fill ~240 ~60 ~2 ~241 ~66 ~2 stone
fill ~240 ~67 ~2 ~241 ~69 ~2 dirt
fill ~240 ~70 ~2 ~241 ~70 ~2 grass_block
fill ~242 ~60 ~2 ~244 ~65 ~2 stone
fill ~242 ~66 ~2 ~244 ~68 ~2 dirt
fill ~242 ~69 ~2 ~244 ~69 ~2 grass_block
fill ~245 ~60 ~2 ~250 ~64 ~2 stone
fill ~245 ~65 ~2 ~250 ~67 ~2 dirt
fill ~245 ~68 ~2 ~250 ~68 ~2 grass_block
fill ~251 ~60 ~2 ~253 ~63 ~2 stone
fill ~251 ~64 ~2 ~253 ~66 ~2 dirt
fill ~251 ~67 ~2 ~253 ~67 ~2 grass_block
fill ~254 ~60 ~2 ~255 ~62 ~2 stone
fill ~254 ~63 ~2 ~255 ~65 ~2 dirt
fill ~254 ~66 ~2 ~255 ~66 ~2 grass_block
fill ~240 ~60 ~3 ~240 ~65 ~3 stone
fill ~240 ~66 ~3 ~240 ~68 ~3 dirt
fill ~240 ~69 ~3 ~240 ~69 ~3 grass_block
fill ~241 ~60 ~3 ~241 ~66 ~3 stone
fill ~241 ~67 ~3 ~241 ~69 ~3 dirt
fill ~241 ~70 ~3 ~241 ~70 ~3 grass_block
fill ~242 ~60 ~3 ~243 ~65 ~3 stone
fill ~242 ~66 ~3 ~243 ~68 ~3 dirt
fill ~242 ~69 ~3 ~243 ~69 ~3 grass_block
fill ~244 ~60 ~3 ~246 ~64 ~3 stone
fill ~244 ~65 ~3 ~246 ~67 ~3 dirt
fill ~244 ~68 ~3 ~246 ~68 ~3 grass_block
fill ~247 ~60 ~3 ~247 ~63 ~3 stone
fill ~247 ~64 ~3 ~247 ~66 ~3 dirt
fill ~247 ~67 ~3 ~247 ~67 ~3 grass_block
fill ~248 ~60 ~3 ~249 ~64 ~3 stone
fill ~248 ~65 ~3 ~249 ~67 ~3 dirt
fill ~248 ~68 ~3 ~249 ~68 ~3 grass_block
fill ~250 ~60 ~3 ~254 ~63 ~3 stone
fill ~250 ~64 ~3 ~254 ~66 ~3 dirt
fill ~250 ~67 ~3 ~254 ~67 ~3 grass_block
fill ~255 ~60 ~3 ~255 ~62 ~3 stone
fill ~255 ~63 ~3 ~255 ~65 ~3 dirt
fill ~255 ~66 ~3 ~255 ~66 ~3 grass_block
fill ~240 ~60 ~4 ~243 ~65 ~4 stone
fill ~240 ~66 ~4 ~243 ~68 ~4 dirt
fill ~240 ~69 ~4 ~243 ~69 ~4 grass_block
fill ~244 ~60 ~4 ~246 ~64 ~4 stone
fill ~244 ~65 ~4 ~246 ~67 ~4 dirt
fill ~244 ~68 ~4 ~246 ~68 ~4 grass_block
fill ~247 ~60 ~4 ~253 ~63 ~4 stone
fill ~247 ~64 ~4 ~253 ~66 ~4 dirt
fill ~247 ~67 ~4 ~253 ~67 ~4 grass_block
fill ~254 ~60 ~4 ~255 ~62 ~4 stone
fill ~254 ~63 ~4 ~255 ~65 ~4 dirt
fill ~254 ~66 ~4 ~255 ~66 ~4 grass_block
fill ~240 ~60 ~5 ~244 ~65 ~5 stone
fill ~240 ~66 ~5 ~244 ~68 ~5 dirt
fill ~240 ~69 ~5 ~244 ~69 ~5 grass_block
fill ~245 ~60 ~5 ~247 ~64 ~5 stone
fill ~245 ~65 ~5 ~247 ~67 ~5 dirt
fill ~245 ~68 ~5 ~247 ~68 ~5 grass_block
fill ~248 ~60 ~5 ~253 ~63 ~5 stone
fill ~248 ~64 ~5 ~253 ~66 ~5 dirt
fill ~248 ~67 ~5 ~253 ~67 ~5 grass_block
fill ~254 ~60 ~5 ~255 ~62 ~5 stone
fill ~254 ~63 ~5 ~255 ~65 ~5 dirt
fill ~254 ~66 ~5 ~255 ~66 ~5 grass_block
fill ~240 ~60 ~6 ~245 ~65 ~6 stone
fill ~240 ~66 ~6 ~245 ~68 ~6 dirt
fill ~240 ~69 ~6 ~245 ~69 ~6 grass_block
fill ~246 ~60 ~6 ~250 ~64 ~6 stone
fill ~246 ~65 ~6 ~250 ~67 ~6 dirt
fill ~246 ~68 ~6 ~250 ~68 ~6 grass_block
fill ~251 ~60 ~6 ~255 ~63 ~6 stone
fill ~251 ~64 ~6 ~255 ~66 ~6 dirt
fill ~251 ~67 ~6 ~255 ~67 ~6 grass_block
fill ~240 ~60 ~7 ~246 ~65 ~7 stone
fill ~240 ~66 ~7 ~246 ~68 ~7 dirt
fill ~240 ~69 ~7 ~246 ~69 ~7 grass_block
fill ~247 ~60 ~7 ~247 ~64 ~7 stone
fill ~247 ~65 ~7 ~247 ~67 ~7 dirt
fill ~247 ~68 ~7 ~247 ~68 ~7 grass_block
fill ~248 ~60 ~7 ~248 ~65 ~7 stone
fill ~248 ~66 ~7 ~248 ~68 ~7 dirt
fill ~248 ~69 ~7 ~248 ~69 ~7 grass_block
fill ~249 ~60 ~7 ~252 ~64 ~7 stone
fill ~249 ~65 ~7 ~252 ~67 ~7 dirt
fill ~249 ~68 ~7 ~252 ~68 ~7 grass_block
fill ~253 ~60 ~7 ~255 ~63 ~7 stone
fill ~253 ~64 ~7 ~255 ~66 ~7 dirt
fill ~253 ~67 ~7 ~255 ~67 ~7 grass_block
fill ~240 ~60 ~8 ~240 ~64 ~8 stone
fill ~240 ~65 ~8 ~240 ~67 ~8 dirt
fill ~240 ~68 ~8 ~240 ~68 ~8 grass_block
fill ~241 ~60 ~8 ~249 ~65 ~8 stone
fill ~241 ~66 ~8 ~249 ~68 ~8 dirt
fill ~241 ~69 ~8 ~249 ~69 ~8 grass_block
fill ~250 ~60 ~8 ~253 ~64 ~8 stone
fill ~250 ~65 ~8 ~253 ~67 ~8 dirt
fill ~250 ~68 ~8 ~253 ~68 ~8 grass_block
fill ~254 ~60 ~8 ~255 ~63 ~8 stone
fill ~254 ~64 ~8 ~255 ~66 ~8 dirt
fill ~254 ~67 ~8 ~255 ~67 ~8 grass_block
fill ~240 ~60 ~9 ~241 ~64 ~9 stone
fill ~240 ~65 ~9 ~241 ~67 ~9 dirt
fill ~240 ~68 ~9 ~241 ~68 ~9 grass_block
fill ~242 ~60 ~9 ~250 ~65 ~9 stone
fill ~242 ~66 ~9 ~250 ~68 ~9 dirt
fill ~242 ~69 ~9 ~250 ~69 ~9 grass_block
fill ~251 ~60 ~9 ~254 ~64 ~9 stone
fill ~251 ~65 ~9 ~254 ~67 ~9 dirt
fill ~251 ~68 ~9 ~254 ~68 ~9 grass_block
fill ~255 ~60 ~9 ~255 ~63 ~9 stone
fill ~255 ~64 ~9 ~255 ~66 ~9 dirt
fill ~255 ~67 ~9 ~255 ~67 ~9 grass_block
fill ~240 ~60 ~10 ~242 ~64 ~10 stone
fill ~240 ~65 ~10 ~242 ~67 ~10 dirt
fill ~240 ~68 ~10 ~242 ~68 ~10 grass_block
fill ~243 ~60 ~10 ~250 ~65 ~10 stone
fill ~243 ~66 ~10 ~250 ~68 ~10 dirt
fill ~243 ~69 ~10 ~250 ~69 ~10 grass_block
fill ~251 ~60 ~10 ~255 ~64 ~10 stone
fill ~251 ~65 ~10 ~255 ~67 ~10 dirt
fill ~251 ~68 ~10 ~255 ~68 ~10 grass_block
fill ~240 ~60 ~11 ~242 ~64 ~11 stone
fill ~240 ~65 ~11 ~242 ~67 ~11 dirt
fill ~240 ~68 ~11 ~242 ~68 ~11 grass_block
fill ~243 ~60 ~11 ~251 ~65 ~11 stone
fill ~243 ~66 ~11 ~251 ~68 ~11 dirt
fill ~243 ~69 ~11 ~251 ~69 ~11 grass_block
fill ~252 ~60 ~11 ~255 ~64 ~11 stone
fill ~252 ~65 ~11 ~255 ~67 ~11 dirt
fill ~252 ~68 ~11 ~255 ~68 ~11 grass_block
fill ~240 ~60 ~12 ~243 ~64 ~12 stone
fill ~240 ~65 ~12 ~243 ~67 ~12 dirt
fill ~240 ~68 ~12 ~243 ~68 ~12 grass_block
fill ~244 ~60 ~12 ~251 ~65 ~12 stone
fill ~244 ~66 ~12 ~251 ~68 ~12 dirt
fill ~244 ~69 ~12 ~251 ~69 ~12 grass_block
fill ~252 ~60 ~12 ~255 ~64 ~12 stone
fill ~252 ~65 ~12 ~255 ~67 ~12 dirt
fill ~252 ~68 ~12 ~255 ~68 ~12 grass_block
fill ~240 ~60 ~13 ~245 ~64 ~13 stone
fill ~240 ~65 ~13 ~245 ~67 ~13 dirt
fill ~240 ~68 ~13 ~245 ~68 ~13 grass_block
fill ~246 ~60 ~13 ~251 ~65 ~13 stone
fill ~246 ~66 ~13 ~251 ~68 ~13 dirt
fill ~246 ~69 ~13 ~251 ~69 ~13 grass_block
fill ~252 ~60 ~13 ~255 ~64 ~13 stone
fill ~252 ~65 ~13 ~255 ~67 ~13 dirt
fill ~252 ~68 ~13 ~255 ~68 ~13 grass_block
fill ~240 ~60 ~14 ~240 ~63 ~14 stone
fill ~240 ~64 ~14 ~240 ~66 ~14 dirt
fill ~240 ~67 ~14 ~240 ~67 ~14 grass_block
fill ~241 ~60 ~14 ~246 ~64 ~14 stone
fill ~241 ~65 ~14 ~246 ~67 ~14 dirt
fill ~241 ~68 ~14 ~246 ~68 ~14 grass_block
fill ~247 ~60 ~14 ~251 ~65 ~14 stone
fill ~247 ~66 ~14 ~251 ~68 ~14 dirt
fill ~247 ~69 ~14 ~251 ~69 ~14 grass_block
fill ~252 ~60 ~14 ~255 ~64 ~14 stone
fill ~252 ~65 ~14 ~255 ~67 ~14 dirt
fill ~252 ~68 ~14 ~255 ~68 ~14 grass_block
fill ~240 ~60 ~15 ~241 ~63 ~15 stone
fill ~240 ~64 ~15 ~241 ~66 ~15 dirt
fill ~240 ~67 ~15 ~241 ~67 ~15 grass_block
fill ~242 ~60 ~15 ~255 ~64 ~15 stone
fill ~242 ~65 ~15 ~255 ~67 ~15 dirt
fill ~242 ~68 ~15 ~255 ~68 ~15 grass_block