fill ~0 ~60 ~16 ~1 ~65 ~16 stone
fill ~0 ~66 ~16 ~1 ~68 ~16 dirt
fill ~0 ~69 ~16 ~1 ~69 ~16 grass_block
fill ~2 ~60 ~16 ~8 ~66 ~16 stone
fill ~2 ~67 ~16 ~8 ~69 ~16 dirt
fill ~2 ~70 ~16 ~8 ~70 ~16 grass_block
fill ~9 ~60 ~16 ~9 ~65 ~16 stone
fill ~9 ~66 ~16 ~9 ~68 ~16 dirt
fill ~9 ~69 ~16 ~9 ~69 ~16 grass_block
fill ~10 ~60 ~16 ~12 ~66 ~16 stone
fill ~10 ~67 ~16 ~12 ~69 ~16 dirt
fill ~10 ~70 ~16 ~12 ~70 ~16 grass_block
fill ~13 ~60 ~16 ~15 ~67 ~16 stone
fill ~13 ~68 ~16 ~15 ~70 ~16 dirt
fill ~13 ~71 ~16 ~15 ~71 ~16 grass_block
fill ~0 ~60 ~17 ~2 ~65 ~17 stone
fill ~0 ~66 ~17 ~2 ~68 ~17 dirt
fill ~0 ~69 ~17 ~2 ~69 ~17 grass_block
fill ~3 ~60 ~17 ~8 ~66 ~17 stone
fill ~3 ~67 ~17 ~8 ~69 ~17 dirt
fill ~3 ~70 ~17 ~8 ~70 ~17 grass_block
fill ~9 ~60 ~17 ~10 ~65 ~17 stone
fill ~9 ~66 ~17 ~10 ~68 ~17 dirt
fill ~9 ~69 ~17 ~10 ~69 ~17 grass_block
fill ~11 ~60 ~17 ~15 ~66 ~17 stone
fill ~11 ~67 ~17 ~15 ~69 ~17 dirt
fill ~11 ~70 ~17 ~15 ~70 ~17 grass_block
fill ~0 ~60 ~18 ~5 ~65 ~18 stone
fill ~0 ~66 ~18 ~5 ~68 ~18 dirt
fill ~0 ~69 ~18 ~5 ~69 ~18 grass_block
fill ~6 ~60 ~18 ~7 ~66 ~18 stone
fill ~6 ~67 ~18 ~7 ~69 ~18 dirt
fill ~6 ~70 ~18 ~7 ~70 ~18 grass_block
fill ~8 ~60 ~18 ~12 ~65 ~18 stone
fill ~8 ~66 ~18 ~12 ~68 ~18 dirt
fill ~8 ~69 ~18 ~12 ~69 ~18 grass_block
fill ~13 ~60 ~18 ~15 ~66 ~18 stone
fill ~13 ~67 ~18 ~15 ~69 ~18 dirt
fill ~13 ~70 ~18 ~15 ~70 ~18 grass_block
fill ~0 ~60 ~19 ~12 ~65 ~19 stone
fill ~0 ~66 ~19 ~12 ~68 ~19 dirt
fill ~0 ~69 ~19 ~12 ~69 ~19 grass_block
fill ~13 ~60 ~19 ~15 ~66 ~19 stone
fill ~13 ~67 ~19 ~15 ~69 ~19 dirt
fill ~13 ~70 ~19 ~15 ~70 ~19 grass_block
fill ~0 ~60 ~20 ~0 ~65 ~20 stone
fill ~0 ~66 ~20 ~0 ~68 ~20 dirt
fill ~0 ~69 ~20 ~0 ~69 ~20 grass_block
fill ~1 ~60 ~20 ~1 ~66 ~20 stone
fill ~1 ~67 ~20 ~1 ~69 ~20 dirt
fill ~1 ~70 ~20 ~1 ~70 ~20 grass_block
fill ~2 ~60 ~20 ~12 ~65 ~20 stone
fill ~2 ~66 ~20 ~12 ~68 ~20 dirt
fill ~2 ~69 ~20 ~12 ~69 ~20 grass_block
fill ~13 ~60 ~20 ~15 ~66 ~20 stone
fill ~13 ~67 ~20 ~15 ~69 ~20 dirt
fill ~13 ~70 ~20 ~15 ~70 ~20 grass_block
fill ~0 ~60 ~21 ~3 ~66 ~21 stone
fill ~0 ~67 ~21 ~3 ~69 ~21 dirt
fill ~0 ~70 ~21 ~3 ~70 ~21 grass_block
fill ~4 ~60 ~21 ~13 ~65 ~21 stone
fill ~4 ~66 ~21 ~13 ~68 ~21 dirt
fill ~4 ~69 ~21 ~13 ~69 ~21 grass_block
fill ~14 ~60 ~21 ~15 ~66 ~21 stone
fill ~14 ~67 ~21 ~15 ~69 ~21 dirt
fill ~14 ~70 ~21 ~15 ~70 ~21 grass_block
fill ~0 ~60 ~22 ~0 ~66 ~22 stone
fill ~0 ~67 ~22 ~0 ~69 ~22 dirt
fill ~0 ~70 ~22 ~0 ~70 ~22 grass_block
fill ~1 ~60 ~22 ~2 ~67 ~22 stone
fill ~1 ~68 ~22 ~2 ~70 ~22 dirt
fill ~1 ~71 ~22 ~2 ~71 ~22 grass_block
fill ~3 ~60 ~22 ~4 ~66 ~22 stone
fill ~3 ~67 ~22 ~4 ~69 ~22 dirt
fill ~3 ~70 ~22 ~4 ~70 ~22 grass_block
fill ~5 ~60 ~22 ~15 ~65 ~22 stone
fill ~5 ~66 ~22 ~15 ~68 ~22 dirt
fill ~5 ~69 ~22 ~15 ~69 ~22 grass_block
fill ~0 ~60 ~23 ~2 ~67 ~23 stone
fill ~0 ~68 ~23 ~2 ~70 ~23 dirt
fill ~0 ~71 ~23 ~2 ~71 ~23 grass_block
fill ~3 ~60 ~23 ~8 ~66 ~23 stone
fill ~3 ~67 ~23 ~8 ~69 ~23 dirt
fill ~3 ~70 ~23 ~8 ~70 ~23 grass_block
fill ~9 ~60 ~23 ~15 ~65 ~23 stone
fill ~9 ~66 ~23 ~15 ~68 ~23 dirt
fill ~9 ~69 ~23 ~15 ~69 ~23 grass_block
fill ~0 ~60 ~24 ~1 ~68 ~24 stone
fill ~0 ~69 ~24 ~1 ~71 ~24 dirt
fill ~0 ~72 ~24 ~1 ~72 ~24 grass_block
fill ~2 ~60 ~24 ~3 ~67 ~24 stone
fill ~2 ~68 ~24 ~3 ~70 ~24 dirt
fill ~2 ~71 ~24 ~3 ~71 ~24 grass_block
fill ~4 ~60 ~24 ~11 ~66 ~24 stone
fill ~4 ~67 ~24 ~11 ~69 ~24 dirt
fill ~4 ~70 ~24 ~11 ~70 ~24 grass_block
fill ~12 ~60 ~24 ~14 ~65 ~24 stone
fill ~12 ~66 ~24 ~14 ~68 ~24 dirt
fill ~12 ~69 ~24 ~14 ~69 ~24 grass_block
fill ~15 ~60 ~24 ~15 ~64 ~24 stone
fill ~15 ~65 ~24 ~15 ~67 ~24 dirt
fill ~15 ~68 ~24 ~15 ~68 ~24 grass_block
fill ~0 ~60 ~25 ~0 ~69 ~25 stone
fill ~0 ~70 ~25 ~0 ~72 ~25 dirt
fill ~0 ~73 ~25 ~0 ~73 ~25 grass_block
fill ~1 ~60 ~25 ~2 ~68 ~25 stone
fill ~1 ~69 ~25 ~2 ~71 ~25 dirt
fill ~1 ~72 ~25 ~2 ~72 ~25 grass_block
fill ~3 ~60 ~25 ~4 ~67 ~25 stone
fill ~3 ~68 ~25 ~4 ~70 ~25 dirt
fill ~3 ~71 ~25 ~4 ~71 ~25 grass_block
fill ~5 ~60 ~25 ~7 ~66 ~25 stone
fill ~5 ~67 ~25 ~7 ~69 ~25 dirt
fill ~5 ~70 ~25 ~7 ~70 ~25 grass_block
fill ~8 ~60 ~25 ~9 ~67 ~25 stone
fill ~8 ~68 ~25 ~9 ~70 ~25 dirt
fill ~8 ~71 ~25 ~9 ~71 ~25 grass_block
fill ~10 ~60 ~25 ~12 ~66 ~25 stone
fill ~10 ~67 ~25 ~12 ~69 ~25 dirt
fill ~10 ~70 ~25 ~12 ~70 ~25 grass_block
fill ~13 ~60 ~25 ~15 ~65 ~25 stone
fill ~13 ~66 ~25 ~15 ~68 ~25 dirt
fill ~13 ~69 ~25 ~15 ~69 ~25 grass_block
fill ~0 ~60 ~26 ~1 ~69 ~26 stone
fill ~0 ~70 ~26 ~1 ~72 ~26 dirt
fill ~0 ~73 ~26 ~1 ~73 ~26 grass_block
fill ~2 ~60 ~26 ~2 ~68 ~26 stone
fill ~2 ~69 ~26 ~2 ~71 ~26 dirt
fill ~2 ~72 ~26 ~2 ~72 ~26 grass_block
fill ~3 ~60 ~26 ~10 ~67 ~26 stone
fill ~3 ~68 ~26 ~10 ~70 ~26 dirt
fill ~3 ~71 ~26 ~10 ~71 ~26 grass_block
fill ~11 ~60 ~26 ~14 ~66 ~26 stone
fill ~11 ~67 ~26 ~14 ~69 ~26 dirt
fill ~11 ~70 ~26 ~14 ~70 ~26 grass_block
fill ~15 ~60 ~26 ~15 ~65 ~26 stone
fill ~15 ~66 ~26 ~15 ~68 ~26 dirt
fill ~15 ~69 ~26 ~15 ~69 ~26 grass_block
fill ~0 ~60 ~27 ~1 ~69 ~27 stone
fill ~0 ~70 ~27 ~1 ~72 ~27 dirt
fill ~0 ~73 ~27 ~1 ~73 ~27 grass_block
fill ~2 ~60 ~27 ~4 ~68 ~27 stone
fill ~2 ~69 ~27 ~4 ~71 ~27 dirt
fill ~2 ~72 ~27 ~4 ~72 ~27 grass_block
fill ~5 ~60 ~27 ~5 ~67 ~27 stone
fill ~5 ~68 ~27 ~5 ~70 ~27 dirt
fill ~5 ~71 ~27 ~5 ~71 ~27 grass_block
fill ~6 ~60 ~27 ~9 ~68 ~27 stone
fill ~6 ~69 ~27 ~9 ~71 ~27 dirt
fill ~6 ~72 ~27 ~9 ~72 ~27 grass_block
fill ~10 ~60 ~27 ~12 ~67 ~27 stone
fill ~10 ~68 ~27 ~12 ~70 ~27 dirt
fill ~10 ~71 ~27 ~12 ~71 ~27 grass_block
fill ~13 ~60 ~27 ~14 ~66 ~27 stone
fill ~13 ~67 ~27 ~14 ~69 ~27 dirt
fill ~13 ~70 ~27 ~14 ~70 ~27 grass_block
fill ~15 ~60 ~27 ~15 ~65 ~27 stone
fill ~15 ~66 ~27 ~15 ~68 ~27 dirt
fill ~15 ~69 ~27 ~15 ~69 ~27 grass_block
fill ~0 ~60 ~28 ~0 ~70 ~28 stone
fill ~0 ~71 ~28 ~0 ~73 ~28 dirt
fill ~0 ~74 ~28 ~0 ~74 ~28 grass_block
fill ~1 ~60 ~28 ~3 ~69 ~28 stone
fill ~1 ~70 ~28 ~3 ~72 ~28 dirt
fill ~1 ~73 ~28 ~3 ~73 ~28 grass_block
fill ~4 ~60 ~28 ~5 ~68 ~28 stone
fill ~4 ~69 ~28 ~5 ~71 ~28 dirt
fill ~4 ~72 ~28 ~5 ~72 ~28 grass_block
fill ~6 ~60 ~28 ~9 ~69 ~28 stone
fill ~6 ~70 ~28 ~9 ~72 ~28 dirt
fill ~6 ~73 ~28 ~9 ~73 ~28 grass_block
fill ~10 ~60 ~28 ~10 ~68 ~28 stone
fill ~10 ~69 ~28 ~10 ~71 ~28 dirt
fill ~10 ~72 ~28 ~10 ~72 ~28 grass_block
fill ~11 ~60 ~28 ~12 ~67 ~28 stone
fill ~11 ~68 ~28 ~12 ~70 ~28 dirt
fill ~11 ~71 ~28 ~12 ~71 ~28 grass_block
fill ~13 ~60 ~28 ~15 ~66 ~28 stone
fill ~13 ~67 ~28 ~15 ~69 ~28 dirt
fill ~13 ~70 ~28 ~15 ~70 ~28 grass_block
fill ~0 ~60 ~29 ~1 ~70 ~29 stone
fill ~0 ~71 ~29 ~1 ~73 ~29 dirt
fill ~0 ~74 ~29 ~1 ~74 ~29 grass_block
fill ~2 ~60 ~29 ~10 ~69 ~29 stone
fill ~2 ~70 ~29 ~10 ~72 ~29 dirt
fill ~2 ~73 ~29 ~10 ~73 ~29 grass_block
fill ~11 ~60 ~29 ~12 ~68 ~29 stone
fill ~11 ~69 ~29 ~12 ~71 ~29 dirt
fill ~11 ~72 ~29 ~12 ~72 ~29 grass_block
fill ~13 ~60 ~29 ~13 ~67 ~29 stone
fill ~13 ~68 ~29 ~13 ~70 ~29 dirt
fill ~13 ~71 ~29 ~13 ~71 ~29 grass_block
fill ~14 ~60 ~29 ~15 ~66 ~29 stone
fill ~14 ~67 ~29 ~15 ~69 ~29 dirt
fill ~14 ~70 ~29 ~15 ~70 ~29 grass_block
fill ~0 ~60 ~30 ~3 ~70 ~30 stone
fill ~0 ~71 ~30 ~3 ~73 ~30 dirt
fill ~0 ~74 ~30 ~3 ~74 ~30 grass_block
fill ~4 ~60 ~30 ~11 ~69 ~30 stone
fill ~4 ~70 ~30 ~11 ~72 ~30 dirt
fill ~4 ~73 ~30 ~11 ~73 ~30 grass_block
fill ~12 ~60 ~30 ~12 ~68 ~30 stone
fill ~12 ~69 ~30 ~12 ~71 ~30 dirt
fill ~12 ~72 ~30 ~12 ~72 ~30 grass_block
fill ~13 ~60 ~30 ~13 ~67 ~30 stone
fill ~13 ~68 ~30 ~13 ~70 ~30 dirt
fill ~13 ~71 ~30 ~13 ~71 ~30 grass_block
fill ~14 ~60 ~30 ~15 ~66 ~30 stone
fill ~14 ~67 ~30 ~15 ~69 ~30 dirt
fill ~14 ~70 ~30 ~15 ~70 ~30 grass_block
fill ~0 ~60 ~31 ~3 ~70 ~31 stone
fill ~0 ~71 ~31 ~3 ~73 ~31 dirt
fill ~0 ~74 ~31 ~3 ~74 ~31 grass_block
fill ~4 ~60 ~31 ~11 ~69 ~31 stone
fill ~4 ~70 ~31 ~11 ~72 ~31 dirt
fill ~4 ~73 ~31 ~11 ~73 ~31 grass_block
fill ~12 ~60 ~31 ~13 ~68 ~31 stone
fill ~12 ~69 ~31 ~13 ~71 ~31 dirt
fill ~12 ~72 ~31 ~13 ~72 ~31 grass_block
fill ~14 ~60 ~31 ~14 ~67 ~31 stone
fill ~14 ~68 ~31 ~14 ~70 ~31 dirt
fill ~14 ~71 ~31 ~14 ~71 ~31 grass_block
fill ~15 ~60 ~31 ~15 ~66 ~31 stone
fill ~15 ~67 ~31 ~15 ~69 ~31 dirt
fill ~15 ~70 ~31 ~15 ~70 ~31 grass_block