fill ~80 ~60 ~32 ~81 ~63 ~32 stone
fill ~80 ~64 ~32 ~81 ~66 ~32 dirt
fill ~80 ~67 ~32 ~81 ~67 ~32 grass_block
fill ~82 ~60 ~32 ~84 ~64 ~32 stone
fill ~82 ~65 ~32 ~84 ~67 ~32 dirt
fill ~82 ~68 ~32 ~84 ~68 ~32 grass_block
fill ~85 ~60 ~32 ~87 ~65 ~32 stone
fill ~85 ~66 ~32 ~87 ~68 ~32 dirt
fill ~85 ~69 ~32 ~87 ~69 ~32 grass_block
fill ~88 ~60 ~32 ~89 ~66 ~32 stone
fill ~88 ~67 ~32 ~89 ~69 ~32 dirt
fill ~88 ~70 ~32 ~89 ~70 ~32 grass_block
fill ~90 ~60 ~32 ~95 ~67 ~32 stone
fill ~90 ~68 ~32 ~95 ~70 ~32 dirt
fill ~90 ~71 ~32 ~95 ~71 ~32 grass_block
fill ~80 ~60 ~33 ~81 ~63 ~33 stone
fill ~80 ~64 ~33 ~81 ~66 ~33 dirt
fill ~80 ~67 ~33 ~81 ~67 ~33 grass_block
fill ~82 ~60 ~33 ~85 ~64 ~33 stone
fill ~82 ~65 ~33 ~85 ~67 ~33 dirt
fill ~82 ~68 ~33 ~85 ~68 ~33 grass_block
fill ~86 ~60 ~33 ~87 ~65 ~33 stone
fill ~86 ~66 ~33 ~87 ~68 ~33 dirt
fill ~86 ~69 ~33 ~87 ~69 ~33 grass_block
fill ~88 ~60 ~33 ~89 ~66 ~33 stone
fill ~88 ~67 ~33 ~89 ~69 ~33 dirt
fill ~88 ~70 ~33 ~89 ~70 ~33 grass_block
fill ~90 ~60 ~33 ~95 ~67 ~33 stone
fill ~90 ~68 ~33 ~95 ~70 ~33 dirt
fill ~90 ~71 ~33 ~95 ~71 ~33 grass_block
fill ~80 ~60 ~34 ~81 ~63 ~34 stone
fill ~80 ~64 ~34 ~81 ~66 ~34 dirt
fill ~80 ~67 ~34 ~81 ~67 ~34 grass_block
fill ~82 ~60 ~34 ~85 ~64 ~34 stone
fill ~82 ~65 ~34 ~85 ~67 ~34 dirt
fill ~82 ~68 ~34 ~85 ~68 ~34 grass_block
fill ~86 ~60 ~34 ~88 ~65 ~34 stone
fill ~86 ~66 ~34 ~88 ~68 ~34 dirt
fill ~86 ~69 ~34 ~88 ~69 ~34 grass_block
fill ~89 ~60 ~34 ~90 ~66 ~34 stone
fill ~89 ~67 ~34 ~90 ~69 ~34 dirt
fill ~89 ~70 ~34 ~90 ~70 ~34 grass_block
fill ~91 ~60 ~34 ~95 ~67 ~34 stone
fill ~91 ~68 ~34 ~95 ~70 ~34 dirt
fill ~91 ~71 ~34 ~95 ~71 ~34 grass_block
fill ~80 ~60 ~35 ~83 ~63 ~35 stone
fill ~80 ~64 ~35 ~83 ~66 ~35 dirt
fill ~80 ~67 ~35 ~83 ~67 ~35 grass_block
fill ~84 ~60 ~35 ~85 ~64 ~35 stone
fill ~84 ~65 ~35 ~85 ~67 ~35 dirt
fill ~84 ~68 ~35 ~85 ~68 ~35 grass_block
fill ~86 ~60 ~35 ~88 ~65 ~35 stone
fill ~86 ~66 ~35 ~88 ~68 ~35 dirt
fill ~86 ~69 ~35 ~88 ~69 ~35 grass_block
fill ~89 ~60 ~35 ~90 ~66 ~35 stone
fill ~89 ~67 ~35 ~90 ~69 ~35 dirt
fill ~89 ~70 ~35 ~90 ~70 ~35 grass_block
fill ~91 ~60 ~35 ~95 ~67 ~35 stone
fill ~91 ~68 ~35 ~95 ~70 ~35 dirt
fill ~91 ~71 ~35 ~95 ~71 ~35 grass_block
fill ~80 ~60 ~36 ~83 ~63 ~36 stone
fill ~80 ~64 ~36 ~83 ~66 ~36 dirt
fill ~80 ~67 ~36 ~83 ~67 ~36 grass_block
fill ~84 ~60 ~36 ~86 ~64 ~36 stone
fill ~84 ~65 ~36 ~86 ~67 ~36 dirt
fill ~84 ~68 ~36 ~86 ~68 ~36 grass_block
fill ~87 ~60 ~36 ~89 ~65 ~36 stone
fill ~87 ~66 ~36 ~89 ~68 ~36 dirt
fill ~87 ~69 ~36 ~89 ~69 ~36 grass_block
fill ~90 ~60 ~36 ~91 ~66 ~36 stone
fill ~90 ~67 ~36 ~91 ~69 ~36 dirt
fill ~90 ~70 ~36 ~91 ~70 ~36 grass_block
fill ~92 ~60 ~36 ~95 ~67 ~36 stone
fill ~92 ~68 ~36 ~95 ~70 ~36 dirt
fill ~92 ~71 ~36 ~95 ~71 ~36 grass_block
fill ~80 ~60 ~37 ~84 ~63 ~37 stone
fill ~80 ~64 ~37 ~84 ~66 ~37 dirt
fill ~80 ~67 ~37 ~84 ~67 ~37 grass_block
fill ~85 ~60 ~37 ~87 ~64 ~37 stone
fill ~85 ~65 ~37 ~87 ~67 ~37 dirt
fill ~85 ~68 ~37 ~87 ~68 ~37 grass_block
fill ~88 ~60 ~37 ~89 ~65 ~37 stone
fill ~88 ~66 ~37 ~89 ~68 ~37 dirt
fill ~88 ~69 ~37 ~89 ~69 ~37 grass_block
fill ~90 ~60 ~37 ~93 ~66 ~37 stone
fill ~90 ~67 ~37 ~93 ~69 ~37 dirt
fill ~90 ~70 ~37 ~93 ~70 ~37 grass_block
fill ~94 ~60 ~37 ~95 ~67 ~37 stone
fill ~94 ~68 ~37 ~95 ~70 ~37 dirt
fill ~94 ~71 ~37 ~95 ~71 ~37 grass_block
fill ~80 ~60 ~38 ~85 ~63 ~38 stone
fill ~80 ~64 ~38 ~85 ~66 ~38 dirt
fill ~80 ~67 ~38 ~85 ~67 ~38 grass_block
fill ~86 ~60 ~38 ~88 ~64 ~38 stone
fill ~86 ~65 ~38 ~88 ~67 ~38 dirt
fill ~86 ~68 ~38 ~88 ~68 ~38 grass_block
fill ~89 ~60 ~38 ~92 ~65 ~38 stone
fill ~89 ~66 ~38 ~92 ~68 ~38 dirt
fill ~89 ~69 ~38 ~92 ~69 ~38 grass_block
fill ~93 ~60 ~38 ~95 ~66 ~38 stone
fill ~93 ~67 ~38 ~95 ~69 ~38 dirt
fill ~93 ~70 ~38 ~95 ~70 ~38 grass_block
fill ~80 ~60 ~39 ~85 ~63 ~39 stone
fill ~80 ~64 ~39 ~85 ~66 ~39 dirt
fill ~80 ~67 ~39 ~85 ~67 ~39 grass_block
fill ~86 ~60 ~39 ~88 ~64 ~39 stone
fill ~86 ~65 ~39 ~88 ~67 ~39 dirt
fill ~86 ~68 ~39 ~88 ~68 ~39 grass_block
fill ~89 ~60 ~39 ~94 ~65 ~39 stone
fill ~89 ~66 ~39 ~94 ~68 ~39 dirt
fill ~89 ~69 ~39 ~94 ~69 ~39 grass_block
fill ~95 ~60 ~39 ~95 ~66 ~39 stone
fill ~95 ~67 ~39 ~95 ~69 ~39 dirt
fill ~95 ~70 ~39 ~95 ~70 ~39 grass_block
fill ~80 ~60 ~40 ~86 ~63 ~40 stone
fill ~80 ~64 ~40 ~86 ~66 ~40 dirt
fill ~80 ~67 ~40 ~86 ~67 ~40 grass_block
fill ~87 ~60 ~40 ~91 ~64 ~40 stone
fill ~87 ~65 ~40 ~91 ~67 ~40 dirt
fill ~87 ~68 ~40 ~91 ~68 ~40 grass_block
fill ~92 ~60 ~40 ~94 ~65 ~40 stone
fill ~92 ~66 ~40 ~94 ~68 ~40 dirt
fill ~92 ~69 ~40 ~94 ~69 ~40 grass_block
fill ~95 ~60 ~40 ~95 ~66 ~40 stone
fill ~95 ~67 ~40 ~95 ~69 ~40 dirt
fill ~95 ~70 ~40 ~95 ~70 ~40 grass_block
fill ~80 ~60 ~41 ~88 ~63 ~41 stone
fill ~80 ~64 ~41 ~88 ~66 ~41 dirt
fill ~80 ~67 ~41 ~88 ~67 ~41 grass_block
fill ~89 ~60 ~41 ~92 ~64 ~41 stone
fill ~89 ~65 ~41 ~92 ~67 ~41 dirt
fill ~89 ~68 ~41 ~92 ~68 ~41 grass_block
fill ~93 ~60 ~41 ~94 ~65 ~41 stone
fill ~93 ~66 ~41 ~94 ~68 ~41 dirt
fill ~93 ~69 ~41 ~94 ~69 ~41 grass_block
fill ~95 ~60 ~41 ~95 ~66 ~41 stone
fill ~95 ~67 ~41 ~95 ~69 ~41 dirt
fill ~95 ~70 ~41 ~95 ~70 ~41 grass_block
fill ~80 ~60 ~42 ~90 ~63 ~42 stone
fill ~80 ~64 ~42 ~90 ~66 ~42 dirt
fill ~80 ~67 ~42 ~90 ~67 ~42 grass_block
fill ~91 ~60 ~42 ~92 ~64 ~42 stone
fill ~91 ~65 ~42 ~92 ~67 ~42 dirt
fill ~91 ~68 ~42 ~92 ~68 ~42 grass_block
fill ~93 ~60 ~42 ~94 ~65 ~42 stone
fill ~93 ~66 ~42 ~94 ~68 ~42 dirt
fill ~93 ~69 ~42 ~94 ~69 ~42 grass_block
fill ~95 ~60 ~42 ~95 ~66 ~42 stone
fill ~95 ~67 ~42 ~95 ~69 ~42 dirt
fill ~95 ~70 ~42 ~95 ~70 ~42 grass_block
fill ~80 ~60 ~43 ~80 ~64 ~43 stone
fill ~80 ~65 ~43 ~80 ~67 ~43 dirt
fill ~80 ~68 ~43 ~80 ~68 ~43 grass_block
fill ~81 ~60 ~43 ~90 ~63 ~43 stone
fill ~81 ~64 ~43 ~90 ~66 ~43 dirt
fill ~81 ~67 ~43 ~90 ~67 ~43 grass_block
fill ~91 ~60 ~43 ~92 ~64 ~43 stone
fill ~91 ~65 ~43 ~92 ~67 ~43 dirt
fill ~91 ~68 ~43 ~92 ~68 ~43 grass_block
fill ~93 ~60 ~43 ~95 ~65 ~43 stone
fill ~93 ~66 ~43 ~95 ~68 ~43 dirt
fill ~93 ~69 ~43 ~95 ~69 ~43 grass_block
fill ~80 ~60 ~44 ~81 ~64 ~44 stone
fill ~80 ~65 ~44 ~81 ~67 ~44 dirt
fill ~80 ~68 ~44 ~81 ~68 ~44 grass_block
fill ~82 ~60 ~44 ~89 ~63 ~44 stone
fill ~82 ~64 ~44 ~89 ~66 ~44 dirt
fill ~82 ~67 ~44 ~89 ~67 ~44 grass_block
fill ~90 ~60 ~44 ~94 ~64 ~44 stone
fill ~90 ~65 ~44 ~94 ~67 ~44 dirt
fill ~90 ~68 ~44 ~94 ~68 ~44 grass_block
fill ~95 ~60 ~44 ~95 ~65 ~44 stone
fill ~95 ~66 ~44 ~95 ~68 ~44 dirt
fill ~95 ~69 ~44 ~95 ~69 ~44 grass_block
fill ~80 ~60 ~45 ~81 ~64 ~45 stone
fill ~80 ~65 ~45 ~81 ~67 ~45 dirt
fill ~80 ~68 ~45 ~81 ~68 ~45 grass_block
fill ~82 ~60 ~45 ~90 ~63 ~45 stone
fill ~82 ~64 ~45 ~90 ~66 ~45 dirt
fill ~82 ~67 ~45 ~90 ~67 ~45 grass_block
fill ~91 ~60 ~45 ~95 ~64 ~45 stone
fill ~91 ~65 ~45 ~95 ~67 ~45 dirt
fill ~91 ~68 ~45 ~95 ~68 ~45 grass_block
fill ~80 ~60 ~46 ~80 ~65 ~46 stone
fill ~80 ~66 ~46 ~80 ~68 ~46 dirt
fill ~80 ~69 ~46 ~80 ~69 ~46 grass_block
fill ~81 ~60 ~46 ~82 ~64 ~46 stone
fill ~81 ~65 ~46 ~82 ~67 ~46 dirt
fill ~81 ~68 ~46 ~82 ~68 ~46 grass_block
fill ~83 ~60 ~46 ~91 ~63 ~46 stone
fill ~83 ~64 ~46 ~91 ~66 ~46 dirt
fill ~83 ~67 ~46 ~91 ~67 ~46 grass_block
fill ~92 ~60 ~46 ~95 ~64 ~46 stone
fill ~92 ~65 ~46 ~95 ~67 ~46 dirt
fill ~92 ~68 ~46 ~95 ~68 ~46 grass_block
fill ~80 ~60 ~47 ~80 ~65 ~47 stone
fill ~80 ~66 ~47 ~80 ~68 ~47 dirt
fill ~80 ~69 ~47 ~80 ~69 ~47 grass_block
fill ~81 ~60 ~47 ~82 ~64 ~47 stone
fill ~81 ~65 ~47 ~82 ~67 ~47 dirt
fill ~81 ~68 ~47 ~82 ~68 ~47 grass_block
fill ~83 ~60 ~47 ~92 ~63 ~47 stone
fill ~83 ~64 ~47 ~92 ~66 ~47 dirt
fill ~83 ~67 ~47 ~92 ~67 ~47 grass_block
fill ~93 ~60 ~47 ~95 ~64 ~47 stone
fill ~93 ~65 ~47 ~95 ~67 ~47 dirt
fill ~93 ~68 ~47 ~95 ~68 ~47 grass_block