fill ~224 ~60 ~48 ~227 ~63 ~48 stone
fill ~224 ~64 ~48 ~227 ~66 ~48 dirt
fill ~224 ~67 ~48 ~227 ~67 ~48 grass_block
fill ~228 ~60 ~48 ~234 ~62 ~48 stone
fill ~228 ~63 ~48 ~234 ~65 ~48 dirt
fill ~228 ~66 ~48 ~234 ~66 ~48 grass_block
fill ~235 ~60 ~48 ~239 ~61 ~48 stone
fill ~235 ~62 ~48 ~239 ~64 ~48 dirt
fill ~235 ~65 ~48 ~239 ~65 ~48 grass_block
fill ~224 ~60 ~49 ~228 ~63 ~49 stone
fill ~224 ~64 ~49 ~228 ~66 ~49 dirt
fill ~224 ~67 ~49 ~228 ~67 ~49 grass_block
fill ~229 ~60 ~49 ~235 ~62 ~49 stone
fill ~229 ~63 ~49 ~235 ~65 ~49 dirt
fill ~229 ~66 ~49 ~235 ~66 ~49 grass_block
fill ~236 ~60 ~49 ~239 ~61 ~49 stone
fill ~236 ~62 ~49 ~239 ~64 ~49 dirt
fill ~236 ~65 ~49 ~239 ~65 ~49 grass_block
fill ~224 ~60 ~50 ~228 ~63 ~50 stone
fill ~224 ~64 ~50 ~228 ~66 ~50 dirt
fill ~224 ~67 ~50 ~228 ~67 ~50 grass_block
fill ~229 ~60 ~50 ~235 ~62 ~50 stone
fill ~229 ~63 ~50 ~235 ~65 ~50 dirt
fill ~229 ~66 ~50 ~235 ~66 ~50 grass_block
fill ~236 ~60 ~50 ~239 ~61 ~50 stone
fill ~236 ~62 ~50 ~239 ~64 ~50 dirt
fill ~236 ~65 ~50 ~239 ~65 ~50 grass_block
fill ~224 ~60 ~51 ~228 ~63 ~51 stone
fill ~224 ~64 ~51 ~228 ~66 ~51 dirt
fill ~224 ~67 ~51 ~228 ~67 ~51 grass_block
fill ~229 ~60 ~51 ~235 ~62 ~51 stone
fill ~229 ~63 ~51 ~235 ~65 ~51 dirt
fill ~229 ~66 ~51 ~235 ~66 ~51 grass_block
fill ~236 ~60 ~51 ~239 ~61 ~51 stone
fill ~236 ~62 ~51 ~239 ~64 ~51 dirt
fill ~236 ~65 ~51 ~239 ~65 ~51 grass_block
fill ~224 ~60 ~52 ~226 ~63 ~52 stone
fill ~224 ~64 ~52 ~226 ~66 ~52 dirt
fill ~224 ~67 ~52 ~226 ~67 ~52 grass_block
fill ~227 ~60 ~52 ~227 ~62 ~52 stone
fill ~227 ~63 ~52 ~227 ~65 ~52 dirt
fill ~227 ~66 ~52 ~227 ~66 ~52 grass_block
fill ~228 ~60 ~52 ~228 ~63 ~52 stone
fill ~228 ~64 ~52 ~228 ~66 ~52 dirt
fill ~228 ~67 ~52 ~228 ~67 ~52 grass_block
fill ~229 ~60 ~52 ~237 ~62 ~52 stone
fill ~229 ~63 ~52 ~237 ~65 ~52 dirt
fill ~229 ~66 ~52 ~237 ~66 ~52 grass_block
fill ~238 ~60 ~52 ~239 ~61 ~52 stone
fill ~238 ~62 ~52 ~239 ~64 ~52 dirt
fill ~238 ~65 ~52 ~239 ~65 ~52 grass_block
fill ~224 ~60 ~53 ~228 ~63 ~53 stone
fill ~224 ~64 ~53 ~228 ~66 ~53 dirt
fill ~224 ~67 ~53 ~228 ~67 ~53 grass_block
fill ~229 ~60 ~53 ~238 ~62 ~53 stone
fill ~229 ~63 ~53 ~238 ~65 ~53 dirt
fill ~229 ~66 ~53 ~238 ~66 ~53 grass_block
fill ~239 ~60 ~53 ~239 ~61 ~53 stone
fill ~239 ~62 ~53 ~239 ~64 ~53 dirt
fill ~239 ~65 ~53 ~239 ~65 ~53 grass_block
fill ~224 ~60 ~54 ~229 ~63 ~54 stone
fill ~224 ~64 ~54 ~229 ~66 ~54 dirt
fill ~224 ~67 ~54 ~229 ~67 ~54 grass_block
fill ~230 ~60 ~54 ~237 ~62 ~54 stone
fill ~230 ~63 ~54 ~237 ~65 ~54 dirt
fill ~230 ~66 ~54 ~237 ~66 ~54 grass_block
fill ~238 ~60 ~54 ~239 ~61 ~54 stone
fill ~238 ~62 ~54 ~239 ~64 ~54 dirt
fill ~238 ~65 ~54 ~239 ~65 ~54 grass_block
fill ~224 ~60 ~55 ~228 ~63 ~55 stone
fill ~224 ~64 ~55 ~228 ~66 ~55 dirt
fill ~224 ~67 ~55 ~228 ~67 ~55 grass_block
fill ~229 ~60 ~55 ~237 ~62 ~55 stone
fill ~229 ~63 ~55 ~237 ~65 ~55 dirt
fill ~229 ~66 ~55 ~237 ~66 ~55 grass_block
fill ~238 ~60 ~55 ~239 ~61 ~55 stone
fill ~238 ~62 ~55 ~239 ~64 ~55 dirt
fill ~238 ~65 ~55 ~239 ~65 ~55 grass_block
fill ~224 ~60 ~56 ~229 ~63 ~56 stone
fill ~224 ~64 ~56 ~229 ~66 ~56 dirt
fill ~224 ~67 ~56 ~229 ~67 ~56 grass_block
fill ~230 ~60 ~56 ~238 ~62 ~56 stone
fill ~230 ~63 ~56 ~238 ~65 ~56 dirt
fill ~230 ~66 ~56 ~238 ~66 ~56 grass_block
fill ~239 ~60 ~56 ~239 ~61 ~56 stone
fill ~239 ~62 ~56 ~239 ~64 ~56 dirt
fill ~239 ~65 ~56 ~239 ~65 ~56 grass_block
fill ~224 ~60 ~57 ~230 ~63 ~57 stone
fill ~224 ~64 ~57 ~230 ~66 ~57 dirt
fill ~224 ~67 ~57 ~230 ~67 ~57 grass_block
fill ~231 ~60 ~57 ~239 ~62 ~57 stone
fill ~231 ~63 ~57 ~239 ~65 ~57 dirt
fill ~231 ~66 ~57 ~239 ~66 ~57 grass_block
fill ~224 ~60 ~58 ~230 ~63 ~58 stone
fill ~224 ~64 ~58 ~230 ~66 ~58 dirt
fill ~224 ~67 ~58 ~230 ~67 ~58 grass_block
fill ~231 ~60 ~58 ~239 ~62 ~58 stone
fill ~231 ~63 ~58 ~239 ~65 ~58 dirt
fill ~231 ~66 ~58 ~239 ~66 ~58 grass_block
fill ~224 ~60 ~59 ~224 ~62 ~59 stone
fill ~224 ~63 ~59 ~224 ~65 ~59 dirt
fill ~224 ~66 ~59 ~224 ~66 ~59 grass_block
fill ~225 ~60 ~59 ~230 ~63 ~59 stone
fill ~225 ~64 ~59 ~230 ~66 ~59 dirt
fill ~225 ~67 ~59 ~230 ~67 ~59 grass_block
fill ~231 ~60 ~59 ~239 ~62 ~59 stone
fill ~231 ~63 ~59 ~239 ~65 ~59 dirt
fill ~231 ~66 ~59 ~239 ~66 ~59 grass_block
fill ~224 ~60 ~60 ~239 ~62 ~60 stone
fill ~224 ~63 ~60 ~239 ~65 ~60 dirt
fill ~224 ~66 ~60 ~239 ~66 ~60 grass_block
fill ~224 ~60 ~61 ~239 ~62 ~61 stone
fill ~224 ~63 ~61 ~239 ~65 ~61 dirt
fill ~224 ~66 ~61 ~239 ~66 ~61 grass_block
fill ~224 ~60 ~62 ~239 ~62 ~62 stone
fill ~224 ~63 ~62 ~239 ~65 ~62 dirt
fill ~224 ~66 ~62 ~239 ~66 ~62 grass_block
fill ~224 ~60 ~63 ~225 ~63 ~63 stone
fill ~224 ~64 ~63 ~225 ~66 ~63 dirt
fill ~224 ~67 ~63 ~225 ~67 ~63 grass_block
fill ~226 ~60 ~63 ~239 ~62 ~63 stone
fill ~226 ~63 ~63 ~239 ~65 ~63 dirt
fill ~226 ~66 ~63 ~239 ~66 ~63 grass_block