fill ~32 ~60 ~64 ~32 ~70 ~64 stone
fill ~32 ~71 ~64 ~32 ~73 ~64 dirt
fill ~32 ~74 ~64 ~32 ~74 ~64 grass_block
fill ~33 ~60 ~64 ~35 ~69 ~64 stone
fill ~33 ~70 ~64 ~35 ~72 ~64 dirt
fill ~33 ~73 ~64 ~35 ~73 ~64 grass_block
fill ~36 ~60 ~64 ~36 ~68 ~64 stone
fill ~36 ~69 ~64 ~36 ~71 ~64 dirt
fill ~36 ~72 ~64 ~36 ~72 ~64 grass_block
fill ~37 ~60 ~64 ~38 ~67 ~64 stone
fill ~37 ~68 ~64 ~38 ~70 ~64 dirt
fill ~37 ~71 ~64 ~38 ~71 ~64 grass_block
fill ~39 ~60 ~64 ~42 ~66 ~64 stone
fill ~39 ~67 ~64 ~42 ~69 ~64 dirt
fill ~39 ~70 ~64 ~42 ~70 ~64 grass_block
fill ~43 ~60 ~64 ~47 ~65 ~64 stone
fill ~43 ~66 ~64 ~47 ~68 ~64 dirt
fill ~43 ~69 ~64 ~47 ~69 ~64 grass_block
fill ~32 ~60 ~65 ~32 ~70 ~65 stone
fill ~32 ~71 ~65 ~32 ~73 ~65 dirt
fill ~32 ~74 ~65 ~32 ~74 ~65 grass_block
fill ~33 ~60 ~65 ~35 ~69 ~65 stone
fill ~33 ~70 ~65 ~35 ~72 ~65 dirt
fill ~33 ~73 ~65 ~35 ~73 ~65 grass_block
fill ~36 ~60 ~65 ~37 ~68 ~65 stone
fill ~36 ~69 ~65 ~37 ~71 ~65 dirt
fill ~36 ~72 ~65 ~37 ~72 ~65 grass_block
fill ~38 ~60 ~65 ~39 ~67 ~65 stone
fill ~38 ~68 ~65 ~39 ~70 ~65 dirt
fill ~38 ~71 ~65 ~39 ~71 ~65 grass_block
fill ~40 ~60 ~65 ~47 ~66 ~65 stone
fill ~40 ~67 ~65 ~47 ~69 ~65 dirt
fill ~40 ~70 ~65 ~47 ~70 ~65 grass_block
fill ~32 ~60 ~66 ~33 ~70 ~66 stone
fill ~32 ~71 ~66 ~33 ~73 ~66 dirt
fill ~32 ~74 ~66 ~33 ~74 ~66 grass_block
fill ~34 ~60 ~66 ~37 ~69 ~66 stone
fill ~34 ~70 ~66 ~37 ~72 ~66 dirt
fill ~34 ~73 ~66 ~37 ~73 ~66 grass_block
fill ~38 ~60 ~66 ~39 ~68 ~66 stone
fill ~38 ~69 ~66 ~39 ~71 ~66 dirt
fill ~38 ~72 ~66 ~39 ~72 ~66 grass_block
fill ~40 ~60 ~66 ~41 ~67 ~66 stone
fill ~40 ~68 ~66 ~41 ~70 ~66 dirt
fill ~40 ~71 ~66 ~41 ~71 ~66 grass_block
fill ~42 ~60 ~66 ~47 ~66 ~66 stone
fill ~42 ~67 ~66 ~47 ~69 ~66 dirt
fill ~42 ~70 ~66 ~47 ~70 ~66 grass_block
fill ~32 ~60 ~67 ~36 ~70 ~67 stone
fill ~32 ~71 ~67 ~36 ~73 ~67 dirt
fill ~32 ~74 ~67 ~36 ~74 ~67 grass_block
fill ~37 ~60 ~67 ~38 ~69 ~67 stone
fill ~37 ~70 ~67 ~38 ~72 ~67 dirt
fill ~37 ~73 ~67 ~38 ~73 ~67 grass_block
fill ~39 ~60 ~67 ~40 ~68 ~67 stone
fill ~39 ~69 ~67 ~40 ~71 ~67 dirt
fill ~39 ~72 ~67 ~40 ~72 ~67 grass_block
fill ~41 ~60 ~67 ~44 ~67 ~67 stone
fill ~41 ~68 ~67 ~44 ~70 ~67 dirt
fill ~41 ~71 ~67 ~44 ~71 ~67 grass_block
fill ~45 ~60 ~67 ~45 ~66 ~67 stone
fill ~45 ~67 ~67 ~45 ~69 ~67 dirt
fill ~45 ~70 ~67 ~45 ~70 ~67 grass_block
fill ~46 ~60 ~67 ~46 ~67 ~67 stone
fill ~46 ~68 ~67 ~46 ~70 ~67 dirt
fill ~46 ~71 ~67 ~46 ~71 ~67 grass_block
fill ~47 ~60 ~67 ~47 ~66 ~67 stone
fill ~47 ~67 ~67 ~47 ~69 ~67 dirt
fill ~47 ~70 ~67 ~47 ~70 ~67 grass_block
fill ~32 ~60 ~68 ~38 ~70 ~68 stone
fill ~32 ~71 ~68 ~38 ~73 ~68 dirt
fill ~32 ~74 ~68 ~38 ~74 ~68 grass_block
fill ~39 ~60 ~68 ~40 ~69 ~68 stone
fill ~39 ~70 ~68 ~40 ~72 ~68 dirt
fill ~39 ~73 ~68 ~40 ~73 ~68 grass_block
fill ~41 ~60 ~68 ~42 ~68 ~68 stone
fill ~41 ~69 ~68 ~42 ~71 ~68 dirt
fill ~41 ~72 ~68 ~42 ~72 ~68 grass_block
fill ~43 ~60 ~68 ~47 ~67 ~68 stone
fill ~43 ~68 ~68 ~47 ~70 ~68 dirt
fill ~43 ~71 ~68 ~47 ~71 ~68 grass_block
fill ~32 ~60 ~69 ~32 ~69 ~69 stone
fill ~32 ~70 ~69 ~32 ~72 ~69 dirt
fill ~32 ~73 ~69 ~32 ~73 ~69 grass_block
fill ~33 ~60 ~69 ~40 ~70 ~69 stone
fill ~33 ~71 ~69 ~40 ~73 ~69 dirt
fill ~33 ~74 ~69 ~40 ~74 ~69 grass_block
fill ~41 ~60 ~69 ~42 ~69 ~69 stone
fill ~41 ~70 ~69 ~42 ~72 ~69 dirt
fill ~41 ~73 ~69 ~42 ~73 ~69 grass_block
fill ~43 ~60 ~69 ~45 ~68 ~69 stone
fill ~43 ~69 ~69 ~45 ~71 ~69 dirt
fill ~43 ~72 ~69 ~45 ~72 ~69 grass_block
fill ~46 ~60 ~69 ~47 ~67 ~69 stone
fill ~46 ~68 ~69 ~47 ~70 ~69 dirt
fill ~46 ~71 ~69 ~47 ~71 ~69 grass_block
fill ~32 ~60 ~70 ~34 ~69 ~70 stone
fill ~32 ~70 ~70 ~34 ~72 ~70 dirt
fill ~32 ~73 ~70 ~34 ~73 ~70 grass_block
fill ~35 ~60 ~70 ~40 ~70 ~70 stone
fill ~35 ~71 ~70 ~40 ~73 ~70 dirt
fill ~35 ~74 ~70 ~40 ~74 ~70 grass_block
fill ~41 ~60 ~70 ~44 ~69 ~70 stone
fill ~41 ~70 ~70 ~44 ~72 ~70 dirt
fill ~41 ~73 ~70 ~44 ~73 ~70 grass_block
fill ~45 ~60 ~70 ~46 ~68 ~70 stone
fill ~45 ~69 ~70 ~46 ~71 ~70 dirt
fill ~45 ~72 ~70 ~46 ~72 ~70 grass_block
fill ~47 ~60 ~70 ~47 ~67 ~70 stone
fill ~47 ~68 ~70 ~47 ~70 ~70 dirt
fill ~47 ~71 ~70 ~47 ~71 ~70 grass_block
fill ~32 ~60 ~71 ~32 ~68 ~71 stone
fill ~32 ~69 ~71 ~32 ~71 ~71 dirt
fill ~32 ~72 ~71 ~32 ~72 ~71 grass_block
fill ~33 ~60 ~71 ~35 ~69 ~71 stone
fill ~33 ~70 ~71 ~35 ~72 ~71 dirt
fill ~33 ~73 ~71 ~35 ~73 ~71 grass_block
fill ~36 ~60 ~71 ~42 ~70 ~71 stone
fill ~36 ~71 ~71 ~42 ~73 ~71 dirt
fill ~36 ~74 ~71 ~42 ~74 ~71 grass_block
fill ~43 ~60 ~71 ~45 ~69 ~71 stone
fill ~43 ~70 ~71 ~45 ~72 ~71 dirt
fill ~43 ~73 ~71 ~45 ~73 ~71 grass_block
fill ~46 ~60 ~71 ~47 ~68 ~71 stone
fill ~46 ~69 ~71 ~47 ~71 ~71 dirt
fill ~46 ~72 ~71 ~47 ~72 ~71 grass_block
fill ~32 ~60 ~72 ~33 ~68 ~72 stone
fill ~32 ~69 ~72 ~33 ~71 ~72 dirt
fill ~32 ~72 ~72 ~33 ~72 ~72 grass_block
fill ~34 ~60 ~72 ~37 ~69 ~72 stone
fill ~34 ~70 ~72 ~37 ~72 ~72 dirt
fill ~34 ~73 ~72 ~37 ~73 ~72 grass_block
fill ~38 ~60 ~72 ~44 ~70 ~72 stone
fill ~38 ~71 ~72 ~44 ~73 ~72 dirt
fill ~38 ~74 ~72 ~44 ~74 ~72 grass_block
fill ~45 ~60 ~72 ~46 ~69 ~72 stone
fill ~45 ~70 ~72 ~46 ~72 ~72 dirt
fill ~45 ~73 ~72 ~46 ~73 ~72 grass_block
fill ~47 ~60 ~72 ~47 ~68 ~72 stone
fill ~47 ~69 ~72 ~47 ~71 ~72 dirt
fill ~47 ~72 ~72 ~47 ~72 ~72 grass_block
fill ~32 ~60 ~73 ~32 ~67 ~73 stone
fill ~32 ~68 ~73 ~32 ~70 ~73 dirt
fill ~32 ~71 ~73 ~32 ~71 ~73 grass_block
fill ~33 ~60 ~73 ~34 ~68 ~73 stone
fill ~33 ~69 ~73 ~34 ~71 ~73 dirt
fill ~33 ~72 ~73 ~34 ~72 ~73 grass_block
fill ~35 ~60 ~73 ~39 ~69 ~73 stone
fill ~35 ~70 ~73 ~39 ~72 ~73 dirt
fill ~35 ~73 ~73 ~39 ~73 ~73 grass_block
fill ~40 ~60 ~73 ~46 ~70 ~73 stone
fill ~40 ~71 ~73 ~46 ~73 ~73 dirt
fill ~40 ~74 ~73 ~46 ~74 ~73 grass_block
fill ~47 ~60 ~73 ~47 ~69 ~73 stone
fill ~47 ~70 ~73 ~47 ~72 ~73 dirt
fill ~47 ~73 ~73 ~47 ~73 ~73 grass_block
fill ~32 ~60 ~74 ~34 ~67 ~74 stone
fill ~32 ~68 ~74 ~34 ~70 ~74 dirt
fill ~32 ~71 ~74 ~34 ~71 ~74 grass_block
fill ~35 ~60 ~74 ~37 ~68 ~74 stone
fill ~35 ~69 ~74 ~37 ~71 ~74 dirt
fill ~35 ~72 ~74 ~37 ~72 ~74 grass_block
fill ~38 ~60 ~74 ~40 ~69 ~74 stone
fill ~38 ~70 ~74 ~40 ~72 ~74 dirt
fill ~38 ~73 ~74 ~40 ~73 ~74 grass_block
fill ~41 ~60 ~74 ~47 ~70 ~74 stone
fill ~41 ~71 ~74 ~47 ~73 ~74 dirt
fill ~41 ~74 ~74 ~47 ~74 ~74 grass_block
fill ~32 ~60 ~75 ~32 ~68 ~75 stone
fill ~32 ~69 ~75 ~32 ~71 ~75 dirt
fill ~32 ~72 ~75 ~32 ~72 ~75 grass_block
fill ~33 ~60 ~75 ~35 ~67 ~75 stone
fill ~33 ~68 ~75 ~35 ~70 ~75 dirt
fill ~33 ~71 ~75 ~35 ~71 ~75 grass_block
fill ~36 ~60 ~75 ~37 ~68 ~75 stone
fill ~36 ~69 ~75 ~37 ~71 ~75 dirt
fill ~36 ~72 ~75 ~37 ~72 ~75 grass_block
fill ~38 ~60 ~75 ~41 ~69 ~75 stone
fill ~38 ~70 ~75 ~41 ~72 ~75 dirt
fill ~38 ~73 ~75 ~41 ~73 ~75 grass_block
fill ~42 ~60 ~75 ~47 ~70 ~75 stone
fill ~42 ~71 ~75 ~47 ~73 ~75 dirt
fill ~42 ~74 ~75 ~47 ~74 ~75 grass_block
fill ~32 ~60 ~76 ~33 ~68 ~76 stone
fill ~32 ~69 ~76 ~33 ~71 ~76 dirt
fill ~32 ~72 ~76 ~33 ~72 ~76 grass_block
fill ~34 ~60 ~76 ~36 ~67 ~76 stone
fill ~34 ~68 ~76 ~36 ~70 ~76 dirt
fill ~34 ~71 ~76 ~36 ~71 ~76 grass_block
fill ~37 ~60 ~76 ~39 ~68 ~76 stone
fill ~37 ~69 ~76 ~39 ~71 ~76 dirt
fill ~37 ~72 ~76 ~39 ~72 ~76 grass_block
fill ~40 ~60 ~76 ~43 ~69 ~76 stone
fill ~40 ~70 ~76 ~43 ~72 ~76 dirt
fill ~40 ~73 ~76 ~43 ~73 ~76 grass_block
fill ~44 ~60 ~76 ~47 ~70 ~76 stone
fill ~44 ~71 ~76 ~47 ~73 ~76 dirt
fill ~44 ~74 ~76 ~47 ~74 ~76 grass_block
fill ~32 ~60 ~77 ~33 ~68 ~77 stone
fill ~32 ~69 ~77 ~33 ~71 ~77 dirt
fill ~32 ~72 ~77 ~33 ~72 ~77 grass_block
fill ~34 ~60 ~77 ~38 ~67 ~77 stone
fill ~34 ~68 ~77 ~38 ~70 ~77 dirt
fill ~34 ~71 ~77 ~38 ~71 ~77 grass_block
fill ~39 ~60 ~77 ~40 ~68 ~77 stone
fill ~39 ~69 ~77 ~40 ~71 ~77 dirt
fill ~39 ~72 ~77 ~40 ~72 ~77 grass_block
fill ~41 ~60 ~77 ~44 ~69 ~77 stone
fill ~41 ~70 ~77 ~44 ~72 ~77 dirt
fill ~41 ~73 ~77 ~44 ~73 ~77 grass_block
fill ~45 ~60 ~77 ~47 ~70 ~77 stone
fill ~45 ~71 ~77 ~47 ~73 ~77 dirt
fill ~45 ~74 ~77 ~47 ~74 ~77 grass_block
fill ~32 ~60 ~78 ~34 ~68 ~78 stone
fill ~32 ~69 ~78 ~34 ~71 ~78 dirt
fill ~32 ~72 ~78 ~34 ~72 ~78 grass_block
fill ~35 ~60 ~78 ~35 ~67 ~78 stone
fill ~35 ~68 ~78 ~35 ~70 ~78 dirt
fill ~35 ~71 ~78 ~35 ~71 ~78 grass_block
fill ~36 ~60 ~78 ~37 ~66 ~78 stone
fill ~36 ~67 ~78 ~37 ~69 ~78 dirt
fill ~36 ~70 ~78 ~37 ~70 ~78 grass_block
fill ~38 ~60 ~78 ~39 ~67 ~78 stone
fill ~38 ~68 ~78 ~39 ~70 ~78 dirt
fill ~38 ~71 ~78 ~39 ~71 ~78 grass_block
fill ~40 ~60 ~78 ~41 ~68 ~78 stone
fill ~40 ~69 ~78 ~41 ~71 ~78 dirt
fill ~40 ~72 ~78 ~41 ~72 ~78 grass_block
fill ~42 ~60 ~78 ~45 ~69 ~78 stone
fill ~42 ~70 ~78 ~45 ~72 ~78 dirt
fill ~42 ~73 ~78 ~45 ~73 ~78 grass_block
fill ~46 ~60 ~78 ~47 ~70 ~78 stone
fill ~46 ~71 ~78 ~47 ~73 ~78 dirt
fill ~46 ~74 ~78 ~47 ~74 ~78 grass_block
fill ~32 ~60 ~79 ~34 ~68 ~79 stone
fill ~32 ~69 ~79 ~34 ~71 ~79 dirt
fill ~32 ~72 ~79 ~34 ~72 ~79 grass_block
fill ~35 ~60 ~79 ~36 ~67 ~79 stone
fill ~35 ~68 ~79 ~36 ~70 ~79 dirt
fill ~35 ~71 ~79 ~36 ~71 ~79 grass_block
fill ~37 ~60 ~79 ~38 ~66 ~79 stone
fill ~37 ~67 ~79 ~38 ~69 ~79 dirt
fill ~37 ~70 ~79 ~38 ~70 ~79 grass_block
fill ~39 ~60 ~79 ~41 ~67 ~79 stone
fill ~39 ~68 ~79 ~41 ~70 ~79 dirt
fill ~39 ~71 ~79 ~41 ~71 ~79 grass_block
fill ~42 ~60 ~79 ~42 ~68 ~79 stone
fill ~42 ~69 ~79 ~42 ~71 ~79 dirt
fill ~42 ~72 ~79 ~42 ~72 ~79 grass_block
fill ~43 ~60 ~79 ~47 ~69 ~79 stone
fill ~43 ~70 ~79 ~47 ~72 ~79 dirt
fill ~43 ~73 ~79 ~47 ~73 ~79 grass_block