fill ~0 ~60 ~96 ~6 ~65 ~96 stone
fill ~0 ~66 ~96 ~6 ~68 ~96 dirt
fill ~0 ~69 ~96 ~6 ~69 ~96 grass_block
fill ~7 ~60 ~96 ~14 ~66 ~96 stone
fill ~7 ~67 ~96 ~14 ~69 ~96 dirt
fill ~7 ~70 ~96 ~14 ~70 ~96 grass_block
fill ~15 ~60 ~96 ~15 ~65 ~96 stone
fill ~15 ~66 ~96 ~15 ~68 ~96 dirt
fill ~15 ~69 ~96 ~15 ~69 ~96 grass_block
fill ~0 ~60 ~97 ~15 ~65 ~97 stone
fill ~0 ~66 ~97 ~15 ~68 ~97 dirt
fill ~0 ~69 ~97 ~15 ~69 ~97 grass_block
fill ~0 ~60 ~98 ~15 ~65 ~98 stone
fill ~0 ~66 ~98 ~15 ~68 ~98 dirt
fill ~0 ~69 ~98 ~15 ~69 ~98 grass_block
fill ~0 ~60 ~99 ~6 ~65 ~99 stone
fill ~0 ~66 ~99 ~6 ~68 ~99 dirt
fill ~0 ~69 ~99 ~6 ~69 ~99 grass_block
fill ~7 ~60 ~99 ~7 ~64 ~99 stone
fill ~7 ~65 ~99 ~7 ~67 ~99 dirt
fill ~7 ~68 ~99 ~7 ~68 ~99 grass_block
fill ~8 ~60 ~99 ~15 ~65 ~99 stone
fill ~8 ~66 ~99 ~15 ~68 ~99 dirt
fill ~8 ~69 ~99 ~15 ~69 ~99 grass_block
fill ~0 ~60 ~100 ~0 ~66 ~100 stone
fill ~0 ~67 ~100 ~0 ~69 ~100 dirt
fill ~0 ~70 ~100 ~0 ~70 ~100 grass_block
fill ~1 ~60 ~100 ~7 ~65 ~100 stone
fill ~1 ~66 ~100 ~7 ~68 ~100 dirt
fill ~1 ~69 ~100 ~7 ~69 ~100 grass_block
fill ~8 ~60 ~100 ~15 ~64 ~100 stone
fill ~8 ~65 ~100 ~15 ~67 ~100 dirt
fill ~8 ~68 ~100 ~15 ~68 ~100 grass_block
fill ~0 ~60 ~101 ~5 ~66 ~101 stone
fill ~0 ~67 ~101 ~5 ~69 ~101 dirt
fill ~0 ~70 ~101 ~5 ~70 ~101 grass_block
fill ~6 ~60 ~101 ~11 ~65 ~101 stone
fill ~6 ~66 ~101 ~11 ~68 ~101 dirt
fill ~6 ~69 ~101 ~11 ~69 ~101 grass_block
fill ~12 ~60 ~101 ~15 ~64 ~101 stone
fill ~12 ~65 ~101 ~15 ~67 ~101 dirt
fill ~12 ~68 ~101 ~15 ~68 ~101 grass_block
fill ~0 ~60 ~102 ~7 ~66 ~102 stone
fill ~0 ~67 ~102 ~7 ~69 ~102 dirt
fill ~0 ~70 ~102 ~7 ~70 ~102 grass_block
fill ~8 ~60 ~102 ~15 ~65 ~102 stone
fill ~8 ~66 ~102 ~15 ~68 ~102 dirt
fill ~8 ~69 ~102 ~15 ~69 ~102 grass_block
fill ~0 ~60 ~103 ~0 ~67 ~103 stone
fill ~0 ~68 ~103 ~0 ~70 ~103 dirt
fill ~0 ~71 ~103 ~0 ~71 ~103 grass_block
fill ~1 ~60 ~103 ~3 ~68 ~103 stone
fill ~1 ~69 ~103 ~3 ~71 ~103 dirt
fill ~1 ~72 ~103 ~3 ~72 ~103 grass_block
fill ~4 ~60 ~103 ~4 ~67 ~103 stone
fill ~4 ~68 ~103 ~4 ~70 ~103 dirt
fill ~4 ~71 ~103 ~4 ~71 ~103 grass_block
fill ~5 ~60 ~103 ~13 ~66 ~103 stone
fill ~5 ~67 ~103 ~13 ~69 ~103 dirt
fill ~5 ~70 ~103 ~13 ~70 ~103 grass_block
fill ~14 ~60 ~103 ~15 ~65 ~103 stone
fill ~14 ~66 ~103 ~15 ~68 ~103 dirt
fill ~14 ~69 ~103 ~15 ~69 ~103 grass_block
fill ~0 ~60 ~104 ~4 ~68 ~104 stone
fill ~0 ~69 ~104 ~4 ~71 ~104 dirt
fill ~0 ~72 ~104 ~4 ~72 ~104 grass_block
fill ~5 ~60 ~104 ~10 ~67 ~104 stone
fill ~5 ~68 ~104 ~10 ~70 ~104 dirt
fill ~5 ~71 ~104 ~10 ~71 ~104 grass_block
fill ~11 ~60 ~104 ~15 ~66 ~104 stone
fill ~11 ~67 ~104 ~15 ~69 ~104 dirt
fill ~11 ~70 ~104 ~15 ~70 ~104 grass_block
fill ~0 ~60 ~105 ~2 ~69 ~105 stone
fill ~0 ~70 ~105 ~2 ~72 ~105 dirt
fill ~0 ~73 ~105 ~2 ~73 ~105 grass_block
fill ~3 ~60 ~105 ~10 ~68 ~105 stone
fill ~3 ~69 ~105 ~10 ~71 ~105 dirt
fill ~3 ~72 ~105 ~10 ~72 ~105 grass_block
fill ~11 ~60 ~105 ~12 ~67 ~105 stone
fill ~11 ~68 ~105 ~12 ~70 ~105 dirt
fill ~11 ~71 ~105 ~12 ~71 ~105 grass_block
fill ~13 ~60 ~105 ~15 ~66 ~105 stone
fill ~13 ~67 ~105 ~15 ~69 ~105 dirt
fill ~13 ~70 ~105 ~15 ~70 ~105 grass_block
fill ~0 ~60 ~106 ~0 ~69 ~106 stone
fill ~0 ~70 ~106 ~0 ~72 ~106 dirt
fill ~0 ~73 ~106 ~0 ~73 ~106 grass_block
fill ~1 ~60 ~106 ~2 ~68 ~106 stone
fill ~1 ~69 ~106 ~2 ~71 ~106 dirt
fill ~1 ~72 ~106 ~2 ~72 ~106 grass_block
fill ~3 ~60 ~106 ~3 ~69 ~106 stone
fill ~3 ~70 ~106 ~3 ~72 ~106 dirt
fill ~3 ~73 ~106 ~3 ~73 ~106 grass_block
fill ~4 ~60 ~106 ~12 ~68 ~106 stone
fill ~4 ~69 ~106 ~12 ~71 ~106 dirt
fill ~4 ~72 ~106 ~12 ~72 ~106 grass_block
fill ~13 ~60 ~106 ~15 ~67 ~106 stone
fill ~13 ~68 ~106 ~15 ~70 ~106 dirt
fill ~13 ~71 ~106 ~15 ~71 ~106 grass_block
fill ~0 ~60 ~107 ~15 ~68 ~107 stone
fill ~0 ~69 ~107 ~15 ~71 ~107 dirt
fill ~0 ~72 ~107 ~15 ~72 ~107 grass_block
fill ~0 ~60 ~108 ~3 ~67 ~108 stone
fill ~0 ~68 ~108 ~3 ~70 ~108 dirt
fill ~0 ~71 ~108 ~3 ~71 ~108 grass_block
fill ~4 ~60 ~108 ~15 ~68 ~108 stone
fill ~4 ~69 ~108 ~15 ~71 ~108 dirt
fill ~4 ~72 ~108 ~15 ~72 ~108 grass_block
fill ~0 ~60 ~109 ~8 ~67 ~109 stone
fill ~0 ~68 ~109 ~8 ~70 ~109 dirt
fill ~0 ~71 ~109 ~8 ~71 ~109 grass_block
fill ~9 ~60 ~109 ~15 ~68 ~109 stone
fill ~9 ~69 ~109 ~15 ~71 ~109 dirt
fill ~9 ~72 ~109 ~15 ~72 ~109 grass_block
fill ~0 ~60 ~110 ~1 ~68 ~110 stone
fill ~0 ~69 ~110 ~1 ~71 ~110 dirt
fill ~0 ~72 ~110 ~1 ~72 ~110 grass_block
fill ~2 ~60 ~110 ~4 ~67 ~110 stone
fill ~2 ~68 ~110 ~4 ~70 ~110 dirt
fill ~2 ~71 ~110 ~4 ~71 ~110 grass_block
fill ~5 ~60 ~110 ~7 ~66 ~110 stone
fill ~5 ~67 ~110 ~7 ~69 ~110 dirt
fill ~5 ~70 ~110 ~7 ~70 ~110 grass_block
fill ~8 ~60 ~110 ~10 ~67 ~110 stone
fill ~8 ~68 ~110 ~10 ~70 ~110 dirt
fill ~8 ~71 ~110 ~10 ~71 ~110 grass_block
fill ~11 ~60 ~110 ~15 ~68 ~110 stone
fill ~11 ~69 ~110 ~15 ~71 ~110 dirt
fill ~11 ~72 ~110 ~15 ~72 ~110 grass_block
fill ~0 ~60 ~111 ~3 ~68 ~111 stone
fill ~0 ~69 ~111 ~3 ~71 ~111 dirt
fill ~0 ~72 ~111 ~3 ~72 ~111 grass_block
fill ~4 ~60 ~111 ~4 ~67 ~111 stone
fill ~4 ~68 ~111 ~4 ~70 ~111 dirt
fill ~4 ~71 ~111 ~4 ~71 ~111 grass_block
fill ~5 ~60 ~111 ~9 ~66 ~111 stone
fill ~5 ~67 ~111 ~9 ~69 ~111 dirt
fill ~5 ~70 ~111 ~9 ~70 ~111 grass_block
fill ~10 ~60 ~111 ~11 ~67 ~111 stone
fill ~10 ~68 ~111 ~11 ~70 ~111 dirt
fill ~10 ~71 ~111 ~11 ~71 ~111 grass_block
fill ~12 ~60 ~111 ~13 ~68 ~111 stone
fill ~12 ~69 ~111 ~13 ~71 ~111 dirt
fill ~12 ~72 ~111 ~13 ~72 ~111 grass_block
fill ~14 ~60 ~111 ~15 ~67 ~111 stone
fill ~14 ~68 ~111 ~15 ~70 ~111 dirt
fill ~14 ~71 ~111 ~15 ~71 ~111 grass_block