fill ~416 ~60 ~64 ~418 ~65 ~64 stone
fill ~416 ~66 ~64 ~418 ~68 ~64 dirt
fill ~416 ~69 ~64 ~418 ~69 ~64 grass_block
fill ~419 ~60 ~64 ~420 ~64 ~64 stone
fill ~419 ~65 ~64 ~420 ~67 ~64 dirt
fill ~419 ~68 ~64 ~420 ~68 ~64 grass_block
fill ~421 ~60 ~64 ~424 ~65 ~64 stone
fill ~421 ~66 ~64 ~424 ~68 ~64 dirt
fill ~421 ~69 ~64 ~424 ~69 ~64 grass_block
fill ~425 ~60 ~64 ~429 ~66 ~64 stone
fill ~425 ~67 ~64 ~429 ~69 ~64 dirt
fill ~425 ~70 ~64 ~429 ~70 ~64 grass_block
fill ~430 ~60 ~64 ~431 ~65 ~64 stone
fill ~430 ~66 ~64 ~431 ~68 ~64 dirt
fill ~430 ~69 ~64 ~431 ~69 ~64 grass_block
fill ~416 ~60 ~65 ~417 ~65 ~65 stone
fill ~416 ~66 ~65 ~417 ~68 ~65 dirt
fill ~416 ~69 ~65 ~417 ~69 ~65 grass_block
fill ~418 ~60 ~65 ~421 ~64 ~65 stone
fill ~418 ~65 ~65 ~421 ~67 ~65 dirt
fill ~418 ~68 ~65 ~421 ~68 ~65 grass_block
fill ~422 ~60 ~65 ~425 ~65 ~65 stone
fill ~422 ~66 ~65 ~425 ~68 ~65 dirt
fill ~422 ~69 ~65 ~425 ~69 ~65 grass_block
fill ~426 ~60 ~65 ~430 ~66 ~65 stone
fill ~426 ~67 ~65 ~430 ~69 ~65 dirt
fill ~426 ~70 ~65 ~430 ~70 ~65 grass_block
fill ~431 ~60 ~65 ~431 ~65 ~65 stone
fill ~431 ~66 ~65 ~431 ~68 ~65 dirt
fill ~431 ~69 ~65 ~431 ~69 ~65 grass_block
fill ~416 ~60 ~66 ~416 ~65 ~66 stone
fill ~416 ~66 ~66 ~416 ~68 ~66 dirt
fill ~416 ~69 ~66 ~416 ~69 ~66 grass_block
fill ~417 ~60 ~66 ~422 ~64 ~66 stone
fill ~417 ~65 ~66 ~422 ~67 ~66 dirt
fill ~417 ~68 ~66 ~422 ~68 ~66 grass_block
fill ~423 ~60 ~66 ~426 ~65 ~66 stone
fill ~423 ~66 ~66 ~426 ~68 ~66 dirt
fill ~423 ~69 ~66 ~426 ~69 ~66 grass_block
fill ~427 ~60 ~66 ~430 ~66 ~66 stone
fill ~427 ~67 ~66 ~430 ~69 ~66 dirt
fill ~427 ~70 ~66 ~430 ~70 ~66 grass_block
fill ~431 ~60 ~66 ~431 ~65 ~66 stone
fill ~431 ~66 ~66 ~431 ~68 ~66 dirt
fill ~431 ~69 ~66 ~431 ~69 ~66 grass_block
fill ~416 ~60 ~67 ~422 ~64 ~67 stone
fill ~416 ~65 ~67 ~422 ~67 ~67 dirt
fill ~416 ~68 ~67 ~422 ~68 ~67 grass_block
fill ~423 ~60 ~67 ~427 ~65 ~67 stone
fill ~423 ~66 ~67 ~427 ~68 ~67 dirt
fill ~423 ~69 ~67 ~427 ~69 ~67 grass_block
fill ~428 ~60 ~67 ~430 ~66 ~67 stone
fill ~428 ~67 ~67 ~430 ~69 ~67 dirt
fill ~428 ~70 ~67 ~430 ~70 ~67 grass_block
fill ~431 ~60 ~67 ~431 ~65 ~67 stone
fill ~431 ~66 ~67 ~431 ~68 ~67 dirt
fill ~431 ~69 ~67 ~431 ~69 ~67 grass_block
fill ~416 ~60 ~68 ~423 ~64 ~68 stone
fill ~416 ~65 ~68 ~423 ~67 ~68 dirt
fill ~416 ~68 ~68 ~423 ~68 ~68 grass_block
fill ~424 ~60 ~68 ~428 ~65 ~68 stone
fill ~424 ~66 ~68 ~428 ~68 ~68 dirt
fill ~424 ~69 ~68 ~428 ~69 ~68 grass_block
fill ~429 ~60 ~68 ~430 ~66 ~68 stone
fill ~429 ~67 ~68 ~430 ~69 ~68 dirt
fill ~429 ~70 ~68 ~430 ~70 ~68 grass_block
fill ~431 ~60 ~68 ~431 ~65 ~68 stone
fill ~431 ~66 ~68 ~431 ~68 ~68 dirt
fill ~431 ~69 ~68 ~431 ~69 ~68 grass_block
fill ~416 ~60 ~69 ~424 ~64 ~69 stone
fill ~416 ~65 ~69 ~424 ~67 ~69 dirt
fill ~416 ~68 ~69 ~424 ~68 ~69 grass_block
fill ~425 ~60 ~69 ~431 ~65 ~69 stone
fill ~425 ~66 ~69 ~431 ~68 ~69 dirt
fill ~425 ~69 ~69 ~431 ~69 ~69 grass_block
fill ~416 ~60 ~70 ~424 ~64 ~70 stone
fill ~416 ~65 ~70 ~424 ~67 ~70 dirt
fill ~416 ~68 ~70 ~424 ~68 ~70 grass_block
fill ~425 ~60 ~70 ~431 ~65 ~70 stone
fill ~425 ~66 ~70 ~431 ~68 ~70 dirt
fill ~425 ~69 ~70 ~431 ~69 ~70 grass_block
fill ~416 ~60 ~71 ~420 ~64 ~71 stone
fill ~416 ~65 ~71 ~420 ~67 ~71 dirt
fill ~416 ~68 ~71 ~420 ~68 ~71 grass_block
fill ~421 ~60 ~71 ~421 ~63 ~71 stone
fill ~421 ~64 ~71 ~421 ~66 ~71 dirt
fill ~421 ~67 ~71 ~421 ~67 ~71 grass_block
fill ~422 ~60 ~71 ~425 ~64 ~71 stone
fill ~422 ~65 ~71 ~425 ~67 ~71 dirt
fill ~422 ~68 ~71 ~425 ~68 ~71 grass_block
fill ~426 ~60 ~71 ~431 ~65 ~71 stone
fill ~426 ~66 ~71 ~431 ~68 ~71 dirt
fill ~426 ~69 ~71 ~431 ~69 ~71 grass_block
fill ~416 ~60 ~72 ~420 ~64 ~72 stone
fill ~416 ~65 ~72 ~420 ~67 ~72 dirt
fill ~416 ~68 ~72 ~420 ~68 ~72 grass_block
fill ~421 ~60 ~72 ~422 ~63 ~72 stone
fill ~421 ~64 ~72 ~422 ~66 ~72 dirt
fill ~421 ~67 ~72 ~422 ~67 ~72 grass_block
fill ~423 ~60 ~72 ~426 ~64 ~72 stone
fill ~423 ~65 ~72 ~426 ~67 ~72 dirt
fill ~423 ~68 ~72 ~426 ~68 ~72 grass_block
fill ~427 ~60 ~72 ~431 ~65 ~72 stone
fill ~427 ~66 ~72 ~431 ~68 ~72 dirt
fill ~427 ~69 ~72 ~431 ~69 ~72 grass_block
fill ~416 ~60 ~73 ~420 ~64 ~73 stone
fill ~416 ~65 ~73 ~420 ~67 ~73 dirt
fill ~416 ~68 ~73 ~420 ~68 ~73 grass_block
fill ~421 ~60 ~73 ~423 ~63 ~73 stone
fill ~421 ~64 ~73 ~423 ~66 ~73 dirt
fill ~421 ~67 ~73 ~423 ~67 ~73 grass_block
fill ~424 ~60 ~73 ~427 ~64 ~73 stone
fill ~424 ~65 ~73 ~427 ~67 ~73 dirt
fill ~424 ~68 ~73 ~427 ~68 ~73 grass_block
fill ~428 ~60 ~73 ~431 ~65 ~73 stone
fill ~428 ~66 ~73 ~431 ~68 ~73 dirt
fill ~428 ~69 ~73 ~431 ~69 ~73 grass_block
fill ~416 ~60 ~74 ~420 ~64 ~74 stone
fill ~416 ~65 ~74 ~420 ~67 ~74 dirt
fill ~416 ~68 ~74 ~420 ~68 ~74 grass_block
fill ~421 ~60 ~74 ~424 ~63 ~74 stone
fill ~421 ~64 ~74 ~424 ~66 ~74 dirt
fill ~421 ~67 ~74 ~424 ~67 ~74 grass_block
fill ~425 ~60 ~74 ~431 ~64 ~74 stone
fill ~425 ~65 ~74 ~431 ~67 ~74 dirt
fill ~425 ~68 ~74 ~431 ~68 ~74 grass_block
fill ~416 ~60 ~75 ~420 ~64 ~75 stone
fill ~416 ~65 ~75 ~420 ~67 ~75 dirt
fill ~416 ~68 ~75 ~420 ~68 ~75 grass_block
fill ~421 ~60 ~75 ~425 ~63 ~75 stone
fill ~421 ~64 ~75 ~425 ~66 ~75 dirt
fill ~421 ~67 ~75 ~425 ~67 ~75 grass_block
fill ~426 ~60 ~75 ~431 ~64 ~75 stone
fill ~426 ~65 ~75 ~431 ~67 ~75 dirt
fill ~426 ~68 ~75 ~431 ~68 ~75 grass_block
fill ~416 ~60 ~76 ~416 ~63 ~76 stone
fill ~416 ~64 ~76 ~416 ~66 ~76 dirt
fill ~416 ~67 ~76 ~416 ~67 ~76 grass_block
fill ~417 ~60 ~76 ~420 ~64 ~76 stone
fill ~417 ~65 ~76 ~420 ~67 ~76 dirt
fill ~417 ~68 ~76 ~420 ~68 ~76 grass_block
fill ~421 ~60 ~76 ~426 ~63 ~76 stone
fill ~421 ~64 ~76 ~426 ~66 ~76 dirt
fill ~421 ~67 ~76 ~426 ~67 ~76 grass_block
fill ~427 ~60 ~76 ~431 ~64 ~76 stone
fill ~427 ~65 ~76 ~431 ~67 ~76 dirt
fill ~427 ~68 ~76 ~431 ~68 ~76 grass_block
fill ~416 ~60 ~77 ~417 ~63 ~77 stone
fill ~416 ~64 ~77 ~417 ~66 ~77 dirt
fill ~416 ~67 ~77 ~417 ~67 ~77 grass_block
fill ~418 ~60 ~77 ~420 ~64 ~77 stone
fill ~418 ~65 ~77 ~420 ~67 ~77 dirt
fill ~418 ~68 ~77 ~420 ~68 ~77 grass_block
fill ~421 ~60 ~77 ~427 ~63 ~77 stone
fill ~421 ~64 ~77 ~427 ~66 ~77 dirt
fill ~421 ~67 ~77 ~427 ~67 ~77 grass_block
fill ~428 ~60 ~77 ~431 ~64 ~77 stone
fill ~428 ~65 ~77 ~431 ~67 ~77 dirt
fill ~428 ~68 ~77 ~431 ~68 ~77 grass_block
fill ~416 ~60 ~78 ~418 ~63 ~78 stone
fill ~416 ~64 ~78 ~418 ~66 ~78 dirt
fill ~416 ~67 ~78 ~418 ~67 ~78 grass_block
fill ~419 ~60 ~78 ~421 ~64 ~78 stone
fill ~419 ~65 ~78 ~421 ~67 ~78 dirt
fill ~419 ~68 ~78 ~421 ~68 ~78 grass_block
fill ~422 ~60 ~78 ~428 ~63 ~78 stone
fill ~422 ~64 ~78 ~428 ~66 ~78 dirt
fill ~422 ~67 ~78 ~428 ~67 ~78 grass_block
fill ~429 ~60 ~78 ~430 ~64 ~78 stone
fill ~429 ~65 ~78 ~430 ~67 ~78 dirt
fill ~429 ~68 ~78 ~430 ~68 ~78 grass_block
fill ~431 ~60 ~78 ~431 ~63 ~78 stone
fill ~431 ~64 ~78 ~431 ~66 ~78 dirt
fill ~431 ~67 ~78 ~431 ~67 ~78 grass_block
fill ~416 ~60 ~79 ~419 ~63 ~79 stone
fill ~416 ~64 ~79 ~419 ~66 ~79 dirt
fill ~416 ~67 ~79 ~419 ~67 ~79 grass_block
fill ~420 ~60 ~79 ~421 ~64 ~79 stone
fill ~420 ~65 ~79 ~421 ~67 ~79 dirt
fill ~420 ~68 ~79 ~421 ~68 ~79 grass_block
fill ~422 ~60 ~79 ~431 ~63 ~79 stone
fill ~422 ~64 ~79 ~431 ~66 ~79 dirt
fill ~422 ~67 ~79 ~431 ~67 ~79 grass_block