fill ~288 ~60 ~112 ~289 ~65 ~112 stone
fill ~288 ~66 ~112 ~289 ~68 ~112 dirt
fill ~288 ~69 ~112 ~289 ~69 ~112 grass_block
fill ~290 ~60 ~112 ~291 ~64 ~112 stone
fill ~290 ~65 ~112 ~291 ~67 ~112 dirt
fill ~290 ~68 ~112 ~291 ~68 ~112 grass_block
fill ~292 ~60 ~112 ~296 ~63 ~112 stone
fill ~292 ~64 ~112 ~296 ~66 ~112 dirt
fill ~292 ~67 ~112 ~296 ~67 ~112 grass_block
fill ~297 ~60 ~112 ~303 ~64 ~112 stone
fill ~297 ~65 ~112 ~303 ~67 ~112 dirt
fill ~297 ~68 ~112 ~303 ~68 ~112 grass_block
fill ~288 ~60 ~113 ~289 ~65 ~113 stone
fill ~288 ~66 ~113 ~289 ~68 ~113 dirt
fill ~288 ~69 ~113 ~289 ~69 ~113 grass_block
fill ~290 ~60 ~113 ~292 ~64 ~113 stone
fill ~290 ~65 ~113 ~292 ~67 ~113 dirt
fill ~290 ~68 ~113 ~292 ~68 ~113 grass_block
fill ~293 ~60 ~113 ~295 ~63 ~113 stone
fill ~293 ~64 ~113 ~295 ~66 ~113 dirt
fill ~293 ~67 ~113 ~295 ~67 ~113 grass_block
fill ~296 ~60 ~113 ~299 ~64 ~113 stone
fill ~296 ~65 ~113 ~299 ~67 ~113 dirt
fill ~296 ~68 ~113 ~299 ~68 ~113 grass_block
fill ~300 ~60 ~113 ~300 ~65 ~113 stone
fill ~300 ~66 ~113 ~300 ~68 ~113 dirt
fill ~300 ~69 ~113 ~300 ~69 ~113 grass_block
fill ~301 ~60 ~113 ~303 ~64 ~113 stone
fill ~301 ~65 ~113 ~303 ~67 ~113 dirt
fill ~301 ~68 ~113 ~303 ~68 ~113 grass_block
fill ~288 ~60 ~114 ~290 ~65 ~114 stone
fill ~288 ~66 ~114 ~290 ~68 ~114 dirt
fill ~288 ~69 ~114 ~290 ~69 ~114 grass_block
fill ~291 ~60 ~114 ~292 ~64 ~114 stone
fill ~291 ~65 ~114 ~292 ~67 ~114 dirt
fill ~291 ~68 ~114 ~292 ~68 ~114 grass_block
fill ~293 ~60 ~114 ~293 ~63 ~114 stone
fill ~293 ~64 ~114 ~293 ~66 ~114 dirt
fill ~293 ~67 ~114 ~293 ~67 ~114 grass_block
fill ~294 ~60 ~114 ~298 ~64 ~114 stone
fill ~294 ~65 ~114 ~298 ~67 ~114 dirt
fill ~294 ~68 ~114 ~298 ~68 ~114 grass_block
fill ~299 ~60 ~114 ~302 ~65 ~114 stone
fill ~299 ~66 ~114 ~302 ~68 ~114 dirt
fill ~299 ~69 ~114 ~302 ~69 ~114 grass_block
fill ~303 ~60 ~114 ~303 ~64 ~114 stone
fill ~303 ~65 ~114 ~303 ~67 ~114 dirt
fill ~303 ~68 ~114 ~303 ~68 ~114 grass_block
fill ~288 ~60 ~115 ~291 ~65 ~115 stone
fill ~288 ~66 ~115 ~291 ~68 ~115 dirt
fill ~288 ~69 ~115 ~291 ~69 ~115 grass_block
fill ~292 ~60 ~115 ~297 ~64 ~115 stone
fill ~292 ~65 ~115 ~297 ~67 ~115 dirt
fill ~292 ~68 ~115 ~297 ~68 ~115 grass_block
fill ~298 ~60 ~115 ~303 ~65 ~115 stone
fill ~298 ~66 ~115 ~303 ~68 ~115 dirt
fill ~298 ~69 ~115 ~303 ~69 ~115 grass_block
fill ~288 ~60 ~116 ~292 ~65 ~116 stone
fill ~288 ~66 ~116 ~292 ~68 ~116 dirt
fill ~288 ~69 ~116 ~292 ~69 ~116 grass_block
fill ~293 ~60 ~116 ~296 ~64 ~116 stone
fill ~293 ~65 ~116 ~296 ~67 ~116 dirt
fill ~293 ~68 ~116 ~296 ~68 ~116 grass_block
fill ~297 ~60 ~116 ~303 ~65 ~116 stone
fill ~297 ~66 ~116 ~303 ~68 ~116 dirt
fill ~297 ~69 ~116 ~303 ~69 ~116 grass_block
fill ~288 ~60 ~117 ~292 ~65 ~117 stone
fill ~288 ~66 ~117 ~292 ~68 ~117 dirt
fill ~288 ~69 ~117 ~292 ~69 ~117 grass_block
fill ~293 ~60 ~117 ~295 ~64 ~117 stone
fill ~293 ~65 ~117 ~295 ~67 ~117 dirt
fill ~293 ~68 ~117 ~295 ~68 ~117 grass_block
fill ~296 ~60 ~117 ~303 ~65 ~117 stone
fill ~296 ~66 ~117 ~303 ~68 ~117 dirt
fill ~296 ~69 ~117 ~303 ~69 ~117 grass_block
fill ~288 ~60 ~118 ~303 ~65 ~118 stone
fill ~288 ~66 ~118 ~303 ~68 ~118 dirt
fill ~288 ~69 ~118 ~303 ~69 ~118 grass_block
fill ~288 ~60 ~119 ~288 ~66 ~119 stone
fill ~288 ~67 ~119 ~288 ~69 ~119 dirt
fill ~288 ~70 ~119 ~288 ~70 ~119 grass_block
fill ~289 ~60 ~119 ~303 ~65 ~119 stone
fill ~289 ~66 ~119 ~303 ~68 ~119 dirt
fill ~289 ~69 ~119 ~303 ~69 ~119 grass_block
fill ~288 ~60 ~120 ~290 ~66 ~120 stone
fill ~288 ~67 ~120 ~290 ~69 ~120 dirt
fill ~288 ~70 ~120 ~290 ~70 ~120 grass_block
fill ~291 ~60 ~120 ~303 ~65 ~120 stone
fill ~291 ~66 ~120 ~303 ~68 ~120 dirt
fill ~291 ~69 ~120 ~303 ~69 ~120 grass_block
fill ~288 ~60 ~121 ~290 ~66 ~121 stone
fill ~288 ~67 ~121 ~290 ~69 ~121 dirt
fill ~288 ~70 ~121 ~290 ~70 ~121 grass_block
fill ~291 ~60 ~121 ~303 ~65 ~121 stone
fill ~291 ~66 ~121 ~303 ~68 ~121 dirt
fill ~291 ~69 ~121 ~303 ~69 ~121 grass_block
fill ~288 ~60 ~122 ~288 ~65 ~122 stone
fill ~288 ~66 ~122 ~288 ~68 ~122 dirt
fill ~288 ~69 ~122 ~288 ~69 ~122 grass_block
fill ~289 ~60 ~122 ~290 ~66 ~122 stone
fill ~289 ~67 ~122 ~290 ~69 ~122 dirt
fill ~289 ~70 ~122 ~290 ~70 ~122 grass_block
fill ~291 ~60 ~122 ~303 ~65 ~122 stone
fill ~291 ~66 ~122 ~303 ~68 ~122 dirt
fill ~291 ~69 ~122 ~303 ~69 ~122 grass_block
fill ~288 ~60 ~123 ~288 ~65 ~123 stone
fill ~288 ~66 ~123 ~288 ~68 ~123 dirt
fill ~288 ~69 ~123 ~288 ~69 ~123 grass_block
fill ~289 ~60 ~123 ~291 ~66 ~123 stone
fill ~289 ~67 ~123 ~291 ~69 ~123 dirt
fill ~289 ~70 ~123 ~291 ~70 ~123 grass_block
fill ~292 ~60 ~123 ~303 ~65 ~123 stone
fill ~292 ~66 ~123 ~303 ~68 ~123 dirt
fill ~292 ~69 ~123 ~303 ~69 ~123 grass_block
fill ~288 ~60 ~124 ~288 ~65 ~124 stone
fill ~288 ~66 ~124 ~288 ~68 ~124 dirt
fill ~288 ~69 ~124 ~288 ~69 ~124 grass_block
fill ~289 ~60 ~124 ~291 ~66 ~124 stone
fill ~289 ~67 ~124 ~291 ~69 ~124 dirt
fill ~289 ~70 ~124 ~291 ~70 ~124 grass_block
fill ~292 ~60 ~124 ~303 ~65 ~124 stone
fill ~292 ~66 ~124 ~303 ~68 ~124 dirt
fill ~292 ~69 ~124 ~303 ~69 ~124 grass_block
fill ~288 ~60 ~125 ~291 ~66 ~125 stone
fill ~288 ~67 ~125 ~291 ~69 ~125 dirt
fill ~288 ~70 ~125 ~291 ~70 ~125 grass_block
fill ~292 ~60 ~125 ~303 ~65 ~125 stone
fill ~292 ~66 ~125 ~303 ~68 ~125 dirt
fill ~292 ~69 ~125 ~303 ~69 ~125 grass_block
fill ~288 ~60 ~126 ~291 ~66 ~126 stone
fill ~288 ~67 ~126 ~291 ~69 ~126 dirt
fill ~288 ~70 ~126 ~291 ~70 ~126 grass_block
fill ~292 ~60 ~126 ~303 ~65 ~126 stone
fill ~292 ~66 ~126 ~303 ~68 ~126 dirt
fill ~292 ~69 ~126 ~303 ~69 ~126 grass_block
fill ~288 ~60 ~127 ~290 ~66 ~127 stone
fill ~288 ~67 ~127 ~290 ~69 ~127 dirt
fill ~288 ~70 ~127 ~290 ~70 ~127 grass_block
fill ~291 ~60 ~127 ~303 ~65 ~127 stone
fill ~291 ~66 ~127 ~303 ~68 ~127 dirt
fill ~291 ~69 ~127 ~303 ~69 ~127 grass_block