fill ~192 ~60 ~80 ~196 ~65 ~80 stone
fill ~192 ~66 ~80 ~196 ~68 ~80 dirt
fill ~192 ~69 ~80 ~196 ~69 ~80 grass_block
fill ~197 ~60 ~80 ~203 ~64 ~80 stone
fill ~197 ~65 ~80 ~203 ~67 ~80 dirt
fill ~197 ~68 ~80 ~203 ~68 ~80 grass_block
fill ~204 ~60 ~80 ~207 ~65 ~80 stone
fill ~204 ~66 ~80 ~207 ~68 ~80 dirt
fill ~204 ~69 ~80 ~207 ~69 ~80 grass_block
fill ~192 ~60 ~81 ~195 ~65 ~81 stone
fill ~192 ~66 ~81 ~195 ~68 ~81 dirt
fill ~192 ~69 ~81 ~195 ~69 ~81 grass_block
fill ~196 ~60 ~81 ~199 ~64 ~81 stone
fill ~196 ~65 ~81 ~199 ~67 ~81 dirt
fill ~196 ~68 ~81 ~199 ~68 ~81 grass_block
fill ~200 ~60 ~81 ~200 ~63 ~81 stone
fill ~200 ~64 ~81 ~200 ~66 ~81 dirt
fill ~200 ~67 ~81 ~200 ~67 ~81 grass_block
fill ~201 ~60 ~81 ~206 ~64 ~81 stone
fill ~201 ~65 ~81 ~206 ~67 ~81 dirt
fill ~201 ~68 ~81 ~206 ~68 ~81 grass_block
fill ~207 ~60 ~81 ~207 ~65 ~81 stone
fill ~207 ~66 ~81 ~207 ~68 ~81 dirt
fill ~207 ~69 ~81 ~207 ~69 ~81 grass_block
fill ~192 ~60 ~82 ~193 ~65 ~82 stone
fill ~192 ~66 ~82 ~193 ~68 ~82 dirt
fill ~192 ~69 ~82 ~193 ~69 ~82 grass_block
fill ~194 ~60 ~82 ~199 ~64 ~82 stone
fill ~194 ~65 ~82 ~199 ~67 ~82 dirt
fill ~194 ~68 ~82 ~199 ~68 ~82 grass_block
fill ~200 ~60 ~82 ~202 ~63 ~82 stone
fill ~200 ~64 ~82 ~202 ~66 ~82 dirt
fill ~200 ~67 ~82 ~202 ~67 ~82 grass_block
fill ~203 ~60 ~82 ~206 ~64 ~82 stone
fill ~203 ~65 ~82 ~206 ~67 ~82 dirt
fill ~203 ~68 ~82 ~206 ~68 ~82 grass_block
fill ~207 ~60 ~82 ~207 ~65 ~82 stone
fill ~207 ~66 ~82 ~207 ~68 ~82 dirt
fill ~207 ~69 ~82 ~207 ~69 ~82 grass_block
fill ~192 ~60 ~83 ~192 ~65 ~83 stone
fill ~192 ~66 ~83 ~192 ~68 ~83 dirt
fill ~192 ~69 ~83 ~192 ~69 ~83 grass_block
fill ~193 ~60 ~83 ~198 ~64 ~83 stone
fill ~193 ~65 ~83 ~198 ~67 ~83 dirt
fill ~193 ~68 ~83 ~198 ~68 ~83 grass_block
fill ~199 ~60 ~83 ~201 ~63 ~83 stone
fill ~199 ~64 ~83 ~201 ~66 ~83 dirt
fill ~199 ~67 ~83 ~201 ~67 ~83 grass_block
fill ~202 ~60 ~83 ~204 ~64 ~83 stone
fill ~202 ~65 ~83 ~204 ~67 ~83 dirt
fill ~202 ~68 ~83 ~204 ~68 ~83 grass_block
fill ~205 ~60 ~83 ~207 ~65 ~83 stone
fill ~205 ~66 ~83 ~207 ~68 ~83 dirt
fill ~205 ~69 ~83 ~207 ~69 ~83 grass_block
fill ~192 ~60 ~84 ~198 ~64 ~84 stone
fill ~192 ~65 ~84 ~198 ~67 ~84 dirt
fill ~192 ~68 ~84 ~198 ~68 ~84 grass_block
fill ~199 ~60 ~84 ~201 ~63 ~84 stone
fill ~199 ~64 ~84 ~201 ~66 ~84 dirt
fill ~199 ~67 ~84 ~201 ~67 ~84 grass_block
fill ~202 ~60 ~84 ~203 ~64 ~84 stone
fill ~202 ~65 ~84 ~203 ~67 ~84 dirt
fill ~202 ~68 ~84 ~203 ~68 ~84 grass_block
fill ~204 ~60 ~84 ~206 ~65 ~84 stone
fill ~204 ~66 ~84 ~206 ~68 ~84 dirt
fill ~204 ~69 ~84 ~206 ~69 ~84 grass_block
fill ~207 ~60 ~84 ~207 ~66 ~84 stone
fill ~207 ~67 ~84 ~207 ~69 ~84 dirt
fill ~207 ~70 ~84 ~207 ~70 ~84 grass_block
fill ~192 ~60 ~85 ~196 ~64 ~85 stone
fill ~192 ~65 ~85 ~196 ~67 ~85 dirt
fill ~192 ~68 ~85 ~196 ~68 ~85 grass_block
fill ~197 ~60 ~85 ~201 ~63 ~85 stone
fill ~197 ~64 ~85 ~201 ~66 ~85 dirt
fill ~197 ~67 ~85 ~201 ~67 ~85 grass_block
fill ~202 ~60 ~85 ~202 ~64 ~85 stone
fill ~202 ~65 ~85 ~202 ~67 ~85 dirt
fill ~202 ~68 ~85 ~202 ~68 ~85 grass_block
fill ~203 ~60 ~85 ~204 ~65 ~85 stone
fill ~203 ~66 ~85 ~204 ~68 ~85 dirt
fill ~203 ~69 ~85 ~204 ~69 ~85 grass_block
fill ~205 ~60 ~85 ~207 ~66 ~85 stone
fill ~205 ~67 ~85 ~207 ~69 ~85 dirt
fill ~205 ~70 ~85 ~207 ~70 ~85 grass_block
fill ~192 ~60 ~86 ~196 ~64 ~86 stone
fill ~192 ~65 ~86 ~196 ~67 ~86 dirt
fill ~192 ~68 ~86 ~196 ~68 ~86 grass_block
fill ~197 ~60 ~86 ~201 ~63 ~86 stone
fill ~197 ~64 ~86 ~201 ~66 ~86 dirt
fill ~197 ~67 ~86 ~201 ~67 ~86 grass_block
fill ~202 ~60 ~86 ~202 ~64 ~86 stone
fill ~202 ~65 ~86 ~202 ~67 ~86 dirt
fill ~202 ~68 ~86 ~202 ~68 ~86 grass_block
fill ~203 ~60 ~86 ~205 ~65 ~86 stone
fill ~203 ~66 ~86 ~205 ~68 ~86 dirt
fill ~203 ~69 ~86 ~205 ~69 ~86 grass_block
fill ~206 ~60 ~86 ~207 ~66 ~86 stone
fill ~206 ~67 ~86 ~207 ~69 ~86 dirt
fill ~206 ~70 ~86 ~207 ~70 ~86 grass_block
fill ~192 ~60 ~87 ~195 ~64 ~87 stone
fill ~192 ~65 ~87 ~195 ~67 ~87 dirt
fill ~192 ~68 ~87 ~195 ~68 ~87 grass_block
fill ~196 ~60 ~87 ~201 ~63 ~87 stone
fill ~196 ~64 ~87 ~201 ~66 ~87 dirt
fill ~196 ~67 ~87 ~201 ~67 ~87 grass_block
fill ~202 ~60 ~87 ~203 ~64 ~87 stone
fill ~202 ~65 ~87 ~203 ~67 ~87 dirt
fill ~202 ~68 ~87 ~203 ~68 ~87 grass_block
fill ~204 ~60 ~87 ~206 ~65 ~87 stone
fill ~204 ~66 ~87 ~206 ~68 ~87 dirt
fill ~204 ~69 ~87 ~206 ~69 ~87 grass_block
fill ~207 ~60 ~87 ~207 ~66 ~87 stone
fill ~207 ~67 ~87 ~207 ~69 ~87 dirt
fill ~207 ~70 ~87 ~207 ~70 ~87 grass_block
fill ~192 ~60 ~88 ~195 ~64 ~88 stone
fill ~192 ~65 ~88 ~195 ~67 ~88 dirt
fill ~192 ~68 ~88 ~195 ~68 ~88 grass_block
fill ~196 ~60 ~88 ~202 ~63 ~88 stone
fill ~196 ~64 ~88 ~202 ~66 ~88 dirt
fill ~196 ~67 ~88 ~202 ~67 ~88 grass_block
fill ~203 ~60 ~88 ~204 ~64 ~88 stone
fill ~203 ~65 ~88 ~204 ~67 ~88 dirt
fill ~203 ~68 ~88 ~204 ~68 ~88 grass_block
fill ~205 ~60 ~88 ~206 ~65 ~88 stone
fill ~205 ~66 ~88 ~206 ~68 ~88 dirt
fill ~205 ~69 ~88 ~206 ~69 ~88 grass_block
fill ~207 ~60 ~88 ~207 ~66 ~88 stone
fill ~207 ~67 ~88 ~207 ~69 ~88 dirt
fill ~207 ~70 ~88 ~207 ~70 ~88 grass_block
fill ~192 ~60 ~89 ~199 ~63 ~89 stone
fill ~192 ~64 ~89 ~199 ~66 ~89 dirt
fill ~192 ~67 ~89 ~199 ~67 ~89 grass_block
fill ~200 ~60 ~89 ~203 ~64 ~89 stone
fill ~200 ~65 ~89 ~203 ~67 ~89 dirt
fill ~200 ~68 ~89 ~203 ~68 ~89 grass_block
fill ~204 ~60 ~89 ~206 ~65 ~89 stone
fill ~204 ~66 ~89 ~206 ~68 ~89 dirt
fill ~204 ~69 ~89 ~206 ~69 ~89 grass_block
fill ~207 ~60 ~89 ~207 ~66 ~89 stone
fill ~207 ~67 ~89 ~207 ~69 ~89 dirt
fill ~207 ~70 ~89 ~207 ~70 ~89 grass_block
fill ~192 ~60 ~90 ~199 ~63 ~90 stone
fill ~192 ~64 ~90 ~199 ~66 ~90 dirt
fill ~192 ~67 ~90 ~199 ~67 ~90 grass_block
fill ~200 ~60 ~90 ~201 ~64 ~90 stone
fill ~200 ~65 ~90 ~201 ~67 ~90 dirt
fill ~200 ~68 ~90 ~201 ~68 ~90 grass_block
fill ~202 ~60 ~90 ~204 ~65 ~90 stone
fill ~202 ~66 ~90 ~204 ~68 ~90 dirt
fill ~202 ~69 ~90 ~204 ~69 ~90 grass_block
fill ~205 ~60 ~90 ~207 ~66 ~90 stone
fill ~205 ~67 ~90 ~207 ~69 ~90 dirt
fill ~205 ~70 ~90 ~207 ~70 ~90 grass_block
fill ~192 ~60 ~91 ~195 ~63 ~91 stone
fill ~192 ~64 ~91 ~195 ~66 ~91 dirt
fill ~192 ~67 ~91 ~195 ~67 ~91 grass_block
fill ~196 ~60 ~91 ~197 ~64 ~91 stone
fill ~196 ~65 ~91 ~197 ~67 ~91 dirt
fill ~196 ~68 ~91 ~197 ~68 ~91 grass_block
fill ~198 ~60 ~91 ~199 ~63 ~91 stone
fill ~198 ~64 ~91 ~199 ~66 ~91 dirt
fill ~198 ~67 ~91 ~199 ~67 ~91 grass_block
fill ~200 ~60 ~91 ~201 ~64 ~91 stone
fill ~200 ~65 ~91 ~201 ~67 ~91 dirt
fill ~200 ~68 ~91 ~201 ~68 ~91 grass_block
fill ~202 ~60 ~91 ~204 ~65 ~91 stone
fill ~202 ~66 ~91 ~204 ~68 ~91 dirt
fill ~202 ~69 ~91 ~204 ~69 ~91 grass_block
fill ~205 ~60 ~91 ~207 ~66 ~91 stone
fill ~205 ~67 ~91 ~207 ~69 ~91 dirt
fill ~205 ~70 ~91 ~207 ~70 ~91 grass_block
fill ~192 ~60 ~92 ~194 ~63 ~92 stone
fill ~192 ~64 ~92 ~194 ~66 ~92 dirt
fill ~192 ~67 ~92 ~194 ~67 ~92 grass_block
fill ~195 ~60 ~92 ~200 ~64 ~92 stone
fill ~195 ~65 ~92 ~200 ~67 ~92 dirt
fill ~195 ~68 ~92 ~200 ~68 ~92 grass_block
fill ~201 ~60 ~92 ~202 ~65 ~92 stone
fill ~201 ~66 ~92 ~202 ~68 ~92 dirt
fill ~201 ~69 ~92 ~202 ~69 ~92 grass_block
fill ~203 ~60 ~92 ~207 ~66 ~92 stone
fill ~203 ~67 ~92 ~207 ~69 ~92 dirt
fill ~203 ~70 ~92 ~207 ~70 ~92 grass_block
fill ~192 ~60 ~93 ~193 ~63 ~93 stone
fill ~192 ~64 ~93 ~193 ~66 ~93 dirt
fill ~192 ~67 ~93 ~193 ~67 ~93 grass_block
fill ~194 ~60 ~93 ~197 ~64 ~93 stone
fill ~194 ~65 ~93 ~197 ~67 ~93 dirt
fill ~194 ~68 ~93 ~197 ~68 ~93 grass_block
fill ~198 ~60 ~93 ~201 ~65 ~93 stone
fill ~198 ~66 ~93 ~201 ~68 ~93 dirt
fill ~198 ~69 ~93 ~201 ~69 ~93 grass_block
fill ~202 ~60 ~93 ~207 ~66 ~93 stone
fill ~202 ~67 ~93 ~207 ~69 ~93 dirt
fill ~202 ~70 ~93 ~207 ~70 ~93 grass_block
fill ~192 ~60 ~94 ~193 ~63 ~94 stone
fill ~192 ~64 ~94 ~193 ~66 ~94 dirt
fill ~192 ~67 ~94 ~193 ~67 ~94 grass_block
fill ~194 ~60 ~94 ~197 ~64 ~94 stone
fill ~194 ~65 ~94 ~197 ~67 ~94 dirt
fill ~194 ~68 ~94 ~197 ~68 ~94 grass_block
fill ~198 ~60 ~94 ~202 ~65 ~94 stone
fill ~198 ~66 ~94 ~202 ~68 ~94 dirt
fill ~198 ~69 ~94 ~202 ~69 ~94 grass_block
fill ~203 ~60 ~94 ~207 ~66 ~94 stone
fill ~203 ~67 ~94 ~207 ~69 ~94 dirt
fill ~203 ~70 ~94 ~207 ~70 ~94 grass_block
fill ~192 ~60 ~95 ~195 ~63 ~95 stone
fill ~192 ~64 ~95 ~195 ~66 ~95 dirt
fill ~192 ~67 ~95 ~195 ~67 ~95 grass_block
fill ~196 ~60 ~95 ~197 ~64 ~95 stone
fill ~196 ~65 ~95 ~197 ~67 ~95 dirt
fill ~196 ~68 ~95 ~197 ~68 ~95 grass_block
fill ~198 ~60 ~95 ~200 ~65 ~95 stone
fill ~198 ~66 ~95 ~200 ~68 ~95 dirt
fill ~198 ~69 ~95 ~200 ~69 ~95 grass_block
fill ~201 ~60 ~95 ~207 ~66 ~95 stone
fill ~201 ~67 ~95 ~207 ~69 ~95 dirt
fill ~201 ~70 ~95 ~207 ~70 ~95 grass_block