fill ~48 ~60 ~0 ~49 ~67 ~0 stone
fill ~48 ~68 ~0 ~49 ~70 ~0 dirt
fill ~48 ~71 ~0 ~49 ~71 ~0 grass_block
fill ~50 ~60 ~0 ~52 ~68 ~0 stone
fill ~50 ~69 ~0 ~52 ~71 ~0 dirt
fill ~50 ~72 ~0 ~52 ~72 ~0 grass_block
fill ~53 ~60 ~0 ~56 ~67 ~0 stone
fill ~53 ~68 ~0 ~56 ~70 ~0 dirt
fill ~53 ~71 ~0 ~56 ~71 ~0 grass_block
fill ~57 ~60 ~0 ~58 ~68 ~0 stone
fill ~57 ~69 ~0 ~58 ~71 ~0 dirt
fill ~57 ~72 ~0 ~58 ~72 ~0 grass_block
fill ~59 ~60 ~0 ~61 ~67 ~0 stone
fill ~59 ~68 ~0 ~61 ~70 ~0 dirt
fill ~59 ~71 ~0 ~61 ~71 ~0 grass_block
fill ~62 ~60 ~0 ~63 ~68 ~0 stone
fill ~62 ~69 ~0 ~63 ~71 ~0 dirt
fill ~62 ~72 ~0 ~63 ~72 ~0 grass_block
fill ~48 ~60 ~1 ~48 ~66 ~1 stone
fill ~48 ~67 ~1 ~48 ~69 ~1 dirt
fill ~48 ~70 ~1 ~48 ~70 ~1 grass_block
fill ~49 ~60 ~1 ~51 ~67 ~1 stone
fill ~49 ~68 ~1 ~51 ~70 ~1 dirt
fill ~49 ~71 ~1 ~51 ~71 ~1 grass_block
fill ~52 ~60 ~1 ~52 ~68 ~1 stone
fill ~52 ~69 ~1 ~52 ~71 ~1 dirt
fill ~52 ~72 ~1 ~52 ~72 ~1 grass_block
fill ~53 ~60 ~1 ~63 ~67 ~1 stone
fill ~53 ~68 ~1 ~63 ~70 ~1 dirt
fill ~53 ~71 ~1 ~63 ~71 ~1 grass_block
fill ~48 ~60 ~2 ~50 ~66 ~2 stone
fill ~48 ~67 ~2 ~50 ~69 ~2 dirt
fill ~48 ~70 ~2 ~50 ~70 ~2 grass_block
fill ~51 ~60 ~2 ~54 ~67 ~2 stone
fill ~51 ~68 ~2 ~54 ~70 ~2 dirt
fill ~51 ~71 ~2 ~54 ~71 ~2 grass_block
fill ~55 ~60 ~2 ~58 ~66 ~2 stone
fill ~55 ~67 ~2 ~58 ~69 ~2 dirt
fill ~55 ~70 ~2 ~58 ~70 ~2 grass_block
fill ~59 ~60 ~2 ~59 ~67 ~2 stone
fill ~59 ~68 ~2 ~59 ~70 ~2 dirt
fill ~59 ~71 ~2 ~59 ~71 ~2 grass_block
fill ~60 ~60 ~2 ~61 ~66 ~2 stone
fill ~60 ~67 ~2 ~61 ~69 ~2 dirt
fill ~60 ~70 ~2 ~61 ~70 ~2 grass_block
fill ~62 ~60 ~2 ~63 ~67 ~2 stone
fill ~62 ~68 ~2 ~63 ~70 ~2 dirt
fill ~62 ~71 ~2 ~63 ~71 ~2 grass_block
fill ~48 ~60 ~3 ~52 ~66 ~3 stone
fill ~48 ~67 ~3 ~52 ~69 ~3 dirt
fill ~48 ~70 ~3 ~52 ~70 ~3 grass_block
fill ~53 ~60 ~3 ~54 ~67 ~3 stone
fill ~53 ~68 ~3 ~54 ~70 ~3 dirt
fill ~53 ~71 ~3 ~54 ~71 ~3 grass_block
fill ~55 ~60 ~3 ~62 ~66 ~3 stone
fill ~55 ~67 ~3 ~62 ~69 ~3 dirt
fill ~55 ~70 ~3 ~62 ~70 ~3 grass_block
fill ~63 ~60 ~3 ~63 ~67 ~3 stone
fill ~63 ~68 ~3 ~63 ~70 ~3 dirt
fill ~63 ~71 ~3 ~63 ~71 ~3 grass_block
fill ~48 ~60 ~4 ~51 ~65 ~4 stone
fill ~48 ~66 ~4 ~51 ~68 ~4 dirt
fill ~48 ~69 ~4 ~51 ~69 ~4 grass_block
fill ~52 ~60 ~4 ~58 ~66 ~4 stone
fill ~52 ~67 ~4 ~58 ~69 ~4 dirt
fill ~52 ~70 ~4 ~58 ~70 ~4 grass_block
fill ~59 ~60 ~4 ~60 ~65 ~4 stone
fill ~59 ~66 ~4 ~60 ~68 ~4 dirt
fill ~59 ~69 ~4 ~60 ~69 ~4 grass_block
fill ~61 ~60 ~4 ~63 ~66 ~4 stone
fill ~61 ~67 ~4 ~63 ~69 ~4 dirt
fill ~61 ~70 ~4 ~63 ~70 ~4 grass_block
fill ~48 ~60 ~5 ~52 ~65 ~5 stone
fill ~48 ~66 ~5 ~52 ~68 ~5 dirt
fill ~48 ~69 ~5 ~52 ~69 ~5 grass_block
fill ~53 ~60 ~5 ~59 ~66 ~5 stone
fill ~53 ~67 ~5 ~59 ~69 ~5 dirt
fill ~53 ~70 ~5 ~59 ~70 ~5 grass_block
fill ~60 ~60 ~5 ~62 ~65 ~5 stone
fill ~60 ~66 ~5 ~62 ~68 ~5 dirt
fill ~60 ~69 ~5 ~62 ~69 ~5 grass_block
fill ~63 ~60 ~5 ~63 ~66 ~5 stone
fill ~63 ~67 ~5 ~63 ~69 ~5 dirt
fill ~63 ~70 ~5 ~63 ~70 ~5 grass_block
fill ~48 ~60 ~6 ~50 ~64 ~6 stone
fill ~48 ~65 ~6 ~50 ~67 ~6 dirt
fill ~48 ~68 ~6 ~50 ~68 ~6 grass_block
fill ~51 ~60 ~6 ~53 ~65 ~6 stone
fill ~51 ~66 ~6 ~53 ~68 ~6 dirt
fill ~51 ~69 ~6 ~53 ~69 ~6 grass_block
fill ~54 ~60 ~6 ~54 ~66 ~6 stone
fill ~54 ~67 ~6 ~54 ~69 ~6 dirt
fill ~54 ~70 ~6 ~54 ~70 ~6 grass_block
fill ~55 ~60 ~6 ~56 ~67 ~6 stone
fill ~55 ~68 ~6 ~56 ~70 ~6 dirt
fill ~55 ~71 ~6 ~56 ~71 ~6 grass_block
fill ~57 ~60 ~6 ~59 ~66 ~6 stone
fill ~57 ~67 ~6 ~59 ~69 ~6 dirt
fill ~57 ~70 ~6 ~59 ~70 ~6 grass_block
fill ~60 ~60 ~6 ~63 ~65 ~6 stone
fill ~60 ~66 ~6 ~63 ~68 ~6 dirt
fill ~60 ~69 ~6 ~63 ~69 ~6 grass_block
fill ~48 ~60 ~7 ~50 ~64 ~7 stone
fill ~48 ~65 ~7 ~50 ~67 ~7 dirt
fill ~48 ~68 ~7 ~50 ~68 ~7 grass_block
fill ~51 ~60 ~7 ~52 ~65 ~7 stone
fill ~51 ~66 ~7 ~52 ~68 ~7 dirt
fill ~51 ~69 ~7 ~52 ~69 ~7 grass_block
fill ~53 ~60 ~7 ~55 ~66 ~7 stone
fill ~53 ~67 ~7 ~55 ~69 ~7 dirt
fill ~53 ~70 ~7 ~55 ~70 ~7 grass_block
fill ~56 ~60 ~7 ~57 ~67 ~7 stone
fill ~56 ~68 ~7 ~57 ~70 ~7 dirt
fill ~56 ~71 ~7 ~57 ~71 ~7 grass_block
fill ~58 ~60 ~7 ~59 ~66 ~7 stone
fill ~58 ~67 ~7 ~59 ~69 ~7 dirt
fill ~58 ~70 ~7 ~59 ~70 ~7 grass_block
fill ~60 ~60 ~7 ~63 ~65 ~7 stone
fill ~60 ~66 ~7 ~63 ~68 ~7 dirt
fill ~60 ~69 ~7 ~63 ~69 ~7 grass_block
fill ~48 ~60 ~8 ~50 ~64 ~8 stone
fill ~48 ~65 ~8 ~50 ~67 ~8 dirt
fill ~48 ~68 ~8 ~50 ~68 ~8 grass_block
fill ~51 ~60 ~8 ~53 ~65 ~8 stone
fill ~51 ~66 ~8 ~53 ~68 ~8 dirt
fill ~51 ~69 ~8 ~53 ~69 ~8 grass_block
fill ~54 ~60 ~8 ~56 ~66 ~8 stone
fill ~54 ~67 ~8 ~56 ~69 ~8 dirt
fill ~54 ~70 ~8 ~56 ~70 ~8 grass_block
fill ~57 ~60 ~8 ~58 ~67 ~8 stone
fill ~57 ~68 ~8 ~58 ~70 ~8 dirt
fill ~57 ~71 ~8 ~58 ~71 ~8 grass_block
fill ~59 ~60 ~8 ~60 ~66 ~8 stone
fill ~59 ~67 ~8 ~60 ~69 ~8 dirt
fill ~59 ~70 ~8 ~60 ~70 ~8 grass_block
fill ~61 ~60 ~8 ~63 ~65 ~8 stone
fill ~61 ~66 ~8 ~63 ~68 ~8 dirt
fill ~61 ~69 ~8 ~63 ~69 ~8 grass_block
fill ~48 ~60 ~9 ~48 ~63 ~9 stone
fill ~48 ~64 ~9 ~48 ~66 ~9 dirt
fill ~48 ~67 ~9 ~48 ~67 ~9 grass_block
fill ~49 ~60 ~9 ~52 ~64 ~9 stone
fill ~49 ~65 ~9 ~52 ~67 ~9 dirt
fill ~49 ~68 ~9 ~52 ~68 ~9 grass_block
fill ~53 ~60 ~9 ~56 ~65 ~9 stone
fill ~53 ~66 ~9 ~56 ~68 ~9 dirt
fill ~53 ~69 ~9 ~56 ~69 ~9 grass_block
fill ~57 ~60 ~9 ~57 ~66 ~9 stone
fill ~57 ~67 ~9 ~57 ~69 ~9 dirt
fill ~57 ~70 ~9 ~57 ~70 ~9 grass_block
fill ~58 ~60 ~9 ~58 ~67 ~9 stone
fill ~58 ~68 ~9 ~58 ~70 ~9 dirt
fill ~58 ~71 ~9 ~58 ~71 ~9 grass_block
fill ~59 ~60 ~9 ~61 ~66 ~9 stone
fill ~59 ~67 ~9 ~61 ~69 ~9 dirt
fill ~59 ~70 ~9 ~61 ~70 ~9 grass_block
fill ~62 ~60 ~9 ~63 ~65 ~9 stone
fill ~62 ~66 ~9 ~63 ~68 ~9 dirt
fill ~62 ~69 ~9 ~63 ~69 ~9 grass_block
fill ~48 ~60 ~10 ~49 ~63 ~10 stone
fill ~48 ~64 ~10 ~49 ~66 ~10 dirt
fill ~48 ~67 ~10 ~49 ~67 ~10 grass_block
fill ~50 ~60 ~10 ~54 ~64 ~10 stone
fill ~50 ~65 ~10 ~54 ~67 ~10 dirt
fill ~50 ~68 ~10 ~54 ~68 ~10 grass_block
fill ~55 ~60 ~10 ~56 ~65 ~10 stone
fill ~55 ~66 ~10 ~56 ~68 ~10 dirt
fill ~55 ~69 ~10 ~56 ~69 ~10 grass_block
fill ~57 ~60 ~10 ~61 ~66 ~10 stone
fill ~57 ~67 ~10 ~61 ~69 ~10 dirt
fill ~57 ~70 ~10 ~61 ~70 ~10 grass_block
fill ~62 ~60 ~10 ~63 ~65 ~10 stone
fill ~62 ~66 ~10 ~63 ~68 ~10 dirt
fill ~62 ~69 ~10 ~63 ~69 ~10 grass_block
fill ~48 ~60 ~11 ~52 ~63 ~11 stone
fill ~48 ~64 ~11 ~52 ~66 ~11 dirt
fill ~48 ~67 ~11 ~52 ~67 ~11 grass_block
fill ~53 ~60 ~11 ~54 ~64 ~11 stone
fill ~53 ~65 ~11 ~54 ~67 ~11 dirt
fill ~53 ~68 ~11 ~54 ~68 ~11 grass_block
fill ~55 ~60 ~11 ~57 ~65 ~11 stone
fill ~55 ~66 ~11 ~57 ~68 ~11 dirt
fill ~55 ~69 ~11 ~57 ~69 ~11 grass_block
fill ~58 ~60 ~11 ~61 ~66 ~11 stone
fill ~58 ~67 ~11 ~61 ~69 ~11 dirt
fill ~58 ~70 ~11 ~61 ~70 ~11 grass_block
fill ~62 ~60 ~11 ~63 ~65 ~11 stone
fill ~62 ~66 ~11 ~63 ~68 ~11 dirt
fill ~62 ~69 ~11 ~63 ~69 ~11 grass_block
fill ~48 ~60 ~12 ~53 ~63 ~12 stone
fill ~48 ~64 ~12 ~53 ~66 ~12 dirt
fill ~48 ~67 ~12 ~53 ~67 ~12 grass_block
fill ~54 ~60 ~12 ~55 ~64 ~12 stone
fill ~54 ~65 ~12 ~55 ~67 ~12 dirt
fill ~54 ~68 ~12 ~55 ~68 ~12 grass_block
fill ~56 ~60 ~12 ~58 ~65 ~12 stone
fill ~56 ~66 ~12 ~58 ~68 ~12 dirt
fill ~56 ~69 ~12 ~58 ~69 ~12 grass_block
fill ~59 ~60 ~12 ~61 ~66 ~12 stone
fill ~59 ~67 ~12 ~61 ~69 ~12 dirt
fill ~59 ~70 ~12 ~61 ~70 ~12 grass_block
fill ~62 ~60 ~12 ~63 ~65 ~12 stone
fill ~62 ~66 ~12 ~63 ~68 ~12 dirt
fill ~62 ~69 ~12 ~63 ~69 ~12 grass_block
fill ~48 ~60 ~13 ~48 ~64 ~13 stone
fill ~48 ~65 ~13 ~48 ~67 ~13 dirt
fill ~48 ~68 ~13 ~48 ~68 ~13 grass_block
fill ~49 ~60 ~13 ~53 ~63 ~13 stone
fill ~49 ~64 ~13 ~53 ~66 ~13 dirt
fill ~49 ~67 ~13 ~53 ~67 ~13 grass_block
fill ~54 ~60 ~13 ~56 ~64 ~13 stone
fill ~54 ~65 ~13 ~56 ~67 ~13 dirt
fill ~54 ~68 ~13 ~56 ~68 ~13 grass_block
fill ~57 ~60 ~13 ~59 ~65 ~13 stone
fill ~57 ~66 ~13 ~59 ~68 ~13 dirt
fill ~57 ~69 ~13 ~59 ~69 ~13 grass_block
fill ~60 ~60 ~13 ~61 ~66 ~13 stone
fill ~60 ~67 ~13 ~61 ~69 ~13 dirt
fill ~60 ~70 ~13 ~61 ~70 ~13 grass_block
fill ~62 ~60 ~13 ~63 ~65 ~13 stone
fill ~62 ~66 ~13 ~63 ~68 ~13 dirt
fill ~62 ~69 ~13 ~63 ~69 ~13 grass_block
fill ~48 ~60 ~14 ~48 ~64 ~14 stone
fill ~48 ~65 ~14 ~48 ~67 ~14 dirt
fill ~48 ~68 ~14 ~48 ~68 ~14 grass_block
fill ~49 ~60 ~14 ~53 ~63 ~14 stone
fill ~49 ~64 ~14 ~53 ~66 ~14 dirt
fill ~49 ~67 ~14 ~53 ~67 ~14 grass_block
fill ~54 ~60 ~14 ~57 ~64 ~14 stone
fill ~54 ~65 ~14 ~57 ~67 ~14 dirt
fill ~54 ~68 ~14 ~57 ~68 ~14 grass_block
fill ~58 ~60 ~14 ~63 ~65 ~14 stone
fill ~58 ~66 ~14 ~63 ~68 ~14 dirt
fill ~58 ~69 ~14 ~63 ~69 ~14 grass_block
fill ~48 ~60 ~15 ~49 ~64 ~15 stone
fill ~48 ~65 ~15 ~49 ~67 ~15 dirt
fill ~48 ~68 ~15 ~49 ~68 ~15 grass_block
fill ~50 ~60 ~15 ~54 ~63 ~15 stone
fill ~50 ~64 ~15 ~54 ~66 ~15 dirt
fill ~50 ~67 ~15 ~54 ~67 ~15 grass_block
fill ~55 ~60 ~15 ~58 ~64 ~15 stone
fill ~55 ~65 ~15 ~58 ~67 ~15 dirt
fill ~55 ~68 ~15 ~58 ~68 ~15 grass_block
fill ~59 ~60 ~15 ~63 ~65 ~15 stone
fill ~59 ~66 ~15 ~63 ~68 ~15 dirt
fill ~59 ~69 ~15 ~63 ~69 ~15 grass_block