fill ~128 ~60 ~96 ~143 ~62 ~96 stone
fill ~128 ~63 ~96 ~143 ~65 ~96 dirt
fill ~128 ~66 ~96 ~143 ~66 ~96 grass_block
fill ~128 ~60 ~97 ~143 ~62 ~97 stone
fill ~128 ~63 ~97 ~143 ~65 ~97 dirt
fill ~128 ~66 ~97 ~143 ~66 ~97 grass_block
fill ~128 ~60 ~98 ~128 ~62 ~98 stone
fill ~128 ~63 ~98 ~128 ~65 ~98 dirt
fill ~128 ~66 ~98 ~128 ~66 ~98 grass_block
fill ~129 ~60 ~98 ~129 ~63 ~98 stone
fill ~129 ~64 ~98 ~129 ~66 ~98 dirt
fill ~129 ~67 ~98 ~129 ~67 ~98 grass_block
fill ~130 ~60 ~98 ~130 ~62 ~98 stone
fill ~130 ~63 ~98 ~130 ~65 ~98 dirt
fill ~130 ~66 ~98 ~130 ~66 ~98 grass_block
fill ~131 ~60 ~98 ~131 ~63 ~98 stone
fill ~131 ~64 ~98 ~131 ~66 ~98 dirt
fill ~131 ~67 ~98 ~131 ~67 ~98 grass_block
fill ~132 ~60 ~98 ~143 ~62 ~98 stone
fill ~132 ~63 ~98 ~143 ~65 ~98 dirt
fill ~132 ~66 ~98 ~143 ~66 ~98 grass_block
fill ~128 ~60 ~99 ~143 ~62 ~99 stone
fill ~128 ~63 ~99 ~143 ~65 ~99 dirt
fill ~128 ~66 ~99 ~143 ~66 ~99 grass_block
fill ~128 ~60 ~100 ~143 ~62 ~100 stone
fill ~128 ~63 ~100 ~143 ~65 ~100 dirt
fill ~128 ~66 ~100 ~143 ~66 ~100 grass_block
fill ~128 ~60 ~101 ~130 ~63 ~101 stone
fill ~128 ~64 ~101 ~130 ~66 ~101 dirt
fill ~128 ~67 ~101 ~130 ~67 ~101 grass_block
fill ~131 ~60 ~101 ~143 ~62 ~101 stone
fill ~131 ~63 ~101 ~143 ~65 ~101 dirt
fill ~131 ~66 ~101 ~143 ~66 ~101 grass_block
fill ~128 ~60 ~102 ~132 ~63 ~102 stone
fill ~128 ~64 ~102 ~132 ~66 ~102 dirt
fill ~128 ~67 ~102 ~132 ~67 ~102 grass_block
fill ~133 ~60 ~102 ~143 ~62 ~102 stone
fill ~133 ~63 ~102 ~143 ~65 ~102 dirt
fill ~133 ~66 ~102 ~143 ~66 ~102 grass_block
fill ~128 ~60 ~103 ~129 ~64 ~103 stone
fill ~128 ~65 ~103 ~129 ~67 ~103 dirt
fill ~128 ~68 ~103 ~129 ~68 ~103 grass_block
fill ~130 ~60 ~103 ~134 ~63 ~103 stone
fill ~130 ~64 ~103 ~134 ~66 ~103 dirt
fill ~130 ~67 ~103 ~134 ~67 ~103 grass_block
fill ~135 ~60 ~103 ~143 ~62 ~103 stone
fill ~135 ~63 ~103 ~143 ~65 ~103 dirt
fill ~135 ~66 ~103 ~143 ~66 ~103 grass_block
fill ~128 ~60 ~104 ~131 ~64 ~104 stone
fill ~128 ~65 ~104 ~131 ~67 ~104 dirt
fill ~128 ~68 ~104 ~131 ~68 ~104 grass_block
fill ~132 ~60 ~104 ~136 ~63 ~104 stone
fill ~132 ~64 ~104 ~136 ~66 ~104 dirt
fill ~132 ~67 ~104 ~136 ~67 ~104 grass_block
fill ~137 ~60 ~104 ~139 ~62 ~104 stone
fill ~137 ~63 ~104 ~139 ~65 ~104 dirt
fill ~137 ~66 ~104 ~139 ~66 ~104 grass_block
fill ~140 ~60 ~104 ~142 ~63 ~104 stone
fill ~140 ~64 ~104 ~142 ~66 ~104 dirt
fill ~140 ~67 ~104 ~142 ~67 ~104 grass_block
fill ~143 ~60 ~104 ~143 ~62 ~104 stone
fill ~143 ~63 ~104 ~143 ~65 ~104 dirt
fill ~143 ~66 ~104 ~143 ~66 ~104 grass_block
fill ~128 ~60 ~105 ~128 ~65 ~105 stone
fill ~128 ~66 ~105 ~128 ~68 ~105 dirt
fill ~128 ~69 ~105 ~128 ~69 ~105 grass_block
fill ~129 ~60 ~105 ~132 ~64 ~105 stone
fill ~129 ~65 ~105 ~132 ~67 ~105 dirt
fill ~129 ~68 ~105 ~132 ~68 ~105 grass_block
fill ~133 ~60 ~105 ~136 ~63 ~105 stone
fill ~133 ~64 ~105 ~136 ~66 ~105 dirt
fill ~133 ~67 ~105 ~136 ~67 ~105 grass_block
fill ~137 ~60 ~105 ~138 ~62 ~105 stone
fill ~137 ~63 ~105 ~138 ~65 ~105 dirt
fill ~137 ~66 ~105 ~138 ~66 ~105 grass_block
fill ~139 ~60 ~105 ~143 ~63 ~105 stone
fill ~139 ~64 ~105 ~143 ~66 ~105 dirt
fill ~139 ~67 ~105 ~143 ~67 ~105 grass_block
fill ~128 ~60 ~106 ~129 ~65 ~106 stone
fill ~128 ~66 ~106 ~129 ~68 ~106 dirt
fill ~128 ~69 ~106 ~129 ~69 ~106 grass_block
fill ~130 ~60 ~106 ~133 ~64 ~106 stone
fill ~130 ~65 ~106 ~133 ~67 ~106 dirt
fill ~130 ~68 ~106 ~133 ~68 ~106 grass_block
fill ~134 ~60 ~106 ~136 ~63 ~106 stone
fill ~134 ~64 ~106 ~136 ~66 ~106 dirt
fill ~134 ~67 ~106 ~136 ~67 ~106 grass_block
fill ~137 ~60 ~106 ~137 ~62 ~106 stone
fill ~137 ~63 ~106 ~137 ~65 ~106 dirt
fill ~137 ~66 ~106 ~137 ~66 ~106 grass_block
fill ~138 ~60 ~106 ~139 ~63 ~106 stone
fill ~138 ~64 ~106 ~139 ~66 ~106 dirt
fill ~138 ~67 ~106 ~139 ~67 ~106 grass_block
fill ~140 ~60 ~106 ~140 ~64 ~106 stone
fill ~140 ~65 ~106 ~140 ~67 ~106 dirt
fill ~140 ~68 ~106 ~140 ~68 ~106 grass_block
fill ~141 ~60 ~106 ~143 ~63 ~106 stone
fill ~141 ~64 ~106 ~143 ~66 ~106 dirt
fill ~141 ~67 ~106 ~143 ~67 ~106 grass_block
fill ~128 ~60 ~107 ~128 ~65 ~107 stone
fill ~128 ~66 ~107 ~128 ~68 ~107 dirt
fill ~128 ~69 ~107 ~128 ~69 ~107 grass_block
fill ~129 ~60 ~107 ~132 ~64 ~107 stone
fill ~129 ~65 ~107 ~132 ~67 ~107 dirt
fill ~129 ~68 ~107 ~132 ~68 ~107 grass_block
fill ~133 ~60 ~107 ~138 ~63 ~107 stone
fill ~133 ~64 ~107 ~138 ~66 ~107 dirt
fill ~133 ~67 ~107 ~138 ~67 ~107 grass_block
fill ~139 ~60 ~107 ~142 ~64 ~107 stone
fill ~139 ~65 ~107 ~142 ~67 ~107 dirt
fill ~139 ~68 ~107 ~142 ~68 ~107 grass_block
fill ~143 ~60 ~107 ~143 ~63 ~107 stone
fill ~143 ~64 ~107 ~143 ~66 ~107 dirt
fill ~143 ~67 ~107 ~143 ~67 ~107 grass_block
fill ~128 ~60 ~108 ~128 ~65 ~108 stone
fill ~128 ~66 ~108 ~128 ~68 ~108 dirt
fill ~128 ~69 ~108 ~128 ~69 ~108 grass_block
fill ~129 ~60 ~108 ~131 ~64 ~108 stone
fill ~129 ~65 ~108 ~131 ~67 ~108 dirt
fill ~129 ~68 ~108 ~131 ~68 ~108 grass_block
fill ~132 ~60 ~108 ~138 ~63 ~108 stone
fill ~132 ~64 ~108 ~138 ~66 ~108 dirt
fill ~132 ~67 ~108 ~138 ~67 ~108 grass_block
fill ~139 ~60 ~108 ~143 ~64 ~108 stone
fill ~139 ~65 ~108 ~143 ~67 ~108 dirt
fill ~139 ~68 ~108 ~143 ~68 ~108 grass_block
fill ~128 ~60 ~109 ~129 ~64 ~109 stone
fill ~128 ~65 ~109 ~129 ~67 ~109 dirt
fill ~128 ~68 ~109 ~129 ~68 ~109 grass_block
fill ~130 ~60 ~109 ~137 ~63 ~109 stone
fill ~130 ~64 ~109 ~137 ~66 ~109 dirt
fill ~130 ~67 ~109 ~137 ~67 ~109 grass_block
fill ~138 ~60 ~109 ~139 ~64 ~109 stone
fill ~138 ~65 ~109 ~139 ~67 ~109 dirt
fill ~138 ~68 ~109 ~139 ~68 ~109 grass_block
fill ~140 ~60 ~109 ~141 ~65 ~109 stone
fill ~140 ~66 ~109 ~141 ~68 ~109 dirt
fill ~140 ~69 ~109 ~141 ~69 ~109 grass_block
fill ~142 ~60 ~109 ~143 ~64 ~109 stone
fill ~142 ~65 ~109 ~143 ~67 ~109 dirt
fill ~142 ~68 ~109 ~143 ~68 ~109 grass_block
fill ~128 ~60 ~110 ~128 ~64 ~110 stone
fill ~128 ~65 ~110 ~128 ~67 ~110 dirt
fill ~128 ~68 ~110 ~128 ~68 ~110 grass_block
fill ~129 ~60 ~110 ~136 ~63 ~110 stone
fill ~129 ~64 ~110 ~136 ~66 ~110 dirt
fill ~129 ~67 ~110 ~136 ~67 ~110 grass_block
fill ~137 ~60 ~110 ~138 ~64 ~110 stone
fill ~137 ~65 ~110 ~138 ~67 ~110 dirt
fill ~137 ~68 ~110 ~138 ~68 ~110 grass_block
fill ~139 ~60 ~110 ~143 ~65 ~110 stone
fill ~139 ~66 ~110 ~143 ~68 ~110 dirt
fill ~139 ~69 ~110 ~143 ~69 ~110 grass_block
fill ~128 ~60 ~111 ~133 ~64 ~111 stone
fill ~128 ~65 ~111 ~133 ~67 ~111 dirt
fill ~128 ~68 ~111 ~133 ~68 ~111 grass_block
fill ~134 ~60 ~111 ~135 ~63 ~111 stone
fill ~134 ~64 ~111 ~135 ~66 ~111 dirt
fill ~134 ~67 ~111 ~135 ~67 ~111 grass_block
fill ~136 ~60 ~111 ~137 ~64 ~111 stone
fill ~136 ~65 ~111 ~137 ~67 ~111 dirt
fill ~136 ~68 ~111 ~137 ~68 ~111 grass_block
fill ~138 ~60 ~111 ~143 ~65 ~111 stone
fill ~138 ~66 ~111 ~143 ~68 ~111 dirt
fill ~138 ~69 ~111 ~143 ~69 ~111 grass_block