fill ~112 ~60 ~32 ~113 ~67 ~32 stone
fill ~112 ~68 ~32 ~113 ~70 ~32 dirt
fill ~112 ~71 ~32 ~113 ~71 ~32 grass_block
fill ~114 ~60 ~32 ~115 ~68 ~32 stone
fill ~114 ~69 ~32 ~115 ~71 ~32 dirt
fill ~114 ~72 ~32 ~115 ~72 ~32 grass_block
fill ~116 ~60 ~32 ~117 ~67 ~32 stone
fill ~116 ~68 ~32 ~117 ~70 ~32 dirt
fill ~116 ~71 ~32 ~117 ~71 ~32 grass_block
fill ~118 ~60 ~32 ~127 ~68 ~32 stone
fill ~118 ~69 ~32 ~127 ~71 ~32 dirt
fill ~118 ~72 ~32 ~127 ~72 ~32 grass_block
fill ~112 ~60 ~33 ~112 ~66 ~33 stone
fill ~112 ~67 ~33 ~112 ~69 ~33 dirt
fill ~112 ~70 ~33 ~112 ~70 ~33 grass_block
fill ~113 ~60 ~33 ~113 ~67 ~33 stone
fill ~113 ~68 ~33 ~113 ~70 ~33 dirt
fill ~113 ~71 ~33 ~113 ~71 ~33 grass_block
fill ~114 ~60 ~33 ~115 ~68 ~33 stone
fill ~114 ~69 ~33 ~115 ~71 ~33 dirt
fill ~114 ~72 ~33 ~115 ~72 ~33 grass_block
fill ~116 ~60 ~33 ~119 ~67 ~33 stone
fill ~116 ~68 ~33 ~119 ~70 ~33 dirt
fill ~116 ~71 ~33 ~119 ~71 ~33 grass_block
fill ~120 ~60 ~33 ~127 ~68 ~33 stone
fill ~120 ~69 ~33 ~127 ~71 ~33 dirt
fill ~120 ~72 ~33 ~127 ~72 ~33 grass_block
fill ~112 ~60 ~34 ~112 ~66 ~34 stone
fill ~112 ~67 ~34 ~112 ~69 ~34 dirt
fill ~112 ~70 ~34 ~112 ~70 ~34 grass_block
fill ~113 ~60 ~34 ~114 ~67 ~34 stone
fill ~113 ~68 ~34 ~114 ~70 ~34 dirt
fill ~113 ~71 ~34 ~114 ~71 ~34 grass_block
fill ~115 ~60 ~34 ~116 ~68 ~34 stone
fill ~115 ~69 ~34 ~116 ~71 ~34 dirt
fill ~115 ~72 ~34 ~116 ~72 ~34 grass_block
fill ~117 ~60 ~34 ~122 ~67 ~34 stone
fill ~117 ~68 ~34 ~122 ~70 ~34 dirt
fill ~117 ~71 ~34 ~122 ~71 ~34 grass_block
fill ~123 ~60 ~34 ~127 ~68 ~34 stone
fill ~123 ~69 ~34 ~127 ~71 ~34 dirt
fill ~123 ~72 ~34 ~127 ~72 ~34 grass_block
fill ~112 ~60 ~35 ~113 ~66 ~35 stone
fill ~112 ~67 ~35 ~113 ~69 ~35 dirt
fill ~112 ~70 ~35 ~113 ~70 ~35 grass_block
fill ~114 ~60 ~35 ~114 ~67 ~35 stone
fill ~114 ~68 ~35 ~114 ~70 ~35 dirt
fill ~114 ~71 ~35 ~114 ~71 ~35 grass_block
fill ~115 ~60 ~35 ~116 ~68 ~35 stone
fill ~115 ~69 ~35 ~116 ~71 ~35 dirt
fill ~115 ~72 ~35 ~116 ~72 ~35 grass_block
fill ~117 ~60 ~35 ~122 ~67 ~35 stone
fill ~117 ~68 ~35 ~122 ~70 ~35 dirt
fill ~117 ~71 ~35 ~122 ~71 ~35 grass_block
fill ~123 ~60 ~35 ~127 ~68 ~35 stone
fill ~123 ~69 ~35 ~127 ~71 ~35 dirt
fill ~123 ~72 ~35 ~127 ~72 ~35 grass_block
fill ~112 ~60 ~36 ~113 ~66 ~36 stone
fill ~112 ~67 ~36 ~113 ~69 ~36 dirt
fill ~112 ~70 ~36 ~113 ~70 ~36 grass_block
fill ~114 ~60 ~36 ~115 ~67 ~36 stone
fill ~114 ~68 ~36 ~115 ~70 ~36 dirt
fill ~114 ~71 ~36 ~115 ~71 ~36 grass_block
fill ~116 ~60 ~36 ~116 ~68 ~36 stone
fill ~116 ~69 ~36 ~116 ~71 ~36 dirt
fill ~116 ~72 ~36 ~116 ~72 ~36 grass_block
fill ~117 ~60 ~36 ~125 ~67 ~36 stone
fill ~117 ~68 ~36 ~125 ~70 ~36 dirt
fill ~117 ~71 ~36 ~125 ~71 ~36 grass_block
fill ~126 ~60 ~36 ~127 ~68 ~36 stone
fill ~126 ~69 ~36 ~127 ~71 ~36 dirt
fill ~126 ~72 ~36 ~127 ~72 ~36 grass_block
fill ~112 ~60 ~37 ~112 ~65 ~37 stone
fill ~112 ~66 ~37 ~112 ~68 ~37 dirt
fill ~112 ~69 ~37 ~112 ~69 ~37 grass_block
fill ~113 ~60 ~37 ~113 ~66 ~37 stone
fill ~113 ~67 ~37 ~113 ~69 ~37 dirt
fill ~113 ~70 ~37 ~113 ~70 ~37 grass_block
fill ~114 ~60 ~37 ~115 ~67 ~37 stone
fill ~114 ~68 ~37 ~115 ~70 ~37 dirt
fill ~114 ~71 ~37 ~115 ~71 ~37 grass_block
fill ~116 ~60 ~37 ~116 ~68 ~37 stone
fill ~116 ~69 ~37 ~116 ~71 ~37 dirt
fill ~116 ~72 ~37 ~116 ~72 ~37 grass_block
fill ~117 ~60 ~37 ~120 ~67 ~37 stone
fill ~117 ~68 ~37 ~120 ~70 ~37 dirt
fill ~117 ~71 ~37 ~120 ~71 ~37 grass_block
fill ~121 ~60 ~37 ~121 ~66 ~37 stone
fill ~121 ~67 ~37 ~121 ~69 ~37 dirt
fill ~121 ~70 ~37 ~121 ~70 ~37 grass_block
fill ~122 ~60 ~37 ~125 ~67 ~37 stone
fill ~122 ~68 ~37 ~125 ~70 ~37 dirt
fill ~122 ~71 ~37 ~125 ~71 ~37 grass_block
fill ~126 ~60 ~37 ~127 ~68 ~37 stone
fill ~126 ~69 ~37 ~127 ~71 ~37 dirt
fill ~126 ~72 ~37 ~127 ~72 ~37 grass_block
fill ~112 ~60 ~38 ~113 ~66 ~38 stone
fill ~112 ~67 ~38 ~113 ~69 ~38 dirt
fill ~112 ~70 ~38 ~113 ~70 ~38 grass_block
fill ~114 ~60 ~38 ~115 ~67 ~38 stone
fill ~114 ~68 ~38 ~115 ~70 ~38 dirt
fill ~114 ~71 ~38 ~115 ~71 ~38 grass_block
fill ~116 ~60 ~38 ~117 ~68 ~38 stone
fill ~116 ~69 ~38 ~117 ~71 ~38 dirt
fill ~116 ~72 ~38 ~117 ~72 ~38 grass_block
fill ~118 ~60 ~38 ~120 ~67 ~38 stone
fill ~118 ~68 ~38 ~120 ~70 ~38 dirt
fill ~118 ~71 ~38 ~120 ~71 ~38 grass_block
fill ~121 ~60 ~38 ~122 ~66 ~38 stone
fill ~121 ~67 ~38 ~122 ~69 ~38 dirt
fill ~121 ~70 ~38 ~122 ~70 ~38 grass_block
fill ~123 ~60 ~38 ~126 ~67 ~38 stone
fill ~123 ~68 ~38 ~126 ~70 ~38 dirt
fill ~123 ~71 ~38 ~126 ~71 ~38 grass_block
fill ~127 ~60 ~38 ~127 ~68 ~38 stone
fill ~127 ~69 ~38 ~127 ~71 ~38 dirt
fill ~127 ~72 ~38 ~127 ~72 ~38 grass_block
fill ~112 ~60 ~39 ~112 ~66 ~39 stone
fill ~112 ~67 ~39 ~112 ~69 ~39 dirt
fill ~112 ~70 ~39 ~112 ~70 ~39 grass_block
fill ~113 ~60 ~39 ~114 ~67 ~39 stone
fill ~113 ~68 ~39 ~114 ~70 ~39 dirt
fill ~113 ~71 ~39 ~114 ~71 ~39 grass_block
fill ~115 ~60 ~39 ~117 ~68 ~39 stone
fill ~115 ~69 ~39 ~117 ~71 ~39 dirt
fill ~115 ~72 ~39 ~117 ~72 ~39 grass_block
fill ~118 ~60 ~39 ~121 ~67 ~39 stone
fill ~118 ~68 ~39 ~121 ~70 ~39 dirt
fill ~118 ~71 ~39 ~121 ~71 ~39 grass_block
fill ~122 ~60 ~39 ~124 ~66 ~39 stone
fill ~122 ~67 ~39 ~124 ~69 ~39 dirt
fill ~122 ~70 ~39 ~124 ~70 ~39 grass_block
fill ~125 ~60 ~39 ~127 ~67 ~39 stone
fill ~125 ~68 ~39 ~127 ~70 ~39 dirt
fill ~125 ~71 ~39 ~127 ~71 ~39 grass_block
fill ~112 ~60 ~40 ~112 ~66 ~40 stone
fill ~112 ~67 ~40 ~112 ~69 ~40 dirt
fill ~112 ~70 ~40 ~112 ~70 ~40 grass_block
fill ~113 ~60 ~40 ~117 ~67 ~40 stone
fill ~113 ~68 ~40 ~117 ~70 ~40 dirt
fill ~113 ~71 ~40 ~117 ~71 ~40 grass_block
fill ~118 ~60 ~40 ~118 ~68 ~40 stone
fill ~118 ~69 ~40 ~118 ~71 ~40 dirt
fill ~118 ~72 ~40 ~118 ~72 ~40 grass_block
fill ~119 ~60 ~40 ~122 ~67 ~40 stone
fill ~119 ~68 ~40 ~122 ~70 ~40 dirt
fill ~119 ~71 ~40 ~122 ~71 ~40 grass_block
fill ~123 ~60 ~40 ~124 ~66 ~40 stone
fill ~123 ~67 ~40 ~124 ~69 ~40 dirt
fill ~123 ~70 ~40 ~124 ~70 ~40 grass_block
fill ~125 ~60 ~40 ~127 ~67 ~40 stone
fill ~125 ~68 ~40 ~127 ~70 ~40 dirt
fill ~125 ~71 ~40 ~127 ~71 ~40 grass_block
fill ~112 ~60 ~41 ~113 ~66 ~41 stone
fill ~112 ~67 ~41 ~113 ~69 ~41 dirt
fill ~112 ~70 ~41 ~113 ~70 ~41 grass_block
fill ~114 ~60 ~41 ~117 ~67 ~41 stone
fill ~114 ~68 ~41 ~117 ~70 ~41 dirt
fill ~114 ~71 ~41 ~117 ~71 ~41 grass_block
fill ~118 ~60 ~41 ~120 ~68 ~41 stone
fill ~118 ~69 ~41 ~120 ~71 ~41 dirt
fill ~118 ~72 ~41 ~120 ~72 ~41 grass_block
fill ~121 ~60 ~41 ~123 ~67 ~41 stone
fill ~121 ~68 ~41 ~123 ~70 ~41 dirt
fill ~121 ~71 ~41 ~123 ~71 ~41 grass_block
fill ~124 ~60 ~41 ~126 ~66 ~41 stone
fill ~124 ~67 ~41 ~126 ~69 ~41 dirt
fill ~124 ~70 ~41 ~126 ~70 ~41 grass_block
fill ~127 ~60 ~41 ~127 ~67 ~41 stone
fill ~127 ~68 ~41 ~127 ~70 ~41 dirt
fill ~127 ~71 ~41 ~127 ~71 ~41 grass_block
fill ~112 ~60 ~42 ~114 ~66 ~42 stone
fill ~112 ~67 ~42 ~114 ~69 ~42 dirt
fill ~112 ~70 ~42 ~114 ~70 ~42 grass_block
fill ~115 ~60 ~42 ~116 ~67 ~42 stone
fill ~115 ~68 ~42 ~116 ~70 ~42 dirt
fill ~115 ~71 ~42 ~116 ~71 ~42 grass_block
fill ~117 ~60 ~42 ~120 ~68 ~42 stone
fill ~117 ~69 ~42 ~120 ~71 ~42 dirt
fill ~117 ~72 ~42 ~120 ~72 ~42 grass_block
fill ~121 ~60 ~42 ~123 ~67 ~42 stone
fill ~121 ~68 ~42 ~123 ~70 ~42 dirt
fill ~121 ~71 ~42 ~123 ~71 ~42 grass_block
fill ~124 ~60 ~42 ~126 ~66 ~42 stone
fill ~124 ~67 ~42 ~126 ~69 ~42 dirt
fill ~124 ~70 ~42 ~126 ~70 ~42 grass_block
fill ~127 ~60 ~42 ~127 ~67 ~42 stone
fill ~127 ~68 ~42 ~127 ~70 ~42 dirt
fill ~127 ~71 ~42 ~127 ~71 ~42 grass_block
fill ~112 ~60 ~43 ~113 ~65 ~43 stone
fill ~112 ~66 ~43 ~113 ~68 ~43 dirt
fill ~112 ~69 ~43 ~113 ~69 ~43 grass_block
fill ~114 ~60 ~43 ~115 ~66 ~43 stone
fill ~114 ~67 ~43 ~115 ~69 ~43 dirt
fill ~114 ~70 ~43 ~115 ~70 ~43 grass_block
fill ~116 ~60 ~43 ~117 ~67 ~43 stone
fill ~116 ~68 ~43 ~117 ~70 ~43 dirt
fill ~116 ~71 ~43 ~117 ~71 ~43 grass_block
fill ~118 ~60 ~43 ~121 ~68 ~43 stone
fill ~118 ~69 ~43 ~121 ~71 ~43 dirt
fill ~118 ~72 ~43 ~121 ~72 ~43 grass_block
fill ~122 ~60 ~43 ~123 ~67 ~43 stone
fill ~122 ~68 ~43 ~123 ~70 ~43 dirt
fill ~122 ~71 ~43 ~123 ~71 ~43 grass_block
fill ~124 ~60 ~43 ~127 ~66 ~43 stone
fill ~124 ~67 ~43 ~127 ~69 ~43 dirt
fill ~124 ~70 ~43 ~127 ~70 ~43 grass_block
fill ~112 ~60 ~44 ~114 ~65 ~44 stone
fill ~112 ~66 ~44 ~114 ~68 ~44 dirt
fill ~112 ~69 ~44 ~114 ~69 ~44 grass_block
fill ~115 ~60 ~44 ~115 ~66 ~44 stone
fill ~115 ~67 ~44 ~115 ~69 ~44 dirt
fill ~115 ~70 ~44 ~115 ~70 ~44 grass_block
fill ~116 ~60 ~44 ~119 ~67 ~44 stone
fill ~116 ~68 ~44 ~119 ~70 ~44 dirt
fill ~116 ~71 ~44 ~119 ~71 ~44 grass_block
fill ~120 ~60 ~44 ~120 ~68 ~44 stone
fill ~120 ~69 ~44 ~120 ~71 ~44 dirt
fill ~120 ~72 ~44 ~120 ~72 ~44 grass_block
fill ~121 ~60 ~44 ~124 ~67 ~44 stone
fill ~121 ~68 ~44 ~124 ~70 ~44 dirt
fill ~121 ~71 ~44 ~124 ~71 ~44 grass_block
fill ~125 ~60 ~44 ~127 ~66 ~44 stone
fill ~125 ~67 ~44 ~127 ~69 ~44 dirt
fill ~125 ~70 ~44 ~127 ~70 ~44 grass_block
fill ~112 ~60 ~45 ~112 ~64 ~45 stone
fill ~112 ~65 ~45 ~112 ~67 ~45 dirt
fill ~112 ~68 ~45 ~112 ~68 ~45 grass_block
fill ~113 ~60 ~45 ~114 ~65 ~45 stone
fill ~113 ~66 ~45 ~114 ~68 ~45 dirt
fill ~113 ~69 ~45 ~114 ~69 ~45 grass_block
fill ~115 ~60 ~45 ~115 ~66 ~45 stone
fill ~115 ~67 ~45 ~115 ~69 ~45 dirt
fill ~115 ~70 ~45 ~115 ~70 ~45 grass_block
fill ~116 ~60 ~45 ~124 ~67 ~45 stone
fill ~116 ~68 ~45 ~124 ~70 ~45 dirt
fill ~116 ~71 ~45 ~124 ~71 ~45 grass_block
fill ~125 ~60 ~45 ~126 ~66 ~45 stone
fill ~125 ~67 ~45 ~126 ~69 ~45 dirt
fill ~125 ~70 ~45 ~126 ~70 ~45 grass_block
fill ~127 ~60 ~45 ~127 ~65 ~45 stone
fill ~127 ~66 ~45 ~127 ~68 ~45 dirt
fill ~127 ~69 ~45 ~127 ~69 ~45 grass_block
fill ~112 ~60 ~46 ~112 ~64 ~46 stone
fill ~112 ~65 ~46 ~112 ~67 ~46 dirt
fill ~112 ~68 ~46 ~112 ~68 ~46 grass_block
fill ~113 ~60 ~46 ~114 ~65 ~46 stone
fill ~113 ~66 ~46 ~114 ~68 ~46 dirt
fill ~113 ~69 ~46 ~114 ~69 ~46 grass_block
fill ~115 ~60 ~46 ~116 ~66 ~46 stone
fill ~115 ~67 ~46 ~116 ~69 ~46 dirt
fill ~115 ~70 ~46 ~116 ~70 ~46 grass_block
fill ~117 ~60 ~46 ~124 ~67 ~46 stone
fill ~117 ~68 ~46 ~124 ~70 ~46 dirt
fill ~117 ~71 ~46 ~124 ~71 ~46 grass_block
fill ~125 ~60 ~46 ~126 ~66 ~46 stone
fill ~125 ~67 ~46 ~126 ~69 ~46 dirt
fill ~125 ~70 ~46 ~126 ~70 ~46 grass_block
fill ~127 ~60 ~46 ~127 ~65 ~46 stone
fill ~127 ~66 ~46 ~127 ~68 ~46 dirt
fill ~127 ~69 ~46 ~127 ~69 ~46 grass_block
fill ~112 ~60 ~47 ~112 ~64 ~47 stone
fill ~112 ~65 ~47 ~112 ~67 ~47 dirt
fill ~112 ~68 ~47 ~112 ~68 ~47 grass_block
fill ~113 ~60 ~47 ~114 ~65 ~47 stone
fill ~113 ~66 ~47 ~114 ~68 ~47 dirt
fill ~113 ~69 ~47 ~114 ~69 ~47 grass_block
fill ~115 ~60 ~47 ~116 ~66 ~47 stone
fill ~115 ~67 ~47 ~116 ~69 ~47 dirt
fill ~115 ~70 ~47 ~116 ~70 ~47 grass_block
fill ~117 ~60 ~47 ~120 ~67 ~47 stone
fill ~117 ~68 ~47 ~120 ~70 ~47 dirt
fill ~117 ~71 ~47 ~120 ~71 ~47 grass_block
fill ~121 ~60 ~47 ~124 ~66 ~47 stone
fill ~121 ~67 ~47 ~124 ~69 ~47 dirt
fill ~121 ~70 ~47 ~124 ~70 ~47 grass_block
fill ~125 ~60 ~47 ~125 ~67 ~47 stone
fill ~125 ~68 ~47 ~125 ~70 ~47 dirt
fill ~125 ~71 ~47 ~125 ~71 ~47 grass_block
fill ~126 ~60 ~47 ~127 ~66 ~47 stone
fill ~126 ~67 ~47 ~127 ~69 ~47 dirt
fill ~126 ~70 ~47 ~127 ~70 ~47 grass_block