fill ~112 ~60 ~80 ~115 ~63 ~80 stone
fill ~112 ~64 ~80 ~115 ~66 ~80 dirt
fill ~112 ~67 ~80 ~115 ~67 ~80 grass_block
fill ~116 ~60 ~80 ~122 ~62 ~80 stone
fill ~116 ~63 ~80 ~122 ~65 ~80 dirt
fill ~116 ~66 ~80 ~122 ~66 ~80 grass_block
fill ~123 ~60 ~80 ~127 ~63 ~80 stone
fill ~123 ~64 ~80 ~127 ~66 ~80 dirt
fill ~123 ~67 ~80 ~127 ~67 ~80 grass_block
fill ~112 ~60 ~81 ~116 ~63 ~81 stone
fill ~112 ~64 ~81 ~116 ~66 ~81 dirt
fill ~112 ~67 ~81 ~116 ~67 ~81 grass_block
fill ~117 ~60 ~81 ~122 ~62 ~81 stone
fill ~117 ~63 ~81 ~122 ~65 ~81 dirt
fill ~117 ~66 ~81 ~122 ~66 ~81 grass_block
fill ~123 ~60 ~81 ~127 ~63 ~81 stone
fill ~123 ~64 ~81 ~127 ~66 ~81 dirt
fill ~123 ~67 ~81 ~127 ~67 ~81 grass_block
fill ~112 ~60 ~82 ~112 ~64 ~82 stone
fill ~112 ~65 ~82 ~112 ~67 ~82 dirt
fill ~112 ~68 ~82 ~112 ~68 ~82 grass_block
fill ~113 ~60 ~82 ~116 ~63 ~82 stone
fill ~113 ~64 ~82 ~116 ~66 ~82 dirt
fill ~113 ~67 ~82 ~116 ~67 ~82 grass_block
fill ~117 ~60 ~82 ~122 ~62 ~82 stone
fill ~117 ~63 ~82 ~122 ~65 ~82 dirt
fill ~117 ~66 ~82 ~122 ~66 ~82 grass_block
fill ~123 ~60 ~82 ~127 ~63 ~82 stone
fill ~123 ~64 ~82 ~127 ~66 ~82 dirt
fill ~123 ~67 ~82 ~127 ~67 ~82 grass_block
fill ~112 ~60 ~83 ~113 ~64 ~83 stone
fill ~112 ~65 ~83 ~113 ~67 ~83 dirt
fill ~112 ~68 ~83 ~113 ~68 ~83 grass_block
fill ~114 ~60 ~83 ~116 ~63 ~83 stone
fill ~114 ~64 ~83 ~116 ~66 ~83 dirt
fill ~114 ~67 ~83 ~116 ~67 ~83 grass_block
fill ~117 ~60 ~83 ~123 ~62 ~83 stone
fill ~117 ~63 ~83 ~123 ~65 ~83 dirt
fill ~117 ~66 ~83 ~123 ~66 ~83 grass_block
fill ~124 ~60 ~83 ~127 ~63 ~83 stone
fill ~124 ~64 ~83 ~127 ~66 ~83 dirt
fill ~124 ~67 ~83 ~127 ~67 ~83 grass_block
fill ~112 ~60 ~84 ~113 ~64 ~84 stone
fill ~112 ~65 ~84 ~113 ~67 ~84 dirt
fill ~112 ~68 ~84 ~113 ~68 ~84 grass_block
fill ~114 ~60 ~84 ~116 ~63 ~84 stone
fill ~114 ~64 ~84 ~116 ~66 ~84 dirt
fill ~114 ~67 ~84 ~116 ~67 ~84 grass_block
fill ~117 ~60 ~84 ~124 ~62 ~84 stone
fill ~117 ~63 ~84 ~124 ~65 ~84 dirt
fill ~117 ~66 ~84 ~124 ~66 ~84 grass_block
fill ~125 ~60 ~84 ~127 ~63 ~84 stone
fill ~125 ~64 ~84 ~127 ~66 ~84 dirt
fill ~125 ~67 ~84 ~127 ~67 ~84 grass_block
fill ~112 ~60 ~85 ~114 ~64 ~85 stone
fill ~112 ~65 ~85 ~114 ~67 ~85 dirt
fill ~112 ~68 ~85 ~114 ~68 ~85 grass_block
fill ~115 ~60 ~85 ~116 ~63 ~85 stone
fill ~115 ~64 ~85 ~116 ~66 ~85 dirt
fill ~115 ~67 ~85 ~116 ~67 ~85 grass_block
fill ~117 ~60 ~85 ~126 ~62 ~85 stone
fill ~117 ~63 ~85 ~126 ~65 ~85 dirt
fill ~117 ~66 ~85 ~126 ~66 ~85 grass_block
fill ~127 ~60 ~85 ~127 ~63 ~85 stone
fill ~127 ~64 ~85 ~127 ~66 ~85 dirt
fill ~127 ~67 ~85 ~127 ~67 ~85 grass_block
fill ~112 ~60 ~86 ~115 ~64 ~86 stone
fill ~112 ~65 ~86 ~115 ~67 ~86 dirt
fill ~112 ~68 ~86 ~115 ~68 ~86 grass_block
fill ~116 ~60 ~86 ~117 ~63 ~86 stone
fill ~116 ~64 ~86 ~117 ~66 ~86 dirt
fill ~116 ~67 ~86 ~117 ~67 ~86 grass_block
fill ~118 ~60 ~86 ~127 ~62 ~86 stone
fill ~118 ~63 ~86 ~127 ~65 ~86 dirt
fill ~118 ~66 ~86 ~127 ~66 ~86 grass_block
fill ~112 ~60 ~87 ~115 ~64 ~87 stone
fill ~112 ~65 ~87 ~115 ~67 ~87 dirt
fill ~112 ~68 ~87 ~115 ~68 ~87 grass_block
fill ~116 ~60 ~87 ~117 ~63 ~87 stone
fill ~116 ~64 ~87 ~117 ~66 ~87 dirt
fill ~116 ~67 ~87 ~117 ~67 ~87 grass_block
fill ~118 ~60 ~87 ~127 ~62 ~87 stone
fill ~118 ~63 ~87 ~127 ~65 ~87 dirt
fill ~118 ~66 ~87 ~127 ~66 ~87 grass_block
fill ~112 ~60 ~88 ~117 ~64 ~88 stone
fill ~112 ~65 ~88 ~117 ~67 ~88 dirt
fill ~112 ~68 ~88 ~117 ~68 ~88 grass_block
fill ~118 ~60 ~88 ~118 ~63 ~88 stone
fill ~118 ~64 ~88 ~118 ~66 ~88 dirt
fill ~118 ~67 ~88 ~118 ~67 ~88 grass_block
fill ~119 ~60 ~88 ~127 ~62 ~88 stone
fill ~119 ~63 ~88 ~127 ~65 ~88 dirt
fill ~119 ~66 ~88 ~127 ~66 ~88 grass_block
fill ~112 ~60 ~89 ~117 ~64 ~89 stone
fill ~112 ~65 ~89 ~117 ~67 ~89 dirt
fill ~112 ~68 ~89 ~117 ~68 ~89 grass_block
fill ~118 ~60 ~89 ~121 ~63 ~89 stone
fill ~118 ~64 ~89 ~121 ~66 ~89 dirt
fill ~118 ~67 ~89 ~121 ~67 ~89 grass_block
fill ~122 ~60 ~89 ~127 ~62 ~89 stone
fill ~122 ~63 ~89 ~127 ~65 ~89 dirt
fill ~122 ~66 ~89 ~127 ~66 ~89 grass_block
fill ~112 ~60 ~90 ~118 ~64 ~90 stone
fill ~112 ~65 ~90 ~118 ~67 ~90 dirt
fill ~112 ~68 ~90 ~118 ~68 ~90 grass_block
fill ~119 ~60 ~90 ~122 ~63 ~90 stone
fill ~119 ~64 ~90 ~122 ~66 ~90 dirt
fill ~119 ~67 ~90 ~122 ~67 ~90 grass_block
fill ~123 ~60 ~90 ~127 ~62 ~90 stone
fill ~123 ~63 ~90 ~127 ~65 ~90 dirt
fill ~123 ~66 ~90 ~127 ~66 ~90 grass_block
fill ~112 ~60 ~91 ~113 ~63 ~91 stone
fill ~112 ~64 ~91 ~113 ~66 ~91 dirt
fill ~112 ~67 ~91 ~113 ~67 ~91 grass_block
fill ~114 ~60 ~91 ~119 ~64 ~91 stone
fill ~114 ~65 ~91 ~119 ~67 ~91 dirt
fill ~114 ~68 ~91 ~119 ~68 ~91 grass_block
fill ~120 ~60 ~91 ~123 ~63 ~91 stone
fill ~120 ~64 ~91 ~123 ~66 ~91 dirt
fill ~120 ~67 ~91 ~123 ~67 ~91 grass_block
fill ~124 ~60 ~91 ~127 ~62 ~91 stone
fill ~124 ~63 ~91 ~127 ~65 ~91 dirt
fill ~124 ~66 ~91 ~127 ~66 ~91 grass_block
fill ~112 ~60 ~92 ~115 ~63 ~92 stone
fill ~112 ~64 ~92 ~115 ~66 ~92 dirt
fill ~112 ~67 ~92 ~115 ~67 ~92 grass_block
fill ~116 ~60 ~92 ~116 ~64 ~92 stone
fill ~116 ~65 ~92 ~116 ~67 ~92 dirt
fill ~116 ~68 ~92 ~116 ~68 ~92 grass_block
fill ~117 ~60 ~92 ~124 ~63 ~92 stone
fill ~117 ~64 ~92 ~124 ~66 ~92 dirt
fill ~117 ~67 ~92 ~124 ~67 ~92 grass_block
fill ~125 ~60 ~92 ~127 ~62 ~92 stone
fill ~125 ~63 ~92 ~127 ~65 ~92 dirt
fill ~125 ~66 ~92 ~127 ~66 ~92 grass_block
fill ~112 ~60 ~93 ~124 ~63 ~93 stone
fill ~112 ~64 ~93 ~124 ~66 ~93 dirt
fill ~112 ~67 ~93 ~124 ~67 ~93 grass_block
fill ~125 ~60 ~93 ~127 ~62 ~93 stone
fill ~125 ~63 ~93 ~127 ~65 ~93 dirt
fill ~125 ~66 ~93 ~127 ~66 ~93 grass_block
fill ~112 ~60 ~94 ~114 ~62 ~94 stone
fill ~112 ~63 ~94 ~114 ~65 ~94 dirt
fill ~112 ~66 ~94 ~114 ~66 ~94 grass_block
fill ~115 ~60 ~94 ~125 ~63 ~94 stone
fill ~115 ~64 ~94 ~125 ~66 ~94 dirt
fill ~115 ~67 ~94 ~125 ~67 ~94 grass_block
fill ~126 ~60 ~94 ~126 ~62 ~94 stone
fill ~126 ~63 ~94 ~126 ~65 ~94 dirt
fill ~126 ~66 ~94 ~126 ~66 ~94 grass_block
fill ~127 ~60 ~94 ~127 ~63 ~94 stone
fill ~127 ~64 ~94 ~127 ~66 ~94 dirt
fill ~127 ~67 ~94 ~127 ~67 ~94 grass_block
fill ~112 ~60 ~95 ~116 ~62 ~95 stone
fill ~112 ~63 ~95 ~116 ~65 ~95 dirt
fill ~112 ~66 ~95 ~116 ~66 ~95 grass_block
fill ~117 ~60 ~95 ~127 ~63 ~95 stone
fill ~117 ~64 ~95 ~127 ~66 ~95 dirt
fill ~117 ~67 ~95 ~127 ~67 ~95 grass_block