fill ~48 ~60 ~64 ~51 ~65 ~64 stone
fill ~48 ~66 ~64 ~51 ~68 ~64 dirt
fill ~48 ~69 ~64 ~51 ~69 ~64 grass_block
fill ~52 ~60 ~64 ~53 ~64 ~64 stone
fill ~52 ~65 ~64 ~53 ~67 ~64 dirt
fill ~52 ~68 ~64 ~53 ~68 ~64 grass_block
fill ~54 ~60 ~64 ~55 ~63 ~64 stone
fill ~54 ~64 ~64 ~55 ~66 ~64 dirt
fill ~54 ~67 ~64 ~55 ~67 ~64 grass_block
fill ~56 ~60 ~64 ~63 ~64 ~64 stone
fill ~56 ~65 ~64 ~63 ~67 ~64 dirt
fill ~56 ~68 ~64 ~63 ~68 ~64 grass_block
fill ~48 ~60 ~65 ~48 ~66 ~65 stone
fill ~48 ~67 ~65 ~48 ~69 ~65 dirt
fill ~48 ~70 ~65 ~48 ~70 ~65 grass_block
fill ~49 ~60 ~65 ~52 ~65 ~65 stone
fill ~49 ~66 ~65 ~52 ~68 ~65 dirt
fill ~49 ~69 ~65 ~52 ~69 ~65 grass_block
fill ~53 ~60 ~65 ~56 ~64 ~65 stone
fill ~53 ~65 ~65 ~56 ~67 ~65 dirt
fill ~53 ~68 ~65 ~56 ~68 ~65 grass_block
fill ~57 ~60 ~65 ~58 ~63 ~65 stone
fill ~57 ~64 ~65 ~58 ~66 ~65 dirt
fill ~57 ~67 ~65 ~58 ~67 ~65 grass_block
fill ~59 ~60 ~65 ~63 ~64 ~65 stone
fill ~59 ~65 ~65 ~63 ~67 ~65 dirt
fill ~59 ~68 ~65 ~63 ~68 ~65 grass_block
fill ~48 ~60 ~66 ~50 ~66 ~66 stone
fill ~48 ~67 ~66 ~50 ~69 ~66 dirt
fill ~48 ~70 ~66 ~50 ~70 ~66 grass_block
fill ~51 ~60 ~66 ~53 ~65 ~66 stone
fill ~51 ~66 ~66 ~53 ~68 ~66 dirt
fill ~51 ~69 ~66 ~53 ~69 ~66 grass_block
fill ~54 ~60 ~66 ~57 ~64 ~66 stone
fill ~54 ~65 ~66 ~57 ~67 ~66 dirt
fill ~54 ~68 ~66 ~57 ~68 ~66 grass_block
fill ~58 ~60 ~66 ~63 ~63 ~66 stone
fill ~58 ~64 ~66 ~63 ~66 ~66 dirt
fill ~58 ~67 ~66 ~63 ~67 ~66 grass_block
fill ~48 ~60 ~67 ~50 ~66 ~67 stone
fill ~48 ~67 ~67 ~50 ~69 ~67 dirt
fill ~48 ~70 ~67 ~50 ~70 ~67 grass_block
fill ~51 ~60 ~67 ~53 ~65 ~67 stone
fill ~51 ~66 ~67 ~53 ~68 ~67 dirt
fill ~51 ~69 ~67 ~53 ~69 ~67 grass_block
fill ~54 ~60 ~67 ~58 ~64 ~67 stone
fill ~54 ~65 ~67 ~58 ~67 ~67 dirt
fill ~54 ~68 ~67 ~58 ~68 ~67 grass_block
fill ~59 ~60 ~67 ~63 ~63 ~67 stone
fill ~59 ~64 ~67 ~63 ~66 ~67 dirt
fill ~59 ~67 ~67 ~63 ~67 ~67 grass_block
fill ~48 ~60 ~68 ~48 ~67 ~68 stone
fill ~48 ~68 ~68 ~48 ~70 ~68 dirt
fill ~48 ~71 ~68 ~48 ~71 ~68 grass_block
fill ~49 ~60 ~68 ~51 ~66 ~68 stone
fill ~49 ~67 ~68 ~51 ~69 ~68 dirt
fill ~49 ~70 ~68 ~51 ~70 ~68 grass_block
fill ~52 ~60 ~68 ~56 ~65 ~68 stone
fill ~52 ~66 ~68 ~56 ~68 ~68 dirt
fill ~52 ~69 ~68 ~56 ~69 ~68 grass_block
fill ~57 ~60 ~68 ~60 ~64 ~68 stone
fill ~57 ~65 ~68 ~60 ~67 ~68 dirt
fill ~57 ~68 ~68 ~60 ~68 ~68 grass_block
fill ~61 ~60 ~68 ~62 ~63 ~68 stone
fill ~61 ~64 ~68 ~62 ~66 ~68 dirt
fill ~61 ~67 ~68 ~62 ~67 ~68 grass_block
fill ~63 ~60 ~68 ~63 ~64 ~68 stone
fill ~63 ~65 ~68 ~63 ~67 ~68 dirt
fill ~63 ~68 ~68 ~63 ~68 ~68 grass_block
fill ~48 ~60 ~69 ~48 ~67 ~69 stone
fill ~48 ~68 ~69 ~48 ~70 ~69 dirt
fill ~48 ~71 ~69 ~48 ~71 ~69 grass_block
fill ~49 ~60 ~69 ~51 ~66 ~69 stone
fill ~49 ~67 ~69 ~51 ~69 ~69 dirt
fill ~49 ~70 ~69 ~51 ~70 ~69 grass_block
fill ~52 ~60 ~69 ~59 ~65 ~69 stone
fill ~52 ~66 ~69 ~59 ~68 ~69 dirt
fill ~52 ~69 ~69 ~59 ~69 ~69 grass_block
fill ~60 ~60 ~69 ~63 ~64 ~69 stone
fill ~60 ~65 ~69 ~63 ~67 ~69 dirt
fill ~60 ~68 ~69 ~63 ~68 ~69 grass_block
fill ~48 ~60 ~70 ~49 ~67 ~70 stone
fill ~48 ~68 ~70 ~49 ~70 ~70 dirt
fill ~48 ~71 ~70 ~49 ~71 ~70 grass_block
fill ~50 ~60 ~70 ~54 ~66 ~70 stone
fill ~50 ~67 ~70 ~54 ~69 ~70 dirt
fill ~50 ~70 ~70 ~54 ~70 ~70 grass_block
fill ~55 ~60 ~70 ~55 ~65 ~70 stone
fill ~55 ~66 ~70 ~55 ~68 ~70 dirt
fill ~55 ~69 ~70 ~55 ~69 ~70 grass_block
fill ~56 ~60 ~70 ~58 ~66 ~70 stone
fill ~56 ~67 ~70 ~58 ~69 ~70 dirt
fill ~56 ~70 ~70 ~58 ~70 ~70 grass_block
fill ~59 ~60 ~70 ~63 ~65 ~70 stone
fill ~59 ~66 ~70 ~63 ~68 ~70 dirt
fill ~59 ~69 ~70 ~63 ~69 ~70 grass_block
fill ~48 ~60 ~71 ~50 ~67 ~71 stone
fill ~48 ~68 ~71 ~50 ~70 ~71 dirt
fill ~48 ~71 ~71 ~50 ~71 ~71 grass_block
fill ~51 ~60 ~71 ~60 ~66 ~71 stone
fill ~51 ~67 ~71 ~60 ~69 ~71 dirt
fill ~51 ~70 ~71 ~60 ~70 ~71 grass_block
fill ~61 ~60 ~71 ~61 ~65 ~71 stone
fill ~61 ~66 ~71 ~61 ~68 ~71 dirt
fill ~61 ~69 ~71 ~61 ~69 ~71 grass_block
fill ~62 ~60 ~71 ~62 ~66 ~71 stone
fill ~62 ~67 ~71 ~62 ~69 ~71 dirt
fill ~62 ~70 ~71 ~62 ~70 ~71 grass_block
fill ~63 ~60 ~71 ~63 ~65 ~71 stone
fill ~63 ~66 ~71 ~63 ~68 ~71 dirt
fill ~63 ~69 ~71 ~63 ~69 ~71 grass_block
fill ~48 ~60 ~72 ~48 ~68 ~72 stone
fill ~48 ~69 ~72 ~48 ~71 ~72 dirt
fill ~48 ~72 ~72 ~48 ~72 ~72 grass_block
fill ~49 ~60 ~72 ~58 ~67 ~72 stone
fill ~49 ~68 ~72 ~58 ~70 ~72 dirt
fill ~49 ~71 ~72 ~58 ~71 ~72 grass_block
fill ~59 ~60 ~72 ~62 ~66 ~72 stone
fill ~59 ~67 ~72 ~62 ~69 ~72 dirt
fill ~59 ~70 ~72 ~62 ~70 ~72 grass_block
fill ~63 ~60 ~72 ~63 ~65 ~72 stone
fill ~63 ~66 ~72 ~63 ~68 ~72 dirt
fill ~63 ~69 ~72 ~63 ~69 ~72 grass_block
fill ~48 ~60 ~73 ~48 ~69 ~73 stone
fill ~48 ~70 ~73 ~48 ~72 ~73 dirt
fill ~48 ~73 ~73 ~48 ~73 ~73 grass_block
fill ~49 ~60 ~73 ~52 ~68 ~73 stone
fill ~49 ~69 ~73 ~52 ~71 ~73 dirt
fill ~49 ~72 ~73 ~52 ~72 ~73 grass_block
fill ~53 ~60 ~73 ~57 ~67 ~73 stone
fill ~53 ~68 ~73 ~57 ~70 ~73 dirt
fill ~53 ~71 ~73 ~57 ~71 ~73 grass_block
fill ~58 ~60 ~73 ~63 ~66 ~73 stone
fill ~58 ~67 ~73 ~63 ~69 ~73 dirt
fill ~58 ~70 ~73 ~63 ~70 ~73 grass_block
fill ~48 ~60 ~74 ~50 ~69 ~74 stone
fill ~48 ~70 ~74 ~50 ~72 ~74 dirt
fill ~48 ~73 ~74 ~50 ~73 ~74 grass_block
fill ~51 ~60 ~74 ~52 ~68 ~74 stone
fill ~51 ~69 ~74 ~52 ~71 ~74 dirt
fill ~51 ~72 ~74 ~52 ~72 ~74 grass_block
fill ~53 ~60 ~74 ~56 ~67 ~74 stone
fill ~53 ~68 ~74 ~56 ~70 ~74 dirt
fill ~53 ~71 ~74 ~56 ~71 ~74 grass_block
fill ~57 ~60 ~74 ~63 ~66 ~74 stone
fill ~57 ~67 ~74 ~63 ~69 ~74 dirt
fill ~57 ~70 ~74 ~63 ~70 ~74 grass_block
fill ~48 ~60 ~75 ~48 ~70 ~75 stone
fill ~48 ~71 ~75 ~48 ~73 ~75 dirt
fill ~48 ~74 ~75 ~48 ~74 ~75 grass_block
fill ~49 ~60 ~75 ~50 ~69 ~75 stone
fill ~49 ~70 ~75 ~50 ~72 ~75 dirt
fill ~49 ~73 ~75 ~50 ~73 ~75 grass_block
fill ~51 ~60 ~75 ~53 ~68 ~75 stone
fill ~51 ~69 ~75 ~53 ~71 ~75 dirt
fill ~51 ~72 ~75 ~53 ~72 ~75 grass_block
fill ~54 ~60 ~75 ~55 ~67 ~75 stone
fill ~54 ~68 ~75 ~55 ~70 ~75 dirt
fill ~54 ~71 ~75 ~55 ~71 ~75 grass_block
fill ~56 ~60 ~75 ~60 ~66 ~75 stone
fill ~56 ~67 ~75 ~60 ~69 ~75 dirt
fill ~56 ~70 ~75 ~60 ~70 ~75 grass_block
fill ~61 ~60 ~75 ~63 ~65 ~75 stone
fill ~61 ~66 ~75 ~63 ~68 ~75 dirt
fill ~61 ~69 ~75 ~63 ~69 ~75 grass_block
fill ~48 ~60 ~76 ~49 ~70 ~76 stone
fill ~48 ~71 ~76 ~49 ~73 ~76 dirt
fill ~48 ~74 ~76 ~49 ~74 ~76 grass_block
fill ~50 ~60 ~76 ~51 ~69 ~76 stone
fill ~50 ~70 ~76 ~51 ~72 ~76 dirt
fill ~50 ~73 ~76 ~51 ~73 ~76 grass_block
fill ~52 ~60 ~76 ~53 ~68 ~76 stone
fill ~52 ~69 ~76 ~53 ~71 ~76 dirt
fill ~52 ~72 ~76 ~53 ~72 ~76 grass_block
fill ~54 ~60 ~76 ~54 ~67 ~76 stone
fill ~54 ~68 ~76 ~54 ~70 ~76 dirt
fill ~54 ~71 ~76 ~54 ~71 ~76 grass_block
fill ~55 ~60 ~76 ~57 ~66 ~76 stone
fill ~55 ~67 ~76 ~57 ~69 ~76 dirt
fill ~55 ~70 ~76 ~57 ~70 ~76 grass_block
fill ~58 ~60 ~76 ~63 ~65 ~76 stone
fill ~58 ~66 ~76 ~63 ~68 ~76 dirt
fill ~58 ~69 ~76 ~63 ~69 ~76 grass_block
fill ~48 ~60 ~77 ~49 ~70 ~77 stone
fill ~48 ~71 ~77 ~49 ~73 ~77 dirt
fill ~48 ~74 ~77 ~49 ~74 ~77 grass_block
fill ~50 ~60 ~77 ~51 ~69 ~77 stone
fill ~50 ~70 ~77 ~51 ~72 ~77 dirt
fill ~50 ~73 ~77 ~51 ~73 ~77 grass_block
fill ~52 ~60 ~77 ~52 ~68 ~77 stone
fill ~52 ~69 ~77 ~52 ~71 ~77 dirt
fill ~52 ~72 ~77 ~52 ~72 ~77 grass_block
fill ~53 ~60 ~77 ~55 ~67 ~77 stone
fill ~53 ~68 ~77 ~55 ~70 ~77 dirt
fill ~53 ~71 ~77 ~55 ~71 ~77 grass_block
fill ~56 ~60 ~77 ~58 ~66 ~77 stone
fill ~56 ~67 ~77 ~58 ~69 ~77 dirt
fill ~56 ~70 ~77 ~58 ~70 ~77 grass_block
fill ~59 ~60 ~77 ~62 ~65 ~77 stone
fill ~59 ~66 ~77 ~62 ~68 ~77 dirt
fill ~59 ~69 ~77 ~62 ~69 ~77 grass_block
fill ~63 ~60 ~77 ~63 ~64 ~77 stone
fill ~63 ~65 ~77 ~63 ~67 ~77 dirt
fill ~63 ~68 ~77 ~63 ~68 ~77 grass_block
fill ~48 ~60 ~78 ~49 ~70 ~78 stone
fill ~48 ~71 ~78 ~49 ~73 ~78 dirt
fill ~48 ~74 ~78 ~49 ~74 ~78 grass_block
fill ~50 ~60 ~78 ~51 ~69 ~78 stone
fill ~50 ~70 ~78 ~51 ~72 ~78 dirt
fill ~50 ~73 ~78 ~51 ~73 ~78 grass_block
fill ~52 ~60 ~78 ~53 ~68 ~78 stone
fill ~52 ~69 ~78 ~53 ~71 ~78 dirt
fill ~52 ~72 ~78 ~53 ~72 ~78 grass_block
fill ~54 ~60 ~78 ~56 ~67 ~78 stone
fill ~54 ~68 ~78 ~56 ~70 ~78 dirt
fill ~54 ~71 ~78 ~56 ~71 ~78 grass_block
fill ~57 ~60 ~78 ~58 ~66 ~78 stone
fill ~57 ~67 ~78 ~58 ~69 ~78 dirt
fill ~57 ~70 ~78 ~58 ~70 ~78 grass_block
fill ~59 ~60 ~78 ~63 ~65 ~78 stone
fill ~59 ~66 ~78 ~63 ~68 ~78 dirt
fill ~59 ~69 ~78 ~63 ~69 ~78 grass_block
fill ~48 ~60 ~79 ~48 ~69 ~79 stone
fill ~48 ~70 ~79 ~48 ~72 ~79 dirt
fill ~48 ~73 ~79 ~48 ~73 ~79 grass_block
fill ~49 ~60 ~79 ~51 ~70 ~79 stone
fill ~49 ~71 ~79 ~51 ~73 ~79 dirt
fill ~49 ~74 ~79 ~51 ~74 ~79 grass_block
fill ~52 ~60 ~79 ~52 ~69 ~79 stone
fill ~52 ~70 ~79 ~52 ~72 ~79 dirt
fill ~52 ~73 ~79 ~52 ~73 ~79 grass_block
fill ~53 ~60 ~79 ~53 ~68 ~79 stone
fill ~53 ~69 ~79 ~53 ~71 ~79 dirt
fill ~53 ~72 ~79 ~53 ~72 ~79 grass_block
fill ~54 ~60 ~79 ~55 ~67 ~79 stone
fill ~54 ~68 ~79 ~55 ~70 ~79 dirt
fill ~54 ~71 ~79 ~55 ~71 ~79 grass_block
fill ~56 ~60 ~79 ~59 ~66 ~79 stone
fill ~56 ~67 ~79 ~59 ~69 ~79 dirt
fill ~56 ~70 ~79 ~59 ~70 ~79 grass_block
fill ~60 ~60 ~79 ~63 ~65 ~79 stone
fill ~60 ~66 ~79 ~63 ~68 ~79 dirt
fill ~60 ~69 ~79 ~63 ~69 ~79 grass_block