fill ~96 ~60 ~80 ~96 ~64 ~80 stone
fill ~96 ~65 ~80 ~96 ~67 ~80 dirt
fill ~96 ~68 ~80 ~96 ~68 ~80 grass_block
fill ~97 ~60 ~80 ~108 ~65 ~80 stone
fill ~97 ~66 ~80 ~108 ~68 ~80 dirt
fill ~97 ~69 ~80 ~108 ~69 ~80 grass_block
fill ~109 ~60 ~80 ~111 ~64 ~80 stone
fill ~109 ~65 ~80 ~111 ~67 ~80 dirt
fill ~109 ~68 ~80 ~111 ~68 ~80 grass_block
fill ~96 ~60 ~81 ~98 ~64 ~81 stone
fill ~96 ~65 ~81 ~98 ~67 ~81 dirt
fill ~96 ~68 ~81 ~98 ~68 ~81 grass_block
fill ~99 ~60 ~81 ~108 ~65 ~81 stone
fill ~99 ~66 ~81 ~108 ~68 ~81 dirt
fill ~99 ~69 ~81 ~108 ~69 ~81 grass_block
fill ~109 ~60 ~81 ~111 ~64 ~81 stone
fill ~109 ~65 ~81 ~111 ~67 ~81 dirt
fill ~109 ~68 ~81 ~111 ~68 ~81 grass_block
fill ~96 ~60 ~82 ~100 ~64 ~82 stone
fill ~96 ~65 ~82 ~100 ~67 ~82 dirt
fill ~96 ~68 ~82 ~100 ~68 ~82 grass_block
fill ~101 ~60 ~82 ~109 ~65 ~82 stone
fill ~101 ~66 ~82 ~109 ~68 ~82 dirt
fill ~101 ~69 ~82 ~109 ~69 ~82 grass_block
fill ~110 ~60 ~82 ~111 ~64 ~82 stone
fill ~110 ~65 ~82 ~111 ~67 ~82 dirt
fill ~110 ~68 ~82 ~111 ~68 ~82 grass_block
fill ~96 ~60 ~83 ~102 ~64 ~83 stone
fill ~96 ~65 ~83 ~102 ~67 ~83 dirt
fill ~96 ~68 ~83 ~102 ~68 ~83 grass_block
fill ~103 ~60 ~83 ~109 ~65 ~83 stone
fill ~103 ~66 ~83 ~109 ~68 ~83 dirt
fill ~103 ~69 ~83 ~109 ~69 ~83 grass_block
fill ~110 ~60 ~83 ~111 ~64 ~83 stone
fill ~110 ~65 ~83 ~111 ~67 ~83 dirt
fill ~110 ~68 ~83 ~111 ~68 ~83 grass_block
fill ~96 ~60 ~84 ~97 ~63 ~84 stone
fill ~96 ~64 ~84 ~97 ~66 ~84 dirt
fill ~96 ~67 ~84 ~97 ~67 ~84 grass_block
fill ~98 ~60 ~84 ~105 ~64 ~84 stone
fill ~98 ~65 ~84 ~105 ~67 ~84 dirt
fill ~98 ~68 ~84 ~105 ~68 ~84 grass_block
fill ~106 ~60 ~84 ~110 ~65 ~84 stone
fill ~106 ~66 ~84 ~110 ~68 ~84 dirt
fill ~106 ~69 ~84 ~110 ~69 ~84 grass_block
fill ~111 ~60 ~84 ~111 ~64 ~84 stone
fill ~111 ~65 ~84 ~111 ~67 ~84 dirt
fill ~111 ~68 ~84 ~111 ~68 ~84 grass_block
fill ~96 ~60 ~85 ~99 ~63 ~85 stone
fill ~96 ~64 ~85 ~99 ~66 ~85 dirt
fill ~96 ~67 ~85 ~99 ~67 ~85 grass_block
fill ~100 ~60 ~85 ~108 ~64 ~85 stone
fill ~100 ~65 ~85 ~108 ~67 ~85 dirt
fill ~100 ~68 ~85 ~108 ~68 ~85 grass_block
fill ~109 ~60 ~85 ~110 ~65 ~85 stone
fill ~109 ~66 ~85 ~110 ~68 ~85 dirt
fill ~109 ~69 ~85 ~110 ~69 ~85 grass_block
fill ~111 ~60 ~85 ~111 ~64 ~85 stone
fill ~111 ~65 ~85 ~111 ~67 ~85 dirt
fill ~111 ~68 ~85 ~111 ~68 ~85 grass_block
fill ~96 ~60 ~86 ~102 ~63 ~86 stone
fill ~96 ~64 ~86 ~102 ~66 ~86 dirt
fill ~96 ~67 ~86 ~102 ~67 ~86 grass_block
fill ~103 ~60 ~86 ~111 ~64 ~86 stone
fill ~103 ~65 ~86 ~111 ~67 ~86 dirt
fill ~103 ~68 ~86 ~111 ~68 ~86 grass_block
fill ~96 ~60 ~87 ~105 ~63 ~87 stone
fill ~96 ~64 ~87 ~105 ~66 ~87 dirt
fill ~96 ~67 ~87 ~105 ~67 ~87 grass_block
fill ~106 ~60 ~87 ~111 ~64 ~87 stone
fill ~106 ~65 ~87 ~111 ~67 ~87 dirt
fill ~106 ~68 ~87 ~111 ~68 ~87 grass_block
fill ~96 ~60 ~88 ~106 ~63 ~88 stone
fill ~96 ~64 ~88 ~106 ~66 ~88 dirt
fill ~96 ~67 ~88 ~106 ~67 ~88 grass_block
fill ~107 ~60 ~88 ~111 ~64 ~88 stone
fill ~107 ~65 ~88 ~111 ~67 ~88 dirt
fill ~107 ~68 ~88 ~111 ~68 ~88 grass_block
fill ~96 ~60 ~89 ~108 ~63 ~89 stone
fill ~96 ~64 ~89 ~108 ~66 ~89 dirt
fill ~96 ~67 ~89 ~108 ~67 ~89 grass_block
fill ~109 ~60 ~89 ~111 ~64 ~89 stone
fill ~109 ~65 ~89 ~111 ~67 ~89 dirt
fill ~109 ~68 ~89 ~111 ~68 ~89 grass_block
fill ~96 ~60 ~90 ~98 ~64 ~90 stone
fill ~96 ~65 ~90 ~98 ~67 ~90 dirt
fill ~96 ~68 ~90 ~98 ~68 ~90 grass_block
fill ~99 ~60 ~90 ~111 ~63 ~90 stone
fill ~99 ~64 ~90 ~111 ~66 ~90 dirt
fill ~99 ~67 ~90 ~111 ~67 ~90 grass_block
fill ~96 ~60 ~91 ~97 ~65 ~91 stone
fill ~96 ~66 ~91 ~97 ~68 ~91 dirt
fill ~96 ~69 ~91 ~97 ~69 ~91 grass_block
fill ~98 ~60 ~91 ~101 ~64 ~91 stone
fill ~98 ~65 ~91 ~101 ~67 ~91 dirt
fill ~98 ~68 ~91 ~101 ~68 ~91 grass_block
fill ~102 ~60 ~91 ~111 ~63 ~91 stone
fill ~102 ~64 ~91 ~111 ~66 ~91 dirt
fill ~102 ~67 ~91 ~111 ~67 ~91 grass_block
fill ~96 ~60 ~92 ~99 ~65 ~92 stone
fill ~96 ~66 ~92 ~99 ~68 ~92 dirt
fill ~96 ~69 ~92 ~99 ~69 ~92 grass_block
fill ~100 ~60 ~92 ~103 ~64 ~92 stone
fill ~100 ~65 ~92 ~103 ~67 ~92 dirt
fill ~100 ~68 ~92 ~103 ~68 ~92 grass_block
fill ~104 ~60 ~92 ~106 ~63 ~92 stone
fill ~104 ~64 ~92 ~106 ~66 ~92 dirt
fill ~104 ~67 ~92 ~106 ~67 ~92 grass_block
fill ~107 ~60 ~92 ~108 ~62 ~92 stone
fill ~107 ~63 ~92 ~108 ~65 ~92 dirt
fill ~107 ~66 ~92 ~108 ~66 ~92 grass_block
fill ~109 ~60 ~92 ~111 ~63 ~92 stone
fill ~109 ~64 ~92 ~111 ~66 ~92 dirt
fill ~109 ~67 ~92 ~111 ~67 ~92 grass_block
fill ~96 ~60 ~93 ~99 ~65 ~93 stone
fill ~96 ~66 ~93 ~99 ~68 ~93 dirt
fill ~96 ~69 ~93 ~99 ~69 ~93 grass_block
fill ~100 ~60 ~93 ~105 ~64 ~93 stone
fill ~100 ~65 ~93 ~105 ~67 ~93 dirt
fill ~100 ~68 ~93 ~105 ~68 ~93 grass_block
fill ~106 ~60 ~93 ~109 ~63 ~93 stone
fill ~106 ~64 ~93 ~109 ~66 ~93 dirt
fill ~106 ~67 ~93 ~109 ~67 ~93 grass_block
fill ~110 ~60 ~93 ~110 ~62 ~93 stone
fill ~110 ~63 ~93 ~110 ~65 ~93 dirt
fill ~110 ~66 ~93 ~110 ~66 ~93 grass_block
fill ~111 ~60 ~93 ~111 ~63 ~93 stone
fill ~111 ~64 ~93 ~111 ~66 ~93 dirt
fill ~111 ~67 ~93 ~111 ~67 ~93 grass_block
fill ~96 ~60 ~94 ~96 ~66 ~94 stone
fill ~96 ~67 ~94 ~96 ~69 ~94 dirt
fill ~96 ~70 ~94 ~96 ~70 ~94 grass_block
fill ~97 ~60 ~94 ~101 ~65 ~94 stone
fill ~97 ~66 ~94 ~101 ~68 ~94 dirt
fill ~97 ~69 ~94 ~101 ~69 ~94 grass_block
fill ~102 ~60 ~94 ~105 ~64 ~94 stone
fill ~102 ~65 ~94 ~105 ~67 ~94 dirt
fill ~102 ~68 ~94 ~105 ~68 ~94 grass_block
fill ~106 ~60 ~94 ~110 ~63 ~94 stone
fill ~106 ~64 ~94 ~110 ~66 ~94 dirt
fill ~106 ~67 ~94 ~110 ~67 ~94 grass_block
fill ~111 ~60 ~94 ~111 ~62 ~94 stone
fill ~111 ~63 ~94 ~111 ~65 ~94 dirt
fill ~111 ~66 ~94 ~111 ~66 ~94 grass_block
fill ~96 ~60 ~95 ~97 ~66 ~95 stone
fill ~96 ~67 ~95 ~97 ~69 ~95 dirt
fill ~96 ~70 ~95 ~97 ~70 ~95 grass_block
fill ~98 ~60 ~95 ~101 ~65 ~95 stone
fill ~98 ~66 ~95 ~101 ~68 ~95 dirt
fill ~98 ~69 ~95 ~101 ~69 ~95 grass_block
fill ~102 ~60 ~95 ~105 ~64 ~95 stone
fill ~102 ~65 ~95 ~105 ~67 ~95 dirt
fill ~102 ~68 ~95 ~105 ~68 ~95 grass_block
fill ~106 ~60 ~95 ~110 ~63 ~95 stone
fill ~106 ~64 ~95 ~110 ~66 ~95 dirt
fill ~106 ~67 ~95 ~110 ~67 ~95 grass_block
fill ~111 ~60 ~95 ~111 ~62 ~95 stone
fill ~111 ~63 ~95 ~111 ~65 ~95 dirt
fill ~111 ~66 ~95 ~111 ~66 ~95 grass_block