fill ~128 ~60 ~64 ~131 ~64 ~64 stone
fill ~128 ~65 ~64 ~131 ~67 ~64 dirt
fill ~128 ~68 ~64 ~131 ~68 ~64 grass_block
fill ~132 ~60 ~64 ~135 ~65 ~64 stone
fill ~132 ~66 ~64 ~135 ~68 ~64 dirt
fill ~132 ~69 ~64 ~135 ~69 ~64 grass_block
fill ~136 ~60 ~64 ~139 ~66 ~64 stone
fill ~136 ~67 ~64 ~139 ~69 ~64 dirt
fill ~136 ~70 ~64 ~139 ~70 ~64 grass_block
fill ~140 ~60 ~64 ~141 ~65 ~64 stone
fill ~140 ~66 ~64 ~141 ~68 ~64 dirt
fill ~140 ~69 ~64 ~141 ~69 ~64 grass_block
fill ~142 ~60 ~64 ~143 ~64 ~64 stone
fill ~142 ~65 ~64 ~143 ~67 ~64 dirt
fill ~142 ~68 ~64 ~143 ~68 ~64 grass_block
fill ~128 ~60 ~65 ~132 ~64 ~65 stone
fill ~128 ~65 ~65 ~132 ~67 ~65 dirt
fill ~128 ~68 ~65 ~132 ~68 ~65 grass_block
fill ~133 ~60 ~65 ~135 ~65 ~65 stone
fill ~133 ~66 ~65 ~135 ~68 ~65 dirt
fill ~133 ~69 ~65 ~135 ~69 ~65 grass_block
fill ~136 ~60 ~65 ~139 ~66 ~65 stone
fill ~136 ~67 ~65 ~139 ~69 ~65 dirt
fill ~136 ~70 ~65 ~139 ~70 ~65 grass_block
fill ~140 ~60 ~65 ~142 ~65 ~65 stone
fill ~140 ~66 ~65 ~142 ~68 ~65 dirt
fill ~140 ~69 ~65 ~142 ~69 ~65 grass_block
fill ~143 ~60 ~65 ~143 ~64 ~65 stone
fill ~143 ~65 ~65 ~143 ~67 ~65 dirt
fill ~143 ~68 ~65 ~143 ~68 ~65 grass_block
fill ~128 ~60 ~66 ~133 ~64 ~66 stone
fill ~128 ~65 ~66 ~133 ~67 ~66 dirt
fill ~128 ~68 ~66 ~133 ~68 ~66 grass_block
fill ~134 ~60 ~66 ~136 ~65 ~66 stone
fill ~134 ~66 ~66 ~136 ~68 ~66 dirt
fill ~134 ~69 ~66 ~136 ~69 ~66 grass_block
fill ~137 ~60 ~66 ~140 ~66 ~66 stone
fill ~137 ~67 ~66 ~140 ~69 ~66 dirt
fill ~137 ~70 ~66 ~140 ~70 ~66 grass_block
fill ~141 ~60 ~66 ~143 ~65 ~66 stone
fill ~141 ~66 ~66 ~143 ~68 ~66 dirt
fill ~141 ~69 ~66 ~143 ~69 ~66 grass_block
fill ~128 ~60 ~67 ~131 ~64 ~67 stone
fill ~128 ~65 ~67 ~131 ~67 ~67 dirt
fill ~128 ~68 ~67 ~131 ~68 ~67 grass_block
fill ~132 ~60 ~67 ~136 ~65 ~67 stone
fill ~132 ~66 ~67 ~136 ~68 ~67 dirt
fill ~132 ~69 ~67 ~136 ~69 ~67 grass_block
fill ~137 ~60 ~67 ~141 ~66 ~67 stone
fill ~137 ~67 ~67 ~141 ~69 ~67 dirt
fill ~137 ~70 ~67 ~141 ~70 ~67 grass_block
fill ~142 ~60 ~67 ~143 ~65 ~67 stone
fill ~142 ~66 ~67 ~143 ~68 ~67 dirt
fill ~142 ~69 ~67 ~143 ~69 ~67 grass_block
fill ~128 ~60 ~68 ~130 ~64 ~68 stone
fill ~128 ~65 ~68 ~130 ~67 ~68 dirt
fill ~128 ~68 ~68 ~130 ~68 ~68 grass_block
fill ~131 ~60 ~68 ~137 ~65 ~68 stone
fill ~131 ~66 ~68 ~137 ~68 ~68 dirt
fill ~131 ~69 ~68 ~137 ~69 ~68 grass_block
fill ~138 ~60 ~68 ~142 ~66 ~68 stone
fill ~138 ~67 ~68 ~142 ~69 ~68 dirt
fill ~138 ~70 ~68 ~142 ~70 ~68 grass_block
fill ~143 ~60 ~68 ~143 ~65 ~68 stone
fill ~143 ~66 ~68 ~143 ~68 ~68 dirt
fill ~143 ~69 ~68 ~143 ~69 ~68 grass_block
fill ~128 ~60 ~69 ~130 ~64 ~69 stone
fill ~128 ~65 ~69 ~130 ~67 ~69 dirt
fill ~128 ~68 ~69 ~130 ~68 ~69 grass_block
fill ~131 ~60 ~69 ~136 ~65 ~69 stone
fill ~131 ~66 ~69 ~136 ~68 ~69 dirt
fill ~131 ~69 ~69 ~136 ~69 ~69 grass_block
fill ~137 ~60 ~69 ~143 ~66 ~69 stone
fill ~137 ~67 ~69 ~143 ~69 ~69 dirt
fill ~137 ~70 ~69 ~143 ~70 ~69 grass_block
fill ~128 ~60 ~70 ~128 ~63 ~70 stone
fill ~128 ~64 ~70 ~128 ~66 ~70 dirt
fill ~128 ~67 ~70 ~128 ~67 ~70 grass_block
fill ~129 ~60 ~70 ~130 ~64 ~70 stone
fill ~129 ~65 ~70 ~130 ~67 ~70 dirt
fill ~129 ~68 ~70 ~130 ~68 ~70 grass_block
fill ~131 ~60 ~70 ~136 ~65 ~70 stone
fill ~131 ~66 ~70 ~136 ~68 ~70 dirt
fill ~131 ~69 ~70 ~136 ~69 ~70 grass_block
fill ~137 ~60 ~70 ~143 ~66 ~70 stone
fill ~137 ~67 ~70 ~143 ~69 ~70 dirt
fill ~137 ~70 ~70 ~143 ~70 ~70 grass_block
fill ~128 ~60 ~71 ~128 ~63 ~71 stone
fill ~128 ~64 ~71 ~128 ~66 ~71 dirt
fill ~128 ~67 ~71 ~128 ~67 ~71 grass_block
fill ~129 ~60 ~71 ~131 ~64 ~71 stone
fill ~129 ~65 ~71 ~131 ~67 ~71 dirt
fill ~129 ~68 ~71 ~131 ~68 ~71 grass_block
fill ~132 ~60 ~71 ~134 ~65 ~71 stone
fill ~132 ~66 ~71 ~134 ~68 ~71 dirt
fill ~132 ~69 ~71 ~134 ~69 ~71 grass_block
fill ~135 ~60 ~71 ~135 ~66 ~71 stone
fill ~135 ~67 ~71 ~135 ~69 ~71 dirt
fill ~135 ~70 ~71 ~135 ~70 ~71 grass_block
fill ~136 ~60 ~71 ~143 ~65 ~71 stone
fill ~136 ~66 ~71 ~143 ~68 ~71 dirt
fill ~136 ~69 ~71 ~143 ~69 ~71 grass_block
fill ~128 ~60 ~72 ~128 ~63 ~72 stone
fill ~128 ~64 ~72 ~128 ~66 ~72 dirt
fill ~128 ~67 ~72 ~128 ~67 ~72 grass_block
fill ~129 ~60 ~72 ~131 ~64 ~72 stone
fill ~129 ~65 ~72 ~131 ~67 ~72 dirt
fill ~129 ~68 ~72 ~131 ~68 ~72 grass_block
fill ~132 ~60 ~72 ~143 ~65 ~72 stone
fill ~132 ~66 ~72 ~143 ~68 ~72 dirt
fill ~132 ~69 ~72 ~143 ~69 ~72 grass_block
fill ~128 ~60 ~73 ~128 ~63 ~73 stone
fill ~128 ~64 ~73 ~128 ~66 ~73 dirt
fill ~128 ~67 ~73 ~128 ~67 ~73 grass_block
fill ~129 ~60 ~73 ~131 ~64 ~73 stone
fill ~129 ~65 ~73 ~131 ~67 ~73 dirt
fill ~129 ~68 ~73 ~131 ~68 ~73 grass_block
fill ~132 ~60 ~73 ~138 ~65 ~73 stone
fill ~132 ~66 ~73 ~138 ~68 ~73 dirt
fill ~132 ~69 ~73 ~138 ~69 ~73 grass_block
fill ~139 ~60 ~73 ~143 ~64 ~73 stone
fill ~139 ~65 ~73 ~143 ~67 ~73 dirt
fill ~139 ~68 ~73 ~143 ~68 ~73 grass_block
fill ~128 ~60 ~74 ~128 ~63 ~74 stone
fill ~128 ~64 ~74 ~128 ~66 ~74 dirt
fill ~128 ~67 ~74 ~128 ~67 ~74 grass_block
fill ~129 ~60 ~74 ~131 ~64 ~74 stone
fill ~129 ~65 ~74 ~131 ~67 ~74 dirt
fill ~129 ~68 ~74 ~131 ~68 ~74 grass_block
fill ~132 ~60 ~74 ~137 ~65 ~74 stone
fill ~132 ~66 ~74 ~137 ~68 ~74 dirt
fill ~132 ~69 ~74 ~137 ~69 ~74 grass_block
fill ~138 ~60 ~74 ~143 ~64 ~74 stone
fill ~138 ~65 ~74 ~143 ~67 ~74 dirt
fill ~138 ~68 ~74 ~143 ~68 ~74 grass_block
fill ~128 ~60 ~75 ~130 ~64 ~75 stone
fill ~128 ~65 ~75 ~130 ~67 ~75 dirt
fill ~128 ~68 ~75 ~130 ~68 ~75 grass_block
fill ~131 ~60 ~75 ~137 ~65 ~75 stone
fill ~131 ~66 ~75 ~137 ~68 ~75 dirt
fill ~131 ~69 ~75 ~137 ~69 ~75 grass_block
fill ~138 ~60 ~75 ~143 ~64 ~75 stone
fill ~138 ~65 ~75 ~143 ~67 ~75 dirt
fill ~138 ~68 ~75 ~143 ~68 ~75 grass_block
fill ~128 ~60 ~76 ~130 ~64 ~76 stone
fill ~128 ~65 ~76 ~130 ~67 ~76 dirt
fill ~128 ~68 ~76 ~130 ~68 ~76 grass_block
fill ~131 ~60 ~76 ~137 ~65 ~76 stone
fill ~131 ~66 ~76 ~137 ~68 ~76 dirt
fill ~131 ~69 ~76 ~137 ~69 ~76 grass_block
fill ~138 ~60 ~76 ~140 ~64 ~76 stone
fill ~138 ~65 ~76 ~140 ~67 ~76 dirt
fill ~138 ~68 ~76 ~140 ~68 ~76 grass_block
fill ~141 ~60 ~76 ~142 ~63 ~76 stone
fill ~141 ~64 ~76 ~142 ~66 ~76 dirt
fill ~141 ~67 ~76 ~142 ~67 ~76 grass_block
fill ~143 ~60 ~76 ~143 ~64 ~76 stone
fill ~143 ~65 ~76 ~143 ~67 ~76 dirt
fill ~143 ~68 ~76 ~143 ~68 ~76 grass_block
fill ~128 ~60 ~77 ~130 ~64 ~77 stone
fill ~128 ~65 ~77 ~130 ~67 ~77 dirt
fill ~128 ~68 ~77 ~130 ~68 ~77 grass_block
fill ~131 ~60 ~77 ~136 ~65 ~77 stone
fill ~131 ~66 ~77 ~136 ~68 ~77 dirt
fill ~131 ~69 ~77 ~136 ~69 ~77 grass_block
fill ~137 ~60 ~77 ~139 ~64 ~77 stone
fill ~137 ~65 ~77 ~139 ~67 ~77 dirt
fill ~137 ~68 ~77 ~139 ~68 ~77 grass_block
fill ~140 ~60 ~77 ~141 ~63 ~77 stone
fill ~140 ~64 ~77 ~141 ~66 ~77 dirt
fill ~140 ~67 ~77 ~141 ~67 ~77 grass_block
fill ~142 ~60 ~77 ~143 ~64 ~77 stone
fill ~142 ~65 ~77 ~143 ~67 ~77 dirt
fill ~142 ~68 ~77 ~143 ~68 ~77 grass_block
fill ~128 ~60 ~78 ~131 ~64 ~78 stone
fill ~128 ~65 ~78 ~131 ~67 ~78 dirt
fill ~128 ~68 ~78 ~131 ~68 ~78 grass_block
fill ~132 ~60 ~78 ~135 ~65 ~78 stone
fill ~132 ~66 ~78 ~135 ~68 ~78 dirt
fill ~132 ~69 ~78 ~135 ~69 ~78 grass_block
fill ~136 ~60 ~78 ~138 ~64 ~78 stone
fill ~136 ~65 ~78 ~138 ~67 ~78 dirt
fill ~136 ~68 ~78 ~138 ~68 ~78 grass_block
fill ~139 ~60 ~78 ~141 ~63 ~78 stone
fill ~139 ~64 ~78 ~141 ~66 ~78 dirt
fill ~139 ~67 ~78 ~141 ~67 ~78 grass_block
fill ~142 ~60 ~78 ~143 ~64 ~78 stone
fill ~142 ~65 ~78 ~143 ~67 ~78 dirt
fill ~142 ~68 ~78 ~143 ~68 ~78 grass_block
fill ~128 ~60 ~79 ~138 ~64 ~79 stone
fill ~128 ~65 ~79 ~138 ~67 ~79 dirt
fill ~128 ~68 ~79 ~138 ~68 ~79 grass_block
fill ~139 ~60 ~79 ~141 ~63 ~79 stone
fill ~139 ~64 ~79 ~141 ~66 ~79 dirt
fill ~139 ~67 ~79 ~141 ~67 ~79 grass_block
fill ~142 ~60 ~79 ~143 ~64 ~79 stone
fill ~142 ~65 ~79 ~143 ~67 ~79 dirt
fill ~142 ~68 ~79 ~143 ~68 ~79 grass_block