fill ~304 ~60 ~48 ~312 ~63 ~48 stone
fill ~304 ~64 ~48 ~312 ~66 ~48 dirt
fill ~304 ~67 ~48 ~312 ~67 ~48 grass_block
fill ~313 ~60 ~48 ~319 ~62 ~48 stone
fill ~313 ~63 ~48 ~319 ~65 ~48 dirt
fill ~313 ~66 ~48 ~319 ~66 ~48 grass_block
fill ~304 ~60 ~49 ~312 ~63 ~49 stone
fill ~304 ~64 ~49 ~312 ~66 ~49 dirt
fill ~304 ~67 ~49 ~312 ~67 ~49 grass_block
fill ~313 ~60 ~49 ~319 ~62 ~49 stone
fill ~313 ~63 ~49 ~319 ~65 ~49 dirt
fill ~313 ~66 ~49 ~319 ~66 ~49 grass_block
fill ~304 ~60 ~50 ~310 ~63 ~50 stone
fill ~304 ~64 ~50 ~310 ~66 ~50 dirt
fill ~304 ~67 ~50 ~310 ~67 ~50 grass_block
fill ~311 ~60 ~50 ~319 ~62 ~50 stone
fill ~311 ~63 ~50 ~319 ~65 ~50 dirt
fill ~311 ~66 ~50 ~319 ~66 ~50 grass_block
fill ~304 ~60 ~51 ~310 ~63 ~51 stone
fill ~304 ~64 ~51 ~310 ~66 ~51 dirt
fill ~304 ~67 ~51 ~310 ~67 ~51 grass_block
fill ~311 ~60 ~51 ~318 ~62 ~51 stone
fill ~311 ~63 ~51 ~318 ~65 ~51 dirt
fill ~311 ~66 ~51 ~318 ~66 ~51 grass_block
fill ~319 ~60 ~51 ~319 ~61 ~51 stone
fill ~319 ~62 ~51 ~319 ~64 ~51 dirt
fill ~319 ~65 ~51 ~319 ~65 ~51 grass_block
fill ~304 ~60 ~52 ~309 ~63 ~52 stone
fill ~304 ~64 ~52 ~309 ~66 ~52 dirt
fill ~304 ~67 ~52 ~309 ~67 ~52 grass_block
fill ~310 ~60 ~52 ~310 ~62 ~52 stone
fill ~310 ~63 ~52 ~310 ~65 ~52 dirt
fill ~310 ~66 ~52 ~310 ~66 ~52 grass_block
fill ~311 ~60 ~52 ~312 ~63 ~52 stone
fill ~311 ~64 ~52 ~312 ~66 ~52 dirt
fill ~311 ~67 ~52 ~312 ~67 ~52 grass_block
fill ~313 ~60 ~52 ~318 ~62 ~52 stone
fill ~313 ~63 ~52 ~318 ~65 ~52 dirt
fill ~313 ~66 ~52 ~318 ~66 ~52 grass_block
fill ~319 ~60 ~52 ~319 ~61 ~52 stone
fill ~319 ~62 ~52 ~319 ~64 ~52 dirt
fill ~319 ~65 ~52 ~319 ~65 ~52 grass_block
fill ~304 ~60 ~53 ~307 ~63 ~53 stone
fill ~304 ~64 ~53 ~307 ~66 ~53 dirt
fill ~304 ~67 ~53 ~307 ~67 ~53 grass_block
fill ~308 ~60 ~53 ~309 ~62 ~53 stone
fill ~308 ~63 ~53 ~309 ~65 ~53 dirt
fill ~308 ~66 ~53 ~309 ~66 ~53 grass_block
fill ~310 ~60 ~53 ~312 ~63 ~53 stone
fill ~310 ~64 ~53 ~312 ~66 ~53 dirt
fill ~310 ~67 ~53 ~312 ~67 ~53 grass_block
fill ~313 ~60 ~53 ~318 ~62 ~53 stone
fill ~313 ~63 ~53 ~318 ~65 ~53 dirt
fill ~313 ~66 ~53 ~318 ~66 ~53 grass_block
fill ~319 ~60 ~53 ~319 ~61 ~53 stone
fill ~319 ~62 ~53 ~319 ~64 ~53 dirt
fill ~319 ~65 ~53 ~319 ~65 ~53 grass_block
fill ~304 ~60 ~54 ~307 ~63 ~54 stone
fill ~304 ~64 ~54 ~307 ~66 ~54 dirt
fill ~304 ~67 ~54 ~307 ~67 ~54 grass_block
fill ~308 ~60 ~54 ~319 ~62 ~54 stone
fill ~308 ~63 ~54 ~319 ~65 ~54 dirt
fill ~308 ~66 ~54 ~319 ~66 ~54 grass_block
fill ~304 ~60 ~55 ~305 ~63 ~55 stone
fill ~304 ~64 ~55 ~305 ~66 ~55 dirt
fill ~304 ~67 ~55 ~305 ~67 ~55 grass_block
fill ~306 ~60 ~55 ~318 ~62 ~55 stone
fill ~306 ~63 ~55 ~318 ~65 ~55 dirt
fill ~306 ~66 ~55 ~318 ~66 ~55 grass_block
fill ~319 ~60 ~55 ~319 ~61 ~55 stone
fill ~319 ~62 ~55 ~319 ~64 ~55 dirt
fill ~319 ~65 ~55 ~319 ~65 ~55 grass_block
fill ~304 ~60 ~56 ~306 ~63 ~56 stone
fill ~304 ~64 ~56 ~306 ~66 ~56 dirt
fill ~304 ~67 ~56 ~306 ~67 ~56 grass_block
fill ~307 ~60 ~56 ~317 ~62 ~56 stone
fill ~307 ~63 ~56 ~317 ~65 ~56 dirt
fill ~307 ~66 ~56 ~317 ~66 ~56 grass_block
fill ~318 ~60 ~56 ~318 ~61 ~56 stone
fill ~318 ~62 ~56 ~318 ~64 ~56 dirt
fill ~318 ~65 ~56 ~318 ~65 ~56 grass_block
fill ~319 ~60 ~56 ~319 ~62 ~56 stone
fill ~319 ~63 ~56 ~319 ~65 ~56 dirt
fill ~319 ~66 ~56 ~319 ~66 ~56 grass_block
fill ~304 ~60 ~57 ~307 ~63 ~57 stone
fill ~304 ~64 ~57 ~307 ~66 ~57 dirt
fill ~304 ~67 ~57 ~307 ~67 ~57 grass_block
fill ~308 ~60 ~57 ~315 ~62 ~57 stone
fill ~308 ~63 ~57 ~315 ~65 ~57 dirt
fill ~308 ~66 ~57 ~315 ~66 ~57 grass_block
fill ~316 ~60 ~57 ~316 ~61 ~57 stone
fill ~316 ~62 ~57 ~316 ~64 ~57 dirt
fill ~316 ~65 ~57 ~316 ~65 ~57 grass_block
fill ~317 ~60 ~57 ~317 ~62 ~57 stone
fill ~317 ~63 ~57 ~317 ~65 ~57 dirt
fill ~317 ~66 ~57 ~317 ~66 ~57 grass_block
fill ~318 ~60 ~57 ~318 ~61 ~57 stone
fill ~318 ~62 ~57 ~318 ~64 ~57 dirt
fill ~318 ~65 ~57 ~318 ~65 ~57 grass_block
fill ~319 ~60 ~57 ~319 ~62 ~57 stone
fill ~319 ~63 ~57 ~319 ~65 ~57 dirt
fill ~319 ~66 ~57 ~319 ~66 ~57 grass_block
fill ~304 ~60 ~58 ~306 ~63 ~58 stone
fill ~304 ~64 ~58 ~306 ~66 ~58 dirt
fill ~304 ~67 ~58 ~306 ~67 ~58 grass_block
fill ~307 ~60 ~58 ~315 ~62 ~58 stone
fill ~307 ~63 ~58 ~315 ~65 ~58 dirt
fill ~307 ~66 ~58 ~315 ~66 ~58 grass_block
fill ~316 ~60 ~58 ~318 ~61 ~58 stone
fill ~316 ~62 ~58 ~318 ~64 ~58 dirt
fill ~316 ~65 ~58 ~318 ~65 ~58 grass_block
fill ~319 ~60 ~58 ~319 ~62 ~58 stone
fill ~319 ~63 ~58 ~319 ~65 ~58 dirt
fill ~319 ~66 ~58 ~319 ~66 ~58 grass_block
fill ~304 ~60 ~59 ~305 ~63 ~59 stone
fill ~304 ~64 ~59 ~305 ~66 ~59 dirt
fill ~304 ~67 ~59 ~305 ~67 ~59 grass_block
fill ~306 ~60 ~59 ~314 ~62 ~59 stone
fill ~306 ~63 ~59 ~314 ~65 ~59 dirt
fill ~306 ~66 ~59 ~314 ~66 ~59 grass_block
fill ~315 ~60 ~59 ~317 ~61 ~59 stone
fill ~315 ~62 ~59 ~317 ~64 ~59 dirt
fill ~315 ~65 ~59 ~317 ~65 ~59 grass_block
fill ~318 ~60 ~59 ~319 ~62 ~59 stone
fill ~318 ~63 ~59 ~319 ~65 ~59 dirt
fill ~318 ~66 ~59 ~319 ~66 ~59 grass_block
fill ~304 ~60 ~60 ~305 ~63 ~60 stone
fill ~304 ~64 ~60 ~305 ~66 ~60 dirt
fill ~304 ~67 ~60 ~305 ~67 ~60 grass_block
fill ~306 ~60 ~60 ~314 ~62 ~60 stone
fill ~306 ~63 ~60 ~314 ~65 ~60 dirt
fill ~306 ~66 ~60 ~314 ~66 ~60 grass_block
fill ~315 ~60 ~60 ~318 ~61 ~60 stone
fill ~315 ~62 ~60 ~318 ~64 ~60 dirt
fill ~315 ~65 ~60 ~318 ~65 ~60 grass_block
fill ~319 ~60 ~60 ~319 ~62 ~60 stone
fill ~319 ~63 ~60 ~319 ~65 ~60 dirt
fill ~319 ~66 ~60 ~319 ~66 ~60 grass_block
fill ~304 ~60 ~61 ~305 ~63 ~61 stone
fill ~304 ~64 ~61 ~305 ~66 ~61 dirt
fill ~304 ~67 ~61 ~305 ~67 ~61 grass_block
fill ~306 ~60 ~61 ~314 ~62 ~61 stone
fill ~306 ~63 ~61 ~314 ~65 ~61 dirt
fill ~306 ~66 ~61 ~314 ~66 ~61 grass_block
fill ~315 ~60 ~61 ~318 ~61 ~61 stone
fill ~315 ~62 ~61 ~318 ~64 ~61 dirt
fill ~315 ~65 ~61 ~318 ~65 ~61 grass_block
fill ~319 ~60 ~61 ~319 ~62 ~61 stone
fill ~319 ~63 ~61 ~319 ~65 ~61 dirt
fill ~319 ~66 ~61 ~319 ~66 ~61 grass_block
fill ~304 ~60 ~62 ~305 ~63 ~62 stone
fill ~304 ~64 ~62 ~305 ~66 ~62 dirt
fill ~304 ~67 ~62 ~305 ~67 ~62 grass_block
fill ~306 ~60 ~62 ~314 ~62 ~62 stone
fill ~306 ~63 ~62 ~314 ~65 ~62 dirt
fill ~306 ~66 ~62 ~314 ~66 ~62 grass_block
fill ~315 ~60 ~62 ~318 ~61 ~62 stone
fill ~315 ~62 ~62 ~318 ~64 ~62 dirt
fill ~315 ~65 ~62 ~318 ~65 ~62 grass_block
fill ~319 ~60 ~62 ~319 ~62 ~62 stone
fill ~319 ~63 ~62 ~319 ~65 ~62 dirt
fill ~319 ~66 ~62 ~319 ~66 ~62 grass_block
fill ~304 ~60 ~63 ~304 ~63 ~63 stone
fill ~304 ~64 ~63 ~304 ~66 ~63 dirt
fill ~304 ~67 ~63 ~304 ~67 ~63 grass_block
fill ~305 ~60 ~63 ~313 ~62 ~63 stone
fill ~305 ~63 ~63 ~313 ~65 ~63 dirt
fill ~305 ~66 ~63 ~313 ~66 ~63 grass_block
fill ~314 ~60 ~63 ~318 ~61 ~63 stone
fill ~314 ~62 ~63 ~318 ~64 ~63 dirt
fill ~314 ~65 ~63 ~318 ~65 ~63 grass_block
fill ~319 ~60 ~63 ~319 ~62 ~63 stone
fill ~319 ~63 ~63 ~319 ~65 ~63 dirt
fill ~319 ~66 ~63 ~319 ~66 ~63 grass_block