fill ~0 ~60 ~80 ~10 ~64 ~80 stone
fill ~0 ~65 ~80 ~10 ~67 ~80 dirt
fill ~0 ~68 ~80 ~10 ~68 ~80 grass_block
fill ~11 ~60 ~80 ~11 ~63 ~80 stone
fill ~11 ~64 ~80 ~11 ~66 ~80 dirt
fill ~11 ~67 ~80 ~11 ~67 ~80 grass_block
fill ~12 ~60 ~80 ~14 ~64 ~80 stone
fill ~12 ~65 ~80 ~14 ~67 ~80 dirt
fill ~12 ~68 ~80 ~14 ~68 ~80 grass_block
fill ~15 ~60 ~80 ~15 ~65 ~80 stone
fill ~15 ~66 ~80 ~15 ~68 ~80 dirt
fill ~15 ~69 ~80 ~15 ~69 ~80 grass_block
fill ~0 ~60 ~81 ~4 ~64 ~81 stone
fill ~0 ~65 ~81 ~4 ~67 ~81 dirt
fill ~0 ~68 ~81 ~4 ~68 ~81 grass_block
fill ~5 ~60 ~81 ~12 ~63 ~81 stone
fill ~5 ~64 ~81 ~12 ~66 ~81 dirt
fill ~5 ~67 ~81 ~12 ~67 ~81 grass_block
fill ~13 ~60 ~81 ~15 ~64 ~81 stone
fill ~13 ~65 ~81 ~15 ~67 ~81 dirt
fill ~13 ~68 ~81 ~15 ~68 ~81 grass_block
fill ~0 ~60 ~82 ~1 ~65 ~82 stone
fill ~0 ~66 ~82 ~1 ~68 ~82 dirt
fill ~0 ~69 ~82 ~1 ~69 ~82 grass_block
fill ~2 ~60 ~82 ~5 ~64 ~82 stone
fill ~2 ~65 ~82 ~5 ~67 ~82 dirt
fill ~2 ~68 ~82 ~5 ~68 ~82 grass_block
fill ~6 ~60 ~82 ~13 ~63 ~82 stone
fill ~6 ~64 ~82 ~13 ~66 ~82 dirt
fill ~6 ~67 ~82 ~13 ~67 ~82 grass_block
fill ~14 ~60 ~82 ~15 ~64 ~82 stone
fill ~14 ~65 ~82 ~15 ~67 ~82 dirt
fill ~14 ~68 ~82 ~15 ~68 ~82 grass_block
fill ~0 ~60 ~83 ~1 ~64 ~83 stone
fill ~0 ~65 ~83 ~1 ~67 ~83 dirt
fill ~0 ~68 ~83 ~1 ~68 ~83 grass_block
fill ~2 ~60 ~83 ~2 ~65 ~83 stone
fill ~2 ~66 ~83 ~2 ~68 ~83 dirt
fill ~2 ~69 ~83 ~2 ~69 ~83 grass_block
fill ~3 ~60 ~83 ~5 ~64 ~83 stone
fill ~3 ~65 ~83 ~5 ~67 ~83 dirt
fill ~3 ~68 ~83 ~5 ~68 ~83 grass_block
fill ~6 ~60 ~83 ~8 ~63 ~83 stone
fill ~6 ~64 ~83 ~8 ~66 ~83 dirt
fill ~6 ~67 ~83 ~8 ~67 ~83 grass_block
fill ~9 ~60 ~83 ~9 ~64 ~83 stone
fill ~9 ~65 ~83 ~9 ~67 ~83 dirt
fill ~9 ~68 ~83 ~9 ~68 ~83 grass_block
fill ~10 ~60 ~83 ~14 ~63 ~83 stone
fill ~10 ~64 ~83 ~14 ~66 ~83 dirt
fill ~10 ~67 ~83 ~14 ~67 ~83 grass_block
fill ~15 ~60 ~83 ~15 ~64 ~83 stone
fill ~15 ~65 ~83 ~15 ~67 ~83 dirt
fill ~15 ~68 ~83 ~15 ~68 ~83 grass_block
fill ~0 ~60 ~84 ~5 ~64 ~84 stone
fill ~0 ~65 ~84 ~5 ~67 ~84 dirt
fill ~0 ~68 ~84 ~5 ~68 ~84 grass_block
fill ~6 ~60 ~84 ~15 ~63 ~84 stone
fill ~6 ~64 ~84 ~15 ~66 ~84 dirt
fill ~6 ~67 ~84 ~15 ~67 ~84 grass_block
fill ~0 ~60 ~85 ~7 ~64 ~85 stone
fill ~0 ~65 ~85 ~7 ~67 ~85 dirt
fill ~0 ~68 ~85 ~7 ~68 ~85 grass_block
fill ~8 ~60 ~85 ~15 ~63 ~85 stone
fill ~8 ~64 ~85 ~15 ~66 ~85 dirt
fill ~8 ~67 ~85 ~15 ~67 ~85 grass_block
fill ~0 ~60 ~86 ~7 ~64 ~86 stone
fill ~0 ~65 ~86 ~7 ~67 ~86 dirt
fill ~0 ~68 ~86 ~7 ~68 ~86 grass_block
fill ~8 ~60 ~86 ~15 ~63 ~86 stone
fill ~8 ~64 ~86 ~15 ~66 ~86 dirt
fill ~8 ~67 ~86 ~15 ~67 ~86 grass_block
fill ~0 ~60 ~87 ~1 ~65 ~87 stone
fill ~0 ~66 ~87 ~1 ~68 ~87 dirt
fill ~0 ~69 ~87 ~1 ~69 ~87 grass_block
fill ~2 ~60 ~87 ~8 ~64 ~87 stone
fill ~2 ~65 ~87 ~8 ~67 ~87 dirt
fill ~2 ~68 ~87 ~8 ~68 ~87 grass_block
fill ~9 ~60 ~87 ~15 ~63 ~87 stone
fill ~9 ~64 ~87 ~15 ~66 ~87 dirt
fill ~9 ~67 ~87 ~15 ~67 ~87 grass_block
fill ~0 ~60 ~88 ~3 ~65 ~88 stone
fill ~0 ~66 ~88 ~3 ~68 ~88 dirt
fill ~0 ~69 ~88 ~3 ~69 ~88 grass_block
fill ~4 ~60 ~88 ~9 ~64 ~88 stone
fill ~4 ~65 ~88 ~9 ~67 ~88 dirt
fill ~4 ~68 ~88 ~9 ~68 ~88 grass_block
fill ~10 ~60 ~88 ~15 ~63 ~88 stone
fill ~10 ~64 ~88 ~15 ~66 ~88 dirt
fill ~10 ~67 ~88 ~15 ~67 ~88 grass_block
fill ~0 ~60 ~89 ~1 ~66 ~89 stone
fill ~0 ~67 ~89 ~1 ~69 ~89 dirt
fill ~0 ~70 ~89 ~1 ~70 ~89 grass_block
fill ~2 ~60 ~89 ~7 ~65 ~89 stone
fill ~2 ~66 ~89 ~7 ~68 ~89 dirt
fill ~2 ~69 ~89 ~7 ~69 ~89 grass_block
fill ~8 ~60 ~89 ~9 ~64 ~89 stone
fill ~8 ~65 ~89 ~9 ~67 ~89 dirt
fill ~8 ~68 ~89 ~9 ~68 ~89 grass_block
fill ~10 ~60 ~89 ~15 ~63 ~89 stone
fill ~10 ~64 ~89 ~15 ~66 ~89 dirt
fill ~10 ~67 ~89 ~15 ~67 ~89 grass_block
fill ~0 ~60 ~90 ~0 ~67 ~90 stone
fill ~0 ~68 ~90 ~0 ~70 ~90 dirt
fill ~0 ~71 ~90 ~0 ~71 ~90 grass_block
fill ~1 ~60 ~90 ~2 ~66 ~90 stone
fill ~1 ~67 ~90 ~2 ~69 ~90 dirt
fill ~1 ~70 ~90 ~2 ~70 ~90 grass_block
fill ~3 ~60 ~90 ~8 ~65 ~90 stone
fill ~3 ~66 ~90 ~8 ~68 ~90 dirt
fill ~3 ~69 ~90 ~8 ~69 ~90 grass_block
fill ~9 ~60 ~90 ~11 ~64 ~90 stone
fill ~9 ~65 ~90 ~11 ~67 ~90 dirt
fill ~9 ~68 ~90 ~11 ~68 ~90 grass_block
fill ~12 ~60 ~90 ~15 ~63 ~90 stone
fill ~12 ~64 ~90 ~15 ~66 ~90 dirt
fill ~12 ~67 ~90 ~15 ~67 ~90 grass_block
fill ~0 ~60 ~91 ~2 ~67 ~91 stone
fill ~0 ~68 ~91 ~2 ~70 ~91 dirt
fill ~0 ~71 ~91 ~2 ~71 ~91 grass_block
fill ~3 ~60 ~91 ~7 ~66 ~91 stone
fill ~3 ~67 ~91 ~7 ~69 ~91 dirt
fill ~3 ~70 ~91 ~7 ~70 ~91 grass_block
fill ~8 ~60 ~91 ~9 ~65 ~91 stone
fill ~8 ~66 ~91 ~9 ~68 ~91 dirt
fill ~8 ~69 ~91 ~9 ~69 ~91 grass_block
fill ~10 ~60 ~91 ~13 ~64 ~91 stone
fill ~10 ~65 ~91 ~13 ~67 ~91 dirt
fill ~10 ~68 ~91 ~13 ~68 ~91 grass_block
fill ~14 ~60 ~91 ~15 ~63 ~91 stone
fill ~14 ~64 ~91 ~15 ~66 ~91 dirt
fill ~14 ~67 ~91 ~15 ~67 ~91 grass_block
fill ~0 ~60 ~92 ~0 ~66 ~92 stone
fill ~0 ~67 ~92 ~0 ~69 ~92 dirt
fill ~0 ~70 ~92 ~0 ~70 ~92 grass_block
fill ~1 ~60 ~92 ~6 ~67 ~92 stone
fill ~1 ~68 ~92 ~6 ~70 ~92 dirt
fill ~1 ~71 ~92 ~6 ~71 ~92 grass_block
fill ~7 ~60 ~92 ~8 ~66 ~92 stone
fill ~7 ~67 ~92 ~8 ~69 ~92 dirt
fill ~7 ~70 ~92 ~8 ~70 ~92 grass_block
fill ~9 ~60 ~92 ~10 ~65 ~92 stone
fill ~9 ~66 ~92 ~10 ~68 ~92 dirt
fill ~9 ~69 ~92 ~10 ~69 ~92 grass_block
fill ~11 ~60 ~92 ~14 ~64 ~92 stone
fill ~11 ~65 ~92 ~14 ~67 ~92 dirt
fill ~11 ~68 ~92 ~14 ~68 ~92 grass_block
fill ~15 ~60 ~92 ~15 ~63 ~92 stone
fill ~15 ~64 ~92 ~15 ~66 ~92 dirt
fill ~15 ~67 ~92 ~15 ~67 ~92 grass_block
fill ~0 ~60 ~93 ~3 ~66 ~93 stone
fill ~0 ~67 ~93 ~3 ~69 ~93 dirt
fill ~0 ~70 ~93 ~3 ~70 ~93 grass_block
fill ~4 ~60 ~93 ~7 ~67 ~93 stone
fill ~4 ~68 ~93 ~7 ~70 ~93 dirt
fill ~4 ~71 ~93 ~7 ~71 ~93 grass_block
fill ~8 ~60 ~93 ~9 ~66 ~93 stone
fill ~8 ~67 ~93 ~9 ~69 ~93 dirt
fill ~8 ~70 ~93 ~9 ~70 ~93 grass_block
fill ~10 ~60 ~93 ~12 ~65 ~93 stone
fill ~10 ~66 ~93 ~12 ~68 ~93 dirt
fill ~10 ~69 ~93 ~12 ~69 ~93 grass_block
fill ~13 ~60 ~93 ~15 ~64 ~93 stone
fill ~13 ~65 ~93 ~15 ~67 ~93 dirt
fill ~13 ~68 ~93 ~15 ~68 ~93 grass_block
fill ~0 ~60 ~94 ~11 ~66 ~94 stone
fill ~0 ~67 ~94 ~11 ~69 ~94 dirt
fill ~0 ~70 ~94 ~11 ~70 ~94 grass_block
fill ~12 ~60 ~94 ~13 ~65 ~94 stone
fill ~12 ~66 ~94 ~13 ~68 ~94 dirt
fill ~12 ~69 ~94 ~13 ~69 ~94 grass_block
fill ~14 ~60 ~94 ~15 ~64 ~94 stone
fill ~14 ~65 ~94 ~15 ~67 ~94 dirt
fill ~14 ~68 ~94 ~15 ~68 ~94 grass_block
fill ~0 ~60 ~95 ~1 ~65 ~95 stone
fill ~0 ~66 ~95 ~1 ~68 ~95 dirt
fill ~0 ~69 ~95 ~1 ~69 ~95 grass_block
fill ~2 ~60 ~95 ~12 ~66 ~95 stone
fill ~2 ~67 ~95 ~12 ~69 ~95 dirt
fill ~2 ~70 ~95 ~12 ~70 ~95 grass_block
fill ~13 ~60 ~95 ~15 ~65 ~95 stone
fill ~13 ~66 ~95 ~15 ~68 ~95 dirt
fill ~13 ~69 ~95 ~15 ~69 ~95 grass_block