fill ~320 ~60 ~48 ~328 ~62 ~48 stone
fill ~320 ~63 ~48 ~328 ~65 ~48 dirt
fill ~320 ~66 ~48 ~328 ~66 ~48 grass_block
fill ~329 ~60 ~48 ~330 ~63 ~48 stone
fill ~329 ~64 ~48 ~330 ~66 ~48 dirt
fill ~329 ~67 ~48 ~330 ~67 ~48 grass_block
fill ~331 ~60 ~48 ~332 ~64 ~48 stone
fill ~331 ~65 ~48 ~332 ~67 ~48 dirt
fill ~331 ~68 ~48 ~332 ~68 ~48 grass_block
fill ~333 ~60 ~48 ~335 ~65 ~48 stone
fill ~333 ~66 ~48 ~335 ~68 ~48 dirt
fill ~333 ~69 ~48 ~335 ~69 ~48 grass_block
fill ~320 ~60 ~49 ~321 ~62 ~49 stone
fill ~320 ~63 ~49 ~321 ~65 ~49 dirt
fill ~320 ~66 ~49 ~321 ~66 ~49 grass_block
fill ~322 ~60 ~49 ~322 ~61 ~49 stone
fill ~322 ~62 ~49 ~322 ~64 ~49 dirt
fill ~322 ~65 ~49 ~322 ~65 ~49 grass_block
fill ~323 ~60 ~49 ~325 ~62 ~49 stone
fill ~323 ~63 ~49 ~325 ~65 ~49 dirt
fill ~323 ~66 ~49 ~325 ~66 ~49 grass_block
fill ~326 ~60 ~49 ~330 ~63 ~49 stone
fill ~326 ~64 ~49 ~330 ~66 ~49 dirt
fill ~326 ~67 ~49 ~330 ~67 ~49 grass_block
fill ~331 ~60 ~49 ~332 ~64 ~49 stone
fill ~331 ~65 ~49 ~332 ~67 ~49 dirt
fill ~331 ~68 ~49 ~332 ~68 ~49 grass_block
fill ~333 ~60 ~49 ~334 ~65 ~49 stone
fill ~333 ~66 ~49 ~334 ~68 ~49 dirt
fill ~333 ~69 ~49 ~334 ~69 ~49 grass_block
fill ~335 ~60 ~49 ~335 ~66 ~49 stone
fill ~335 ~67 ~49 ~335 ~69 ~49 dirt
fill ~335 ~70 ~49 ~335 ~70 ~49 grass_block
fill ~320 ~60 ~50 ~320 ~61 ~50 stone
fill ~320 ~62 ~50 ~320 ~64 ~50 dirt
fill ~320 ~65 ~50 ~320 ~65 ~50 grass_block
fill ~321 ~60 ~50 ~323 ~62 ~50 stone
fill ~321 ~63 ~50 ~323 ~65 ~50 dirt
fill ~321 ~66 ~50 ~323 ~66 ~50 grass_block
fill ~324 ~60 ~50 ~325 ~63 ~50 stone
fill ~324 ~64 ~50 ~325 ~66 ~50 dirt
fill ~324 ~67 ~50 ~325 ~67 ~50 grass_block
fill ~326 ~60 ~50 ~327 ~64 ~50 stone
fill ~326 ~65 ~50 ~327 ~67 ~50 dirt
fill ~326 ~68 ~50 ~327 ~68 ~50 grass_block
fill ~328 ~60 ~50 ~329 ~63 ~50 stone
fill ~328 ~64 ~50 ~329 ~66 ~50 dirt
fill ~328 ~67 ~50 ~329 ~67 ~50 grass_block
fill ~330 ~60 ~50 ~331 ~64 ~50 stone
fill ~330 ~65 ~50 ~331 ~67 ~50 dirt
fill ~330 ~68 ~50 ~331 ~68 ~50 grass_block
fill ~332 ~60 ~50 ~335 ~65 ~50 stone
fill ~332 ~66 ~50 ~335 ~68 ~50 dirt
fill ~332 ~69 ~50 ~335 ~69 ~50 grass_block
fill ~320 ~60 ~51 ~321 ~62 ~51 stone
fill ~320 ~63 ~51 ~321 ~65 ~51 dirt
fill ~320 ~66 ~51 ~321 ~66 ~51 grass_block
fill ~322 ~60 ~51 ~324 ~63 ~51 stone
fill ~322 ~64 ~51 ~324 ~66 ~51 dirt
fill ~322 ~67 ~51 ~324 ~67 ~51 grass_block
fill ~325 ~60 ~51 ~330 ~64 ~51 stone
fill ~325 ~65 ~51 ~330 ~67 ~51 dirt
fill ~325 ~68 ~51 ~330 ~68 ~51 grass_block
fill ~331 ~60 ~51 ~335 ~65 ~51 stone
fill ~331 ~66 ~51 ~335 ~68 ~51 dirt
fill ~331 ~69 ~51 ~335 ~69 ~51 grass_block
fill ~320 ~60 ~52 ~322 ~62 ~52 stone
fill ~320 ~63 ~52 ~322 ~65 ~52 dirt
fill ~320 ~66 ~52 ~322 ~66 ~52 grass_block
fill ~323 ~60 ~52 ~324 ~63 ~52 stone
fill ~323 ~64 ~52 ~324 ~66 ~52 dirt
fill ~323 ~67 ~52 ~324 ~67 ~52 grass_block
fill ~325 ~60 ~52 ~329 ~64 ~52 stone
fill ~325 ~65 ~52 ~329 ~67 ~52 dirt
fill ~325 ~68 ~52 ~329 ~68 ~52 grass_block
fill ~330 ~60 ~52 ~335 ~65 ~52 stone
fill ~330 ~66 ~52 ~335 ~68 ~52 dirt
fill ~330 ~69 ~52 ~335 ~69 ~52 grass_block
fill ~320 ~60 ~53 ~322 ~62 ~53 stone
fill ~320 ~63 ~53 ~322 ~65 ~53 dirt
fill ~320 ~66 ~53 ~322 ~66 ~53 grass_block
fill ~323 ~60 ~53 ~324 ~63 ~53 stone
fill ~323 ~64 ~53 ~324 ~66 ~53 dirt
fill ~323 ~67 ~53 ~324 ~67 ~53 grass_block
fill ~325 ~60 ~53 ~328 ~64 ~53 stone
fill ~325 ~65 ~53 ~328 ~67 ~53 dirt
fill ~325 ~68 ~53 ~328 ~68 ~53 grass_block
fill ~329 ~60 ~53 ~335 ~65 ~53 stone
fill ~329 ~66 ~53 ~335 ~68 ~53 dirt
fill ~329 ~69 ~53 ~335 ~69 ~53 grass_block
fill ~320 ~60 ~54 ~322 ~62 ~54 stone
fill ~320 ~63 ~54 ~322 ~65 ~54 dirt
fill ~320 ~66 ~54 ~322 ~66 ~54 grass_block
fill ~323 ~60 ~54 ~325 ~63 ~54 stone
fill ~323 ~64 ~54 ~325 ~66 ~54 dirt
fill ~323 ~67 ~54 ~325 ~67 ~54 grass_block
fill ~326 ~60 ~54 ~329 ~64 ~54 stone
fill ~326 ~65 ~54 ~329 ~67 ~54 dirt
fill ~326 ~68 ~54 ~329 ~68 ~54 grass_block
fill ~330 ~60 ~54 ~330 ~65 ~54 stone
fill ~330 ~66 ~54 ~330 ~68 ~54 dirt
fill ~330 ~69 ~54 ~330 ~69 ~54 grass_block
fill ~331 ~60 ~54 ~331 ~64 ~54 stone
fill ~331 ~65 ~54 ~331 ~67 ~54 dirt
fill ~331 ~68 ~54 ~331 ~68 ~54 grass_block
fill ~332 ~60 ~54 ~332 ~65 ~54 stone
fill ~332 ~66 ~54 ~332 ~68 ~54 dirt
fill ~332 ~69 ~54 ~332 ~69 ~54 grass_block
fill ~333 ~60 ~54 ~333 ~64 ~54 stone
fill ~333 ~65 ~54 ~333 ~67 ~54 dirt
fill ~333 ~68 ~54 ~333 ~68 ~54 grass_block
fill ~334 ~60 ~54 ~335 ~65 ~54 stone
fill ~334 ~66 ~54 ~335 ~68 ~54 dirt
fill ~334 ~69 ~54 ~335 ~69 ~54 grass_block
fill ~320 ~60 ~55 ~322 ~62 ~55 stone
fill ~320 ~63 ~55 ~322 ~65 ~55 dirt
fill ~320 ~66 ~55 ~322 ~66 ~55 grass_block
fill ~323 ~60 ~55 ~323 ~63 ~55 stone
fill ~323 ~64 ~55 ~323 ~66 ~55 dirt
fill ~323 ~67 ~55 ~323 ~67 ~55 grass_block
fill ~324 ~60 ~55 ~334 ~64 ~55 stone
fill ~324 ~65 ~55 ~334 ~67 ~55 dirt
fill ~324 ~68 ~55 ~334 ~68 ~55 grass_block
fill ~335 ~60 ~55 ~335 ~65 ~55 stone
fill ~335 ~66 ~55 ~335 ~68 ~55 dirt
fill ~335 ~69 ~55 ~335 ~69 ~55 grass_block
fill ~320 ~60 ~56 ~322 ~62 ~56 stone
fill ~320 ~63 ~56 ~322 ~65 ~56 dirt
fill ~320 ~66 ~56 ~322 ~66 ~56 grass_block
fill ~323 ~60 ~56 ~323 ~63 ~56 stone
fill ~323 ~64 ~56 ~323 ~66 ~56 dirt
fill ~323 ~67 ~56 ~323 ~67 ~56 grass_block
fill ~324 ~60 ~56 ~334 ~64 ~56 stone
fill ~324 ~65 ~56 ~334 ~67 ~56 dirt
fill ~324 ~68 ~56 ~334 ~68 ~56 grass_block
fill ~335 ~60 ~56 ~335 ~65 ~56 stone
fill ~335 ~66 ~56 ~335 ~68 ~56 dirt
fill ~335 ~69 ~56 ~335 ~69 ~56 grass_block
fill ~320 ~60 ~57 ~321 ~62 ~57 stone
fill ~320 ~63 ~57 ~321 ~65 ~57 dirt
fill ~320 ~66 ~57 ~321 ~66 ~57 grass_block
fill ~322 ~60 ~57 ~323 ~63 ~57 stone
fill ~322 ~64 ~57 ~323 ~66 ~57 dirt
fill ~322 ~67 ~57 ~323 ~67 ~57 grass_block
fill ~324 ~60 ~57 ~334 ~64 ~57 stone
fill ~324 ~65 ~57 ~334 ~67 ~57 dirt
fill ~324 ~68 ~57 ~334 ~68 ~57 grass_block
fill ~335 ~60 ~57 ~335 ~65 ~57 stone
fill ~335 ~66 ~57 ~335 ~68 ~57 dirt
fill ~335 ~69 ~57 ~335 ~69 ~57 grass_block
fill ~320 ~60 ~58 ~321 ~62 ~58 stone
fill ~320 ~63 ~58 ~321 ~65 ~58 dirt
fill ~320 ~66 ~58 ~321 ~66 ~58 grass_block
fill ~322 ~60 ~58 ~323 ~63 ~58 stone
fill ~322 ~64 ~58 ~323 ~66 ~58 dirt
fill ~322 ~67 ~58 ~323 ~67 ~58 grass_block
fill ~324 ~60 ~58 ~328 ~64 ~58 stone
fill ~324 ~65 ~58 ~328 ~67 ~58 dirt
fill ~324 ~68 ~58 ~328 ~68 ~58 grass_block
fill ~329 ~60 ~58 ~330 ~63 ~58 stone
fill ~329 ~64 ~58 ~330 ~66 ~58 dirt
fill ~329 ~67 ~58 ~330 ~67 ~58 grass_block
fill ~331 ~60 ~58 ~333 ~64 ~58 stone
fill ~331 ~65 ~58 ~333 ~67 ~58 dirt
fill ~331 ~68 ~58 ~333 ~68 ~58 grass_block
fill ~334 ~60 ~58 ~335 ~65 ~58 stone
fill ~334 ~66 ~58 ~335 ~68 ~58 dirt
fill ~334 ~69 ~58 ~335 ~69 ~58 grass_block
fill ~320 ~60 ~59 ~320 ~62 ~59 stone
fill ~320 ~63 ~59 ~320 ~65 ~59 dirt
fill ~320 ~66 ~59 ~320 ~66 ~59 grass_block
fill ~321 ~60 ~59 ~323 ~63 ~59 stone
fill ~321 ~64 ~59 ~323 ~66 ~59 dirt
fill ~321 ~67 ~59 ~323 ~67 ~59 grass_block
fill ~324 ~60 ~59 ~327 ~64 ~59 stone
fill ~324 ~65 ~59 ~327 ~67 ~59 dirt
fill ~324 ~68 ~59 ~327 ~68 ~59 grass_block
fill ~328 ~60 ~59 ~330 ~63 ~59 stone
fill ~328 ~64 ~59 ~330 ~66 ~59 dirt
fill ~328 ~67 ~59 ~330 ~67 ~59 grass_block
fill ~331 ~60 ~59 ~333 ~64 ~59 stone
fill ~331 ~65 ~59 ~333 ~67 ~59 dirt
fill ~331 ~68 ~59 ~333 ~68 ~59 grass_block
fill ~334 ~60 ~59 ~335 ~65 ~59 stone
fill ~334 ~66 ~59 ~335 ~68 ~59 dirt
fill ~334 ~69 ~59 ~335 ~69 ~59 grass_block
fill ~320 ~60 ~60 ~320 ~62 ~60 stone
fill ~320 ~63 ~60 ~320 ~65 ~60 dirt
fill ~320 ~66 ~60 ~320 ~66 ~60 grass_block
fill ~321 ~60 ~60 ~329 ~63 ~60 stone
fill ~321 ~64 ~60 ~329 ~66 ~60 dirt
fill ~321 ~67 ~60 ~329 ~67 ~60 grass_block
fill ~330 ~60 ~60 ~333 ~64 ~60 stone
fill ~330 ~65 ~60 ~333 ~67 ~60 dirt
fill ~330 ~68 ~60 ~333 ~68 ~60 grass_block
fill ~334 ~60 ~60 ~335 ~65 ~60 stone
fill ~334 ~66 ~60 ~335 ~68 ~60 dirt
fill ~334 ~69 ~60 ~335 ~69 ~60 grass_block
fill ~320 ~60 ~61 ~320 ~62 ~61 stone
fill ~320 ~63 ~61 ~320 ~65 ~61 dirt
fill ~320 ~66 ~61 ~320 ~66 ~61 grass_block
fill ~321 ~60 ~61 ~328 ~63 ~61 stone
fill ~321 ~64 ~61 ~328 ~66 ~61 dirt
fill ~321 ~67 ~61 ~328 ~67 ~61 grass_block
fill ~329 ~60 ~61 ~335 ~64 ~61 stone
fill ~329 ~65 ~61 ~335 ~67 ~61 dirt
fill ~329 ~68 ~61 ~335 ~68 ~61 grass_block
fill ~320 ~60 ~62 ~320 ~62 ~62 stone
fill ~320 ~63 ~62 ~320 ~65 ~62 dirt
fill ~320 ~66 ~62 ~320 ~66 ~62 grass_block
fill ~321 ~60 ~62 ~327 ~63 ~62 stone
fill ~321 ~64 ~62 ~327 ~66 ~62 dirt
fill ~321 ~67 ~62 ~327 ~67 ~62 grass_block
fill ~328 ~60 ~62 ~335 ~64 ~62 stone
fill ~328 ~65 ~62 ~335 ~67 ~62 dirt
fill ~328 ~68 ~62 ~335 ~68 ~62 grass_block
fill ~320 ~60 ~63 ~320 ~62 ~63 stone
fill ~320 ~63 ~63 ~320 ~65 ~63 dirt
fill ~320 ~66 ~63 ~320 ~66 ~63 grass_block
fill ~321 ~60 ~63 ~327 ~63 ~63 stone
fill ~321 ~64 ~63 ~327 ~66 ~63 dirt
fill ~321 ~67 ~63 ~327 ~67 ~63 grass_block
fill ~328 ~60 ~63 ~335 ~64 ~63 stone
fill ~328 ~65 ~63 ~335 ~67 ~63 dirt
fill ~328 ~68 ~63 ~335 ~68 ~63 grass_block