fill ~224 ~60 ~96 ~237 ~65 ~96 stone
fill ~224 ~66 ~96 ~237 ~68 ~96 dirt
fill ~224 ~69 ~96 ~237 ~69 ~96 grass_block
fill ~238 ~60 ~96 ~239 ~66 ~96 stone
fill ~238 ~67 ~96 ~239 ~69 ~96 dirt
fill ~238 ~70 ~96 ~239 ~70 ~96 grass_block
fill ~224 ~60 ~97 ~224 ~64 ~97 stone
fill ~224 ~65 ~97 ~224 ~67 ~97 dirt
fill ~224 ~68 ~97 ~224 ~68 ~97 grass_block
fill ~225 ~60 ~97 ~231 ~65 ~97 stone
fill ~225 ~66 ~97 ~231 ~68 ~97 dirt
fill ~225 ~69 ~97 ~231 ~69 ~97 grass_block
fill ~232 ~60 ~97 ~235 ~64 ~97 stone
fill ~232 ~65 ~97 ~235 ~67 ~97 dirt
fill ~232 ~68 ~97 ~235 ~68 ~97 grass_block
fill ~236 ~60 ~97 ~238 ~65 ~97 stone
fill ~236 ~66 ~97 ~238 ~68 ~97 dirt
fill ~236 ~69 ~97 ~238 ~69 ~97 grass_block
fill ~239 ~60 ~97 ~239 ~66 ~97 stone
fill ~239 ~67 ~97 ~239 ~69 ~97 dirt
fill ~239 ~70 ~97 ~239 ~70 ~97 grass_block
fill ~224 ~60 ~98 ~225 ~64 ~98 stone
fill ~224 ~65 ~98 ~225 ~67 ~98 dirt
fill ~224 ~68 ~98 ~225 ~68 ~98 grass_block
fill ~226 ~60 ~98 ~230 ~65 ~98 stone
fill ~226 ~66 ~98 ~230 ~68 ~98 dirt
fill ~226 ~69 ~98 ~230 ~69 ~98 grass_block
fill ~231 ~60 ~98 ~236 ~64 ~98 stone
fill ~231 ~65 ~98 ~236 ~67 ~98 dirt
fill ~231 ~68 ~98 ~236 ~68 ~98 grass_block
fill ~237 ~60 ~98 ~239 ~65 ~98 stone
fill ~237 ~66 ~98 ~239 ~68 ~98 dirt
fill ~237 ~69 ~98 ~239 ~69 ~98 grass_block
fill ~224 ~60 ~99 ~227 ~64 ~99 stone
fill ~224 ~65 ~99 ~227 ~67 ~99 dirt
fill ~224 ~68 ~99 ~227 ~68 ~99 grass_block
fill ~228 ~60 ~99 ~230 ~65 ~99 stone
fill ~228 ~66 ~99 ~230 ~68 ~99 dirt
fill ~228 ~69 ~99 ~230 ~69 ~99 grass_block
fill ~231 ~60 ~99 ~237 ~64 ~99 stone
fill ~231 ~65 ~99 ~237 ~67 ~99 dirt
fill ~231 ~68 ~99 ~237 ~68 ~99 grass_block
fill ~238 ~60 ~99 ~239 ~65 ~99 stone
fill ~238 ~66 ~99 ~239 ~68 ~99 dirt
fill ~238 ~69 ~99 ~239 ~69 ~99 grass_block
fill ~224 ~60 ~100 ~224 ~63 ~100 stone
fill ~224 ~64 ~100 ~224 ~66 ~100 dirt
fill ~224 ~67 ~100 ~224 ~67 ~100 grass_block
fill ~225 ~60 ~100 ~228 ~64 ~100 stone
fill ~225 ~65 ~100 ~228 ~67 ~100 dirt
fill ~225 ~68 ~100 ~228 ~68 ~100 grass_block
fill ~229 ~60 ~100 ~230 ~65 ~100 stone
fill ~229 ~66 ~100 ~230 ~68 ~100 dirt
fill ~229 ~69 ~100 ~230 ~69 ~100 grass_block
fill ~231 ~60 ~100 ~232 ~64 ~100 stone
fill ~231 ~65 ~100 ~232 ~67 ~100 dirt
fill ~231 ~68 ~100 ~232 ~68 ~100 grass_block
fill ~233 ~60 ~100 ~235 ~63 ~100 stone
fill ~233 ~64 ~100 ~235 ~66 ~100 dirt
fill ~233 ~67 ~100 ~235 ~67 ~100 grass_block
fill ~236 ~60 ~100 ~238 ~64 ~100 stone
fill ~236 ~65 ~100 ~238 ~67 ~100 dirt
fill ~236 ~68 ~100 ~238 ~68 ~100 grass_block
fill ~239 ~60 ~100 ~239 ~65 ~100 stone
fill ~239 ~66 ~100 ~239 ~68 ~100 dirt
fill ~239 ~69 ~100 ~239 ~69 ~100 grass_block
fill ~224 ~60 ~101 ~226 ~63 ~101 stone
fill ~224 ~64 ~101 ~226 ~66 ~101 dirt
fill ~224 ~67 ~101 ~226 ~67 ~101 grass_block
fill ~227 ~60 ~101 ~233 ~64 ~101 stone
fill ~227 ~65 ~101 ~233 ~67 ~101 dirt
fill ~227 ~68 ~101 ~233 ~68 ~101 grass_block
fill ~234 ~60 ~101 ~236 ~63 ~101 stone
fill ~234 ~64 ~101 ~236 ~66 ~101 dirt
fill ~234 ~67 ~101 ~236 ~67 ~101 grass_block
fill ~237 ~60 ~101 ~239 ~64 ~101 stone
fill ~237 ~65 ~101 ~239 ~67 ~101 dirt
fill ~237 ~68 ~101 ~239 ~68 ~101 grass_block
fill ~224 ~60 ~102 ~228 ~63 ~102 stone
fill ~224 ~64 ~102 ~228 ~66 ~102 dirt
fill ~224 ~67 ~102 ~228 ~67 ~102 grass_block
fill ~229 ~60 ~102 ~233 ~64 ~102 stone
fill ~229 ~65 ~102 ~233 ~67 ~102 dirt
fill ~229 ~68 ~102 ~233 ~68 ~102 grass_block
fill ~234 ~60 ~102 ~237 ~63 ~102 stone
fill ~234 ~64 ~102 ~237 ~66 ~102 dirt
fill ~234 ~67 ~102 ~237 ~67 ~102 grass_block
fill ~238 ~60 ~102 ~239 ~64 ~102 stone
fill ~238 ~65 ~102 ~239 ~67 ~102 dirt
fill ~238 ~68 ~102 ~239 ~68 ~102 grass_block
fill ~224 ~60 ~103 ~229 ~63 ~103 stone
fill ~224 ~64 ~103 ~229 ~66 ~103 dirt
fill ~224 ~67 ~103 ~229 ~67 ~103 grass_block
fill ~230 ~60 ~103 ~233 ~64 ~103 stone
fill ~230 ~65 ~103 ~233 ~67 ~103 dirt
fill ~230 ~68 ~103 ~233 ~68 ~103 grass_block
fill ~234 ~60 ~103 ~237 ~63 ~103 stone
fill ~234 ~64 ~103 ~237 ~66 ~103 dirt
fill ~234 ~67 ~103 ~237 ~67 ~103 grass_block
fill ~238 ~60 ~103 ~239 ~64 ~103 stone
fill ~238 ~65 ~103 ~239 ~67 ~103 dirt
fill ~238 ~68 ~103 ~239 ~68 ~103 grass_block
fill ~224 ~60 ~104 ~224 ~64 ~104 stone
fill ~224 ~65 ~104 ~224 ~67 ~104 dirt
fill ~224 ~68 ~104 ~224 ~68 ~104 grass_block
fill ~225 ~60 ~104 ~238 ~63 ~104 stone
fill ~225 ~64 ~104 ~238 ~66 ~104 dirt
fill ~225 ~67 ~104 ~238 ~67 ~104 grass_block
fill ~239 ~60 ~104 ~239 ~64 ~104 stone
fill ~239 ~65 ~104 ~239 ~67 ~104 dirt
fill ~239 ~68 ~104 ~239 ~68 ~104 grass_block
fill ~224 ~60 ~105 ~225 ~64 ~105 stone
fill ~224 ~65 ~105 ~225 ~67 ~105 dirt
fill ~224 ~68 ~105 ~225 ~68 ~105 grass_block
fill ~226 ~60 ~105 ~239 ~63 ~105 stone
fill ~226 ~64 ~105 ~239 ~66 ~105 dirt
fill ~226 ~67 ~105 ~239 ~67 ~105 grass_block
fill ~224 ~60 ~106 ~226 ~64 ~106 stone
fill ~224 ~65 ~106 ~226 ~67 ~106 dirt
fill ~224 ~68 ~106 ~226 ~68 ~106 grass_block
fill ~227 ~60 ~106 ~239 ~63 ~106 stone
fill ~227 ~64 ~106 ~239 ~66 ~106 dirt
fill ~227 ~67 ~106 ~239 ~67 ~106 grass_block
fill ~224 ~60 ~107 ~224 ~65 ~107 stone
fill ~224 ~66 ~107 ~224 ~68 ~107 dirt
fill ~224 ~69 ~107 ~224 ~69 ~107 grass_block
fill ~225 ~60 ~107 ~227 ~64 ~107 stone
fill ~225 ~65 ~107 ~227 ~67 ~107 dirt
fill ~225 ~68 ~107 ~227 ~68 ~107 grass_block
fill ~228 ~60 ~107 ~239 ~63 ~107 stone
fill ~228 ~64 ~107 ~239 ~66 ~107 dirt
fill ~228 ~67 ~107 ~239 ~67 ~107 grass_block
fill ~224 ~60 ~108 ~224 ~65 ~108 stone
fill ~224 ~66 ~108 ~224 ~68 ~108 dirt
fill ~224 ~69 ~108 ~224 ~69 ~108 grass_block
fill ~225 ~60 ~108 ~229 ~64 ~108 stone
fill ~225 ~65 ~108 ~229 ~67 ~108 dirt
fill ~225 ~68 ~108 ~229 ~68 ~108 grass_block
fill ~230 ~60 ~108 ~239 ~63 ~108 stone
fill ~230 ~64 ~108 ~239 ~66 ~108 dirt
fill ~230 ~67 ~108 ~239 ~67 ~108 grass_block
fill ~224 ~60 ~109 ~228 ~65 ~109 stone
fill ~224 ~66 ~109 ~228 ~68 ~109 dirt
fill ~224 ~69 ~109 ~228 ~69 ~109 grass_block
fill ~229 ~60 ~109 ~233 ~64 ~109 stone
fill ~229 ~65 ~109 ~233 ~67 ~109 dirt
fill ~229 ~68 ~109 ~233 ~68 ~109 grass_block
fill ~234 ~60 ~109 ~236 ~63 ~109 stone
fill ~234 ~64 ~109 ~236 ~66 ~109 dirt
fill ~234 ~67 ~109 ~236 ~67 ~109 grass_block
fill ~237 ~60 ~109 ~237 ~62 ~109 stone
fill ~237 ~63 ~109 ~237 ~65 ~109 dirt
fill ~237 ~66 ~109 ~237 ~66 ~109 grass_block
fill ~238 ~60 ~109 ~239 ~63 ~109 stone
fill ~238 ~64 ~109 ~239 ~66 ~109 dirt
fill ~238 ~67 ~109 ~239 ~67 ~109 grass_block
fill ~224 ~60 ~110 ~225 ~66 ~110 stone
fill ~224 ~67 ~110 ~225 ~69 ~110 dirt
fill ~224 ~70 ~110 ~225 ~70 ~110 grass_block
fill ~226 ~60 ~110 ~232 ~65 ~110 stone
fill ~226 ~66 ~110 ~232 ~68 ~110 dirt
fill ~226 ~69 ~110 ~232 ~69 ~110 grass_block
fill ~233 ~60 ~110 ~235 ~64 ~110 stone
fill ~233 ~65 ~110 ~235 ~67 ~110 dirt
fill ~233 ~68 ~110 ~235 ~68 ~110 grass_block
fill ~236 ~60 ~110 ~237 ~63 ~110 stone
fill ~236 ~64 ~110 ~237 ~66 ~110 dirt
fill ~236 ~67 ~110 ~237 ~67 ~110 grass_block
fill ~238 ~60 ~110 ~238 ~62 ~110 stone
fill ~238 ~63 ~110 ~238 ~65 ~110 dirt
fill ~238 ~66 ~110 ~238 ~66 ~110 grass_block
fill ~239 ~60 ~110 ~239 ~63 ~110 stone
fill ~239 ~64 ~110 ~239 ~66 ~110 dirt
fill ~239 ~67 ~110 ~239 ~67 ~110 grass_block
fill ~224 ~60 ~111 ~226 ~66 ~111 stone
fill ~224 ~67 ~111 ~226 ~69 ~111 dirt
fill ~224 ~70 ~111 ~226 ~70 ~111 grass_block
fill ~227 ~60 ~111 ~233 ~65 ~111 stone
fill ~227 ~66 ~111 ~233 ~68 ~111 dirt
fill ~227 ~69 ~111 ~233 ~69 ~111 grass_block
fill ~234 ~60 ~111 ~236 ~64 ~111 stone
fill ~234 ~65 ~111 ~236 ~67 ~111 dirt
fill ~234 ~68 ~111 ~236 ~68 ~111 grass_block
fill ~237 ~60 ~111 ~239 ~63 ~111 stone
fill ~237 ~64 ~111 ~239 ~66 ~111 dirt
fill ~237 ~67 ~111 ~239 ~67 ~111 grass_block