fill ~272 ~60 ~16 ~274 ~63 ~16 stone
fill ~272 ~64 ~16 ~274 ~66 ~16 dirt
fill ~272 ~67 ~16 ~274 ~67 ~16 grass_block
fill ~275 ~60 ~16 ~284 ~64 ~16 stone
fill ~275 ~65 ~16 ~284 ~67 ~16 dirt
fill ~275 ~68 ~16 ~284 ~68 ~16 grass_block
fill ~285 ~60 ~16 ~287 ~63 ~16 stone
fill ~285 ~64 ~16 ~287 ~66 ~16 dirt
fill ~285 ~67 ~16 ~287 ~67 ~16 grass_block
fill ~272 ~60 ~17 ~275 ~63 ~17 stone
fill ~272 ~64 ~17 ~275 ~66 ~17 dirt
fill ~272 ~67 ~17 ~275 ~67 ~17 grass_block
fill ~276 ~60 ~17 ~280 ~64 ~17 stone
fill ~276 ~65 ~17 ~280 ~67 ~17 dirt
fill ~276 ~68 ~17 ~280 ~68 ~17 grass_block
fill ~281 ~60 ~17 ~287 ~63 ~17 stone
fill ~281 ~64 ~17 ~287 ~66 ~17 dirt
fill ~281 ~67 ~17 ~287 ~67 ~17 grass_block
fill ~272 ~60 ~18 ~275 ~63 ~18 stone
fill ~272 ~64 ~18 ~275 ~66 ~18 dirt
fill ~272 ~67 ~18 ~275 ~67 ~18 grass_block
fill ~276 ~60 ~18 ~276 ~64 ~18 stone
fill ~276 ~65 ~18 ~276 ~67 ~18 dirt
fill ~276 ~68 ~18 ~276 ~68 ~18 grass_block
fill ~277 ~60 ~18 ~287 ~63 ~18 stone
fill ~277 ~64 ~18 ~287 ~66 ~18 dirt
fill ~277 ~67 ~18 ~287 ~67 ~18 grass_block
fill ~272 ~60 ~19 ~272 ~62 ~19 stone
fill ~272 ~63 ~19 ~272 ~65 ~19 dirt
fill ~272 ~66 ~19 ~272 ~66 ~19 grass_block
fill ~273 ~60 ~19 ~287 ~63 ~19 stone
fill ~273 ~64 ~19 ~287 ~66 ~19 dirt
fill ~273 ~67 ~19 ~287 ~67 ~19 grass_block
fill ~272 ~60 ~20 ~272 ~62 ~20 stone
fill ~272 ~63 ~20 ~272 ~65 ~20 dirt
fill ~272 ~66 ~20 ~272 ~66 ~20 grass_block
fill ~273 ~60 ~20 ~287 ~63 ~20 stone
fill ~273 ~64 ~20 ~287 ~66 ~20 dirt
fill ~273 ~67 ~20 ~287 ~67 ~20 grass_block
fill ~272 ~60 ~21 ~273 ~62 ~21 stone
fill ~272 ~63 ~21 ~273 ~65 ~21 dirt
fill ~272 ~66 ~21 ~273 ~66 ~21 grass_block
fill ~274 ~60 ~21 ~286 ~63 ~21 stone
fill ~274 ~64 ~21 ~286 ~66 ~21 dirt
fill ~274 ~67 ~21 ~286 ~67 ~21 grass_block
fill ~287 ~60 ~21 ~287 ~64 ~21 stone
fill ~287 ~65 ~21 ~287 ~67 ~21 dirt
fill ~287 ~68 ~21 ~287 ~68 ~21 grass_block
fill ~272 ~60 ~22 ~275 ~62 ~22 stone
fill ~272 ~63 ~22 ~275 ~65 ~22 dirt
fill ~272 ~66 ~22 ~275 ~66 ~22 grass_block
fill ~276 ~60 ~22 ~287 ~63 ~22 stone
fill ~276 ~64 ~22 ~287 ~66 ~22 dirt
fill ~276 ~67 ~22 ~287 ~67 ~22 grass_block
fill ~272 ~60 ~23 ~274 ~62 ~23 stone
fill ~272 ~63 ~23 ~274 ~65 ~23 dirt
fill ~272 ~66 ~23 ~274 ~66 ~23 grass_block
fill ~275 ~60 ~23 ~286 ~63 ~23 stone
fill ~275 ~64 ~23 ~286 ~66 ~23 dirt
fill ~275 ~67 ~23 ~286 ~67 ~23 grass_block
fill ~287 ~60 ~23 ~287 ~64 ~23 stone
fill ~287 ~65 ~23 ~287 ~67 ~23 dirt
fill ~287 ~68 ~23 ~287 ~68 ~23 grass_block
fill ~272 ~60 ~24 ~276 ~62 ~24 stone
fill ~272 ~63 ~24 ~276 ~65 ~24 dirt
fill ~272 ~66 ~24 ~276 ~66 ~24 grass_block
fill ~277 ~60 ~24 ~278 ~63 ~24 stone
fill ~277 ~64 ~24 ~278 ~66 ~24 dirt
fill ~277 ~67 ~24 ~278 ~67 ~24 grass_block
fill ~279 ~60 ~24 ~280 ~62 ~24 stone
fill ~279 ~63 ~24 ~280 ~65 ~24 dirt
fill ~279 ~66 ~24 ~280 ~66 ~24 grass_block
fill ~281 ~60 ~24 ~285 ~63 ~24 stone
fill ~281 ~64 ~24 ~285 ~66 ~24 dirt
fill ~281 ~67 ~24 ~285 ~67 ~24 grass_block
fill ~286 ~60 ~24 ~287 ~64 ~24 stone
fill ~286 ~65 ~24 ~287 ~67 ~24 dirt
fill ~286 ~68 ~24 ~287 ~68 ~24 grass_block
fill ~272 ~60 ~25 ~279 ~62 ~25 stone
fill ~272 ~63 ~25 ~279 ~65 ~25 dirt
fill ~272 ~66 ~25 ~279 ~66 ~25 grass_block
fill ~280 ~60 ~25 ~285 ~63 ~25 stone
fill ~280 ~64 ~25 ~285 ~66 ~25 dirt
fill ~280 ~67 ~25 ~285 ~67 ~25 grass_block
fill ~286 ~60 ~25 ~287 ~64 ~25 stone
fill ~286 ~65 ~25 ~287 ~67 ~25 dirt
fill ~286 ~68 ~25 ~287 ~68 ~25 grass_block
fill ~272 ~60 ~26 ~279 ~62 ~26 stone
fill ~272 ~63 ~26 ~279 ~65 ~26 dirt
fill ~272 ~66 ~26 ~279 ~66 ~26 grass_block
fill ~280 ~60 ~26 ~284 ~63 ~26 stone
fill ~280 ~64 ~26 ~284 ~66 ~26 dirt
fill ~280 ~67 ~26 ~284 ~67 ~26 grass_block
fill ~285 ~60 ~26 ~287 ~64 ~26 stone
fill ~285 ~65 ~26 ~287 ~67 ~26 dirt
fill ~285 ~68 ~26 ~287 ~68 ~26 grass_block
fill ~272 ~60 ~27 ~279 ~62 ~27 stone
fill ~272 ~63 ~27 ~279 ~65 ~27 dirt
fill ~272 ~66 ~27 ~279 ~66 ~27 grass_block
fill ~280 ~60 ~27 ~283 ~63 ~27 stone
fill ~280 ~64 ~27 ~283 ~66 ~27 dirt
fill ~280 ~67 ~27 ~283 ~67 ~27 grass_block
fill ~284 ~60 ~27 ~287 ~64 ~27 stone
fill ~284 ~65 ~27 ~287 ~67 ~27 dirt
fill ~284 ~68 ~27 ~287 ~68 ~27 grass_block
fill ~272 ~60 ~28 ~279 ~62 ~28 stone
fill ~272 ~63 ~28 ~279 ~65 ~28 dirt
fill ~272 ~66 ~28 ~279 ~66 ~28 grass_block
fill ~280 ~60 ~28 ~284 ~63 ~28 stone
fill ~280 ~64 ~28 ~284 ~66 ~28 dirt
fill ~280 ~67 ~28 ~284 ~67 ~28 grass_block
fill ~285 ~60 ~28 ~287 ~64 ~28 stone
fill ~285 ~65 ~28 ~287 ~67 ~28 dirt
fill ~285 ~68 ~28 ~287 ~68 ~28 grass_block
fill ~272 ~60 ~29 ~279 ~62 ~29 stone
fill ~272 ~63 ~29 ~279 ~65 ~29 dirt
fill ~272 ~66 ~29 ~279 ~66 ~29 grass_block
fill ~280 ~60 ~29 ~284 ~63 ~29 stone
fill ~280 ~64 ~29 ~284 ~66 ~29 dirt
fill ~280 ~67 ~29 ~284 ~67 ~29 grass_block
fill ~285 ~60 ~29 ~286 ~64 ~29 stone
fill ~285 ~65 ~29 ~286 ~67 ~29 dirt
fill ~285 ~68 ~29 ~286 ~68 ~29 grass_block
fill ~287 ~60 ~29 ~287 ~63 ~29 stone
fill ~287 ~64 ~29 ~287 ~66 ~29 dirt
fill ~287 ~67 ~29 ~287 ~67 ~29 grass_block
fill ~272 ~60 ~30 ~278 ~62 ~30 stone
fill ~272 ~63 ~30 ~278 ~65 ~30 dirt
fill ~272 ~66 ~30 ~278 ~66 ~30 grass_block
fill ~279 ~60 ~30 ~285 ~63 ~30 stone
fill ~279 ~64 ~30 ~285 ~66 ~30 dirt
fill ~279 ~67 ~30 ~285 ~67 ~30 grass_block
fill ~286 ~60 ~30 ~286 ~64 ~30 stone
fill ~286 ~65 ~30 ~286 ~67 ~30 dirt
fill ~286 ~68 ~30 ~286 ~68 ~30 grass_block
fill ~287 ~60 ~30 ~287 ~63 ~30 stone
fill ~287 ~64 ~30 ~287 ~66 ~30 dirt
fill ~287 ~67 ~30 ~287 ~67 ~30 grass_block
fill ~272 ~60 ~31 ~278 ~62 ~31 stone
fill ~272 ~63 ~31 ~278 ~65 ~31 dirt
fill ~272 ~66 ~31 ~278 ~66 ~31 grass_block
fill ~279 ~60 ~31 ~287 ~63 ~31 stone
fill ~279 ~64 ~31 ~287 ~66 ~31 dirt
fill ~279 ~67 ~31 ~287 ~67 ~31 grass_block