fill ~464 ~60 ~80 ~469 ~63 ~80 stone
fill ~464 ~64 ~80 ~469 ~66 ~80 dirt
fill ~464 ~67 ~80 ~469 ~67 ~80 grass_block
fill ~464 ~60 ~81 ~469 ~63 ~81 stone
fill ~464 ~64 ~81 ~469 ~66 ~81 dirt
fill ~464 ~67 ~81 ~469 ~67 ~81 grass_block
fill ~464 ~60 ~82 ~464 ~62 ~82 stone
fill ~464 ~63 ~82 ~464 ~65 ~82 dirt
fill ~464 ~66 ~82 ~464 ~66 ~82 grass_block
fill ~465 ~60 ~82 ~469 ~63 ~82 stone
fill ~465 ~64 ~82 ~469 ~66 ~82 dirt
fill ~465 ~67 ~82 ~469 ~67 ~82 grass_block
fill ~464 ~60 ~83 ~464 ~63 ~83 stone
fill ~464 ~64 ~83 ~464 ~66 ~83 dirt
fill ~464 ~67 ~83 ~464 ~67 ~83 grass_block
fill ~465 ~60 ~83 ~465 ~62 ~83 stone
fill ~465 ~63 ~83 ~465 ~65 ~83 dirt
fill ~465 ~66 ~83 ~465 ~66 ~83 grass_block
fill ~466 ~60 ~83 ~469 ~63 ~83 stone
fill ~466 ~64 ~83 ~469 ~66 ~83 dirt
fill ~466 ~67 ~83 ~469 ~67 ~83 grass_block
fill ~464 ~60 ~84 ~464 ~63 ~84 stone
fill ~464 ~64 ~84 ~464 ~66 ~84 dirt
fill ~464 ~67 ~84 ~464 ~67 ~84 grass_block
fill ~465 ~60 ~84 ~467 ~62 ~84 stone
fill ~465 ~63 ~84 ~467 ~65 ~84 dirt
fill ~465 ~66 ~84 ~467 ~66 ~84 grass_block
fill ~468 ~60 ~84 ~468 ~63 ~84 stone
fill ~468 ~64 ~84 ~468 ~66 ~84 dirt
fill ~468 ~67 ~84 ~468 ~67 ~84 grass_block
fill ~469 ~60 ~84 ~469 ~62 ~84 stone
fill ~469 ~63 ~84 ~469 ~65 ~84 dirt
fill ~469 ~66 ~84 ~469 ~66 ~84 grass_block
fill ~464 ~60 ~85 ~465 ~63 ~85 stone
fill ~464 ~64 ~85 ~465 ~66 ~85 dirt
fill ~464 ~67 ~85 ~465 ~67 ~85 grass_block
fill ~466 ~60 ~85 ~469 ~62 ~85 stone
fill ~466 ~63 ~85 ~469 ~65 ~85 dirt
fill ~466 ~66 ~85 ~469 ~66 ~85 grass_block
fill ~464 ~60 ~86 ~466 ~63 ~86 stone
fill ~464 ~64 ~86 ~466 ~66 ~86 dirt
fill ~464 ~67 ~86 ~466 ~67 ~86 grass_block
fill ~467 ~60 ~86 ~469 ~62 ~86 stone
fill ~467 ~63 ~86 ~469 ~65 ~86 dirt
fill ~467 ~66 ~86 ~469 ~66 ~86 grass_block
fill ~464 ~60 ~87 ~466 ~63 ~87 stone
fill ~464 ~64 ~87 ~466 ~66 ~87 dirt
fill ~464 ~67 ~87 ~466 ~67 ~87 grass_block
fill ~467 ~60 ~87 ~469 ~62 ~87 stone
fill ~467 ~63 ~87 ~469 ~65 ~87 dirt
fill ~467 ~66 ~87 ~469 ~66 ~87 grass_block
fill ~464 ~60 ~88 ~466 ~63 ~88 stone
fill ~464 ~64 ~88 ~466 ~66 ~88 dirt
fill ~464 ~67 ~88 ~466 ~67 ~88 grass_block
fill ~467 ~60 ~88 ~469 ~62 ~88 stone
fill ~467 ~63 ~88 ~469 ~65 ~88 dirt
fill ~467 ~66 ~88 ~469 ~66 ~88 grass_block
fill ~464 ~60 ~89 ~466 ~63 ~89 stone
fill ~464 ~64 ~89 ~466 ~66 ~89 dirt
fill ~464 ~67 ~89 ~466 ~67 ~89 grass_block
fill ~467 ~60 ~89 ~469 ~62 ~89 stone
fill ~467 ~63 ~89 ~469 ~65 ~89 dirt
fill ~467 ~66 ~89 ~469 ~66 ~89 grass_block
fill ~464 ~60 ~90 ~466 ~63 ~90 stone
fill ~464 ~64 ~90 ~466 ~66 ~90 dirt
fill ~464 ~67 ~90 ~466 ~67 ~90 grass_block
fill ~467 ~60 ~90 ~469 ~62 ~90 stone
fill ~467 ~63 ~90 ~469 ~65 ~90 dirt
fill ~467 ~66 ~90 ~469 ~66 ~90 grass_block
fill ~464 ~60 ~91 ~466 ~63 ~91 stone
fill ~464 ~64 ~91 ~466 ~66 ~91 dirt
fill ~464 ~67 ~91 ~466 ~67 ~91 grass_block
fill ~467 ~60 ~91 ~469 ~62 ~91 stone
fill ~467 ~63 ~91 ~469 ~65 ~91 dirt
fill ~467 ~66 ~91 ~469 ~66 ~91 grass_block
fill ~464 ~60 ~92 ~464 ~64 ~92 stone
fill ~464 ~65 ~92 ~464 ~67 ~92 dirt
fill ~464 ~68 ~92 ~464 ~68 ~92 grass_block
fill ~465 ~60 ~92 ~467 ~63 ~92 stone
fill ~465 ~64 ~92 ~467 ~66 ~92 dirt
fill ~465 ~67 ~92 ~467 ~67 ~92 grass_block
fill ~468 ~60 ~92 ~469 ~62 ~92 stone
fill ~468 ~63 ~92 ~469 ~65 ~92 dirt
fill ~468 ~66 ~92 ~469 ~66 ~92 grass_block
fill ~464 ~60 ~93 ~467 ~63 ~93 stone
fill ~464 ~64 ~93 ~467 ~66 ~93 dirt
fill ~464 ~67 ~93 ~467 ~67 ~93 grass_block
fill ~468 ~60 ~93 ~469 ~62 ~93 stone
fill ~468 ~63 ~93 ~469 ~65 ~93 dirt
fill ~468 ~66 ~93 ~469 ~66 ~93 grass_block
fill ~464 ~60 ~94 ~464 ~64 ~94 stone
fill ~464 ~65 ~94 ~464 ~67 ~94 dirt
fill ~464 ~68 ~94 ~464 ~68 ~94 grass_block
fill ~465 ~60 ~94 ~467 ~63 ~94 stone
fill ~465 ~64 ~94 ~467 ~66 ~94 dirt
fill ~465 ~67 ~94 ~467 ~67 ~94 grass_block
fill ~468 ~60 ~94 ~469 ~62 ~94 stone
fill ~468 ~63 ~94 ~469 ~65 ~94 dirt
fill ~468 ~66 ~94 ~469 ~66 ~94 grass_block
fill ~464 ~60 ~95 ~464 ~64 ~95 stone
fill ~464 ~65 ~95 ~464 ~67 ~95 dirt
fill ~464 ~68 ~95 ~464 ~68 ~95 grass_block
fill ~465 ~60 ~95 ~467 ~63 ~95 stone
fill ~465 ~64 ~95 ~467 ~66 ~95 dirt
fill ~465 ~67 ~95 ~467 ~67 ~95 grass_block
fill ~468 ~60 ~95 ~469 ~62 ~95 stone
fill ~468 ~63 ~95 ~469 ~65 ~95 dirt
fill ~468 ~66 ~95 ~469 ~66 ~95 grass_block