fill ~336 ~60 ~64 ~339 ~64 ~64 stone
fill ~336 ~65 ~64 ~339 ~67 ~64 dirt
fill ~336 ~68 ~64 ~339 ~68 ~64 grass_block
fill ~340 ~60 ~64 ~348 ~65 ~64 stone
fill ~340 ~66 ~64 ~348 ~68 ~64 dirt
fill ~340 ~69 ~64 ~348 ~69 ~64 grass_block
fill ~349 ~60 ~64 ~351 ~64 ~64 stone
fill ~349 ~65 ~64 ~351 ~67 ~64 dirt
fill ~349 ~68 ~64 ~351 ~68 ~64 grass_block
fill ~336 ~60 ~65 ~336 ~63 ~65 stone
fill ~336 ~64 ~65 ~336 ~66 ~65 dirt
fill ~336 ~67 ~65 ~336 ~67 ~65 grass_block
fill ~337 ~60 ~65 ~340 ~64 ~65 stone
fill ~337 ~65 ~65 ~340 ~67 ~65 dirt
fill ~337 ~68 ~65 ~340 ~68 ~65 grass_block
fill ~341 ~60 ~65 ~348 ~65 ~65 stone
fill ~341 ~66 ~65 ~348 ~68 ~65 dirt
fill ~341 ~69 ~65 ~348 ~69 ~65 grass_block
fill ~349 ~60 ~65 ~351 ~64 ~65 stone
fill ~349 ~65 ~65 ~351 ~67 ~65 dirt
fill ~349 ~68 ~65 ~351 ~68 ~65 grass_block
fill ~336 ~60 ~66 ~337 ~63 ~66 stone
fill ~336 ~64 ~66 ~337 ~66 ~66 dirt
fill ~336 ~67 ~66 ~337 ~67 ~66 grass_block
fill ~338 ~60 ~66 ~341 ~64 ~66 stone
fill ~338 ~65 ~66 ~341 ~67 ~66 dirt
fill ~338 ~68 ~66 ~341 ~68 ~66 grass_block
fill ~342 ~60 ~66 ~349 ~65 ~66 stone
fill ~342 ~66 ~66 ~349 ~68 ~66 dirt
fill ~342 ~69 ~66 ~349 ~69 ~66 grass_block
fill ~350 ~60 ~66 ~351 ~64 ~66 stone
fill ~350 ~65 ~66 ~351 ~67 ~66 dirt
fill ~350 ~68 ~66 ~351 ~68 ~66 grass_block
fill ~336 ~60 ~67 ~338 ~63 ~67 stone
fill ~336 ~64 ~67 ~338 ~66 ~67 dirt
fill ~336 ~67 ~67 ~338 ~67 ~67 grass_block
fill ~339 ~60 ~67 ~342 ~64 ~67 stone
fill ~339 ~65 ~67 ~342 ~67 ~67 dirt
fill ~339 ~68 ~67 ~342 ~68 ~67 grass_block
fill ~343 ~60 ~67 ~351 ~65 ~67 stone
fill ~343 ~66 ~67 ~351 ~68 ~67 dirt
fill ~343 ~69 ~67 ~351 ~69 ~67 grass_block
fill ~336 ~60 ~68 ~338 ~63 ~68 stone
fill ~336 ~64 ~68 ~338 ~66 ~68 dirt
fill ~336 ~67 ~68 ~338 ~67 ~68 grass_block
fill ~339 ~60 ~68 ~344 ~64 ~68 stone
fill ~339 ~65 ~68 ~344 ~67 ~68 dirt
fill ~339 ~68 ~68 ~344 ~68 ~68 grass_block
fill ~345 ~60 ~68 ~351 ~65 ~68 stone
fill ~345 ~66 ~68 ~351 ~68 ~68 dirt
fill ~345 ~69 ~68 ~351 ~69 ~68 grass_block
fill ~336 ~60 ~69 ~339 ~63 ~69 stone
fill ~336 ~64 ~69 ~339 ~66 ~69 dirt
fill ~336 ~67 ~69 ~339 ~67 ~69 grass_block
fill ~340 ~60 ~69 ~346 ~64 ~69 stone
fill ~340 ~65 ~69 ~346 ~67 ~69 dirt
fill ~340 ~68 ~69 ~346 ~68 ~69 grass_block
fill ~347 ~60 ~69 ~351 ~65 ~69 stone
fill ~347 ~66 ~69 ~351 ~68 ~69 dirt
fill ~347 ~69 ~69 ~351 ~69 ~69 grass_block
fill ~336 ~60 ~70 ~344 ~63 ~70 stone
fill ~336 ~64 ~70 ~344 ~66 ~70 dirt
fill ~336 ~67 ~70 ~344 ~67 ~70 grass_block
fill ~345 ~60 ~70 ~346 ~64 ~70 stone
fill ~345 ~65 ~70 ~346 ~67 ~70 dirt
fill ~345 ~68 ~70 ~346 ~68 ~70 grass_block
fill ~347 ~60 ~70 ~351 ~65 ~70 stone
fill ~347 ~66 ~70 ~351 ~68 ~70 dirt
fill ~347 ~69 ~70 ~351 ~69 ~70 grass_block
fill ~336 ~60 ~71 ~344 ~63 ~71 stone
fill ~336 ~64 ~71 ~344 ~66 ~71 dirt
fill ~336 ~67 ~71 ~344 ~67 ~71 grass_block
fill ~345 ~60 ~71 ~347 ~64 ~71 stone
fill ~345 ~65 ~71 ~347 ~67 ~71 dirt
fill ~345 ~68 ~71 ~347 ~68 ~71 grass_block
fill ~348 ~60 ~71 ~351 ~65 ~71 stone
fill ~348 ~66 ~71 ~351 ~68 ~71 dirt
fill ~348 ~69 ~71 ~351 ~69 ~71 grass_block
fill ~336 ~60 ~72 ~344 ~63 ~72 stone
fill ~336 ~64 ~72 ~344 ~66 ~72 dirt
fill ~336 ~67 ~72 ~344 ~67 ~72 grass_block
fill ~345 ~60 ~72 ~348 ~64 ~72 stone
fill ~345 ~65 ~72 ~348 ~67 ~72 dirt
fill ~345 ~68 ~72 ~348 ~68 ~72 grass_block
fill ~349 ~60 ~72 ~351 ~65 ~72 stone
fill ~349 ~66 ~72 ~351 ~68 ~72 dirt
fill ~349 ~69 ~72 ~351 ~69 ~72 grass_block
fill ~336 ~60 ~73 ~337 ~62 ~73 stone
fill ~336 ~63 ~73 ~337 ~65 ~73 dirt
fill ~336 ~66 ~73 ~337 ~66 ~73 grass_block
fill ~338 ~60 ~73 ~344 ~63 ~73 stone
fill ~338 ~64 ~73 ~344 ~66 ~73 dirt
fill ~338 ~67 ~73 ~344 ~67 ~73 grass_block
fill ~345 ~60 ~73 ~350 ~64 ~73 stone
fill ~345 ~65 ~73 ~350 ~67 ~73 dirt
fill ~345 ~68 ~73 ~350 ~68 ~73 grass_block
fill ~351 ~60 ~73 ~351 ~65 ~73 stone
fill ~351 ~66 ~73 ~351 ~68 ~73 dirt
fill ~351 ~69 ~73 ~351 ~69 ~73 grass_block
fill ~336 ~60 ~74 ~342 ~62 ~74 stone
fill ~336 ~63 ~74 ~342 ~65 ~74 dirt
fill ~336 ~66 ~74 ~342 ~66 ~74 grass_block
fill ~343 ~60 ~74 ~344 ~63 ~74 stone
fill ~343 ~64 ~74 ~344 ~66 ~74 dirt
fill ~343 ~67 ~74 ~344 ~67 ~74 grass_block
fill ~345 ~60 ~74 ~350 ~64 ~74 stone
fill ~345 ~65 ~74 ~350 ~67 ~74 dirt
fill ~345 ~68 ~74 ~350 ~68 ~74 grass_block
fill ~351 ~60 ~74 ~351 ~65 ~74 stone
fill ~351 ~66 ~74 ~351 ~68 ~74 dirt
fill ~351 ~69 ~74 ~351 ~69 ~74 grass_block
fill ~336 ~60 ~75 ~340 ~62 ~75 stone
fill ~336 ~63 ~75 ~340 ~65 ~75 dirt
fill ~336 ~66 ~75 ~340 ~66 ~75 grass_block
fill ~341 ~60 ~75 ~343 ~63 ~75 stone
fill ~341 ~64 ~75 ~343 ~66 ~75 dirt
fill ~341 ~67 ~75 ~343 ~67 ~75 grass_block
fill ~344 ~60 ~75 ~351 ~64 ~75 stone
fill ~344 ~65 ~75 ~351 ~67 ~75 dirt
fill ~344 ~68 ~75 ~351 ~68 ~75 grass_block
fill ~336 ~60 ~76 ~336 ~62 ~76 stone
fill ~336 ~63 ~76 ~336 ~65 ~76 dirt
fill ~336 ~66 ~76 ~336 ~66 ~76 grass_block
fill ~337 ~60 ~76 ~338 ~63 ~76 stone
fill ~337 ~64 ~76 ~338 ~66 ~76 dirt
fill ~337 ~67 ~76 ~338 ~67 ~76 grass_block
fill ~339 ~60 ~76 ~339 ~62 ~76 stone
fill ~339 ~63 ~76 ~339 ~65 ~76 dirt
fill ~339 ~66 ~76 ~339 ~66 ~76 grass_block
fill ~340 ~60 ~76 ~341 ~63 ~76 stone
fill ~340 ~64 ~76 ~341 ~66 ~76 dirt
fill ~340 ~67 ~76 ~341 ~67 ~76 grass_block
fill ~342 ~60 ~76 ~351 ~64 ~76 stone
fill ~342 ~65 ~76 ~351 ~67 ~76 dirt
fill ~342 ~68 ~76 ~351 ~68 ~76 grass_block
fill ~336 ~60 ~77 ~341 ~63 ~77 stone
fill ~336 ~64 ~77 ~341 ~66 ~77 dirt
fill ~336 ~67 ~77 ~341 ~67 ~77 grass_block
fill ~342 ~60 ~77 ~351 ~64 ~77 stone
fill ~342 ~65 ~77 ~351 ~67 ~77 dirt
fill ~342 ~68 ~77 ~351 ~68 ~77 grass_block
fill ~336 ~60 ~78 ~342 ~63 ~78 stone
fill ~336 ~64 ~78 ~342 ~66 ~78 dirt
fill ~336 ~67 ~78 ~342 ~67 ~78 grass_block
fill ~343 ~60 ~78 ~351 ~64 ~78 stone
fill ~343 ~65 ~78 ~351 ~67 ~78 dirt
fill ~343 ~68 ~78 ~351 ~68 ~78 grass_block
fill ~336 ~60 ~79 ~339 ~63 ~79 stone
fill ~336 ~64 ~79 ~339 ~66 ~79 dirt
fill ~336 ~67 ~79 ~339 ~67 ~79 grass_block
fill ~340 ~60 ~79 ~345 ~64 ~79 stone
fill ~340 ~65 ~79 ~345 ~67 ~79 dirt
fill ~340 ~68 ~79 ~345 ~68 ~79 grass_block
fill ~346 ~60 ~79 ~347 ~63 ~79 stone
fill ~346 ~64 ~79 ~347 ~66 ~79 dirt
fill ~346 ~67 ~79 ~347 ~67 ~79 grass_block
fill ~348 ~60 ~79 ~351 ~64 ~79 stone
fill ~348 ~65 ~79 ~351 ~67 ~79 dirt
fill ~348 ~68 ~79 ~351 ~68 ~79 grass_block