fill ~304 ~60 ~0 ~306 ~63 ~0 stone
fill ~304 ~64 ~0 ~306 ~66 ~0 dirt
fill ~304 ~67 ~0 ~306 ~67 ~0 grass_block
fill ~307 ~60 ~0 ~307 ~64 ~0 stone
fill ~307 ~65 ~0 ~307 ~67 ~0 dirt
fill ~307 ~68 ~0 ~307 ~68 ~0 grass_block
fill ~308 ~60 ~0 ~309 ~63 ~0 stone
fill ~308 ~64 ~0 ~309 ~66 ~0 dirt
fill ~308 ~67 ~0 ~309 ~67 ~0 grass_block
fill ~310 ~60 ~0 ~311 ~64 ~0 stone
fill ~310 ~65 ~0 ~311 ~67 ~0 dirt
fill ~310 ~68 ~0 ~311 ~68 ~0 grass_block
fill ~312 ~60 ~0 ~313 ~63 ~0 stone
fill ~312 ~64 ~0 ~313 ~66 ~0 dirt
fill ~312 ~67 ~0 ~313 ~67 ~0 grass_block
fill ~314 ~60 ~0 ~316 ~64 ~0 stone
fill ~314 ~65 ~0 ~316 ~67 ~0 dirt
fill ~314 ~68 ~0 ~316 ~68 ~0 grass_block
fill ~317 ~60 ~0 ~319 ~65 ~0 stone
fill ~317 ~66 ~0 ~319 ~68 ~0 dirt
fill ~317 ~69 ~0 ~319 ~69 ~0 grass_block
fill ~304 ~60 ~1 ~304 ~64 ~1 stone
fill ~304 ~65 ~1 ~304 ~67 ~1 dirt
fill ~304 ~68 ~1 ~304 ~68 ~1 grass_block
fill ~305 ~60 ~1 ~313 ~63 ~1 stone
fill ~305 ~64 ~1 ~313 ~66 ~1 dirt
fill ~305 ~67 ~1 ~313 ~67 ~1 grass_block
fill ~314 ~60 ~1 ~318 ~64 ~1 stone
fill ~314 ~65 ~1 ~318 ~67 ~1 dirt
fill ~314 ~68 ~1 ~318 ~68 ~1 grass_block
fill ~319 ~60 ~1 ~319 ~65 ~1 stone
fill ~319 ~66 ~1 ~319 ~68 ~1 dirt
fill ~319 ~69 ~1 ~319 ~69 ~1 grass_block
fill ~304 ~60 ~2 ~305 ~65 ~2 stone
fill ~304 ~66 ~2 ~305 ~68 ~2 dirt
fill ~304 ~69 ~2 ~305 ~69 ~2 grass_block
fill ~306 ~60 ~2 ~308 ~64 ~2 stone
fill ~306 ~65 ~2 ~308 ~67 ~2 dirt
fill ~306 ~68 ~2 ~308 ~68 ~2 grass_block
fill ~309 ~60 ~2 ~314 ~63 ~2 stone
fill ~309 ~64 ~2 ~314 ~66 ~2 dirt
fill ~309 ~67 ~2 ~314 ~67 ~2 grass_block
fill ~315 ~60 ~2 ~319 ~64 ~2 stone
fill ~315 ~65 ~2 ~319 ~67 ~2 dirt
fill ~315 ~68 ~2 ~319 ~68 ~2 grass_block
fill ~304 ~60 ~3 ~307 ~65 ~3 stone
fill ~304 ~66 ~3 ~307 ~68 ~3 dirt
fill ~304 ~69 ~3 ~307 ~69 ~3 grass_block
fill ~308 ~60 ~3 ~310 ~64 ~3 stone
fill ~308 ~65 ~3 ~310 ~67 ~3 dirt
fill ~308 ~68 ~3 ~310 ~68 ~3 grass_block
fill ~311 ~60 ~3 ~317 ~63 ~3 stone
fill ~311 ~64 ~3 ~317 ~66 ~3 dirt
fill ~311 ~67 ~3 ~317 ~67 ~3 grass_block
fill ~318 ~60 ~3 ~319 ~64 ~3 stone
fill ~318 ~65 ~3 ~319 ~67 ~3 dirt
fill ~318 ~68 ~3 ~319 ~68 ~3 grass_block
fill ~304 ~60 ~4 ~309 ~65 ~4 stone
fill ~304 ~66 ~4 ~309 ~68 ~4 dirt
fill ~304 ~69 ~4 ~309 ~69 ~4 grass_block
fill ~310 ~60 ~4 ~313 ~64 ~4 stone
fill ~310 ~65 ~4 ~313 ~67 ~4 dirt
fill ~310 ~68 ~4 ~313 ~68 ~4 grass_block
fill ~314 ~60 ~4 ~319 ~63 ~4 stone
fill ~314 ~64 ~4 ~319 ~66 ~4 dirt
fill ~314 ~67 ~4 ~319 ~67 ~4 grass_block
fill ~304 ~60 ~5 ~312 ~65 ~5 stone
fill ~304 ~66 ~5 ~312 ~68 ~5 dirt
fill ~304 ~69 ~5 ~312 ~69 ~5 grass_block
fill ~313 ~60 ~5 ~316 ~64 ~5 stone
fill ~313 ~65 ~5 ~316 ~67 ~5 dirt
fill ~313 ~68 ~5 ~316 ~68 ~5 grass_block
fill ~317 ~60 ~5 ~319 ~63 ~5 stone
fill ~317 ~64 ~5 ~319 ~66 ~5 dirt
fill ~317 ~67 ~5 ~319 ~67 ~5 grass_block
fill ~304 ~60 ~6 ~315 ~65 ~6 stone
fill ~304 ~66 ~6 ~315 ~68 ~6 dirt
fill ~304 ~69 ~6 ~315 ~69 ~6 grass_block
fill ~316 ~60 ~6 ~317 ~64 ~6 stone
fill ~316 ~65 ~6 ~317 ~67 ~6 dirt
fill ~316 ~68 ~6 ~317 ~68 ~6 grass_block
fill ~318 ~60 ~6 ~319 ~63 ~6 stone
fill ~318 ~64 ~6 ~319 ~66 ~6 dirt
fill ~318 ~67 ~6 ~319 ~67 ~6 grass_block
fill ~304 ~60 ~7 ~317 ~65 ~7 stone
fill ~304 ~66 ~7 ~317 ~68 ~7 dirt
fill ~304 ~69 ~7 ~317 ~69 ~7 grass_block
fill ~318 ~60 ~7 ~319 ~64 ~7 stone
fill ~318 ~65 ~7 ~319 ~67 ~7 dirt
fill ~318 ~68 ~7 ~319 ~68 ~7 grass_block
fill ~304 ~60 ~8 ~319 ~65 ~8 stone
fill ~304 ~66 ~8 ~319 ~68 ~8 dirt
fill ~304 ~69 ~8 ~319 ~69 ~8 grass_block
fill ~304 ~60 ~9 ~319 ~65 ~9 stone
fill ~304 ~66 ~9 ~319 ~68 ~9 dirt
fill ~304 ~69 ~9 ~319 ~69 ~9 grass_block
fill ~304 ~60 ~10 ~319 ~65 ~10 stone
fill ~304 ~66 ~10 ~319 ~68 ~10 dirt
fill ~304 ~69 ~10 ~319 ~69 ~10 grass_block
fill ~304 ~60 ~11 ~319 ~65 ~11 stone
fill ~304 ~66 ~11 ~319 ~68 ~11 dirt
fill ~304 ~69 ~11 ~319 ~69 ~11 grass_block
fill ~304 ~60 ~12 ~315 ~65 ~12 stone
fill ~304 ~66 ~12 ~315 ~68 ~12 dirt
fill ~304 ~69 ~12 ~315 ~69 ~12 grass_block
fill ~316 ~60 ~12 ~318 ~64 ~12 stone
fill ~316 ~65 ~12 ~318 ~67 ~12 dirt
fill ~316 ~68 ~12 ~318 ~68 ~12 grass_block
fill ~319 ~60 ~12 ~319 ~65 ~12 stone
fill ~319 ~66 ~12 ~319 ~68 ~12 dirt
fill ~319 ~69 ~12 ~319 ~69 ~12 grass_block
fill ~304 ~60 ~13 ~314 ~65 ~13 stone
fill ~304 ~66 ~13 ~314 ~68 ~13 dirt
fill ~304 ~69 ~13 ~314 ~69 ~13 grass_block
fill ~315 ~60 ~13 ~319 ~64 ~13 stone
fill ~315 ~65 ~13 ~319 ~67 ~13 dirt
fill ~315 ~68 ~13 ~319 ~68 ~13 grass_block
fill ~304 ~60 ~14 ~304 ~64 ~14 stone
fill ~304 ~65 ~14 ~304 ~67 ~14 dirt
fill ~304 ~68 ~14 ~304 ~68 ~14 grass_block
fill ~305 ~60 ~14 ~313 ~65 ~14 stone
fill ~305 ~66 ~14 ~313 ~68 ~14 dirt
fill ~305 ~69 ~14 ~313 ~69 ~14 grass_block
fill ~314 ~60 ~14 ~319 ~64 ~14 stone
fill ~314 ~65 ~14 ~319 ~67 ~14 dirt
fill ~314 ~68 ~14 ~319 ~68 ~14 grass_block
fill ~304 ~60 ~15 ~304 ~64 ~15 stone
fill ~304 ~65 ~15 ~304 ~67 ~15 dirt
fill ~304 ~68 ~15 ~304 ~68 ~15 grass_block
fill ~305 ~60 ~15 ~313 ~65 ~15 stone
fill ~305 ~66 ~15 ~313 ~68 ~15 dirt
fill ~305 ~69 ~15 ~313 ~69 ~15 grass_block
fill ~314 ~60 ~15 ~319 ~64 ~15 stone
fill ~314 ~65 ~15 ~319 ~67 ~15 dirt
fill ~314 ~68 ~15 ~319 ~68 ~15 grass_block