fill ~208 ~60 ~128 ~210 ~62 ~128 stone
fill ~208 ~63 ~128 ~210 ~65 ~128 dirt
fill ~208 ~66 ~128 ~210 ~66 ~128 grass_block
fill ~211 ~60 ~128 ~223 ~63 ~128 stone
fill ~211 ~64 ~128 ~223 ~66 ~128 dirt
fill ~211 ~67 ~128 ~223 ~67 ~128 grass_block
fill ~208 ~60 ~129 ~211 ~62 ~129 stone
fill ~208 ~63 ~129 ~211 ~65 ~129 dirt
fill ~208 ~66 ~129 ~211 ~66 ~129 grass_block
fill ~212 ~60 ~129 ~222 ~63 ~129 stone
fill ~212 ~64 ~129 ~222 ~66 ~129 dirt
fill ~212 ~67 ~129 ~222 ~67 ~129 grass_block
fill ~223 ~60 ~129 ~223 ~62 ~129 stone
fill ~223 ~63 ~129 ~223 ~65 ~129 dirt
fill ~223 ~66 ~129 ~223 ~66 ~129 grass_block
fill ~208 ~60 ~130 ~215 ~62 ~130 stone
fill ~208 ~63 ~130 ~215 ~65 ~130 dirt
fill ~208 ~66 ~130 ~215 ~66 ~130 grass_block
fill ~216 ~60 ~130 ~221 ~63 ~130 stone
fill ~216 ~64 ~130 ~221 ~66 ~130 dirt
fill ~216 ~67 ~130 ~221 ~67 ~130 grass_block
fill ~222 ~60 ~130 ~223 ~62 ~130 stone
fill ~222 ~63 ~130 ~223 ~65 ~130 dirt
fill ~222 ~66 ~130 ~223 ~66 ~130 grass_block
fill ~208 ~60 ~131 ~216 ~62 ~131 stone
fill ~208 ~63 ~131 ~216 ~65 ~131 dirt
fill ~208 ~66 ~131 ~216 ~66 ~131 grass_block
fill ~217 ~60 ~131 ~221 ~63 ~131 stone
fill ~217 ~64 ~131 ~221 ~66 ~131 dirt
fill ~217 ~67 ~131 ~221 ~67 ~131 grass_block
fill ~222 ~60 ~131 ~223 ~62 ~131 stone
fill ~222 ~63 ~131 ~223 ~65 ~131 dirt
fill ~222 ~66 ~131 ~223 ~66 ~131 grass_block
fill ~208 ~60 ~132 ~218 ~62 ~132 stone
fill ~208 ~63 ~132 ~218 ~65 ~132 dirt
fill ~208 ~66 ~132 ~218 ~66 ~132 grass_block
fill ~219 ~60 ~132 ~220 ~63 ~132 stone
fill ~219 ~64 ~132 ~220 ~66 ~132 dirt
fill ~219 ~67 ~132 ~220 ~67 ~132 grass_block
fill ~221 ~60 ~132 ~223 ~62 ~132 stone
fill ~221 ~63 ~132 ~223 ~65 ~132 dirt
fill ~221 ~66 ~132 ~223 ~66 ~132 grass_block
fill ~208 ~60 ~133 ~223 ~62 ~133 stone
fill ~208 ~63 ~133 ~223 ~65 ~133 dirt
fill ~208 ~66 ~133 ~223 ~66 ~133 grass_block
fill ~208 ~60 ~134 ~223 ~62 ~134 stone
fill ~208 ~63 ~134 ~223 ~65 ~134 dirt
fill ~208 ~66 ~134 ~223 ~66 ~134 grass_block
fill ~208 ~60 ~135 ~223 ~62 ~135 stone
fill ~208 ~63 ~135 ~223 ~65 ~135 dirt
fill ~208 ~66 ~135 ~223 ~66 ~135 grass_block
fill ~208 ~60 ~136 ~223 ~62 ~136 stone
fill ~208 ~63 ~136 ~223 ~65 ~136 dirt
fill ~208 ~66 ~136 ~223 ~66 ~136 grass_block
fill ~208 ~60 ~137 ~216 ~62 ~137 stone
fill ~208 ~63 ~137 ~216 ~65 ~137 dirt
fill ~208 ~66 ~137 ~216 ~66 ~137 grass_block
fill ~217 ~60 ~137 ~219 ~61 ~137 stone
fill ~217 ~62 ~137 ~219 ~64 ~137 dirt
fill ~217 ~65 ~137 ~219 ~65 ~137 grass_block
fill ~220 ~60 ~137 ~223 ~62 ~137 stone
fill ~220 ~63 ~137 ~223 ~65 ~137 dirt
fill ~220 ~66 ~137 ~223 ~66 ~137 grass_block
fill ~208 ~60 ~138 ~208 ~63 ~138 stone
fill ~208 ~64 ~138 ~208 ~66 ~138 dirt
fill ~208 ~67 ~138 ~208 ~67 ~138 grass_block
fill ~209 ~60 ~138 ~217 ~62 ~138 stone
fill ~209 ~63 ~138 ~217 ~65 ~138 dirt
fill ~209 ~66 ~138 ~217 ~66 ~138 grass_block
fill ~218 ~60 ~138 ~218 ~61 ~138 stone
fill ~218 ~62 ~138 ~218 ~64 ~138 dirt
fill ~218 ~65 ~138 ~218 ~65 ~138 grass_block
fill ~219 ~60 ~138 ~223 ~62 ~138 stone
fill ~219 ~63 ~138 ~223 ~65 ~138 dirt
fill ~219 ~66 ~138 ~223 ~66 ~138 grass_block
fill ~208 ~60 ~139 ~210 ~63 ~139 stone
fill ~208 ~64 ~139 ~210 ~66 ~139 dirt
fill ~208 ~67 ~139 ~210 ~67 ~139 grass_block
fill ~211 ~60 ~139 ~218 ~62 ~139 stone
fill ~211 ~63 ~139 ~218 ~65 ~139 dirt
fill ~211 ~66 ~139 ~218 ~66 ~139 grass_block
fill ~219 ~60 ~139 ~220 ~63 ~139 stone
fill ~219 ~64 ~139 ~220 ~66 ~139 dirt
fill ~219 ~67 ~139 ~220 ~67 ~139 grass_block
fill ~221 ~60 ~139 ~223 ~62 ~139 stone
fill ~221 ~63 ~139 ~223 ~65 ~139 dirt
fill ~221 ~66 ~139 ~223 ~66 ~139 grass_block
fill ~208 ~60 ~140 ~212 ~63 ~140 stone
fill ~208 ~64 ~140 ~212 ~66 ~140 dirt
fill ~208 ~67 ~140 ~212 ~67 ~140 grass_block
fill ~213 ~60 ~140 ~218 ~62 ~140 stone
fill ~213 ~63 ~140 ~218 ~65 ~140 dirt
fill ~213 ~66 ~140 ~218 ~66 ~140 grass_block
fill ~219 ~60 ~140 ~223 ~63 ~140 stone
fill ~219 ~64 ~140 ~223 ~66 ~140 dirt
fill ~219 ~67 ~140 ~223 ~67 ~140 grass_block
fill ~208 ~60 ~141 ~214 ~63 ~141 stone
fill ~208 ~64 ~141 ~214 ~66 ~141 dirt
fill ~208 ~67 ~141 ~214 ~67 ~141 grass_block
fill ~215 ~60 ~141 ~219 ~62 ~141 stone
fill ~215 ~63 ~141 ~219 ~65 ~141 dirt
fill ~215 ~66 ~141 ~219 ~66 ~141 grass_block
fill ~220 ~60 ~141 ~223 ~63 ~141 stone
fill ~220 ~64 ~141 ~223 ~66 ~141 dirt
fill ~220 ~67 ~141 ~223 ~67 ~141 grass_block
fill ~208 ~60 ~142 ~214 ~63 ~142 stone
fill ~208 ~64 ~142 ~214 ~66 ~142 dirt
fill ~208 ~67 ~142 ~214 ~67 ~142 grass_block
fill ~215 ~60 ~142 ~219 ~62 ~142 stone
fill ~215 ~63 ~142 ~219 ~65 ~142 dirt
fill ~215 ~66 ~142 ~219 ~66 ~142 grass_block
fill ~220 ~60 ~142 ~221 ~63 ~142 stone
fill ~220 ~64 ~142 ~221 ~66 ~142 dirt
fill ~220 ~67 ~142 ~221 ~67 ~142 grass_block
fill ~222 ~60 ~142 ~222 ~64 ~142 stone
fill ~222 ~65 ~142 ~222 ~67 ~142 dirt
fill ~222 ~68 ~142 ~222 ~68 ~142 grass_block
fill ~223 ~60 ~142 ~223 ~63 ~142 stone
fill ~223 ~64 ~142 ~223 ~66 ~142 dirt
fill ~223 ~67 ~142 ~223 ~67 ~142 grass_block
fill ~208 ~60 ~143 ~213 ~63 ~143 stone
fill ~208 ~64 ~143 ~213 ~66 ~143 dirt
fill ~208 ~67 ~143 ~213 ~67 ~143 grass_block
fill ~214 ~60 ~143 ~218 ~62 ~143 stone
fill ~214 ~63 ~143 ~218 ~65 ~143 dirt
fill ~214 ~66 ~143 ~218 ~66 ~143 grass_block
fill ~219 ~60 ~143 ~221 ~63 ~143 stone
fill ~219 ~64 ~143 ~221 ~66 ~143 dirt
fill ~219 ~67 ~143 ~221 ~67 ~143 grass_block
fill ~222 ~60 ~143 ~223 ~64 ~143 stone
fill ~222 ~65 ~143 ~223 ~67 ~143 dirt
fill ~222 ~68 ~143 ~223 ~68 ~143 grass_block