fill ~336 ~60 ~48 ~341 ~66 ~48 stone
fill ~336 ~67 ~48 ~341 ~69 ~48 dirt
fill ~336 ~70 ~48 ~341 ~70 ~48 grass_block
fill ~342 ~60 ~48 ~351 ~65 ~48 stone
fill ~342 ~66 ~48 ~351 ~68 ~48 dirt
fill ~342 ~69 ~48 ~351 ~69 ~48 grass_block
fill ~336 ~60 ~49 ~343 ~66 ~49 stone
fill ~336 ~67 ~49 ~343 ~69 ~49 dirt
fill ~336 ~70 ~49 ~343 ~70 ~49 grass_block
fill ~344 ~60 ~49 ~344 ~65 ~49 stone
fill ~344 ~66 ~49 ~344 ~68 ~49 dirt
fill ~344 ~69 ~49 ~344 ~69 ~49 grass_block
fill ~345 ~60 ~49 ~347 ~66 ~49 stone
fill ~345 ~67 ~49 ~347 ~69 ~49 dirt
fill ~345 ~70 ~49 ~347 ~70 ~49 grass_block
fill ~348 ~60 ~49 ~351 ~65 ~49 stone
fill ~348 ~66 ~49 ~351 ~68 ~49 dirt
fill ~348 ~69 ~49 ~351 ~69 ~49 grass_block
fill ~336 ~60 ~50 ~341 ~66 ~50 stone
fill ~336 ~67 ~50 ~341 ~69 ~50 dirt
fill ~336 ~70 ~50 ~341 ~70 ~50 grass_block
fill ~342 ~60 ~50 ~342 ~67 ~50 stone
fill ~342 ~68 ~50 ~342 ~70 ~50 dirt
fill ~342 ~71 ~50 ~342 ~71 ~50 grass_block
fill ~343 ~60 ~50 ~349 ~66 ~50 stone
fill ~343 ~67 ~50 ~349 ~69 ~50 dirt
fill ~343 ~70 ~50 ~349 ~70 ~50 grass_block
fill ~350 ~60 ~50 ~351 ~65 ~50 stone
fill ~350 ~66 ~50 ~351 ~68 ~50 dirt
fill ~350 ~69 ~50 ~351 ~69 ~50 grass_block
fill ~336 ~60 ~51 ~336 ~65 ~51 stone
fill ~336 ~66 ~51 ~336 ~68 ~51 dirt
fill ~336 ~69 ~51 ~336 ~69 ~51 grass_block
fill ~337 ~60 ~51 ~342 ~66 ~51 stone
fill ~337 ~67 ~51 ~342 ~69 ~51 dirt
fill ~337 ~70 ~51 ~342 ~70 ~51 grass_block
fill ~343 ~60 ~51 ~346 ~67 ~51 stone
fill ~343 ~68 ~51 ~346 ~70 ~51 dirt
fill ~343 ~71 ~51 ~346 ~71 ~51 grass_block
fill ~347 ~60 ~51 ~349 ~66 ~51 stone
fill ~347 ~67 ~51 ~349 ~69 ~51 dirt
fill ~347 ~70 ~51 ~349 ~70 ~51 grass_block
fill ~350 ~60 ~51 ~351 ~65 ~51 stone
fill ~350 ~66 ~51 ~351 ~68 ~51 dirt
fill ~350 ~69 ~51 ~351 ~69 ~51 grass_block
fill ~336 ~60 ~52 ~337 ~65 ~52 stone
fill ~336 ~66 ~52 ~337 ~68 ~52 dirt
fill ~336 ~69 ~52 ~337 ~69 ~52 grass_block
fill ~338 ~60 ~52 ~342 ~66 ~52 stone
fill ~338 ~67 ~52 ~342 ~69 ~52 dirt
fill ~338 ~70 ~52 ~342 ~70 ~52 grass_block
fill ~343 ~60 ~52 ~346 ~67 ~52 stone
fill ~343 ~68 ~52 ~346 ~70 ~52 dirt
fill ~343 ~71 ~52 ~346 ~71 ~52 grass_block
fill ~347 ~60 ~52 ~350 ~66 ~52 stone
fill ~347 ~67 ~52 ~350 ~69 ~52 dirt
fill ~347 ~70 ~52 ~350 ~70 ~52 grass_block
fill ~351 ~60 ~52 ~351 ~65 ~52 stone
fill ~351 ~66 ~52 ~351 ~68 ~52 dirt
fill ~351 ~69 ~52 ~351 ~69 ~52 grass_block
fill ~336 ~60 ~53 ~338 ~65 ~53 stone
fill ~336 ~66 ~53 ~338 ~68 ~53 dirt
fill ~336 ~69 ~53 ~338 ~69 ~53 grass_block
fill ~339 ~60 ~53 ~344 ~66 ~53 stone
fill ~339 ~67 ~53 ~344 ~69 ~53 dirt
fill ~339 ~70 ~53 ~344 ~70 ~53 grass_block
fill ~345 ~60 ~53 ~347 ~67 ~53 stone
fill ~345 ~68 ~53 ~347 ~70 ~53 dirt
fill ~345 ~71 ~53 ~347 ~71 ~53 grass_block
fill ~348 ~60 ~53 ~351 ~66 ~53 stone
fill ~348 ~67 ~53 ~351 ~69 ~53 dirt
fill ~348 ~70 ~53 ~351 ~70 ~53 grass_block
fill ~336 ~60 ~54 ~339 ~65 ~54 stone
fill ~336 ~66 ~54 ~339 ~68 ~54 dirt
fill ~336 ~69 ~54 ~339 ~69 ~54 grass_block
fill ~340 ~60 ~54 ~345 ~66 ~54 stone
fill ~340 ~67 ~54 ~345 ~69 ~54 dirt
fill ~340 ~70 ~54 ~345 ~70 ~54 grass_block
fill ~346 ~60 ~54 ~348 ~67 ~54 stone
fill ~346 ~68 ~54 ~348 ~70 ~54 dirt
fill ~346 ~71 ~54 ~348 ~71 ~54 grass_block
fill ~349 ~60 ~54 ~351 ~66 ~54 stone
fill ~349 ~67 ~54 ~351 ~69 ~54 dirt
fill ~349 ~70 ~54 ~351 ~70 ~54 grass_block
fill ~336 ~60 ~55 ~340 ~65 ~55 stone
fill ~336 ~66 ~55 ~340 ~68 ~55 dirt
fill ~336 ~69 ~55 ~340 ~69 ~55 grass_block
fill ~341 ~60 ~55 ~351 ~66 ~55 stone
fill ~341 ~67 ~55 ~351 ~69 ~55 dirt
fill ~341 ~70 ~55 ~351 ~70 ~55 grass_block
fill ~336 ~60 ~56 ~340 ~65 ~56 stone
fill ~336 ~66 ~56 ~340 ~68 ~56 dirt
fill ~336 ~69 ~56 ~340 ~69 ~56 grass_block
fill ~341 ~60 ~56 ~351 ~66 ~56 stone
fill ~341 ~67 ~56 ~351 ~69 ~56 dirt
fill ~341 ~70 ~56 ~351 ~70 ~56 grass_block
fill ~336 ~60 ~57 ~342 ~65 ~57 stone
fill ~336 ~66 ~57 ~342 ~68 ~57 dirt
fill ~336 ~69 ~57 ~342 ~69 ~57 grass_block
fill ~343 ~60 ~57 ~351 ~66 ~57 stone
fill ~343 ~67 ~57 ~351 ~69 ~57 dirt
fill ~343 ~70 ~57 ~351 ~70 ~57 grass_block
fill ~336 ~60 ~58 ~346 ~65 ~58 stone
fill ~336 ~66 ~58 ~346 ~68 ~58 dirt
fill ~336 ~69 ~58 ~346 ~69 ~58 grass_block
fill ~347 ~60 ~58 ~351 ~66 ~58 stone
fill ~347 ~67 ~58 ~351 ~69 ~58 dirt
fill ~347 ~70 ~58 ~351 ~70 ~58 grass_block
fill ~336 ~60 ~59 ~350 ~65 ~59 stone
fill ~336 ~66 ~59 ~350 ~68 ~59 dirt
fill ~336 ~69 ~59 ~350 ~69 ~59 grass_block
fill ~351 ~60 ~59 ~351 ~66 ~59 stone
fill ~351 ~67 ~59 ~351 ~69 ~59 dirt
fill ~351 ~70 ~59 ~351 ~70 ~59 grass_block
fill ~336 ~60 ~60 ~351 ~65 ~60 stone
fill ~336 ~66 ~60 ~351 ~68 ~60 dirt
fill ~336 ~69 ~60 ~351 ~69 ~60 grass_block
fill ~336 ~60 ~61 ~351 ~65 ~61 stone
fill ~336 ~66 ~61 ~351 ~68 ~61 dirt
fill ~336 ~69 ~61 ~351 ~69 ~61 grass_block
fill ~336 ~60 ~62 ~336 ~64 ~62 stone
fill ~336 ~65 ~62 ~336 ~67 ~62 dirt
fill ~336 ~68 ~62 ~336 ~68 ~62 grass_block
fill ~337 ~60 ~62 ~351 ~65 ~62 stone
fill ~337 ~66 ~62 ~351 ~68 ~62 dirt
fill ~337 ~69 ~62 ~351 ~69 ~62 grass_block
fill ~336 ~60 ~63 ~338 ~64 ~63 stone
fill ~336 ~65 ~63 ~338 ~67 ~63 dirt
fill ~336 ~68 ~63 ~338 ~68 ~63 grass_block
fill ~339 ~60 ~63 ~346 ~65 ~63 stone
fill ~339 ~66 ~63 ~346 ~68 ~63 dirt
fill ~339 ~69 ~63 ~346 ~69 ~63 grass_block
fill ~347 ~60 ~63 ~349 ~64 ~63 stone
fill ~347 ~65 ~63 ~349 ~67 ~63 dirt
fill ~347 ~68 ~63 ~349 ~68 ~63 grass_block
fill ~350 ~60 ~63 ~351 ~65 ~63 stone
fill ~350 ~66 ~63 ~351 ~68 ~63 dirt
fill ~350 ~69 ~63 ~351 ~69 ~63 grass_block