fill ~144 ~60 ~16 ~144 ~64 ~16 stone
fill ~144 ~65 ~16 ~144 ~67 ~16 dirt
fill ~144 ~68 ~16 ~144 ~68 ~16 grass_block
fill ~145 ~60 ~16 ~145 ~63 ~16 stone
fill ~145 ~64 ~16 ~145 ~66 ~16 dirt
fill ~145 ~67 ~16 ~145 ~67 ~16 grass_block
fill ~146 ~60 ~16 ~147 ~64 ~16 stone
fill ~146 ~65 ~16 ~147 ~67 ~16 dirt
fill ~146 ~68 ~16 ~147 ~68 ~16 grass_block
fill ~148 ~60 ~16 ~148 ~63 ~16 stone
fill ~148 ~64 ~16 ~148 ~66 ~16 dirt
fill ~148 ~67 ~16 ~148 ~67 ~16 grass_block
fill ~149 ~60 ~16 ~155 ~64 ~16 stone
fill ~149 ~65 ~16 ~155 ~67 ~16 dirt
fill ~149 ~68 ~16 ~155 ~68 ~16 grass_block
fill ~156 ~60 ~16 ~159 ~63 ~16 stone
fill ~156 ~64 ~16 ~159 ~66 ~16 dirt
fill ~156 ~67 ~16 ~159 ~67 ~16 grass_block
fill ~144 ~60 ~17 ~152 ~63 ~17 stone
fill ~144 ~64 ~17 ~152 ~66 ~17 dirt
fill ~144 ~67 ~17 ~152 ~67 ~17 grass_block
fill ~153 ~60 ~17 ~155 ~64 ~17 stone
fill ~153 ~65 ~17 ~155 ~67 ~17 dirt
fill ~153 ~68 ~17 ~155 ~68 ~17 grass_block
fill ~156 ~60 ~17 ~159 ~63 ~17 stone
fill ~156 ~64 ~17 ~159 ~66 ~17 dirt
fill ~156 ~67 ~17 ~159 ~67 ~17 grass_block
fill ~144 ~60 ~18 ~159 ~63 ~18 stone
fill ~144 ~64 ~18 ~159 ~66 ~18 dirt
fill ~144 ~67 ~18 ~159 ~67 ~18 grass_block
fill ~144 ~60 ~19 ~159 ~63 ~19 stone
fill ~144 ~64 ~19 ~159 ~66 ~19 dirt
fill ~144 ~67 ~19 ~159 ~67 ~19 grass_block
fill ~144 ~60 ~20 ~159 ~63 ~20 stone
fill ~144 ~64 ~20 ~159 ~66 ~20 dirt
fill ~144 ~67 ~20 ~159 ~67 ~20 grass_block
fill ~144 ~60 ~21 ~159 ~63 ~21 stone
fill ~144 ~64 ~21 ~159 ~66 ~21 dirt
fill ~144 ~67 ~21 ~159 ~67 ~21 grass_block
fill ~144 ~60 ~22 ~145 ~63 ~22 stone
fill ~144 ~64 ~22 ~145 ~66 ~22 dirt
fill ~144 ~67 ~22 ~145 ~67 ~22 grass_block
fill ~146 ~60 ~22 ~147 ~64 ~22 stone
fill ~146 ~65 ~22 ~147 ~67 ~22 dirt
fill ~146 ~68 ~22 ~147 ~68 ~22 grass_block
fill ~148 ~60 ~22 ~159 ~63 ~22 stone
fill ~148 ~64 ~22 ~159 ~66 ~22 dirt
fill ~148 ~67 ~22 ~159 ~67 ~22 grass_block
fill ~144 ~60 ~23 ~144 ~63 ~23 stone
fill ~144 ~64 ~23 ~144 ~66 ~23 dirt
fill ~144 ~67 ~23 ~144 ~67 ~23 grass_block
fill ~145 ~60 ~23 ~149 ~64 ~23 stone
fill ~145 ~65 ~23 ~149 ~67 ~23 dirt
fill ~145 ~68 ~23 ~149 ~68 ~23 grass_block
fill ~150 ~60 ~23 ~155 ~63 ~23 stone
fill ~150 ~64 ~23 ~155 ~66 ~23 dirt
fill ~150 ~67 ~23 ~155 ~67 ~23 grass_block
fill ~156 ~60 ~23 ~156 ~62 ~23 stone
fill ~156 ~63 ~23 ~156 ~65 ~23 dirt
fill ~156 ~66 ~23 ~156 ~66 ~23 grass_block
fill ~157 ~60 ~23 ~159 ~63 ~23 stone
fill ~157 ~64 ~23 ~159 ~66 ~23 dirt
fill ~157 ~67 ~23 ~159 ~67 ~23 grass_block
fill ~144 ~60 ~24 ~144 ~63 ~24 stone
fill ~144 ~64 ~24 ~144 ~66 ~24 dirt
fill ~144 ~67 ~24 ~144 ~67 ~24 grass_block
fill ~145 ~60 ~24 ~146 ~64 ~24 stone
fill ~145 ~65 ~24 ~146 ~67 ~24 dirt
fill ~145 ~68 ~24 ~146 ~68 ~24 grass_block
fill ~147 ~60 ~24 ~148 ~65 ~24 stone
fill ~147 ~66 ~24 ~148 ~68 ~24 dirt
fill ~147 ~69 ~24 ~148 ~69 ~24 grass_block
fill ~149 ~60 ~24 ~151 ~64 ~24 stone
fill ~149 ~65 ~24 ~151 ~67 ~24 dirt
fill ~149 ~68 ~24 ~151 ~68 ~24 grass_block
fill ~152 ~60 ~24 ~157 ~63 ~24 stone
fill ~152 ~64 ~24 ~157 ~66 ~24 dirt
fill ~152 ~67 ~24 ~157 ~67 ~24 grass_block
fill ~158 ~60 ~24 ~159 ~62 ~24 stone
fill ~158 ~63 ~24 ~159 ~65 ~24 dirt
fill ~158 ~66 ~24 ~159 ~66 ~24 grass_block
fill ~144 ~60 ~25 ~144 ~63 ~25 stone
fill ~144 ~64 ~25 ~144 ~66 ~25 dirt
fill ~144 ~67 ~25 ~144 ~67 ~25 grass_block
fill ~145 ~60 ~25 ~147 ~64 ~25 stone
fill ~145 ~65 ~25 ~147 ~67 ~25 dirt
fill ~145 ~68 ~25 ~147 ~68 ~25 grass_block
fill ~148 ~60 ~25 ~149 ~65 ~25 stone
fill ~148 ~66 ~25 ~149 ~68 ~25 dirt
fill ~148 ~69 ~25 ~149 ~69 ~25 grass_block
fill ~150 ~60 ~25 ~153 ~64 ~25 stone
fill ~150 ~65 ~25 ~153 ~67 ~25 dirt
fill ~150 ~68 ~25 ~153 ~68 ~25 grass_block
fill ~154 ~60 ~25 ~159 ~63 ~25 stone
fill ~154 ~64 ~25 ~159 ~66 ~25 dirt
fill ~154 ~67 ~25 ~159 ~67 ~25 grass_block
fill ~144 ~60 ~26 ~144 ~63 ~26 stone
fill ~144 ~64 ~26 ~144 ~66 ~26 dirt
fill ~144 ~67 ~26 ~144 ~67 ~26 grass_block
fill ~145 ~60 ~26 ~147 ~64 ~26 stone
fill ~145 ~65 ~26 ~147 ~67 ~26 dirt
fill ~145 ~68 ~26 ~147 ~68 ~26 grass_block
fill ~148 ~60 ~26 ~151 ~65 ~26 stone
fill ~148 ~66 ~26 ~151 ~68 ~26 dirt
fill ~148 ~69 ~26 ~151 ~69 ~26 grass_block
fill ~152 ~60 ~26 ~154 ~64 ~26 stone
fill ~152 ~65 ~26 ~154 ~67 ~26 dirt
fill ~152 ~68 ~26 ~154 ~68 ~26 grass_block
fill ~155 ~60 ~26 ~159 ~63 ~26 stone
fill ~155 ~64 ~26 ~159 ~66 ~26 dirt
fill ~155 ~67 ~26 ~159 ~67 ~26 grass_block
fill ~144 ~60 ~27 ~144 ~63 ~27 stone
fill ~144 ~64 ~27 ~144 ~66 ~27 dirt
fill ~144 ~67 ~27 ~144 ~67 ~27 grass_block
fill ~145 ~60 ~27 ~145 ~64 ~27 stone
fill ~145 ~65 ~27 ~145 ~67 ~27 dirt
fill ~145 ~68 ~27 ~145 ~68 ~27 grass_block
fill ~146 ~60 ~27 ~151 ~65 ~27 stone
fill ~146 ~66 ~27 ~151 ~68 ~27 dirt
fill ~146 ~69 ~27 ~151 ~69 ~27 grass_block
fill ~152 ~60 ~27 ~155 ~64 ~27 stone
fill ~152 ~65 ~27 ~155 ~67 ~27 dirt
fill ~152 ~68 ~27 ~155 ~68 ~27 grass_block
fill ~156 ~60 ~27 ~159 ~63 ~27 stone
fill ~156 ~64 ~27 ~159 ~66 ~27 dirt
fill ~156 ~67 ~27 ~159 ~67 ~27 grass_block
fill ~144 ~60 ~28 ~144 ~63 ~28 stone
fill ~144 ~64 ~28 ~144 ~66 ~28 dirt
fill ~144 ~67 ~28 ~144 ~67 ~28 grass_block
fill ~145 ~60 ~28 ~145 ~64 ~28 stone
fill ~145 ~65 ~28 ~145 ~67 ~28 dirt
fill ~145 ~68 ~28 ~145 ~68 ~28 grass_block
fill ~146 ~60 ~28 ~152 ~65 ~28 stone
fill ~146 ~66 ~28 ~152 ~68 ~28 dirt
fill ~146 ~69 ~28 ~152 ~69 ~28 grass_block
fill ~153 ~60 ~28 ~155 ~64 ~28 stone
fill ~153 ~65 ~28 ~155 ~67 ~28 dirt
fill ~153 ~68 ~28 ~155 ~68 ~28 grass_block
fill ~156 ~60 ~28 ~159 ~63 ~28 stone
fill ~156 ~64 ~28 ~159 ~66 ~28 dirt
fill ~156 ~67 ~28 ~159 ~67 ~28 grass_block
fill ~144 ~60 ~29 ~145 ~64 ~29 stone
fill ~144 ~65 ~29 ~145 ~67 ~29 dirt
fill ~144 ~68 ~29 ~145 ~68 ~29 grass_block
fill ~146 ~60 ~29 ~147 ~65 ~29 stone
fill ~146 ~66 ~29 ~147 ~68 ~29 dirt
fill ~146 ~69 ~29 ~147 ~69 ~29 grass_block
fill ~148 ~60 ~29 ~148 ~66 ~29 stone
fill ~148 ~67 ~29 ~148 ~69 ~29 dirt
fill ~148 ~70 ~29 ~148 ~70 ~29 grass_block
fill ~149 ~60 ~29 ~152 ~65 ~29 stone
fill ~149 ~66 ~29 ~152 ~68 ~29 dirt
fill ~149 ~69 ~29 ~152 ~69 ~29 grass_block
fill ~153 ~60 ~29 ~155 ~64 ~29 stone
fill ~153 ~65 ~29 ~155 ~67 ~29 dirt
fill ~153 ~68 ~29 ~155 ~68 ~29 grass_block
fill ~156 ~60 ~29 ~159 ~63 ~29 stone
fill ~156 ~64 ~29 ~159 ~66 ~29 dirt
fill ~156 ~67 ~29 ~159 ~67 ~29 grass_block
fill ~144 ~60 ~30 ~145 ~64 ~30 stone
fill ~144 ~65 ~30 ~145 ~67 ~30 dirt
fill ~144 ~68 ~30 ~145 ~68 ~30 grass_block
fill ~146 ~60 ~30 ~148 ~65 ~30 stone
fill ~146 ~66 ~30 ~148 ~68 ~30 dirt
fill ~146 ~69 ~30 ~148 ~69 ~30 grass_block
fill ~149 ~60 ~30 ~149 ~66 ~30 stone
fill ~149 ~67 ~30 ~149 ~69 ~30 dirt
fill ~149 ~70 ~30 ~149 ~70 ~30 grass_block
fill ~150 ~60 ~30 ~151 ~65 ~30 stone
fill ~150 ~66 ~30 ~151 ~68 ~30 dirt
fill ~150 ~69 ~30 ~151 ~69 ~30 grass_block
fill ~152 ~60 ~30 ~155 ~64 ~30 stone
fill ~152 ~65 ~30 ~155 ~67 ~30 dirt
fill ~152 ~68 ~30 ~155 ~68 ~30 grass_block
fill ~156 ~60 ~30 ~159 ~63 ~30 stone
fill ~156 ~64 ~30 ~159 ~66 ~30 dirt
fill ~156 ~67 ~30 ~159 ~67 ~30 grass_block
fill ~144 ~60 ~31 ~146 ~64 ~31 stone
fill ~144 ~65 ~31 ~146 ~67 ~31 dirt
fill ~144 ~68 ~31 ~146 ~68 ~31 grass_block
fill ~147 ~60 ~31 ~148 ~65 ~31 stone
fill ~147 ~66 ~31 ~148 ~68 ~31 dirt
fill ~147 ~69 ~31 ~148 ~69 ~31 grass_block
fill ~149 ~60 ~31 ~149 ~66 ~31 stone
fill ~149 ~67 ~31 ~149 ~69 ~31 dirt
fill ~149 ~70 ~31 ~149 ~70 ~31 grass_block
fill ~150 ~60 ~31 ~152 ~65 ~31 stone
fill ~150 ~66 ~31 ~152 ~68 ~31 dirt
fill ~150 ~69 ~31 ~152 ~69 ~31 grass_block
fill ~153 ~60 ~31 ~155 ~64 ~31 stone
fill ~153 ~65 ~31 ~155 ~67 ~31 dirt
fill ~153 ~68 ~31 ~155 ~68 ~31 grass_block
fill ~156 ~60 ~31 ~159 ~63 ~31 stone
fill ~156 ~64 ~31 ~159 ~66 ~31 dirt
fill ~156 ~67 ~31 ~159 ~67 ~31 grass_block