fill ~176 ~60 ~48 ~183 ~66 ~48 stone
fill ~176 ~67 ~48 ~183 ~69 ~48 dirt
fill ~176 ~70 ~48 ~183 ~70 ~48 grass_block
fill ~184 ~60 ~48 ~186 ~65 ~48 stone
fill ~184 ~66 ~48 ~186 ~68 ~48 dirt
fill ~184 ~69 ~48 ~186 ~69 ~48 grass_block
fill ~187 ~60 ~48 ~188 ~64 ~48 stone
fill ~187 ~65 ~48 ~188 ~67 ~48 dirt
fill ~187 ~68 ~48 ~188 ~68 ~48 grass_block
fill ~189 ~60 ~48 ~189 ~63 ~48 stone
fill ~189 ~64 ~48 ~189 ~66 ~48 dirt
fill ~189 ~67 ~48 ~189 ~67 ~48 grass_block
fill ~190 ~60 ~48 ~191 ~64 ~48 stone
fill ~190 ~65 ~48 ~191 ~67 ~48 dirt
fill ~190 ~68 ~48 ~191 ~68 ~48 grass_block
fill ~176 ~60 ~49 ~182 ~66 ~49 stone
fill ~176 ~67 ~49 ~182 ~69 ~49 dirt
fill ~176 ~70 ~49 ~182 ~70 ~49 grass_block
fill ~183 ~60 ~49 ~186 ~65 ~49 stone
fill ~183 ~66 ~49 ~186 ~68 ~49 dirt
fill ~183 ~69 ~49 ~186 ~69 ~49 grass_block
fill ~187 ~60 ~49 ~191 ~64 ~49 stone
fill ~187 ~65 ~49 ~191 ~67 ~49 dirt
fill ~187 ~68 ~49 ~191 ~68 ~49 grass_block
fill ~176 ~60 ~50 ~176 ~67 ~50 stone
fill ~176 ~68 ~50 ~176 ~70 ~50 dirt
fill ~176 ~71 ~50 ~176 ~71 ~50 grass_block
fill ~177 ~60 ~50 ~181 ~66 ~50 stone
fill ~177 ~67 ~50 ~181 ~69 ~50 dirt
fill ~177 ~70 ~50 ~181 ~70 ~50 grass_block
fill ~182 ~60 ~50 ~186 ~65 ~50 stone
fill ~182 ~66 ~50 ~186 ~68 ~50 dirt
fill ~182 ~69 ~50 ~186 ~69 ~50 grass_block
fill ~187 ~60 ~50 ~191 ~64 ~50 stone
fill ~187 ~65 ~50 ~191 ~67 ~50 dirt
fill ~187 ~68 ~50 ~191 ~68 ~50 grass_block
fill ~176 ~60 ~51 ~178 ~67 ~51 stone
fill ~176 ~68 ~51 ~178 ~70 ~51 dirt
fill ~176 ~71 ~51 ~178 ~71 ~51 grass_block
fill ~179 ~60 ~51 ~181 ~66 ~51 stone
fill ~179 ~67 ~51 ~181 ~69 ~51 dirt
fill ~179 ~70 ~51 ~181 ~70 ~51 grass_block
fill ~182 ~60 ~51 ~185 ~65 ~51 stone
fill ~182 ~66 ~51 ~185 ~68 ~51 dirt
fill ~182 ~69 ~51 ~185 ~69 ~51 grass_block
fill ~186 ~60 ~51 ~189 ~64 ~51 stone
fill ~186 ~65 ~51 ~189 ~67 ~51 dirt
fill ~186 ~68 ~51 ~189 ~68 ~51 grass_block
fill ~190 ~60 ~51 ~191 ~65 ~51 stone
fill ~190 ~66 ~51 ~191 ~68 ~51 dirt
fill ~190 ~69 ~51 ~191 ~69 ~51 grass_block
fill ~176 ~60 ~52 ~178 ~67 ~52 stone
fill ~176 ~68 ~52 ~178 ~70 ~52 dirt
fill ~176 ~71 ~52 ~178 ~71 ~52 grass_block
fill ~179 ~60 ~52 ~181 ~66 ~52 stone
fill ~179 ~67 ~52 ~181 ~69 ~52 dirt
fill ~179 ~70 ~52 ~181 ~70 ~52 grass_block
fill ~182 ~60 ~52 ~185 ~65 ~52 stone
fill ~182 ~66 ~52 ~185 ~68 ~52 dirt
fill ~182 ~69 ~52 ~185 ~69 ~52 grass_block
fill ~186 ~60 ~52 ~188 ~64 ~52 stone
fill ~186 ~65 ~52 ~188 ~67 ~52 dirt
fill ~186 ~68 ~52 ~188 ~68 ~52 grass_block
fill ~189 ~60 ~52 ~191 ~65 ~52 stone
fill ~189 ~66 ~52 ~191 ~68 ~52 dirt
fill ~189 ~69 ~52 ~191 ~69 ~52 grass_block
fill ~176 ~60 ~53 ~179 ~67 ~53 stone
fill ~176 ~68 ~53 ~179 ~70 ~53 dirt
fill ~176 ~71 ~53 ~179 ~71 ~53 grass_block
fill ~180 ~60 ~53 ~182 ~66 ~53 stone
fill ~180 ~67 ~53 ~182 ~69 ~53 dirt
fill ~180 ~70 ~53 ~182 ~70 ~53 grass_block
fill ~183 ~60 ~53 ~185 ~65 ~53 stone
fill ~183 ~66 ~53 ~185 ~68 ~53 dirt
fill ~183 ~69 ~53 ~185 ~69 ~53 grass_block
fill ~186 ~60 ~53 ~187 ~64 ~53 stone
fill ~186 ~65 ~53 ~187 ~67 ~53 dirt
fill ~186 ~68 ~53 ~187 ~68 ~53 grass_block
fill ~188 ~60 ~53 ~191 ~65 ~53 stone
fill ~188 ~66 ~53 ~191 ~68 ~53 dirt
fill ~188 ~69 ~53 ~191 ~69 ~53 grass_block
fill ~176 ~60 ~54 ~179 ~67 ~54 stone
fill ~176 ~68 ~54 ~179 ~70 ~54 dirt
fill ~176 ~71 ~54 ~179 ~71 ~54 grass_block
fill ~180 ~60 ~54 ~182 ~66 ~54 stone
fill ~180 ~67 ~54 ~182 ~69 ~54 dirt
fill ~180 ~70 ~54 ~182 ~70 ~54 grass_block
fill ~183 ~60 ~54 ~185 ~65 ~54 stone
fill ~183 ~66 ~54 ~185 ~68 ~54 dirt
fill ~183 ~69 ~54 ~185 ~69 ~54 grass_block
fill ~186 ~60 ~54 ~186 ~64 ~54 stone
fill ~186 ~65 ~54 ~186 ~67 ~54 dirt
fill ~186 ~68 ~54 ~186 ~68 ~54 grass_block
fill ~187 ~60 ~54 ~191 ~65 ~54 stone
fill ~187 ~66 ~54 ~191 ~68 ~54 dirt
fill ~187 ~69 ~54 ~191 ~69 ~54 grass_block
fill ~176 ~60 ~55 ~180 ~67 ~55 stone
fill ~176 ~68 ~55 ~180 ~70 ~55 dirt
fill ~176 ~71 ~55 ~180 ~71 ~55 grass_block
fill ~181 ~60 ~55 ~182 ~66 ~55 stone
fill ~181 ~67 ~55 ~182 ~69 ~55 dirt
fill ~181 ~70 ~55 ~182 ~70 ~55 grass_block
fill ~183 ~60 ~55 ~191 ~65 ~55 stone
fill ~183 ~66 ~55 ~191 ~68 ~55 dirt
fill ~183 ~69 ~55 ~191 ~69 ~55 grass_block
fill ~176 ~60 ~56 ~181 ~67 ~56 stone
fill ~176 ~68 ~56 ~181 ~70 ~56 dirt
fill ~176 ~71 ~56 ~181 ~71 ~56 grass_block
fill ~182 ~60 ~56 ~183 ~66 ~56 stone
fill ~182 ~67 ~56 ~183 ~69 ~56 dirt
fill ~182 ~70 ~56 ~183 ~70 ~56 grass_block
fill ~184 ~60 ~56 ~191 ~65 ~56 stone
fill ~184 ~66 ~56 ~191 ~68 ~56 dirt
fill ~184 ~69 ~56 ~191 ~69 ~56 grass_block
fill ~176 ~60 ~57 ~181 ~67 ~57 stone
fill ~176 ~68 ~57 ~181 ~70 ~57 dirt
fill ~176 ~71 ~57 ~181 ~71 ~57 grass_block
fill ~182 ~60 ~57 ~183 ~66 ~57 stone
fill ~182 ~67 ~57 ~183 ~69 ~57 dirt
fill ~182 ~70 ~57 ~183 ~70 ~57 grass_block
fill ~184 ~60 ~57 ~191 ~65 ~57 stone
fill ~184 ~66 ~57 ~191 ~68 ~57 dirt
fill ~184 ~69 ~57 ~191 ~69 ~57 grass_block
fill ~176 ~60 ~58 ~181 ~67 ~58 stone
fill ~176 ~68 ~58 ~181 ~70 ~58 dirt
fill ~176 ~71 ~58 ~181 ~71 ~58 grass_block
fill ~182 ~60 ~58 ~186 ~66 ~58 stone
fill ~182 ~67 ~58 ~186 ~69 ~58 dirt
fill ~182 ~70 ~58 ~186 ~70 ~58 grass_block
fill ~187 ~60 ~58 ~191 ~65 ~58 stone
fill ~187 ~66 ~58 ~191 ~68 ~58 dirt
fill ~187 ~69 ~58 ~191 ~69 ~58 grass_block
fill ~176 ~60 ~59 ~182 ~67 ~59 stone
fill ~176 ~68 ~59 ~182 ~70 ~59 dirt
fill ~176 ~71 ~59 ~182 ~71 ~59 grass_block
fill ~183 ~60 ~59 ~187 ~66 ~59 stone
fill ~183 ~67 ~59 ~187 ~69 ~59 dirt
fill ~183 ~70 ~59 ~187 ~70 ~59 grass_block
fill ~188 ~60 ~59 ~191 ~65 ~59 stone
fill ~188 ~66 ~59 ~191 ~68 ~59 dirt
fill ~188 ~69 ~59 ~191 ~69 ~59 grass_block
fill ~176 ~60 ~60 ~183 ~67 ~60 stone
fill ~176 ~68 ~60 ~183 ~70 ~60 dirt
fill ~176 ~71 ~60 ~183 ~71 ~60 grass_block
fill ~184 ~60 ~60 ~190 ~66 ~60 stone
fill ~184 ~67 ~60 ~190 ~69 ~60 dirt
fill ~184 ~70 ~60 ~190 ~70 ~60 grass_block
fill ~191 ~60 ~60 ~191 ~65 ~60 stone
fill ~191 ~66 ~60 ~191 ~68 ~60 dirt
fill ~191 ~69 ~60 ~191 ~69 ~60 grass_block
fill ~176 ~60 ~61 ~184 ~67 ~61 stone
fill ~176 ~68 ~61 ~184 ~70 ~61 dirt
fill ~176 ~71 ~61 ~184 ~71 ~61 grass_block
fill ~185 ~60 ~61 ~191 ~66 ~61 stone
fill ~185 ~67 ~61 ~191 ~69 ~61 dirt
fill ~185 ~70 ~61 ~191 ~70 ~61 grass_block
fill ~176 ~60 ~62 ~185 ~67 ~62 stone
fill ~176 ~68 ~62 ~185 ~70 ~62 dirt
fill ~176 ~71 ~62 ~185 ~71 ~62 grass_block
fill ~186 ~60 ~62 ~191 ~66 ~62 stone
fill ~186 ~67 ~62 ~191 ~69 ~62 dirt
fill ~186 ~70 ~62 ~191 ~70 ~62 grass_block
fill ~176 ~60 ~63 ~186 ~67 ~63 stone
fill ~176 ~68 ~63 ~186 ~70 ~63 dirt
fill ~176 ~71 ~63 ~186 ~71 ~63 grass_block
fill ~187 ~60 ~63 ~191 ~66 ~63 stone
fill ~187 ~67 ~63 ~191 ~69 ~63 dirt
fill ~187 ~70 ~63 ~191 ~70 ~63 grass_block