fill ~288 ~60 ~32 ~292 ~63 ~32 stone
fill ~288 ~64 ~32 ~292 ~66 ~32 dirt
fill ~288 ~67 ~32 ~292 ~67 ~32 grass_block
fill ~293 ~60 ~32 ~295 ~62 ~32 stone
fill ~293 ~63 ~32 ~295 ~65 ~32 dirt
fill ~293 ~66 ~32 ~295 ~66 ~32 grass_block
fill ~296 ~60 ~32 ~297 ~63 ~32 stone
fill ~296 ~64 ~32 ~297 ~66 ~32 dirt
fill ~296 ~67 ~32 ~297 ~67 ~32 grass_block
fill ~298 ~60 ~32 ~302 ~64 ~32 stone
fill ~298 ~65 ~32 ~302 ~67 ~32 dirt
fill ~298 ~68 ~32 ~302 ~68 ~32 grass_block
fill ~303 ~60 ~32 ~303 ~65 ~32 stone
fill ~303 ~66 ~32 ~303 ~68 ~32 dirt
fill ~303 ~69 ~32 ~303 ~69 ~32 grass_block
fill ~288 ~60 ~33 ~290 ~63 ~33 stone
fill ~288 ~64 ~33 ~290 ~66 ~33 dirt
fill ~288 ~67 ~33 ~290 ~67 ~33 grass_block
fill ~291 ~60 ~33 ~291 ~62 ~33 stone
fill ~291 ~63 ~33 ~291 ~65 ~33 dirt
fill ~291 ~66 ~33 ~291 ~66 ~33 grass_block
fill ~292 ~60 ~33 ~292 ~63 ~33 stone
fill ~292 ~64 ~33 ~292 ~66 ~33 dirt
fill ~292 ~67 ~33 ~292 ~67 ~33 grass_block
fill ~293 ~60 ~33 ~295 ~62 ~33 stone
fill ~293 ~63 ~33 ~295 ~65 ~33 dirt
fill ~293 ~66 ~33 ~295 ~66 ~33 grass_block
fill ~296 ~60 ~33 ~299 ~63 ~33 stone
fill ~296 ~64 ~33 ~299 ~66 ~33 dirt
fill ~296 ~67 ~33 ~299 ~67 ~33 grass_block
fill ~300 ~60 ~33 ~302 ~64 ~33 stone
fill ~300 ~65 ~33 ~302 ~67 ~33 dirt
fill ~300 ~68 ~33 ~302 ~68 ~33 grass_block
fill ~303 ~60 ~33 ~303 ~65 ~33 stone
fill ~303 ~66 ~33 ~303 ~68 ~33 dirt
fill ~303 ~69 ~33 ~303 ~69 ~33 grass_block
fill ~288 ~60 ~34 ~290 ~63 ~34 stone
fill ~288 ~64 ~34 ~290 ~66 ~34 dirt
fill ~288 ~67 ~34 ~290 ~67 ~34 grass_block
fill ~291 ~60 ~34 ~295 ~62 ~34 stone
fill ~291 ~63 ~34 ~295 ~65 ~34 dirt
fill ~291 ~66 ~34 ~295 ~66 ~34 grass_block
fill ~296 ~60 ~34 ~297 ~63 ~34 stone
fill ~296 ~64 ~34 ~297 ~66 ~34 dirt
fill ~296 ~67 ~34 ~297 ~67 ~34 grass_block
fill ~298 ~60 ~34 ~301 ~64 ~34 stone
fill ~298 ~65 ~34 ~301 ~67 ~34 dirt
fill ~298 ~68 ~34 ~301 ~68 ~34 grass_block
fill ~302 ~60 ~34 ~303 ~65 ~34 stone
fill ~302 ~66 ~34 ~303 ~68 ~34 dirt
fill ~302 ~69 ~34 ~303 ~69 ~34 grass_block
fill ~288 ~60 ~35 ~289 ~63 ~35 stone
fill ~288 ~64 ~35 ~289 ~66 ~35 dirt
fill ~288 ~67 ~35 ~289 ~67 ~35 grass_block
fill ~290 ~60 ~35 ~294 ~62 ~35 stone
fill ~290 ~63 ~35 ~294 ~65 ~35 dirt
fill ~290 ~66 ~35 ~294 ~66 ~35 grass_block
fill ~295 ~60 ~35 ~296 ~63 ~35 stone
fill ~295 ~64 ~35 ~296 ~66 ~35 dirt
fill ~295 ~67 ~35 ~296 ~67 ~35 grass_block
fill ~297 ~60 ~35 ~299 ~64 ~35 stone
fill ~297 ~65 ~35 ~299 ~67 ~35 dirt
fill ~297 ~68 ~35 ~299 ~68 ~35 grass_block
fill ~300 ~60 ~35 ~303 ~65 ~35 stone
fill ~300 ~66 ~35 ~303 ~68 ~35 dirt
fill ~300 ~69 ~35 ~303 ~69 ~35 grass_block
fill ~288 ~60 ~36 ~289 ~63 ~36 stone
fill ~288 ~64 ~36 ~289 ~66 ~36 dirt
fill ~288 ~67 ~36 ~289 ~67 ~36 grass_block
fill ~290 ~60 ~36 ~294 ~62 ~36 stone
fill ~290 ~63 ~36 ~294 ~65 ~36 dirt
fill ~290 ~66 ~36 ~294 ~66 ~36 grass_block
fill ~295 ~60 ~36 ~297 ~63 ~36 stone
fill ~295 ~64 ~36 ~297 ~66 ~36 dirt
fill ~295 ~67 ~36 ~297 ~67 ~36 grass_block
fill ~298 ~60 ~36 ~299 ~64 ~36 stone
fill ~298 ~65 ~36 ~299 ~67 ~36 dirt
fill ~298 ~68 ~36 ~299 ~68 ~36 grass_block
fill ~300 ~60 ~36 ~303 ~65 ~36 stone
fill ~300 ~66 ~36 ~303 ~68 ~36 dirt
fill ~300 ~69 ~36 ~303 ~69 ~36 grass_block
fill ~288 ~60 ~37 ~289 ~63 ~37 stone
fill ~288 ~64 ~37 ~289 ~66 ~37 dirt
fill ~288 ~67 ~37 ~289 ~67 ~37 grass_block
fill ~290 ~60 ~37 ~294 ~62 ~37 stone
fill ~290 ~63 ~37 ~294 ~65 ~37 dirt
fill ~290 ~66 ~37 ~294 ~66 ~37 grass_block
fill ~295 ~60 ~37 ~297 ~63 ~37 stone
fill ~295 ~64 ~37 ~297 ~66 ~37 dirt
fill ~295 ~67 ~37 ~297 ~67 ~37 grass_block
fill ~298 ~60 ~37 ~299 ~64 ~37 stone
fill ~298 ~65 ~37 ~299 ~67 ~37 dirt
fill ~298 ~68 ~37 ~299 ~68 ~37 grass_block
fill ~300 ~60 ~37 ~303 ~65 ~37 stone
fill ~300 ~66 ~37 ~303 ~68 ~37 dirt
fill ~300 ~69 ~37 ~303 ~69 ~37 grass_block
fill ~288 ~60 ~38 ~290 ~63 ~38 stone
fill ~288 ~64 ~38 ~290 ~66 ~38 dirt
fill ~288 ~67 ~38 ~290 ~67 ~38 grass_block
fill ~291 ~60 ~38 ~295 ~62 ~38 stone
fill ~291 ~63 ~38 ~295 ~65 ~38 dirt
fill ~291 ~66 ~38 ~295 ~66 ~38 grass_block
fill ~296 ~60 ~38 ~297 ~63 ~38 stone
fill ~296 ~64 ~38 ~297 ~66 ~38 dirt
fill ~296 ~67 ~38 ~297 ~67 ~38 grass_block
fill ~298 ~60 ~38 ~300 ~64 ~38 stone
fill ~298 ~65 ~38 ~300 ~67 ~38 dirt
fill ~298 ~68 ~38 ~300 ~68 ~38 grass_block
fill ~301 ~60 ~38 ~303 ~65 ~38 stone
fill ~301 ~66 ~38 ~303 ~68 ~38 dirt
fill ~301 ~69 ~38 ~303 ~69 ~38 grass_block
fill ~288 ~60 ~39 ~288 ~63 ~39 stone
fill ~288 ~64 ~39 ~288 ~66 ~39 dirt
fill ~288 ~67 ~39 ~288 ~67 ~39 grass_block
fill ~289 ~60 ~39 ~294 ~62 ~39 stone
fill ~289 ~63 ~39 ~294 ~65 ~39 dirt
fill ~289 ~66 ~39 ~294 ~66 ~39 grass_block
fill ~295 ~60 ~39 ~298 ~63 ~39 stone
fill ~295 ~64 ~39 ~298 ~66 ~39 dirt
fill ~295 ~67 ~39 ~298 ~67 ~39 grass_block
fill ~299 ~60 ~39 ~300 ~64 ~39 stone
fill ~299 ~65 ~39 ~300 ~67 ~39 dirt
fill ~299 ~68 ~39 ~300 ~68 ~39 grass_block
fill ~301 ~60 ~39 ~302 ~65 ~39 stone
fill ~301 ~66 ~39 ~302 ~68 ~39 dirt
fill ~301 ~69 ~39 ~302 ~69 ~39 grass_block
fill ~303 ~60 ~39 ~303 ~64 ~39 stone
fill ~303 ~65 ~39 ~303 ~67 ~39 dirt
fill ~303 ~68 ~39 ~303 ~68 ~39 grass_block
fill ~288 ~60 ~40 ~295 ~62 ~40 stone
fill ~288 ~63 ~40 ~295 ~65 ~40 dirt
fill ~288 ~66 ~40 ~295 ~66 ~40 grass_block
fill ~296 ~60 ~40 ~298 ~63 ~40 stone
fill ~296 ~64 ~40 ~298 ~66 ~40 dirt
fill ~296 ~67 ~40 ~298 ~67 ~40 grass_block
fill ~299 ~60 ~40 ~303 ~64 ~40 stone
fill ~299 ~65 ~40 ~303 ~67 ~40 dirt
fill ~299 ~68 ~40 ~303 ~68 ~40 grass_block
fill ~288 ~60 ~41 ~295 ~62 ~41 stone
fill ~288 ~63 ~41 ~295 ~65 ~41 dirt
fill ~288 ~66 ~41 ~295 ~66 ~41 grass_block
fill ~296 ~60 ~41 ~299 ~63 ~41 stone
fill ~296 ~64 ~41 ~299 ~66 ~41 dirt
fill ~296 ~67 ~41 ~299 ~67 ~41 grass_block
fill ~300 ~60 ~41 ~303 ~64 ~41 stone
fill ~300 ~65 ~41 ~303 ~67 ~41 dirt
fill ~300 ~68 ~41 ~303 ~68 ~41 grass_block
fill ~288 ~60 ~42 ~295 ~62 ~42 stone
fill ~288 ~63 ~42 ~295 ~65 ~42 dirt
fill ~288 ~66 ~42 ~295 ~66 ~42 grass_block
fill ~296 ~60 ~42 ~296 ~63 ~42 stone
fill ~296 ~64 ~42 ~296 ~66 ~42 dirt
fill ~296 ~67 ~42 ~296 ~67 ~42 grass_block
fill ~297 ~60 ~42 ~303 ~64 ~42 stone
fill ~297 ~65 ~42 ~303 ~67 ~42 dirt
fill ~297 ~68 ~42 ~303 ~68 ~42 grass_block
fill ~288 ~60 ~43 ~291 ~62 ~43 stone
fill ~288 ~63 ~43 ~291 ~65 ~43 dirt
fill ~288 ~66 ~43 ~291 ~66 ~43 grass_block
fill ~292 ~60 ~43 ~292 ~61 ~43 stone
fill ~292 ~62 ~43 ~292 ~64 ~43 dirt
fill ~292 ~65 ~43 ~292 ~65 ~43 grass_block
fill ~293 ~60 ~43 ~295 ~62 ~43 stone
fill ~293 ~63 ~43 ~295 ~65 ~43 dirt
fill ~293 ~66 ~43 ~295 ~66 ~43 grass_block
fill ~296 ~60 ~43 ~296 ~63 ~43 stone
fill ~296 ~64 ~43 ~296 ~66 ~43 dirt
fill ~296 ~67 ~43 ~296 ~67 ~43 grass_block
fill ~297 ~60 ~43 ~303 ~64 ~43 stone
fill ~297 ~65 ~43 ~303 ~67 ~43 dirt
fill ~297 ~68 ~43 ~303 ~68 ~43 grass_block
fill ~288 ~60 ~44 ~295 ~62 ~44 stone
fill ~288 ~63 ~44 ~295 ~65 ~44 dirt
fill ~288 ~66 ~44 ~295 ~66 ~44 grass_block
fill ~296 ~60 ~44 ~296 ~63 ~44 stone
fill ~296 ~64 ~44 ~296 ~66 ~44 dirt
fill ~296 ~67 ~44 ~296 ~67 ~44 grass_block
fill ~297 ~60 ~44 ~303 ~64 ~44 stone
fill ~297 ~65 ~44 ~303 ~67 ~44 dirt
fill ~297 ~68 ~44 ~303 ~68 ~44 grass_block
fill ~288 ~60 ~45 ~290 ~62 ~45 stone
fill ~288 ~63 ~45 ~290 ~65 ~45 dirt
fill ~288 ~66 ~45 ~290 ~66 ~45 grass_block
fill ~291 ~60 ~45 ~292 ~61 ~45 stone
fill ~291 ~62 ~45 ~292 ~64 ~45 dirt
fill ~291 ~65 ~45 ~292 ~65 ~45 grass_block
fill ~293 ~60 ~45 ~294 ~62 ~45 stone
fill ~293 ~63 ~45 ~294 ~65 ~45 dirt
fill ~293 ~66 ~45 ~294 ~66 ~45 grass_block
fill ~295 ~60 ~45 ~296 ~63 ~45 stone
fill ~295 ~64 ~45 ~296 ~66 ~45 dirt
fill ~295 ~67 ~45 ~296 ~67 ~45 grass_block
fill ~297 ~60 ~45 ~303 ~64 ~45 stone
fill ~297 ~65 ~45 ~303 ~67 ~45 dirt
fill ~297 ~68 ~45 ~303 ~68 ~45 grass_block
fill ~288 ~60 ~46 ~292 ~61 ~46 stone
fill ~288 ~62 ~46 ~292 ~64 ~46 dirt
fill ~288 ~65 ~46 ~292 ~65 ~46 grass_block
fill ~293 ~60 ~46 ~294 ~62 ~46 stone
fill ~293 ~63 ~46 ~294 ~65 ~46 dirt
fill ~293 ~66 ~46 ~294 ~66 ~46 grass_block
fill ~295 ~60 ~46 ~296 ~63 ~46 stone
fill ~295 ~64 ~46 ~296 ~66 ~46 dirt
fill ~295 ~67 ~46 ~296 ~67 ~46 grass_block
fill ~297 ~60 ~46 ~303 ~64 ~46 stone
fill ~297 ~65 ~46 ~303 ~67 ~46 dirt
fill ~297 ~68 ~46 ~303 ~68 ~46 grass_block
fill ~288 ~60 ~47 ~292 ~61 ~47 stone
fill ~288 ~62 ~47 ~292 ~64 ~47 dirt
fill ~288 ~65 ~47 ~292 ~65 ~47 grass_block
fill ~293 ~60 ~47 ~295 ~62 ~47 stone
fill ~293 ~63 ~47 ~295 ~65 ~47 dirt
fill ~293 ~66 ~47 ~295 ~66 ~47 grass_block
fill ~296 ~60 ~47 ~298 ~63 ~47 stone
fill ~296 ~64 ~47 ~298 ~66 ~47 dirt
fill ~296 ~67 ~47 ~298 ~67 ~47 grass_block
fill ~299 ~60 ~47 ~303 ~64 ~47 stone
fill ~299 ~65 ~47 ~303 ~67 ~47 dirt
fill ~299 ~68 ~47 ~303 ~68 ~47 grass_block