fill ~80 ~60 ~64 ~83 ~66 ~64 stone
fill ~80 ~67 ~64 ~83 ~69 ~64 dirt
fill ~80 ~70 ~64 ~83 ~70 ~64 grass_block
fill ~84 ~60 ~64 ~85 ~65 ~64 stone
fill ~84 ~66 ~64 ~85 ~68 ~64 dirt
fill ~84 ~69 ~64 ~85 ~69 ~64 grass_block
fill ~86 ~60 ~64 ~88 ~64 ~64 stone
fill ~86 ~65 ~64 ~88 ~67 ~64 dirt
fill ~86 ~68 ~64 ~88 ~68 ~64 grass_block
fill ~89 ~60 ~64 ~90 ~63 ~64 stone
fill ~89 ~64 ~64 ~90 ~66 ~64 dirt
fill ~89 ~67 ~64 ~90 ~67 ~64 grass_block
fill ~91 ~60 ~64 ~91 ~64 ~64 stone
fill ~91 ~65 ~64 ~91 ~67 ~64 dirt
fill ~91 ~68 ~64 ~91 ~68 ~64 grass_block
fill ~92 ~60 ~64 ~95 ~63 ~64 stone
fill ~92 ~64 ~64 ~95 ~66 ~64 dirt
fill ~92 ~67 ~64 ~95 ~67 ~64 grass_block
fill ~80 ~60 ~65 ~85 ~66 ~65 stone
fill ~80 ~67 ~65 ~85 ~69 ~65 dirt
fill ~80 ~70 ~65 ~85 ~70 ~65 grass_block
fill ~86 ~60 ~65 ~86 ~65 ~65 stone
fill ~86 ~66 ~65 ~86 ~68 ~65 dirt
fill ~86 ~69 ~65 ~86 ~69 ~65 grass_block
fill ~87 ~60 ~65 ~92 ~64 ~65 stone
fill ~87 ~65 ~65 ~92 ~67 ~65 dirt
fill ~87 ~68 ~65 ~92 ~68 ~65 grass_block
fill ~93 ~60 ~65 ~95 ~63 ~65 stone
fill ~93 ~64 ~65 ~95 ~66 ~65 dirt
fill ~93 ~67 ~65 ~95 ~67 ~65 grass_block
fill ~80 ~60 ~66 ~86 ~66 ~66 stone
fill ~80 ~67 ~66 ~86 ~69 ~66 dirt
fill ~80 ~70 ~66 ~86 ~70 ~66 grass_block
fill ~87 ~60 ~66 ~88 ~65 ~66 stone
fill ~87 ~66 ~66 ~88 ~68 ~66 dirt
fill ~87 ~69 ~66 ~88 ~69 ~66 grass_block
fill ~89 ~60 ~66 ~93 ~64 ~66 stone
fill ~89 ~65 ~66 ~93 ~67 ~66 dirt
fill ~89 ~68 ~66 ~93 ~68 ~66 grass_block
fill ~94 ~60 ~66 ~95 ~63 ~66 stone
fill ~94 ~64 ~66 ~95 ~66 ~66 dirt
fill ~94 ~67 ~66 ~95 ~67 ~66 grass_block
fill ~80 ~60 ~67 ~87 ~66 ~67 stone
fill ~80 ~67 ~67 ~87 ~69 ~67 dirt
fill ~80 ~70 ~67 ~87 ~70 ~67 grass_block
fill ~88 ~60 ~67 ~90 ~65 ~67 stone
fill ~88 ~66 ~67 ~90 ~68 ~67 dirt
fill ~88 ~69 ~67 ~90 ~69 ~67 grass_block
fill ~91 ~60 ~67 ~93 ~64 ~67 stone
fill ~91 ~65 ~67 ~93 ~67 ~67 dirt
fill ~91 ~68 ~67 ~93 ~68 ~67 grass_block
fill ~94 ~60 ~67 ~95 ~63 ~67 stone
fill ~94 ~64 ~67 ~95 ~66 ~67 dirt
fill ~94 ~67 ~67 ~95 ~67 ~67 grass_block
fill ~80 ~60 ~68 ~82 ~65 ~68 stone
fill ~80 ~66 ~68 ~82 ~68 ~68 dirt
fill ~80 ~69 ~68 ~82 ~69 ~68 grass_block
fill ~83 ~60 ~68 ~88 ~66 ~68 stone
fill ~83 ~67 ~68 ~88 ~69 ~68 dirt
fill ~83 ~70 ~68 ~88 ~70 ~68 grass_block
fill ~89 ~60 ~68 ~91 ~65 ~68 stone
fill ~89 ~66 ~68 ~91 ~68 ~68 dirt
fill ~89 ~69 ~68 ~91 ~69 ~68 grass_block
fill ~92 ~60 ~68 ~94 ~64 ~68 stone
fill ~92 ~65 ~68 ~94 ~67 ~68 dirt
fill ~92 ~68 ~68 ~94 ~68 ~68 grass_block
fill ~95 ~60 ~68 ~95 ~63 ~68 stone
fill ~95 ~64 ~68 ~95 ~66 ~68 dirt
fill ~95 ~67 ~68 ~95 ~67 ~68 grass_block
fill ~80 ~60 ~69 ~84 ~65 ~69 stone
fill ~80 ~66 ~69 ~84 ~68 ~69 dirt
fill ~80 ~69 ~69 ~84 ~69 ~69 grass_block
fill ~85 ~60 ~69 ~90 ~66 ~69 stone
fill ~85 ~67 ~69 ~90 ~69 ~69 dirt
fill ~85 ~70 ~69 ~90 ~70 ~69 grass_block
fill ~91 ~60 ~69 ~93 ~65 ~69 stone
fill ~91 ~66 ~69 ~93 ~68 ~69 dirt
fill ~91 ~69 ~69 ~93 ~69 ~69 grass_block
fill ~94 ~60 ~69 ~95 ~64 ~69 stone
fill ~94 ~65 ~69 ~95 ~67 ~69 dirt
fill ~94 ~68 ~69 ~95 ~68 ~69 grass_block
fill ~80 ~60 ~70 ~85 ~65 ~70 stone
fill ~80 ~66 ~70 ~85 ~68 ~70 dirt
fill ~80 ~69 ~70 ~85 ~69 ~70 grass_block
fill ~86 ~60 ~70 ~92 ~66 ~70 stone
fill ~86 ~67 ~70 ~92 ~69 ~70 dirt
fill ~86 ~70 ~70 ~92 ~70 ~70 grass_block
fill ~93 ~60 ~70 ~94 ~65 ~70 stone
fill ~93 ~66 ~70 ~94 ~68 ~70 dirt
fill ~93 ~69 ~70 ~94 ~69 ~70 grass_block
fill ~95 ~60 ~70 ~95 ~64 ~70 stone
fill ~95 ~65 ~70 ~95 ~67 ~70 dirt
fill ~95 ~68 ~70 ~95 ~68 ~70 grass_block
fill ~80 ~60 ~71 ~80 ~65 ~71 stone
fill ~80 ~66 ~71 ~80 ~68 ~71 dirt
fill ~80 ~69 ~71 ~80 ~69 ~71 grass_block
fill ~81 ~60 ~71 ~82 ~64 ~71 stone
fill ~81 ~65 ~71 ~82 ~67 ~71 dirt
fill ~81 ~68 ~71 ~82 ~68 ~71 grass_block
fill ~83 ~60 ~71 ~87 ~65 ~71 stone
fill ~83 ~66 ~71 ~87 ~68 ~71 dirt
fill ~83 ~69 ~71 ~87 ~69 ~71 grass_block
fill ~88 ~60 ~71 ~93 ~66 ~71 stone
fill ~88 ~67 ~71 ~93 ~69 ~71 dirt
fill ~88 ~70 ~71 ~93 ~70 ~71 grass_block
fill ~94 ~60 ~71 ~95 ~65 ~71 stone
fill ~94 ~66 ~71 ~95 ~68 ~71 dirt
fill ~94 ~69 ~71 ~95 ~69 ~71 grass_block
fill ~80 ~60 ~72 ~83 ~64 ~72 stone
fill ~80 ~65 ~72 ~83 ~67 ~72 dirt
fill ~80 ~68 ~72 ~83 ~68 ~72 grass_block
fill ~84 ~60 ~72 ~87 ~65 ~72 stone
fill ~84 ~66 ~72 ~87 ~68 ~72 dirt
fill ~84 ~69 ~72 ~87 ~69 ~72 grass_block
fill ~88 ~60 ~72 ~95 ~66 ~72 stone
fill ~88 ~67 ~72 ~95 ~69 ~72 dirt
fill ~88 ~70 ~72 ~95 ~70 ~72 grass_block
fill ~80 ~60 ~73 ~84 ~64 ~73 stone
fill ~80 ~65 ~73 ~84 ~67 ~73 dirt
fill ~80 ~68 ~73 ~84 ~68 ~73 grass_block
fill ~85 ~60 ~73 ~92 ~65 ~73 stone
fill ~85 ~66 ~73 ~92 ~68 ~73 dirt
fill ~85 ~69 ~73 ~92 ~69 ~73 grass_block
fill ~93 ~60 ~73 ~95 ~66 ~73 stone
fill ~93 ~67 ~73 ~95 ~69 ~73 dirt
fill ~93 ~70 ~73 ~95 ~70 ~73 grass_block
fill ~80 ~60 ~74 ~85 ~64 ~74 stone
fill ~80 ~65 ~74 ~85 ~67 ~74 dirt
fill ~80 ~68 ~74 ~85 ~68 ~74 grass_block
fill ~86 ~60 ~74 ~94 ~65 ~74 stone
fill ~86 ~66 ~74 ~94 ~68 ~74 dirt
fill ~86 ~69 ~74 ~94 ~69 ~74 grass_block
fill ~95 ~60 ~74 ~95 ~66 ~74 stone
fill ~95 ~67 ~74 ~95 ~69 ~74 dirt
fill ~95 ~70 ~74 ~95 ~70 ~74 grass_block
fill ~80 ~60 ~75 ~82 ~63 ~75 stone
fill ~80 ~64 ~75 ~82 ~66 ~75 dirt
fill ~80 ~67 ~75 ~82 ~67 ~75 grass_block
fill ~83 ~60 ~75 ~87 ~64 ~75 stone
fill ~83 ~65 ~75 ~87 ~67 ~75 dirt
fill ~83 ~68 ~75 ~87 ~68 ~75 grass_block
fill ~88 ~60 ~75 ~95 ~65 ~75 stone
fill ~88 ~66 ~75 ~95 ~68 ~75 dirt
fill ~88 ~69 ~75 ~95 ~69 ~75 grass_block
fill ~80 ~60 ~76 ~83 ~63 ~76 stone
fill ~80 ~64 ~76 ~83 ~66 ~76 dirt
fill ~80 ~67 ~76 ~83 ~67 ~76 grass_block
fill ~84 ~60 ~76 ~91 ~64 ~76 stone
fill ~84 ~65 ~76 ~91 ~67 ~76 dirt
fill ~84 ~68 ~76 ~91 ~68 ~76 grass_block
fill ~92 ~60 ~76 ~95 ~65 ~76 stone
fill ~92 ~66 ~76 ~95 ~68 ~76 dirt
fill ~92 ~69 ~76 ~95 ~69 ~76 grass_block
fill ~80 ~60 ~77 ~86 ~63 ~77 stone
fill ~80 ~64 ~77 ~86 ~66 ~77 dirt
fill ~80 ~67 ~77 ~86 ~67 ~77 grass_block
fill ~87 ~60 ~77 ~92 ~64 ~77 stone
fill ~87 ~65 ~77 ~92 ~67 ~77 dirt
fill ~87 ~68 ~77 ~92 ~68 ~77 grass_block
fill ~93 ~60 ~77 ~95 ~65 ~77 stone
fill ~93 ~66 ~77 ~95 ~68 ~77 dirt
fill ~93 ~69 ~77 ~95 ~69 ~77 grass_block
fill ~80 ~60 ~78 ~88 ~63 ~78 stone
fill ~80 ~64 ~78 ~88 ~66 ~78 dirt
fill ~80 ~67 ~78 ~88 ~67 ~78 grass_block
fill ~89 ~60 ~78 ~94 ~64 ~78 stone
fill ~89 ~65 ~78 ~94 ~67 ~78 dirt
fill ~89 ~68 ~78 ~94 ~68 ~78 grass_block
fill ~95 ~60 ~78 ~95 ~65 ~78 stone
fill ~95 ~66 ~78 ~95 ~68 ~78 dirt
fill ~95 ~69 ~78 ~95 ~69 ~78 grass_block
fill ~80 ~60 ~79 ~82 ~64 ~79 stone
fill ~80 ~65 ~79 ~82 ~67 ~79 dirt
fill ~80 ~68 ~79 ~82 ~68 ~79 grass_block
fill ~83 ~60 ~79 ~90 ~63 ~79 stone
fill ~83 ~64 ~79 ~90 ~66 ~79 dirt
fill ~83 ~67 ~79 ~90 ~67 ~79 grass_block
fill ~91 ~60 ~79 ~95 ~64 ~79 stone
fill ~91 ~65 ~79 ~95 ~67 ~79 dirt
fill ~91 ~68 ~79 ~95 ~68 ~79 grass_block