fill ~160 ~60 ~64 ~160 ~66 ~64 stone
fill ~160 ~67 ~64 ~160 ~69 ~64 dirt
fill ~160 ~70 ~64 ~160 ~70 ~64 grass_block
fill ~161 ~60 ~64 ~163 ~65 ~64 stone
fill ~161 ~66 ~64 ~163 ~68 ~64 dirt
fill ~161 ~69 ~64 ~163 ~69 ~64 grass_block
fill ~164 ~60 ~64 ~165 ~64 ~64 stone
fill ~164 ~65 ~64 ~165 ~67 ~64 dirt
fill ~164 ~68 ~64 ~165 ~68 ~64 grass_block
fill ~166 ~60 ~64 ~168 ~65 ~64 stone
fill ~166 ~66 ~64 ~168 ~68 ~64 dirt
fill ~166 ~69 ~64 ~168 ~69 ~64 grass_block
fill ~169 ~60 ~64 ~175 ~66 ~64 stone
fill ~169 ~67 ~64 ~175 ~69 ~64 dirt
fill ~169 ~70 ~64 ~175 ~70 ~64 grass_block
fill ~160 ~60 ~65 ~163 ~65 ~65 stone
fill ~160 ~66 ~65 ~163 ~68 ~65 dirt
fill ~160 ~69 ~65 ~163 ~69 ~65 grass_block
fill ~164 ~60 ~65 ~165 ~64 ~65 stone
fill ~164 ~65 ~65 ~165 ~67 ~65 dirt
fill ~164 ~68 ~65 ~165 ~68 ~65 grass_block
fill ~166 ~60 ~65 ~169 ~65 ~65 stone
fill ~166 ~66 ~65 ~169 ~68 ~65 dirt
fill ~166 ~69 ~65 ~169 ~69 ~65 grass_block
fill ~170 ~60 ~65 ~175 ~66 ~65 stone
fill ~170 ~67 ~65 ~175 ~69 ~65 dirt
fill ~170 ~70 ~65 ~175 ~70 ~65 grass_block
fill ~160 ~60 ~66 ~163 ~65 ~66 stone
fill ~160 ~66 ~66 ~163 ~68 ~66 dirt
fill ~160 ~69 ~66 ~163 ~69 ~66 grass_block
fill ~164 ~60 ~66 ~166 ~64 ~66 stone
fill ~164 ~65 ~66 ~166 ~67 ~66 dirt
fill ~164 ~68 ~66 ~166 ~68 ~66 grass_block
fill ~167 ~60 ~66 ~170 ~65 ~66 stone
fill ~167 ~66 ~66 ~170 ~68 ~66 dirt
fill ~167 ~69 ~66 ~170 ~69 ~66 grass_block
fill ~171 ~60 ~66 ~175 ~66 ~66 stone
fill ~171 ~67 ~66 ~175 ~69 ~66 dirt
fill ~171 ~70 ~66 ~175 ~70 ~66 grass_block
fill ~160 ~60 ~67 ~164 ~65 ~67 stone
fill ~160 ~66 ~67 ~164 ~68 ~67 dirt
fill ~160 ~69 ~67 ~164 ~69 ~67 grass_block
fill ~165 ~60 ~67 ~167 ~64 ~67 stone
fill ~165 ~65 ~67 ~167 ~67 ~67 dirt
fill ~165 ~68 ~67 ~167 ~68 ~67 grass_block
fill ~168 ~60 ~67 ~171 ~65 ~67 stone
fill ~168 ~66 ~67 ~171 ~68 ~67 dirt
fill ~168 ~69 ~67 ~171 ~69 ~67 grass_block
fill ~172 ~60 ~67 ~175 ~66 ~67 stone
fill ~172 ~67 ~67 ~175 ~69 ~67 dirt
fill ~172 ~70 ~67 ~175 ~70 ~67 grass_block
fill ~160 ~60 ~68 ~164 ~65 ~68 stone
fill ~160 ~66 ~68 ~164 ~68 ~68 dirt
fill ~160 ~69 ~68 ~164 ~69 ~68 grass_block
fill ~165 ~60 ~68 ~168 ~64 ~68 stone
fill ~165 ~65 ~68 ~168 ~67 ~68 dirt
fill ~165 ~68 ~68 ~168 ~68 ~68 grass_block
fill ~169 ~60 ~68 ~172 ~65 ~68 stone
fill ~169 ~66 ~68 ~172 ~68 ~68 dirt
fill ~169 ~69 ~68 ~172 ~69 ~68 grass_block
fill ~173 ~60 ~68 ~174 ~66 ~68 stone
fill ~173 ~67 ~68 ~174 ~69 ~68 dirt
fill ~173 ~70 ~68 ~174 ~70 ~68 grass_block
fill ~175 ~60 ~68 ~175 ~65 ~68 stone
fill ~175 ~66 ~68 ~175 ~68 ~68 dirt
fill ~175 ~69 ~68 ~175 ~69 ~68 grass_block
fill ~160 ~60 ~69 ~160 ~64 ~69 stone
fill ~160 ~65 ~69 ~160 ~67 ~69 dirt
fill ~160 ~68 ~69 ~160 ~68 ~69 grass_block
fill ~161 ~60 ~69 ~165 ~65 ~69 stone
fill ~161 ~66 ~69 ~165 ~68 ~69 dirt
fill ~161 ~69 ~69 ~165 ~69 ~69 grass_block
fill ~166 ~60 ~69 ~169 ~64 ~69 stone
fill ~166 ~65 ~69 ~169 ~67 ~69 dirt
fill ~166 ~68 ~69 ~169 ~68 ~69 grass_block
fill ~170 ~60 ~69 ~175 ~65 ~69 stone
fill ~170 ~66 ~69 ~175 ~68 ~69 dirt
fill ~170 ~69 ~69 ~175 ~69 ~69 grass_block
fill ~160 ~60 ~70 ~160 ~64 ~70 stone
fill ~160 ~65 ~70 ~160 ~67 ~70 dirt
fill ~160 ~68 ~70 ~160 ~68 ~70 grass_block
fill ~161 ~60 ~70 ~165 ~65 ~70 stone
fill ~161 ~66 ~70 ~165 ~68 ~70 dirt
fill ~161 ~69 ~70 ~165 ~69 ~70 grass_block
fill ~166 ~60 ~70 ~170 ~64 ~70 stone
fill ~166 ~65 ~70 ~170 ~67 ~70 dirt
fill ~166 ~68 ~70 ~170 ~68 ~70 grass_block
fill ~171 ~60 ~70 ~175 ~65 ~70 stone
fill ~171 ~66 ~70 ~175 ~68 ~70 dirt
fill ~171 ~69 ~70 ~175 ~69 ~70 grass_block
fill ~160 ~60 ~71 ~161 ~64 ~71 stone
fill ~160 ~65 ~71 ~161 ~67 ~71 dirt
fill ~160 ~68 ~71 ~161 ~68 ~71 grass_block
fill ~162 ~60 ~71 ~165 ~65 ~71 stone
fill ~162 ~66 ~71 ~165 ~68 ~71 dirt
fill ~162 ~69 ~71 ~165 ~69 ~71 grass_block
fill ~166 ~60 ~71 ~171 ~64 ~71 stone
fill ~166 ~65 ~71 ~171 ~67 ~71 dirt
fill ~166 ~68 ~71 ~171 ~68 ~71 grass_block
fill ~172 ~60 ~71 ~175 ~65 ~71 stone
fill ~172 ~66 ~71 ~175 ~68 ~71 dirt
fill ~172 ~69 ~71 ~175 ~69 ~71 grass_block
fill ~160 ~60 ~72 ~161 ~64 ~72 stone
fill ~160 ~65 ~72 ~161 ~67 ~72 dirt
fill ~160 ~68 ~72 ~161 ~68 ~72 grass_block
fill ~162 ~60 ~72 ~166 ~65 ~72 stone
fill ~162 ~66 ~72 ~166 ~68 ~72 dirt
fill ~162 ~69 ~72 ~166 ~69 ~72 grass_block
fill ~167 ~60 ~72 ~172 ~64 ~72 stone
fill ~167 ~65 ~72 ~172 ~67 ~72 dirt
fill ~167 ~68 ~72 ~172 ~68 ~72 grass_block
fill ~173 ~60 ~72 ~175 ~65 ~72 stone
fill ~173 ~66 ~72 ~175 ~68 ~72 dirt
fill ~173 ~69 ~72 ~175 ~69 ~72 grass_block
fill ~160 ~60 ~73 ~162 ~64 ~73 stone
fill ~160 ~65 ~73 ~162 ~67 ~73 dirt
fill ~160 ~68 ~73 ~162 ~68 ~73 grass_block
fill ~163 ~60 ~73 ~167 ~65 ~73 stone
fill ~163 ~66 ~73 ~167 ~68 ~73 dirt
fill ~163 ~69 ~73 ~167 ~69 ~73 grass_block
fill ~168 ~60 ~73 ~173 ~64 ~73 stone
fill ~168 ~65 ~73 ~173 ~67 ~73 dirt
fill ~168 ~68 ~73 ~173 ~68 ~73 grass_block
fill ~174 ~60 ~73 ~175 ~65 ~73 stone
fill ~174 ~66 ~73 ~175 ~68 ~73 dirt
fill ~174 ~69 ~73 ~175 ~69 ~73 grass_block
fill ~160 ~60 ~74 ~162 ~64 ~74 stone
fill ~160 ~65 ~74 ~162 ~67 ~74 dirt
fill ~160 ~68 ~74 ~162 ~68 ~74 grass_block
fill ~163 ~60 ~74 ~167 ~65 ~74 stone
fill ~163 ~66 ~74 ~167 ~68 ~74 dirt
fill ~163 ~69 ~74 ~167 ~69 ~74 grass_block
fill ~168 ~60 ~74 ~170 ~64 ~74 stone
fill ~168 ~65 ~74 ~170 ~67 ~74 dirt
fill ~168 ~68 ~74 ~170 ~68 ~74 grass_block
fill ~171 ~60 ~74 ~171 ~63 ~74 stone
fill ~171 ~64 ~74 ~171 ~66 ~74 dirt
fill ~171 ~67 ~74 ~171 ~67 ~74 grass_block
fill ~172 ~60 ~74 ~174 ~64 ~74 stone
fill ~172 ~65 ~74 ~174 ~67 ~74 dirt
fill ~172 ~68 ~74 ~174 ~68 ~74 grass_block
fill ~175 ~60 ~74 ~175 ~65 ~74 stone
fill ~175 ~66 ~74 ~175 ~68 ~74 dirt
fill ~175 ~69 ~74 ~175 ~69 ~74 grass_block
fill ~160 ~60 ~75 ~160 ~63 ~75 stone
fill ~160 ~64 ~75 ~160 ~66 ~75 dirt
fill ~160 ~67 ~75 ~160 ~67 ~75 grass_block
fill ~161 ~60 ~75 ~163 ~64 ~75 stone
fill ~161 ~65 ~75 ~163 ~67 ~75 dirt
fill ~161 ~68 ~75 ~163 ~68 ~75 grass_block
fill ~164 ~60 ~75 ~167 ~65 ~75 stone
fill ~164 ~66 ~75 ~167 ~68 ~75 dirt
fill ~164 ~69 ~75 ~167 ~69 ~75 grass_block
fill ~168 ~60 ~75 ~170 ~64 ~75 stone
fill ~168 ~65 ~75 ~170 ~67 ~75 dirt
fill ~168 ~68 ~75 ~170 ~68 ~75 grass_block
fill ~171 ~60 ~75 ~172 ~63 ~75 stone
fill ~171 ~64 ~75 ~172 ~66 ~75 dirt
fill ~171 ~67 ~75 ~172 ~67 ~75 grass_block
fill ~173 ~60 ~75 ~175 ~64 ~75 stone
fill ~173 ~65 ~75 ~175 ~67 ~75 dirt
fill ~173 ~68 ~75 ~175 ~68 ~75 grass_block
fill ~160 ~60 ~76 ~161 ~63 ~76 stone
fill ~160 ~64 ~76 ~161 ~66 ~76 dirt
fill ~160 ~67 ~76 ~161 ~67 ~76 grass_block
fill ~162 ~60 ~76 ~165 ~64 ~76 stone
fill ~162 ~65 ~76 ~165 ~67 ~76 dirt
fill ~162 ~68 ~76 ~165 ~68 ~76 grass_block
fill ~166 ~60 ~76 ~168 ~65 ~76 stone
fill ~166 ~66 ~76 ~168 ~68 ~76 dirt
fill ~166 ~69 ~76 ~168 ~69 ~76 grass_block
fill ~169 ~60 ~76 ~172 ~64 ~76 stone
fill ~169 ~65 ~76 ~172 ~67 ~76 dirt
fill ~169 ~68 ~76 ~172 ~68 ~76 grass_block
fill ~173 ~60 ~76 ~173 ~63 ~76 stone
fill ~173 ~64 ~76 ~173 ~66 ~76 dirt
fill ~173 ~67 ~76 ~173 ~67 ~76 grass_block
fill ~174 ~60 ~76 ~175 ~64 ~76 stone
fill ~174 ~65 ~76 ~175 ~67 ~76 dirt
fill ~174 ~68 ~76 ~175 ~68 ~76 grass_block
fill ~160 ~60 ~77 ~162 ~63 ~77 stone
fill ~160 ~64 ~77 ~162 ~66 ~77 dirt
fill ~160 ~67 ~77 ~162 ~67 ~77 grass_block
fill ~163 ~60 ~77 ~166 ~64 ~77 stone
fill ~163 ~65 ~77 ~166 ~67 ~77 dirt
fill ~163 ~68 ~77 ~166 ~68 ~77 grass_block
fill ~167 ~60 ~77 ~168 ~65 ~77 stone
fill ~167 ~66 ~77 ~168 ~68 ~77 dirt
fill ~167 ~69 ~77 ~168 ~69 ~77 grass_block
fill ~169 ~60 ~77 ~172 ~64 ~77 stone
fill ~169 ~65 ~77 ~172 ~67 ~77 dirt
fill ~169 ~68 ~77 ~172 ~68 ~77 grass_block
fill ~173 ~60 ~77 ~174 ~63 ~77 stone
fill ~173 ~64 ~77 ~174 ~66 ~77 dirt
fill ~173 ~67 ~77 ~174 ~67 ~77 grass_block
fill ~175 ~60 ~77 ~175 ~64 ~77 stone
fill ~175 ~65 ~77 ~175 ~67 ~77 dirt
fill ~175 ~68 ~77 ~175 ~68 ~77 grass_block
fill ~160 ~60 ~78 ~164 ~63 ~78 stone
fill ~160 ~64 ~78 ~164 ~66 ~78 dirt
fill ~160 ~67 ~78 ~164 ~67 ~78 grass_block
fill ~165 ~60 ~78 ~166 ~64 ~78 stone
fill ~165 ~65 ~78 ~166 ~67 ~78 dirt
fill ~165 ~68 ~78 ~166 ~68 ~78 grass_block
fill ~167 ~60 ~78 ~169 ~65 ~78 stone
fill ~167 ~66 ~78 ~169 ~68 ~78 dirt
fill ~167 ~69 ~78 ~169 ~69 ~78 grass_block
fill ~170 ~60 ~78 ~172 ~64 ~78 stone
fill ~170 ~65 ~78 ~172 ~67 ~78 dirt
fill ~170 ~68 ~78 ~172 ~68 ~78 grass_block
fill ~173 ~60 ~78 ~174 ~63 ~78 stone
fill ~173 ~64 ~78 ~174 ~66 ~78 dirt
fill ~173 ~67 ~78 ~174 ~67 ~78 grass_block
fill ~175 ~60 ~78 ~175 ~64 ~78 stone
fill ~175 ~65 ~78 ~175 ~67 ~78 dirt
fill ~175 ~68 ~78 ~175 ~68 ~78 grass_block
fill ~160 ~60 ~79 ~160 ~64 ~79 stone
fill ~160 ~65 ~79 ~160 ~67 ~79 dirt
fill ~160 ~68 ~79 ~160 ~68 ~79 grass_block
fill ~161 ~60 ~79 ~165 ~63 ~79 stone
fill ~161 ~64 ~79 ~165 ~66 ~79 dirt
fill ~161 ~67 ~79 ~165 ~67 ~79 grass_block
fill ~166 ~60 ~79 ~168 ~64 ~79 stone
fill ~166 ~65 ~79 ~168 ~67 ~79 dirt
fill ~166 ~68 ~79 ~168 ~68 ~79 grass_block
fill ~169 ~60 ~79 ~169 ~65 ~79 stone
fill ~169 ~66 ~79 ~169 ~68 ~79 dirt
fill ~169 ~69 ~79 ~169 ~69 ~79 grass_block
fill ~170 ~60 ~79 ~172 ~64 ~79 stone
fill ~170 ~65 ~79 ~172 ~67 ~79 dirt
fill ~170 ~68 ~79 ~172 ~68 ~79 grass_block
fill ~173 ~60 ~79 ~175 ~63 ~79 stone
fill ~173 ~64 ~79 ~175 ~66 ~79 dirt
fill ~173 ~67 ~79 ~175 ~67 ~79 grass_block