fill ~432 ~60 ~80 ~433 ~63 ~80 stone
fill ~432 ~64 ~80 ~433 ~66 ~80 dirt
fill ~432 ~67 ~80 ~433 ~67 ~80 grass_block
fill ~434 ~60 ~80 ~442 ~64 ~80 stone
fill ~434 ~65 ~80 ~442 ~67 ~80 dirt
fill ~434 ~68 ~80 ~442 ~68 ~80 grass_block
fill ~443 ~60 ~80 ~444 ~63 ~80 stone
fill ~443 ~64 ~80 ~444 ~66 ~80 dirt
fill ~443 ~67 ~80 ~444 ~67 ~80 grass_block
fill ~445 ~60 ~80 ~447 ~64 ~80 stone
fill ~445 ~65 ~80 ~447 ~67 ~80 dirt
fill ~445 ~68 ~80 ~447 ~68 ~80 grass_block
fill ~432 ~60 ~81 ~433 ~63 ~81 stone
fill ~432 ~64 ~81 ~433 ~66 ~81 dirt
fill ~432 ~67 ~81 ~433 ~67 ~81 grass_block
fill ~434 ~60 ~81 ~442 ~64 ~81 stone
fill ~434 ~65 ~81 ~442 ~67 ~81 dirt
fill ~434 ~68 ~81 ~442 ~68 ~81 grass_block
fill ~443 ~60 ~81 ~445 ~63 ~81 stone
fill ~443 ~64 ~81 ~445 ~66 ~81 dirt
fill ~443 ~67 ~81 ~445 ~67 ~81 grass_block
fill ~446 ~60 ~81 ~447 ~64 ~81 stone
fill ~446 ~65 ~81 ~447 ~67 ~81 dirt
fill ~446 ~68 ~81 ~447 ~68 ~81 grass_block
fill ~432 ~60 ~82 ~432 ~63 ~82 stone
fill ~432 ~64 ~82 ~432 ~66 ~82 dirt
fill ~432 ~67 ~82 ~432 ~67 ~82 grass_block
fill ~433 ~60 ~82 ~442 ~64 ~82 stone
fill ~433 ~65 ~82 ~442 ~67 ~82 dirt
fill ~433 ~68 ~82 ~442 ~68 ~82 grass_block
fill ~443 ~60 ~82 ~446 ~63 ~82 stone
fill ~443 ~64 ~82 ~446 ~66 ~82 dirt
fill ~443 ~67 ~82 ~446 ~67 ~82 grass_block
fill ~447 ~60 ~82 ~447 ~64 ~82 stone
fill ~447 ~65 ~82 ~447 ~67 ~82 dirt
fill ~447 ~68 ~82 ~447 ~68 ~82 grass_block
fill ~432 ~60 ~83 ~432 ~63 ~83 stone
fill ~432 ~64 ~83 ~432 ~66 ~83 dirt
fill ~432 ~67 ~83 ~432 ~67 ~83 grass_block
fill ~433 ~60 ~83 ~443 ~64 ~83 stone
fill ~433 ~65 ~83 ~443 ~67 ~83 dirt
fill ~433 ~68 ~83 ~443 ~68 ~83 grass_block
fill ~444 ~60 ~83 ~446 ~63 ~83 stone
fill ~444 ~64 ~83 ~446 ~66 ~83 dirt
fill ~444 ~67 ~83 ~446 ~67 ~83 grass_block
fill ~447 ~60 ~83 ~447 ~64 ~83 stone
fill ~447 ~65 ~83 ~447 ~67 ~83 dirt
fill ~447 ~68 ~83 ~447 ~68 ~83 grass_block
fill ~432 ~60 ~84 ~432 ~63 ~84 stone
fill ~432 ~64 ~84 ~432 ~66 ~84 dirt
fill ~432 ~67 ~84 ~432 ~67 ~84 grass_block
fill ~433 ~60 ~84 ~443 ~64 ~84 stone
fill ~433 ~65 ~84 ~443 ~67 ~84 dirt
fill ~433 ~68 ~84 ~443 ~68 ~84 grass_block
fill ~444 ~60 ~84 ~447 ~63 ~84 stone
fill ~444 ~64 ~84 ~447 ~66 ~84 dirt
fill ~444 ~67 ~84 ~447 ~67 ~84 grass_block
fill ~432 ~60 ~85 ~432 ~63 ~85 stone
fill ~432 ~64 ~85 ~432 ~66 ~85 dirt
fill ~432 ~67 ~85 ~432 ~67 ~85 grass_block
fill ~433 ~60 ~85 ~443 ~64 ~85 stone
fill ~433 ~65 ~85 ~443 ~67 ~85 dirt
fill ~433 ~68 ~85 ~443 ~68 ~85 grass_block
fill ~444 ~60 ~85 ~447 ~63 ~85 stone
fill ~444 ~64 ~85 ~447 ~66 ~85 dirt
fill ~444 ~67 ~85 ~447 ~67 ~85 grass_block
fill ~432 ~60 ~86 ~432 ~63 ~86 stone
fill ~432 ~64 ~86 ~432 ~66 ~86 dirt
fill ~432 ~67 ~86 ~432 ~67 ~86 grass_block
fill ~433 ~60 ~86 ~443 ~64 ~86 stone
fill ~433 ~65 ~86 ~443 ~67 ~86 dirt
fill ~433 ~68 ~86 ~443 ~68 ~86 grass_block
fill ~444 ~60 ~86 ~447 ~63 ~86 stone
fill ~444 ~64 ~86 ~447 ~66 ~86 dirt
fill ~444 ~67 ~86 ~447 ~67 ~86 grass_block
fill ~432 ~60 ~87 ~433 ~63 ~87 stone
fill ~432 ~64 ~87 ~433 ~66 ~87 dirt
fill ~432 ~67 ~87 ~433 ~67 ~87 grass_block
fill ~434 ~60 ~87 ~443 ~64 ~87 stone
fill ~434 ~65 ~87 ~443 ~67 ~87 dirt
fill ~434 ~68 ~87 ~443 ~68 ~87 grass_block
fill ~444 ~60 ~87 ~447 ~63 ~87 stone
fill ~444 ~64 ~87 ~447 ~66 ~87 dirt
fill ~444 ~67 ~87 ~447 ~67 ~87 grass_block
fill ~432 ~60 ~88 ~435 ~63 ~88 stone
fill ~432 ~64 ~88 ~435 ~66 ~88 dirt
fill ~432 ~67 ~88 ~435 ~67 ~88 grass_block
fill ~436 ~60 ~88 ~443 ~64 ~88 stone
fill ~436 ~65 ~88 ~443 ~67 ~88 dirt
fill ~436 ~68 ~88 ~443 ~68 ~88 grass_block
fill ~444 ~60 ~88 ~447 ~63 ~88 stone
fill ~444 ~64 ~88 ~447 ~66 ~88 dirt
fill ~444 ~67 ~88 ~447 ~67 ~88 grass_block
fill ~432 ~60 ~89 ~437 ~63 ~89 stone
fill ~432 ~64 ~89 ~437 ~66 ~89 dirt
fill ~432 ~67 ~89 ~437 ~67 ~89 grass_block
fill ~438 ~60 ~89 ~443 ~64 ~89 stone
fill ~438 ~65 ~89 ~443 ~67 ~89 dirt
fill ~438 ~68 ~89 ~443 ~68 ~89 grass_block
fill ~444 ~60 ~89 ~447 ~63 ~89 stone
fill ~444 ~64 ~89 ~447 ~66 ~89 dirt
fill ~444 ~67 ~89 ~447 ~67 ~89 grass_block
fill ~432 ~60 ~90 ~432 ~62 ~90 stone
fill ~432 ~63 ~90 ~432 ~65 ~90 dirt
fill ~432 ~66 ~90 ~432 ~66 ~90 grass_block
fill ~433 ~60 ~90 ~439 ~63 ~90 stone
fill ~433 ~64 ~90 ~439 ~66 ~90 dirt
fill ~433 ~67 ~90 ~439 ~67 ~90 grass_block
fill ~440 ~60 ~90 ~443 ~64 ~90 stone
fill ~440 ~65 ~90 ~443 ~67 ~90 dirt
fill ~440 ~68 ~90 ~443 ~68 ~90 grass_block
fill ~444 ~60 ~90 ~447 ~63 ~90 stone
fill ~444 ~64 ~90 ~447 ~66 ~90 dirt
fill ~444 ~67 ~90 ~447 ~67 ~90 grass_block
fill ~432 ~60 ~91 ~432 ~62 ~91 stone
fill ~432 ~63 ~91 ~432 ~65 ~91 dirt
fill ~432 ~66 ~91 ~432 ~66 ~91 grass_block
fill ~433 ~60 ~91 ~441 ~63 ~91 stone
fill ~433 ~64 ~91 ~441 ~66 ~91 dirt
fill ~433 ~67 ~91 ~441 ~67 ~91 grass_block
fill ~442 ~60 ~91 ~443 ~64 ~91 stone
fill ~442 ~65 ~91 ~443 ~67 ~91 dirt
fill ~442 ~68 ~91 ~443 ~68 ~91 grass_block
fill ~444 ~60 ~91 ~447 ~63 ~91 stone
fill ~444 ~64 ~91 ~447 ~66 ~91 dirt
fill ~444 ~67 ~91 ~447 ~67 ~91 grass_block
fill ~432 ~60 ~92 ~435 ~62 ~92 stone
fill ~432 ~63 ~92 ~435 ~65 ~92 dirt
fill ~432 ~66 ~92 ~435 ~66 ~92 grass_block
fill ~436 ~60 ~92 ~447 ~63 ~92 stone
fill ~436 ~64 ~92 ~447 ~66 ~92 dirt
fill ~436 ~67 ~92 ~447 ~67 ~92 grass_block
fill ~432 ~60 ~93 ~439 ~62 ~93 stone
fill ~432 ~63 ~93 ~439 ~65 ~93 dirt
fill ~432 ~66 ~93 ~439 ~66 ~93 grass_block
fill ~440 ~60 ~93 ~447 ~63 ~93 stone
fill ~440 ~64 ~93 ~447 ~66 ~93 dirt
fill ~440 ~67 ~93 ~447 ~67 ~93 grass_block
fill ~432 ~60 ~94 ~441 ~62 ~94 stone
fill ~432 ~63 ~94 ~441 ~65 ~94 dirt
fill ~432 ~66 ~94 ~441 ~66 ~94 grass_block
fill ~442 ~60 ~94 ~447 ~63 ~94 stone
fill ~442 ~64 ~94 ~447 ~66 ~94 dirt
fill ~442 ~67 ~94 ~447 ~67 ~94 grass_block
fill ~432 ~60 ~95 ~432 ~61 ~95 stone
fill ~432 ~62 ~95 ~432 ~64 ~95 dirt
fill ~432 ~65 ~95 ~432 ~65 ~95 grass_block
fill ~433 ~60 ~95 ~443 ~62 ~95 stone
fill ~433 ~63 ~95 ~443 ~65 ~95 dirt
fill ~433 ~66 ~95 ~443 ~66 ~95 grass_block
fill ~444 ~60 ~95 ~447 ~63 ~95 stone
fill ~444 ~64 ~95 ~447 ~66 ~95 dirt
fill ~444 ~67 ~95 ~447 ~67 ~95 grass_block