fill ~224 ~60 ~112 ~228 ~66 ~112 stone
fill ~224 ~67 ~112 ~228 ~69 ~112 dirt
fill ~224 ~70 ~112 ~228 ~70 ~112 grass_block
fill ~229 ~60 ~112 ~233 ~65 ~112 stone
fill ~229 ~66 ~112 ~233 ~68 ~112 dirt
fill ~229 ~69 ~112 ~233 ~69 ~112 grass_block
fill ~234 ~60 ~112 ~237 ~64 ~112 stone
fill ~234 ~65 ~112 ~237 ~67 ~112 dirt
fill ~234 ~68 ~112 ~237 ~68 ~112 grass_block
fill ~238 ~60 ~112 ~239 ~63 ~112 stone
fill ~238 ~64 ~112 ~239 ~66 ~112 dirt
fill ~238 ~67 ~112 ~239 ~67 ~112 grass_block
fill ~224 ~60 ~113 ~235 ~65 ~113 stone
fill ~224 ~66 ~113 ~235 ~68 ~113 dirt
fill ~224 ~69 ~113 ~235 ~69 ~113 grass_block
fill ~236 ~60 ~113 ~239 ~64 ~113 stone
fill ~236 ~65 ~113 ~239 ~67 ~113 dirt
fill ~236 ~68 ~113 ~239 ~68 ~113 grass_block
fill ~224 ~60 ~114 ~237 ~65 ~114 stone
fill ~224 ~66 ~114 ~237 ~68 ~114 dirt
fill ~224 ~69 ~114 ~237 ~69 ~114 grass_block
fill ~238 ~60 ~114 ~239 ~64 ~114 stone
fill ~238 ~65 ~114 ~239 ~67 ~114 dirt
fill ~238 ~68 ~114 ~239 ~68 ~114 grass_block
fill ~224 ~60 ~115 ~236 ~65 ~115 stone
fill ~224 ~66 ~115 ~236 ~68 ~115 dirt
fill ~224 ~69 ~115 ~236 ~69 ~115 grass_block
fill ~237 ~60 ~115 ~239 ~64 ~115 stone
fill ~237 ~65 ~115 ~239 ~67 ~115 dirt
fill ~237 ~68 ~115 ~239 ~68 ~115 grass_block
fill ~224 ~60 ~116 ~228 ~64 ~116 stone
fill ~224 ~65 ~116 ~228 ~67 ~116 dirt
fill ~224 ~68 ~116 ~228 ~68 ~116 grass_block
fill ~229 ~60 ~116 ~233 ~65 ~116 stone
fill ~229 ~66 ~116 ~233 ~68 ~116 dirt
fill ~229 ~69 ~116 ~233 ~69 ~116 grass_block
fill ~234 ~60 ~116 ~235 ~66 ~116 stone
fill ~234 ~67 ~116 ~235 ~69 ~116 dirt
fill ~234 ~70 ~116 ~235 ~70 ~116 grass_block
fill ~236 ~60 ~116 ~237 ~65 ~116 stone
fill ~236 ~66 ~116 ~237 ~68 ~116 dirt
fill ~236 ~69 ~116 ~237 ~69 ~116 grass_block
fill ~238 ~60 ~116 ~239 ~64 ~116 stone
fill ~238 ~65 ~116 ~239 ~67 ~116 dirt
fill ~238 ~68 ~116 ~239 ~68 ~116 grass_block
fill ~224 ~60 ~117 ~229 ~64 ~117 stone
fill ~224 ~65 ~117 ~229 ~67 ~117 dirt
fill ~224 ~68 ~117 ~229 ~68 ~117 grass_block
fill ~230 ~60 ~117 ~234 ~65 ~117 stone
fill ~230 ~66 ~117 ~234 ~68 ~117 dirt
fill ~230 ~69 ~117 ~234 ~69 ~117 grass_block
fill ~235 ~60 ~117 ~236 ~66 ~117 stone
fill ~235 ~67 ~117 ~236 ~69 ~117 dirt
fill ~235 ~70 ~117 ~236 ~70 ~117 grass_block
fill ~237 ~60 ~117 ~239 ~65 ~117 stone
fill ~237 ~66 ~117 ~239 ~68 ~117 dirt
fill ~237 ~69 ~117 ~239 ~69 ~117 grass_block
fill ~224 ~60 ~118 ~229 ~64 ~118 stone
fill ~224 ~65 ~118 ~229 ~67 ~118 dirt
fill ~224 ~68 ~118 ~229 ~68 ~118 grass_block
fill ~230 ~60 ~118 ~239 ~65 ~118 stone
fill ~230 ~66 ~118 ~239 ~68 ~118 dirt
fill ~230 ~69 ~118 ~239 ~69 ~118 grass_block
fill ~224 ~60 ~119 ~226 ~63 ~119 stone
fill ~224 ~64 ~119 ~226 ~66 ~119 dirt
fill ~224 ~67 ~119 ~226 ~67 ~119 grass_block
fill ~227 ~60 ~119 ~229 ~64 ~119 stone
fill ~227 ~65 ~119 ~229 ~67 ~119 dirt
fill ~227 ~68 ~119 ~229 ~68 ~119 grass_block
fill ~230 ~60 ~119 ~239 ~65 ~119 stone
fill ~230 ~66 ~119 ~239 ~68 ~119 dirt
fill ~230 ~69 ~119 ~239 ~69 ~119 grass_block
fill ~224 ~60 ~120 ~226 ~63 ~120 stone
fill ~224 ~64 ~120 ~226 ~66 ~120 dirt
fill ~224 ~67 ~120 ~226 ~67 ~120 grass_block
fill ~227 ~60 ~120 ~230 ~64 ~120 stone
fill ~227 ~65 ~120 ~230 ~67 ~120 dirt
fill ~227 ~68 ~120 ~230 ~68 ~120 grass_block
fill ~231 ~60 ~120 ~239 ~65 ~120 stone
fill ~231 ~66 ~120 ~239 ~68 ~120 dirt
fill ~231 ~69 ~120 ~239 ~69 ~120 grass_block
fill ~224 ~60 ~121 ~226 ~63 ~121 stone
fill ~224 ~64 ~121 ~226 ~66 ~121 dirt
fill ~224 ~67 ~121 ~226 ~67 ~121 grass_block
fill ~227 ~60 ~121 ~230 ~64 ~121 stone
fill ~227 ~65 ~121 ~230 ~67 ~121 dirt
fill ~227 ~68 ~121 ~230 ~68 ~121 grass_block
fill ~231 ~60 ~121 ~239 ~65 ~121 stone
fill ~231 ~66 ~121 ~239 ~68 ~121 dirt
fill ~231 ~69 ~121 ~239 ~69 ~121 grass_block
fill ~224 ~60 ~122 ~226 ~63 ~122 stone
fill ~224 ~64 ~122 ~226 ~66 ~122 dirt
fill ~224 ~67 ~122 ~226 ~67 ~122 grass_block
fill ~227 ~60 ~122 ~229 ~64 ~122 stone
fill ~227 ~65 ~122 ~229 ~67 ~122 dirt
fill ~227 ~68 ~122 ~229 ~68 ~122 grass_block
fill ~230 ~60 ~122 ~232 ~65 ~122 stone
fill ~230 ~66 ~122 ~232 ~68 ~122 dirt
fill ~230 ~69 ~122 ~232 ~69 ~122 grass_block
fill ~233 ~60 ~122 ~236 ~64 ~122 stone
fill ~233 ~65 ~122 ~236 ~67 ~122 dirt
fill ~233 ~68 ~122 ~236 ~68 ~122 grass_block
fill ~237 ~60 ~122 ~239 ~65 ~122 stone
fill ~237 ~66 ~122 ~239 ~68 ~122 dirt
fill ~237 ~69 ~122 ~239 ~69 ~122 grass_block
fill ~224 ~60 ~123 ~226 ~63 ~123 stone
fill ~224 ~64 ~123 ~226 ~66 ~123 dirt
fill ~224 ~67 ~123 ~226 ~67 ~123 grass_block
fill ~227 ~60 ~123 ~230 ~64 ~123 stone
fill ~227 ~65 ~123 ~230 ~67 ~123 dirt
fill ~227 ~68 ~123 ~230 ~68 ~123 grass_block
fill ~231 ~60 ~123 ~231 ~65 ~123 stone
fill ~231 ~66 ~123 ~231 ~68 ~123 dirt
fill ~231 ~69 ~123 ~231 ~69 ~123 grass_block
fill ~232 ~60 ~123 ~237 ~64 ~123 stone
fill ~232 ~65 ~123 ~237 ~67 ~123 dirt
fill ~232 ~68 ~123 ~237 ~68 ~123 grass_block
fill ~238 ~60 ~123 ~239 ~65 ~123 stone
fill ~238 ~66 ~123 ~239 ~68 ~123 dirt
fill ~238 ~69 ~123 ~239 ~69 ~123 grass_block
fill ~224 ~60 ~124 ~226 ~63 ~124 stone
fill ~224 ~64 ~124 ~226 ~66 ~124 dirt
fill ~224 ~67 ~124 ~226 ~67 ~124 grass_block
fill ~227 ~60 ~124 ~238 ~64 ~124 stone
fill ~227 ~65 ~124 ~238 ~67 ~124 dirt
fill ~227 ~68 ~124 ~238 ~68 ~124 grass_block
fill ~239 ~60 ~124 ~239 ~65 ~124 stone
fill ~239 ~66 ~124 ~239 ~68 ~124 dirt
fill ~239 ~69 ~124 ~239 ~69 ~124 grass_block
fill ~224 ~60 ~125 ~226 ~63 ~125 stone
fill ~224 ~64 ~125 ~226 ~66 ~125 dirt
fill ~224 ~67 ~125 ~226 ~67 ~125 grass_block
fill ~227 ~60 ~125 ~239 ~64 ~125 stone
fill ~227 ~65 ~125 ~239 ~67 ~125 dirt
fill ~227 ~68 ~125 ~239 ~68 ~125 grass_block
fill ~224 ~60 ~126 ~226 ~63 ~126 stone
fill ~224 ~64 ~126 ~226 ~66 ~126 dirt
fill ~224 ~67 ~126 ~226 ~67 ~126 grass_block
fill ~227 ~60 ~126 ~235 ~64 ~126 stone
fill ~227 ~65 ~126 ~235 ~67 ~126 dirt
fill ~227 ~68 ~126 ~235 ~68 ~126 grass_block
fill ~236 ~60 ~126 ~236 ~63 ~126 stone
fill ~236 ~64 ~126 ~236 ~66 ~126 dirt
fill ~236 ~67 ~126 ~236 ~67 ~126 grass_block
fill ~237 ~60 ~126 ~239 ~64 ~126 stone
fill ~237 ~65 ~126 ~239 ~67 ~126 dirt
fill ~237 ~68 ~126 ~239 ~68 ~126 grass_block
fill ~224 ~60 ~127 ~227 ~63 ~127 stone
fill ~224 ~64 ~127 ~227 ~66 ~127 dirt
fill ~224 ~67 ~127 ~227 ~67 ~127 grass_block
fill ~228 ~60 ~127 ~235 ~64 ~127 stone
fill ~228 ~65 ~127 ~235 ~67 ~127 dirt
fill ~228 ~68 ~127 ~235 ~68 ~127 grass_block
fill ~236 ~60 ~127 ~237 ~63 ~127 stone
fill ~236 ~64 ~127 ~237 ~66 ~127 dirt
fill ~236 ~67 ~127 ~237 ~67 ~127 grass_block
fill ~238 ~60 ~127 ~239 ~64 ~127 stone
fill ~238 ~65 ~127 ~239 ~67 ~127 dirt
fill ~238 ~68 ~127 ~239 ~68 ~127 grass_block