fill ~416 ~60 ~16 ~426 ~63 ~16 stone
fill ~416 ~64 ~16 ~426 ~66 ~16 dirt
fill ~416 ~67 ~16 ~426 ~67 ~16 grass_block
fill ~427 ~60 ~16 ~427 ~62 ~16 stone
fill ~427 ~63 ~16 ~427 ~65 ~16 dirt
fill ~427 ~66 ~16 ~427 ~66 ~16 grass_block
fill ~428 ~60 ~16 ~431 ~63 ~16 stone
fill ~428 ~64 ~16 ~431 ~66 ~16 dirt
fill ~428 ~67 ~16 ~431 ~67 ~16 grass_block
fill ~416 ~60 ~17 ~425 ~63 ~17 stone
fill ~416 ~64 ~17 ~425 ~66 ~17 dirt
fill ~416 ~67 ~17 ~425 ~67 ~17 grass_block
fill ~426 ~60 ~17 ~428 ~62 ~17 stone
fill ~426 ~63 ~17 ~428 ~65 ~17 dirt
fill ~426 ~66 ~17 ~428 ~66 ~17 grass_block
fill ~429 ~60 ~17 ~431 ~63 ~17 stone
fill ~429 ~64 ~17 ~431 ~66 ~17 dirt
fill ~429 ~67 ~17 ~431 ~67 ~17 grass_block
fill ~416 ~60 ~18 ~419 ~62 ~18 stone
fill ~416 ~63 ~18 ~419 ~65 ~18 dirt
fill ~416 ~66 ~18 ~419 ~66 ~18 grass_block
fill ~420 ~60 ~18 ~426 ~63 ~18 stone
fill ~420 ~64 ~18 ~426 ~66 ~18 dirt
fill ~420 ~67 ~18 ~426 ~67 ~18 grass_block
fill ~427 ~60 ~18 ~428 ~62 ~18 stone
fill ~427 ~63 ~18 ~428 ~65 ~18 dirt
fill ~427 ~66 ~18 ~428 ~66 ~18 grass_block
fill ~429 ~60 ~18 ~431 ~63 ~18 stone
fill ~429 ~64 ~18 ~431 ~66 ~18 dirt
fill ~429 ~67 ~18 ~431 ~67 ~18 grass_block
fill ~416 ~60 ~19 ~422 ~62 ~19 stone
fill ~416 ~63 ~19 ~422 ~65 ~19 dirt
fill ~416 ~66 ~19 ~422 ~66 ~19 grass_block
fill ~423 ~60 ~19 ~425 ~63 ~19 stone
fill ~423 ~64 ~19 ~425 ~66 ~19 dirt
fill ~423 ~67 ~19 ~425 ~67 ~19 grass_block
fill ~426 ~60 ~19 ~429 ~62 ~19 stone
fill ~426 ~63 ~19 ~429 ~65 ~19 dirt
fill ~426 ~66 ~19 ~429 ~66 ~19 grass_block
fill ~430 ~60 ~19 ~431 ~63 ~19 stone
fill ~430 ~64 ~19 ~431 ~66 ~19 dirt
fill ~430 ~67 ~19 ~431 ~67 ~19 grass_block
fill ~416 ~60 ~20 ~424 ~62 ~20 stone
fill ~416 ~63 ~20 ~424 ~65 ~20 dirt
fill ~416 ~66 ~20 ~424 ~66 ~20 grass_block
fill ~425 ~60 ~20 ~425 ~63 ~20 stone
fill ~425 ~64 ~20 ~425 ~66 ~20 dirt
fill ~425 ~67 ~20 ~425 ~67 ~20 grass_block
fill ~426 ~60 ~20 ~429 ~62 ~20 stone
fill ~426 ~63 ~20 ~429 ~65 ~20 dirt
fill ~426 ~66 ~20 ~429 ~66 ~20 grass_block
fill ~430 ~60 ~20 ~431 ~63 ~20 stone
fill ~430 ~64 ~20 ~431 ~66 ~20 dirt
fill ~430 ~67 ~20 ~431 ~67 ~20 grass_block
fill ~416 ~60 ~21 ~416 ~62 ~21 stone
fill ~416 ~63 ~21 ~416 ~65 ~21 dirt
fill ~416 ~66 ~21 ~416 ~66 ~21 grass_block
fill ~417 ~60 ~21 ~421 ~61 ~21 stone
fill ~417 ~62 ~21 ~421 ~64 ~21 dirt
fill ~417 ~65 ~21 ~421 ~65 ~21 grass_block
fill ~422 ~60 ~21 ~430 ~62 ~21 stone
fill ~422 ~63 ~21 ~430 ~65 ~21 dirt
fill ~422 ~66 ~21 ~430 ~66 ~21 grass_block
fill ~431 ~60 ~21 ~431 ~63 ~21 stone
fill ~431 ~64 ~21 ~431 ~66 ~21 dirt
fill ~431 ~67 ~21 ~431 ~67 ~21 grass_block
fill ~416 ~60 ~22 ~423 ~61 ~22 stone
fill ~416 ~62 ~22 ~423 ~64 ~22 dirt
fill ~416 ~65 ~22 ~423 ~65 ~22 grass_block
fill ~424 ~60 ~22 ~430 ~62 ~22 stone
fill ~424 ~63 ~22 ~430 ~65 ~22 dirt
fill ~424 ~66 ~22 ~430 ~66 ~22 grass_block
fill ~431 ~60 ~22 ~431 ~63 ~22 stone
fill ~431 ~64 ~22 ~431 ~66 ~22 dirt
fill ~431 ~67 ~22 ~431 ~67 ~22 grass_block
fill ~416 ~60 ~23 ~419 ~61 ~23 stone
fill ~416 ~62 ~23 ~419 ~64 ~23 dirt
fill ~416 ~65 ~23 ~419 ~65 ~23 grass_block
fill ~420 ~60 ~23 ~421 ~62 ~23 stone
fill ~420 ~63 ~23 ~421 ~65 ~23 dirt
fill ~420 ~66 ~23 ~421 ~66 ~23 grass_block
fill ~422 ~60 ~23 ~425 ~61 ~23 stone
fill ~422 ~62 ~23 ~425 ~64 ~23 dirt
fill ~422 ~65 ~23 ~425 ~65 ~23 grass_block
fill ~426 ~60 ~23 ~431 ~62 ~23 stone
fill ~426 ~63 ~23 ~431 ~65 ~23 dirt
fill ~426 ~66 ~23 ~431 ~66 ~23 grass_block
fill ~416 ~60 ~24 ~417 ~61 ~24 stone
fill ~416 ~62 ~24 ~417 ~64 ~24 dirt
fill ~416 ~65 ~24 ~417 ~65 ~24 grass_block
fill ~418 ~60 ~24 ~422 ~62 ~24 stone
fill ~418 ~63 ~24 ~422 ~65 ~24 dirt
fill ~418 ~66 ~24 ~422 ~66 ~24 grass_block
fill ~423 ~60 ~24 ~430 ~61 ~24 stone
fill ~423 ~62 ~24 ~430 ~64 ~24 dirt
fill ~423 ~65 ~24 ~430 ~65 ~24 grass_block
fill ~431 ~60 ~24 ~431 ~62 ~24 stone
fill ~431 ~63 ~24 ~431 ~65 ~24 dirt
fill ~431 ~66 ~24 ~431 ~66 ~24 grass_block
fill ~416 ~60 ~25 ~423 ~62 ~25 stone
fill ~416 ~63 ~25 ~423 ~65 ~25 dirt
fill ~416 ~66 ~25 ~423 ~66 ~25 grass_block
fill ~424 ~60 ~25 ~431 ~61 ~25 stone
fill ~424 ~62 ~25 ~431 ~64 ~25 dirt
fill ~424 ~65 ~25 ~431 ~65 ~25 grass_block
fill ~416 ~60 ~26 ~418 ~63 ~26 stone
fill ~416 ~64 ~26 ~418 ~66 ~26 dirt
fill ~416 ~67 ~26 ~418 ~67 ~26 grass_block
fill ~419 ~60 ~26 ~422 ~62 ~26 stone
fill ~419 ~63 ~26 ~422 ~65 ~26 dirt
fill ~419 ~66 ~26 ~422 ~66 ~26 grass_block
fill ~423 ~60 ~26 ~425 ~61 ~26 stone
fill ~423 ~62 ~26 ~425 ~64 ~26 dirt
fill ~423 ~65 ~26 ~425 ~65 ~26 grass_block
fill ~426 ~60 ~26 ~428 ~62 ~26 stone
fill ~426 ~63 ~26 ~428 ~65 ~26 dirt
fill ~426 ~66 ~26 ~428 ~66 ~26 grass_block
fill ~429 ~60 ~26 ~431 ~61 ~26 stone
fill ~429 ~62 ~26 ~431 ~64 ~26 dirt
fill ~429 ~65 ~26 ~431 ~65 ~26 grass_block
fill ~416 ~60 ~27 ~417 ~63 ~27 stone
fill ~416 ~64 ~27 ~417 ~66 ~27 dirt
fill ~416 ~67 ~27 ~417 ~67 ~27 grass_block
fill ~418 ~60 ~27 ~422 ~62 ~27 stone
fill ~418 ~63 ~27 ~422 ~65 ~27 dirt
fill ~418 ~66 ~27 ~422 ~66 ~27 grass_block
fill ~423 ~60 ~27 ~424 ~61 ~27 stone
fill ~423 ~62 ~27 ~424 ~64 ~27 dirt
fill ~423 ~65 ~27 ~424 ~65 ~27 grass_block
fill ~425 ~60 ~27 ~425 ~62 ~27 stone
fill ~425 ~63 ~27 ~425 ~65 ~27 dirt
fill ~425 ~66 ~27 ~425 ~66 ~27 grass_block
fill ~426 ~60 ~27 ~427 ~63 ~27 stone
fill ~426 ~64 ~27 ~427 ~66 ~27 dirt
fill ~426 ~67 ~27 ~427 ~67 ~27 grass_block
fill ~428 ~60 ~27 ~431 ~62 ~27 stone
fill ~428 ~63 ~27 ~431 ~65 ~27 dirt
fill ~428 ~66 ~27 ~431 ~66 ~27 grass_block
fill ~416 ~60 ~28 ~418 ~63 ~28 stone
fill ~416 ~64 ~28 ~418 ~66 ~28 dirt
fill ~416 ~67 ~28 ~418 ~67 ~28 grass_block
fill ~419 ~60 ~28 ~421 ~62 ~28 stone
fill ~419 ~63 ~28 ~421 ~65 ~28 dirt
fill ~419 ~66 ~28 ~421 ~66 ~28 grass_block
fill ~422 ~60 ~28 ~423 ~61 ~28 stone
fill ~422 ~62 ~28 ~423 ~64 ~28 dirt
fill ~422 ~65 ~28 ~423 ~65 ~28 grass_block
fill ~424 ~60 ~28 ~425 ~62 ~28 stone
fill ~424 ~63 ~28 ~425 ~65 ~28 dirt
fill ~424 ~66 ~28 ~425 ~66 ~28 grass_block
fill ~426 ~60 ~28 ~428 ~63 ~28 stone
fill ~426 ~64 ~28 ~428 ~66 ~28 dirt
fill ~426 ~67 ~28 ~428 ~67 ~28 grass_block
fill ~429 ~60 ~28 ~431 ~62 ~28 stone
fill ~429 ~63 ~28 ~431 ~65 ~28 dirt
fill ~429 ~66 ~28 ~431 ~66 ~28 grass_block
fill ~416 ~60 ~29 ~417 ~63 ~29 stone
fill ~416 ~64 ~29 ~417 ~66 ~29 dirt
fill ~416 ~67 ~29 ~417 ~67 ~29 grass_block
fill ~418 ~60 ~29 ~420 ~62 ~29 stone
fill ~418 ~63 ~29 ~420 ~65 ~29 dirt
fill ~418 ~66 ~29 ~420 ~66 ~29 grass_block
fill ~421 ~60 ~29 ~422 ~61 ~29 stone
fill ~421 ~62 ~29 ~422 ~64 ~29 dirt
fill ~421 ~65 ~29 ~422 ~65 ~29 grass_block
fill ~423 ~60 ~29 ~424 ~62 ~29 stone
fill ~423 ~63 ~29 ~424 ~65 ~29 dirt
fill ~423 ~66 ~29 ~424 ~66 ~29 grass_block
fill ~425 ~60 ~29 ~426 ~63 ~29 stone
fill ~425 ~64 ~29 ~426 ~66 ~29 dirt
fill ~425 ~67 ~29 ~426 ~67 ~29 grass_block
fill ~427 ~60 ~29 ~427 ~64 ~29 stone
fill ~427 ~65 ~29 ~427 ~67 ~29 dirt
fill ~427 ~68 ~29 ~427 ~68 ~29 grass_block
fill ~428 ~60 ~29 ~431 ~63 ~29 stone
fill ~428 ~64 ~29 ~431 ~66 ~29 dirt
fill ~428 ~67 ~29 ~431 ~67 ~29 grass_block
fill ~416 ~60 ~30 ~417 ~63 ~30 stone
fill ~416 ~64 ~30 ~417 ~66 ~30 dirt
fill ~416 ~67 ~30 ~417 ~67 ~30 grass_block
fill ~418 ~60 ~30 ~421 ~62 ~30 stone
fill ~418 ~63 ~30 ~421 ~65 ~30 dirt
fill ~418 ~66 ~30 ~421 ~66 ~30 grass_block
fill ~422 ~60 ~30 ~422 ~61 ~30 stone
fill ~422 ~62 ~30 ~422 ~64 ~30 dirt
fill ~422 ~65 ~30 ~422 ~65 ~30 grass_block
fill ~423 ~60 ~30 ~423 ~62 ~30 stone
fill ~423 ~63 ~30 ~423 ~65 ~30 dirt
fill ~423 ~66 ~30 ~423 ~66 ~30 grass_block
fill ~424 ~60 ~30 ~425 ~63 ~30 stone
fill ~424 ~64 ~30 ~425 ~66 ~30 dirt
fill ~424 ~67 ~30 ~425 ~67 ~30 grass_block
fill ~426 ~60 ~30 ~427 ~64 ~30 stone
fill ~426 ~65 ~30 ~427 ~67 ~30 dirt
fill ~426 ~68 ~30 ~427 ~68 ~30 grass_block
fill ~428 ~60 ~30 ~431 ~63 ~30 stone
fill ~428 ~64 ~30 ~431 ~66 ~30 dirt
fill ~428 ~67 ~30 ~431 ~67 ~30 grass_block
fill ~416 ~60 ~31 ~417 ~63 ~31 stone
fill ~416 ~64 ~31 ~417 ~66 ~31 dirt
fill ~416 ~67 ~31 ~417 ~67 ~31 grass_block
fill ~418 ~60 ~31 ~423 ~62 ~31 stone
fill ~418 ~63 ~31 ~423 ~65 ~31 dirt
fill ~418 ~66 ~31 ~423 ~66 ~31 grass_block
fill ~424 ~60 ~31 ~425 ~63 ~31 stone
fill ~424 ~64 ~31 ~425 ~66 ~31 dirt
fill ~424 ~67 ~31 ~425 ~67 ~31 grass_block
fill ~426 ~60 ~31 ~427 ~64 ~31 stone
fill ~426 ~65 ~31 ~427 ~67 ~31 dirt
fill ~426 ~68 ~31 ~427 ~68 ~31 grass_block
fill ~428 ~60 ~31 ~431 ~63 ~31 stone
fill ~428 ~64 ~31 ~431 ~66 ~31 dirt
fill ~428 ~67 ~31 ~431 ~67 ~31 grass_block