fill ~96 ~60 ~48 ~101 ~64 ~48 stone
fill ~96 ~65 ~48 ~101 ~67 ~48 dirt
fill ~96 ~68 ~48 ~101 ~68 ~48 grass_block
fill ~102 ~60 ~48 ~105 ~65 ~48 stone
fill ~102 ~66 ~48 ~105 ~68 ~48 dirt
fill ~102 ~69 ~48 ~105 ~69 ~48 grass_block
fill ~106 ~60 ~48 ~108 ~64 ~48 stone
fill ~106 ~65 ~48 ~108 ~67 ~48 dirt
fill ~106 ~68 ~48 ~108 ~68 ~48 grass_block
fill ~109 ~60 ~48 ~110 ~63 ~48 stone
fill ~109 ~64 ~48 ~110 ~66 ~48 dirt
fill ~109 ~67 ~48 ~110 ~67 ~48 grass_block
fill ~111 ~60 ~48 ~111 ~64 ~48 stone
fill ~111 ~65 ~48 ~111 ~67 ~48 dirt
fill ~111 ~68 ~48 ~111 ~68 ~48 grass_block
fill ~96 ~60 ~49 ~97 ~63 ~49 stone
fill ~96 ~64 ~49 ~97 ~66 ~49 dirt
fill ~96 ~67 ~49 ~97 ~67 ~49 grass_block
fill ~98 ~60 ~49 ~101 ~64 ~49 stone
fill ~98 ~65 ~49 ~101 ~67 ~49 dirt
fill ~98 ~68 ~49 ~101 ~68 ~49 grass_block
fill ~102 ~60 ~49 ~104 ~65 ~49 stone
fill ~102 ~66 ~49 ~104 ~68 ~49 dirt
fill ~102 ~69 ~49 ~104 ~69 ~49 grass_block
fill ~105 ~60 ~49 ~108 ~64 ~49 stone
fill ~105 ~65 ~49 ~108 ~67 ~49 dirt
fill ~105 ~68 ~49 ~108 ~68 ~49 grass_block
fill ~109 ~60 ~49 ~110 ~63 ~49 stone
fill ~109 ~64 ~49 ~110 ~66 ~49 dirt
fill ~109 ~67 ~49 ~110 ~67 ~49 grass_block
fill ~111 ~60 ~49 ~111 ~64 ~49 stone
fill ~111 ~65 ~49 ~111 ~67 ~49 dirt
fill ~111 ~68 ~49 ~111 ~68 ~49 grass_block
fill ~96 ~60 ~50 ~96 ~63 ~50 stone
fill ~96 ~64 ~50 ~96 ~66 ~50 dirt
fill ~96 ~67 ~50 ~96 ~67 ~50 grass_block
fill ~97 ~60 ~50 ~102 ~64 ~50 stone
fill ~97 ~65 ~50 ~102 ~67 ~50 dirt
fill ~97 ~68 ~50 ~102 ~68 ~50 grass_block
fill ~103 ~60 ~50 ~104 ~65 ~50 stone
fill ~103 ~66 ~50 ~104 ~68 ~50 dirt
fill ~103 ~69 ~50 ~104 ~69 ~50 grass_block
fill ~105 ~60 ~50 ~108 ~64 ~50 stone
fill ~105 ~65 ~50 ~108 ~67 ~50 dirt
fill ~105 ~68 ~50 ~108 ~68 ~50 grass_block
fill ~109 ~60 ~50 ~110 ~63 ~50 stone
fill ~109 ~64 ~50 ~110 ~66 ~50 dirt
fill ~109 ~67 ~50 ~110 ~67 ~50 grass_block
fill ~111 ~60 ~50 ~111 ~64 ~50 stone
fill ~111 ~65 ~50 ~111 ~67 ~50 dirt
fill ~111 ~68 ~50 ~111 ~68 ~50 grass_block
fill ~96 ~60 ~51 ~96 ~63 ~51 stone
fill ~96 ~64 ~51 ~96 ~66 ~51 dirt
fill ~96 ~67 ~51 ~96 ~67 ~51 grass_block
fill ~97 ~60 ~51 ~107 ~64 ~51 stone
fill ~97 ~65 ~51 ~107 ~67 ~51 dirt
fill ~97 ~68 ~51 ~107 ~68 ~51 grass_block
fill ~108 ~60 ~51 ~110 ~63 ~51 stone
fill ~108 ~64 ~51 ~110 ~66 ~51 dirt
fill ~108 ~67 ~51 ~110 ~67 ~51 grass_block
fill ~111 ~60 ~51 ~111 ~64 ~51 stone
fill ~111 ~65 ~51 ~111 ~67 ~51 dirt
fill ~111 ~68 ~51 ~111 ~68 ~51 grass_block
fill ~96 ~60 ~52 ~96 ~63 ~52 stone
fill ~96 ~64 ~52 ~96 ~66 ~52 dirt
fill ~96 ~67 ~52 ~96 ~67 ~52 grass_block
fill ~97 ~60 ~52 ~103 ~64 ~52 stone
fill ~97 ~65 ~52 ~103 ~67 ~52 dirt
fill ~97 ~68 ~52 ~103 ~68 ~52 grass_block
fill ~104 ~60 ~52 ~104 ~65 ~52 stone
fill ~104 ~66 ~52 ~104 ~68 ~52 dirt
fill ~104 ~69 ~52 ~104 ~69 ~52 grass_block
fill ~105 ~60 ~52 ~107 ~64 ~52 stone
fill ~105 ~65 ~52 ~107 ~67 ~52 dirt
fill ~105 ~68 ~52 ~107 ~68 ~52 grass_block
fill ~108 ~60 ~52 ~110 ~63 ~52 stone
fill ~108 ~64 ~52 ~110 ~66 ~52 dirt
fill ~108 ~67 ~52 ~110 ~67 ~52 grass_block
fill ~111 ~60 ~52 ~111 ~64 ~52 stone
fill ~111 ~65 ~52 ~111 ~67 ~52 dirt
fill ~111 ~68 ~52 ~111 ~68 ~52 grass_block
fill ~96 ~60 ~53 ~97 ~63 ~53 stone
fill ~96 ~64 ~53 ~97 ~66 ~53 dirt
fill ~96 ~67 ~53 ~97 ~67 ~53 grass_block
fill ~98 ~60 ~53 ~107 ~64 ~53 stone
fill ~98 ~65 ~53 ~107 ~67 ~53 dirt
fill ~98 ~68 ~53 ~107 ~68 ~53 grass_block
fill ~108 ~60 ~53 ~110 ~63 ~53 stone
fill ~108 ~64 ~53 ~110 ~66 ~53 dirt
fill ~108 ~67 ~53 ~110 ~67 ~53 grass_block
fill ~111 ~60 ~53 ~111 ~64 ~53 stone
fill ~111 ~65 ~53 ~111 ~67 ~53 dirt
fill ~111 ~68 ~53 ~111 ~68 ~53 grass_block
fill ~96 ~60 ~54 ~99 ~63 ~54 stone
fill ~96 ~64 ~54 ~99 ~66 ~54 dirt
fill ~96 ~67 ~54 ~99 ~67 ~54 grass_block
fill ~100 ~60 ~54 ~108 ~64 ~54 stone
fill ~100 ~65 ~54 ~108 ~67 ~54 dirt
fill ~100 ~68 ~54 ~108 ~68 ~54 grass_block
fill ~109 ~60 ~54 ~111 ~63 ~54 stone
fill ~109 ~64 ~54 ~111 ~66 ~54 dirt
fill ~109 ~67 ~54 ~111 ~67 ~54 grass_block
fill ~96 ~60 ~55 ~100 ~63 ~55 stone
fill ~96 ~64 ~55 ~100 ~66 ~55 dirt
fill ~96 ~67 ~55 ~100 ~67 ~55 grass_block
fill ~101 ~60 ~55 ~108 ~64 ~55 stone
fill ~101 ~65 ~55 ~108 ~67 ~55 dirt
fill ~101 ~68 ~55 ~108 ~68 ~55 grass_block
fill ~109 ~60 ~55 ~111 ~63 ~55 stone
fill ~109 ~64 ~55 ~111 ~66 ~55 dirt
fill ~109 ~67 ~55 ~111 ~67 ~55 grass_block
fill ~96 ~60 ~56 ~101 ~63 ~56 stone
fill ~96 ~64 ~56 ~101 ~66 ~56 dirt
fill ~96 ~67 ~56 ~101 ~67 ~56 grass_block
fill ~102 ~60 ~56 ~108 ~64 ~56 stone
fill ~102 ~65 ~56 ~108 ~67 ~56 dirt
fill ~102 ~68 ~56 ~108 ~68 ~56 grass_block
fill ~109 ~60 ~56 ~111 ~63 ~56 stone
fill ~109 ~64 ~56 ~111 ~66 ~56 dirt
fill ~109 ~67 ~56 ~111 ~67 ~56 grass_block
fill ~96 ~60 ~57 ~96 ~62 ~57 stone
fill ~96 ~63 ~57 ~96 ~65 ~57 dirt
fill ~96 ~66 ~57 ~96 ~66 ~57 grass_block
fill ~97 ~60 ~57 ~102 ~63 ~57 stone
fill ~97 ~64 ~57 ~102 ~66 ~57 dirt
fill ~97 ~67 ~57 ~102 ~67 ~57 grass_block
fill ~103 ~60 ~57 ~108 ~64 ~57 stone
fill ~103 ~65 ~57 ~108 ~67 ~57 dirt
fill ~103 ~68 ~57 ~108 ~68 ~57 grass_block
fill ~109 ~60 ~57 ~111 ~63 ~57 stone
fill ~109 ~64 ~57 ~111 ~66 ~57 dirt
fill ~109 ~67 ~57 ~111 ~67 ~57 grass_block
fill ~96 ~60 ~58 ~96 ~62 ~58 stone
fill ~96 ~63 ~58 ~96 ~65 ~58 dirt
fill ~96 ~66 ~58 ~96 ~66 ~58 grass_block
fill ~97 ~60 ~58 ~104 ~63 ~58 stone
fill ~97 ~64 ~58 ~104 ~66 ~58 dirt
fill ~97 ~67 ~58 ~104 ~67 ~58 grass_block
fill ~105 ~60 ~58 ~109 ~64 ~58 stone
fill ~105 ~65 ~58 ~109 ~67 ~58 dirt
fill ~105 ~68 ~58 ~109 ~68 ~58 grass_block
fill ~110 ~60 ~58 ~111 ~63 ~58 stone
fill ~110 ~64 ~58 ~111 ~66 ~58 dirt
fill ~110 ~67 ~58 ~111 ~67 ~58 grass_block
fill ~96 ~60 ~59 ~96 ~63 ~59 stone
fill ~96 ~64 ~59 ~96 ~66 ~59 dirt
fill ~96 ~67 ~59 ~96 ~67 ~59 grass_block
fill ~97 ~60 ~59 ~100 ~62 ~59 stone
fill ~97 ~63 ~59 ~100 ~65 ~59 dirt
fill ~97 ~66 ~59 ~100 ~66 ~59 grass_block
fill ~101 ~60 ~59 ~105 ~63 ~59 stone
fill ~101 ~64 ~59 ~105 ~66 ~59 dirt
fill ~101 ~67 ~59 ~105 ~67 ~59 grass_block
fill ~106 ~60 ~59 ~109 ~64 ~59 stone
fill ~106 ~65 ~59 ~109 ~67 ~59 dirt
fill ~106 ~68 ~59 ~109 ~68 ~59 grass_block
fill ~110 ~60 ~59 ~111 ~63 ~59 stone
fill ~110 ~64 ~59 ~111 ~66 ~59 dirt
fill ~110 ~67 ~59 ~111 ~67 ~59 grass_block
fill ~96 ~60 ~60 ~97 ~63 ~60 stone
fill ~96 ~64 ~60 ~97 ~66 ~60 dirt
fill ~96 ~67 ~60 ~97 ~67 ~60 grass_block
fill ~98 ~60 ~60 ~103 ~62 ~60 stone
fill ~98 ~63 ~60 ~103 ~65 ~60 dirt
fill ~98 ~66 ~60 ~103 ~66 ~60 grass_block
fill ~104 ~60 ~60 ~106 ~63 ~60 stone
fill ~104 ~64 ~60 ~106 ~66 ~60 dirt
fill ~104 ~67 ~60 ~106 ~67 ~60 grass_block
fill ~107 ~60 ~60 ~109 ~64 ~60 stone
fill ~107 ~65 ~60 ~109 ~67 ~60 dirt
fill ~107 ~68 ~60 ~109 ~68 ~60 grass_block
fill ~110 ~60 ~60 ~111 ~63 ~60 stone
fill ~110 ~64 ~60 ~111 ~66 ~60 dirt
fill ~110 ~67 ~60 ~111 ~67 ~60 grass_block
fill ~96 ~60 ~61 ~100 ~63 ~61 stone
fill ~96 ~64 ~61 ~100 ~66 ~61 dirt
fill ~96 ~67 ~61 ~100 ~67 ~61 grass_block
fill ~101 ~60 ~61 ~103 ~62 ~61 stone
fill ~101 ~63 ~61 ~103 ~65 ~61 dirt
fill ~101 ~66 ~61 ~103 ~66 ~61 grass_block
fill ~104 ~60 ~61 ~107 ~63 ~61 stone
fill ~104 ~64 ~61 ~107 ~66 ~61 dirt
fill ~104 ~67 ~61 ~107 ~67 ~61 grass_block
fill ~108 ~60 ~61 ~109 ~64 ~61 stone
fill ~108 ~65 ~61 ~109 ~67 ~61 dirt
fill ~108 ~68 ~61 ~109 ~68 ~61 grass_block
fill ~110 ~60 ~61 ~111 ~63 ~61 stone
fill ~110 ~64 ~61 ~111 ~66 ~61 dirt
fill ~110 ~67 ~61 ~111 ~67 ~61 grass_block
fill ~96 ~60 ~62 ~101 ~63 ~62 stone
fill ~96 ~64 ~62 ~101 ~66 ~62 dirt
fill ~96 ~67 ~62 ~101 ~67 ~62 grass_block
fill ~102 ~60 ~62 ~105 ~62 ~62 stone
fill ~102 ~63 ~62 ~105 ~65 ~62 dirt
fill ~102 ~66 ~62 ~105 ~66 ~62 grass_block
fill ~106 ~60 ~62 ~108 ~63 ~62 stone
fill ~106 ~64 ~62 ~108 ~66 ~62 dirt
fill ~106 ~67 ~62 ~108 ~67 ~62 grass_block
fill ~109 ~60 ~62 ~109 ~64 ~62 stone
fill ~109 ~65 ~62 ~109 ~67 ~62 dirt
fill ~109 ~68 ~62 ~109 ~68 ~62 grass_block
fill ~110 ~60 ~62 ~111 ~63 ~62 stone
fill ~110 ~64 ~62 ~111 ~66 ~62 dirt
fill ~110 ~67 ~62 ~111 ~67 ~62 grass_block
fill ~96 ~60 ~63 ~96 ~63 ~63 stone
fill ~96 ~64 ~63 ~96 ~66 ~63 dirt
fill ~96 ~67 ~63 ~96 ~67 ~63 grass_block
fill ~97 ~60 ~63 ~98 ~64 ~63 stone
fill ~97 ~65 ~63 ~98 ~67 ~63 dirt
fill ~97 ~68 ~63 ~98 ~68 ~63 grass_block
fill ~99 ~60 ~63 ~102 ~63 ~63 stone
fill ~99 ~64 ~63 ~102 ~66 ~63 dirt
fill ~99 ~67 ~63 ~102 ~67 ~63 grass_block
fill ~103 ~60 ~63 ~105 ~62 ~63 stone
fill ~103 ~63 ~63 ~105 ~65 ~63 dirt
fill ~103 ~66 ~63 ~105 ~66 ~63 grass_block
fill ~106 ~60 ~63 ~111 ~63 ~63 stone
fill ~106 ~64 ~63 ~111 ~66 ~63 dirt
fill ~106 ~67 ~63 ~111 ~67 ~63 grass_block