fill ~176 ~60 ~128 ~184 ~64 ~128 stone
fill ~176 ~65 ~128 ~184 ~67 ~128 dirt
fill ~176 ~68 ~128 ~184 ~68 ~128 grass_block
fill ~185 ~60 ~128 ~191 ~63 ~128 stone
fill ~185 ~64 ~128 ~191 ~66 ~128 dirt
fill ~185 ~67 ~128 ~191 ~67 ~128 grass_block
fill ~176 ~60 ~129 ~185 ~64 ~129 stone
fill ~176 ~65 ~129 ~185 ~67 ~129 dirt
fill ~176 ~68 ~129 ~185 ~68 ~129 grass_block
fill ~186 ~60 ~129 ~191 ~63 ~129 stone
fill ~186 ~64 ~129 ~191 ~66 ~129 dirt
fill ~186 ~67 ~129 ~191 ~67 ~129 grass_block
fill ~176 ~60 ~130 ~184 ~64 ~130 stone
fill ~176 ~65 ~130 ~184 ~67 ~130 dirt
fill ~176 ~68 ~130 ~184 ~68 ~130 grass_block
fill ~185 ~60 ~130 ~191 ~63 ~130 stone
fill ~185 ~64 ~130 ~191 ~66 ~130 dirt
fill ~185 ~67 ~130 ~191 ~67 ~130 grass_block
fill ~176 ~60 ~131 ~183 ~64 ~131 stone
fill ~176 ~65 ~131 ~183 ~67 ~131 dirt
fill ~176 ~68 ~131 ~183 ~68 ~131 grass_block
fill ~184 ~60 ~131 ~191 ~63 ~131 stone
fill ~184 ~64 ~131 ~191 ~66 ~131 dirt
fill ~184 ~67 ~131 ~191 ~67 ~131 grass_block
fill ~176 ~60 ~132 ~182 ~64 ~132 stone
fill ~176 ~65 ~132 ~182 ~67 ~132 dirt
fill ~176 ~68 ~132 ~182 ~68 ~132 grass_block
fill ~183 ~60 ~132 ~190 ~63 ~132 stone
fill ~183 ~64 ~132 ~190 ~66 ~132 dirt
fill ~183 ~67 ~132 ~190 ~67 ~132 grass_block
fill ~191 ~60 ~132 ~191 ~62 ~132 stone
fill ~191 ~63 ~132 ~191 ~65 ~132 dirt
fill ~191 ~66 ~132 ~191 ~66 ~132 grass_block
fill ~176 ~60 ~133 ~181 ~64 ~133 stone
fill ~176 ~65 ~133 ~181 ~67 ~133 dirt
fill ~176 ~68 ~133 ~181 ~68 ~133 grass_block
fill ~182 ~60 ~133 ~187 ~63 ~133 stone
fill ~182 ~64 ~133 ~187 ~66 ~133 dirt
fill ~182 ~67 ~133 ~187 ~67 ~133 grass_block
fill ~188 ~60 ~133 ~191 ~62 ~133 stone
fill ~188 ~63 ~133 ~191 ~65 ~133 dirt
fill ~188 ~66 ~133 ~191 ~66 ~133 grass_block
fill ~176 ~60 ~134 ~181 ~64 ~134 stone
fill ~176 ~65 ~134 ~181 ~67 ~134 dirt
fill ~176 ~68 ~134 ~181 ~68 ~134 grass_block
fill ~182 ~60 ~134 ~187 ~63 ~134 stone
fill ~182 ~64 ~134 ~187 ~66 ~134 dirt
fill ~182 ~67 ~134 ~187 ~67 ~134 grass_block
fill ~188 ~60 ~134 ~188 ~62 ~134 stone
fill ~188 ~63 ~134 ~188 ~65 ~134 dirt
fill ~188 ~66 ~134 ~188 ~66 ~134 grass_block
fill ~189 ~60 ~134 ~191 ~63 ~134 stone
fill ~189 ~64 ~134 ~191 ~66 ~134 dirt
fill ~189 ~67 ~134 ~191 ~67 ~134 grass_block
fill ~176 ~60 ~135 ~180 ~64 ~135 stone
fill ~176 ~65 ~135 ~180 ~67 ~135 dirt
fill ~176 ~68 ~135 ~180 ~68 ~135 grass_block
fill ~181 ~60 ~135 ~188 ~63 ~135 stone
fill ~181 ~64 ~135 ~188 ~66 ~135 dirt
fill ~181 ~67 ~135 ~188 ~67 ~135 grass_block
fill ~189 ~60 ~135 ~190 ~64 ~135 stone
fill ~189 ~65 ~135 ~190 ~67 ~135 dirt
fill ~189 ~68 ~135 ~190 ~68 ~135 grass_block
fill ~191 ~60 ~135 ~191 ~63 ~135 stone
fill ~191 ~64 ~135 ~191 ~66 ~135 dirt
fill ~191 ~67 ~135 ~191 ~67 ~135 grass_block
fill ~176 ~60 ~136 ~179 ~64 ~136 stone
fill ~176 ~65 ~136 ~179 ~67 ~136 dirt
fill ~176 ~68 ~136 ~179 ~68 ~136 grass_block
fill ~180 ~60 ~136 ~184 ~63 ~136 stone
fill ~180 ~64 ~136 ~184 ~66 ~136 dirt
fill ~180 ~67 ~136 ~184 ~67 ~136 grass_block
fill ~185 ~60 ~136 ~185 ~62 ~136 stone
fill ~185 ~63 ~136 ~185 ~65 ~136 dirt
fill ~185 ~66 ~136 ~185 ~66 ~136 grass_block
fill ~186 ~60 ~136 ~188 ~63 ~136 stone
fill ~186 ~64 ~136 ~188 ~66 ~136 dirt
fill ~186 ~67 ~136 ~188 ~67 ~136 grass_block
fill ~189 ~60 ~136 ~191 ~64 ~136 stone
fill ~189 ~65 ~136 ~191 ~67 ~136 dirt
fill ~189 ~68 ~136 ~191 ~68 ~136 grass_block
fill ~176 ~60 ~137 ~189 ~63 ~137 stone
fill ~176 ~64 ~137 ~189 ~66 ~137 dirt
fill ~176 ~67 ~137 ~189 ~67 ~137 grass_block
fill ~190 ~60 ~137 ~191 ~64 ~137 stone
fill ~190 ~65 ~137 ~191 ~67 ~137 dirt
fill ~190 ~68 ~137 ~191 ~68 ~137 grass_block
fill ~176 ~60 ~138 ~185 ~63 ~138 stone
fill ~176 ~64 ~138 ~185 ~66 ~138 dirt
fill ~176 ~67 ~138 ~185 ~67 ~138 grass_block
fill ~186 ~60 ~138 ~191 ~64 ~138 stone
fill ~186 ~65 ~138 ~191 ~67 ~138 dirt
fill ~186 ~68 ~138 ~191 ~68 ~138 grass_block
fill ~176 ~60 ~139 ~178 ~64 ~139 stone
fill ~176 ~65 ~139 ~178 ~67 ~139 dirt
fill ~176 ~68 ~139 ~178 ~68 ~139 grass_block
fill ~179 ~60 ~139 ~185 ~63 ~139 stone
fill ~179 ~64 ~139 ~185 ~66 ~139 dirt
fill ~179 ~67 ~139 ~185 ~67 ~139 grass_block
fill ~186 ~60 ~139 ~187 ~64 ~139 stone
fill ~186 ~65 ~139 ~187 ~67 ~139 dirt
fill ~186 ~68 ~139 ~187 ~68 ~139 grass_block
fill ~188 ~60 ~139 ~190 ~65 ~139 stone
fill ~188 ~66 ~139 ~190 ~68 ~139 dirt
fill ~188 ~69 ~139 ~190 ~69 ~139 grass_block
fill ~191 ~60 ~139 ~191 ~64 ~139 stone
fill ~191 ~65 ~139 ~191 ~67 ~139 dirt
fill ~191 ~68 ~139 ~191 ~68 ~139 grass_block
fill ~176 ~60 ~140 ~179 ~64 ~140 stone
fill ~176 ~65 ~140 ~179 ~67 ~140 dirt
fill ~176 ~68 ~140 ~179 ~68 ~140 grass_block
fill ~180 ~60 ~140 ~185 ~63 ~140 stone
fill ~180 ~64 ~140 ~185 ~66 ~140 dirt
fill ~180 ~67 ~140 ~185 ~67 ~140 grass_block
fill ~186 ~60 ~140 ~187 ~64 ~140 stone
fill ~186 ~65 ~140 ~187 ~67 ~140 dirt
fill ~186 ~68 ~140 ~187 ~68 ~140 grass_block
fill ~188 ~60 ~140 ~191 ~65 ~140 stone
fill ~188 ~66 ~140 ~191 ~68 ~140 dirt
fill ~188 ~69 ~140 ~191 ~69 ~140 grass_block
fill ~176 ~60 ~141 ~179 ~64 ~141 stone
fill ~176 ~65 ~141 ~179 ~67 ~141 dirt
fill ~176 ~68 ~141 ~179 ~68 ~141 grass_block
fill ~180 ~60 ~141 ~185 ~63 ~141 stone
fill ~180 ~64 ~141 ~185 ~66 ~141 dirt
fill ~180 ~67 ~141 ~185 ~67 ~141 grass_block
fill ~186 ~60 ~141 ~187 ~64 ~141 stone
fill ~186 ~65 ~141 ~187 ~67 ~141 dirt
fill ~186 ~68 ~141 ~187 ~68 ~141 grass_block
fill ~188 ~60 ~141 ~191 ~65 ~141 stone
fill ~188 ~66 ~141 ~191 ~68 ~141 dirt
fill ~188 ~69 ~141 ~191 ~69 ~141 grass_block
fill ~176 ~60 ~142 ~176 ~65 ~142 stone
fill ~176 ~66 ~142 ~176 ~68 ~142 dirt
fill ~176 ~69 ~142 ~176 ~69 ~142 grass_block
fill ~177 ~60 ~142 ~180 ~64 ~142 stone
fill ~177 ~65 ~142 ~180 ~67 ~142 dirt
fill ~177 ~68 ~142 ~180 ~68 ~142 grass_block
fill ~181 ~60 ~142 ~185 ~63 ~142 stone
fill ~181 ~64 ~142 ~185 ~66 ~142 dirt
fill ~181 ~67 ~142 ~185 ~67 ~142 grass_block
fill ~186 ~60 ~142 ~187 ~64 ~142 stone
fill ~186 ~65 ~142 ~187 ~67 ~142 dirt
fill ~186 ~68 ~142 ~187 ~68 ~142 grass_block
fill ~188 ~60 ~142 ~191 ~65 ~142 stone
fill ~188 ~66 ~142 ~191 ~68 ~142 dirt
fill ~188 ~69 ~142 ~191 ~69 ~142 grass_block
fill ~176 ~60 ~143 ~176 ~65 ~143 stone
fill ~176 ~66 ~143 ~176 ~68 ~143 dirt
fill ~176 ~69 ~143 ~176 ~69 ~143 grass_block
fill ~177 ~60 ~143 ~180 ~64 ~143 stone
fill ~177 ~65 ~143 ~180 ~67 ~143 dirt
fill ~177 ~68 ~143 ~180 ~68 ~143 grass_block
fill ~181 ~60 ~143 ~185 ~63 ~143 stone
fill ~181 ~64 ~143 ~185 ~66 ~143 dirt
fill ~181 ~67 ~143 ~185 ~67 ~143 grass_block
fill ~186 ~60 ~143 ~187 ~64 ~143 stone
fill ~186 ~65 ~143 ~187 ~67 ~143 dirt
fill ~186 ~68 ~143 ~187 ~68 ~143 grass_block
fill ~188 ~60 ~143 ~191 ~65 ~143 stone
fill ~188 ~66 ~143 ~191 ~68 ~143 dirt
fill ~188 ~69 ~143 ~191 ~69 ~143 grass_block