fill ~336 ~60 ~96 ~337 ~60 ~96 stone
fill ~336 ~61 ~96 ~337 ~63 ~96 dirt
fill ~336 ~64 ~96 ~337 ~64 ~96 grass_block
fill ~338 ~60 ~96 ~343 ~61 ~96 stone
fill ~338 ~62 ~96 ~343 ~64 ~96 dirt
fill ~338 ~65 ~96 ~343 ~65 ~96 grass_block
fill ~344 ~60 ~96 ~346 ~62 ~96 stone
fill ~344 ~63 ~96 ~346 ~65 ~96 dirt
fill ~344 ~66 ~96 ~346 ~66 ~96 grass_block
fill ~347 ~60 ~96 ~349 ~63 ~96 stone
fill ~347 ~64 ~96 ~349 ~66 ~96 dirt
fill ~347 ~67 ~96 ~349 ~67 ~96 grass_block
fill ~350 ~60 ~96 ~351 ~62 ~96 stone
fill ~350 ~63 ~96 ~351 ~65 ~96 dirt
fill ~350 ~66 ~96 ~351 ~66 ~96 grass_block
fill ~336 ~60 ~97 ~337 ~60 ~97 stone
fill ~336 ~61 ~97 ~337 ~63 ~97 dirt
fill ~336 ~64 ~97 ~337 ~64 ~97 grass_block
fill ~338 ~60 ~97 ~338 ~61 ~97 stone
fill ~338 ~62 ~97 ~338 ~64 ~97 dirt
fill ~338 ~65 ~97 ~338 ~65 ~97 grass_block
fill ~339 ~60 ~97 ~339 ~60 ~97 stone
fill ~339 ~61 ~97 ~339 ~63 ~97 dirt
fill ~339 ~64 ~97 ~339 ~64 ~97 grass_block
fill ~340 ~60 ~97 ~344 ~61 ~97 stone
fill ~340 ~62 ~97 ~344 ~64 ~97 dirt
fill ~340 ~65 ~97 ~344 ~65 ~97 grass_block
fill ~345 ~60 ~97 ~348 ~62 ~97 stone
fill ~345 ~63 ~97 ~348 ~65 ~97 dirt
fill ~345 ~66 ~97 ~348 ~66 ~97 grass_block
fill ~349 ~60 ~97 ~349 ~63 ~97 stone
fill ~349 ~64 ~97 ~349 ~66 ~97 dirt
fill ~349 ~67 ~97 ~349 ~67 ~97 grass_block
fill ~350 ~60 ~97 ~351 ~62 ~97 stone
fill ~350 ~63 ~97 ~351 ~65 ~97 dirt
fill ~350 ~66 ~97 ~351 ~66 ~97 grass_block
fill ~336 ~60 ~98 ~337 ~60 ~98 stone
fill ~336 ~61 ~98 ~337 ~63 ~98 dirt
fill ~336 ~64 ~98 ~337 ~64 ~98 grass_block
fill ~338 ~60 ~98 ~345 ~61 ~98 stone
fill ~338 ~62 ~98 ~345 ~64 ~98 dirt
fill ~338 ~65 ~98 ~345 ~65 ~98 grass_block
fill ~346 ~60 ~98 ~351 ~62 ~98 stone
fill ~346 ~63 ~98 ~351 ~65 ~98 dirt
fill ~346 ~66 ~98 ~351 ~66 ~98 grass_block
fill ~336 ~60 ~99 ~337 ~60 ~99 stone
fill ~336 ~61 ~99 ~337 ~63 ~99 dirt
fill ~336 ~64 ~99 ~337 ~64 ~99 grass_block
fill ~338 ~60 ~99 ~346 ~61 ~99 stone
fill ~338 ~62 ~99 ~346 ~64 ~99 dirt
fill ~338 ~65 ~99 ~346 ~65 ~99 grass_block
fill ~347 ~60 ~99 ~351 ~62 ~99 stone
fill ~347 ~63 ~99 ~351 ~65 ~99 dirt
fill ~347 ~66 ~99 ~351 ~66 ~99 grass_block
fill ~336 ~60 ~100 ~338 ~60 ~100 stone
fill ~336 ~61 ~100 ~338 ~63 ~100 dirt
fill ~336 ~64 ~100 ~338 ~64 ~100 grass_block
fill ~339 ~60 ~100 ~347 ~61 ~100 stone
fill ~339 ~62 ~100 ~347 ~64 ~100 dirt
fill ~339 ~65 ~100 ~347 ~65 ~100 grass_block
fill ~348 ~60 ~100 ~351 ~62 ~100 stone
fill ~348 ~63 ~100 ~351 ~65 ~100 dirt
fill ~348 ~66 ~100 ~351 ~66 ~100 grass_block
fill ~336 ~60 ~101 ~340 ~60 ~101 stone
fill ~336 ~61 ~101 ~340 ~63 ~101 dirt
fill ~336 ~64 ~101 ~340 ~64 ~101 grass_block
fill ~341 ~60 ~101 ~348 ~61 ~101 stone
fill ~341 ~62 ~101 ~348 ~64 ~101 dirt
fill ~341 ~65 ~101 ~348 ~65 ~101 grass_block
fill ~349 ~60 ~101 ~351 ~62 ~101 stone
fill ~349 ~63 ~101 ~351 ~65 ~101 dirt
fill ~349 ~66 ~101 ~351 ~66 ~101 grass_block
fill ~336 ~60 ~102 ~341 ~60 ~102 stone
fill ~336 ~61 ~102 ~341 ~63 ~102 dirt
fill ~336 ~64 ~102 ~341 ~64 ~102 grass_block
fill ~342 ~60 ~102 ~350 ~61 ~102 stone
fill ~342 ~62 ~102 ~350 ~64 ~102 dirt
fill ~342 ~65 ~102 ~350 ~65 ~102 grass_block
fill ~351 ~60 ~102 ~351 ~62 ~102 stone
fill ~351 ~63 ~102 ~351 ~65 ~102 dirt
fill ~351 ~66 ~102 ~351 ~66 ~102 grass_block
fill ~336 ~60 ~103 ~338 ~60 ~103 stone
fill ~336 ~61 ~103 ~338 ~63 ~103 dirt
fill ~336 ~64 ~103 ~338 ~64 ~103 grass_block
fill ~339 ~60 ~103 ~339 ~61 ~103 stone
fill ~339 ~62 ~103 ~339 ~64 ~103 dirt
fill ~339 ~65 ~103 ~339 ~65 ~103 grass_block
fill ~340 ~60 ~103 ~341 ~60 ~103 stone
fill ~340 ~61 ~103 ~341 ~63 ~103 dirt
fill ~340 ~64 ~103 ~341 ~64 ~103 grass_block
fill ~342 ~60 ~103 ~351 ~61 ~103 stone
fill ~342 ~62 ~103 ~351 ~64 ~103 dirt
fill ~342 ~65 ~103 ~351 ~65 ~103 grass_block
fill ~336 ~60 ~104 ~341 ~60 ~104 stone
fill ~336 ~61 ~104 ~341 ~63 ~104 dirt
fill ~336 ~64 ~104 ~341 ~64 ~104 grass_block
fill ~342 ~60 ~104 ~346 ~61 ~104 stone
fill ~342 ~62 ~104 ~346 ~64 ~104 dirt
fill ~342 ~65 ~104 ~346 ~65 ~104 grass_block
fill ~347 ~60 ~104 ~347 ~60 ~104 stone
fill ~347 ~61 ~104 ~347 ~63 ~104 dirt
fill ~347 ~64 ~104 ~347 ~64 ~104 grass_block
fill ~348 ~60 ~104 ~351 ~61 ~104 stone
fill ~348 ~62 ~104 ~351 ~64 ~104 dirt
fill ~348 ~65 ~104 ~351 ~65 ~104 grass_block
fill ~336 ~60 ~105 ~342 ~60 ~105 stone
fill ~336 ~61 ~105 ~342 ~63 ~105 dirt
fill ~336 ~64 ~105 ~342 ~64 ~105 grass_block
fill ~343 ~60 ~105 ~351 ~61 ~105 stone
fill ~343 ~62 ~105 ~351 ~64 ~105 dirt
fill ~343 ~65 ~105 ~351 ~65 ~105 grass_block
fill ~336 ~60 ~106 ~342 ~60 ~106 stone
fill ~336 ~61 ~106 ~342 ~63 ~106 dirt
fill ~336 ~64 ~106 ~342 ~64 ~106 grass_block
fill ~343 ~60 ~106 ~347 ~61 ~106 stone
fill ~343 ~62 ~106 ~347 ~64 ~106 dirt
fill ~343 ~65 ~106 ~347 ~65 ~106 grass_block
fill ~348 ~60 ~106 ~349 ~60 ~106 stone
fill ~348 ~61 ~106 ~349 ~63 ~106 dirt
fill ~348 ~64 ~106 ~349 ~64 ~106 grass_block
fill ~350 ~60 ~106 ~351 ~61 ~106 stone
fill ~350 ~62 ~106 ~351 ~64 ~106 dirt
fill ~350 ~65 ~106 ~351 ~65 ~106 grass_block
fill ~336 ~60 ~107 ~343 ~60 ~107 stone
fill ~336 ~61 ~107 ~343 ~63 ~107 dirt
fill ~336 ~64 ~107 ~343 ~64 ~107 grass_block
fill ~344 ~60 ~107 ~347 ~61 ~107 stone
fill ~344 ~62 ~107 ~347 ~64 ~107 dirt
fill ~344 ~65 ~107 ~347 ~65 ~107 grass_block
fill ~348 ~60 ~107 ~349 ~60 ~107 stone
fill ~348 ~61 ~107 ~349 ~63 ~107 dirt
fill ~348 ~64 ~107 ~349 ~64 ~107 grass_block
fill ~350 ~60 ~107 ~351 ~61 ~107 stone
fill ~350 ~62 ~107 ~351 ~64 ~107 dirt
fill ~350 ~65 ~107 ~351 ~65 ~107 grass_block
fill ~336 ~60 ~108 ~346 ~60 ~108 stone
fill ~336 ~61 ~108 ~346 ~63 ~108 dirt
fill ~336 ~64 ~108 ~346 ~64 ~108 grass_block
fill ~347 ~60 ~108 ~347 ~61 ~108 stone
fill ~347 ~62 ~108 ~347 ~64 ~108 dirt
fill ~347 ~65 ~108 ~347 ~65 ~108 grass_block
fill ~348 ~60 ~108 ~351 ~60 ~108 stone
fill ~348 ~61 ~108 ~351 ~63 ~108 dirt
fill ~348 ~64 ~108 ~351 ~64 ~108 grass_block
fill ~336 ~60 ~109 ~347 ~60 ~109 stone
fill ~336 ~61 ~109 ~347 ~63 ~109 dirt
fill ~336 ~64 ~109 ~347 ~64 ~109 grass_block
fill ~348 ~60 ~109 ~348 ~61 ~109 stone
fill ~348 ~62 ~109 ~348 ~64 ~109 dirt
fill ~348 ~65 ~109 ~348 ~65 ~109 grass_block
fill ~349 ~60 ~109 ~351 ~60 ~109 stone
fill ~349 ~61 ~109 ~351 ~63 ~109 dirt
fill ~349 ~64 ~109 ~351 ~64 ~109 grass_block
fill ~336 ~60 ~110 ~351 ~60 ~110 stone
fill ~336 ~61 ~110 ~351 ~63 ~110 dirt
fill ~336 ~64 ~110 ~351 ~64 ~110 grass_block
fill ~336 ~60 ~111 ~337 ~61 ~111 stone
fill ~336 ~62 ~111 ~337 ~64 ~111 dirt
fill ~336 ~65 ~111 ~337 ~65 ~111 grass_block
fill ~338 ~60 ~111 ~351 ~60 ~111 stone
fill ~338 ~61 ~111 ~351 ~63 ~111 dirt
fill ~338 ~64 ~111 ~351 ~64 ~111 grass_block