fill ~192 ~60 ~112 ~194 ~62 ~112 stone
fill ~192 ~63 ~112 ~194 ~65 ~112 dirt
fill ~192 ~66 ~112 ~194 ~66 ~112 grass_block
fill ~195 ~60 ~112 ~196 ~63 ~112 stone
fill ~195 ~64 ~112 ~196 ~66 ~112 dirt
fill ~195 ~67 ~112 ~196 ~67 ~112 grass_block
fill ~197 ~60 ~112 ~201 ~64 ~112 stone
fill ~197 ~65 ~112 ~201 ~67 ~112 dirt
fill ~197 ~68 ~112 ~201 ~68 ~112 grass_block
fill ~202 ~60 ~112 ~205 ~63 ~112 stone
fill ~202 ~64 ~112 ~205 ~66 ~112 dirt
fill ~202 ~67 ~112 ~205 ~67 ~112 grass_block
fill ~206 ~60 ~112 ~206 ~62 ~112 stone
fill ~206 ~63 ~112 ~206 ~65 ~112 dirt
fill ~206 ~66 ~112 ~206 ~66 ~112 grass_block
fill ~207 ~60 ~112 ~207 ~63 ~112 stone
fill ~207 ~64 ~112 ~207 ~66 ~112 dirt
fill ~207 ~67 ~112 ~207 ~67 ~112 grass_block
fill ~192 ~60 ~113 ~194 ~62 ~113 stone
fill ~192 ~63 ~113 ~194 ~65 ~113 dirt
fill ~192 ~66 ~113 ~194 ~66 ~113 grass_block
fill ~195 ~60 ~113 ~197 ~63 ~113 stone
fill ~195 ~64 ~113 ~197 ~66 ~113 dirt
fill ~195 ~67 ~113 ~197 ~67 ~113 grass_block
fill ~198 ~60 ~113 ~201 ~64 ~113 stone
fill ~198 ~65 ~113 ~201 ~67 ~113 dirt
fill ~198 ~68 ~113 ~201 ~68 ~113 grass_block
fill ~202 ~60 ~113 ~205 ~63 ~113 stone
fill ~202 ~64 ~113 ~205 ~66 ~113 dirt
fill ~202 ~67 ~113 ~205 ~67 ~113 grass_block
fill ~206 ~60 ~113 ~206 ~62 ~113 stone
fill ~206 ~63 ~113 ~206 ~65 ~113 dirt
fill ~206 ~66 ~113 ~206 ~66 ~113 grass_block
fill ~207 ~60 ~113 ~207 ~63 ~113 stone
fill ~207 ~64 ~113 ~207 ~66 ~113 dirt
fill ~207 ~67 ~113 ~207 ~67 ~113 grass_block
fill ~192 ~60 ~114 ~194 ~62 ~114 stone
fill ~192 ~63 ~114 ~194 ~65 ~114 dirt
fill ~192 ~66 ~114 ~194 ~66 ~114 grass_block
fill ~195 ~60 ~114 ~198 ~63 ~114 stone
fill ~195 ~64 ~114 ~198 ~66 ~114 dirt
fill ~195 ~67 ~114 ~198 ~67 ~114 grass_block
fill ~199 ~60 ~114 ~201 ~64 ~114 stone
fill ~199 ~65 ~114 ~201 ~67 ~114 dirt
fill ~199 ~68 ~114 ~201 ~68 ~114 grass_block
fill ~202 ~60 ~114 ~205 ~63 ~114 stone
fill ~202 ~64 ~114 ~205 ~66 ~114 dirt
fill ~202 ~67 ~114 ~205 ~67 ~114 grass_block
fill ~206 ~60 ~114 ~206 ~62 ~114 stone
fill ~206 ~63 ~114 ~206 ~65 ~114 dirt
fill ~206 ~66 ~114 ~206 ~66 ~114 grass_block
fill ~207 ~60 ~114 ~207 ~63 ~114 stone
fill ~207 ~64 ~114 ~207 ~66 ~114 dirt
fill ~207 ~67 ~114 ~207 ~67 ~114 grass_block
fill ~192 ~60 ~115 ~195 ~62 ~115 stone
fill ~192 ~63 ~115 ~195 ~65 ~115 dirt
fill ~192 ~66 ~115 ~195 ~66 ~115 grass_block
fill ~196 ~60 ~115 ~198 ~63 ~115 stone
fill ~196 ~64 ~115 ~198 ~66 ~115 dirt
fill ~196 ~67 ~115 ~198 ~67 ~115 grass_block
fill ~199 ~60 ~115 ~201 ~64 ~115 stone
fill ~199 ~65 ~115 ~201 ~67 ~115 dirt
fill ~199 ~68 ~115 ~201 ~68 ~115 grass_block
fill ~202 ~60 ~115 ~205 ~63 ~115 stone
fill ~202 ~64 ~115 ~205 ~66 ~115 dirt
fill ~202 ~67 ~115 ~205 ~67 ~115 grass_block
fill ~206 ~60 ~115 ~207 ~62 ~115 stone
fill ~206 ~63 ~115 ~207 ~65 ~115 dirt
fill ~206 ~66 ~115 ~207 ~66 ~115 grass_block
fill ~192 ~60 ~116 ~196 ~62 ~116 stone
fill ~192 ~63 ~116 ~196 ~65 ~116 dirt
fill ~192 ~66 ~116 ~196 ~66 ~116 grass_block
fill ~197 ~60 ~116 ~199 ~63 ~116 stone
fill ~197 ~64 ~116 ~199 ~66 ~116 dirt
fill ~197 ~67 ~116 ~199 ~67 ~116 grass_block
fill ~200 ~60 ~116 ~201 ~64 ~116 stone
fill ~200 ~65 ~116 ~201 ~67 ~116 dirt
fill ~200 ~68 ~116 ~201 ~68 ~116 grass_block
fill ~202 ~60 ~116 ~205 ~63 ~116 stone
fill ~202 ~64 ~116 ~205 ~66 ~116 dirt
fill ~202 ~67 ~116 ~205 ~67 ~116 grass_block
fill ~206 ~60 ~116 ~207 ~62 ~116 stone
fill ~206 ~63 ~116 ~207 ~65 ~116 dirt
fill ~206 ~66 ~116 ~207 ~66 ~116 grass_block
fill ~192 ~60 ~117 ~192 ~63 ~117 stone
fill ~192 ~64 ~117 ~192 ~66 ~117 dirt
fill ~192 ~67 ~117 ~192 ~67 ~117 grass_block
fill ~193 ~60 ~117 ~197 ~62 ~117 stone
fill ~193 ~63 ~117 ~197 ~65 ~117 dirt
fill ~193 ~66 ~117 ~197 ~66 ~117 grass_block
fill ~198 ~60 ~117 ~200 ~63 ~117 stone
fill ~198 ~64 ~117 ~200 ~66 ~117 dirt
fill ~198 ~67 ~117 ~200 ~67 ~117 grass_block
fill ~201 ~60 ~117 ~201 ~64 ~117 stone
fill ~201 ~65 ~117 ~201 ~67 ~117 dirt
fill ~201 ~68 ~117 ~201 ~68 ~117 grass_block
fill ~202 ~60 ~117 ~205 ~63 ~117 stone
fill ~202 ~64 ~117 ~205 ~66 ~117 dirt
fill ~202 ~67 ~117 ~205 ~67 ~117 grass_block
fill ~206 ~60 ~117 ~207 ~62 ~117 stone
fill ~206 ~63 ~117 ~207 ~65 ~117 dirt
fill ~206 ~66 ~117 ~207 ~66 ~117 grass_block
fill ~192 ~60 ~118 ~192 ~63 ~118 stone
fill ~192 ~64 ~118 ~192 ~66 ~118 dirt
fill ~192 ~67 ~118 ~192 ~67 ~118 grass_block
fill ~193 ~60 ~118 ~198 ~62 ~118 stone
fill ~193 ~63 ~118 ~198 ~65 ~118 dirt
fill ~193 ~66 ~118 ~198 ~66 ~118 grass_block
fill ~199 ~60 ~118 ~205 ~63 ~118 stone
fill ~199 ~64 ~118 ~205 ~66 ~118 dirt
fill ~199 ~67 ~118 ~205 ~67 ~118 grass_block
fill ~206 ~60 ~118 ~207 ~62 ~118 stone
fill ~206 ~63 ~118 ~207 ~65 ~118 dirt
fill ~206 ~66 ~118 ~207 ~66 ~118 grass_block
fill ~192 ~60 ~119 ~198 ~62 ~119 stone
fill ~192 ~63 ~119 ~198 ~65 ~119 dirt
fill ~192 ~66 ~119 ~198 ~66 ~119 grass_block
fill ~199 ~60 ~119 ~206 ~63 ~119 stone
fill ~199 ~64 ~119 ~206 ~66 ~119 dirt
fill ~199 ~67 ~119 ~206 ~67 ~119 grass_block
fill ~207 ~60 ~119 ~207 ~62 ~119 stone
fill ~207 ~63 ~119 ~207 ~65 ~119 dirt
fill ~207 ~66 ~119 ~207 ~66 ~119 grass_block
fill ~192 ~60 ~120 ~199 ~62 ~120 stone
fill ~192 ~63 ~120 ~199 ~65 ~120 dirt
fill ~192 ~66 ~120 ~199 ~66 ~120 grass_block
fill ~200 ~60 ~120 ~206 ~63 ~120 stone
fill ~200 ~64 ~120 ~206 ~66 ~120 dirt
fill ~200 ~67 ~120 ~206 ~67 ~120 grass_block
fill ~207 ~60 ~120 ~207 ~62 ~120 stone
fill ~207 ~63 ~120 ~207 ~65 ~120 dirt
fill ~207 ~66 ~120 ~207 ~66 ~120 grass_block
fill ~192 ~60 ~121 ~199 ~62 ~121 stone
fill ~192 ~63 ~121 ~199 ~65 ~121 dirt
fill ~192 ~66 ~121 ~199 ~66 ~121 grass_block
fill ~200 ~60 ~121 ~205 ~63 ~121 stone
fill ~200 ~64 ~121 ~205 ~66 ~121 dirt
fill ~200 ~67 ~121 ~205 ~67 ~121 grass_block
fill ~206 ~60 ~121 ~207 ~62 ~121 stone
fill ~206 ~63 ~121 ~207 ~65 ~121 dirt
fill ~206 ~66 ~121 ~207 ~66 ~121 grass_block
fill ~192 ~60 ~122 ~201 ~62 ~122 stone
fill ~192 ~63 ~122 ~201 ~65 ~122 dirt
fill ~192 ~66 ~122 ~201 ~66 ~122 grass_block
fill ~202 ~60 ~122 ~205 ~63 ~122 stone
fill ~202 ~64 ~122 ~205 ~66 ~122 dirt
fill ~202 ~67 ~122 ~205 ~67 ~122 grass_block
fill ~206 ~60 ~122 ~207 ~62 ~122 stone
fill ~206 ~63 ~122 ~207 ~65 ~122 dirt
fill ~206 ~66 ~122 ~207 ~66 ~122 grass_block
fill ~192 ~60 ~123 ~203 ~62 ~123 stone
fill ~192 ~63 ~123 ~203 ~65 ~123 dirt
fill ~192 ~66 ~123 ~203 ~66 ~123 grass_block
fill ~204 ~60 ~123 ~205 ~63 ~123 stone
fill ~204 ~64 ~123 ~205 ~66 ~123 dirt
fill ~204 ~67 ~123 ~205 ~67 ~123 grass_block
fill ~206 ~60 ~123 ~207 ~62 ~123 stone
fill ~206 ~63 ~123 ~207 ~65 ~123 dirt
fill ~206 ~66 ~123 ~207 ~66 ~123 grass_block
fill ~192 ~60 ~124 ~204 ~62 ~124 stone
fill ~192 ~63 ~124 ~204 ~65 ~124 dirt
fill ~192 ~66 ~124 ~204 ~66 ~124 grass_block
fill ~205 ~60 ~124 ~205 ~63 ~124 stone
fill ~205 ~64 ~124 ~205 ~66 ~124 dirt
fill ~205 ~67 ~124 ~205 ~67 ~124 grass_block
fill ~206 ~60 ~124 ~207 ~62 ~124 stone
fill ~206 ~63 ~124 ~207 ~65 ~124 dirt
fill ~206 ~66 ~124 ~207 ~66 ~124 grass_block
fill ~192 ~60 ~125 ~207 ~62 ~125 stone
fill ~192 ~63 ~125 ~207 ~65 ~125 dirt
fill ~192 ~66 ~125 ~207 ~66 ~125 grass_block
fill ~192 ~60 ~126 ~207 ~62 ~126 stone
fill ~192 ~63 ~126 ~207 ~65 ~126 dirt
fill ~192 ~66 ~126 ~207 ~66 ~126 grass_block
fill ~192 ~60 ~127 ~207 ~62 ~127 stone
fill ~192 ~63 ~127 ~207 ~65 ~127 dirt
fill ~192 ~66 ~127 ~207 ~66 ~127 grass_block