fill ~160 ~60 ~112 ~170 ~62 ~112 stone
fill ~160 ~63 ~112 ~170 ~65 ~112 dirt
fill ~160 ~66 ~112 ~170 ~66 ~112 grass_block
fill ~171 ~60 ~112 ~175 ~63 ~112 stone
fill ~171 ~64 ~112 ~175 ~66 ~112 dirt
fill ~171 ~67 ~112 ~175 ~67 ~112 grass_block
fill ~160 ~60 ~113 ~174 ~62 ~113 stone
fill ~160 ~63 ~113 ~174 ~65 ~113 dirt
fill ~160 ~66 ~113 ~174 ~66 ~113 grass_block
fill ~175 ~60 ~113 ~175 ~63 ~113 stone
fill ~175 ~64 ~113 ~175 ~66 ~113 dirt
fill ~175 ~67 ~113 ~175 ~67 ~113 grass_block
fill ~160 ~60 ~114 ~175 ~62 ~114 stone
fill ~160 ~63 ~114 ~175 ~65 ~114 dirt
fill ~160 ~66 ~114 ~175 ~66 ~114 grass_block
fill ~160 ~60 ~115 ~175 ~62 ~115 stone
fill ~160 ~63 ~115 ~175 ~65 ~115 dirt
fill ~160 ~66 ~115 ~175 ~66 ~115 grass_block
fill ~160 ~60 ~116 ~160 ~63 ~116 stone
fill ~160 ~64 ~116 ~160 ~66 ~116 dirt
fill ~160 ~67 ~116 ~160 ~67 ~116 grass_block
fill ~161 ~60 ~116 ~175 ~62 ~116 stone
fill ~161 ~63 ~116 ~175 ~65 ~116 dirt
fill ~161 ~66 ~116 ~175 ~66 ~116 grass_block
fill ~160 ~60 ~117 ~163 ~63 ~117 stone
fill ~160 ~64 ~117 ~163 ~66 ~117 dirt
fill ~160 ~67 ~117 ~163 ~67 ~117 grass_block
fill ~164 ~60 ~117 ~175 ~62 ~117 stone
fill ~164 ~63 ~117 ~175 ~65 ~117 dirt
fill ~164 ~66 ~117 ~175 ~66 ~117 grass_block
fill ~160 ~60 ~118 ~168 ~63 ~118 stone
fill ~160 ~64 ~118 ~168 ~66 ~118 dirt
fill ~160 ~67 ~118 ~168 ~67 ~118 grass_block
fill ~169 ~60 ~118 ~175 ~62 ~118 stone
fill ~169 ~63 ~118 ~175 ~65 ~118 dirt
fill ~169 ~66 ~118 ~175 ~66 ~118 grass_block
fill ~160 ~60 ~119 ~161 ~64 ~119 stone
fill ~160 ~65 ~119 ~161 ~67 ~119 dirt
fill ~160 ~68 ~119 ~161 ~68 ~119 grass_block
fill ~162 ~60 ~119 ~170 ~63 ~119 stone
fill ~162 ~64 ~119 ~170 ~66 ~119 dirt
fill ~162 ~67 ~119 ~170 ~67 ~119 grass_block
fill ~171 ~60 ~119 ~175 ~62 ~119 stone
fill ~171 ~63 ~119 ~175 ~65 ~119 dirt
fill ~171 ~66 ~119 ~175 ~66 ~119 grass_block
fill ~160 ~60 ~120 ~163 ~64 ~120 stone
fill ~160 ~65 ~120 ~163 ~67 ~120 dirt
fill ~160 ~68 ~120 ~163 ~68 ~120 grass_block
fill ~164 ~60 ~120 ~170 ~63 ~120 stone
fill ~164 ~64 ~120 ~170 ~66 ~120 dirt
fill ~164 ~67 ~120 ~170 ~67 ~120 grass_block
fill ~171 ~60 ~120 ~175 ~62 ~120 stone
fill ~171 ~63 ~120 ~175 ~65 ~120 dirt
fill ~171 ~66 ~120 ~175 ~66 ~120 grass_block
fill ~160 ~60 ~121 ~163 ~64 ~121 stone
fill ~160 ~65 ~121 ~163 ~67 ~121 dirt
fill ~160 ~68 ~121 ~163 ~68 ~121 grass_block
fill ~164 ~60 ~121 ~170 ~63 ~121 stone
fill ~164 ~64 ~121 ~170 ~66 ~121 dirt
fill ~164 ~67 ~121 ~170 ~67 ~121 grass_block
fill ~171 ~60 ~121 ~175 ~62 ~121 stone
fill ~171 ~63 ~121 ~175 ~65 ~121 dirt
fill ~171 ~66 ~121 ~175 ~66 ~121 grass_block
fill ~160 ~60 ~122 ~161 ~64 ~122 stone
fill ~160 ~65 ~122 ~161 ~67 ~122 dirt
fill ~160 ~68 ~122 ~161 ~68 ~122 grass_block
fill ~162 ~60 ~122 ~168 ~63 ~122 stone
fill ~162 ~64 ~122 ~168 ~66 ~122 dirt
fill ~162 ~67 ~122 ~168 ~67 ~122 grass_block
fill ~169 ~60 ~122 ~173 ~62 ~122 stone
fill ~169 ~63 ~122 ~173 ~65 ~122 dirt
fill ~169 ~66 ~122 ~173 ~66 ~122 grass_block
fill ~174 ~60 ~122 ~175 ~63 ~122 stone
fill ~174 ~64 ~122 ~175 ~66 ~122 dirt
fill ~174 ~67 ~122 ~175 ~67 ~122 grass_block
fill ~160 ~60 ~123 ~160 ~64 ~123 stone
fill ~160 ~65 ~123 ~160 ~67 ~123 dirt
fill ~160 ~68 ~123 ~160 ~68 ~123 grass_block
fill ~161 ~60 ~123 ~167 ~63 ~123 stone
fill ~161 ~64 ~123 ~167 ~66 ~123 dirt
fill ~161 ~67 ~123 ~167 ~67 ~123 grass_block
fill ~168 ~60 ~123 ~168 ~62 ~123 stone
fill ~168 ~63 ~123 ~168 ~65 ~123 dirt
fill ~168 ~66 ~123 ~168 ~66 ~123 grass_block
fill ~169 ~60 ~123 ~175 ~63 ~123 stone
fill ~169 ~64 ~123 ~175 ~66 ~123 dirt
fill ~169 ~67 ~123 ~175 ~67 ~123 grass_block
fill ~160 ~60 ~124 ~160 ~64 ~124 stone
fill ~160 ~65 ~124 ~160 ~67 ~124 dirt
fill ~160 ~68 ~124 ~160 ~68 ~124 grass_block
fill ~161 ~60 ~124 ~166 ~63 ~124 stone
fill ~161 ~64 ~124 ~166 ~66 ~124 dirt
fill ~161 ~67 ~124 ~166 ~67 ~124 grass_block
fill ~167 ~60 ~124 ~168 ~62 ~124 stone
fill ~167 ~63 ~124 ~168 ~65 ~124 dirt
fill ~167 ~66 ~124 ~168 ~66 ~124 grass_block
fill ~169 ~60 ~124 ~169 ~63 ~124 stone
fill ~169 ~64 ~124 ~169 ~66 ~124 dirt
fill ~169 ~67 ~124 ~169 ~67 ~124 grass_block
fill ~170 ~60 ~124 ~172 ~64 ~124 stone
fill ~170 ~65 ~124 ~172 ~67 ~124 dirt
fill ~170 ~68 ~124 ~172 ~68 ~124 grass_block
fill ~173 ~60 ~124 ~175 ~63 ~124 stone
fill ~173 ~64 ~124 ~175 ~66 ~124 dirt
fill ~173 ~67 ~124 ~175 ~67 ~124 grass_block
fill ~160 ~60 ~125 ~161 ~64 ~125 stone
fill ~160 ~65 ~125 ~161 ~67 ~125 dirt
fill ~160 ~68 ~125 ~161 ~68 ~125 grass_block
fill ~162 ~60 ~125 ~169 ~63 ~125 stone
fill ~162 ~64 ~125 ~169 ~66 ~125 dirt
fill ~162 ~67 ~125 ~169 ~67 ~125 grass_block
fill ~170 ~60 ~125 ~174 ~64 ~125 stone
fill ~170 ~65 ~125 ~174 ~67 ~125 dirt
fill ~170 ~68 ~125 ~174 ~68 ~125 grass_block
fill ~175 ~60 ~125 ~175 ~63 ~125 stone
fill ~175 ~64 ~125 ~175 ~66 ~125 dirt
fill ~175 ~67 ~125 ~175 ~67 ~125 grass_block
fill ~160 ~60 ~126 ~162 ~64 ~126 stone
fill ~160 ~65 ~126 ~162 ~67 ~126 dirt
fill ~160 ~68 ~126 ~162 ~68 ~126 grass_block
fill ~163 ~60 ~126 ~167 ~63 ~126 stone
fill ~163 ~64 ~126 ~167 ~66 ~126 dirt
fill ~163 ~67 ~126 ~167 ~67 ~126 grass_block
fill ~168 ~60 ~126 ~175 ~64 ~126 stone
fill ~168 ~65 ~126 ~175 ~67 ~126 dirt
fill ~168 ~68 ~126 ~175 ~68 ~126 grass_block
fill ~160 ~60 ~127 ~161 ~64 ~127 stone
fill ~160 ~65 ~127 ~161 ~67 ~127 dirt
fill ~160 ~68 ~127 ~161 ~68 ~127 grass_block
fill ~162 ~60 ~127 ~167 ~63 ~127 stone
fill ~162 ~64 ~127 ~167 ~66 ~127 dirt
fill ~162 ~67 ~127 ~167 ~67 ~127 grass_block
fill ~168 ~60 ~127 ~169 ~64 ~127 stone
fill ~168 ~65 ~127 ~169 ~67 ~127 dirt
fill ~168 ~68 ~127 ~169 ~68 ~127 grass_block
fill ~170 ~60 ~127 ~172 ~65 ~127 stone
fill ~170 ~66 ~127 ~172 ~68 ~127 dirt
fill ~170 ~69 ~127 ~172 ~69 ~127 grass_block
fill ~173 ~60 ~127 ~175 ~64 ~127 stone
fill ~173 ~65 ~127 ~175 ~67 ~127 dirt
fill ~173 ~68 ~127 ~175 ~68 ~127 grass_block