fill ~448 ~60 ~64 ~455 ~65 ~64 stone
fill ~448 ~66 ~64 ~455 ~68 ~64 dirt
fill ~448 ~69 ~64 ~455 ~69 ~64 grass_block
fill ~456 ~60 ~64 ~457 ~64 ~64 stone
fill ~456 ~65 ~64 ~457 ~67 ~64 dirt
fill ~456 ~68 ~64 ~457 ~68 ~64 grass_block
fill ~458 ~60 ~64 ~461 ~65 ~64 stone
fill ~458 ~66 ~64 ~461 ~68 ~64 dirt
fill ~458 ~69 ~64 ~461 ~69 ~64 grass_block
fill ~462 ~60 ~64 ~463 ~64 ~64 stone
fill ~462 ~65 ~64 ~463 ~67 ~64 dirt
fill ~462 ~68 ~64 ~463 ~68 ~64 grass_block
fill ~448 ~60 ~65 ~463 ~65 ~65 stone
fill ~448 ~66 ~65 ~463 ~68 ~65 dirt
fill ~448 ~69 ~65 ~463 ~69 ~65 grass_block
fill ~448 ~60 ~66 ~463 ~65 ~66 stone
fill ~448 ~66 ~66 ~463 ~68 ~66 dirt
fill ~448 ~69 ~66 ~463 ~69 ~66 grass_block
fill ~448 ~60 ~67 ~463 ~65 ~67 stone
fill ~448 ~66 ~67 ~463 ~68 ~67 dirt
fill ~448 ~69 ~67 ~463 ~69 ~67 grass_block
fill ~448 ~60 ~68 ~450 ~65 ~68 stone
fill ~448 ~66 ~68 ~450 ~68 ~68 dirt
fill ~448 ~69 ~68 ~450 ~69 ~68 grass_block
fill ~451 ~60 ~68 ~452 ~64 ~68 stone
fill ~451 ~65 ~68 ~452 ~67 ~68 dirt
fill ~451 ~68 ~68 ~452 ~68 ~68 grass_block
fill ~453 ~60 ~68 ~463 ~65 ~68 stone
fill ~453 ~66 ~68 ~463 ~68 ~68 dirt
fill ~453 ~69 ~68 ~463 ~69 ~68 grass_block
fill ~448 ~60 ~69 ~450 ~65 ~69 stone
fill ~448 ~66 ~69 ~450 ~68 ~69 dirt
fill ~448 ~69 ~69 ~450 ~69 ~69 grass_block
fill ~451 ~60 ~69 ~454 ~64 ~69 stone
fill ~451 ~65 ~69 ~454 ~67 ~69 dirt
fill ~451 ~68 ~69 ~454 ~68 ~69 grass_block
fill ~455 ~60 ~69 ~463 ~65 ~69 stone
fill ~455 ~66 ~69 ~463 ~68 ~69 dirt
fill ~455 ~69 ~69 ~463 ~69 ~69 grass_block
fill ~448 ~60 ~70 ~450 ~65 ~70 stone
fill ~448 ~66 ~70 ~450 ~68 ~70 dirt
fill ~448 ~69 ~70 ~450 ~69 ~70 grass_block
fill ~451 ~60 ~70 ~455 ~64 ~70 stone
fill ~451 ~65 ~70 ~455 ~67 ~70 dirt
fill ~451 ~68 ~70 ~455 ~68 ~70 grass_block
fill ~456 ~60 ~70 ~463 ~65 ~70 stone
fill ~456 ~66 ~70 ~463 ~68 ~70 dirt
fill ~456 ~69 ~70 ~463 ~69 ~70 grass_block
fill ~448 ~60 ~71 ~450 ~65 ~71 stone
fill ~448 ~66 ~71 ~450 ~68 ~71 dirt
fill ~448 ~69 ~71 ~450 ~69 ~71 grass_block
fill ~451 ~60 ~71 ~457 ~64 ~71 stone
fill ~451 ~65 ~71 ~457 ~67 ~71 dirt
fill ~451 ~68 ~71 ~457 ~68 ~71 grass_block
fill ~458 ~60 ~71 ~463 ~65 ~71 stone
fill ~458 ~66 ~71 ~463 ~68 ~71 dirt
fill ~458 ~69 ~71 ~463 ~69 ~71 grass_block
fill ~448 ~60 ~72 ~450 ~65 ~72 stone
fill ~448 ~66 ~72 ~450 ~68 ~72 dirt
fill ~448 ~69 ~72 ~450 ~69 ~72 grass_block
fill ~451 ~60 ~72 ~459 ~64 ~72 stone
fill ~451 ~65 ~72 ~459 ~67 ~72 dirt
fill ~451 ~68 ~72 ~459 ~68 ~72 grass_block
fill ~460 ~60 ~72 ~463 ~65 ~72 stone
fill ~460 ~66 ~72 ~463 ~68 ~72 dirt
fill ~460 ~69 ~72 ~463 ~69 ~72 grass_block
fill ~448 ~60 ~73 ~451 ~65 ~73 stone
fill ~448 ~66 ~73 ~451 ~68 ~73 dirt
fill ~448 ~69 ~73 ~451 ~69 ~73 grass_block
fill ~452 ~60 ~73 ~461 ~64 ~73 stone
fill ~452 ~65 ~73 ~461 ~67 ~73 dirt
fill ~452 ~68 ~73 ~461 ~68 ~73 grass_block
fill ~462 ~60 ~73 ~463 ~65 ~73 stone
fill ~462 ~66 ~73 ~463 ~68 ~73 dirt
fill ~462 ~69 ~73 ~463 ~69 ~73 grass_block
fill ~448 ~60 ~74 ~452 ~65 ~74 stone
fill ~448 ~66 ~74 ~452 ~68 ~74 dirt
fill ~448 ~69 ~74 ~452 ~69 ~74 grass_block
fill ~453 ~60 ~74 ~463 ~64 ~74 stone
fill ~453 ~65 ~74 ~463 ~67 ~74 dirt
fill ~453 ~68 ~74 ~463 ~68 ~74 grass_block
fill ~448 ~60 ~75 ~452 ~65 ~75 stone
fill ~448 ~66 ~75 ~452 ~68 ~75 dirt
fill ~448 ~69 ~75 ~452 ~69 ~75 grass_block
fill ~453 ~60 ~75 ~463 ~64 ~75 stone
fill ~453 ~65 ~75 ~463 ~67 ~75 dirt
fill ~453 ~68 ~75 ~463 ~68 ~75 grass_block
fill ~448 ~60 ~76 ~452 ~65 ~76 stone
fill ~448 ~66 ~76 ~452 ~68 ~76 dirt
fill ~448 ~69 ~76 ~452 ~69 ~76 grass_block
fill ~453 ~60 ~76 ~456 ~64 ~76 stone
fill ~453 ~65 ~76 ~456 ~67 ~76 dirt
fill ~453 ~68 ~76 ~456 ~68 ~76 grass_block
fill ~457 ~60 ~76 ~458 ~63 ~76 stone
fill ~457 ~64 ~76 ~458 ~66 ~76 dirt
fill ~457 ~67 ~76 ~458 ~67 ~76 grass_block
fill ~459 ~60 ~76 ~463 ~64 ~76 stone
fill ~459 ~65 ~76 ~463 ~67 ~76 dirt
fill ~459 ~68 ~76 ~463 ~68 ~76 grass_block
fill ~448 ~60 ~77 ~453 ~65 ~77 stone
fill ~448 ~66 ~77 ~453 ~68 ~77 dirt
fill ~448 ~69 ~77 ~453 ~69 ~77 grass_block
fill ~454 ~60 ~77 ~457 ~64 ~77 stone
fill ~454 ~65 ~77 ~457 ~67 ~77 dirt
fill ~454 ~68 ~77 ~457 ~68 ~77 grass_block
fill ~458 ~60 ~77 ~460 ~63 ~77 stone
fill ~458 ~64 ~77 ~460 ~66 ~77 dirt
fill ~458 ~67 ~77 ~460 ~67 ~77 grass_block
fill ~461 ~60 ~77 ~463 ~64 ~77 stone
fill ~461 ~65 ~77 ~463 ~67 ~77 dirt
fill ~461 ~68 ~77 ~463 ~68 ~77 grass_block
fill ~448 ~60 ~78 ~449 ~64 ~78 stone
fill ~448 ~65 ~78 ~449 ~67 ~78 dirt
fill ~448 ~68 ~78 ~449 ~68 ~78 grass_block
fill ~450 ~60 ~78 ~454 ~65 ~78 stone
fill ~450 ~66 ~78 ~454 ~68 ~78 dirt
fill ~450 ~69 ~78 ~454 ~69 ~78 grass_block
fill ~455 ~60 ~78 ~458 ~64 ~78 stone
fill ~455 ~65 ~78 ~458 ~67 ~78 dirt
fill ~455 ~68 ~78 ~458 ~68 ~78 grass_block
fill ~459 ~60 ~78 ~462 ~63 ~78 stone
fill ~459 ~64 ~78 ~462 ~66 ~78 dirt
fill ~459 ~67 ~78 ~462 ~67 ~78 grass_block
fill ~463 ~60 ~78 ~463 ~64 ~78 stone
fill ~463 ~65 ~78 ~463 ~67 ~78 dirt
fill ~463 ~68 ~78 ~463 ~68 ~78 grass_block
fill ~448 ~60 ~79 ~449 ~64 ~79 stone
fill ~448 ~65 ~79 ~449 ~67 ~79 dirt
fill ~448 ~68 ~79 ~449 ~68 ~79 grass_block
fill ~450 ~60 ~79 ~454 ~65 ~79 stone
fill ~450 ~66 ~79 ~454 ~68 ~79 dirt
fill ~450 ~69 ~79 ~454 ~69 ~79 grass_block
fill ~455 ~60 ~79 ~458 ~64 ~79 stone
fill ~455 ~65 ~79 ~458 ~67 ~79 dirt
fill ~455 ~68 ~79 ~458 ~68 ~79 grass_block
fill ~459 ~60 ~79 ~463 ~63 ~79 stone
fill ~459 ~64 ~79 ~463 ~66 ~79 dirt
fill ~459 ~67 ~79 ~463 ~67 ~79 grass_block