fill ~176 ~60 ~80 ~176 ~63 ~80 stone
fill ~176 ~64 ~80 ~176 ~66 ~80 dirt
fill ~176 ~67 ~80 ~176 ~67 ~80 grass_block
fill ~177 ~60 ~80 ~180 ~64 ~80 stone
fill ~177 ~65 ~80 ~180 ~67 ~80 dirt
fill ~177 ~68 ~80 ~180 ~68 ~80 grass_block
fill ~181 ~60 ~80 ~184 ~63 ~80 stone
fill ~181 ~64 ~80 ~184 ~66 ~80 dirt
fill ~181 ~67 ~80 ~184 ~67 ~80 grass_block
fill ~185 ~60 ~80 ~185 ~64 ~80 stone
fill ~185 ~65 ~80 ~185 ~67 ~80 dirt
fill ~185 ~68 ~80 ~185 ~68 ~80 grass_block
fill ~186 ~60 ~80 ~191 ~65 ~80 stone
fill ~186 ~66 ~80 ~191 ~68 ~80 dirt
fill ~186 ~69 ~80 ~191 ~69 ~80 grass_block
fill ~176 ~60 ~81 ~177 ~63 ~81 stone
fill ~176 ~64 ~81 ~177 ~66 ~81 dirt
fill ~176 ~67 ~81 ~177 ~67 ~81 grass_block
fill ~178 ~60 ~81 ~180 ~64 ~81 stone
fill ~178 ~65 ~81 ~180 ~67 ~81 dirt
fill ~178 ~68 ~81 ~180 ~68 ~81 grass_block
fill ~181 ~60 ~81 ~184 ~63 ~81 stone
fill ~181 ~64 ~81 ~184 ~66 ~81 dirt
fill ~181 ~67 ~81 ~184 ~67 ~81 grass_block
fill ~185 ~60 ~81 ~186 ~64 ~81 stone
fill ~185 ~65 ~81 ~186 ~67 ~81 dirt
fill ~185 ~68 ~81 ~186 ~68 ~81 grass_block
fill ~187 ~60 ~81 ~191 ~65 ~81 stone
fill ~187 ~66 ~81 ~191 ~68 ~81 dirt
fill ~187 ~69 ~81 ~191 ~69 ~81 grass_block
fill ~176 ~60 ~82 ~178 ~63 ~82 stone
fill ~176 ~64 ~82 ~178 ~66 ~82 dirt
fill ~176 ~67 ~82 ~178 ~67 ~82 grass_block
fill ~179 ~60 ~82 ~180 ~64 ~82 stone
fill ~179 ~65 ~82 ~180 ~67 ~82 dirt
fill ~179 ~68 ~82 ~180 ~68 ~82 grass_block
fill ~181 ~60 ~82 ~184 ~63 ~82 stone
fill ~181 ~64 ~82 ~184 ~66 ~82 dirt
fill ~181 ~67 ~82 ~184 ~67 ~82 grass_block
fill ~185 ~60 ~82 ~186 ~64 ~82 stone
fill ~185 ~65 ~82 ~186 ~67 ~82 dirt
fill ~185 ~68 ~82 ~186 ~68 ~82 grass_block
fill ~187 ~60 ~82 ~191 ~65 ~82 stone
fill ~187 ~66 ~82 ~191 ~68 ~82 dirt
fill ~187 ~69 ~82 ~191 ~69 ~82 grass_block
fill ~176 ~60 ~83 ~184 ~63 ~83 stone
fill ~176 ~64 ~83 ~184 ~66 ~83 dirt
fill ~176 ~67 ~83 ~184 ~67 ~83 grass_block
fill ~185 ~60 ~83 ~186 ~64 ~83 stone
fill ~185 ~65 ~83 ~186 ~67 ~83 dirt
fill ~185 ~68 ~83 ~186 ~68 ~83 grass_block
fill ~187 ~60 ~83 ~191 ~65 ~83 stone
fill ~187 ~66 ~83 ~191 ~68 ~83 dirt
fill ~187 ~69 ~83 ~191 ~69 ~83 grass_block
fill ~176 ~60 ~84 ~183 ~63 ~84 stone
fill ~176 ~64 ~84 ~183 ~66 ~84 dirt
fill ~176 ~67 ~84 ~183 ~67 ~84 grass_block
fill ~184 ~60 ~84 ~186 ~64 ~84 stone
fill ~184 ~65 ~84 ~186 ~67 ~84 dirt
fill ~184 ~68 ~84 ~186 ~68 ~84 grass_block
fill ~187 ~60 ~84 ~191 ~65 ~84 stone
fill ~187 ~66 ~84 ~191 ~68 ~84 dirt
fill ~187 ~69 ~84 ~191 ~69 ~84 grass_block
fill ~176 ~60 ~85 ~176 ~64 ~85 stone
fill ~176 ~65 ~85 ~176 ~67 ~85 dirt
fill ~176 ~68 ~85 ~176 ~68 ~85 grass_block
fill ~177 ~60 ~85 ~183 ~63 ~85 stone
fill ~177 ~64 ~85 ~183 ~66 ~85 dirt
fill ~177 ~67 ~85 ~183 ~67 ~85 grass_block
fill ~184 ~60 ~85 ~187 ~64 ~85 stone
fill ~184 ~65 ~85 ~187 ~67 ~85 dirt
fill ~184 ~68 ~85 ~187 ~68 ~85 grass_block
fill ~188 ~60 ~85 ~190 ~65 ~85 stone
fill ~188 ~66 ~85 ~190 ~68 ~85 dirt
fill ~188 ~69 ~85 ~190 ~69 ~85 grass_block
fill ~191 ~60 ~85 ~191 ~64 ~85 stone
fill ~191 ~65 ~85 ~191 ~67 ~85 dirt
fill ~191 ~68 ~85 ~191 ~68 ~85 grass_block
fill ~176 ~60 ~86 ~177 ~64 ~86 stone
fill ~176 ~65 ~86 ~177 ~67 ~86 dirt
fill ~176 ~68 ~86 ~177 ~68 ~86 grass_block
fill ~178 ~60 ~86 ~183 ~63 ~86 stone
fill ~178 ~64 ~86 ~183 ~66 ~86 dirt
fill ~178 ~67 ~86 ~183 ~67 ~86 grass_block
fill ~184 ~60 ~86 ~191 ~64 ~86 stone
fill ~184 ~65 ~86 ~191 ~67 ~86 dirt
fill ~184 ~68 ~86 ~191 ~68 ~86 grass_block
fill ~176 ~60 ~87 ~178 ~64 ~87 stone
fill ~176 ~65 ~87 ~178 ~67 ~87 dirt
fill ~176 ~68 ~87 ~178 ~68 ~87 grass_block
fill ~179 ~60 ~87 ~180 ~63 ~87 stone
fill ~179 ~64 ~87 ~180 ~66 ~87 dirt
fill ~179 ~67 ~87 ~180 ~67 ~87 grass_block
fill ~181 ~60 ~87 ~181 ~62 ~87 stone
fill ~181 ~63 ~87 ~181 ~65 ~87 dirt
fill ~181 ~66 ~87 ~181 ~66 ~87 grass_block
fill ~182 ~60 ~87 ~184 ~63 ~87 stone
fill ~182 ~64 ~87 ~184 ~66 ~87 dirt
fill ~182 ~67 ~87 ~184 ~67 ~87 grass_block
fill ~185 ~60 ~87 ~191 ~64 ~87 stone
fill ~185 ~65 ~87 ~191 ~67 ~87 dirt
fill ~185 ~68 ~87 ~191 ~68 ~87 grass_block
fill ~176 ~60 ~88 ~178 ~64 ~88 stone
fill ~176 ~65 ~88 ~178 ~67 ~88 dirt
fill ~176 ~68 ~88 ~178 ~68 ~88 grass_block
fill ~179 ~60 ~88 ~184 ~63 ~88 stone
fill ~179 ~64 ~88 ~184 ~66 ~88 dirt
fill ~179 ~67 ~88 ~184 ~67 ~88 grass_block
fill ~185 ~60 ~88 ~191 ~64 ~88 stone
fill ~185 ~65 ~88 ~191 ~67 ~88 dirt
fill ~185 ~68 ~88 ~191 ~68 ~88 grass_block
fill ~176 ~60 ~89 ~176 ~63 ~89 stone
fill ~176 ~64 ~89 ~176 ~66 ~89 dirt
fill ~176 ~67 ~89 ~176 ~67 ~89 grass_block
fill ~177 ~60 ~89 ~179 ~64 ~89 stone
fill ~177 ~65 ~89 ~179 ~67 ~89 dirt
fill ~177 ~68 ~89 ~179 ~68 ~89 grass_block
fill ~180 ~60 ~89 ~185 ~63 ~89 stone
fill ~180 ~64 ~89 ~185 ~66 ~89 dirt
fill ~180 ~67 ~89 ~185 ~67 ~89 grass_block
fill ~186 ~60 ~89 ~190 ~64 ~89 stone
fill ~186 ~65 ~89 ~190 ~67 ~89 dirt
fill ~186 ~68 ~89 ~190 ~68 ~89 grass_block
fill ~191 ~60 ~89 ~191 ~63 ~89 stone
fill ~191 ~64 ~89 ~191 ~66 ~89 dirt
fill ~191 ~67 ~89 ~191 ~67 ~89 grass_block
fill ~176 ~60 ~90 ~176 ~63 ~90 stone
fill ~176 ~64 ~90 ~176 ~66 ~90 dirt
fill ~176 ~67 ~90 ~176 ~67 ~90 grass_block
fill ~177 ~60 ~90 ~179 ~64 ~90 stone
fill ~177 ~65 ~90 ~179 ~67 ~90 dirt
fill ~177 ~68 ~90 ~179 ~68 ~90 grass_block
fill ~180 ~60 ~90 ~182 ~63 ~90 stone
fill ~180 ~64 ~90 ~182 ~66 ~90 dirt
fill ~180 ~67 ~90 ~182 ~67 ~90 grass_block
fill ~183 ~60 ~90 ~183 ~62 ~90 stone
fill ~183 ~63 ~90 ~183 ~65 ~90 dirt
fill ~183 ~66 ~90 ~183 ~66 ~90 grass_block
fill ~184 ~60 ~90 ~185 ~63 ~90 stone
fill ~184 ~64 ~90 ~185 ~66 ~90 dirt
fill ~184 ~67 ~90 ~185 ~67 ~90 grass_block
fill ~186 ~60 ~90 ~189 ~64 ~90 stone
fill ~186 ~65 ~90 ~189 ~67 ~90 dirt
fill ~186 ~68 ~90 ~189 ~68 ~90 grass_block
fill ~190 ~60 ~90 ~191 ~63 ~90 stone
fill ~190 ~64 ~90 ~191 ~66 ~90 dirt
fill ~190 ~67 ~90 ~191 ~67 ~90 grass_block
fill ~176 ~60 ~91 ~177 ~63 ~91 stone
fill ~176 ~64 ~91 ~177 ~66 ~91 dirt
fill ~176 ~67 ~91 ~177 ~67 ~91 grass_block
fill ~178 ~60 ~91 ~180 ~64 ~91 stone
fill ~178 ~65 ~91 ~180 ~67 ~91 dirt
fill ~178 ~68 ~91 ~180 ~68 ~91 grass_block
fill ~181 ~60 ~91 ~182 ~63 ~91 stone
fill ~181 ~64 ~91 ~182 ~66 ~91 dirt
fill ~181 ~67 ~91 ~182 ~67 ~91 grass_block
fill ~183 ~60 ~91 ~183 ~62 ~91 stone
fill ~183 ~63 ~91 ~183 ~65 ~91 dirt
fill ~183 ~66 ~91 ~183 ~66 ~91 grass_block
fill ~184 ~60 ~91 ~191 ~63 ~91 stone
fill ~184 ~64 ~91 ~191 ~66 ~91 dirt
fill ~184 ~67 ~91 ~191 ~67 ~91 grass_block
fill ~176 ~60 ~92 ~178 ~63 ~92 stone
fill ~176 ~64 ~92 ~178 ~66 ~92 dirt
fill ~176 ~67 ~92 ~178 ~67 ~92 grass_block
fill ~179 ~60 ~92 ~180 ~64 ~92 stone
fill ~179 ~65 ~92 ~180 ~67 ~92 dirt
fill ~179 ~68 ~92 ~180 ~68 ~92 grass_block
fill ~181 ~60 ~92 ~183 ~63 ~92 stone
fill ~181 ~64 ~92 ~183 ~66 ~92 dirt
fill ~181 ~67 ~92 ~183 ~67 ~92 grass_block
fill ~184 ~60 ~92 ~185 ~62 ~92 stone
fill ~184 ~63 ~92 ~185 ~65 ~92 dirt
fill ~184 ~66 ~92 ~185 ~66 ~92 grass_block
fill ~186 ~60 ~92 ~191 ~63 ~92 stone
fill ~186 ~64 ~92 ~191 ~66 ~92 dirt
fill ~186 ~67 ~92 ~191 ~67 ~92 grass_block
fill ~176 ~60 ~93 ~178 ~63 ~93 stone
fill ~176 ~64 ~93 ~178 ~66 ~93 dirt
fill ~176 ~67 ~93 ~178 ~67 ~93 grass_block
fill ~179 ~60 ~93 ~181 ~64 ~93 stone
fill ~179 ~65 ~93 ~181 ~67 ~93 dirt
fill ~179 ~68 ~93 ~181 ~68 ~93 grass_block
fill ~182 ~60 ~93 ~190 ~63 ~93 stone
fill ~182 ~64 ~93 ~190 ~66 ~93 dirt
fill ~182 ~67 ~93 ~190 ~67 ~93 grass_block
fill ~191 ~60 ~93 ~191 ~62 ~93 stone
fill ~191 ~63 ~93 ~191 ~65 ~93 dirt
fill ~191 ~66 ~93 ~191 ~66 ~93 grass_block
fill ~176 ~60 ~94 ~179 ~63 ~94 stone
fill ~176 ~64 ~94 ~179 ~66 ~94 dirt
fill ~176 ~67 ~94 ~179 ~67 ~94 grass_block
fill ~180 ~60 ~94 ~181 ~64 ~94 stone
fill ~180 ~65 ~94 ~181 ~67 ~94 dirt
fill ~180 ~68 ~94 ~181 ~68 ~94 grass_block
fill ~182 ~60 ~94 ~190 ~63 ~94 stone
fill ~182 ~64 ~94 ~190 ~66 ~94 dirt
fill ~182 ~67 ~94 ~190 ~67 ~94 grass_block
fill ~191 ~60 ~94 ~191 ~62 ~94 stone
fill ~191 ~63 ~94 ~191 ~65 ~94 dirt
fill ~191 ~66 ~94 ~191 ~66 ~94 grass_block
fill ~176 ~60 ~95 ~176 ~63 ~95 stone
fill ~176 ~64 ~95 ~176 ~66 ~95 dirt
fill ~176 ~67 ~95 ~176 ~67 ~95 grass_block
fill ~177 ~60 ~95 ~177 ~62 ~95 stone
fill ~177 ~63 ~95 ~177 ~65 ~95 dirt
fill ~177 ~66 ~95 ~177 ~66 ~95 grass_block
fill ~178 ~60 ~95 ~179 ~63 ~95 stone
fill ~178 ~64 ~95 ~179 ~66 ~95 dirt
fill ~178 ~67 ~95 ~179 ~67 ~95 grass_block
fill ~180 ~60 ~95 ~182 ~64 ~95 stone
fill ~180 ~65 ~95 ~182 ~67 ~95 dirt
fill ~180 ~68 ~95 ~182 ~68 ~95 grass_block
fill ~183 ~60 ~95 ~189 ~63 ~95 stone
fill ~183 ~64 ~95 ~189 ~66 ~95 dirt
fill ~183 ~67 ~95 ~189 ~67 ~95 grass_block
fill ~190 ~60 ~95 ~191 ~62 ~95 stone
fill ~190 ~63 ~95 ~191 ~65 ~95 dirt
fill ~190 ~66 ~95 ~191 ~66 ~95 grass_block