fill ~80 ~60 ~128 ~88 ~63 ~128 stone
fill ~80 ~64 ~128 ~88 ~66 ~128 dirt
fill ~80 ~67 ~128 ~88 ~67 ~128 grass_block
fill ~89 ~60 ~128 ~95 ~64 ~128 stone
fill ~89 ~65 ~128 ~95 ~67 ~128 dirt
fill ~89 ~68 ~128 ~95 ~68 ~128 grass_block
fill ~80 ~60 ~129 ~94 ~63 ~129 stone
fill ~80 ~64 ~129 ~94 ~66 ~129 dirt
fill ~80 ~67 ~129 ~94 ~67 ~129 grass_block
fill ~95 ~60 ~129 ~95 ~64 ~129 stone
fill ~95 ~65 ~129 ~95 ~67 ~129 dirt
fill ~95 ~68 ~129 ~95 ~68 ~129 grass_block
fill ~80 ~60 ~130 ~95 ~63 ~130 stone
fill ~80 ~64 ~130 ~95 ~66 ~130 dirt
fill ~80 ~67 ~130 ~95 ~67 ~130 grass_block
fill ~80 ~60 ~131 ~95 ~63 ~131 stone
fill ~80 ~64 ~131 ~95 ~66 ~131 dirt
fill ~80 ~67 ~131 ~95 ~67 ~131 grass_block
fill ~80 ~60 ~132 ~95 ~63 ~132 stone
fill ~80 ~64 ~132 ~95 ~66 ~132 dirt
fill ~80 ~67 ~132 ~95 ~67 ~132 grass_block
fill ~80 ~60 ~133 ~95 ~63 ~133 stone
fill ~80 ~64 ~133 ~95 ~66 ~133 dirt
fill ~80 ~67 ~133 ~95 ~67 ~133 grass_block
fill ~80 ~60 ~134 ~95 ~63 ~134 stone
fill ~80 ~64 ~134 ~95 ~66 ~134 dirt
fill ~80 ~67 ~134 ~95 ~67 ~134 grass_block
fill ~80 ~60 ~135 ~80 ~64 ~135 stone
fill ~80 ~65 ~135 ~80 ~67 ~135 dirt
fill ~80 ~68 ~135 ~80 ~68 ~135 grass_block
fill ~81 ~60 ~135 ~95 ~63 ~135 stone
fill ~81 ~64 ~135 ~95 ~66 ~135 dirt
fill ~81 ~67 ~135 ~95 ~67 ~135 grass_block
fill ~80 ~60 ~136 ~81 ~64 ~136 stone
fill ~80 ~65 ~136 ~81 ~67 ~136 dirt
fill ~80 ~68 ~136 ~81 ~68 ~136 grass_block
fill ~82 ~60 ~136 ~95 ~63 ~136 stone
fill ~82 ~64 ~136 ~95 ~66 ~136 dirt
fill ~82 ~67 ~136 ~95 ~67 ~136 grass_block
fill ~80 ~60 ~137 ~81 ~64 ~137 stone
fill ~80 ~65 ~137 ~81 ~67 ~137 dirt
fill ~80 ~68 ~137 ~81 ~68 ~137 grass_block
fill ~82 ~60 ~137 ~95 ~63 ~137 stone
fill ~82 ~64 ~137 ~95 ~66 ~137 dirt
fill ~82 ~67 ~137 ~95 ~67 ~137 grass_block
fill ~80 ~60 ~138 ~81 ~64 ~138 stone
fill ~80 ~65 ~138 ~81 ~67 ~138 dirt
fill ~80 ~68 ~138 ~81 ~68 ~138 grass_block
fill ~82 ~60 ~138 ~95 ~63 ~138 stone
fill ~82 ~64 ~138 ~95 ~66 ~138 dirt
fill ~82 ~67 ~138 ~95 ~67 ~138 grass_block
fill ~80 ~60 ~139 ~81 ~64 ~139 stone
fill ~80 ~65 ~139 ~81 ~67 ~139 dirt
fill ~80 ~68 ~139 ~81 ~68 ~139 grass_block
fill ~82 ~60 ~139 ~84 ~63 ~139 stone
fill ~82 ~64 ~139 ~84 ~66 ~139 dirt
fill ~82 ~67 ~139 ~84 ~67 ~139 grass_block
fill ~85 ~60 ~139 ~88 ~64 ~139 stone
fill ~85 ~65 ~139 ~88 ~67 ~139 dirt
fill ~85 ~68 ~139 ~88 ~68 ~139 grass_block
fill ~89 ~60 ~139 ~95 ~63 ~139 stone
fill ~89 ~64 ~139 ~95 ~66 ~139 dirt
fill ~89 ~67 ~139 ~95 ~67 ~139 grass_block
fill ~80 ~60 ~140 ~82 ~64 ~140 stone
fill ~80 ~65 ~140 ~82 ~67 ~140 dirt
fill ~80 ~68 ~140 ~82 ~68 ~140 grass_block
fill ~83 ~60 ~140 ~83 ~63 ~140 stone
fill ~83 ~64 ~140 ~83 ~66 ~140 dirt
fill ~83 ~67 ~140 ~83 ~67 ~140 grass_block
fill ~84 ~60 ~140 ~89 ~64 ~140 stone
fill ~84 ~65 ~140 ~89 ~67 ~140 dirt
fill ~84 ~68 ~140 ~89 ~68 ~140 grass_block
fill ~90 ~60 ~140 ~95 ~63 ~140 stone
fill ~90 ~64 ~140 ~95 ~66 ~140 dirt
fill ~90 ~67 ~140 ~95 ~67 ~140 grass_block
fill ~80 ~60 ~141 ~80 ~64 ~141 stone
fill ~80 ~65 ~141 ~80 ~67 ~141 dirt
fill ~80 ~68 ~141 ~80 ~68 ~141 grass_block
fill ~81 ~60 ~141 ~82 ~63 ~141 stone
fill ~81 ~64 ~141 ~82 ~66 ~141 dirt
fill ~81 ~67 ~141 ~82 ~67 ~141 grass_block
fill ~83 ~60 ~141 ~85 ~64 ~141 stone
fill ~83 ~65 ~141 ~85 ~67 ~141 dirt
fill ~83 ~68 ~141 ~85 ~68 ~141 grass_block
fill ~86 ~60 ~141 ~87 ~65 ~141 stone
fill ~86 ~66 ~141 ~87 ~68 ~141 dirt
fill ~86 ~69 ~141 ~87 ~69 ~141 grass_block
fill ~88 ~60 ~141 ~91 ~64 ~141 stone
fill ~88 ~65 ~141 ~91 ~67 ~141 dirt
fill ~88 ~68 ~141 ~91 ~68 ~141 grass_block
fill ~92 ~60 ~141 ~95 ~63 ~141 stone
fill ~92 ~64 ~141 ~95 ~66 ~141 dirt
fill ~92 ~67 ~141 ~95 ~67 ~141 grass_block
fill ~80 ~60 ~142 ~80 ~63 ~142 stone
fill ~80 ~64 ~142 ~80 ~66 ~142 dirt
fill ~80 ~67 ~142 ~80 ~67 ~142 grass_block
fill ~81 ~60 ~142 ~85 ~64 ~142 stone
fill ~81 ~65 ~142 ~85 ~67 ~142 dirt
fill ~81 ~68 ~142 ~85 ~68 ~142 grass_block
fill ~86 ~60 ~142 ~87 ~65 ~142 stone
fill ~86 ~66 ~142 ~87 ~68 ~142 dirt
fill ~86 ~69 ~142 ~87 ~69 ~142 grass_block
fill ~88 ~60 ~142 ~91 ~64 ~142 stone
fill ~88 ~65 ~142 ~91 ~67 ~142 dirt
fill ~88 ~68 ~142 ~91 ~68 ~142 grass_block
fill ~92 ~60 ~142 ~95 ~63 ~142 stone
fill ~92 ~64 ~142 ~95 ~66 ~142 dirt
fill ~92 ~67 ~142 ~95 ~67 ~142 grass_block
fill ~80 ~60 ~143 ~84 ~64 ~143 stone
fill ~80 ~65 ~143 ~84 ~67 ~143 dirt
fill ~80 ~68 ~143 ~84 ~68 ~143 grass_block
fill ~85 ~60 ~143 ~89 ~65 ~143 stone
fill ~85 ~66 ~143 ~89 ~68 ~143 dirt
fill ~85 ~69 ~143 ~89 ~69 ~143 grass_block
fill ~90 ~60 ~143 ~92 ~64 ~143 stone
fill ~90 ~65 ~143 ~92 ~67 ~143 dirt
fill ~90 ~68 ~143 ~92 ~68 ~143 grass_block
fill ~93 ~60 ~143 ~95 ~63 ~143 stone
fill ~93 ~64 ~143 ~95 ~66 ~143 dirt
fill ~93 ~67 ~143 ~95 ~67 ~143 grass_block