fill ~48 ~60 ~48 ~49 ~68 ~48 stone
fill ~48 ~69 ~48 ~49 ~71 ~48 dirt
fill ~48 ~72 ~48 ~49 ~72 ~48 grass_block
fill ~50 ~60 ~48 ~51 ~67 ~48 stone
fill ~50 ~68 ~48 ~51 ~70 ~48 dirt
fill ~50 ~71 ~48 ~51 ~71 ~48 grass_block
fill ~52 ~60 ~48 ~55 ~66 ~48 stone
fill ~52 ~67 ~48 ~55 ~69 ~48 dirt
fill ~52 ~70 ~48 ~55 ~70 ~48 grass_block
fill ~56 ~60 ~48 ~60 ~65 ~48 stone
fill ~56 ~66 ~48 ~60 ~68 ~48 dirt
fill ~56 ~69 ~48 ~60 ~69 ~48 grass_block
fill ~61 ~60 ~48 ~63 ~64 ~48 stone
fill ~61 ~65 ~48 ~63 ~67 ~48 dirt
fill ~61 ~68 ~48 ~63 ~68 ~48 grass_block
fill ~48 ~60 ~49 ~51 ~68 ~49 stone
fill ~48 ~69 ~49 ~51 ~71 ~49 dirt
fill ~48 ~72 ~49 ~51 ~72 ~49 grass_block
fill ~52 ~60 ~49 ~54 ~67 ~49 stone
fill ~52 ~68 ~49 ~54 ~70 ~49 dirt
fill ~52 ~71 ~49 ~54 ~71 ~49 grass_block
fill ~55 ~60 ~49 ~57 ~66 ~49 stone
fill ~55 ~67 ~49 ~57 ~69 ~49 dirt
fill ~55 ~70 ~49 ~57 ~70 ~49 grass_block
fill ~58 ~60 ~49 ~61 ~65 ~49 stone
fill ~58 ~66 ~49 ~61 ~68 ~49 dirt
fill ~58 ~69 ~49 ~61 ~69 ~49 grass_block
fill ~62 ~60 ~49 ~63 ~64 ~49 stone
fill ~62 ~65 ~49 ~63 ~67 ~49 dirt
fill ~62 ~68 ~49 ~63 ~68 ~49 grass_block
fill ~48 ~60 ~50 ~52 ~68 ~50 stone
fill ~48 ~69 ~50 ~52 ~71 ~50 dirt
fill ~48 ~72 ~50 ~52 ~72 ~50 grass_block
fill ~53 ~60 ~50 ~55 ~67 ~50 stone
fill ~53 ~68 ~50 ~55 ~70 ~50 dirt
fill ~53 ~71 ~50 ~55 ~71 ~50 grass_block
fill ~56 ~60 ~50 ~58 ~66 ~50 stone
fill ~56 ~67 ~50 ~58 ~69 ~50 dirt
fill ~56 ~70 ~50 ~58 ~70 ~50 grass_block
fill ~59 ~60 ~50 ~61 ~65 ~50 stone
fill ~59 ~66 ~50 ~61 ~68 ~50 dirt
fill ~59 ~69 ~50 ~61 ~69 ~50 grass_block
fill ~62 ~60 ~50 ~63 ~64 ~50 stone
fill ~62 ~65 ~50 ~63 ~67 ~50 dirt
fill ~62 ~68 ~50 ~63 ~68 ~50 grass_block
fill ~48 ~60 ~51 ~51 ~67 ~51 stone
fill ~48 ~68 ~51 ~51 ~70 ~51 dirt
fill ~48 ~71 ~51 ~51 ~71 ~51 grass_block
fill ~52 ~60 ~51 ~54 ~68 ~51 stone
fill ~52 ~69 ~51 ~54 ~71 ~51 dirt
fill ~52 ~72 ~51 ~54 ~72 ~51 grass_block
fill ~55 ~60 ~51 ~56 ~67 ~51 stone
fill ~55 ~68 ~51 ~56 ~70 ~51 dirt
fill ~55 ~71 ~51 ~56 ~71 ~51 grass_block
fill ~57 ~60 ~51 ~58 ~66 ~51 stone
fill ~57 ~67 ~51 ~58 ~69 ~51 dirt
fill ~57 ~70 ~51 ~58 ~70 ~51 grass_block
fill ~59 ~60 ~51 ~63 ~65 ~51 stone
fill ~59 ~66 ~51 ~63 ~68 ~51 dirt
fill ~59 ~69 ~51 ~63 ~69 ~51 grass_block
fill ~48 ~60 ~52 ~52 ~67 ~52 stone
fill ~48 ~68 ~52 ~52 ~70 ~52 dirt
fill ~48 ~71 ~52 ~52 ~71 ~52 grass_block
fill ~53 ~60 ~52 ~53 ~68 ~52 stone
fill ~53 ~69 ~52 ~53 ~71 ~52 dirt
fill ~53 ~72 ~52 ~53 ~72 ~52 grass_block
fill ~54 ~60 ~52 ~57 ~67 ~52 stone
fill ~54 ~68 ~52 ~57 ~70 ~52 dirt
fill ~54 ~71 ~52 ~57 ~71 ~52 grass_block
fill ~58 ~60 ~52 ~60 ~66 ~52 stone
fill ~58 ~67 ~52 ~60 ~69 ~52 dirt
fill ~58 ~70 ~52 ~60 ~70 ~52 grass_block
fill ~61 ~60 ~52 ~63 ~65 ~52 stone
fill ~61 ~66 ~52 ~63 ~68 ~52 dirt
fill ~61 ~69 ~52 ~63 ~69 ~52 grass_block
fill ~48 ~60 ~53 ~51 ~66 ~53 stone
fill ~48 ~67 ~53 ~51 ~69 ~53 dirt
fill ~48 ~70 ~53 ~51 ~70 ~53 grass_block
fill ~52 ~60 ~53 ~58 ~67 ~53 stone
fill ~52 ~68 ~53 ~58 ~70 ~53 dirt
fill ~52 ~71 ~53 ~58 ~71 ~53 grass_block
fill ~59 ~60 ~53 ~61 ~66 ~53 stone
fill ~59 ~67 ~53 ~61 ~69 ~53 dirt
fill ~59 ~70 ~53 ~61 ~70 ~53 grass_block
fill ~62 ~60 ~53 ~63 ~65 ~53 stone
fill ~62 ~66 ~53 ~63 ~68 ~53 dirt
fill ~62 ~69 ~53 ~63 ~69 ~53 grass_block
fill ~48 ~60 ~54 ~48 ~66 ~54 stone
fill ~48 ~67 ~54 ~48 ~69 ~54 dirt
fill ~48 ~70 ~54 ~48 ~70 ~54 grass_block
fill ~49 ~60 ~54 ~49 ~65 ~54 stone
fill ~49 ~66 ~54 ~49 ~68 ~54 dirt
fill ~49 ~69 ~54 ~49 ~69 ~54 grass_block
fill ~50 ~60 ~54 ~52 ~66 ~54 stone
fill ~50 ~67 ~54 ~52 ~69 ~54 dirt
fill ~50 ~70 ~54 ~52 ~70 ~54 grass_block
fill ~53 ~60 ~54 ~60 ~67 ~54 stone
fill ~53 ~68 ~54 ~60 ~70 ~54 dirt
fill ~53 ~71 ~54 ~60 ~71 ~54 grass_block
fill ~61 ~60 ~54 ~63 ~66 ~54 stone
fill ~61 ~67 ~54 ~63 ~69 ~54 dirt
fill ~61 ~70 ~54 ~63 ~70 ~54 grass_block
fill ~48 ~60 ~55 ~51 ~65 ~55 stone
fill ~48 ~66 ~55 ~51 ~68 ~55 dirt
fill ~48 ~69 ~55 ~51 ~69 ~55 grass_block
fill ~52 ~60 ~55 ~54 ~66 ~55 stone
fill ~52 ~67 ~55 ~54 ~69 ~55 dirt
fill ~52 ~70 ~55 ~54 ~70 ~55 grass_block
fill ~55 ~60 ~55 ~62 ~67 ~55 stone
fill ~55 ~68 ~55 ~62 ~70 ~55 dirt
fill ~55 ~71 ~55 ~62 ~71 ~55 grass_block
fill ~63 ~60 ~55 ~63 ~66 ~55 stone
fill ~63 ~67 ~55 ~63 ~69 ~55 dirt
fill ~63 ~70 ~55 ~63 ~70 ~55 grass_block
fill ~48 ~60 ~56 ~52 ~65 ~56 stone
fill ~48 ~66 ~56 ~52 ~68 ~56 dirt
fill ~48 ~69 ~56 ~52 ~69 ~56 grass_block
fill ~53 ~60 ~56 ~55 ~66 ~56 stone
fill ~53 ~67 ~56 ~55 ~69 ~56 dirt
fill ~53 ~70 ~56 ~55 ~70 ~56 grass_block
fill ~56 ~60 ~56 ~63 ~67 ~56 stone
fill ~56 ~68 ~56 ~63 ~70 ~56 dirt
fill ~56 ~71 ~56 ~63 ~71 ~56 grass_block
fill ~48 ~60 ~57 ~48 ~64 ~57 stone
fill ~48 ~65 ~57 ~48 ~67 ~57 dirt
fill ~48 ~68 ~57 ~48 ~68 ~57 grass_block
fill ~49 ~60 ~57 ~53 ~65 ~57 stone
fill ~49 ~66 ~57 ~53 ~68 ~57 dirt
fill ~49 ~69 ~57 ~53 ~69 ~57 grass_block
fill ~54 ~60 ~57 ~56 ~66 ~57 stone
fill ~54 ~67 ~57 ~56 ~69 ~57 dirt
fill ~54 ~70 ~57 ~56 ~70 ~57 grass_block
fill ~57 ~60 ~57 ~63 ~67 ~57 stone
fill ~57 ~68 ~57 ~63 ~70 ~57 dirt
fill ~57 ~71 ~57 ~63 ~71 ~57 grass_block
fill ~48 ~60 ~58 ~48 ~64 ~58 stone
fill ~48 ~65 ~58 ~48 ~67 ~58 dirt
fill ~48 ~68 ~58 ~48 ~68 ~58 grass_block
fill ~49 ~60 ~58 ~55 ~65 ~58 stone
fill ~49 ~66 ~58 ~55 ~68 ~58 dirt
fill ~49 ~69 ~58 ~55 ~69 ~58 grass_block
fill ~56 ~60 ~58 ~61 ~66 ~58 stone
fill ~56 ~67 ~58 ~61 ~69 ~58 dirt
fill ~56 ~70 ~58 ~61 ~70 ~58 grass_block
fill ~62 ~60 ~58 ~63 ~67 ~58 stone
fill ~62 ~68 ~58 ~63 ~70 ~58 dirt
fill ~62 ~71 ~58 ~63 ~71 ~58 grass_block
fill ~48 ~60 ~59 ~50 ~64 ~59 stone
fill ~48 ~65 ~59 ~50 ~67 ~59 dirt
fill ~48 ~68 ~59 ~50 ~68 ~59 grass_block
fill ~51 ~60 ~59 ~56 ~65 ~59 stone
fill ~51 ~66 ~59 ~56 ~68 ~59 dirt
fill ~51 ~69 ~59 ~56 ~69 ~59 grass_block
fill ~57 ~60 ~59 ~63 ~66 ~59 stone
fill ~57 ~67 ~59 ~63 ~69 ~59 dirt
fill ~57 ~70 ~59 ~63 ~70 ~59 grass_block
fill ~48 ~60 ~60 ~53 ~64 ~60 stone
fill ~48 ~65 ~60 ~53 ~67 ~60 dirt
fill ~48 ~68 ~60 ~53 ~68 ~60 grass_block
fill ~54 ~60 ~60 ~57 ~65 ~60 stone
fill ~54 ~66 ~60 ~57 ~68 ~60 dirt
fill ~54 ~69 ~60 ~57 ~69 ~60 grass_block
fill ~58 ~60 ~60 ~63 ~66 ~60 stone
fill ~58 ~67 ~60 ~63 ~69 ~60 dirt
fill ~58 ~70 ~60 ~63 ~70 ~60 grass_block
fill ~48 ~60 ~61 ~54 ~64 ~61 stone
fill ~48 ~65 ~61 ~54 ~67 ~61 dirt
fill ~48 ~68 ~61 ~54 ~68 ~61 grass_block
fill ~55 ~60 ~61 ~63 ~65 ~61 stone
fill ~55 ~66 ~61 ~63 ~68 ~61 dirt
fill ~55 ~69 ~61 ~63 ~69 ~61 grass_block
fill ~48 ~60 ~62 ~56 ~64 ~62 stone
fill ~48 ~65 ~62 ~56 ~67 ~62 dirt
fill ~48 ~68 ~62 ~56 ~68 ~62 grass_block
fill ~57 ~60 ~62 ~63 ~65 ~62 stone
fill ~57 ~66 ~62 ~63 ~68 ~62 dirt
fill ~57 ~69 ~62 ~63 ~69 ~62 grass_block
fill ~48 ~60 ~63 ~61 ~64 ~63 stone
fill ~48 ~65 ~63 ~61 ~67 ~63 dirt
fill ~48 ~68 ~63 ~61 ~68 ~63 grass_block
fill ~62 ~60 ~63 ~63 ~65 ~63 stone
fill ~62 ~66 ~63 ~63 ~68 ~63 dirt
fill ~62 ~69 ~63 ~63 ~69 ~63 grass_block