fill ~288 ~60 ~64 ~289 ~61 ~64 stone
fill ~288 ~62 ~64 ~289 ~64 ~64 dirt
fill ~288 ~65 ~64 ~289 ~65 ~64 grass_block
fill ~290 ~60 ~64 ~290 ~60 ~64 stone
fill ~290 ~61 ~64 ~290 ~63 ~64 dirt
fill ~290 ~64 ~64 ~290 ~64 ~64 grass_block
fill ~291 ~60 ~64 ~297 ~61 ~64 stone
fill ~291 ~62 ~64 ~297 ~64 ~64 dirt
fill ~291 ~65 ~64 ~297 ~65 ~64 grass_block
fill ~298 ~60 ~64 ~302 ~62 ~64 stone
fill ~298 ~63 ~64 ~302 ~65 ~64 dirt
fill ~298 ~66 ~64 ~302 ~66 ~64 grass_block
fill ~303 ~60 ~64 ~303 ~63 ~64 stone
fill ~303 ~64 ~64 ~303 ~66 ~64 dirt
fill ~303 ~67 ~64 ~303 ~67 ~64 grass_block
fill ~288 ~60 ~65 ~299 ~61 ~65 stone
fill ~288 ~62 ~65 ~299 ~64 ~65 dirt
fill ~288 ~65 ~65 ~299 ~65 ~65 grass_block
fill ~300 ~60 ~65 ~303 ~62 ~65 stone
fill ~300 ~63 ~65 ~303 ~65 ~65 dirt
fill ~300 ~66 ~65 ~303 ~66 ~65 grass_block
fill ~288 ~60 ~66 ~299 ~61 ~66 stone
fill ~288 ~62 ~66 ~299 ~64 ~66 dirt
fill ~288 ~65 ~66 ~299 ~65 ~66 grass_block
fill ~300 ~60 ~66 ~303 ~62 ~66 stone
fill ~300 ~63 ~66 ~303 ~65 ~66 dirt
fill ~300 ~66 ~66 ~303 ~66 ~66 grass_block
fill ~288 ~60 ~67 ~300 ~61 ~67 stone
fill ~288 ~62 ~67 ~300 ~64 ~67 dirt
fill ~288 ~65 ~67 ~300 ~65 ~67 grass_block
fill ~301 ~60 ~67 ~303 ~62 ~67 stone
fill ~301 ~63 ~67 ~303 ~65 ~67 dirt
fill ~301 ~66 ~67 ~303 ~66 ~67 grass_block
fill ~288 ~60 ~68 ~293 ~61 ~68 stone
fill ~288 ~62 ~68 ~293 ~64 ~68 dirt
fill ~288 ~65 ~68 ~293 ~65 ~68 grass_block
fill ~294 ~60 ~68 ~294 ~60 ~68 stone
fill ~294 ~61 ~68 ~294 ~63 ~68 dirt
fill ~294 ~64 ~68 ~294 ~64 ~68 grass_block
fill ~295 ~60 ~68 ~301 ~61 ~68 stone
fill ~295 ~62 ~68 ~301 ~64 ~68 dirt
fill ~295 ~65 ~68 ~301 ~65 ~68 grass_block
fill ~302 ~60 ~68 ~303 ~62 ~68 stone
fill ~302 ~63 ~68 ~303 ~65 ~68 dirt
fill ~302 ~66 ~68 ~303 ~66 ~68 grass_block
fill ~288 ~60 ~69 ~295 ~61 ~69 stone
fill ~288 ~62 ~69 ~295 ~64 ~69 dirt
fill ~288 ~65 ~69 ~295 ~65 ~69 grass_block
fill ~296 ~60 ~69 ~296 ~60 ~69 stone
fill ~296 ~61 ~69 ~296 ~63 ~69 dirt
fill ~296 ~64 ~69 ~296 ~64 ~69 grass_block
fill ~297 ~60 ~69 ~303 ~61 ~69 stone
fill ~297 ~62 ~69 ~303 ~64 ~69 dirt
fill ~297 ~65 ~69 ~303 ~65 ~69 grass_block
fill ~288 ~60 ~70 ~303 ~61 ~70 stone
fill ~288 ~62 ~70 ~303 ~64 ~70 dirt
fill ~288 ~65 ~70 ~303 ~65 ~70 grass_block
fill ~288 ~60 ~71 ~296 ~61 ~71 stone
fill ~288 ~62 ~71 ~296 ~64 ~71 dirt
fill ~288 ~65 ~71 ~296 ~65 ~71 grass_block
fill ~297 ~60 ~71 ~298 ~60 ~71 stone
fill ~297 ~61 ~71 ~298 ~63 ~71 dirt
fill ~297 ~64 ~71 ~298 ~64 ~71 grass_block
fill ~299 ~60 ~71 ~303 ~61 ~71 stone
fill ~299 ~62 ~71 ~303 ~64 ~71 dirt
fill ~299 ~65 ~71 ~303 ~65 ~71 grass_block
fill ~288 ~60 ~72 ~296 ~61 ~72 stone
fill ~288 ~62 ~72 ~296 ~64 ~72 dirt
fill ~288 ~65 ~72 ~296 ~65 ~72 grass_block
fill ~297 ~60 ~72 ~297 ~60 ~72 stone
fill ~297 ~61 ~72 ~297 ~63 ~72 dirt
fill ~297 ~64 ~72 ~297 ~64 ~72 grass_block
fill ~298 ~60 ~72 ~303 ~61 ~72 stone
fill ~298 ~62 ~72 ~303 ~64 ~72 dirt
fill ~298 ~65 ~72 ~303 ~65 ~72 grass_block
fill ~288 ~60 ~73 ~298 ~61 ~73 stone
fill ~288 ~62 ~73 ~298 ~64 ~73 dirt
fill ~288 ~65 ~73 ~298 ~65 ~73 grass_block
fill ~299 ~60 ~73 ~299 ~60 ~73 stone
fill ~299 ~61 ~73 ~299 ~63 ~73 dirt
fill ~299 ~64 ~73 ~299 ~64 ~73 grass_block
fill ~300 ~60 ~73 ~303 ~61 ~73 stone
fill ~300 ~62 ~73 ~303 ~64 ~73 dirt
fill ~300 ~65 ~73 ~303 ~65 ~73 grass_block
fill ~288 ~60 ~74 ~298 ~61 ~74 stone
fill ~288 ~62 ~74 ~298 ~64 ~74 dirt
fill ~288 ~65 ~74 ~298 ~65 ~74 grass_block
fill ~299 ~60 ~74 ~300 ~60 ~74 stone
fill ~299 ~61 ~74 ~300 ~63 ~74 dirt
fill ~299 ~64 ~74 ~300 ~64 ~74 grass_block
fill ~301 ~60 ~74 ~301 ~61 ~74 stone
fill ~301 ~62 ~74 ~301 ~64 ~74 dirt
fill ~301 ~65 ~74 ~301 ~65 ~74 grass_block
fill ~302 ~60 ~74 ~303 ~60 ~74 stone
fill ~302 ~61 ~74 ~303 ~63 ~74 dirt
fill ~302 ~64 ~74 ~303 ~64 ~74 grass_block
fill ~288 ~60 ~75 ~299 ~61 ~75 stone
fill ~288 ~62 ~75 ~299 ~64 ~75 dirt
fill ~288 ~65 ~75 ~299 ~65 ~75 grass_block
fill ~300 ~60 ~75 ~300 ~60 ~75 stone
fill ~300 ~61 ~75 ~300 ~63 ~75 dirt
fill ~300 ~64 ~75 ~300 ~64 ~75 grass_block
fill ~301 ~60 ~75 ~303 ~61 ~75 stone
fill ~301 ~62 ~75 ~303 ~64 ~75 dirt
fill ~301 ~65 ~75 ~303 ~65 ~75 grass_block
fill ~288 ~60 ~76 ~288 ~62 ~76 stone
fill ~288 ~63 ~76 ~288 ~65 ~76 dirt
fill ~288 ~66 ~76 ~288 ~66 ~76 grass_block
fill ~289 ~60 ~76 ~297 ~61 ~76 stone
fill ~289 ~62 ~76 ~297 ~64 ~76 dirt
fill ~289 ~65 ~76 ~297 ~65 ~76 grass_block
fill ~298 ~60 ~76 ~298 ~60 ~76 stone
fill ~298 ~61 ~76 ~298 ~63 ~76 dirt
fill ~298 ~64 ~76 ~298 ~64 ~76 grass_block
fill ~299 ~60 ~76 ~300 ~61 ~76 stone
fill ~299 ~62 ~76 ~300 ~64 ~76 dirt
fill ~299 ~65 ~76 ~300 ~65 ~76 grass_block
fill ~301 ~60 ~76 ~302 ~60 ~76 stone
fill ~301 ~61 ~76 ~302 ~63 ~76 dirt
fill ~301 ~64 ~76 ~302 ~64 ~76 grass_block
fill ~303 ~60 ~76 ~303 ~61 ~76 stone
fill ~303 ~62 ~76 ~303 ~64 ~76 dirt
fill ~303 ~65 ~76 ~303 ~65 ~76 grass_block
fill ~288 ~60 ~77 ~288 ~62 ~77 stone
fill ~288 ~63 ~77 ~288 ~65 ~77 dirt
fill ~288 ~66 ~77 ~288 ~66 ~77 grass_block
fill ~289 ~60 ~77 ~302 ~61 ~77 stone
fill ~289 ~62 ~77 ~302 ~64 ~77 dirt
fill ~289 ~65 ~77 ~302 ~65 ~77 grass_block
fill ~303 ~60 ~77 ~303 ~60 ~77 stone
fill ~303 ~61 ~77 ~303 ~63 ~77 dirt
fill ~303 ~64 ~77 ~303 ~64 ~77 grass_block
fill ~288 ~60 ~78 ~288 ~62 ~78 stone
fill ~288 ~63 ~78 ~288 ~65 ~78 dirt
fill ~288 ~66 ~78 ~288 ~66 ~78 grass_block
fill ~289 ~60 ~78 ~299 ~61 ~78 stone
fill ~289 ~62 ~78 ~299 ~64 ~78 dirt
fill ~289 ~65 ~78 ~299 ~65 ~78 grass_block
fill ~300 ~60 ~78 ~300 ~60 ~78 stone
fill ~300 ~61 ~78 ~300 ~63 ~78 dirt
fill ~300 ~64 ~78 ~300 ~64 ~78 grass_block
fill ~301 ~60 ~78 ~301 ~61 ~78 stone
fill ~301 ~62 ~78 ~301 ~64 ~78 dirt
fill ~301 ~65 ~78 ~301 ~65 ~78 grass_block
fill ~302 ~60 ~78 ~303 ~60 ~78 stone
fill ~302 ~61 ~78 ~303 ~63 ~78 dirt
fill ~302 ~64 ~78 ~303 ~64 ~78 grass_block
fill ~288 ~60 ~79 ~290 ~62 ~79 stone
fill ~288 ~63 ~79 ~290 ~65 ~79 dirt
fill ~288 ~66 ~79 ~290 ~66 ~79 grass_block
fill ~291 ~60 ~79 ~299 ~61 ~79 stone
fill ~291 ~62 ~79 ~299 ~64 ~79 dirt
fill ~291 ~65 ~79 ~299 ~65 ~79 grass_block
fill ~300 ~60 ~79 ~300 ~60 ~79 stone
fill ~300 ~61 ~79 ~300 ~63 ~79 dirt
fill ~300 ~64 ~79 ~300 ~64 ~79 grass_block
fill ~301 ~60 ~79 ~303 ~61 ~79 stone
fill ~301 ~62 ~79 ~303 ~64 ~79 dirt
fill ~301 ~65 ~79 ~303 ~65 ~79 grass_block