fill ~224 ~60 ~32 ~239 ~61 ~32 stone
fill ~224 ~62 ~32 ~239 ~64 ~32 dirt
fill ~224 ~65 ~32 ~239 ~65 ~32 grass_block
fill ~224 ~60 ~33 ~239 ~61 ~33 stone
fill ~224 ~62 ~33 ~239 ~64 ~33 dirt
fill ~224 ~65 ~33 ~239 ~65 ~33 grass_block
fill ~224 ~60 ~34 ~239 ~61 ~34 stone
fill ~224 ~62 ~34 ~239 ~64 ~34 dirt
fill ~224 ~65 ~34 ~239 ~65 ~34 grass_block
fill ~224 ~60 ~35 ~239 ~61 ~35 stone
fill ~224 ~62 ~35 ~239 ~64 ~35 dirt
fill ~224 ~65 ~35 ~239 ~65 ~35 grass_block
fill ~224 ~60 ~36 ~239 ~61 ~36 stone
fill ~224 ~62 ~36 ~239 ~64 ~36 dirt
fill ~224 ~65 ~36 ~239 ~65 ~36 grass_block
fill ~224 ~60 ~37 ~239 ~61 ~37 stone
fill ~224 ~62 ~37 ~239 ~64 ~37 dirt
fill ~224 ~65 ~37 ~239 ~65 ~37 grass_block
fill ~224 ~60 ~38 ~239 ~61 ~38 stone
fill ~224 ~62 ~38 ~239 ~64 ~38 dirt
fill ~224 ~65 ~38 ~239 ~65 ~38 grass_block
fill ~224 ~60 ~39 ~239 ~61 ~39 stone
fill ~224 ~62 ~39 ~239 ~64 ~39 dirt
fill ~224 ~65 ~39 ~239 ~65 ~39 grass_block
fill ~224 ~60 ~40 ~239 ~61 ~40 stone
fill ~224 ~62 ~40 ~239 ~64 ~40 dirt
fill ~224 ~65 ~40 ~239 ~65 ~40 grass_block
fill ~224 ~60 ~41 ~239 ~61 ~41 stone
fill ~224 ~62 ~41 ~239 ~64 ~41 dirt
fill ~224 ~65 ~41 ~239 ~65 ~41 grass_block
fill ~224 ~60 ~42 ~239 ~61 ~42 stone
fill ~224 ~62 ~42 ~239 ~64 ~42 dirt
fill ~224 ~65 ~42 ~239 ~65 ~42 grass_block
fill ~224 ~60 ~43 ~226 ~62 ~43 stone
fill ~224 ~63 ~43 ~226 ~65 ~43 dirt
fill ~224 ~66 ~43 ~226 ~66 ~43 grass_block
fill ~227 ~60 ~43 ~239 ~61 ~43 stone
fill ~227 ~62 ~43 ~239 ~64 ~43 dirt
fill ~227 ~65 ~43 ~239 ~65 ~43 grass_block
fill ~224 ~60 ~44 ~228 ~62 ~44 stone
fill ~224 ~63 ~44 ~228 ~65 ~44 dirt
fill ~224 ~66 ~44 ~228 ~66 ~44 grass_block
fill ~229 ~60 ~44 ~239 ~61 ~44 stone
fill ~229 ~62 ~44 ~239 ~64 ~44 dirt
fill ~229 ~65 ~44 ~239 ~65 ~44 grass_block
fill ~224 ~60 ~45 ~224 ~63 ~45 stone
fill ~224 ~64 ~45 ~224 ~66 ~45 dirt
fill ~224 ~67 ~45 ~224 ~67 ~45 grass_block
fill ~225 ~60 ~45 ~231 ~62 ~45 stone
fill ~225 ~63 ~45 ~231 ~65 ~45 dirt
fill ~225 ~66 ~45 ~231 ~66 ~45 grass_block
fill ~232 ~60 ~45 ~239 ~61 ~45 stone
fill ~232 ~62 ~45 ~239 ~64 ~45 dirt
fill ~232 ~65 ~45 ~239 ~65 ~45 grass_block
fill ~224 ~60 ~46 ~226 ~63 ~46 stone
fill ~224 ~64 ~46 ~226 ~66 ~46 dirt
fill ~224 ~67 ~46 ~226 ~67 ~46 grass_block
fill ~227 ~60 ~46 ~231 ~62 ~46 stone
fill ~227 ~63 ~46 ~231 ~65 ~46 dirt
fill ~227 ~66 ~46 ~231 ~66 ~46 grass_block
fill ~232 ~60 ~46 ~239 ~61 ~46 stone
fill ~232 ~62 ~46 ~239 ~64 ~46 dirt
fill ~232 ~65 ~46 ~239 ~65 ~46 grass_block
fill ~224 ~60 ~47 ~226 ~63 ~47 stone
fill ~224 ~64 ~47 ~226 ~66 ~47 dirt
fill ~224 ~67 ~47 ~226 ~67 ~47 grass_block
fill ~227 ~60 ~47 ~233 ~62 ~47 stone
fill ~227 ~63 ~47 ~233 ~65 ~47 dirt
fill ~227 ~66 ~47 ~233 ~66 ~47 grass_block
fill ~234 ~60 ~47 ~239 ~61 ~47 stone
fill ~234 ~62 ~47 ~239 ~64 ~47 dirt
fill ~234 ~65 ~47 ~239 ~65 ~47 grass_block