fill ~32 ~60 ~96 ~34 ~63 ~96 stone
fill ~32 ~64 ~96 ~34 ~66 ~96 dirt
fill ~32 ~67 ~96 ~34 ~67 ~96 grass_block
fill ~35 ~60 ~96 ~38 ~64 ~96 stone
fill ~35 ~65 ~96 ~38 ~67 ~96 dirt
fill ~35 ~68 ~96 ~38 ~68 ~96 grass_block
fill ~39 ~60 ~96 ~40 ~65 ~96 stone
fill ~39 ~66 ~96 ~40 ~68 ~96 dirt
fill ~39 ~69 ~96 ~40 ~69 ~96 grass_block
fill ~41 ~60 ~96 ~44 ~66 ~96 stone
fill ~41 ~67 ~96 ~44 ~69 ~96 dirt
fill ~41 ~70 ~96 ~44 ~70 ~96 grass_block
fill ~45 ~60 ~96 ~47 ~65 ~96 stone
fill ~45 ~66 ~96 ~47 ~68 ~96 dirt
fill ~45 ~69 ~96 ~47 ~69 ~96 grass_block
fill ~32 ~60 ~97 ~36 ~63 ~97 stone
fill ~32 ~64 ~97 ~36 ~66 ~97 dirt
fill ~32 ~67 ~97 ~36 ~67 ~97 grass_block
fill ~37 ~60 ~97 ~39 ~64 ~97 stone
fill ~37 ~65 ~97 ~39 ~67 ~97 dirt
fill ~37 ~68 ~97 ~39 ~68 ~97 grass_block
fill ~40 ~60 ~97 ~42 ~65 ~97 stone
fill ~40 ~66 ~97 ~42 ~68 ~97 dirt
fill ~40 ~69 ~97 ~42 ~69 ~97 grass_block
fill ~43 ~60 ~97 ~45 ~66 ~97 stone
fill ~43 ~67 ~97 ~45 ~69 ~97 dirt
fill ~43 ~70 ~97 ~45 ~70 ~97 grass_block
fill ~46 ~60 ~97 ~47 ~65 ~97 stone
fill ~46 ~66 ~97 ~47 ~68 ~97 dirt
fill ~46 ~69 ~97 ~47 ~69 ~97 grass_block
fill ~32 ~60 ~98 ~37 ~63 ~98 stone
fill ~32 ~64 ~98 ~37 ~66 ~98 dirt
fill ~32 ~67 ~98 ~37 ~67 ~98 grass_block
fill ~38 ~60 ~98 ~40 ~64 ~98 stone
fill ~38 ~65 ~98 ~40 ~67 ~98 dirt
fill ~38 ~68 ~98 ~40 ~68 ~98 grass_block
fill ~41 ~60 ~98 ~47 ~65 ~98 stone
fill ~41 ~66 ~98 ~47 ~68 ~98 dirt
fill ~41 ~69 ~98 ~47 ~69 ~98 grass_block
fill ~32 ~60 ~99 ~37 ~63 ~99 stone
fill ~32 ~64 ~99 ~37 ~66 ~99 dirt
fill ~32 ~67 ~99 ~37 ~67 ~99 grass_block
fill ~38 ~60 ~99 ~42 ~64 ~99 stone
fill ~38 ~65 ~99 ~42 ~67 ~99 dirt
fill ~38 ~68 ~99 ~42 ~68 ~99 grass_block
fill ~43 ~60 ~99 ~47 ~65 ~99 stone
fill ~43 ~66 ~99 ~47 ~68 ~99 dirt
fill ~43 ~69 ~99 ~47 ~69 ~99 grass_block
fill ~32 ~60 ~100 ~38 ~63 ~100 stone
fill ~32 ~64 ~100 ~38 ~66 ~100 dirt
fill ~32 ~67 ~100 ~38 ~67 ~100 grass_block
fill ~39 ~60 ~100 ~46 ~64 ~100 stone
fill ~39 ~65 ~100 ~46 ~67 ~100 dirt
fill ~39 ~68 ~100 ~46 ~68 ~100 grass_block
fill ~47 ~60 ~100 ~47 ~65 ~100 stone
fill ~47 ~66 ~100 ~47 ~68 ~100 dirt
fill ~47 ~69 ~100 ~47 ~69 ~100 grass_block
fill ~32 ~60 ~101 ~32 ~64 ~101 stone
fill ~32 ~65 ~101 ~32 ~67 ~101 dirt
fill ~32 ~68 ~101 ~32 ~68 ~101 grass_block
fill ~33 ~60 ~101 ~40 ~63 ~101 stone
fill ~33 ~64 ~101 ~40 ~66 ~101 dirt
fill ~33 ~67 ~101 ~40 ~67 ~101 grass_block
fill ~41 ~60 ~101 ~47 ~64 ~101 stone
fill ~41 ~65 ~101 ~47 ~67 ~101 dirt
fill ~41 ~68 ~101 ~47 ~68 ~101 grass_block
fill ~32 ~60 ~102 ~33 ~64 ~102 stone
fill ~32 ~65 ~102 ~33 ~67 ~102 dirt
fill ~32 ~68 ~102 ~33 ~68 ~102 grass_block
fill ~34 ~60 ~102 ~46 ~63 ~102 stone
fill ~34 ~64 ~102 ~46 ~66 ~102 dirt
fill ~34 ~67 ~102 ~46 ~67 ~102 grass_block
fill ~47 ~60 ~102 ~47 ~64 ~102 stone
fill ~47 ~65 ~102 ~47 ~67 ~102 dirt
fill ~47 ~68 ~102 ~47 ~68 ~102 grass_block
fill ~32 ~60 ~103 ~34 ~64 ~103 stone
fill ~32 ~65 ~103 ~34 ~67 ~103 dirt
fill ~32 ~68 ~103 ~34 ~68 ~103 grass_block
fill ~35 ~60 ~103 ~47 ~63 ~103 stone
fill ~35 ~64 ~103 ~47 ~66 ~103 dirt
fill ~35 ~67 ~103 ~47 ~67 ~103 grass_block
fill ~32 ~60 ~104 ~34 ~64 ~104 stone
fill ~32 ~65 ~104 ~34 ~67 ~104 dirt
fill ~32 ~68 ~104 ~34 ~68 ~104 grass_block
fill ~35 ~60 ~104 ~47 ~63 ~104 stone
fill ~35 ~64 ~104 ~47 ~66 ~104 dirt
fill ~35 ~67 ~104 ~47 ~67 ~104 grass_block
fill ~32 ~60 ~105 ~39 ~64 ~105 stone
fill ~32 ~65 ~105 ~39 ~67 ~105 dirt
fill ~32 ~68 ~105 ~39 ~68 ~105 grass_block
fill ~40 ~60 ~105 ~47 ~63 ~105 stone
fill ~40 ~64 ~105 ~47 ~66 ~105 dirt
fill ~40 ~67 ~105 ~47 ~67 ~105 grass_block
fill ~32 ~60 ~106 ~41 ~64 ~106 stone
fill ~32 ~65 ~106 ~41 ~67 ~106 dirt
fill ~32 ~68 ~106 ~41 ~68 ~106 grass_block
fill ~42 ~60 ~106 ~47 ~63 ~106 stone
fill ~42 ~64 ~106 ~47 ~66 ~106 dirt
fill ~42 ~67 ~106 ~47 ~67 ~106 grass_block
fill ~32 ~60 ~107 ~34 ~65 ~107 stone
fill ~32 ~66 ~107 ~34 ~68 ~107 dirt
fill ~32 ~69 ~107 ~34 ~69 ~107 grass_block
fill ~35 ~60 ~107 ~36 ~64 ~107 stone
fill ~35 ~65 ~107 ~36 ~67 ~107 dirt
fill ~35 ~68 ~107 ~36 ~68 ~107 grass_block
fill ~37 ~60 ~107 ~37 ~65 ~107 stone
fill ~37 ~66 ~107 ~37 ~68 ~107 dirt
fill ~37 ~69 ~107 ~37 ~69 ~107 grass_block
fill ~38 ~60 ~107 ~42 ~64 ~107 stone
fill ~38 ~65 ~107 ~42 ~67 ~107 dirt
fill ~38 ~68 ~107 ~42 ~68 ~107 grass_block
fill ~43 ~60 ~107 ~47 ~63 ~107 stone
fill ~43 ~64 ~107 ~47 ~66 ~107 dirt
fill ~43 ~67 ~107 ~47 ~67 ~107 grass_block
fill ~32 ~60 ~108 ~34 ~66 ~108 stone
fill ~32 ~67 ~108 ~34 ~69 ~108 dirt
fill ~32 ~70 ~108 ~34 ~70 ~108 grass_block
fill ~35 ~60 ~108 ~39 ~65 ~108 stone
fill ~35 ~66 ~108 ~39 ~68 ~108 dirt
fill ~35 ~69 ~108 ~39 ~69 ~108 grass_block
fill ~40 ~60 ~108 ~44 ~64 ~108 stone
fill ~40 ~65 ~108 ~44 ~67 ~108 dirt
fill ~40 ~68 ~108 ~44 ~68 ~108 grass_block
fill ~45 ~60 ~108 ~47 ~63 ~108 stone
fill ~45 ~64 ~108 ~47 ~66 ~108 dirt
fill ~45 ~67 ~108 ~47 ~67 ~108 grass_block
fill ~32 ~60 ~109 ~33 ~67 ~109 stone
fill ~32 ~68 ~109 ~33 ~70 ~109 dirt
fill ~32 ~71 ~109 ~33 ~71 ~109 grass_block
fill ~34 ~60 ~109 ~36 ~66 ~109 stone
fill ~34 ~67 ~109 ~36 ~69 ~109 dirt
fill ~34 ~70 ~109 ~36 ~70 ~109 grass_block
fill ~37 ~60 ~109 ~41 ~65 ~109 stone
fill ~37 ~66 ~109 ~41 ~68 ~109 dirt
fill ~37 ~69 ~109 ~41 ~69 ~109 grass_block
fill ~42 ~60 ~109 ~45 ~64 ~109 stone
fill ~42 ~65 ~109 ~45 ~67 ~109 dirt
fill ~42 ~68 ~109 ~45 ~68 ~109 grass_block
fill ~46 ~60 ~109 ~47 ~63 ~109 stone
fill ~46 ~64 ~109 ~47 ~66 ~109 dirt
fill ~46 ~67 ~109 ~47 ~67 ~109 grass_block
fill ~32 ~60 ~110 ~33 ~68 ~110 stone
fill ~32 ~69 ~110 ~33 ~71 ~110 dirt
fill ~32 ~72 ~110 ~33 ~72 ~110 grass_block
fill ~34 ~60 ~110 ~35 ~67 ~110 stone
fill ~34 ~68 ~110 ~35 ~70 ~110 dirt
fill ~34 ~71 ~110 ~35 ~71 ~110 grass_block
fill ~36 ~60 ~110 ~38 ~66 ~110 stone
fill ~36 ~67 ~110 ~38 ~69 ~110 dirt
fill ~36 ~70 ~110 ~38 ~70 ~110 grass_block
fill ~39 ~60 ~110 ~42 ~65 ~110 stone
fill ~39 ~66 ~110 ~42 ~68 ~110 dirt
fill ~39 ~69 ~110 ~42 ~69 ~110 grass_block
fill ~43 ~60 ~110 ~47 ~64 ~110 stone
fill ~43 ~65 ~110 ~47 ~67 ~110 dirt
fill ~43 ~68 ~110 ~47 ~68 ~110 grass_block
fill ~32 ~60 ~111 ~34 ~68 ~111 stone
fill ~32 ~69 ~111 ~34 ~71 ~111 dirt
fill ~32 ~72 ~111 ~34 ~72 ~111 grass_block
fill ~35 ~60 ~111 ~35 ~67 ~111 stone
fill ~35 ~68 ~111 ~35 ~70 ~111 dirt
fill ~35 ~71 ~111 ~35 ~71 ~111 grass_block
fill ~36 ~60 ~111 ~41 ~66 ~111 stone
fill ~36 ~67 ~111 ~41 ~69 ~111 dirt
fill ~36 ~70 ~111 ~41 ~70 ~111 grass_block
fill ~42 ~60 ~111 ~44 ~65 ~111 stone
fill ~42 ~66 ~111 ~44 ~68 ~111 dirt
fill ~42 ~69 ~111 ~44 ~69 ~111 grass_block
fill ~45 ~60 ~111 ~47 ~64 ~111 stone
fill ~45 ~65 ~111 ~47 ~67 ~111 dirt
fill ~45 ~68 ~111 ~47 ~68 ~111 grass_block