fill ~256 ~60 ~80 ~262 ~64 ~80 stone
fill ~256 ~65 ~80 ~262 ~67 ~80 dirt
fill ~256 ~68 ~80 ~262 ~68 ~80 grass_block
fill ~263 ~60 ~80 ~265 ~63 ~80 stone
fill ~263 ~64 ~80 ~265 ~66 ~80 dirt
fill ~263 ~67 ~80 ~265 ~67 ~80 grass_block
fill ~266 ~60 ~80 ~269 ~62 ~80 stone
fill ~266 ~63 ~80 ~269 ~65 ~80 dirt
fill ~266 ~66 ~80 ~269 ~66 ~80 grass_block
fill ~270 ~60 ~80 ~271 ~63 ~80 stone
fill ~270 ~64 ~80 ~271 ~66 ~80 dirt
fill ~270 ~67 ~80 ~271 ~67 ~80 grass_block
fill ~256 ~60 ~81 ~262 ~64 ~81 stone
fill ~256 ~65 ~81 ~262 ~67 ~81 dirt
fill ~256 ~68 ~81 ~262 ~68 ~81 grass_block
fill ~263 ~60 ~81 ~264 ~63 ~81 stone
fill ~263 ~64 ~81 ~264 ~66 ~81 dirt
fill ~263 ~67 ~81 ~264 ~67 ~81 grass_block
fill ~265 ~60 ~81 ~267 ~62 ~81 stone
fill ~265 ~63 ~81 ~267 ~65 ~81 dirt
fill ~265 ~66 ~81 ~267 ~66 ~81 grass_block
fill ~268 ~60 ~81 ~271 ~63 ~81 stone
fill ~268 ~64 ~81 ~271 ~66 ~81 dirt
fill ~268 ~67 ~81 ~271 ~67 ~81 grass_block
fill ~256 ~60 ~82 ~257 ~65 ~82 stone
fill ~256 ~66 ~82 ~257 ~68 ~82 dirt
fill ~256 ~69 ~82 ~257 ~69 ~82 grass_block
fill ~258 ~60 ~82 ~263 ~64 ~82 stone
fill ~258 ~65 ~82 ~263 ~67 ~82 dirt
fill ~258 ~68 ~82 ~263 ~68 ~82 grass_block
fill ~264 ~60 ~82 ~265 ~63 ~82 stone
fill ~264 ~64 ~82 ~265 ~66 ~82 dirt
fill ~264 ~67 ~82 ~265 ~67 ~82 grass_block
fill ~266 ~60 ~82 ~267 ~62 ~82 stone
fill ~266 ~63 ~82 ~267 ~65 ~82 dirt
fill ~266 ~66 ~82 ~267 ~66 ~82 grass_block
fill ~268 ~60 ~82 ~271 ~63 ~82 stone
fill ~268 ~64 ~82 ~271 ~66 ~82 dirt
fill ~268 ~67 ~82 ~271 ~67 ~82 grass_block
fill ~256 ~60 ~83 ~259 ~65 ~83 stone
fill ~256 ~66 ~83 ~259 ~68 ~83 dirt
fill ~256 ~69 ~83 ~259 ~69 ~83 grass_block
fill ~260 ~60 ~83 ~263 ~64 ~83 stone
fill ~260 ~65 ~83 ~263 ~67 ~83 dirt
fill ~260 ~68 ~83 ~263 ~68 ~83 grass_block
fill ~264 ~60 ~83 ~271 ~63 ~83 stone
fill ~264 ~64 ~83 ~271 ~66 ~83 dirt
fill ~264 ~67 ~83 ~271 ~67 ~83 grass_block
fill ~256 ~60 ~84 ~260 ~65 ~84 stone
fill ~256 ~66 ~84 ~260 ~68 ~84 dirt
fill ~256 ~69 ~84 ~260 ~69 ~84 grass_block
fill ~261 ~60 ~84 ~263 ~64 ~84 stone
fill ~261 ~65 ~84 ~263 ~67 ~84 dirt
fill ~261 ~68 ~84 ~263 ~68 ~84 grass_block
fill ~264 ~60 ~84 ~268 ~63 ~84 stone
fill ~264 ~64 ~84 ~268 ~66 ~84 dirt
fill ~264 ~67 ~84 ~268 ~67 ~84 grass_block
fill ~269 ~60 ~84 ~269 ~64 ~84 stone
fill ~269 ~65 ~84 ~269 ~67 ~84 dirt
fill ~269 ~68 ~84 ~269 ~68 ~84 grass_block
fill ~270 ~60 ~84 ~271 ~63 ~84 stone
fill ~270 ~64 ~84 ~271 ~66 ~84 dirt
fill ~270 ~67 ~84 ~271 ~67 ~84 grass_block
fill ~256 ~60 ~85 ~261 ~65 ~85 stone
fill ~256 ~66 ~85 ~261 ~68 ~85 dirt
fill ~256 ~69 ~85 ~261 ~69 ~85 grass_block
fill ~262 ~60 ~85 ~263 ~64 ~85 stone
fill ~262 ~65 ~85 ~263 ~67 ~85 dirt
fill ~262 ~68 ~85 ~263 ~68 ~85 grass_block
fill ~264 ~60 ~85 ~268 ~63 ~85 stone
fill ~264 ~64 ~85 ~268 ~66 ~85 dirt
fill ~264 ~67 ~85 ~268 ~67 ~85 grass_block
fill ~269 ~60 ~85 ~271 ~64 ~85 stone
fill ~269 ~65 ~85 ~271 ~67 ~85 dirt
fill ~269 ~68 ~85 ~271 ~68 ~85 grass_block
fill ~256 ~60 ~86 ~262 ~65 ~86 stone
fill ~256 ~66 ~86 ~262 ~68 ~86 dirt
fill ~256 ~69 ~86 ~262 ~69 ~86 grass_block
fill ~263 ~60 ~86 ~264 ~64 ~86 stone
fill ~263 ~65 ~86 ~264 ~67 ~86 dirt
fill ~263 ~68 ~86 ~264 ~68 ~86 grass_block
fill ~265 ~60 ~86 ~267 ~63 ~86 stone
fill ~265 ~64 ~86 ~267 ~66 ~86 dirt
fill ~265 ~67 ~86 ~267 ~67 ~86 grass_block
fill ~268 ~60 ~86 ~271 ~64 ~86 stone
fill ~268 ~65 ~86 ~271 ~67 ~86 dirt
fill ~268 ~68 ~86 ~271 ~68 ~86 grass_block
fill ~256 ~60 ~87 ~261 ~65 ~87 stone
fill ~256 ~66 ~87 ~261 ~68 ~87 dirt
fill ~256 ~69 ~87 ~261 ~69 ~87 grass_block
fill ~262 ~60 ~87 ~264 ~64 ~87 stone
fill ~262 ~65 ~87 ~264 ~67 ~87 dirt
fill ~262 ~68 ~87 ~264 ~68 ~87 grass_block
fill ~265 ~60 ~87 ~266 ~63 ~87 stone
fill ~265 ~64 ~87 ~266 ~66 ~87 dirt
fill ~265 ~67 ~87 ~266 ~67 ~87 grass_block
fill ~267 ~60 ~87 ~271 ~64 ~87 stone
fill ~267 ~65 ~87 ~271 ~67 ~87 dirt
fill ~267 ~68 ~87 ~271 ~68 ~87 grass_block
fill ~256 ~60 ~88 ~257 ~66 ~88 stone
fill ~256 ~67 ~88 ~257 ~69 ~88 dirt
fill ~256 ~70 ~88 ~257 ~70 ~88 grass_block
fill ~258 ~60 ~88 ~261 ~65 ~88 stone
fill ~258 ~66 ~88 ~261 ~68 ~88 dirt
fill ~258 ~69 ~88 ~261 ~69 ~88 grass_block
fill ~262 ~60 ~88 ~271 ~64 ~88 stone
fill ~262 ~65 ~88 ~271 ~67 ~88 dirt
fill ~262 ~68 ~88 ~271 ~68 ~88 grass_block
fill ~256 ~60 ~89 ~258 ~66 ~89 stone
fill ~256 ~67 ~89 ~258 ~69 ~89 dirt
fill ~256 ~70 ~89 ~258 ~70 ~89 grass_block
fill ~259 ~60 ~89 ~264 ~65 ~89 stone
fill ~259 ~66 ~89 ~264 ~68 ~89 dirt
fill ~259 ~69 ~89 ~264 ~69 ~89 grass_block
fill ~265 ~60 ~89 ~271 ~64 ~89 stone
fill ~265 ~65 ~89 ~271 ~67 ~89 dirt
fill ~265 ~68 ~89 ~271 ~68 ~89 grass_block
fill ~256 ~60 ~90 ~256 ~65 ~90 stone
fill ~256 ~66 ~90 ~256 ~68 ~90 dirt
fill ~256 ~69 ~90 ~256 ~69 ~90 grass_block
fill ~257 ~60 ~90 ~258 ~66 ~90 stone
fill ~257 ~67 ~90 ~258 ~69 ~90 dirt
fill ~257 ~70 ~90 ~258 ~70 ~90 grass_block
fill ~259 ~60 ~90 ~265 ~65 ~90 stone
fill ~259 ~66 ~90 ~265 ~68 ~90 dirt
fill ~259 ~69 ~90 ~265 ~69 ~90 grass_block
fill ~266 ~60 ~90 ~271 ~64 ~90 stone
fill ~266 ~65 ~90 ~271 ~67 ~90 dirt
fill ~266 ~68 ~90 ~271 ~68 ~90 grass_block
fill ~256 ~60 ~91 ~256 ~65 ~91 stone
fill ~256 ~66 ~91 ~256 ~68 ~91 dirt
fill ~256 ~69 ~91 ~256 ~69 ~91 grass_block
fill ~257 ~60 ~91 ~261 ~66 ~91 stone
fill ~257 ~67 ~91 ~261 ~69 ~91 dirt
fill ~257 ~70 ~91 ~261 ~70 ~91 grass_block
fill ~262 ~60 ~91 ~268 ~65 ~91 stone
fill ~262 ~66 ~91 ~268 ~68 ~91 dirt
fill ~262 ~69 ~91 ~268 ~69 ~91 grass_block
fill ~269 ~60 ~91 ~271 ~64 ~91 stone
fill ~269 ~65 ~91 ~271 ~67 ~91 dirt
fill ~269 ~68 ~91 ~271 ~68 ~91 grass_block
fill ~256 ~60 ~92 ~257 ~65 ~92 stone
fill ~256 ~66 ~92 ~257 ~68 ~92 dirt
fill ~256 ~69 ~92 ~257 ~69 ~92 grass_block
fill ~258 ~60 ~92 ~261 ~66 ~92 stone
fill ~258 ~67 ~92 ~261 ~69 ~92 dirt
fill ~258 ~70 ~92 ~261 ~70 ~92 grass_block
fill ~262 ~60 ~92 ~271 ~65 ~92 stone
fill ~262 ~66 ~92 ~271 ~68 ~92 dirt
fill ~262 ~69 ~92 ~271 ~69 ~92 grass_block
fill ~256 ~60 ~93 ~257 ~65 ~93 stone
fill ~256 ~66 ~93 ~257 ~68 ~93 dirt
fill ~256 ~69 ~93 ~257 ~69 ~93 grass_block
fill ~258 ~60 ~93 ~262 ~66 ~93 stone
fill ~258 ~67 ~93 ~262 ~69 ~93 dirt
fill ~258 ~70 ~93 ~262 ~70 ~93 grass_block
fill ~263 ~60 ~93 ~271 ~65 ~93 stone
fill ~263 ~66 ~93 ~271 ~68 ~93 dirt
fill ~263 ~69 ~93 ~271 ~69 ~93 grass_block
fill ~256 ~60 ~94 ~256 ~64 ~94 stone
fill ~256 ~65 ~94 ~256 ~67 ~94 dirt
fill ~256 ~68 ~94 ~256 ~68 ~94 grass_block
fill ~257 ~60 ~94 ~259 ~65 ~94 stone
fill ~257 ~66 ~94 ~259 ~68 ~94 dirt
fill ~257 ~69 ~94 ~259 ~69 ~94 grass_block
fill ~260 ~60 ~94 ~261 ~66 ~94 stone
fill ~260 ~67 ~94 ~261 ~69 ~94 dirt
fill ~260 ~70 ~94 ~261 ~70 ~94 grass_block
fill ~262 ~60 ~94 ~271 ~65 ~94 stone
fill ~262 ~66 ~94 ~271 ~68 ~94 dirt
fill ~262 ~69 ~94 ~271 ~69 ~94 grass_block
fill ~256 ~60 ~95 ~256 ~64 ~95 stone
fill ~256 ~65 ~95 ~256 ~67 ~95 dirt
fill ~256 ~68 ~95 ~256 ~68 ~95 grass_block
fill ~257 ~60 ~95 ~260 ~65 ~95 stone
fill ~257 ~66 ~95 ~260 ~68 ~95 dirt
fill ~257 ~69 ~95 ~260 ~69 ~95 grass_block
fill ~261 ~60 ~95 ~261 ~66 ~95 stone
fill ~261 ~67 ~95 ~261 ~69 ~95 dirt
fill ~261 ~70 ~95 ~261 ~70 ~95 grass_block
fill ~262 ~60 ~95 ~271 ~65 ~95 stone
fill ~262 ~66 ~95 ~271 ~68 ~95 dirt
fill ~262 ~69 ~95 ~271 ~69 ~95 grass_block