fill ~160 ~60 ~48 ~167 ~67 ~48 stone
fill ~160 ~68 ~48 ~167 ~70 ~48 dirt
fill ~160 ~71 ~48 ~167 ~71 ~48 grass_block
fill ~168 ~60 ~48 ~175 ~66 ~48 stone
fill ~168 ~67 ~48 ~175 ~69 ~48 dirt
fill ~168 ~70 ~48 ~175 ~70 ~48 grass_block
fill ~160 ~60 ~49 ~167 ~67 ~49 stone
fill ~160 ~68 ~49 ~167 ~70 ~49 dirt
fill ~160 ~71 ~49 ~167 ~71 ~49 grass_block
fill ~168 ~60 ~49 ~171 ~66 ~49 stone
fill ~168 ~67 ~49 ~171 ~69 ~49 dirt
fill ~168 ~70 ~49 ~171 ~70 ~49 grass_block
fill ~172 ~60 ~49 ~175 ~67 ~49 stone
fill ~172 ~68 ~49 ~175 ~70 ~49 dirt
fill ~172 ~71 ~49 ~175 ~71 ~49 grass_block
fill ~160 ~60 ~50 ~168 ~67 ~50 stone
fill ~160 ~68 ~50 ~168 ~70 ~50 dirt
fill ~160 ~71 ~50 ~168 ~71 ~50 grass_block
fill ~169 ~60 ~50 ~171 ~66 ~50 stone
fill ~169 ~67 ~50 ~171 ~69 ~50 dirt
fill ~169 ~70 ~50 ~171 ~70 ~50 grass_block
fill ~172 ~60 ~50 ~175 ~67 ~50 stone
fill ~172 ~68 ~50 ~175 ~70 ~50 dirt
fill ~172 ~71 ~50 ~175 ~71 ~50 grass_block
fill ~160 ~60 ~51 ~169 ~67 ~51 stone
fill ~160 ~68 ~51 ~169 ~70 ~51 dirt
fill ~160 ~71 ~51 ~169 ~71 ~51 grass_block
fill ~170 ~60 ~51 ~170 ~66 ~51 stone
fill ~170 ~67 ~51 ~170 ~69 ~51 dirt
fill ~170 ~70 ~51 ~170 ~70 ~51 grass_block
fill ~171 ~60 ~51 ~175 ~67 ~51 stone
fill ~171 ~68 ~51 ~175 ~70 ~51 dirt
fill ~171 ~71 ~51 ~175 ~71 ~51 grass_block
fill ~160 ~60 ~52 ~175 ~67 ~52 stone
fill ~160 ~68 ~52 ~175 ~70 ~52 dirt
fill ~160 ~71 ~52 ~175 ~71 ~52 grass_block
fill ~160 ~60 ~53 ~175 ~67 ~53 stone
fill ~160 ~68 ~53 ~175 ~70 ~53 dirt
fill ~160 ~71 ~53 ~175 ~71 ~53 grass_block
fill ~160 ~60 ~54 ~175 ~67 ~54 stone
fill ~160 ~68 ~54 ~175 ~70 ~54 dirt
fill ~160 ~71 ~54 ~175 ~71 ~54 grass_block
fill ~160 ~60 ~55 ~175 ~67 ~55 stone
fill ~160 ~68 ~55 ~175 ~70 ~55 dirt
fill ~160 ~71 ~55 ~175 ~71 ~55 grass_block
fill ~160 ~60 ~56 ~161 ~66 ~56 stone
fill ~160 ~67 ~56 ~161 ~69 ~56 dirt
fill ~160 ~70 ~56 ~161 ~70 ~56 grass_block
fill ~162 ~60 ~56 ~175 ~67 ~56 stone
fill ~162 ~68 ~56 ~175 ~70 ~56 dirt
fill ~162 ~71 ~56 ~175 ~71 ~56 grass_block
fill ~160 ~60 ~57 ~163 ~66 ~57 stone
fill ~160 ~67 ~57 ~163 ~69 ~57 dirt
fill ~160 ~70 ~57 ~163 ~70 ~57 grass_block
fill ~164 ~60 ~57 ~175 ~67 ~57 stone
fill ~164 ~68 ~57 ~175 ~70 ~57 dirt
fill ~164 ~71 ~57 ~175 ~71 ~57 grass_block
fill ~160 ~60 ~58 ~160 ~65 ~58 stone
fill ~160 ~66 ~58 ~160 ~68 ~58 dirt
fill ~160 ~69 ~58 ~160 ~69 ~58 grass_block
fill ~161 ~60 ~58 ~165 ~66 ~58 stone
fill ~161 ~67 ~58 ~165 ~69 ~58 dirt
fill ~161 ~70 ~58 ~165 ~70 ~58 grass_block
fill ~166 ~60 ~58 ~175 ~67 ~58 stone
fill ~166 ~68 ~58 ~175 ~70 ~58 dirt
fill ~166 ~71 ~58 ~175 ~71 ~58 grass_block
fill ~160 ~60 ~59 ~162 ~65 ~59 stone
fill ~160 ~66 ~59 ~162 ~68 ~59 dirt
fill ~160 ~69 ~59 ~162 ~69 ~59 grass_block
fill ~163 ~60 ~59 ~166 ~66 ~59 stone
fill ~163 ~67 ~59 ~166 ~69 ~59 dirt
fill ~163 ~70 ~59 ~166 ~70 ~59 grass_block
fill ~167 ~60 ~59 ~175 ~67 ~59 stone
fill ~167 ~68 ~59 ~175 ~70 ~59 dirt
fill ~167 ~71 ~59 ~175 ~71 ~59 grass_block
fill ~160 ~60 ~60 ~164 ~65 ~60 stone
fill ~160 ~66 ~60 ~164 ~68 ~60 dirt
fill ~160 ~69 ~60 ~164 ~69 ~60 grass_block
fill ~165 ~60 ~60 ~167 ~66 ~60 stone
fill ~165 ~67 ~60 ~167 ~69 ~60 dirt
fill ~165 ~70 ~60 ~167 ~70 ~60 grass_block
fill ~168 ~60 ~60 ~175 ~67 ~60 stone
fill ~168 ~68 ~60 ~175 ~70 ~60 dirt
fill ~168 ~71 ~60 ~175 ~71 ~60 grass_block
fill ~160 ~60 ~61 ~166 ~65 ~61 stone
fill ~160 ~66 ~61 ~166 ~68 ~61 dirt
fill ~160 ~69 ~61 ~166 ~69 ~61 grass_block
fill ~167 ~60 ~61 ~168 ~66 ~61 stone
fill ~167 ~67 ~61 ~168 ~69 ~61 dirt
fill ~167 ~70 ~61 ~168 ~70 ~61 grass_block
fill ~169 ~60 ~61 ~175 ~67 ~61 stone
fill ~169 ~68 ~61 ~175 ~70 ~61 dirt
fill ~169 ~71 ~61 ~175 ~71 ~61 grass_block
fill ~160 ~60 ~62 ~160 ~66 ~62 stone
fill ~160 ~67 ~62 ~160 ~69 ~62 dirt
fill ~160 ~70 ~62 ~160 ~70 ~62 grass_block
fill ~161 ~60 ~62 ~167 ~65 ~62 stone
fill ~161 ~66 ~62 ~167 ~68 ~62 dirt
fill ~161 ~69 ~62 ~167 ~69 ~62 grass_block
fill ~168 ~60 ~62 ~170 ~66 ~62 stone
fill ~168 ~67 ~62 ~170 ~69 ~62 dirt
fill ~168 ~70 ~62 ~170 ~70 ~62 grass_block
fill ~171 ~60 ~62 ~175 ~67 ~62 stone
fill ~171 ~68 ~62 ~175 ~70 ~62 dirt
fill ~171 ~71 ~62 ~175 ~71 ~62 grass_block
fill ~160 ~60 ~63 ~160 ~66 ~63 stone
fill ~160 ~67 ~63 ~160 ~69 ~63 dirt
fill ~160 ~70 ~63 ~160 ~70 ~63 grass_block
fill ~161 ~60 ~63 ~163 ~65 ~63 stone
fill ~161 ~66 ~63 ~163 ~68 ~63 dirt
fill ~161 ~69 ~63 ~163 ~69 ~63 grass_block
fill ~164 ~60 ~63 ~164 ~64 ~63 stone
fill ~164 ~65 ~63 ~164 ~67 ~63 dirt
fill ~164 ~68 ~63 ~164 ~68 ~63 grass_block
fill ~165 ~60 ~63 ~168 ~65 ~63 stone
fill ~165 ~66 ~63 ~168 ~68 ~63 dirt
fill ~165 ~69 ~63 ~168 ~69 ~63 grass_block
fill ~169 ~60 ~63 ~171 ~66 ~63 stone
fill ~169 ~67 ~63 ~171 ~69 ~63 dirt
fill ~169 ~70 ~63 ~171 ~70 ~63 grass_block
fill ~172 ~60 ~63 ~173 ~67 ~63 stone
fill ~172 ~68 ~63 ~173 ~70 ~63 dirt
fill ~172 ~71 ~63 ~173 ~71 ~63 grass_block
fill ~174 ~60 ~63 ~175 ~66 ~63 stone
fill ~174 ~67 ~63 ~175 ~69 ~63 dirt
fill ~174 ~70 ~63 ~175 ~70 ~63 grass_block