fill ~112 ~60 ~0 ~113 ~64 ~0 stone
fill ~112 ~65 ~0 ~113 ~67 ~0 dirt
fill ~112 ~68 ~0 ~113 ~68 ~0 grass_block
fill ~114 ~60 ~0 ~115 ~65 ~0 stone
fill ~114 ~66 ~0 ~115 ~68 ~0 dirt
fill ~114 ~69 ~0 ~115 ~69 ~0 grass_block
fill ~116 ~60 ~0 ~118 ~64 ~0 stone
fill ~116 ~65 ~0 ~118 ~67 ~0 dirt
fill ~116 ~68 ~0 ~118 ~68 ~0 grass_block
fill ~119 ~60 ~0 ~126 ~63 ~0 stone
fill ~119 ~64 ~0 ~126 ~66 ~0 dirt
fill ~119 ~67 ~0 ~126 ~67 ~0 grass_block
fill ~127 ~60 ~0 ~127 ~62 ~0 stone
fill ~127 ~63 ~0 ~127 ~65 ~0 dirt
fill ~127 ~66 ~0 ~127 ~66 ~0 grass_block
fill ~112 ~60 ~1 ~116 ~65 ~1 stone
fill ~112 ~66 ~1 ~116 ~68 ~1 dirt
fill ~112 ~69 ~1 ~116 ~69 ~1 grass_block
fill ~117 ~60 ~1 ~122 ~64 ~1 stone
fill ~117 ~65 ~1 ~122 ~67 ~1 dirt
fill ~117 ~68 ~1 ~122 ~68 ~1 grass_block
fill ~123 ~60 ~1 ~127 ~63 ~1 stone
fill ~123 ~64 ~1 ~127 ~66 ~1 dirt
fill ~123 ~67 ~1 ~127 ~67 ~1 grass_block
fill ~112 ~60 ~2 ~114 ~65 ~2 stone
fill ~112 ~66 ~2 ~114 ~68 ~2 dirt
fill ~112 ~69 ~2 ~114 ~69 ~2 grass_block
fill ~115 ~60 ~2 ~116 ~66 ~2 stone
fill ~115 ~67 ~2 ~116 ~69 ~2 dirt
fill ~115 ~70 ~2 ~116 ~70 ~2 grass_block
fill ~117 ~60 ~2 ~121 ~65 ~2 stone
fill ~117 ~66 ~2 ~121 ~68 ~2 dirt
fill ~117 ~69 ~2 ~121 ~69 ~2 grass_block
fill ~122 ~60 ~2 ~125 ~64 ~2 stone
fill ~122 ~65 ~2 ~125 ~67 ~2 dirt
fill ~122 ~68 ~2 ~125 ~68 ~2 grass_block
fill ~126 ~60 ~2 ~127 ~63 ~2 stone
fill ~126 ~64 ~2 ~127 ~66 ~2 dirt
fill ~126 ~67 ~2 ~127 ~67 ~2 grass_block
fill ~112 ~60 ~3 ~114 ~65 ~3 stone
fill ~112 ~66 ~3 ~114 ~68 ~3 dirt
fill ~112 ~69 ~3 ~114 ~69 ~3 grass_block
fill ~115 ~60 ~3 ~120 ~66 ~3 stone
fill ~115 ~67 ~3 ~120 ~69 ~3 dirt
fill ~115 ~70 ~3 ~120 ~70 ~3 grass_block
fill ~121 ~60 ~3 ~123 ~65 ~3 stone
fill ~121 ~66 ~3 ~123 ~68 ~3 dirt
fill ~121 ~69 ~3 ~123 ~69 ~3 grass_block
fill ~124 ~60 ~3 ~127 ~64 ~3 stone
fill ~124 ~65 ~3 ~127 ~67 ~3 dirt
fill ~124 ~68 ~3 ~127 ~68 ~3 grass_block
fill ~112 ~60 ~4 ~116 ~65 ~4 stone
fill ~112 ~66 ~4 ~116 ~68 ~4 dirt
fill ~112 ~69 ~4 ~116 ~69 ~4 grass_block
fill ~117 ~60 ~4 ~123 ~66 ~4 stone
fill ~117 ~67 ~4 ~123 ~69 ~4 dirt
fill ~117 ~70 ~4 ~123 ~70 ~4 grass_block
fill ~124 ~60 ~4 ~127 ~65 ~4 stone
fill ~124 ~66 ~4 ~127 ~68 ~4 dirt
fill ~124 ~69 ~4 ~127 ~69 ~4 grass_block
fill ~112 ~60 ~5 ~119 ~65 ~5 stone
fill ~112 ~66 ~5 ~119 ~68 ~5 dirt
fill ~112 ~69 ~5 ~119 ~69 ~5 grass_block
fill ~120 ~60 ~5 ~122 ~66 ~5 stone
fill ~120 ~67 ~5 ~122 ~69 ~5 dirt
fill ~120 ~70 ~5 ~122 ~70 ~5 grass_block
fill ~123 ~60 ~5 ~127 ~65 ~5 stone
fill ~123 ~66 ~5 ~127 ~68 ~5 dirt
fill ~123 ~69 ~5 ~127 ~69 ~5 grass_block
fill ~112 ~60 ~6 ~114 ~64 ~6 stone
fill ~112 ~65 ~6 ~114 ~67 ~6 dirt
fill ~112 ~68 ~6 ~114 ~68 ~6 grass_block
fill ~115 ~60 ~6 ~127 ~65 ~6 stone
fill ~115 ~66 ~6 ~127 ~68 ~6 dirt
fill ~115 ~69 ~6 ~127 ~69 ~6 grass_block
fill ~112 ~60 ~7 ~117 ~64 ~7 stone
fill ~112 ~65 ~7 ~117 ~67 ~7 dirt
fill ~112 ~68 ~7 ~117 ~68 ~7 grass_block
fill ~118 ~60 ~7 ~127 ~65 ~7 stone
fill ~118 ~66 ~7 ~127 ~68 ~7 dirt
fill ~118 ~69 ~7 ~127 ~69 ~7 grass_block
fill ~112 ~60 ~8 ~113 ~65 ~8 stone
fill ~112 ~66 ~8 ~113 ~68 ~8 dirt
fill ~112 ~69 ~8 ~113 ~69 ~8 grass_block
fill ~114 ~60 ~8 ~121 ~64 ~8 stone
fill ~114 ~65 ~8 ~121 ~67 ~8 dirt
fill ~114 ~68 ~8 ~121 ~68 ~8 grass_block
fill ~122 ~60 ~8 ~127 ~65 ~8 stone
fill ~122 ~66 ~8 ~127 ~68 ~8 dirt
fill ~122 ~69 ~8 ~127 ~69 ~8 grass_block
fill ~112 ~60 ~9 ~113 ~65 ~9 stone
fill ~112 ~66 ~9 ~113 ~68 ~9 dirt
fill ~112 ~69 ~9 ~113 ~69 ~9 grass_block
fill ~114 ~60 ~9 ~114 ~64 ~9 stone
fill ~114 ~65 ~9 ~114 ~67 ~9 dirt
fill ~114 ~68 ~9 ~114 ~68 ~9 grass_block
fill ~115 ~60 ~9 ~115 ~65 ~9 stone
fill ~115 ~66 ~9 ~115 ~68 ~9 dirt
fill ~115 ~69 ~9 ~115 ~69 ~9 grass_block
fill ~116 ~60 ~9 ~127 ~64 ~9 stone
fill ~116 ~65 ~9 ~127 ~67 ~9 dirt
fill ~116 ~68 ~9 ~127 ~68 ~9 grass_block
fill ~112 ~60 ~10 ~116 ~65 ~10 stone
fill ~112 ~66 ~10 ~116 ~68 ~10 dirt
fill ~112 ~69 ~10 ~116 ~69 ~10 grass_block
fill ~117 ~60 ~10 ~127 ~64 ~10 stone
fill ~117 ~65 ~10 ~127 ~67 ~10 dirt
fill ~117 ~68 ~10 ~127 ~68 ~10 grass_block
fill ~112 ~60 ~11 ~116 ~65 ~11 stone
fill ~112 ~66 ~11 ~116 ~68 ~11 dirt
fill ~112 ~69 ~11 ~116 ~69 ~11 grass_block
fill ~117 ~60 ~11 ~127 ~64 ~11 stone
fill ~117 ~65 ~11 ~127 ~67 ~11 dirt
fill ~117 ~68 ~11 ~127 ~68 ~11 grass_block
fill ~112 ~60 ~12 ~116 ~65 ~12 stone
fill ~112 ~66 ~12 ~116 ~68 ~12 dirt
fill ~112 ~69 ~12 ~116 ~69 ~12 grass_block
fill ~117 ~60 ~12 ~127 ~64 ~12 stone
fill ~117 ~65 ~12 ~127 ~67 ~12 dirt
fill ~117 ~68 ~12 ~127 ~68 ~12 grass_block
fill ~112 ~60 ~13 ~112 ~66 ~13 stone
fill ~112 ~67 ~13 ~112 ~69 ~13 dirt
fill ~112 ~70 ~13 ~112 ~70 ~13 grass_block
fill ~113 ~60 ~13 ~118 ~65 ~13 stone
fill ~113 ~66 ~13 ~118 ~68 ~13 dirt
fill ~113 ~69 ~13 ~118 ~69 ~13 grass_block
fill ~119 ~60 ~13 ~125 ~64 ~13 stone
fill ~119 ~65 ~13 ~125 ~67 ~13 dirt
fill ~119 ~68 ~13 ~125 ~68 ~13 grass_block
fill ~126 ~60 ~13 ~127 ~63 ~13 stone
fill ~126 ~64 ~13 ~127 ~66 ~13 dirt
fill ~126 ~67 ~13 ~127 ~67 ~13 grass_block
fill ~112 ~60 ~14 ~114 ~66 ~14 stone
fill ~112 ~67 ~14 ~114 ~69 ~14 dirt
fill ~112 ~70 ~14 ~114 ~70 ~14 grass_block
fill ~115 ~60 ~14 ~118 ~65 ~14 stone
fill ~115 ~66 ~14 ~118 ~68 ~14 dirt
fill ~115 ~69 ~14 ~118 ~69 ~14 grass_block
fill ~119 ~60 ~14 ~127 ~64 ~14 stone
fill ~119 ~65 ~14 ~127 ~67 ~14 dirt
fill ~119 ~68 ~14 ~127 ~68 ~14 grass_block
fill ~112 ~60 ~15 ~114 ~66 ~15 stone
fill ~112 ~67 ~15 ~114 ~69 ~15 dirt
fill ~112 ~70 ~15 ~114 ~70 ~15 grass_block
fill ~115 ~60 ~15 ~117 ~65 ~15 stone
fill ~115 ~66 ~15 ~117 ~68 ~15 dirt
fill ~115 ~69 ~15 ~117 ~69 ~15 grass_block
fill ~118 ~60 ~15 ~127 ~64 ~15 stone
fill ~118 ~65 ~15 ~127 ~67 ~15 dirt
fill ~118 ~68 ~15 ~127 ~68 ~15 grass_block