fill ~48 ~60 ~112 ~61 ~63 ~112 stone
fill ~48 ~64 ~112 ~61 ~66 ~112 dirt
fill ~48 ~67 ~112 ~61 ~67 ~112 grass_block
fill ~62 ~60 ~112 ~62 ~64 ~112 stone
fill ~62 ~65 ~112 ~62 ~67 ~112 dirt
fill ~62 ~68 ~112 ~62 ~68 ~112 grass_block
fill ~63 ~60 ~112 ~63 ~63 ~112 stone
fill ~63 ~64 ~112 ~63 ~66 ~112 dirt
fill ~63 ~67 ~112 ~63 ~67 ~112 grass_block
fill ~48 ~60 ~113 ~48 ~64 ~113 stone
fill ~48 ~65 ~113 ~48 ~67 ~113 dirt
fill ~48 ~68 ~113 ~48 ~68 ~113 grass_block
fill ~49 ~60 ~113 ~61 ~63 ~113 stone
fill ~49 ~64 ~113 ~61 ~66 ~113 dirt
fill ~49 ~67 ~113 ~61 ~67 ~113 grass_block
fill ~62 ~60 ~113 ~63 ~64 ~113 stone
fill ~62 ~65 ~113 ~63 ~67 ~113 dirt
fill ~62 ~68 ~113 ~63 ~68 ~113 grass_block
fill ~48 ~60 ~114 ~48 ~64 ~114 stone
fill ~48 ~65 ~114 ~48 ~67 ~114 dirt
fill ~48 ~68 ~114 ~48 ~68 ~114 grass_block
fill ~49 ~60 ~114 ~63 ~63 ~114 stone
fill ~49 ~64 ~114 ~63 ~66 ~114 dirt
fill ~49 ~67 ~114 ~63 ~67 ~114 grass_block
fill ~48 ~60 ~115 ~49 ~64 ~115 stone
fill ~48 ~65 ~115 ~49 ~67 ~115 dirt
fill ~48 ~68 ~115 ~49 ~68 ~115 grass_block
fill ~50 ~60 ~115 ~63 ~63 ~115 stone
fill ~50 ~64 ~115 ~63 ~66 ~115 dirt
fill ~50 ~67 ~115 ~63 ~67 ~115 grass_block
fill ~48 ~60 ~116 ~50 ~64 ~116 stone
fill ~48 ~65 ~116 ~50 ~67 ~116 dirt
fill ~48 ~68 ~116 ~50 ~68 ~116 grass_block
fill ~51 ~60 ~116 ~63 ~63 ~116 stone
fill ~51 ~64 ~116 ~63 ~66 ~116 dirt
fill ~51 ~67 ~116 ~63 ~67 ~116 grass_block
fill ~48 ~60 ~117 ~51 ~64 ~117 stone
fill ~48 ~65 ~117 ~51 ~67 ~117 dirt
fill ~48 ~68 ~117 ~51 ~68 ~117 grass_block
fill ~52 ~60 ~117 ~63 ~63 ~117 stone
fill ~52 ~64 ~117 ~63 ~66 ~117 dirt
fill ~52 ~67 ~117 ~63 ~67 ~117 grass_block
fill ~48 ~60 ~118 ~48 ~65 ~118 stone
fill ~48 ~66 ~118 ~48 ~68 ~118 dirt
fill ~48 ~69 ~118 ~48 ~69 ~118 grass_block
fill ~49 ~60 ~118 ~52 ~64 ~118 stone
fill ~49 ~65 ~118 ~52 ~67 ~118 dirt
fill ~49 ~68 ~118 ~52 ~68 ~118 grass_block
fill ~53 ~60 ~118 ~63 ~63 ~118 stone
fill ~53 ~64 ~118 ~63 ~66 ~118 dirt
fill ~53 ~67 ~118 ~63 ~67 ~118 grass_block
fill ~48 ~60 ~119 ~49 ~65 ~119 stone
fill ~48 ~66 ~119 ~49 ~68 ~119 dirt
fill ~48 ~69 ~119 ~49 ~69 ~119 grass_block
fill ~50 ~60 ~119 ~52 ~64 ~119 stone
fill ~50 ~65 ~119 ~52 ~67 ~119 dirt
fill ~50 ~68 ~119 ~52 ~68 ~119 grass_block
fill ~53 ~60 ~119 ~63 ~63 ~119 stone
fill ~53 ~64 ~119 ~63 ~66 ~119 dirt
fill ~53 ~67 ~119 ~63 ~67 ~119 grass_block
fill ~48 ~60 ~120 ~49 ~65 ~120 stone
fill ~48 ~66 ~120 ~49 ~68 ~120 dirt
fill ~48 ~69 ~120 ~49 ~69 ~120 grass_block
fill ~50 ~60 ~120 ~53 ~64 ~120 stone
fill ~50 ~65 ~120 ~53 ~67 ~120 dirt
fill ~50 ~68 ~120 ~53 ~68 ~120 grass_block
fill ~54 ~60 ~120 ~63 ~63 ~120 stone
fill ~54 ~64 ~120 ~63 ~66 ~120 dirt
fill ~54 ~67 ~120 ~63 ~67 ~120 grass_block
fill ~48 ~60 ~121 ~48 ~66 ~121 stone
fill ~48 ~67 ~121 ~48 ~69 ~121 dirt
fill ~48 ~70 ~121 ~48 ~70 ~121 grass_block
fill ~49 ~60 ~121 ~51 ~65 ~121 stone
fill ~49 ~66 ~121 ~51 ~68 ~121 dirt
fill ~49 ~69 ~121 ~51 ~69 ~121 grass_block
fill ~52 ~60 ~121 ~55 ~64 ~121 stone
fill ~52 ~65 ~121 ~55 ~67 ~121 dirt
fill ~52 ~68 ~121 ~55 ~68 ~121 grass_block
fill ~56 ~60 ~121 ~63 ~63 ~121 stone
fill ~56 ~64 ~121 ~63 ~66 ~121 dirt
fill ~56 ~67 ~121 ~63 ~67 ~121 grass_block
fill ~48 ~60 ~122 ~49 ~66 ~122 stone
fill ~48 ~67 ~122 ~49 ~69 ~122 dirt
fill ~48 ~70 ~122 ~49 ~70 ~122 grass_block
fill ~50 ~60 ~122 ~54 ~65 ~122 stone
fill ~50 ~66 ~122 ~54 ~68 ~122 dirt
fill ~50 ~69 ~122 ~54 ~69 ~122 grass_block
fill ~55 ~60 ~122 ~57 ~64 ~122 stone
fill ~55 ~65 ~122 ~57 ~67 ~122 dirt
fill ~55 ~68 ~122 ~57 ~68 ~122 grass_block
fill ~58 ~60 ~122 ~63 ~63 ~122 stone
fill ~58 ~64 ~122 ~63 ~66 ~122 dirt
fill ~58 ~67 ~122 ~63 ~67 ~122 grass_block
fill ~48 ~60 ~123 ~55 ~65 ~123 stone
fill ~48 ~66 ~123 ~55 ~68 ~123 dirt
fill ~48 ~69 ~123 ~55 ~69 ~123 grass_block
fill ~56 ~60 ~123 ~59 ~64 ~123 stone
fill ~56 ~65 ~123 ~59 ~67 ~123 dirt
fill ~56 ~68 ~123 ~59 ~68 ~123 grass_block
fill ~60 ~60 ~123 ~63 ~63 ~123 stone
fill ~60 ~64 ~123 ~63 ~66 ~123 dirt
fill ~60 ~67 ~123 ~63 ~67 ~123 grass_block
fill ~48 ~60 ~124 ~57 ~65 ~124 stone
fill ~48 ~66 ~124 ~57 ~68 ~124 dirt
fill ~48 ~69 ~124 ~57 ~69 ~124 grass_block
fill ~58 ~60 ~124 ~60 ~64 ~124 stone
fill ~58 ~65 ~124 ~60 ~67 ~124 dirt
fill ~58 ~68 ~124 ~60 ~68 ~124 grass_block
fill ~61 ~60 ~124 ~63 ~63 ~124 stone
fill ~61 ~64 ~124 ~63 ~66 ~124 dirt
fill ~61 ~67 ~124 ~63 ~67 ~124 grass_block
fill ~48 ~60 ~125 ~52 ~65 ~125 stone
fill ~48 ~66 ~125 ~52 ~68 ~125 dirt
fill ~48 ~69 ~125 ~52 ~69 ~125 grass_block
fill ~53 ~60 ~125 ~56 ~64 ~125 stone
fill ~53 ~65 ~125 ~56 ~67 ~125 dirt
fill ~53 ~68 ~125 ~56 ~68 ~125 grass_block
fill ~57 ~60 ~125 ~57 ~65 ~125 stone
fill ~57 ~66 ~125 ~57 ~68 ~125 dirt
fill ~57 ~69 ~125 ~57 ~69 ~125 grass_block
fill ~58 ~60 ~125 ~61 ~64 ~125 stone
fill ~58 ~65 ~125 ~61 ~67 ~125 dirt
fill ~58 ~68 ~125 ~61 ~68 ~125 grass_block
fill ~62 ~60 ~125 ~63 ~63 ~125 stone
fill ~62 ~64 ~125 ~63 ~66 ~125 dirt
fill ~62 ~67 ~125 ~63 ~67 ~125 grass_block
fill ~48 ~60 ~126 ~51 ~65 ~126 stone
fill ~48 ~66 ~126 ~51 ~68 ~126 dirt
fill ~48 ~69 ~126 ~51 ~69 ~126 grass_block
fill ~52 ~60 ~126 ~61 ~64 ~126 stone
fill ~52 ~65 ~126 ~61 ~67 ~126 dirt
fill ~52 ~68 ~126 ~61 ~68 ~126 grass_block
fill ~62 ~60 ~126 ~63 ~63 ~126 stone
fill ~62 ~64 ~126 ~63 ~66 ~126 dirt
fill ~62 ~67 ~126 ~63 ~67 ~126 grass_block
fill ~48 ~60 ~127 ~48 ~65 ~127 stone
fill ~48 ~66 ~127 ~48 ~68 ~127 dirt
fill ~48 ~69 ~127 ~48 ~69 ~127 grass_block
fill ~49 ~60 ~127 ~63 ~64 ~127 stone
fill ~49 ~65 ~127 ~63 ~67 ~127 dirt
fill ~49 ~68 ~127 ~63 ~68 ~127 grass_block