fill ~16 ~60 ~16 ~16 ~67 ~16 stone
fill ~16 ~68 ~16 ~16 ~70 ~16 dirt
fill ~16 ~71 ~16 ~16 ~71 ~16 grass_block
fill ~17 ~60 ~16 ~19 ~68 ~16 stone
fill ~17 ~69 ~16 ~19 ~71 ~16 dirt
fill ~17 ~72 ~16 ~19 ~72 ~16 grass_block
fill ~20 ~60 ~16 ~23 ~67 ~16 stone
fill ~20 ~68 ~16 ~23 ~70 ~16 dirt
fill ~20 ~71 ~16 ~23 ~71 ~16 grass_block
fill ~24 ~60 ~16 ~31 ~68 ~16 stone
fill ~24 ~69 ~16 ~31 ~71 ~16 dirt
fill ~24 ~72 ~16 ~31 ~72 ~16 grass_block
fill ~16 ~60 ~17 ~17 ~67 ~17 stone
fill ~16 ~68 ~17 ~17 ~70 ~17 dirt
fill ~16 ~71 ~17 ~17 ~71 ~17 grass_block
fill ~18 ~60 ~17 ~18 ~68 ~17 stone
fill ~18 ~69 ~17 ~18 ~71 ~17 dirt
fill ~18 ~72 ~17 ~18 ~72 ~17 grass_block
fill ~19 ~60 ~17 ~26 ~67 ~17 stone
fill ~19 ~68 ~17 ~26 ~70 ~17 dirt
fill ~19 ~71 ~17 ~26 ~71 ~17 grass_block
fill ~27 ~60 ~17 ~31 ~68 ~17 stone
fill ~27 ~69 ~17 ~31 ~71 ~17 dirt
fill ~27 ~72 ~17 ~31 ~72 ~17 grass_block
fill ~16 ~60 ~18 ~20 ~67 ~18 stone
fill ~16 ~68 ~18 ~20 ~70 ~18 dirt
fill ~16 ~71 ~18 ~20 ~71 ~18 grass_block
fill ~21 ~60 ~18 ~24 ~66 ~18 stone
fill ~21 ~67 ~18 ~24 ~69 ~18 dirt
fill ~21 ~70 ~18 ~24 ~70 ~18 grass_block
fill ~25 ~60 ~18 ~27 ~67 ~18 stone
fill ~25 ~68 ~18 ~27 ~70 ~18 dirt
fill ~25 ~71 ~18 ~27 ~71 ~18 grass_block
fill ~28 ~60 ~18 ~31 ~68 ~18 stone
fill ~28 ~69 ~18 ~31 ~71 ~18 dirt
fill ~28 ~72 ~18 ~31 ~72 ~18 grass_block
fill ~16 ~60 ~19 ~18 ~66 ~19 stone
fill ~16 ~67 ~19 ~18 ~69 ~19 dirt
fill ~16 ~70 ~19 ~18 ~70 ~19 grass_block
fill ~19 ~60 ~19 ~20 ~67 ~19 stone
fill ~19 ~68 ~19 ~20 ~70 ~19 dirt
fill ~19 ~71 ~19 ~20 ~71 ~19 grass_block
fill ~21 ~60 ~19 ~26 ~66 ~19 stone
fill ~21 ~67 ~19 ~26 ~69 ~19 dirt
fill ~21 ~70 ~19 ~26 ~70 ~19 grass_block
fill ~27 ~60 ~19 ~30 ~67 ~19 stone
fill ~27 ~68 ~19 ~30 ~70 ~19 dirt
fill ~27 ~71 ~19 ~30 ~71 ~19 grass_block
fill ~31 ~60 ~19 ~31 ~68 ~19 stone
fill ~31 ~69 ~19 ~31 ~71 ~19 dirt
fill ~31 ~72 ~19 ~31 ~72 ~19 grass_block
fill ~16 ~60 ~20 ~19 ~66 ~20 stone
fill ~16 ~67 ~20 ~19 ~69 ~20 dirt
fill ~16 ~70 ~20 ~19 ~70 ~20 grass_block
fill ~20 ~60 ~20 ~21 ~67 ~20 stone
fill ~20 ~68 ~20 ~21 ~70 ~20 dirt
fill ~20 ~71 ~20 ~21 ~71 ~20 grass_block
fill ~22 ~60 ~20 ~28 ~66 ~20 stone
fill ~22 ~67 ~20 ~28 ~69 ~20 dirt
fill ~22 ~70 ~20 ~28 ~70 ~20 grass_block
fill ~29 ~60 ~20 ~31 ~67 ~20 stone
fill ~29 ~68 ~20 ~31 ~70 ~20 dirt
fill ~29 ~71 ~20 ~31 ~71 ~20 grass_block
fill ~16 ~60 ~21 ~24 ~66 ~21 stone
fill ~16 ~67 ~21 ~24 ~69 ~21 dirt
fill ~16 ~70 ~21 ~24 ~70 ~21 grass_block
fill ~25 ~60 ~21 ~26 ~65 ~21 stone
fill ~25 ~66 ~21 ~26 ~68 ~21 dirt
fill ~25 ~69 ~21 ~26 ~69 ~21 grass_block
fill ~27 ~60 ~21 ~30 ~66 ~21 stone
fill ~27 ~67 ~21 ~30 ~69 ~21 dirt
fill ~27 ~70 ~21 ~30 ~70 ~21 grass_block
fill ~31 ~60 ~21 ~31 ~67 ~21 stone
fill ~31 ~68 ~21 ~31 ~70 ~21 dirt
fill ~31 ~71 ~21 ~31 ~71 ~21 grass_block
fill ~16 ~60 ~22 ~17 ~65 ~22 stone
fill ~16 ~66 ~22 ~17 ~68 ~22 dirt
fill ~16 ~69 ~22 ~17 ~69 ~22 grass_block
fill ~18 ~60 ~22 ~24 ~66 ~22 stone
fill ~18 ~67 ~22 ~24 ~69 ~22 dirt
fill ~18 ~70 ~22 ~24 ~70 ~22 grass_block
fill ~25 ~60 ~22 ~28 ~65 ~22 stone
fill ~25 ~66 ~22 ~28 ~68 ~22 dirt
fill ~25 ~69 ~22 ~28 ~69 ~22 grass_block
fill ~29 ~60 ~22 ~31 ~66 ~22 stone
fill ~29 ~67 ~22 ~31 ~69 ~22 dirt
fill ~29 ~70 ~22 ~31 ~70 ~22 grass_block
fill ~16 ~60 ~23 ~20 ~65 ~23 stone
fill ~16 ~66 ~23 ~20 ~68 ~23 dirt
fill ~16 ~69 ~23 ~20 ~69 ~23 grass_block
fill ~21 ~60 ~23 ~24 ~66 ~23 stone
fill ~21 ~67 ~23 ~24 ~69 ~23 dirt
fill ~21 ~70 ~23 ~24 ~70 ~23 grass_block
fill ~25 ~60 ~23 ~29 ~65 ~23 stone
fill ~25 ~66 ~23 ~29 ~68 ~23 dirt
fill ~25 ~69 ~23 ~29 ~69 ~23 grass_block
fill ~30 ~60 ~23 ~31 ~66 ~23 stone
fill ~30 ~67 ~23 ~31 ~69 ~23 dirt
fill ~30 ~70 ~23 ~31 ~70 ~23 grass_block
fill ~16 ~60 ~24 ~19 ~64 ~24 stone
fill ~16 ~65 ~24 ~19 ~67 ~24 dirt
fill ~16 ~68 ~24 ~19 ~68 ~24 grass_block
fill ~20 ~60 ~24 ~24 ~65 ~24 stone
fill ~20 ~66 ~24 ~24 ~68 ~24 dirt
fill ~20 ~69 ~24 ~24 ~69 ~24 grass_block
fill ~25 ~60 ~24 ~25 ~66 ~24 stone
fill ~25 ~67 ~24 ~25 ~69 ~24 dirt
fill ~25 ~70 ~24 ~25 ~70 ~24 grass_block
fill ~26 ~60 ~24 ~30 ~65 ~24 stone
fill ~26 ~66 ~24 ~30 ~68 ~24 dirt
fill ~26 ~69 ~24 ~30 ~69 ~24 grass_block
fill ~31 ~60 ~24 ~31 ~66 ~24 stone
fill ~31 ~67 ~24 ~31 ~69 ~24 dirt
fill ~31 ~70 ~24 ~31 ~70 ~24 grass_block
fill ~16 ~60 ~25 ~16 ~65 ~25 stone
fill ~16 ~66 ~25 ~16 ~68 ~25 dirt
fill ~16 ~69 ~25 ~16 ~69 ~25 grass_block
fill ~17 ~60 ~25 ~20 ~64 ~25 stone
fill ~17 ~65 ~25 ~20 ~67 ~25 dirt
fill ~17 ~68 ~25 ~20 ~68 ~25 grass_block
fill ~21 ~60 ~25 ~28 ~65 ~25 stone
fill ~21 ~66 ~25 ~28 ~68 ~25 dirt
fill ~21 ~69 ~25 ~28 ~69 ~25 grass_block
fill ~29 ~60 ~25 ~29 ~64 ~25 stone
fill ~29 ~65 ~25 ~29 ~67 ~25 dirt
fill ~29 ~68 ~25 ~29 ~68 ~25 grass_block
fill ~30 ~60 ~25 ~31 ~65 ~25 stone
fill ~30 ~66 ~25 ~31 ~68 ~25 dirt
fill ~30 ~69 ~25 ~31 ~69 ~25 grass_block
fill ~16 ~60 ~26 ~16 ~65 ~26 stone
fill ~16 ~66 ~26 ~16 ~68 ~26 dirt
fill ~16 ~69 ~26 ~16 ~69 ~26 grass_block
fill ~17 ~60 ~26 ~23 ~64 ~26 stone
fill ~17 ~65 ~26 ~23 ~67 ~26 dirt
fill ~17 ~68 ~26 ~23 ~68 ~26 grass_block
fill ~24 ~60 ~26 ~27 ~65 ~26 stone
fill ~24 ~66 ~26 ~27 ~68 ~26 dirt
fill ~24 ~69 ~26 ~27 ~69 ~26 grass_block
fill ~28 ~60 ~26 ~30 ~64 ~26 stone
fill ~28 ~65 ~26 ~30 ~67 ~26 dirt
fill ~28 ~68 ~26 ~30 ~68 ~26 grass_block
fill ~31 ~60 ~26 ~31 ~65 ~26 stone
fill ~31 ~66 ~26 ~31 ~68 ~26 dirt
fill ~31 ~69 ~26 ~31 ~69 ~26 grass_block
fill ~16 ~60 ~27 ~18 ~65 ~27 stone
fill ~16 ~66 ~27 ~18 ~68 ~27 dirt
fill ~16 ~69 ~27 ~18 ~69 ~27 grass_block
fill ~19 ~60 ~27 ~25 ~64 ~27 stone
fill ~19 ~65 ~27 ~25 ~67 ~27 dirt
fill ~19 ~68 ~27 ~25 ~68 ~27 grass_block
fill ~26 ~60 ~27 ~28 ~65 ~27 stone
fill ~26 ~66 ~27 ~28 ~68 ~27 dirt
fill ~26 ~69 ~27 ~28 ~69 ~27 grass_block
fill ~29 ~60 ~27 ~31 ~64 ~27 stone
fill ~29 ~65 ~27 ~31 ~67 ~27 dirt
fill ~29 ~68 ~27 ~31 ~68 ~27 grass_block
fill ~16 ~60 ~28 ~16 ~66 ~28 stone
fill ~16 ~67 ~28 ~16 ~69 ~28 dirt
fill ~16 ~70 ~28 ~16 ~70 ~28 grass_block
fill ~17 ~60 ~28 ~19 ~65 ~28 stone
fill ~17 ~66 ~28 ~19 ~68 ~28 dirt
fill ~17 ~69 ~28 ~19 ~69 ~28 grass_block
fill ~20 ~60 ~28 ~31 ~64 ~28 stone
fill ~20 ~65 ~28 ~31 ~67 ~28 dirt
fill ~20 ~68 ~28 ~31 ~68 ~28 grass_block
fill ~16 ~60 ~29 ~16 ~66 ~29 stone
fill ~16 ~67 ~29 ~16 ~69 ~29 dirt
fill ~16 ~70 ~29 ~16 ~70 ~29 grass_block
fill ~17 ~60 ~29 ~19 ~65 ~29 stone
fill ~17 ~66 ~29 ~19 ~68 ~29 dirt
fill ~17 ~69 ~29 ~19 ~69 ~29 grass_block
fill ~20 ~60 ~29 ~31 ~64 ~29 stone
fill ~20 ~65 ~29 ~31 ~67 ~29 dirt
fill ~20 ~68 ~29 ~31 ~68 ~29 grass_block
fill ~16 ~60 ~30 ~16 ~66 ~30 stone
fill ~16 ~67 ~30 ~16 ~69 ~30 dirt
fill ~16 ~70 ~30 ~16 ~70 ~30 grass_block
fill ~17 ~60 ~30 ~24 ~65 ~30 stone
fill ~17 ~66 ~30 ~24 ~68 ~30 dirt
fill ~17 ~69 ~30 ~24 ~69 ~30 grass_block
fill ~25 ~60 ~30 ~31 ~64 ~30 stone
fill ~25 ~65 ~30 ~31 ~67 ~30 dirt
fill ~25 ~68 ~30 ~31 ~68 ~30 grass_block
fill ~16 ~60 ~31 ~18 ~66 ~31 stone
fill ~16 ~67 ~31 ~18 ~69 ~31 dirt
fill ~16 ~70 ~31 ~18 ~70 ~31 grass_block
fill ~19 ~60 ~31 ~20 ~65 ~31 stone
fill ~19 ~66 ~31 ~20 ~68 ~31 dirt
fill ~19 ~69 ~31 ~20 ~69 ~31 grass_block
fill ~21 ~60 ~31 ~23 ~66 ~31 stone
fill ~21 ~67 ~31 ~23 ~69 ~31 dirt
fill ~21 ~70 ~31 ~23 ~70 ~31 grass_block
fill ~24 ~60 ~31 ~29 ~65 ~31 stone
fill ~24 ~66 ~31 ~29 ~68 ~31 dirt
fill ~24 ~69 ~31 ~29 ~69 ~31 grass_block
fill ~30 ~60 ~31 ~31 ~64 ~31 stone
fill ~30 ~65 ~31 ~31 ~67 ~31 dirt
fill ~30 ~68 ~31 ~31 ~68 ~31 grass_block