fill ~240 ~60 ~32 ~248 ~61 ~32 stone
fill ~240 ~62 ~32 ~248 ~64 ~32 dirt
fill ~240 ~65 ~32 ~248 ~65 ~32 grass_block
fill ~249 ~60 ~32 ~253 ~62 ~32 stone
fill ~249 ~63 ~32 ~253 ~65 ~32 dirt
fill ~249 ~66 ~32 ~253 ~66 ~32 grass_block
fill ~254 ~60 ~32 ~255 ~63 ~32 stone
fill ~254 ~64 ~32 ~255 ~66 ~32 dirt
fill ~254 ~67 ~32 ~255 ~67 ~32 grass_block
fill ~240 ~60 ~33 ~250 ~61 ~33 stone
fill ~240 ~62 ~33 ~250 ~64 ~33 dirt
fill ~240 ~65 ~33 ~250 ~65 ~33 grass_block
fill ~251 ~60 ~33 ~255 ~62 ~33 stone
fill ~251 ~63 ~33 ~255 ~65 ~33 dirt
fill ~251 ~66 ~33 ~255 ~66 ~33 grass_block
fill ~240 ~60 ~34 ~253 ~61 ~34 stone
fill ~240 ~62 ~34 ~253 ~64 ~34 dirt
fill ~240 ~65 ~34 ~253 ~65 ~34 grass_block
fill ~254 ~60 ~34 ~255 ~62 ~34 stone
fill ~254 ~63 ~34 ~255 ~65 ~34 dirt
fill ~254 ~66 ~34 ~255 ~66 ~34 grass_block
fill ~240 ~60 ~35 ~245 ~61 ~35 stone
fill ~240 ~62 ~35 ~245 ~64 ~35 dirt
fill ~240 ~65 ~35 ~245 ~65 ~35 grass_block
fill ~246 ~60 ~35 ~246 ~60 ~35 stone
fill ~246 ~61 ~35 ~246 ~63 ~35 dirt
fill ~246 ~64 ~35 ~246 ~64 ~35 grass_block
fill ~247 ~60 ~35 ~255 ~61 ~35 stone
fill ~247 ~62 ~35 ~255 ~64 ~35 dirt
fill ~247 ~65 ~35 ~255 ~65 ~35 grass_block
fill ~240 ~60 ~36 ~255 ~61 ~36 stone
fill ~240 ~62 ~36 ~255 ~64 ~36 dirt
fill ~240 ~65 ~36 ~255 ~65 ~36 grass_block
fill ~240 ~60 ~37 ~255 ~61 ~37 stone
fill ~240 ~62 ~37 ~255 ~64 ~37 dirt
fill ~240 ~65 ~37 ~255 ~65 ~37 grass_block
fill ~240 ~60 ~38 ~255 ~61 ~38 stone
fill ~240 ~62 ~38 ~255 ~64 ~38 dirt
fill ~240 ~65 ~38 ~255 ~65 ~38 grass_block
fill ~240 ~60 ~39 ~255 ~61 ~39 stone
fill ~240 ~62 ~39 ~255 ~64 ~39 dirt
fill ~240 ~65 ~39 ~255 ~65 ~39 grass_block
fill ~240 ~60 ~40 ~255 ~61 ~40 stone
fill ~240 ~62 ~40 ~255 ~64 ~40 dirt
fill ~240 ~65 ~40 ~255 ~65 ~40 grass_block
fill ~240 ~60 ~41 ~255 ~61 ~41 stone
fill ~240 ~62 ~41 ~255 ~64 ~41 dirt
fill ~240 ~65 ~41 ~255 ~65 ~41 grass_block
fill ~240 ~60 ~42 ~255 ~61 ~42 stone
fill ~240 ~62 ~42 ~255 ~64 ~42 dirt
fill ~240 ~65 ~42 ~255 ~65 ~42 grass_block
fill ~240 ~60 ~43 ~255 ~61 ~43 stone
fill ~240 ~62 ~43 ~255 ~64 ~43 dirt
fill ~240 ~65 ~43 ~255 ~65 ~43 grass_block
fill ~240 ~60 ~44 ~255 ~61 ~44 stone
fill ~240 ~62 ~44 ~255 ~64 ~44 dirt
fill ~240 ~65 ~44 ~255 ~65 ~44 grass_block
fill ~240 ~60 ~45 ~255 ~61 ~45 stone
fill ~240 ~62 ~45 ~255 ~64 ~45 dirt
fill ~240 ~65 ~45 ~255 ~65 ~45 grass_block
fill ~240 ~60 ~46 ~242 ~61 ~46 stone
fill ~240 ~62 ~46 ~242 ~64 ~46 dirt
fill ~240 ~65 ~46 ~242 ~65 ~46 grass_block
fill ~243 ~60 ~46 ~246 ~62 ~46 stone
fill ~243 ~63 ~46 ~246 ~65 ~46 dirt
fill ~243 ~66 ~46 ~246 ~66 ~46 grass_block
fill ~247 ~60 ~46 ~250 ~61 ~46 stone
fill ~247 ~62 ~46 ~250 ~64 ~46 dirt
fill ~247 ~65 ~46 ~250 ~65 ~46 grass_block
fill ~251 ~60 ~46 ~251 ~62 ~46 stone
fill ~251 ~63 ~46 ~251 ~65 ~46 dirt
fill ~251 ~66 ~46 ~251 ~66 ~46 grass_block
fill ~252 ~60 ~46 ~255 ~61 ~46 stone
fill ~252 ~62 ~46 ~255 ~64 ~46 dirt
fill ~252 ~65 ~46 ~255 ~65 ~46 grass_block
fill ~240 ~60 ~47 ~241 ~61 ~47 stone
fill ~240 ~62 ~47 ~241 ~64 ~47 dirt
fill ~240 ~65 ~47 ~241 ~65 ~47 grass_block
fill ~242 ~60 ~47 ~251 ~62 ~47 stone
fill ~242 ~63 ~47 ~251 ~65 ~47 dirt
fill ~242 ~66 ~47 ~251 ~66 ~47 grass_block
fill ~252 ~60 ~47 ~255 ~61 ~47 stone
fill ~252 ~62 ~47 ~255 ~64 ~47 dirt
fill ~252 ~65 ~47 ~255 ~65 ~47 grass_block