fill ~320 ~60 ~0 ~323 ~65 ~0 stone
fill ~320 ~66 ~0 ~323 ~68 ~0 dirt
fill ~320 ~69 ~0 ~323 ~69 ~0 grass_block
fill ~324 ~60 ~0 ~325 ~64 ~0 stone
fill ~324 ~65 ~0 ~325 ~67 ~0 dirt
fill ~324 ~68 ~0 ~325 ~68 ~0 grass_block
fill ~326 ~60 ~0 ~329 ~63 ~0 stone
fill ~326 ~64 ~0 ~329 ~66 ~0 dirt
fill ~326 ~67 ~0 ~329 ~67 ~0 grass_block
fill ~330 ~60 ~0 ~333 ~64 ~0 stone
fill ~330 ~65 ~0 ~333 ~67 ~0 dirt
fill ~330 ~68 ~0 ~333 ~68 ~0 grass_block
fill ~334 ~60 ~0 ~335 ~65 ~0 stone
fill ~334 ~66 ~0 ~335 ~68 ~0 dirt
fill ~334 ~69 ~0 ~335 ~69 ~0 grass_block
fill ~320 ~60 ~1 ~322 ~65 ~1 stone
fill ~320 ~66 ~1 ~322 ~68 ~1 dirt
fill ~320 ~69 ~1 ~322 ~69 ~1 grass_block
fill ~323 ~60 ~1 ~325 ~64 ~1 stone
fill ~323 ~65 ~1 ~325 ~67 ~1 dirt
fill ~323 ~68 ~1 ~325 ~68 ~1 grass_block
fill ~326 ~60 ~1 ~328 ~63 ~1 stone
fill ~326 ~64 ~1 ~328 ~66 ~1 dirt
fill ~326 ~67 ~1 ~328 ~67 ~1 grass_block
fill ~329 ~60 ~1 ~332 ~64 ~1 stone
fill ~329 ~65 ~1 ~332 ~67 ~1 dirt
fill ~329 ~68 ~1 ~332 ~68 ~1 grass_block
fill ~333 ~60 ~1 ~333 ~65 ~1 stone
fill ~333 ~66 ~1 ~333 ~68 ~1 dirt
fill ~333 ~69 ~1 ~333 ~69 ~1 grass_block
fill ~334 ~60 ~1 ~334 ~64 ~1 stone
fill ~334 ~65 ~1 ~334 ~67 ~1 dirt
fill ~334 ~68 ~1 ~334 ~68 ~1 grass_block
fill ~335 ~60 ~1 ~335 ~65 ~1 stone
fill ~335 ~66 ~1 ~335 ~68 ~1 dirt
fill ~335 ~69 ~1 ~335 ~69 ~1 grass_block
fill ~320 ~60 ~2 ~325 ~64 ~2 stone
fill ~320 ~65 ~2 ~325 ~67 ~2 dirt
fill ~320 ~68 ~2 ~325 ~68 ~2 grass_block
fill ~326 ~60 ~2 ~329 ~63 ~2 stone
fill ~326 ~64 ~2 ~329 ~66 ~2 dirt
fill ~326 ~67 ~2 ~329 ~67 ~2 grass_block
fill ~330 ~60 ~2 ~335 ~64 ~2 stone
fill ~330 ~65 ~2 ~335 ~67 ~2 dirt
fill ~330 ~68 ~2 ~335 ~68 ~2 grass_block
fill ~320 ~60 ~3 ~325 ~64 ~3 stone
fill ~320 ~65 ~3 ~325 ~67 ~3 dirt
fill ~320 ~68 ~3 ~325 ~68 ~3 grass_block
fill ~326 ~60 ~3 ~329 ~63 ~3 stone
fill ~326 ~64 ~3 ~329 ~66 ~3 dirt
fill ~326 ~67 ~3 ~329 ~67 ~3 grass_block
fill ~330 ~60 ~3 ~335 ~64 ~3 stone
fill ~330 ~65 ~3 ~335 ~67 ~3 dirt
fill ~330 ~68 ~3 ~335 ~68 ~3 grass_block
fill ~320 ~60 ~4 ~321 ~63 ~4 stone
fill ~320 ~64 ~4 ~321 ~66 ~4 dirt
fill ~320 ~67 ~4 ~321 ~67 ~4 grass_block
fill ~322 ~60 ~4 ~325 ~64 ~4 stone
fill ~322 ~65 ~4 ~325 ~67 ~4 dirt
fill ~322 ~68 ~4 ~325 ~68 ~4 grass_block
fill ~326 ~60 ~4 ~329 ~63 ~4 stone
fill ~326 ~64 ~4 ~329 ~66 ~4 dirt
fill ~326 ~67 ~4 ~329 ~67 ~4 grass_block
fill ~330 ~60 ~4 ~335 ~64 ~4 stone
fill ~330 ~65 ~4 ~335 ~67 ~4 dirt
fill ~330 ~68 ~4 ~335 ~68 ~4 grass_block
fill ~320 ~60 ~5 ~324 ~63 ~5 stone
fill ~320 ~64 ~5 ~324 ~66 ~5 dirt
fill ~320 ~67 ~5 ~324 ~67 ~5 grass_block
fill ~325 ~60 ~5 ~325 ~64 ~5 stone
fill ~325 ~65 ~5 ~325 ~67 ~5 dirt
fill ~325 ~68 ~5 ~325 ~68 ~5 grass_block
fill ~326 ~60 ~5 ~330 ~63 ~5 stone
fill ~326 ~64 ~5 ~330 ~66 ~5 dirt
fill ~326 ~67 ~5 ~330 ~67 ~5 grass_block
fill ~331 ~60 ~5 ~335 ~64 ~5 stone
fill ~331 ~65 ~5 ~335 ~67 ~5 dirt
fill ~331 ~68 ~5 ~335 ~68 ~5 grass_block
fill ~320 ~60 ~6 ~330 ~63 ~6 stone
fill ~320 ~64 ~6 ~330 ~66 ~6 dirt
fill ~320 ~67 ~6 ~330 ~67 ~6 grass_block
fill ~331 ~60 ~6 ~335 ~64 ~6 stone
fill ~331 ~65 ~6 ~335 ~67 ~6 dirt
fill ~331 ~68 ~6 ~335 ~68 ~6 grass_block
fill ~320 ~60 ~7 ~321 ~64 ~7 stone
fill ~320 ~65 ~7 ~321 ~67 ~7 dirt
fill ~320 ~68 ~7 ~321 ~68 ~7 grass_block
fill ~322 ~60 ~7 ~332 ~63 ~7 stone
fill ~322 ~64 ~7 ~332 ~66 ~7 dirt
fill ~322 ~67 ~7 ~332 ~67 ~7 grass_block
fill ~333 ~60 ~7 ~335 ~64 ~7 stone
fill ~333 ~65 ~7 ~335 ~67 ~7 dirt
fill ~333 ~68 ~7 ~335 ~68 ~7 grass_block
fill ~320 ~60 ~8 ~321 ~65 ~8 stone
fill ~320 ~66 ~8 ~321 ~68 ~8 dirt
fill ~320 ~69 ~8 ~321 ~69 ~8 grass_block
fill ~322 ~60 ~8 ~322 ~64 ~8 stone
fill ~322 ~65 ~8 ~322 ~67 ~8 dirt
fill ~322 ~68 ~8 ~322 ~68 ~8 grass_block
fill ~323 ~60 ~8 ~335 ~63 ~8 stone
fill ~323 ~64 ~8 ~335 ~66 ~8 dirt
fill ~323 ~67 ~8 ~335 ~67 ~8 grass_block
fill ~320 ~60 ~9 ~322 ~65 ~9 stone
fill ~320 ~66 ~9 ~322 ~68 ~9 dirt
fill ~320 ~69 ~9 ~322 ~69 ~9 grass_block
fill ~323 ~60 ~9 ~327 ~64 ~9 stone
fill ~323 ~65 ~9 ~327 ~67 ~9 dirt
fill ~323 ~68 ~9 ~327 ~68 ~9 grass_block
fill ~328 ~60 ~9 ~330 ~63 ~9 stone
fill ~328 ~64 ~9 ~330 ~66 ~9 dirt
fill ~328 ~67 ~9 ~330 ~67 ~9 grass_block
fill ~331 ~60 ~9 ~333 ~62 ~9 stone
fill ~331 ~63 ~9 ~333 ~65 ~9 dirt
fill ~331 ~66 ~9 ~333 ~66 ~9 grass_block
fill ~334 ~60 ~9 ~335 ~63 ~9 stone
fill ~334 ~64 ~9 ~335 ~66 ~9 dirt
fill ~334 ~67 ~9 ~335 ~67 ~9 grass_block
fill ~320 ~60 ~10 ~323 ~65 ~10 stone
fill ~320 ~66 ~10 ~323 ~68 ~10 dirt
fill ~320 ~69 ~10 ~323 ~69 ~10 grass_block
fill ~324 ~60 ~10 ~324 ~64 ~10 stone
fill ~324 ~65 ~10 ~324 ~67 ~10 dirt
fill ~324 ~68 ~10 ~324 ~68 ~10 grass_block
fill ~325 ~60 ~10 ~325 ~65 ~10 stone
fill ~325 ~66 ~10 ~325 ~68 ~10 dirt
fill ~325 ~69 ~10 ~325 ~69 ~10 grass_block
fill ~326 ~60 ~10 ~329 ~64 ~10 stone
fill ~326 ~65 ~10 ~329 ~67 ~10 dirt
fill ~326 ~68 ~10 ~329 ~68 ~10 grass_block
fill ~330 ~60 ~10 ~333 ~63 ~10 stone
fill ~330 ~64 ~10 ~333 ~66 ~10 dirt
fill ~330 ~67 ~10 ~333 ~67 ~10 grass_block
fill ~334 ~60 ~10 ~335 ~62 ~10 stone
fill ~334 ~63 ~10 ~335 ~65 ~10 dirt
fill ~334 ~66 ~10 ~335 ~66 ~10 grass_block
fill ~320 ~60 ~11 ~328 ~65 ~11 stone
fill ~320 ~66 ~11 ~328 ~68 ~11 dirt
fill ~320 ~69 ~11 ~328 ~69 ~11 grass_block
fill ~329 ~60 ~11 ~332 ~64 ~11 stone
fill ~329 ~65 ~11 ~332 ~67 ~11 dirt
fill ~329 ~68 ~11 ~332 ~68 ~11 grass_block
fill ~333 ~60 ~11 ~334 ~63 ~11 stone
fill ~333 ~64 ~11 ~334 ~66 ~11 dirt
fill ~333 ~67 ~11 ~334 ~67 ~11 grass_block
fill ~335 ~60 ~11 ~335 ~62 ~11 stone
fill ~335 ~63 ~11 ~335 ~65 ~11 dirt
fill ~335 ~66 ~11 ~335 ~66 ~11 grass_block
fill ~320 ~60 ~12 ~331 ~65 ~12 stone
fill ~320 ~66 ~12 ~331 ~68 ~12 dirt
fill ~320 ~69 ~12 ~331 ~69 ~12 grass_block
fill ~332 ~60 ~12 ~333 ~64 ~12 stone
fill ~332 ~65 ~12 ~333 ~67 ~12 dirt
fill ~332 ~68 ~12 ~333 ~68 ~12 grass_block
fill ~334 ~60 ~12 ~335 ~63 ~12 stone
fill ~334 ~64 ~12 ~335 ~66 ~12 dirt
fill ~334 ~67 ~12 ~335 ~67 ~12 grass_block
fill ~320 ~60 ~13 ~332 ~65 ~13 stone
fill ~320 ~66 ~13 ~332 ~68 ~13 dirt
fill ~320 ~69 ~13 ~332 ~69 ~13 grass_block
fill ~333 ~60 ~13 ~335 ~64 ~13 stone
fill ~333 ~65 ~13 ~335 ~67 ~13 dirt
fill ~333 ~68 ~13 ~335 ~68 ~13 grass_block
fill ~320 ~60 ~14 ~320 ~64 ~14 stone
fill ~320 ~65 ~14 ~320 ~67 ~14 dirt
fill ~320 ~68 ~14 ~320 ~68 ~14 grass_block
fill ~321 ~60 ~14 ~327 ~65 ~14 stone
fill ~321 ~66 ~14 ~327 ~68 ~14 dirt
fill ~321 ~69 ~14 ~327 ~69 ~14 grass_block
fill ~328 ~60 ~14 ~329 ~66 ~14 stone
fill ~328 ~67 ~14 ~329 ~69 ~14 dirt
fill ~328 ~70 ~14 ~329 ~70 ~14 grass_block
fill ~330 ~60 ~14 ~334 ~65 ~14 stone
fill ~330 ~66 ~14 ~334 ~68 ~14 dirt
fill ~330 ~69 ~14 ~334 ~69 ~14 grass_block
fill ~335 ~60 ~14 ~335 ~64 ~14 stone
fill ~335 ~65 ~14 ~335 ~67 ~14 dirt
fill ~335 ~68 ~14 ~335 ~68 ~14 grass_block
fill ~320 ~60 ~15 ~320 ~64 ~15 stone
fill ~320 ~65 ~15 ~320 ~67 ~15 dirt
fill ~320 ~68 ~15 ~320 ~68 ~15 grass_block
fill ~321 ~60 ~15 ~327 ~65 ~15 stone
fill ~321 ~66 ~15 ~327 ~68 ~15 dirt
fill ~321 ~69 ~15 ~327 ~69 ~15 grass_block
fill ~328 ~60 ~15 ~331 ~66 ~15 stone
fill ~328 ~67 ~15 ~331 ~69 ~15 dirt
fill ~328 ~70 ~15 ~331 ~70 ~15 grass_block
fill ~332 ~60 ~15 ~335 ~65 ~15 stone
fill ~332 ~66 ~15 ~335 ~68 ~15 dirt
fill ~332 ~69 ~15 ~335 ~69 ~15 grass_block