fill ~384 ~60 ~80 ~388 ~62 ~80 stone
fill ~384 ~63 ~80 ~388 ~65 ~80 dirt
fill ~384 ~66 ~80 ~388 ~66 ~80 grass_block
fill ~389 ~60 ~80 ~399 ~63 ~80 stone
fill ~389 ~64 ~80 ~399 ~66 ~80 dirt
fill ~389 ~67 ~80 ~399 ~67 ~80 grass_block
fill ~384 ~60 ~81 ~390 ~62 ~81 stone
fill ~384 ~63 ~81 ~390 ~65 ~81 dirt
fill ~384 ~66 ~81 ~390 ~66 ~81 grass_block
fill ~391 ~60 ~81 ~392 ~63 ~81 stone
fill ~391 ~64 ~81 ~392 ~66 ~81 dirt
fill ~391 ~67 ~81 ~392 ~67 ~81 grass_block
fill ~393 ~60 ~81 ~394 ~62 ~81 stone
fill ~393 ~63 ~81 ~394 ~65 ~81 dirt
fill ~393 ~66 ~81 ~394 ~66 ~81 grass_block
fill ~395 ~60 ~81 ~399 ~63 ~81 stone
fill ~395 ~64 ~81 ~399 ~66 ~81 dirt
fill ~395 ~67 ~81 ~399 ~67 ~81 grass_block
fill ~384 ~60 ~82 ~395 ~62 ~82 stone
fill ~384 ~63 ~82 ~395 ~65 ~82 dirt
fill ~384 ~66 ~82 ~395 ~66 ~82 grass_block
fill ~396 ~60 ~82 ~399 ~63 ~82 stone
fill ~396 ~64 ~82 ~399 ~66 ~82 dirt
fill ~396 ~67 ~82 ~399 ~67 ~82 grass_block
fill ~384 ~60 ~83 ~384 ~63 ~83 stone
fill ~384 ~64 ~83 ~384 ~66 ~83 dirt
fill ~384 ~67 ~83 ~384 ~67 ~83 grass_block
fill ~385 ~60 ~83 ~399 ~62 ~83 stone
fill ~385 ~63 ~83 ~399 ~65 ~83 dirt
fill ~385 ~66 ~83 ~399 ~66 ~83 grass_block
fill ~384 ~60 ~84 ~386 ~63 ~84 stone
fill ~384 ~64 ~84 ~386 ~66 ~84 dirt
fill ~384 ~67 ~84 ~386 ~67 ~84 grass_block
fill ~387 ~60 ~84 ~391 ~62 ~84 stone
fill ~387 ~63 ~84 ~391 ~65 ~84 dirt
fill ~387 ~66 ~84 ~391 ~66 ~84 grass_block
fill ~392 ~60 ~84 ~395 ~61 ~84 stone
fill ~392 ~62 ~84 ~395 ~64 ~84 dirt
fill ~392 ~65 ~84 ~395 ~65 ~84 grass_block
fill ~396 ~60 ~84 ~399 ~62 ~84 stone
fill ~396 ~63 ~84 ~399 ~65 ~84 dirt
fill ~396 ~66 ~84 ~399 ~66 ~84 grass_block
fill ~384 ~60 ~85 ~385 ~63 ~85 stone
fill ~384 ~64 ~85 ~385 ~66 ~85 dirt
fill ~384 ~67 ~85 ~385 ~67 ~85 grass_block
fill ~386 ~60 ~85 ~391 ~62 ~85 stone
fill ~386 ~63 ~85 ~391 ~65 ~85 dirt
fill ~386 ~66 ~85 ~391 ~66 ~85 grass_block
fill ~392 ~60 ~85 ~395 ~61 ~85 stone
fill ~392 ~62 ~85 ~395 ~64 ~85 dirt
fill ~392 ~65 ~85 ~395 ~65 ~85 grass_block
fill ~396 ~60 ~85 ~397 ~62 ~85 stone
fill ~396 ~63 ~85 ~397 ~65 ~85 dirt
fill ~396 ~66 ~85 ~397 ~66 ~85 grass_block
fill ~398 ~60 ~85 ~398 ~61 ~85 stone
fill ~398 ~62 ~85 ~398 ~64 ~85 dirt
fill ~398 ~65 ~85 ~398 ~65 ~85 grass_block
fill ~399 ~60 ~85 ~399 ~62 ~85 stone
fill ~399 ~63 ~85 ~399 ~65 ~85 dirt
fill ~399 ~66 ~85 ~399 ~66 ~85 grass_block
fill ~384 ~60 ~86 ~385 ~63 ~86 stone
fill ~384 ~64 ~86 ~385 ~66 ~86 dirt
fill ~384 ~67 ~86 ~385 ~67 ~86 grass_block
fill ~386 ~60 ~86 ~388 ~62 ~86 stone
fill ~386 ~63 ~86 ~388 ~65 ~86 dirt
fill ~386 ~66 ~86 ~388 ~66 ~86 grass_block
fill ~389 ~60 ~86 ~390 ~63 ~86 stone
fill ~389 ~64 ~86 ~390 ~66 ~86 dirt
fill ~389 ~67 ~86 ~390 ~67 ~86 grass_block
fill ~391 ~60 ~86 ~396 ~62 ~86 stone
fill ~391 ~63 ~86 ~396 ~65 ~86 dirt
fill ~391 ~66 ~86 ~396 ~66 ~86 grass_block
fill ~397 ~60 ~86 ~399 ~61 ~86 stone
fill ~397 ~62 ~86 ~399 ~64 ~86 dirt
fill ~397 ~65 ~86 ~399 ~65 ~86 grass_block
fill ~384 ~60 ~87 ~384 ~64 ~87 stone
fill ~384 ~65 ~87 ~384 ~67 ~87 dirt
fill ~384 ~68 ~87 ~384 ~68 ~87 grass_block
fill ~385 ~60 ~87 ~388 ~63 ~87 stone
fill ~385 ~64 ~87 ~388 ~66 ~87 dirt
fill ~385 ~67 ~87 ~388 ~67 ~87 grass_block
fill ~389 ~60 ~87 ~389 ~64 ~87 stone
fill ~389 ~65 ~87 ~389 ~67 ~87 dirt
fill ~389 ~68 ~87 ~389 ~68 ~87 grass_block
fill ~390 ~60 ~87 ~395 ~63 ~87 stone
fill ~390 ~64 ~87 ~395 ~66 ~87 dirt
fill ~390 ~67 ~87 ~395 ~67 ~87 grass_block
fill ~396 ~60 ~87 ~397 ~62 ~87 stone
fill ~396 ~63 ~87 ~397 ~65 ~87 dirt
fill ~396 ~66 ~87 ~397 ~66 ~87 grass_block
fill ~398 ~60 ~87 ~399 ~61 ~87 stone
fill ~398 ~62 ~87 ~399 ~64 ~87 dirt
fill ~398 ~65 ~87 ~399 ~65 ~87 grass_block
fill ~384 ~60 ~88 ~384 ~65 ~88 stone
fill ~384 ~66 ~88 ~384 ~68 ~88 dirt
fill ~384 ~69 ~88 ~384 ~69 ~88 grass_block
fill ~385 ~60 ~88 ~386 ~64 ~88 stone
fill ~385 ~65 ~88 ~386 ~67 ~88 dirt
fill ~385 ~68 ~88 ~386 ~68 ~88 grass_block
fill ~387 ~60 ~88 ~389 ~65 ~88 stone
fill ~387 ~66 ~88 ~389 ~68 ~88 dirt
fill ~387 ~69 ~88 ~389 ~69 ~88 grass_block
fill ~390 ~60 ~88 ~391 ~64 ~88 stone
fill ~390 ~65 ~88 ~391 ~67 ~88 dirt
fill ~390 ~68 ~88 ~391 ~68 ~88 grass_block
fill ~392 ~60 ~88 ~394 ~63 ~88 stone
fill ~392 ~64 ~88 ~394 ~66 ~88 dirt
fill ~392 ~67 ~88 ~394 ~67 ~88 grass_block
fill ~395 ~60 ~88 ~399 ~62 ~88 stone
fill ~395 ~63 ~88 ~399 ~65 ~88 dirt
fill ~395 ~66 ~88 ~399 ~66 ~88 grass_block
fill ~384 ~60 ~89 ~390 ~65 ~89 stone
fill ~384 ~66 ~89 ~390 ~68 ~89 dirt
fill ~384 ~69 ~89 ~390 ~69 ~89 grass_block
fill ~391 ~60 ~89 ~391 ~64 ~89 stone
fill ~391 ~65 ~89 ~391 ~67 ~89 dirt
fill ~391 ~68 ~89 ~391 ~68 ~89 grass_block
fill ~392 ~60 ~89 ~393 ~63 ~89 stone
fill ~392 ~64 ~89 ~393 ~66 ~89 dirt
fill ~392 ~67 ~89 ~393 ~67 ~89 grass_block
fill ~394 ~60 ~89 ~399 ~62 ~89 stone
fill ~394 ~63 ~89 ~399 ~65 ~89 dirt
fill ~394 ~66 ~89 ~399 ~66 ~89 grass_block
fill ~384 ~60 ~90 ~386 ~66 ~90 stone
fill ~384 ~67 ~90 ~386 ~69 ~90 dirt
fill ~384 ~70 ~90 ~386 ~70 ~90 grass_block
fill ~387 ~60 ~90 ~390 ~65 ~90 stone
fill ~387 ~66 ~90 ~390 ~68 ~90 dirt
fill ~387 ~69 ~90 ~390 ~69 ~90 grass_block
fill ~391 ~60 ~90 ~392 ~64 ~90 stone
fill ~391 ~65 ~90 ~392 ~67 ~90 dirt
fill ~391 ~68 ~90 ~392 ~68 ~90 grass_block
fill ~393 ~60 ~90 ~394 ~63 ~90 stone
fill ~393 ~64 ~90 ~394 ~66 ~90 dirt
fill ~393 ~67 ~90 ~394 ~67 ~90 grass_block
fill ~395 ~60 ~90 ~395 ~62 ~90 stone
fill ~395 ~63 ~90 ~395 ~65 ~90 dirt
fill ~395 ~66 ~90 ~395 ~66 ~90 grass_block
fill ~396 ~60 ~90 ~399 ~63 ~90 stone
fill ~396 ~64 ~90 ~399 ~66 ~90 dirt
fill ~396 ~67 ~90 ~399 ~67 ~90 grass_block
fill ~384 ~60 ~91 ~390 ~65 ~91 stone
fill ~384 ~66 ~91 ~390 ~68 ~91 dirt
fill ~384 ~69 ~91 ~390 ~69 ~91 grass_block
fill ~391 ~60 ~91 ~392 ~64 ~91 stone
fill ~391 ~65 ~91 ~392 ~67 ~91 dirt
fill ~391 ~68 ~91 ~392 ~68 ~91 grass_block
fill ~393 ~60 ~91 ~397 ~63 ~91 stone
fill ~393 ~64 ~91 ~397 ~66 ~91 dirt
fill ~393 ~67 ~91 ~397 ~67 ~91 grass_block
fill ~398 ~60 ~91 ~399 ~64 ~91 stone
fill ~398 ~65 ~91 ~399 ~67 ~91 dirt
fill ~398 ~68 ~91 ~399 ~68 ~91 grass_block
fill ~384 ~60 ~92 ~391 ~65 ~92 stone
fill ~384 ~66 ~92 ~391 ~68 ~92 dirt
fill ~384 ~69 ~92 ~391 ~69 ~92 grass_block
fill ~392 ~60 ~92 ~395 ~64 ~92 stone
fill ~392 ~65 ~92 ~395 ~67 ~92 dirt
fill ~392 ~68 ~92 ~395 ~68 ~92 grass_block
fill ~396 ~60 ~92 ~396 ~63 ~92 stone
fill ~396 ~64 ~92 ~396 ~66 ~92 dirt
fill ~396 ~67 ~92 ~396 ~67 ~92 grass_block
fill ~397 ~60 ~92 ~399 ~64 ~92 stone
fill ~397 ~65 ~92 ~399 ~67 ~92 dirt
fill ~397 ~68 ~92 ~399 ~68 ~92 grass_block
fill ~384 ~60 ~93 ~393 ~65 ~93 stone
fill ~384 ~66 ~93 ~393 ~68 ~93 dirt
fill ~384 ~69 ~93 ~393 ~69 ~93 grass_block
fill ~394 ~60 ~93 ~397 ~64 ~93 stone
fill ~394 ~65 ~93 ~397 ~67 ~93 dirt
fill ~394 ~68 ~93 ~397 ~68 ~93 grass_block
fill ~398 ~60 ~93 ~399 ~65 ~93 stone
fill ~398 ~66 ~93 ~399 ~68 ~93 dirt
fill ~398 ~69 ~93 ~399 ~69 ~93 grass_block
fill ~384 ~60 ~94 ~390 ~65 ~94 stone
fill ~384 ~66 ~94 ~390 ~68 ~94 dirt
fill ~384 ~69 ~94 ~390 ~69 ~94 grass_block
fill ~391 ~60 ~94 ~393 ~64 ~94 stone
fill ~391 ~65 ~94 ~393 ~67 ~94 dirt
fill ~391 ~68 ~94 ~393 ~68 ~94 grass_block
fill ~394 ~60 ~94 ~394 ~65 ~94 stone
fill ~394 ~66 ~94 ~394 ~68 ~94 dirt
fill ~394 ~69 ~94 ~394 ~69 ~94 grass_block
fill ~395 ~60 ~94 ~397 ~64 ~94 stone
fill ~395 ~65 ~94 ~397 ~67 ~94 dirt
fill ~395 ~68 ~94 ~397 ~68 ~94 grass_block
fill ~398 ~60 ~94 ~399 ~65 ~94 stone
fill ~398 ~66 ~94 ~399 ~68 ~94 dirt
fill ~398 ~69 ~94 ~399 ~69 ~94 grass_block
fill ~384 ~60 ~95 ~390 ~65 ~95 stone
fill ~384 ~66 ~95 ~390 ~68 ~95 dirt
fill ~384 ~69 ~95 ~390 ~69 ~95 grass_block
fill ~391 ~60 ~95 ~399 ~64 ~95 stone
fill ~391 ~65 ~95 ~399 ~67 ~95 dirt
fill ~391 ~68 ~95 ~399 ~68 ~95 grass_block