fill ~32 ~60 ~112 ~36 ~68 ~112 stone
fill ~32 ~69 ~112 ~36 ~71 ~112 dirt
fill ~32 ~72 ~112 ~36 ~72 ~112 grass_block
fill ~37 ~60 ~112 ~38 ~67 ~112 stone
fill ~37 ~68 ~112 ~38 ~70 ~112 dirt
fill ~37 ~71 ~112 ~38 ~71 ~112 grass_block
fill ~39 ~60 ~112 ~41 ~66 ~112 stone
fill ~39 ~67 ~112 ~41 ~69 ~112 dirt
fill ~39 ~70 ~112 ~41 ~70 ~112 grass_block
fill ~42 ~60 ~112 ~44 ~65 ~112 stone
fill ~42 ~66 ~112 ~44 ~68 ~112 dirt
fill ~42 ~69 ~112 ~44 ~69 ~112 grass_block
fill ~45 ~60 ~112 ~47 ~64 ~112 stone
fill ~45 ~65 ~112 ~47 ~67 ~112 dirt
fill ~45 ~68 ~112 ~47 ~68 ~112 grass_block
fill ~32 ~60 ~113 ~37 ~68 ~113 stone
fill ~32 ~69 ~113 ~37 ~71 ~113 dirt
fill ~32 ~72 ~113 ~37 ~72 ~113 grass_block
fill ~38 ~60 ~113 ~39 ~67 ~113 stone
fill ~38 ~68 ~113 ~39 ~70 ~113 dirt
fill ~38 ~71 ~113 ~39 ~71 ~113 grass_block
fill ~40 ~60 ~113 ~41 ~66 ~113 stone
fill ~40 ~67 ~113 ~41 ~69 ~113 dirt
fill ~40 ~70 ~113 ~41 ~70 ~113 grass_block
fill ~42 ~60 ~113 ~45 ~65 ~113 stone
fill ~42 ~66 ~113 ~45 ~68 ~113 dirt
fill ~42 ~69 ~113 ~45 ~69 ~113 grass_block
fill ~46 ~60 ~113 ~47 ~64 ~113 stone
fill ~46 ~65 ~113 ~47 ~67 ~113 dirt
fill ~46 ~68 ~113 ~47 ~68 ~113 grass_block
fill ~32 ~60 ~114 ~32 ~68 ~114 stone
fill ~32 ~69 ~114 ~32 ~71 ~114 dirt
fill ~32 ~72 ~114 ~32 ~72 ~114 grass_block
fill ~33 ~60 ~114 ~35 ~67 ~114 stone
fill ~33 ~68 ~114 ~35 ~70 ~114 dirt
fill ~33 ~71 ~114 ~35 ~71 ~114 grass_block
fill ~36 ~60 ~114 ~38 ~68 ~114 stone
fill ~36 ~69 ~114 ~38 ~71 ~114 dirt
fill ~36 ~72 ~114 ~38 ~72 ~114 grass_block
fill ~39 ~60 ~114 ~39 ~67 ~114 stone
fill ~39 ~68 ~114 ~39 ~70 ~114 dirt
fill ~39 ~71 ~114 ~39 ~71 ~114 grass_block
fill ~40 ~60 ~114 ~43 ~66 ~114 stone
fill ~40 ~67 ~114 ~43 ~69 ~114 dirt
fill ~40 ~70 ~114 ~43 ~70 ~114 grass_block
fill ~44 ~60 ~114 ~46 ~65 ~114 stone
fill ~44 ~66 ~114 ~46 ~68 ~114 dirt
fill ~44 ~69 ~114 ~46 ~69 ~114 grass_block
fill ~47 ~60 ~114 ~47 ~64 ~114 stone
fill ~47 ~65 ~114 ~47 ~67 ~114 dirt
fill ~47 ~68 ~114 ~47 ~68 ~114 grass_block
fill ~32 ~60 ~115 ~37 ~67 ~115 stone
fill ~32 ~68 ~115 ~37 ~70 ~115 dirt
fill ~32 ~71 ~115 ~37 ~71 ~115 grass_block
fill ~38 ~60 ~115 ~39 ~68 ~115 stone
fill ~38 ~69 ~115 ~39 ~71 ~115 dirt
fill ~38 ~72 ~115 ~39 ~72 ~115 grass_block
fill ~40 ~60 ~115 ~40 ~67 ~115 stone
fill ~40 ~68 ~115 ~40 ~70 ~115 dirt
fill ~40 ~71 ~115 ~40 ~71 ~115 grass_block
fill ~41 ~60 ~115 ~43 ~66 ~115 stone
fill ~41 ~67 ~115 ~43 ~69 ~115 dirt
fill ~41 ~70 ~115 ~43 ~70 ~115 grass_block
fill ~44 ~60 ~115 ~45 ~65 ~115 stone
fill ~44 ~66 ~115 ~45 ~68 ~115 dirt
fill ~44 ~69 ~115 ~45 ~69 ~115 grass_block
fill ~46 ~60 ~115 ~47 ~64 ~115 stone
fill ~46 ~65 ~115 ~47 ~67 ~115 dirt
fill ~46 ~68 ~115 ~47 ~68 ~115 grass_block
fill ~32 ~60 ~116 ~38 ~67 ~116 stone
fill ~32 ~68 ~116 ~38 ~70 ~116 dirt
fill ~32 ~71 ~116 ~38 ~71 ~116 grass_block
fill ~39 ~60 ~116 ~39 ~68 ~116 stone
fill ~39 ~69 ~116 ~39 ~71 ~116 dirt
fill ~39 ~72 ~116 ~39 ~72 ~116 grass_block
fill ~40 ~60 ~116 ~41 ~67 ~116 stone
fill ~40 ~68 ~116 ~41 ~70 ~116 dirt
fill ~40 ~71 ~116 ~41 ~71 ~116 grass_block
fill ~42 ~60 ~116 ~43 ~66 ~116 stone
fill ~42 ~67 ~116 ~43 ~69 ~116 dirt
fill ~42 ~70 ~116 ~43 ~70 ~116 grass_block
fill ~44 ~60 ~116 ~46 ~65 ~116 stone
fill ~44 ~66 ~116 ~46 ~68 ~116 dirt
fill ~44 ~69 ~116 ~46 ~69 ~116 grass_block
fill ~47 ~60 ~116 ~47 ~64 ~116 stone
fill ~47 ~65 ~116 ~47 ~67 ~116 dirt
fill ~47 ~68 ~116 ~47 ~68 ~116 grass_block
fill ~32 ~60 ~117 ~32 ~67 ~117 stone
fill ~32 ~68 ~117 ~32 ~70 ~117 dirt
fill ~32 ~71 ~117 ~32 ~71 ~117 grass_block
fill ~33 ~60 ~117 ~36 ~66 ~117 stone
fill ~33 ~67 ~117 ~36 ~69 ~117 dirt
fill ~33 ~70 ~117 ~36 ~70 ~117 grass_block
fill ~37 ~60 ~117 ~41 ~67 ~117 stone
fill ~37 ~68 ~117 ~41 ~70 ~117 dirt
fill ~37 ~71 ~117 ~41 ~71 ~117 grass_block
fill ~42 ~60 ~117 ~44 ~66 ~117 stone
fill ~42 ~67 ~117 ~44 ~69 ~117 dirt
fill ~42 ~70 ~117 ~44 ~70 ~117 grass_block
fill ~45 ~60 ~117 ~47 ~65 ~117 stone
fill ~45 ~66 ~117 ~47 ~68 ~117 dirt
fill ~45 ~69 ~117 ~47 ~69 ~117 grass_block
fill ~32 ~60 ~118 ~37 ~66 ~118 stone
fill ~32 ~67 ~118 ~37 ~69 ~118 dirt
fill ~32 ~70 ~118 ~37 ~70 ~118 grass_block
fill ~38 ~60 ~118 ~41 ~67 ~118 stone
fill ~38 ~68 ~118 ~41 ~70 ~118 dirt
fill ~38 ~71 ~118 ~41 ~71 ~118 grass_block
fill ~42 ~60 ~118 ~44 ~66 ~118 stone
fill ~42 ~67 ~118 ~44 ~69 ~118 dirt
fill ~42 ~70 ~118 ~44 ~70 ~118 grass_block
fill ~45 ~60 ~118 ~47 ~65 ~118 stone
fill ~45 ~66 ~118 ~47 ~68 ~118 dirt
fill ~45 ~69 ~118 ~47 ~69 ~118 grass_block
fill ~32 ~60 ~119 ~37 ~66 ~119 stone
fill ~32 ~67 ~119 ~37 ~69 ~119 dirt
fill ~32 ~70 ~119 ~37 ~70 ~119 grass_block
fill ~38 ~60 ~119 ~43 ~67 ~119 stone
fill ~38 ~68 ~119 ~43 ~70 ~119 dirt
fill ~38 ~71 ~119 ~43 ~71 ~119 grass_block
fill ~44 ~60 ~119 ~46 ~66 ~119 stone
fill ~44 ~67 ~119 ~46 ~69 ~119 dirt
fill ~44 ~70 ~119 ~46 ~70 ~119 grass_block
fill ~47 ~60 ~119 ~47 ~65 ~119 stone
fill ~47 ~66 ~119 ~47 ~68 ~119 dirt
fill ~47 ~69 ~119 ~47 ~69 ~119 grass_block
fill ~32 ~60 ~120 ~33 ~65 ~120 stone
fill ~32 ~66 ~120 ~33 ~68 ~120 dirt
fill ~32 ~69 ~120 ~33 ~69 ~120 grass_block
fill ~34 ~60 ~120 ~38 ~66 ~120 stone
fill ~34 ~67 ~120 ~38 ~69 ~120 dirt
fill ~34 ~70 ~120 ~38 ~70 ~120 grass_block
fill ~39 ~60 ~120 ~44 ~67 ~120 stone
fill ~39 ~68 ~120 ~44 ~70 ~120 dirt
fill ~39 ~71 ~120 ~44 ~71 ~120 grass_block
fill ~45 ~60 ~120 ~47 ~66 ~120 stone
fill ~45 ~67 ~120 ~47 ~69 ~120 dirt
fill ~45 ~70 ~120 ~47 ~70 ~120 grass_block
fill ~32 ~60 ~121 ~34 ~65 ~121 stone
fill ~32 ~66 ~121 ~34 ~68 ~121 dirt
fill ~32 ~69 ~121 ~34 ~69 ~121 grass_block
fill ~35 ~60 ~121 ~42 ~66 ~121 stone
fill ~35 ~67 ~121 ~42 ~69 ~121 dirt
fill ~35 ~70 ~121 ~42 ~70 ~121 grass_block
fill ~43 ~60 ~121 ~44 ~67 ~121 stone
fill ~43 ~68 ~121 ~44 ~70 ~121 dirt
fill ~43 ~71 ~121 ~44 ~71 ~121 grass_block
fill ~45 ~60 ~121 ~47 ~66 ~121 stone
fill ~45 ~67 ~121 ~47 ~69 ~121 dirt
fill ~45 ~70 ~121 ~47 ~70 ~121 grass_block
fill ~32 ~60 ~122 ~34 ~65 ~122 stone
fill ~32 ~66 ~122 ~34 ~68 ~122 dirt
fill ~32 ~69 ~122 ~34 ~69 ~122 grass_block
fill ~35 ~60 ~122 ~47 ~66 ~122 stone
fill ~35 ~67 ~122 ~47 ~69 ~122 dirt
fill ~35 ~70 ~122 ~47 ~70 ~122 grass_block
fill ~32 ~60 ~123 ~35 ~65 ~123 stone
fill ~32 ~66 ~123 ~35 ~68 ~123 dirt
fill ~32 ~69 ~123 ~35 ~69 ~123 grass_block
fill ~36 ~60 ~123 ~47 ~66 ~123 stone
fill ~36 ~67 ~123 ~47 ~69 ~123 dirt
fill ~36 ~70 ~123 ~47 ~70 ~123 grass_block
fill ~32 ~60 ~124 ~38 ~65 ~124 stone
fill ~32 ~66 ~124 ~38 ~68 ~124 dirt
fill ~32 ~69 ~124 ~38 ~69 ~124 grass_block
fill ~39 ~60 ~124 ~42 ~66 ~124 stone
fill ~39 ~67 ~124 ~42 ~69 ~124 dirt
fill ~39 ~70 ~124 ~42 ~70 ~124 grass_block
fill ~43 ~60 ~124 ~45 ~65 ~124 stone
fill ~43 ~66 ~124 ~45 ~68 ~124 dirt
fill ~43 ~69 ~124 ~45 ~69 ~124 grass_block
fill ~46 ~60 ~124 ~46 ~66 ~124 stone
fill ~46 ~67 ~124 ~46 ~69 ~124 dirt
fill ~46 ~70 ~124 ~46 ~70 ~124 grass_block
fill ~47 ~60 ~124 ~47 ~65 ~124 stone
fill ~47 ~66 ~124 ~47 ~68 ~124 dirt
fill ~47 ~69 ~124 ~47 ~69 ~124 grass_block
fill ~32 ~60 ~125 ~32 ~64 ~125 stone
fill ~32 ~65 ~125 ~32 ~67 ~125 dirt
fill ~32 ~68 ~125 ~32 ~68 ~125 grass_block
fill ~33 ~60 ~125 ~47 ~65 ~125 stone
fill ~33 ~66 ~125 ~47 ~68 ~125 dirt
fill ~33 ~69 ~125 ~47 ~69 ~125 grass_block
fill ~32 ~60 ~126 ~35 ~64 ~126 stone
fill ~32 ~65 ~126 ~35 ~67 ~126 dirt
fill ~32 ~68 ~126 ~35 ~68 ~126 grass_block
fill ~36 ~60 ~126 ~47 ~65 ~126 stone
fill ~36 ~66 ~126 ~47 ~68 ~126 dirt
fill ~36 ~69 ~126 ~47 ~69 ~126 grass_block
fill ~32 ~60 ~127 ~39 ~64 ~127 stone
fill ~32 ~65 ~127 ~39 ~67 ~127 dirt
fill ~32 ~68 ~127 ~39 ~68 ~127 grass_block
fill ~40 ~60 ~127 ~47 ~65 ~127 stone
fill ~40 ~66 ~127 ~47 ~68 ~127 dirt
fill ~40 ~69 ~127 ~47 ~69 ~127 grass_block