fill ~224 ~60 ~128 ~227 ~63 ~128 stone
fill ~224 ~64 ~128 ~227 ~66 ~128 dirt
fill ~224 ~67 ~128 ~227 ~67 ~128 grass_block
fill ~228 ~60 ~128 ~235 ~64 ~128 stone
fill ~228 ~65 ~128 ~235 ~67 ~128 dirt
fill ~228 ~68 ~128 ~235 ~68 ~128 grass_block
fill ~236 ~60 ~128 ~238 ~63 ~128 stone
fill ~236 ~64 ~128 ~238 ~66 ~128 dirt
fill ~236 ~67 ~128 ~238 ~67 ~128 grass_block
fill ~239 ~60 ~128 ~239 ~64 ~128 stone
fill ~239 ~65 ~128 ~239 ~67 ~128 dirt
fill ~239 ~68 ~128 ~239 ~68 ~128 grass_block
fill ~224 ~60 ~129 ~224 ~62 ~129 stone
fill ~224 ~63 ~129 ~224 ~65 ~129 dirt
fill ~224 ~66 ~129 ~224 ~66 ~129 grass_block
fill ~225 ~60 ~129 ~228 ~63 ~129 stone
fill ~225 ~64 ~129 ~228 ~66 ~129 dirt
fill ~225 ~67 ~129 ~228 ~67 ~129 grass_block
fill ~229 ~60 ~129 ~235 ~64 ~129 stone
fill ~229 ~65 ~129 ~235 ~67 ~129 dirt
fill ~229 ~68 ~129 ~235 ~68 ~129 grass_block
fill ~236 ~60 ~129 ~239 ~63 ~129 stone
fill ~236 ~64 ~129 ~239 ~66 ~129 dirt
fill ~236 ~67 ~129 ~239 ~67 ~129 grass_block
fill ~224 ~60 ~130 ~224 ~62 ~130 stone
fill ~224 ~63 ~130 ~224 ~65 ~130 dirt
fill ~224 ~66 ~130 ~224 ~66 ~130 grass_block
fill ~225 ~60 ~130 ~228 ~63 ~130 stone
fill ~225 ~64 ~130 ~228 ~66 ~130 dirt
fill ~225 ~67 ~130 ~228 ~67 ~130 grass_block
fill ~229 ~60 ~130 ~236 ~64 ~130 stone
fill ~229 ~65 ~130 ~236 ~67 ~130 dirt
fill ~229 ~68 ~130 ~236 ~68 ~130 grass_block
fill ~237 ~60 ~130 ~239 ~63 ~130 stone
fill ~237 ~64 ~130 ~239 ~66 ~130 dirt
fill ~237 ~67 ~130 ~239 ~67 ~130 grass_block
fill ~224 ~60 ~131 ~224 ~62 ~131 stone
fill ~224 ~63 ~131 ~224 ~65 ~131 dirt
fill ~224 ~66 ~131 ~224 ~66 ~131 grass_block
fill ~225 ~60 ~131 ~231 ~63 ~131 stone
fill ~225 ~64 ~131 ~231 ~66 ~131 dirt
fill ~225 ~67 ~131 ~231 ~67 ~131 grass_block
fill ~232 ~60 ~131 ~235 ~64 ~131 stone
fill ~232 ~65 ~131 ~235 ~67 ~131 dirt
fill ~232 ~68 ~131 ~235 ~68 ~131 grass_block
fill ~236 ~60 ~131 ~239 ~63 ~131 stone
fill ~236 ~64 ~131 ~239 ~66 ~131 dirt
fill ~236 ~67 ~131 ~239 ~67 ~131 grass_block
fill ~224 ~60 ~132 ~224 ~62 ~132 stone
fill ~224 ~63 ~132 ~224 ~65 ~132 dirt
fill ~224 ~66 ~132 ~224 ~66 ~132 grass_block
fill ~225 ~60 ~132 ~232 ~63 ~132 stone
fill ~225 ~64 ~132 ~232 ~66 ~132 dirt
fill ~225 ~67 ~132 ~232 ~67 ~132 grass_block
fill ~233 ~60 ~132 ~236 ~64 ~132 stone
fill ~233 ~65 ~132 ~236 ~67 ~132 dirt
fill ~233 ~68 ~132 ~236 ~68 ~132 grass_block
fill ~237 ~60 ~132 ~239 ~63 ~132 stone
fill ~237 ~64 ~132 ~239 ~66 ~132 dirt
fill ~237 ~67 ~132 ~239 ~67 ~132 grass_block
fill ~224 ~60 ~133 ~225 ~62 ~133 stone
fill ~224 ~63 ~133 ~225 ~65 ~133 dirt
fill ~224 ~66 ~133 ~225 ~66 ~133 grass_block
fill ~226 ~60 ~133 ~234 ~63 ~133 stone
fill ~226 ~64 ~133 ~234 ~66 ~133 dirt
fill ~226 ~67 ~133 ~234 ~67 ~133 grass_block
fill ~235 ~60 ~133 ~235 ~64 ~133 stone
fill ~235 ~65 ~133 ~235 ~67 ~133 dirt
fill ~235 ~68 ~133 ~235 ~68 ~133 grass_block
fill ~236 ~60 ~133 ~239 ~63 ~133 stone
fill ~236 ~64 ~133 ~239 ~66 ~133 dirt
fill ~236 ~67 ~133 ~239 ~67 ~133 grass_block
fill ~224 ~60 ~134 ~225 ~62 ~134 stone
fill ~224 ~63 ~134 ~225 ~65 ~134 dirt
fill ~224 ~66 ~134 ~225 ~66 ~134 grass_block
fill ~226 ~60 ~134 ~239 ~63 ~134 stone
fill ~226 ~64 ~134 ~239 ~66 ~134 dirt
fill ~226 ~67 ~134 ~239 ~67 ~134 grass_block
fill ~224 ~60 ~135 ~229 ~62 ~135 stone
fill ~224 ~63 ~135 ~229 ~65 ~135 dirt
fill ~224 ~66 ~135 ~229 ~66 ~135 grass_block
fill ~230 ~60 ~135 ~239 ~63 ~135 stone
fill ~230 ~64 ~135 ~239 ~66 ~135 dirt
fill ~230 ~67 ~135 ~239 ~67 ~135 grass_block
fill ~224 ~60 ~136 ~231 ~62 ~136 stone
fill ~224 ~63 ~136 ~231 ~65 ~136 dirt
fill ~224 ~66 ~136 ~231 ~66 ~136 grass_block
fill ~232 ~60 ~136 ~239 ~63 ~136 stone
fill ~232 ~64 ~136 ~239 ~66 ~136 dirt
fill ~232 ~67 ~136 ~239 ~67 ~136 grass_block
fill ~224 ~60 ~137 ~232 ~62 ~137 stone
fill ~224 ~63 ~137 ~232 ~65 ~137 dirt
fill ~224 ~66 ~137 ~232 ~66 ~137 grass_block
fill ~233 ~60 ~137 ~233 ~63 ~137 stone
fill ~233 ~64 ~137 ~233 ~66 ~137 dirt
fill ~233 ~67 ~137 ~233 ~67 ~137 grass_block
fill ~234 ~60 ~137 ~234 ~62 ~137 stone
fill ~234 ~63 ~137 ~234 ~65 ~137 dirt
fill ~234 ~66 ~137 ~234 ~66 ~137 grass_block
fill ~235 ~60 ~137 ~239 ~63 ~137 stone
fill ~235 ~64 ~137 ~239 ~66 ~137 dirt
fill ~235 ~67 ~137 ~239 ~67 ~137 grass_block
fill ~224 ~60 ~138 ~237 ~62 ~138 stone
fill ~224 ~63 ~138 ~237 ~65 ~138 dirt
fill ~224 ~66 ~138 ~237 ~66 ~138 grass_block
fill ~238 ~60 ~138 ~239 ~63 ~138 stone
fill ~238 ~64 ~138 ~239 ~66 ~138 dirt
fill ~238 ~67 ~138 ~239 ~67 ~138 grass_block
fill ~224 ~60 ~139 ~239 ~62 ~139 stone
fill ~224 ~63 ~139 ~239 ~65 ~139 dirt
fill ~224 ~66 ~139 ~239 ~66 ~139 grass_block
fill ~224 ~60 ~140 ~239 ~62 ~140 stone
fill ~224 ~63 ~140 ~239 ~65 ~140 dirt
fill ~224 ~66 ~140 ~239 ~66 ~140 grass_block
fill ~224 ~60 ~141 ~225 ~63 ~141 stone
fill ~224 ~64 ~141 ~225 ~66 ~141 dirt
fill ~224 ~67 ~141 ~225 ~67 ~141 grass_block
fill ~226 ~60 ~141 ~239 ~62 ~141 stone
fill ~226 ~63 ~141 ~239 ~65 ~141 dirt
fill ~226 ~66 ~141 ~239 ~66 ~141 grass_block
fill ~224 ~60 ~142 ~227 ~63 ~142 stone
fill ~224 ~64 ~142 ~227 ~66 ~142 dirt
fill ~224 ~67 ~142 ~227 ~67 ~142 grass_block
fill ~228 ~60 ~142 ~233 ~62 ~142 stone
fill ~228 ~63 ~142 ~233 ~65 ~142 dirt
fill ~228 ~66 ~142 ~233 ~66 ~142 grass_block
fill ~234 ~60 ~142 ~234 ~61 ~142 stone
fill ~234 ~62 ~142 ~234 ~64 ~142 dirt
fill ~234 ~65 ~142 ~234 ~65 ~142 grass_block
fill ~235 ~60 ~142 ~239 ~62 ~142 stone
fill ~235 ~63 ~142 ~239 ~65 ~142 dirt
fill ~235 ~66 ~142 ~239 ~66 ~142 grass_block
fill ~224 ~60 ~143 ~224 ~64 ~143 stone
fill ~224 ~65 ~143 ~224 ~67 ~143 dirt
fill ~224 ~68 ~143 ~224 ~68 ~143 grass_block
fill ~225 ~60 ~143 ~228 ~63 ~143 stone
fill ~225 ~64 ~143 ~228 ~66 ~143 dirt
fill ~225 ~67 ~143 ~228 ~67 ~143 grass_block
fill ~229 ~60 ~143 ~239 ~62 ~143 stone
fill ~229 ~63 ~143 ~239 ~65 ~143 dirt
fill ~229 ~66 ~143 ~239 ~66 ~143 grass_block