fill ~208 ~60 ~80 ~208 ~65 ~80 stone
fill ~208 ~66 ~80 ~208 ~68 ~80 dirt
fill ~208 ~69 ~80 ~208 ~69 ~80 grass_block
fill ~209 ~60 ~80 ~211 ~66 ~80 stone
fill ~209 ~67 ~80 ~211 ~69 ~80 dirt
fill ~209 ~70 ~80 ~211 ~70 ~80 grass_block
fill ~212 ~60 ~80 ~215 ~67 ~80 stone
fill ~212 ~68 ~80 ~215 ~70 ~80 dirt
fill ~212 ~71 ~80 ~215 ~71 ~80 grass_block
fill ~216 ~60 ~80 ~216 ~66 ~80 stone
fill ~216 ~67 ~80 ~216 ~69 ~80 dirt
fill ~216 ~70 ~80 ~216 ~70 ~80 grass_block
fill ~217 ~60 ~80 ~222 ~67 ~80 stone
fill ~217 ~68 ~80 ~222 ~70 ~80 dirt
fill ~217 ~71 ~80 ~222 ~71 ~80 grass_block
fill ~223 ~60 ~80 ~223 ~66 ~80 stone
fill ~223 ~67 ~80 ~223 ~69 ~80 dirt
fill ~223 ~70 ~80 ~223 ~70 ~80 grass_block
fill ~208 ~60 ~81 ~208 ~65 ~81 stone
fill ~208 ~66 ~81 ~208 ~68 ~81 dirt
fill ~208 ~69 ~81 ~208 ~69 ~81 grass_block
fill ~209 ~60 ~81 ~212 ~66 ~81 stone
fill ~209 ~67 ~81 ~212 ~69 ~81 dirt
fill ~209 ~70 ~81 ~212 ~70 ~81 grass_block
fill ~213 ~60 ~81 ~223 ~67 ~81 stone
fill ~213 ~68 ~81 ~223 ~70 ~81 dirt
fill ~213 ~71 ~81 ~223 ~71 ~81 grass_block
fill ~208 ~60 ~82 ~208 ~65 ~82 stone
fill ~208 ~66 ~82 ~208 ~68 ~82 dirt
fill ~208 ~69 ~82 ~208 ~69 ~82 grass_block
fill ~209 ~60 ~82 ~213 ~66 ~82 stone
fill ~209 ~67 ~82 ~213 ~69 ~82 dirt
fill ~209 ~70 ~82 ~213 ~70 ~82 grass_block
fill ~214 ~60 ~82 ~223 ~67 ~82 stone
fill ~214 ~68 ~82 ~223 ~70 ~82 dirt
fill ~214 ~71 ~82 ~223 ~71 ~82 grass_block
fill ~208 ~60 ~83 ~208 ~65 ~83 stone
fill ~208 ~66 ~83 ~208 ~68 ~83 dirt
fill ~208 ~69 ~83 ~208 ~69 ~83 grass_block
fill ~209 ~60 ~83 ~215 ~66 ~83 stone
fill ~209 ~67 ~83 ~215 ~69 ~83 dirt
fill ~209 ~70 ~83 ~215 ~70 ~83 grass_block
fill ~216 ~60 ~83 ~223 ~67 ~83 stone
fill ~216 ~68 ~83 ~223 ~70 ~83 dirt
fill ~216 ~71 ~83 ~223 ~71 ~83 grass_block
fill ~208 ~60 ~84 ~221 ~66 ~84 stone
fill ~208 ~67 ~84 ~221 ~69 ~84 dirt
fill ~208 ~70 ~84 ~221 ~70 ~84 grass_block
fill ~222 ~60 ~84 ~223 ~67 ~84 stone
fill ~222 ~68 ~84 ~223 ~70 ~84 dirt
fill ~222 ~71 ~84 ~223 ~71 ~84 grass_block
fill ~208 ~60 ~85 ~221 ~66 ~85 stone
fill ~208 ~67 ~85 ~221 ~69 ~85 dirt
fill ~208 ~70 ~85 ~221 ~70 ~85 grass_block
fill ~222 ~60 ~85 ~223 ~67 ~85 stone
fill ~222 ~68 ~85 ~223 ~70 ~85 dirt
fill ~222 ~71 ~85 ~223 ~71 ~85 grass_block
fill ~208 ~60 ~86 ~223 ~66 ~86 stone
fill ~208 ~67 ~86 ~223 ~69 ~86 dirt
fill ~208 ~70 ~86 ~223 ~70 ~86 grass_block
fill ~208 ~60 ~87 ~215 ~66 ~87 stone
fill ~208 ~67 ~87 ~215 ~69 ~87 dirt
fill ~208 ~70 ~87 ~215 ~70 ~87 grass_block
fill ~216 ~60 ~87 ~218 ~65 ~87 stone
fill ~216 ~66 ~87 ~218 ~68 ~87 dirt
fill ~216 ~69 ~87 ~218 ~69 ~87 grass_block
fill ~219 ~60 ~87 ~223 ~66 ~87 stone
fill ~219 ~67 ~87 ~223 ~69 ~87 dirt
fill ~219 ~70 ~87 ~223 ~70 ~87 grass_block
fill ~208 ~60 ~88 ~213 ~66 ~88 stone
fill ~208 ~67 ~88 ~213 ~69 ~88 dirt
fill ~208 ~70 ~88 ~213 ~70 ~88 grass_block
fill ~214 ~60 ~88 ~221 ~65 ~88 stone
fill ~214 ~66 ~88 ~221 ~68 ~88 dirt
fill ~214 ~69 ~88 ~221 ~69 ~88 grass_block
fill ~222 ~60 ~88 ~223 ~66 ~88 stone
fill ~222 ~67 ~88 ~223 ~69 ~88 dirt
fill ~222 ~70 ~88 ~223 ~70 ~88 grass_block
fill ~208 ~60 ~89 ~212 ~66 ~89 stone
fill ~208 ~67 ~89 ~212 ~69 ~89 dirt
fill ~208 ~70 ~89 ~212 ~70 ~89 grass_block
fill ~213 ~60 ~89 ~222 ~65 ~89 stone
fill ~213 ~66 ~89 ~222 ~68 ~89 dirt
fill ~213 ~69 ~89 ~222 ~69 ~89 grass_block
fill ~223 ~60 ~89 ~223 ~66 ~89 stone
fill ~223 ~67 ~89 ~223 ~69 ~89 dirt
fill ~223 ~70 ~89 ~223 ~70 ~89 grass_block
fill ~208 ~60 ~90 ~212 ~66 ~90 stone
fill ~208 ~67 ~90 ~212 ~69 ~90 dirt
fill ~208 ~70 ~90 ~212 ~70 ~90 grass_block
fill ~213 ~60 ~90 ~223 ~65 ~90 stone
fill ~213 ~66 ~90 ~223 ~68 ~90 dirt
fill ~213 ~69 ~90 ~223 ~69 ~90 grass_block
fill ~208 ~60 ~91 ~212 ~66 ~91 stone
fill ~208 ~67 ~91 ~212 ~69 ~91 dirt
fill ~208 ~70 ~91 ~212 ~70 ~91 grass_block
fill ~213 ~60 ~91 ~216 ~65 ~91 stone
fill ~213 ~66 ~91 ~216 ~68 ~91 dirt
fill ~213 ~69 ~91 ~216 ~69 ~91 grass_block
fill ~217 ~60 ~91 ~219 ~64 ~91 stone
fill ~217 ~65 ~91 ~219 ~67 ~91 dirt
fill ~217 ~68 ~91 ~219 ~68 ~91 grass_block
fill ~220 ~60 ~91 ~221 ~65 ~91 stone
fill ~220 ~66 ~91 ~221 ~68 ~91 dirt
fill ~220 ~69 ~91 ~221 ~69 ~91 grass_block
fill ~222 ~60 ~91 ~223 ~64 ~91 stone
fill ~222 ~65 ~91 ~223 ~67 ~91 dirt
fill ~222 ~68 ~91 ~223 ~68 ~91 grass_block
fill ~208 ~60 ~92 ~212 ~66 ~92 stone
fill ~208 ~67 ~92 ~212 ~69 ~92 dirt
fill ~208 ~70 ~92 ~212 ~70 ~92 grass_block
fill ~213 ~60 ~92 ~216 ~65 ~92 stone
fill ~213 ~66 ~92 ~216 ~68 ~92 dirt
fill ~213 ~69 ~92 ~216 ~69 ~92 grass_block
fill ~217 ~60 ~92 ~222 ~64 ~92 stone
fill ~217 ~65 ~92 ~222 ~67 ~92 dirt
fill ~217 ~68 ~92 ~222 ~68 ~92 grass_block
fill ~223 ~60 ~92 ~223 ~65 ~92 stone
fill ~223 ~66 ~92 ~223 ~68 ~92 dirt
fill ~223 ~69 ~92 ~223 ~69 ~92 grass_block
fill ~208 ~60 ~93 ~213 ~66 ~93 stone
fill ~208 ~67 ~93 ~213 ~69 ~93 dirt
fill ~208 ~70 ~93 ~213 ~70 ~93 grass_block
fill ~214 ~60 ~93 ~216 ~65 ~93 stone
fill ~214 ~66 ~93 ~216 ~68 ~93 dirt
fill ~214 ~69 ~93 ~216 ~69 ~93 grass_block
fill ~217 ~60 ~93 ~222 ~64 ~93 stone
fill ~217 ~65 ~93 ~222 ~67 ~93 dirt
fill ~217 ~68 ~93 ~222 ~68 ~93 grass_block
fill ~223 ~60 ~93 ~223 ~65 ~93 stone
fill ~223 ~66 ~93 ~223 ~68 ~93 dirt
fill ~223 ~69 ~93 ~223 ~69 ~93 grass_block
fill ~208 ~60 ~94 ~212 ~66 ~94 stone
fill ~208 ~67 ~94 ~212 ~69 ~94 dirt
fill ~208 ~70 ~94 ~212 ~70 ~94 grass_block
fill ~213 ~60 ~94 ~216 ~65 ~94 stone
fill ~213 ~66 ~94 ~216 ~68 ~94 dirt
fill ~213 ~69 ~94 ~216 ~69 ~94 grass_block
fill ~217 ~60 ~94 ~222 ~64 ~94 stone
fill ~217 ~65 ~94 ~222 ~67 ~94 dirt
fill ~217 ~68 ~94 ~222 ~68 ~94 grass_block
fill ~223 ~60 ~94 ~223 ~65 ~94 stone
fill ~223 ~66 ~94 ~223 ~68 ~94 dirt
fill ~223 ~69 ~94 ~223 ~69 ~94 grass_block
fill ~208 ~60 ~95 ~211 ~66 ~95 stone
fill ~208 ~67 ~95 ~211 ~69 ~95 dirt
fill ~208 ~70 ~95 ~211 ~70 ~95 grass_block
fill ~212 ~60 ~95 ~216 ~65 ~95 stone
fill ~212 ~66 ~95 ~216 ~68 ~95 dirt
fill ~212 ~69 ~95 ~216 ~69 ~95 grass_block
fill ~217 ~60 ~95 ~223 ~64 ~95 stone
fill ~217 ~65 ~95 ~223 ~67 ~95 dirt
fill ~217 ~68 ~95 ~223 ~68 ~95 grass_block