fill ~208 ~60 ~48 ~214 ~64 ~48 stone
fill ~208 ~65 ~48 ~214 ~67 ~48 dirt
fill ~208 ~68 ~48 ~214 ~68 ~48 grass_block
fill ~215 ~60 ~48 ~223 ~63 ~48 stone
fill ~215 ~64 ~48 ~223 ~66 ~48 dirt
fill ~215 ~67 ~48 ~223 ~67 ~48 grass_block
fill ~208 ~60 ~49 ~215 ~64 ~49 stone
fill ~208 ~65 ~49 ~215 ~67 ~49 dirt
fill ~208 ~68 ~49 ~215 ~68 ~49 grass_block
fill ~216 ~60 ~49 ~223 ~63 ~49 stone
fill ~216 ~64 ~49 ~223 ~66 ~49 dirt
fill ~216 ~67 ~49 ~223 ~67 ~49 grass_block
fill ~208 ~60 ~50 ~216 ~64 ~50 stone
fill ~208 ~65 ~50 ~216 ~67 ~50 dirt
fill ~208 ~68 ~50 ~216 ~68 ~50 grass_block
fill ~217 ~60 ~50 ~223 ~63 ~50 stone
fill ~217 ~64 ~50 ~223 ~66 ~50 dirt
fill ~217 ~67 ~50 ~223 ~67 ~50 grass_block
fill ~208 ~60 ~51 ~216 ~64 ~51 stone
fill ~208 ~65 ~51 ~216 ~67 ~51 dirt
fill ~208 ~68 ~51 ~216 ~68 ~51 grass_block
fill ~217 ~60 ~51 ~223 ~63 ~51 stone
fill ~217 ~64 ~51 ~223 ~66 ~51 dirt
fill ~217 ~67 ~51 ~223 ~67 ~51 grass_block
fill ~208 ~60 ~52 ~217 ~64 ~52 stone
fill ~208 ~65 ~52 ~217 ~67 ~52 dirt
fill ~208 ~68 ~52 ~217 ~68 ~52 grass_block
fill ~218 ~60 ~52 ~223 ~63 ~52 stone
fill ~218 ~64 ~52 ~223 ~66 ~52 dirt
fill ~218 ~67 ~52 ~223 ~67 ~52 grass_block
fill ~208 ~60 ~53 ~209 ~63 ~53 stone
fill ~208 ~64 ~53 ~209 ~66 ~53 dirt
fill ~208 ~67 ~53 ~209 ~67 ~53 grass_block
fill ~210 ~60 ~53 ~218 ~64 ~53 stone
fill ~210 ~65 ~53 ~218 ~67 ~53 dirt
fill ~210 ~68 ~53 ~218 ~68 ~53 grass_block
fill ~219 ~60 ~53 ~223 ~63 ~53 stone
fill ~219 ~64 ~53 ~223 ~66 ~53 dirt
fill ~219 ~67 ~53 ~223 ~67 ~53 grass_block
fill ~208 ~60 ~54 ~213 ~63 ~54 stone
fill ~208 ~64 ~54 ~213 ~66 ~54 dirt
fill ~208 ~67 ~54 ~213 ~67 ~54 grass_block
fill ~214 ~60 ~54 ~218 ~64 ~54 stone
fill ~214 ~65 ~54 ~218 ~67 ~54 dirt
fill ~214 ~68 ~54 ~218 ~68 ~54 grass_block
fill ~219 ~60 ~54 ~219 ~63 ~54 stone
fill ~219 ~64 ~54 ~219 ~66 ~54 dirt
fill ~219 ~67 ~54 ~219 ~67 ~54 grass_block
fill ~220 ~60 ~54 ~220 ~64 ~54 stone
fill ~220 ~65 ~54 ~220 ~67 ~54 dirt
fill ~220 ~68 ~54 ~220 ~68 ~54 grass_block
fill ~221 ~60 ~54 ~223 ~63 ~54 stone
fill ~221 ~64 ~54 ~223 ~66 ~54 dirt
fill ~221 ~67 ~54 ~223 ~67 ~54 grass_block
fill ~208 ~60 ~55 ~223 ~63 ~55 stone
fill ~208 ~64 ~55 ~223 ~66 ~55 dirt
fill ~208 ~67 ~55 ~223 ~67 ~55 grass_block
fill ~208 ~60 ~56 ~210 ~63 ~56 stone
fill ~208 ~64 ~56 ~210 ~66 ~56 dirt
fill ~208 ~67 ~56 ~210 ~67 ~56 grass_block
fill ~211 ~60 ~56 ~212 ~62 ~56 stone
fill ~211 ~63 ~56 ~212 ~65 ~56 dirt
fill ~211 ~66 ~56 ~212 ~66 ~56 grass_block
fill ~213 ~60 ~56 ~223 ~63 ~56 stone
fill ~213 ~64 ~56 ~223 ~66 ~56 dirt
fill ~213 ~67 ~56 ~223 ~67 ~56 grass_block
fill ~208 ~60 ~57 ~215 ~63 ~57 stone
fill ~208 ~64 ~57 ~215 ~66 ~57 dirt
fill ~208 ~67 ~57 ~215 ~67 ~57 grass_block
fill ~216 ~60 ~57 ~216 ~62 ~57 stone
fill ~216 ~63 ~57 ~216 ~65 ~57 dirt
fill ~216 ~66 ~57 ~216 ~66 ~57 grass_block
fill ~217 ~60 ~57 ~223 ~63 ~57 stone
fill ~217 ~64 ~57 ~223 ~66 ~57 dirt
fill ~217 ~67 ~57 ~223 ~67 ~57 grass_block
fill ~208 ~60 ~58 ~211 ~64 ~58 stone
fill ~208 ~65 ~58 ~211 ~67 ~58 dirt
fill ~208 ~68 ~58 ~211 ~68 ~58 grass_block
fill ~212 ~60 ~58 ~216 ~63 ~58 stone
fill ~212 ~64 ~58 ~216 ~66 ~58 dirt
fill ~212 ~67 ~58 ~216 ~67 ~58 grass_block
fill ~217 ~60 ~58 ~219 ~62 ~58 stone
fill ~217 ~63 ~58 ~219 ~65 ~58 dirt
fill ~217 ~66 ~58 ~219 ~66 ~58 grass_block
fill ~220 ~60 ~58 ~223 ~63 ~58 stone
fill ~220 ~64 ~58 ~223 ~66 ~58 dirt
fill ~220 ~67 ~58 ~223 ~67 ~58 grass_block
fill ~208 ~60 ~59 ~209 ~65 ~59 stone
fill ~208 ~66 ~59 ~209 ~68 ~59 dirt
fill ~208 ~69 ~59 ~209 ~69 ~59 grass_block
fill ~210 ~60 ~59 ~214 ~64 ~59 stone
fill ~210 ~65 ~59 ~214 ~67 ~59 dirt
fill ~210 ~68 ~59 ~214 ~68 ~59 grass_block
fill ~215 ~60 ~59 ~217 ~63 ~59 stone
fill ~215 ~64 ~59 ~217 ~66 ~59 dirt
fill ~215 ~67 ~59 ~217 ~67 ~59 grass_block
fill ~218 ~60 ~59 ~223 ~62 ~59 stone
fill ~218 ~63 ~59 ~223 ~65 ~59 dirt
fill ~218 ~66 ~59 ~223 ~66 ~59 grass_block
fill ~208 ~60 ~60 ~211 ~65 ~60 stone
fill ~208 ~66 ~60 ~211 ~68 ~60 dirt
fill ~208 ~69 ~60 ~211 ~69 ~60 grass_block
fill ~212 ~60 ~60 ~215 ~64 ~60 stone
fill ~212 ~65 ~60 ~215 ~67 ~60 dirt
fill ~212 ~68 ~60 ~215 ~68 ~60 grass_block
fill ~216 ~60 ~60 ~219 ~63 ~60 stone
fill ~216 ~64 ~60 ~219 ~66 ~60 dirt
fill ~216 ~67 ~60 ~219 ~67 ~60 grass_block
fill ~220 ~60 ~60 ~223 ~62 ~60 stone
fill ~220 ~63 ~60 ~223 ~65 ~60 dirt
fill ~220 ~66 ~60 ~223 ~66 ~60 grass_block
fill ~208 ~60 ~61 ~212 ~65 ~61 stone
fill ~208 ~66 ~61 ~212 ~68 ~61 dirt
fill ~208 ~69 ~61 ~212 ~69 ~61 grass_block
fill ~213 ~60 ~61 ~216 ~64 ~61 stone
fill ~213 ~65 ~61 ~216 ~67 ~61 dirt
fill ~213 ~68 ~61 ~216 ~68 ~61 grass_block
fill ~217 ~60 ~61 ~220 ~63 ~61 stone
fill ~217 ~64 ~61 ~220 ~66 ~61 dirt
fill ~217 ~67 ~61 ~220 ~67 ~61 grass_block
fill ~221 ~60 ~61 ~223 ~62 ~61 stone
fill ~221 ~63 ~61 ~223 ~65 ~61 dirt
fill ~221 ~66 ~61 ~223 ~66 ~61 grass_block
fill ~208 ~60 ~62 ~208 ~66 ~62 stone
fill ~208 ~67 ~62 ~208 ~69 ~62 dirt
fill ~208 ~70 ~62 ~208 ~70 ~62 grass_block
fill ~209 ~60 ~62 ~211 ~65 ~62 stone
fill ~209 ~66 ~62 ~211 ~68 ~62 dirt
fill ~209 ~69 ~62 ~211 ~69 ~62 grass_block
fill ~212 ~60 ~62 ~217 ~64 ~62 stone
fill ~212 ~65 ~62 ~217 ~67 ~62 dirt
fill ~212 ~68 ~62 ~217 ~68 ~62 grass_block
fill ~218 ~60 ~62 ~220 ~63 ~62 stone
fill ~218 ~64 ~62 ~220 ~66 ~62 dirt
fill ~218 ~67 ~62 ~220 ~67 ~62 grass_block
fill ~221 ~60 ~62 ~223 ~62 ~62 stone
fill ~221 ~63 ~62 ~223 ~65 ~62 dirt
fill ~221 ~66 ~62 ~223 ~66 ~62 grass_block
fill ~208 ~60 ~63 ~208 ~66 ~63 stone
fill ~208 ~67 ~63 ~208 ~69 ~63 dirt
fill ~208 ~70 ~63 ~208 ~70 ~63 grass_block
fill ~209 ~60 ~63 ~211 ~65 ~63 stone
fill ~209 ~66 ~63 ~211 ~68 ~63 dirt
fill ~209 ~69 ~63 ~211 ~69 ~63 grass_block
fill ~212 ~60 ~63 ~214 ~64 ~63 stone
fill ~212 ~65 ~63 ~214 ~67 ~63 dirt
fill ~212 ~68 ~63 ~214 ~68 ~63 grass_block
fill ~215 ~60 ~63 ~220 ~63 ~63 stone
fill ~215 ~64 ~63 ~220 ~66 ~63 dirt
fill ~215 ~67 ~63 ~220 ~67 ~63 grass_block
fill ~221 ~60 ~63 ~223 ~62 ~63 stone
fill ~221 ~63 ~63 ~223 ~65 ~63 dirt
fill ~221 ~66 ~63 ~223 ~66 ~63 grass_block