fill ~16 ~60 ~0 ~18 ~65 ~0 stone
fill ~16 ~66 ~0 ~18 ~68 ~0 dirt
fill ~16 ~69 ~0 ~18 ~69 ~0 grass_block
fill ~19 ~60 ~0 ~21 ~64 ~0 stone
fill ~19 ~65 ~0 ~21 ~67 ~0 dirt
fill ~19 ~68 ~0 ~21 ~68 ~0 grass_block
fill ~22 ~60 ~0 ~22 ~63 ~0 stone
fill ~22 ~64 ~0 ~22 ~66 ~0 dirt
fill ~22 ~67 ~0 ~22 ~67 ~0 grass_block
fill ~23 ~60 ~0 ~23 ~64 ~0 stone
fill ~23 ~65 ~0 ~23 ~67 ~0 dirt
fill ~23 ~68 ~0 ~23 ~68 ~0 grass_block
fill ~24 ~60 ~0 ~26 ~63 ~0 stone
fill ~24 ~64 ~0 ~26 ~66 ~0 dirt
fill ~24 ~67 ~0 ~26 ~67 ~0 grass_block
fill ~27 ~60 ~0 ~31 ~64 ~0 stone
fill ~27 ~65 ~0 ~31 ~67 ~0 dirt
fill ~27 ~68 ~0 ~31 ~68 ~0 grass_block
fill ~16 ~60 ~1 ~16 ~66 ~1 stone
fill ~16 ~67 ~1 ~16 ~69 ~1 dirt
fill ~16 ~70 ~1 ~16 ~70 ~1 grass_block
fill ~17 ~60 ~1 ~20 ~65 ~1 stone
fill ~17 ~66 ~1 ~20 ~68 ~1 dirt
fill ~17 ~69 ~1 ~20 ~69 ~1 grass_block
fill ~21 ~60 ~1 ~24 ~64 ~1 stone
fill ~21 ~65 ~1 ~24 ~67 ~1 dirt
fill ~21 ~68 ~1 ~24 ~68 ~1 grass_block
fill ~25 ~60 ~1 ~30 ~63 ~1 stone
fill ~25 ~64 ~1 ~30 ~66 ~1 dirt
fill ~25 ~67 ~1 ~30 ~67 ~1 grass_block
fill ~31 ~60 ~1 ~31 ~64 ~1 stone
fill ~31 ~65 ~1 ~31 ~67 ~1 dirt
fill ~31 ~68 ~1 ~31 ~68 ~1 grass_block
fill ~16 ~60 ~2 ~18 ~66 ~2 stone
fill ~16 ~67 ~2 ~18 ~69 ~2 dirt
fill ~16 ~70 ~2 ~18 ~70 ~2 grass_block
fill ~19 ~60 ~2 ~21 ~65 ~2 stone
fill ~19 ~66 ~2 ~21 ~68 ~2 dirt
fill ~19 ~69 ~2 ~21 ~69 ~2 grass_block
fill ~22 ~60 ~2 ~26 ~64 ~2 stone
fill ~22 ~65 ~2 ~26 ~67 ~2 dirt
fill ~22 ~68 ~2 ~26 ~68 ~2 grass_block
fill ~27 ~60 ~2 ~31 ~63 ~2 stone
fill ~27 ~64 ~2 ~31 ~66 ~2 dirt
fill ~27 ~67 ~2 ~31 ~67 ~2 grass_block
fill ~16 ~60 ~3 ~17 ~67 ~3 stone
fill ~16 ~68 ~3 ~17 ~70 ~3 dirt
fill ~16 ~71 ~3 ~17 ~71 ~3 grass_block
fill ~18 ~60 ~3 ~19 ~66 ~3 stone
fill ~18 ~67 ~3 ~19 ~69 ~3 dirt
fill ~18 ~70 ~3 ~19 ~70 ~3 grass_block
fill ~20 ~60 ~3 ~22 ~65 ~3 stone
fill ~20 ~66 ~3 ~22 ~68 ~3 dirt
fill ~20 ~69 ~3 ~22 ~69 ~3 grass_block
fill ~23 ~60 ~3 ~30 ~64 ~3 stone
fill ~23 ~65 ~3 ~30 ~67 ~3 dirt
fill ~23 ~68 ~3 ~30 ~68 ~3 grass_block
fill ~31 ~60 ~3 ~31 ~63 ~3 stone
fill ~31 ~64 ~3 ~31 ~66 ~3 dirt
fill ~31 ~67 ~3 ~31 ~67 ~3 grass_block
fill ~16 ~60 ~4 ~17 ~68 ~4 stone
fill ~16 ~69 ~4 ~17 ~71 ~4 dirt
fill ~16 ~72 ~4 ~17 ~72 ~4 grass_block
fill ~18 ~60 ~4 ~18 ~67 ~4 stone
fill ~18 ~68 ~4 ~18 ~70 ~4 dirt
fill ~18 ~71 ~4 ~18 ~71 ~4 grass_block
fill ~19 ~60 ~4 ~21 ~66 ~4 stone
fill ~19 ~67 ~4 ~21 ~69 ~4 dirt
fill ~19 ~70 ~4 ~21 ~70 ~4 grass_block
fill ~22 ~60 ~4 ~25 ~65 ~4 stone
fill ~22 ~66 ~4 ~25 ~68 ~4 dirt
fill ~22 ~69 ~4 ~25 ~69 ~4 grass_block
fill ~26 ~60 ~4 ~31 ~64 ~4 stone
fill ~26 ~65 ~4 ~31 ~67 ~4 dirt
fill ~26 ~68 ~4 ~31 ~68 ~4 grass_block
fill ~16 ~60 ~5 ~17 ~68 ~5 stone
fill ~16 ~69 ~5 ~17 ~71 ~5 dirt
fill ~16 ~72 ~5 ~17 ~72 ~5 grass_block
fill ~18 ~60 ~5 ~21 ~67 ~5 stone
fill ~18 ~68 ~5 ~21 ~70 ~5 dirt
fill ~18 ~71 ~5 ~21 ~71 ~5 grass_block
fill ~22 ~60 ~5 ~23 ~66 ~5 stone
fill ~22 ~67 ~5 ~23 ~69 ~5 dirt
fill ~22 ~70 ~5 ~23 ~70 ~5 grass_block
fill ~24 ~60 ~5 ~30 ~65 ~5 stone
fill ~24 ~66 ~5 ~30 ~68 ~5 dirt
fill ~24 ~69 ~5 ~30 ~69 ~5 grass_block
fill ~31 ~60 ~5 ~31 ~64 ~5 stone
fill ~31 ~65 ~5 ~31 ~67 ~5 dirt
fill ~31 ~68 ~5 ~31 ~68 ~5 grass_block
fill ~16 ~60 ~6 ~17 ~69 ~6 stone
fill ~16 ~70 ~6 ~17 ~72 ~6 dirt
fill ~16 ~73 ~6 ~17 ~73 ~6 grass_block
fill ~18 ~60 ~6 ~19 ~68 ~6 stone
fill ~18 ~69 ~6 ~19 ~71 ~6 dirt
fill ~18 ~72 ~6 ~19 ~72 ~6 grass_block
fill ~20 ~60 ~6 ~22 ~67 ~6 stone
fill ~20 ~68 ~6 ~22 ~70 ~6 dirt
fill ~20 ~71 ~6 ~22 ~71 ~6 grass_block
fill ~23 ~60 ~6 ~24 ~66 ~6 stone
fill ~23 ~67 ~6 ~24 ~69 ~6 dirt
fill ~23 ~70 ~6 ~24 ~70 ~6 grass_block
fill ~25 ~60 ~6 ~25 ~65 ~6 stone
fill ~25 ~66 ~6 ~25 ~68 ~6 dirt
fill ~25 ~69 ~6 ~25 ~69 ~6 grass_block
fill ~26 ~60 ~6 ~26 ~66 ~6 stone
fill ~26 ~67 ~6 ~26 ~69 ~6 dirt
fill ~26 ~70 ~6 ~26 ~70 ~6 grass_block
fill ~27 ~60 ~6 ~31 ~65 ~6 stone
fill ~27 ~66 ~6 ~31 ~68 ~6 dirt
fill ~27 ~69 ~6 ~31 ~69 ~6 grass_block
fill ~16 ~60 ~7 ~19 ~69 ~7 stone
fill ~16 ~70 ~7 ~19 ~72 ~7 dirt
fill ~16 ~73 ~7 ~19 ~73 ~7 grass_block
fill ~20 ~60 ~7 ~21 ~68 ~7 stone
fill ~20 ~69 ~7 ~21 ~71 ~7 dirt
fill ~20 ~72 ~7 ~21 ~72 ~7 grass_block
fill ~22 ~60 ~7 ~24 ~67 ~7 stone
fill ~22 ~68 ~7 ~24 ~70 ~7 dirt
fill ~22 ~71 ~7 ~24 ~71 ~7 grass_block
fill ~25 ~60 ~7 ~29 ~66 ~7 stone
fill ~25 ~67 ~7 ~29 ~69 ~7 dirt
fill ~25 ~70 ~7 ~29 ~70 ~7 grass_block
fill ~30 ~60 ~7 ~31 ~65 ~7 stone
fill ~30 ~66 ~7 ~31 ~68 ~7 dirt
fill ~30 ~69 ~7 ~31 ~69 ~7 grass_block
fill ~16 ~60 ~8 ~21 ~69 ~8 stone
fill ~16 ~70 ~8 ~21 ~72 ~8 dirt
fill ~16 ~73 ~8 ~21 ~73 ~8 grass_block
fill ~22 ~60 ~8 ~23 ~68 ~8 stone
fill ~22 ~69 ~8 ~23 ~71 ~8 dirt
fill ~22 ~72 ~8 ~23 ~72 ~8 grass_block
fill ~24 ~60 ~8 ~26 ~67 ~8 stone
fill ~24 ~68 ~8 ~26 ~70 ~8 dirt
fill ~24 ~71 ~8 ~26 ~71 ~8 grass_block
fill ~27 ~60 ~8 ~29 ~66 ~8 stone
fill ~27 ~67 ~8 ~29 ~69 ~8 dirt
fill ~27 ~70 ~8 ~29 ~70 ~8 grass_block
fill ~30 ~60 ~8 ~31 ~65 ~8 stone
fill ~30 ~66 ~8 ~31 ~68 ~8 dirt
fill ~30 ~69 ~8 ~31 ~69 ~8 grass_block
fill ~16 ~60 ~9 ~23 ~69 ~9 stone
fill ~16 ~70 ~9 ~23 ~72 ~9 dirt
fill ~16 ~73 ~9 ~23 ~73 ~9 grass_block
fill ~24 ~60 ~9 ~25 ~68 ~9 stone
fill ~24 ~69 ~9 ~25 ~71 ~9 dirt
fill ~24 ~72 ~9 ~25 ~72 ~9 grass_block
fill ~26 ~60 ~9 ~27 ~67 ~9 stone
fill ~26 ~68 ~9 ~27 ~70 ~9 dirt
fill ~26 ~71 ~9 ~27 ~71 ~9 grass_block
fill ~28 ~60 ~9 ~29 ~66 ~9 stone
fill ~28 ~67 ~9 ~29 ~69 ~9 dirt
fill ~28 ~70 ~9 ~29 ~70 ~9 grass_block
fill ~30 ~60 ~9 ~31 ~65 ~9 stone
fill ~30 ~66 ~9 ~31 ~68 ~9 dirt
fill ~30 ~69 ~9 ~31 ~69 ~9 grass_block
fill ~16 ~60 ~10 ~25 ~69 ~10 stone
fill ~16 ~70 ~10 ~25 ~72 ~10 dirt
fill ~16 ~73 ~10 ~25 ~73 ~10 grass_block
fill ~26 ~60 ~10 ~27 ~68 ~10 stone
fill ~26 ~69 ~10 ~27 ~71 ~10 dirt
fill ~26 ~72 ~10 ~27 ~72 ~10 grass_block
fill ~28 ~60 ~10 ~28 ~67 ~10 stone
fill ~28 ~68 ~10 ~28 ~70 ~10 dirt
fill ~28 ~71 ~10 ~28 ~71 ~10 grass_block
fill ~29 ~60 ~10 ~31 ~66 ~10 stone
fill ~29 ~67 ~10 ~31 ~69 ~10 dirt
fill ~29 ~70 ~10 ~31 ~70 ~10 grass_block
fill ~16 ~60 ~11 ~27 ~69 ~11 stone
fill ~16 ~70 ~11 ~27 ~72 ~11 dirt
fill ~16 ~73 ~11 ~27 ~73 ~11 grass_block
fill ~28 ~60 ~11 ~29 ~68 ~11 stone
fill ~28 ~69 ~11 ~29 ~71 ~11 dirt
fill ~28 ~72 ~11 ~29 ~72 ~11 grass_block
fill ~30 ~60 ~11 ~30 ~67 ~11 stone
fill ~30 ~68 ~11 ~30 ~70 ~11 dirt
fill ~30 ~71 ~11 ~30 ~71 ~11 grass_block
fill ~31 ~60 ~11 ~31 ~66 ~11 stone
fill ~31 ~67 ~11 ~31 ~69 ~11 dirt
fill ~31 ~70 ~11 ~31 ~70 ~11 grass_block
fill ~16 ~60 ~12 ~27 ~69 ~12 stone
fill ~16 ~70 ~12 ~27 ~72 ~12 dirt
fill ~16 ~73 ~12 ~27 ~73 ~12 grass_block
fill ~28 ~60 ~12 ~30 ~68 ~12 stone
fill ~28 ~69 ~12 ~30 ~71 ~12 dirt
fill ~28 ~72 ~12 ~30 ~72 ~12 grass_block
fill ~31 ~60 ~12 ~31 ~67 ~12 stone
fill ~31 ~68 ~12 ~31 ~70 ~12 dirt
fill ~31 ~71 ~12 ~31 ~71 ~12 grass_block
fill ~16 ~60 ~13 ~17 ~69 ~13 stone
fill ~16 ~70 ~13 ~17 ~72 ~13 dirt
fill ~16 ~73 ~13 ~17 ~73 ~13 grass_block
fill ~18 ~60 ~13 ~20 ~68 ~13 stone
fill ~18 ~69 ~13 ~20 ~71 ~13 dirt
fill ~18 ~72 ~13 ~20 ~72 ~13 grass_block
fill ~21 ~60 ~13 ~30 ~69 ~13 stone
fill ~21 ~70 ~13 ~30 ~72 ~13 dirt
fill ~21 ~73 ~13 ~30 ~73 ~13 grass_block
fill ~31 ~60 ~13 ~31 ~68 ~13 stone
fill ~31 ~69 ~13 ~31 ~71 ~13 dirt
fill ~31 ~72 ~13 ~31 ~72 ~13 grass_block
fill ~16 ~60 ~14 ~16 ~69 ~14 stone
fill ~16 ~70 ~14 ~16 ~72 ~14 dirt
fill ~16 ~73 ~14 ~16 ~73 ~14 grass_block
fill ~17 ~60 ~14 ~24 ~68 ~14 stone
fill ~17 ~69 ~14 ~24 ~71 ~14 dirt
fill ~17 ~72 ~14 ~24 ~72 ~14 grass_block
fill ~25 ~60 ~14 ~28 ~69 ~14 stone
fill ~25 ~70 ~14 ~28 ~72 ~14 dirt
fill ~25 ~73 ~14 ~28 ~73 ~14 grass_block
fill ~29 ~60 ~14 ~31 ~68 ~14 stone
fill ~29 ~69 ~14 ~31 ~71 ~14 dirt
fill ~29 ~72 ~14 ~31 ~72 ~14 grass_block
fill ~16 ~60 ~15 ~27 ~68 ~15 stone
fill ~16 ~69 ~15 ~27 ~71 ~15 dirt
fill ~16 ~72 ~15 ~27 ~72 ~15 grass_block
fill ~28 ~60 ~15 ~28 ~69 ~15 stone
fill ~28 ~70 ~15 ~28 ~72 ~15 dirt
fill ~28 ~73 ~15 ~28 ~73 ~15 grass_block
fill ~29 ~60 ~15 ~31 ~68 ~15 stone
fill ~29 ~69 ~15 ~31 ~71 ~15 dirt
fill ~29 ~72 ~15 ~31 ~72 ~15 grass_block