fill ~272 ~60 ~32 ~274 ~62 ~32 stone
fill ~272 ~63 ~32 ~274 ~65 ~32 dirt
fill ~272 ~66 ~32 ~274 ~66 ~32 grass_block
fill ~275 ~60 ~32 ~275 ~61 ~32 stone
fill ~275 ~62 ~32 ~275 ~64 ~32 dirt
fill ~275 ~65 ~32 ~275 ~65 ~32 grass_block
fill ~276 ~60 ~32 ~278 ~62 ~32 stone
fill ~276 ~63 ~32 ~278 ~65 ~32 dirt
fill ~276 ~66 ~32 ~278 ~66 ~32 grass_block
fill ~279 ~60 ~32 ~284 ~63 ~32 stone
fill ~279 ~64 ~32 ~284 ~66 ~32 dirt
fill ~279 ~67 ~32 ~284 ~67 ~32 grass_block
fill ~285 ~60 ~32 ~285 ~64 ~32 stone
fill ~285 ~65 ~32 ~285 ~67 ~32 dirt
fill ~285 ~68 ~32 ~285 ~68 ~32 grass_block
fill ~286 ~60 ~32 ~287 ~63 ~32 stone
fill ~286 ~64 ~32 ~287 ~66 ~32 dirt
fill ~286 ~67 ~32 ~287 ~67 ~32 grass_block
fill ~272 ~60 ~33 ~274 ~62 ~33 stone
fill ~272 ~63 ~33 ~274 ~65 ~33 dirt
fill ~272 ~66 ~33 ~274 ~66 ~33 grass_block
fill ~275 ~60 ~33 ~276 ~61 ~33 stone
fill ~275 ~62 ~33 ~276 ~64 ~33 dirt
fill ~275 ~65 ~33 ~276 ~65 ~33 grass_block
fill ~277 ~60 ~33 ~277 ~62 ~33 stone
fill ~277 ~63 ~33 ~277 ~65 ~33 dirt
fill ~277 ~66 ~33 ~277 ~66 ~33 grass_block
fill ~278 ~60 ~33 ~287 ~63 ~33 stone
fill ~278 ~64 ~33 ~287 ~66 ~33 dirt
fill ~278 ~67 ~33 ~287 ~67 ~33 grass_block
fill ~272 ~60 ~34 ~273 ~62 ~34 stone
fill ~272 ~63 ~34 ~273 ~65 ~34 dirt
fill ~272 ~66 ~34 ~273 ~66 ~34 grass_block
fill ~274 ~60 ~34 ~276 ~61 ~34 stone
fill ~274 ~62 ~34 ~276 ~64 ~34 dirt
fill ~274 ~65 ~34 ~276 ~65 ~34 grass_block
fill ~277 ~60 ~34 ~277 ~62 ~34 stone
fill ~277 ~63 ~34 ~277 ~65 ~34 dirt
fill ~277 ~66 ~34 ~277 ~66 ~34 grass_block
fill ~278 ~60 ~34 ~287 ~63 ~34 stone
fill ~278 ~64 ~34 ~287 ~66 ~34 dirt
fill ~278 ~67 ~34 ~287 ~67 ~34 grass_block
fill ~272 ~60 ~35 ~273 ~62 ~35 stone
fill ~272 ~63 ~35 ~273 ~65 ~35 dirt
fill ~272 ~66 ~35 ~273 ~66 ~35 grass_block
fill ~274 ~60 ~35 ~275 ~61 ~35 stone
fill ~274 ~62 ~35 ~275 ~64 ~35 dirt
fill ~274 ~65 ~35 ~275 ~65 ~35 grass_block
fill ~276 ~60 ~35 ~277 ~62 ~35 stone
fill ~276 ~63 ~35 ~277 ~65 ~35 dirt
fill ~276 ~66 ~35 ~277 ~66 ~35 grass_block
fill ~278 ~60 ~35 ~287 ~63 ~35 stone
fill ~278 ~64 ~35 ~287 ~66 ~35 dirt
fill ~278 ~67 ~35 ~287 ~67 ~35 grass_block
fill ~272 ~60 ~36 ~273 ~62 ~36 stone
fill ~272 ~63 ~36 ~273 ~65 ~36 dirt
fill ~272 ~66 ~36 ~273 ~66 ~36 grass_block
fill ~274 ~60 ~36 ~275 ~61 ~36 stone
fill ~274 ~62 ~36 ~275 ~64 ~36 dirt
fill ~274 ~65 ~36 ~275 ~65 ~36 grass_block
fill ~276 ~60 ~36 ~277 ~62 ~36 stone
fill ~276 ~63 ~36 ~277 ~65 ~36 dirt
fill ~276 ~66 ~36 ~277 ~66 ~36 grass_block
fill ~278 ~60 ~36 ~287 ~63 ~36 stone
fill ~278 ~64 ~36 ~287 ~66 ~36 dirt
fill ~278 ~67 ~36 ~287 ~67 ~36 grass_block
fill ~272 ~60 ~37 ~272 ~62 ~37 stone
fill ~272 ~63 ~37 ~272 ~65 ~37 dirt
fill ~272 ~66 ~37 ~272 ~66 ~37 grass_block
fill ~273 ~60 ~37 ~273 ~61 ~37 stone
fill ~273 ~62 ~37 ~273 ~64 ~37 dirt
fill ~273 ~65 ~37 ~273 ~65 ~37 grass_block
fill ~274 ~60 ~37 ~277 ~62 ~37 stone
fill ~274 ~63 ~37 ~277 ~65 ~37 dirt
fill ~274 ~66 ~37 ~277 ~66 ~37 grass_block
fill ~278 ~60 ~37 ~287 ~63 ~37 stone
fill ~278 ~64 ~37 ~287 ~66 ~37 dirt
fill ~278 ~67 ~37 ~287 ~67 ~37 grass_block
fill ~272 ~60 ~38 ~273 ~61 ~38 stone
fill ~272 ~62 ~38 ~273 ~64 ~38 dirt
fill ~272 ~65 ~38 ~273 ~65 ~38 grass_block
fill ~274 ~60 ~38 ~277 ~62 ~38 stone
fill ~274 ~63 ~38 ~277 ~65 ~38 dirt
fill ~274 ~66 ~38 ~277 ~66 ~38 grass_block
fill ~278 ~60 ~38 ~287 ~63 ~38 stone
fill ~278 ~64 ~38 ~287 ~66 ~38 dirt
fill ~278 ~67 ~38 ~287 ~67 ~38 grass_block
fill ~272 ~60 ~39 ~274 ~61 ~39 stone
fill ~272 ~62 ~39 ~274 ~64 ~39 dirt
fill ~272 ~65 ~39 ~274 ~65 ~39 grass_block
fill ~275 ~60 ~39 ~278 ~62 ~39 stone
fill ~275 ~63 ~39 ~278 ~65 ~39 dirt
fill ~275 ~66 ~39 ~278 ~66 ~39 grass_block
fill ~279 ~60 ~39 ~287 ~63 ~39 stone
fill ~279 ~64 ~39 ~287 ~66 ~39 dirt
fill ~279 ~67 ~39 ~287 ~67 ~39 grass_block
fill ~272 ~60 ~40 ~275 ~61 ~40 stone
fill ~272 ~62 ~40 ~275 ~64 ~40 dirt
fill ~272 ~65 ~40 ~275 ~65 ~40 grass_block
fill ~276 ~60 ~40 ~279 ~62 ~40 stone
fill ~276 ~63 ~40 ~279 ~65 ~40 dirt
fill ~276 ~66 ~40 ~279 ~66 ~40 grass_block
fill ~280 ~60 ~40 ~282 ~63 ~40 stone
fill ~280 ~64 ~40 ~282 ~66 ~40 dirt
fill ~280 ~67 ~40 ~282 ~67 ~40 grass_block
fill ~283 ~60 ~40 ~283 ~62 ~40 stone
fill ~283 ~63 ~40 ~283 ~65 ~40 dirt
fill ~283 ~66 ~40 ~283 ~66 ~40 grass_block
fill ~284 ~60 ~40 ~285 ~63 ~40 stone
fill ~284 ~64 ~40 ~285 ~66 ~40 dirt
fill ~284 ~67 ~40 ~285 ~67 ~40 grass_block
fill ~286 ~60 ~40 ~287 ~62 ~40 stone
fill ~286 ~63 ~40 ~287 ~65 ~40 dirt
fill ~286 ~66 ~40 ~287 ~66 ~40 grass_block
fill ~272 ~60 ~41 ~276 ~61 ~41 stone
fill ~272 ~62 ~41 ~276 ~64 ~41 dirt
fill ~272 ~65 ~41 ~276 ~65 ~41 grass_block
fill ~277 ~60 ~41 ~287 ~62 ~41 stone
fill ~277 ~63 ~41 ~287 ~65 ~41 dirt
fill ~277 ~66 ~41 ~287 ~66 ~41 grass_block
fill ~272 ~60 ~42 ~276 ~61 ~42 stone
fill ~272 ~62 ~42 ~276 ~64 ~42 dirt
fill ~272 ~65 ~42 ~276 ~65 ~42 grass_block
fill ~277 ~60 ~42 ~287 ~62 ~42 stone
fill ~277 ~63 ~42 ~287 ~65 ~42 dirt
fill ~277 ~66 ~42 ~287 ~66 ~42 grass_block
fill ~272 ~60 ~43 ~278 ~61 ~43 stone
fill ~272 ~62 ~43 ~278 ~64 ~43 dirt
fill ~272 ~65 ~43 ~278 ~65 ~43 grass_block
fill ~279 ~60 ~43 ~287 ~62 ~43 stone
fill ~279 ~63 ~43 ~287 ~65 ~43 dirt
fill ~279 ~66 ~43 ~287 ~66 ~43 grass_block
fill ~272 ~60 ~44 ~272 ~61 ~44 stone
fill ~272 ~62 ~44 ~272 ~64 ~44 dirt
fill ~272 ~65 ~44 ~272 ~65 ~44 grass_block
fill ~273 ~60 ~44 ~273 ~62 ~44 stone
fill ~273 ~63 ~44 ~273 ~65 ~44 dirt
fill ~273 ~66 ~44 ~273 ~66 ~44 grass_block
fill ~274 ~60 ~44 ~279 ~61 ~44 stone
fill ~274 ~62 ~44 ~279 ~64 ~44 dirt
fill ~274 ~65 ~44 ~279 ~65 ~44 grass_block
fill ~280 ~60 ~44 ~280 ~62 ~44 stone
fill ~280 ~63 ~44 ~280 ~65 ~44 dirt
fill ~280 ~66 ~44 ~280 ~66 ~44 grass_block
fill ~281 ~60 ~44 ~281 ~61 ~44 stone
fill ~281 ~62 ~44 ~281 ~64 ~44 dirt
fill ~281 ~65 ~44 ~281 ~65 ~44 grass_block
fill ~282 ~60 ~44 ~287 ~62 ~44 stone
fill ~282 ~63 ~44 ~287 ~65 ~44 dirt
fill ~282 ~66 ~44 ~287 ~66 ~44 grass_block
fill ~272 ~60 ~45 ~284 ~61 ~45 stone
fill ~272 ~62 ~45 ~284 ~64 ~45 dirt
fill ~272 ~65 ~45 ~284 ~65 ~45 grass_block
fill ~285 ~60 ~45 ~287 ~62 ~45 stone
fill ~285 ~63 ~45 ~287 ~65 ~45 dirt
fill ~285 ~66 ~45 ~287 ~66 ~45 grass_block
fill ~272 ~60 ~46 ~287 ~61 ~46 stone
fill ~272 ~62 ~46 ~287 ~64 ~46 dirt
fill ~272 ~65 ~46 ~287 ~65 ~46 grass_block
fill ~272 ~60 ~47 ~287 ~61 ~47 stone
fill ~272 ~62 ~47 ~287 ~64 ~47 dirt
fill ~272 ~65 ~47 ~287 ~65 ~47 grass_block