fill ~144 ~60 ~64 ~149 ~64 ~64 stone
fill ~144 ~65 ~64 ~149 ~67 ~64 dirt
fill ~144 ~68 ~64 ~149 ~68 ~64 grass_block
fill ~150 ~60 ~64 ~152 ~65 ~64 stone
fill ~150 ~66 ~64 ~152 ~68 ~64 dirt
fill ~150 ~69 ~64 ~152 ~69 ~64 grass_block
fill ~153 ~60 ~64 ~159 ~66 ~64 stone
fill ~153 ~67 ~64 ~159 ~69 ~64 dirt
fill ~153 ~70 ~64 ~159 ~70 ~64 grass_block
fill ~144 ~60 ~65 ~150 ~64 ~65 stone
fill ~144 ~65 ~65 ~150 ~67 ~65 dirt
fill ~144 ~68 ~65 ~150 ~68 ~65 grass_block
fill ~151 ~60 ~65 ~154 ~65 ~65 stone
fill ~151 ~66 ~65 ~154 ~68 ~65 dirt
fill ~151 ~69 ~65 ~154 ~69 ~65 grass_block
fill ~155 ~60 ~65 ~159 ~66 ~65 stone
fill ~155 ~67 ~65 ~159 ~69 ~65 dirt
fill ~155 ~70 ~65 ~159 ~70 ~65 grass_block
fill ~144 ~60 ~66 ~151 ~64 ~66 stone
fill ~144 ~65 ~66 ~151 ~67 ~66 dirt
fill ~144 ~68 ~66 ~151 ~68 ~66 grass_block
fill ~152 ~60 ~66 ~159 ~65 ~66 stone
fill ~152 ~66 ~66 ~159 ~68 ~66 dirt
fill ~152 ~69 ~66 ~159 ~69 ~66 grass_block
fill ~144 ~60 ~67 ~144 ~65 ~67 stone
fill ~144 ~66 ~67 ~144 ~68 ~67 dirt
fill ~144 ~69 ~67 ~144 ~69 ~67 grass_block
fill ~145 ~60 ~67 ~152 ~64 ~67 stone
fill ~145 ~65 ~67 ~152 ~67 ~67 dirt
fill ~145 ~68 ~67 ~152 ~68 ~67 grass_block
fill ~153 ~60 ~67 ~159 ~65 ~67 stone
fill ~153 ~66 ~67 ~159 ~68 ~67 dirt
fill ~153 ~69 ~67 ~159 ~69 ~67 grass_block
fill ~144 ~60 ~68 ~144 ~65 ~68 stone
fill ~144 ~66 ~68 ~144 ~68 ~68 dirt
fill ~144 ~69 ~68 ~144 ~69 ~68 grass_block
fill ~145 ~60 ~68 ~153 ~64 ~68 stone
fill ~145 ~65 ~68 ~153 ~67 ~68 dirt
fill ~145 ~68 ~68 ~153 ~68 ~68 grass_block
fill ~154 ~60 ~68 ~159 ~65 ~68 stone
fill ~154 ~66 ~68 ~159 ~68 ~68 dirt
fill ~154 ~69 ~68 ~159 ~69 ~68 grass_block
fill ~144 ~60 ~69 ~145 ~65 ~69 stone
fill ~144 ~66 ~69 ~145 ~68 ~69 dirt
fill ~144 ~69 ~69 ~145 ~69 ~69 grass_block
fill ~146 ~60 ~69 ~148 ~64 ~69 stone
fill ~146 ~65 ~69 ~148 ~67 ~69 dirt
fill ~146 ~68 ~69 ~148 ~68 ~69 grass_block
fill ~149 ~60 ~69 ~150 ~63 ~69 stone
fill ~149 ~64 ~69 ~150 ~66 ~69 dirt
fill ~149 ~67 ~69 ~150 ~67 ~69 grass_block
fill ~151 ~60 ~69 ~159 ~64 ~69 stone
fill ~151 ~65 ~69 ~159 ~67 ~69 dirt
fill ~151 ~68 ~69 ~159 ~68 ~69 grass_block
fill ~144 ~60 ~70 ~144 ~66 ~70 stone
fill ~144 ~67 ~70 ~144 ~69 ~70 dirt
fill ~144 ~70 ~70 ~144 ~70 ~70 grass_block
fill ~145 ~60 ~70 ~146 ~65 ~70 stone
fill ~145 ~66 ~70 ~146 ~68 ~70 dirt
fill ~145 ~69 ~70 ~146 ~69 ~70 grass_block
fill ~147 ~60 ~70 ~150 ~64 ~70 stone
fill ~147 ~65 ~70 ~150 ~67 ~70 dirt
fill ~147 ~68 ~70 ~150 ~68 ~70 grass_block
fill ~151 ~60 ~70 ~152 ~63 ~70 stone
fill ~151 ~64 ~70 ~152 ~66 ~70 dirt
fill ~151 ~67 ~70 ~152 ~67 ~70 grass_block
fill ~153 ~60 ~70 ~159 ~64 ~70 stone
fill ~153 ~65 ~70 ~159 ~67 ~70 dirt
fill ~153 ~68 ~70 ~159 ~68 ~70 grass_block
fill ~144 ~60 ~71 ~145 ~66 ~71 stone
fill ~144 ~67 ~71 ~145 ~69 ~71 dirt
fill ~144 ~70 ~71 ~145 ~70 ~71 grass_block
fill ~146 ~60 ~71 ~147 ~65 ~71 stone
fill ~146 ~66 ~71 ~147 ~68 ~71 dirt
fill ~146 ~69 ~71 ~147 ~69 ~71 grass_block
fill ~148 ~60 ~71 ~151 ~64 ~71 stone
fill ~148 ~65 ~71 ~151 ~67 ~71 dirt
fill ~148 ~68 ~71 ~151 ~68 ~71 grass_block
fill ~152 ~60 ~71 ~154 ~63 ~71 stone
fill ~152 ~64 ~71 ~154 ~66 ~71 dirt
fill ~152 ~67 ~71 ~154 ~67 ~71 grass_block
fill ~155 ~60 ~71 ~159 ~64 ~71 stone
fill ~155 ~65 ~71 ~159 ~67 ~71 dirt
fill ~155 ~68 ~71 ~159 ~68 ~71 grass_block
fill ~144 ~60 ~72 ~148 ~65 ~72 stone
fill ~144 ~66 ~72 ~148 ~68 ~72 dirt
fill ~144 ~69 ~72 ~148 ~69 ~72 grass_block
fill ~149 ~60 ~72 ~153 ~64 ~72 stone
fill ~149 ~65 ~72 ~153 ~67 ~72 dirt
fill ~149 ~68 ~72 ~153 ~68 ~72 grass_block
fill ~154 ~60 ~72 ~156 ~63 ~72 stone
fill ~154 ~64 ~72 ~156 ~66 ~72 dirt
fill ~154 ~67 ~72 ~156 ~67 ~72 grass_block
fill ~157 ~60 ~72 ~159 ~64 ~72 stone
fill ~157 ~65 ~72 ~159 ~67 ~72 dirt
fill ~157 ~68 ~72 ~159 ~68 ~72 grass_block
fill ~144 ~60 ~73 ~144 ~64 ~73 stone
fill ~144 ~65 ~73 ~144 ~67 ~73 dirt
fill ~144 ~68 ~73 ~144 ~68 ~73 grass_block
fill ~145 ~60 ~73 ~146 ~65 ~73 stone
fill ~145 ~66 ~73 ~146 ~68 ~73 dirt
fill ~145 ~69 ~73 ~146 ~69 ~73 grass_block
fill ~147 ~60 ~73 ~147 ~66 ~73 stone
fill ~147 ~67 ~73 ~147 ~69 ~73 dirt
fill ~147 ~70 ~73 ~147 ~70 ~73 grass_block
fill ~148 ~60 ~73 ~150 ~65 ~73 stone
fill ~148 ~66 ~73 ~150 ~68 ~73 dirt
fill ~148 ~69 ~73 ~150 ~69 ~73 grass_block
fill ~151 ~60 ~73 ~153 ~64 ~73 stone
fill ~151 ~65 ~73 ~153 ~67 ~73 dirt
fill ~151 ~68 ~73 ~153 ~68 ~73 grass_block
fill ~154 ~60 ~73 ~158 ~63 ~73 stone
fill ~154 ~64 ~73 ~158 ~66 ~73 dirt
fill ~154 ~67 ~73 ~158 ~67 ~73 grass_block
fill ~159 ~60 ~73 ~159 ~64 ~73 stone
fill ~159 ~65 ~73 ~159 ~67 ~73 dirt
fill ~159 ~68 ~73 ~159 ~68 ~73 grass_block
fill ~144 ~60 ~74 ~144 ~64 ~74 stone
fill ~144 ~65 ~74 ~144 ~67 ~74 dirt
fill ~144 ~68 ~74 ~144 ~68 ~74 grass_block
fill ~145 ~60 ~74 ~146 ~65 ~74 stone
fill ~145 ~66 ~74 ~146 ~68 ~74 dirt
fill ~145 ~69 ~74 ~146 ~69 ~74 grass_block
fill ~147 ~60 ~74 ~149 ~66 ~74 stone
fill ~147 ~67 ~74 ~149 ~69 ~74 dirt
fill ~147 ~70 ~74 ~149 ~70 ~74 grass_block
fill ~150 ~60 ~74 ~152 ~65 ~74 stone
fill ~150 ~66 ~74 ~152 ~68 ~74 dirt
fill ~150 ~69 ~74 ~152 ~69 ~74 grass_block
fill ~153 ~60 ~74 ~155 ~64 ~74 stone
fill ~153 ~65 ~74 ~155 ~67 ~74 dirt
fill ~153 ~68 ~74 ~155 ~68 ~74 grass_block
fill ~156 ~60 ~74 ~159 ~63 ~74 stone
fill ~156 ~64 ~74 ~159 ~66 ~74 dirt
fill ~156 ~67 ~74 ~159 ~67 ~74 grass_block
fill ~144 ~60 ~75 ~145 ~64 ~75 stone
fill ~144 ~65 ~75 ~145 ~67 ~75 dirt
fill ~144 ~68 ~75 ~145 ~68 ~75 grass_block
fill ~146 ~60 ~75 ~147 ~65 ~75 stone
fill ~146 ~66 ~75 ~147 ~68 ~75 dirt
fill ~146 ~69 ~75 ~147 ~69 ~75 grass_block
fill ~148 ~60 ~75 ~150 ~66 ~75 stone
fill ~148 ~67 ~75 ~150 ~69 ~75 dirt
fill ~148 ~70 ~75 ~150 ~70 ~75 grass_block
fill ~151 ~60 ~75 ~153 ~65 ~75 stone
fill ~151 ~66 ~75 ~153 ~68 ~75 dirt
fill ~151 ~69 ~75 ~153 ~69 ~75 grass_block
fill ~154 ~60 ~75 ~156 ~64 ~75 stone
fill ~154 ~65 ~75 ~156 ~67 ~75 dirt
fill ~154 ~68 ~75 ~156 ~68 ~75 grass_block
fill ~157 ~60 ~75 ~159 ~63 ~75 stone
fill ~157 ~64 ~75 ~159 ~66 ~75 dirt
fill ~157 ~67 ~75 ~159 ~67 ~75 grass_block
fill ~144 ~60 ~76 ~145 ~64 ~76 stone
fill ~144 ~65 ~76 ~145 ~67 ~76 dirt
fill ~144 ~68 ~76 ~145 ~68 ~76 grass_block
fill ~146 ~60 ~76 ~148 ~65 ~76 stone
fill ~146 ~66 ~76 ~148 ~68 ~76 dirt
fill ~146 ~69 ~76 ~148 ~69 ~76 grass_block
fill ~149 ~60 ~76 ~151 ~66 ~76 stone
fill ~149 ~67 ~76 ~151 ~69 ~76 dirt
fill ~149 ~70 ~76 ~151 ~70 ~76 grass_block
fill ~152 ~60 ~76 ~152 ~65 ~76 stone
fill ~152 ~66 ~76 ~152 ~68 ~76 dirt
fill ~152 ~69 ~76 ~152 ~69 ~76 grass_block
fill ~153 ~60 ~76 ~157 ~64 ~76 stone
fill ~153 ~65 ~76 ~157 ~67 ~76 dirt
fill ~153 ~68 ~76 ~157 ~68 ~76 grass_block
fill ~158 ~60 ~76 ~159 ~63 ~76 stone
fill ~158 ~64 ~76 ~159 ~66 ~76 dirt
fill ~158 ~67 ~76 ~159 ~67 ~76 grass_block
fill ~144 ~60 ~77 ~144 ~64 ~77 stone
fill ~144 ~65 ~77 ~144 ~67 ~77 dirt
fill ~144 ~68 ~77 ~144 ~68 ~77 grass_block
fill ~145 ~60 ~77 ~147 ~65 ~77 stone
fill ~145 ~66 ~77 ~147 ~68 ~77 dirt
fill ~145 ~69 ~77 ~147 ~69 ~77 grass_block
fill ~148 ~60 ~77 ~152 ~66 ~77 stone
fill ~148 ~67 ~77 ~152 ~69 ~77 dirt
fill ~148 ~70 ~77 ~152 ~70 ~77 grass_block
fill ~153 ~60 ~77 ~155 ~65 ~77 stone
fill ~153 ~66 ~77 ~155 ~68 ~77 dirt
fill ~153 ~69 ~77 ~155 ~69 ~77 grass_block
fill ~156 ~60 ~77 ~158 ~64 ~77 stone
fill ~156 ~65 ~77 ~158 ~67 ~77 dirt
fill ~156 ~68 ~77 ~158 ~68 ~77 grass_block
fill ~159 ~60 ~77 ~159 ~63 ~77 stone
fill ~159 ~64 ~77 ~159 ~66 ~77 dirt
fill ~159 ~67 ~77 ~159 ~67 ~77 grass_block
fill ~144 ~60 ~78 ~147 ~65 ~78 stone
fill ~144 ~66 ~78 ~147 ~68 ~78 dirt
fill ~144 ~69 ~78 ~147 ~69 ~78 grass_block
fill ~148 ~60 ~78 ~153 ~66 ~78 stone
fill ~148 ~67 ~78 ~153 ~69 ~78 dirt
fill ~148 ~70 ~78 ~153 ~70 ~78 grass_block
fill ~154 ~60 ~78 ~156 ~65 ~78 stone
fill ~154 ~66 ~78 ~156 ~68 ~78 dirt
fill ~154 ~69 ~78 ~156 ~69 ~78 grass_block
fill ~157 ~60 ~78 ~159 ~64 ~78 stone
fill ~157 ~65 ~78 ~159 ~67 ~78 dirt
fill ~157 ~68 ~78 ~159 ~68 ~78 grass_block
fill ~144 ~60 ~79 ~147 ~65 ~79 stone
fill ~144 ~66 ~79 ~147 ~68 ~79 dirt
fill ~144 ~69 ~79 ~147 ~69 ~79 grass_block
fill ~148 ~60 ~79 ~154 ~66 ~79 stone
fill ~148 ~67 ~79 ~154 ~69 ~79 dirt
fill ~148 ~70 ~79 ~154 ~70 ~79 grass_block
fill ~155 ~60 ~79 ~157 ~65 ~79 stone
fill ~155 ~66 ~79 ~157 ~68 ~79 dirt
fill ~155 ~69 ~79 ~157 ~69 ~79 grass_block
fill ~158 ~60 ~79 ~159 ~64 ~79 stone
fill ~158 ~65 ~79 ~159 ~67 ~79 dirt
fill ~158 ~68 ~79 ~159 ~68 ~79 grass_block