fill ~256 ~60 ~0 ~265 ~62 ~0 stone
fill ~256 ~63 ~0 ~265 ~65 ~0 dirt
fill ~256 ~66 ~0 ~265 ~66 ~0 grass_block
fill ~266 ~60 ~0 ~271 ~63 ~0 stone
fill ~266 ~64 ~0 ~271 ~66 ~0 dirt
fill ~266 ~67 ~0 ~271 ~67 ~0 grass_block
fill ~256 ~60 ~1 ~264 ~62 ~1 stone
fill ~256 ~63 ~1 ~264 ~65 ~1 dirt
fill ~256 ~66 ~1 ~264 ~66 ~1 grass_block
fill ~265 ~60 ~1 ~266 ~63 ~1 stone
fill ~265 ~64 ~1 ~266 ~66 ~1 dirt
fill ~265 ~67 ~1 ~266 ~67 ~1 grass_block
fill ~267 ~60 ~1 ~271 ~64 ~1 stone
fill ~267 ~65 ~1 ~271 ~67 ~1 dirt
fill ~267 ~68 ~1 ~271 ~68 ~1 grass_block
fill ~256 ~60 ~2 ~263 ~62 ~2 stone
fill ~256 ~63 ~2 ~263 ~65 ~2 dirt
fill ~256 ~66 ~2 ~263 ~66 ~2 grass_block
fill ~264 ~60 ~2 ~265 ~63 ~2 stone
fill ~264 ~64 ~2 ~265 ~66 ~2 dirt
fill ~264 ~67 ~2 ~265 ~67 ~2 grass_block
fill ~266 ~60 ~2 ~267 ~64 ~2 stone
fill ~266 ~65 ~2 ~267 ~67 ~2 dirt
fill ~266 ~68 ~2 ~267 ~68 ~2 grass_block
fill ~268 ~60 ~2 ~271 ~65 ~2 stone
fill ~268 ~66 ~2 ~271 ~68 ~2 dirt
fill ~268 ~69 ~2 ~271 ~69 ~2 grass_block
fill ~256 ~60 ~3 ~262 ~62 ~3 stone
fill ~256 ~63 ~3 ~262 ~65 ~3 dirt
fill ~256 ~66 ~3 ~262 ~66 ~3 grass_block
fill ~263 ~60 ~3 ~265 ~63 ~3 stone
fill ~263 ~64 ~3 ~265 ~66 ~3 dirt
fill ~263 ~67 ~3 ~265 ~67 ~3 grass_block
fill ~266 ~60 ~3 ~267 ~64 ~3 stone
fill ~266 ~65 ~3 ~267 ~67 ~3 dirt
fill ~266 ~68 ~3 ~267 ~68 ~3 grass_block
fill ~268 ~60 ~3 ~271 ~65 ~3 stone
fill ~268 ~66 ~3 ~271 ~68 ~3 dirt
fill ~268 ~69 ~3 ~271 ~69 ~3 grass_block
fill ~256 ~60 ~4 ~261 ~62 ~4 stone
fill ~256 ~63 ~4 ~261 ~65 ~4 dirt
fill ~256 ~66 ~4 ~261 ~66 ~4 grass_block
fill ~262 ~60 ~4 ~265 ~63 ~4 stone
fill ~262 ~64 ~4 ~265 ~66 ~4 dirt
fill ~262 ~67 ~4 ~265 ~67 ~4 grass_block
fill ~266 ~60 ~4 ~268 ~64 ~4 stone
fill ~266 ~65 ~4 ~268 ~67 ~4 dirt
fill ~266 ~68 ~4 ~268 ~68 ~4 grass_block
fill ~269 ~60 ~4 ~271 ~65 ~4 stone
fill ~269 ~66 ~4 ~271 ~68 ~4 dirt
fill ~269 ~69 ~4 ~271 ~69 ~4 grass_block
fill ~256 ~60 ~5 ~262 ~62 ~5 stone
fill ~256 ~63 ~5 ~262 ~65 ~5 dirt
fill ~256 ~66 ~5 ~262 ~66 ~5 grass_block
fill ~263 ~60 ~5 ~266 ~63 ~5 stone
fill ~263 ~64 ~5 ~266 ~66 ~5 dirt
fill ~263 ~67 ~5 ~266 ~67 ~5 grass_block
fill ~267 ~60 ~5 ~268 ~64 ~5 stone
fill ~267 ~65 ~5 ~268 ~67 ~5 dirt
fill ~267 ~68 ~5 ~268 ~68 ~5 grass_block
fill ~269 ~60 ~5 ~271 ~65 ~5 stone
fill ~269 ~66 ~5 ~271 ~68 ~5 dirt
fill ~269 ~69 ~5 ~271 ~69 ~5 grass_block
fill ~256 ~60 ~6 ~263 ~62 ~6 stone
fill ~256 ~63 ~6 ~263 ~65 ~6 dirt
fill ~256 ~66 ~6 ~263 ~66 ~6 grass_block
fill ~264 ~60 ~6 ~267 ~63 ~6 stone
fill ~264 ~64 ~6 ~267 ~66 ~6 dirt
fill ~264 ~67 ~6 ~267 ~67 ~6 grass_block
fill ~268 ~60 ~6 ~269 ~64 ~6 stone
fill ~268 ~65 ~6 ~269 ~67 ~6 dirt
fill ~268 ~68 ~6 ~269 ~68 ~6 grass_block
fill ~270 ~60 ~6 ~271 ~65 ~6 stone
fill ~270 ~66 ~6 ~271 ~68 ~6 dirt
fill ~270 ~69 ~6 ~271 ~69 ~6 grass_block
fill ~256 ~60 ~7 ~257 ~63 ~7 stone
fill ~256 ~64 ~7 ~257 ~66 ~7 dirt
fill ~256 ~67 ~7 ~257 ~67 ~7 grass_block
fill ~258 ~60 ~7 ~263 ~62 ~7 stone
fill ~258 ~63 ~7 ~263 ~65 ~7 dirt
fill ~258 ~66 ~7 ~263 ~66 ~7 grass_block
fill ~264 ~60 ~7 ~268 ~63 ~7 stone
fill ~264 ~64 ~7 ~268 ~66 ~7 dirt
fill ~264 ~67 ~7 ~268 ~67 ~7 grass_block
fill ~269 ~60 ~7 ~271 ~64 ~7 stone
fill ~269 ~65 ~7 ~271 ~67 ~7 dirt
fill ~269 ~68 ~7 ~271 ~68 ~7 grass_block
fill ~256 ~60 ~8 ~257 ~63 ~8 stone
fill ~256 ~64 ~8 ~257 ~66 ~8 dirt
fill ~256 ~67 ~8 ~257 ~67 ~8 grass_block
fill ~258 ~60 ~8 ~264 ~62 ~8 stone
fill ~258 ~63 ~8 ~264 ~65 ~8 dirt
fill ~258 ~66 ~8 ~264 ~66 ~8 grass_block
fill ~265 ~60 ~8 ~269 ~63 ~8 stone
fill ~265 ~64 ~8 ~269 ~66 ~8 dirt
fill ~265 ~67 ~8 ~269 ~67 ~8 grass_block
fill ~270 ~60 ~8 ~271 ~64 ~8 stone
fill ~270 ~65 ~8 ~271 ~67 ~8 dirt
fill ~270 ~68 ~8 ~271 ~68 ~8 grass_block
fill ~256 ~60 ~9 ~258 ~63 ~9 stone
fill ~256 ~64 ~9 ~258 ~66 ~9 dirt
fill ~256 ~67 ~9 ~258 ~67 ~9 grass_block
fill ~259 ~60 ~9 ~265 ~62 ~9 stone
fill ~259 ~63 ~9 ~265 ~65 ~9 dirt
fill ~259 ~66 ~9 ~265 ~66 ~9 grass_block
fill ~266 ~60 ~9 ~270 ~63 ~9 stone
fill ~266 ~64 ~9 ~270 ~66 ~9 dirt
fill ~266 ~67 ~9 ~270 ~67 ~9 grass_block
fill ~271 ~60 ~9 ~271 ~64 ~9 stone
fill ~271 ~65 ~9 ~271 ~67 ~9 dirt
fill ~271 ~68 ~9 ~271 ~68 ~9 grass_block
fill ~256 ~60 ~10 ~259 ~63 ~10 stone
fill ~256 ~64 ~10 ~259 ~66 ~10 dirt
fill ~256 ~67 ~10 ~259 ~67 ~10 grass_block
fill ~260 ~60 ~10 ~266 ~62 ~10 stone
fill ~260 ~63 ~10 ~266 ~65 ~10 dirt
fill ~260 ~66 ~10 ~266 ~66 ~10 grass_block
fill ~267 ~60 ~10 ~271 ~63 ~10 stone
fill ~267 ~64 ~10 ~271 ~66 ~10 dirt
fill ~267 ~67 ~10 ~271 ~67 ~10 grass_block
fill ~256 ~60 ~11 ~259 ~63 ~11 stone
fill ~256 ~64 ~11 ~259 ~66 ~11 dirt
fill ~256 ~67 ~11 ~259 ~67 ~11 grass_block
fill ~260 ~60 ~11 ~267 ~62 ~11 stone
fill ~260 ~63 ~11 ~267 ~65 ~11 dirt
fill ~260 ~66 ~11 ~267 ~66 ~11 grass_block
fill ~268 ~60 ~11 ~271 ~63 ~11 stone
fill ~268 ~64 ~11 ~271 ~66 ~11 dirt
fill ~268 ~67 ~11 ~271 ~67 ~11 grass_block
fill ~256 ~60 ~12 ~256 ~64 ~12 stone
fill ~256 ~65 ~12 ~256 ~67 ~12 dirt
fill ~256 ~68 ~12 ~256 ~68 ~12 grass_block
fill ~257 ~60 ~12 ~260 ~63 ~12 stone
fill ~257 ~64 ~12 ~260 ~66 ~12 dirt
fill ~257 ~67 ~12 ~260 ~67 ~12 grass_block
fill ~261 ~60 ~12 ~269 ~62 ~12 stone
fill ~261 ~63 ~12 ~269 ~65 ~12 dirt
fill ~261 ~66 ~12 ~269 ~66 ~12 grass_block
fill ~270 ~60 ~12 ~271 ~63 ~12 stone
fill ~270 ~64 ~12 ~271 ~66 ~12 dirt
fill ~270 ~67 ~12 ~271 ~67 ~12 grass_block
fill ~256 ~60 ~13 ~257 ~64 ~13 stone
fill ~256 ~65 ~13 ~257 ~67 ~13 dirt
fill ~256 ~68 ~13 ~257 ~68 ~13 grass_block
fill ~258 ~60 ~13 ~261 ~63 ~13 stone
fill ~258 ~64 ~13 ~261 ~66 ~13 dirt
fill ~258 ~67 ~13 ~261 ~67 ~13 grass_block
fill ~262 ~60 ~13 ~269 ~62 ~13 stone
fill ~262 ~63 ~13 ~269 ~65 ~13 dirt
fill ~262 ~66 ~13 ~269 ~66 ~13 grass_block
fill ~270 ~60 ~13 ~271 ~63 ~13 stone
fill ~270 ~64 ~13 ~271 ~66 ~13 dirt
fill ~270 ~67 ~13 ~271 ~67 ~13 grass_block
fill ~256 ~60 ~14 ~257 ~64 ~14 stone
fill ~256 ~65 ~14 ~257 ~67 ~14 dirt
fill ~256 ~68 ~14 ~257 ~68 ~14 grass_block
fill ~258 ~60 ~14 ~262 ~63 ~14 stone
fill ~258 ~64 ~14 ~262 ~66 ~14 dirt
fill ~258 ~67 ~14 ~262 ~67 ~14 grass_block
fill ~263 ~60 ~14 ~269 ~62 ~14 stone
fill ~263 ~63 ~14 ~269 ~65 ~14 dirt
fill ~263 ~66 ~14 ~269 ~66 ~14 grass_block
fill ~270 ~60 ~14 ~271 ~63 ~14 stone
fill ~270 ~64 ~14 ~271 ~66 ~14 dirt
fill ~270 ~67 ~14 ~271 ~67 ~14 grass_block
fill ~256 ~60 ~15 ~257 ~64 ~15 stone
fill ~256 ~65 ~15 ~257 ~67 ~15 dirt
fill ~256 ~68 ~15 ~257 ~68 ~15 grass_block
fill ~258 ~60 ~15 ~262 ~63 ~15 stone
fill ~258 ~64 ~15 ~262 ~66 ~15 dirt
fill ~258 ~67 ~15 ~262 ~67 ~15 grass_block
fill ~263 ~60 ~15 ~270 ~62 ~15 stone
fill ~263 ~63 ~15 ~270 ~65 ~15 dirt
fill ~263 ~66 ~15 ~270 ~66 ~15 grass_block
fill ~271 ~60 ~15 ~271 ~63 ~15 stone
fill ~271 ~64 ~15 ~271 ~66 ~15 dirt
fill ~271 ~67 ~15 ~271 ~67 ~15 grass_block