fill ~128 ~60 ~112 ~129 ~64 ~112 stone
fill ~128 ~65 ~112 ~129 ~67 ~112 dirt
fill ~128 ~68 ~112 ~129 ~68 ~112 grass_block
fill ~130 ~60 ~112 ~130 ~65 ~112 stone
fill ~130 ~66 ~112 ~130 ~68 ~112 dirt
fill ~130 ~69 ~112 ~130 ~69 ~112 grass_block
fill ~131 ~60 ~112 ~134 ~64 ~112 stone
fill ~131 ~65 ~112 ~134 ~67 ~112 dirt
fill ~131 ~68 ~112 ~134 ~68 ~112 grass_block
fill ~135 ~60 ~112 ~136 ~63 ~112 stone
fill ~135 ~64 ~112 ~136 ~66 ~112 dirt
fill ~135 ~67 ~112 ~136 ~67 ~112 grass_block
fill ~137 ~60 ~112 ~138 ~64 ~112 stone
fill ~137 ~65 ~112 ~138 ~67 ~112 dirt
fill ~137 ~68 ~112 ~138 ~68 ~112 grass_block
fill ~139 ~60 ~112 ~143 ~65 ~112 stone
fill ~139 ~66 ~112 ~143 ~68 ~112 dirt
fill ~139 ~69 ~112 ~143 ~69 ~112 grass_block
fill ~128 ~60 ~113 ~131 ~65 ~113 stone
fill ~128 ~66 ~113 ~131 ~68 ~113 dirt
fill ~128 ~69 ~113 ~131 ~69 ~113 grass_block
fill ~132 ~60 ~113 ~137 ~64 ~113 stone
fill ~132 ~65 ~113 ~137 ~67 ~113 dirt
fill ~132 ~68 ~113 ~137 ~68 ~113 grass_block
fill ~138 ~60 ~113 ~143 ~65 ~113 stone
fill ~138 ~66 ~113 ~143 ~68 ~113 dirt
fill ~138 ~69 ~113 ~143 ~69 ~113 grass_block
fill ~128 ~60 ~114 ~128 ~65 ~114 stone
fill ~128 ~66 ~114 ~128 ~68 ~114 dirt
fill ~128 ~69 ~114 ~128 ~69 ~114 grass_block
fill ~129 ~60 ~114 ~130 ~66 ~114 stone
fill ~129 ~67 ~114 ~130 ~69 ~114 dirt
fill ~129 ~70 ~114 ~130 ~70 ~114 grass_block
fill ~131 ~60 ~114 ~132 ~65 ~114 stone
fill ~131 ~66 ~114 ~132 ~68 ~114 dirt
fill ~131 ~69 ~114 ~132 ~69 ~114 grass_block
fill ~133 ~60 ~114 ~133 ~64 ~114 stone
fill ~133 ~65 ~114 ~133 ~67 ~114 dirt
fill ~133 ~68 ~114 ~133 ~68 ~114 grass_block
fill ~134 ~60 ~114 ~143 ~65 ~114 stone
fill ~134 ~66 ~114 ~143 ~68 ~114 dirt
fill ~134 ~69 ~114 ~143 ~69 ~114 grass_block
fill ~128 ~60 ~115 ~131 ~66 ~115 stone
fill ~128 ~67 ~115 ~131 ~69 ~115 dirt
fill ~128 ~70 ~115 ~131 ~70 ~115 grass_block
fill ~132 ~60 ~115 ~133 ~65 ~115 stone
fill ~132 ~66 ~115 ~133 ~68 ~115 dirt
fill ~132 ~69 ~115 ~133 ~69 ~115 grass_block
fill ~134 ~60 ~115 ~138 ~66 ~115 stone
fill ~134 ~67 ~115 ~138 ~69 ~115 dirt
fill ~134 ~70 ~115 ~138 ~70 ~115 grass_block
fill ~139 ~60 ~115 ~142 ~65 ~115 stone
fill ~139 ~66 ~115 ~142 ~68 ~115 dirt
fill ~139 ~69 ~115 ~142 ~69 ~115 grass_block
fill ~143 ~60 ~115 ~143 ~64 ~115 stone
fill ~143 ~65 ~115 ~143 ~67 ~115 dirt
fill ~143 ~68 ~115 ~143 ~68 ~115 grass_block
fill ~128 ~60 ~116 ~128 ~66 ~116 stone
fill ~128 ~67 ~116 ~128 ~69 ~116 dirt
fill ~128 ~70 ~116 ~128 ~70 ~116 grass_block
fill ~129 ~60 ~116 ~130 ~67 ~116 stone
fill ~129 ~68 ~116 ~130 ~70 ~116 dirt
fill ~129 ~71 ~116 ~130 ~71 ~116 grass_block
fill ~131 ~60 ~116 ~138 ~66 ~116 stone
fill ~131 ~67 ~116 ~138 ~69 ~116 dirt
fill ~131 ~70 ~116 ~138 ~70 ~116 grass_block
fill ~139 ~60 ~116 ~141 ~65 ~116 stone
fill ~139 ~66 ~116 ~141 ~68 ~116 dirt
fill ~139 ~69 ~116 ~141 ~69 ~116 grass_block
fill ~142 ~60 ~116 ~143 ~64 ~116 stone
fill ~142 ~65 ~116 ~143 ~67 ~116 dirt
fill ~142 ~68 ~116 ~143 ~68 ~116 grass_block
fill ~128 ~60 ~117 ~132 ~67 ~117 stone
fill ~128 ~68 ~117 ~132 ~70 ~117 dirt
fill ~128 ~71 ~117 ~132 ~71 ~117 grass_block
fill ~133 ~60 ~117 ~133 ~66 ~117 stone
fill ~133 ~67 ~117 ~133 ~69 ~117 dirt
fill ~133 ~70 ~117 ~133 ~70 ~117 grass_block
fill ~134 ~60 ~117 ~135 ~67 ~117 stone
fill ~134 ~68 ~117 ~135 ~70 ~117 dirt
fill ~134 ~71 ~117 ~135 ~71 ~117 grass_block
fill ~136 ~60 ~117 ~138 ~66 ~117 stone
fill ~136 ~67 ~117 ~138 ~69 ~117 dirt
fill ~136 ~70 ~117 ~138 ~70 ~117 grass_block
fill ~139 ~60 ~117 ~140 ~65 ~117 stone
fill ~139 ~66 ~117 ~140 ~68 ~117 dirt
fill ~139 ~69 ~117 ~140 ~69 ~117 grass_block
fill ~141 ~60 ~117 ~143 ~64 ~117 stone
fill ~141 ~65 ~117 ~143 ~67 ~117 dirt
fill ~141 ~68 ~117 ~143 ~68 ~117 grass_block
fill ~128 ~60 ~118 ~136 ~67 ~118 stone
fill ~128 ~68 ~118 ~136 ~70 ~118 dirt
fill ~128 ~71 ~118 ~136 ~71 ~118 grass_block
fill ~137 ~60 ~118 ~139 ~66 ~118 stone
fill ~137 ~67 ~118 ~139 ~69 ~118 dirt
fill ~137 ~70 ~118 ~139 ~70 ~118 grass_block
fill ~140 ~60 ~118 ~140 ~65 ~118 stone
fill ~140 ~66 ~118 ~140 ~68 ~118 dirt
fill ~140 ~69 ~118 ~140 ~69 ~118 grass_block
fill ~141 ~60 ~118 ~143 ~64 ~118 stone
fill ~141 ~65 ~118 ~143 ~67 ~118 dirt
fill ~141 ~68 ~118 ~143 ~68 ~118 grass_block
fill ~128 ~60 ~119 ~137 ~67 ~119 stone
fill ~128 ~68 ~119 ~137 ~70 ~119 dirt
fill ~128 ~71 ~119 ~137 ~71 ~119 grass_block
fill ~138 ~60 ~119 ~139 ~66 ~119 stone
fill ~138 ~67 ~119 ~139 ~69 ~119 dirt
fill ~138 ~70 ~119 ~139 ~70 ~119 grass_block
fill ~140 ~60 ~119 ~142 ~65 ~119 stone
fill ~140 ~66 ~119 ~142 ~68 ~119 dirt
fill ~140 ~69 ~119 ~142 ~69 ~119 grass_block
fill ~143 ~60 ~119 ~143 ~64 ~119 stone
fill ~143 ~65 ~119 ~143 ~67 ~119 dirt
fill ~143 ~68 ~119 ~143 ~68 ~119 grass_block
fill ~128 ~60 ~120 ~138 ~67 ~120 stone
fill ~128 ~68 ~120 ~138 ~70 ~120 dirt
fill ~128 ~71 ~120 ~138 ~71 ~120 grass_block
fill ~139 ~60 ~120 ~142 ~66 ~120 stone
fill ~139 ~67 ~120 ~142 ~69 ~120 dirt
fill ~139 ~70 ~120 ~142 ~70 ~120 grass_block
fill ~143 ~60 ~120 ~143 ~65 ~120 stone
fill ~143 ~66 ~120 ~143 ~68 ~120 dirt
fill ~143 ~69 ~120 ~143 ~69 ~120 grass_block
fill ~128 ~60 ~121 ~140 ~67 ~121 stone
fill ~128 ~68 ~121 ~140 ~70 ~121 dirt
fill ~128 ~71 ~121 ~140 ~71 ~121 grass_block
fill ~141 ~60 ~121 ~143 ~66 ~121 stone
fill ~141 ~67 ~121 ~143 ~69 ~121 dirt
fill ~141 ~70 ~121 ~143 ~70 ~121 grass_block
fill ~128 ~60 ~122 ~141 ~67 ~122 stone
fill ~128 ~68 ~122 ~141 ~70 ~122 dirt
fill ~128 ~71 ~122 ~141 ~71 ~122 grass_block
fill ~142 ~60 ~122 ~143 ~66 ~122 stone
fill ~142 ~67 ~122 ~143 ~69 ~122 dirt
fill ~142 ~70 ~122 ~143 ~70 ~122 grass_block
fill ~128 ~60 ~123 ~143 ~67 ~123 stone
fill ~128 ~68 ~123 ~143 ~70 ~123 dirt
fill ~128 ~71 ~123 ~143 ~71 ~123 grass_block
fill ~128 ~60 ~124 ~128 ~67 ~124 stone
fill ~128 ~68 ~124 ~128 ~70 ~124 dirt
fill ~128 ~71 ~124 ~128 ~71 ~124 grass_block
fill ~129 ~60 ~124 ~131 ~66 ~124 stone
fill ~129 ~67 ~124 ~131 ~69 ~124 dirt
fill ~129 ~70 ~124 ~131 ~70 ~124 grass_block
fill ~132 ~60 ~124 ~143 ~67 ~124 stone
fill ~132 ~68 ~124 ~143 ~70 ~124 dirt
fill ~132 ~71 ~124 ~143 ~71 ~124 grass_block
fill ~128 ~60 ~125 ~128 ~67 ~125 stone
fill ~128 ~68 ~125 ~128 ~70 ~125 dirt
fill ~128 ~71 ~125 ~128 ~71 ~125 grass_block
fill ~129 ~60 ~125 ~133 ~66 ~125 stone
fill ~129 ~67 ~125 ~133 ~69 ~125 dirt
fill ~129 ~70 ~125 ~133 ~70 ~125 grass_block
fill ~134 ~60 ~125 ~143 ~67 ~125 stone
fill ~134 ~68 ~125 ~143 ~70 ~125 dirt
fill ~134 ~71 ~125 ~143 ~71 ~125 grass_block
fill ~128 ~60 ~126 ~130 ~66 ~126 stone
fill ~128 ~67 ~126 ~130 ~69 ~126 dirt
fill ~128 ~70 ~126 ~130 ~70 ~126 grass_block
fill ~131 ~60 ~126 ~131 ~65 ~126 stone
fill ~131 ~66 ~126 ~131 ~68 ~126 dirt
fill ~131 ~69 ~126 ~131 ~69 ~126 grass_block
fill ~132 ~60 ~126 ~135 ~66 ~126 stone
fill ~132 ~67 ~126 ~135 ~69 ~126 dirt
fill ~132 ~70 ~126 ~135 ~70 ~126 grass_block
fill ~136 ~60 ~126 ~143 ~67 ~126 stone
fill ~136 ~68 ~126 ~143 ~70 ~126 dirt
fill ~136 ~71 ~126 ~143 ~71 ~126 grass_block
fill ~128 ~60 ~127 ~130 ~66 ~127 stone
fill ~128 ~67 ~127 ~130 ~69 ~127 dirt
fill ~128 ~70 ~127 ~130 ~70 ~127 grass_block
fill ~131 ~60 ~127 ~133 ~65 ~127 stone
fill ~131 ~66 ~127 ~133 ~68 ~127 dirt
fill ~131 ~69 ~127 ~133 ~69 ~127 grass_block
fill ~134 ~60 ~127 ~137 ~66 ~127 stone
fill ~134 ~67 ~127 ~137 ~69 ~127 dirt
fill ~134 ~70 ~127 ~137 ~70 ~127 grass_block
fill ~138 ~60 ~127 ~143 ~67 ~127 stone
fill ~138 ~68 ~127 ~143 ~70 ~127 dirt
fill ~138 ~71 ~127 ~143 ~71 ~127 grass_block