fill ~240 ~60 ~112 ~240 ~63 ~112 stone
fill ~240 ~64 ~112 ~240 ~66 ~112 dirt
fill ~240 ~67 ~112 ~240 ~67 ~112 grass_block
fill ~241 ~60 ~112 ~244 ~62 ~112 stone
fill ~241 ~63 ~112 ~244 ~65 ~112 dirt
fill ~241 ~66 ~112 ~244 ~66 ~112 grass_block
fill ~245 ~60 ~112 ~249 ~63 ~112 stone
fill ~245 ~64 ~112 ~249 ~66 ~112 dirt
fill ~245 ~67 ~112 ~249 ~67 ~112 grass_block
fill ~250 ~60 ~112 ~254 ~64 ~112 stone
fill ~250 ~65 ~112 ~254 ~67 ~112 dirt
fill ~250 ~68 ~112 ~254 ~68 ~112 grass_block
fill ~255 ~60 ~112 ~255 ~63 ~112 stone
fill ~255 ~64 ~112 ~255 ~66 ~112 dirt
fill ~255 ~67 ~112 ~255 ~67 ~112 grass_block
fill ~240 ~60 ~113 ~242 ~63 ~113 stone
fill ~240 ~64 ~113 ~242 ~66 ~113 dirt
fill ~240 ~67 ~113 ~242 ~67 ~113 grass_block
fill ~243 ~60 ~113 ~245 ~62 ~113 stone
fill ~243 ~63 ~113 ~245 ~65 ~113 dirt
fill ~243 ~66 ~113 ~245 ~66 ~113 grass_block
fill ~246 ~60 ~113 ~255 ~63 ~113 stone
fill ~246 ~64 ~113 ~255 ~66 ~113 dirt
fill ~246 ~67 ~113 ~255 ~67 ~113 grass_block
fill ~240 ~60 ~114 ~244 ~63 ~114 stone
fill ~240 ~64 ~114 ~244 ~66 ~114 dirt
fill ~240 ~67 ~114 ~244 ~67 ~114 grass_block
fill ~245 ~60 ~114 ~248 ~62 ~114 stone
fill ~245 ~63 ~114 ~248 ~65 ~114 dirt
fill ~245 ~66 ~114 ~248 ~66 ~114 grass_block
fill ~249 ~60 ~114 ~255 ~63 ~114 stone
fill ~249 ~64 ~114 ~255 ~66 ~114 dirt
fill ~249 ~67 ~114 ~255 ~67 ~114 grass_block
fill ~240 ~60 ~115 ~242 ~63 ~115 stone
fill ~240 ~64 ~115 ~242 ~66 ~115 dirt
fill ~240 ~67 ~115 ~242 ~67 ~115 grass_block
fill ~243 ~60 ~115 ~243 ~64 ~115 stone
fill ~243 ~65 ~115 ~243 ~67 ~115 dirt
fill ~243 ~68 ~115 ~243 ~68 ~115 grass_block
fill ~244 ~60 ~115 ~246 ~63 ~115 stone
fill ~244 ~64 ~115 ~246 ~66 ~115 dirt
fill ~244 ~67 ~115 ~246 ~67 ~115 grass_block
fill ~247 ~60 ~115 ~249 ~62 ~115 stone
fill ~247 ~63 ~115 ~249 ~65 ~115 dirt
fill ~247 ~66 ~115 ~249 ~66 ~115 grass_block
fill ~250 ~60 ~115 ~255 ~63 ~115 stone
fill ~250 ~64 ~115 ~255 ~66 ~115 dirt
fill ~250 ~67 ~115 ~255 ~67 ~115 grass_block
fill ~240 ~60 ~116 ~244 ~64 ~116 stone
fill ~240 ~65 ~116 ~244 ~67 ~116 dirt
fill ~240 ~68 ~116 ~244 ~68 ~116 grass_block
fill ~245 ~60 ~116 ~247 ~63 ~116 stone
fill ~245 ~64 ~116 ~247 ~66 ~116 dirt
fill ~245 ~67 ~116 ~247 ~67 ~116 grass_block
fill ~248 ~60 ~116 ~253 ~62 ~116 stone
fill ~248 ~63 ~116 ~253 ~65 ~116 dirt
fill ~248 ~66 ~116 ~253 ~66 ~116 grass_block
fill ~254 ~60 ~116 ~255 ~63 ~116 stone
fill ~254 ~64 ~116 ~255 ~66 ~116 dirt
fill ~254 ~67 ~116 ~255 ~67 ~116 grass_block
fill ~240 ~60 ~117 ~242 ~65 ~117 stone
fill ~240 ~66 ~117 ~242 ~68 ~117 dirt
fill ~240 ~69 ~117 ~242 ~69 ~117 grass_block
fill ~243 ~60 ~117 ~246 ~64 ~117 stone
fill ~243 ~65 ~117 ~246 ~67 ~117 dirt
fill ~243 ~68 ~117 ~246 ~68 ~117 grass_block
fill ~247 ~60 ~117 ~249 ~63 ~117 stone
fill ~247 ~64 ~117 ~249 ~66 ~117 dirt
fill ~247 ~67 ~117 ~249 ~67 ~117 grass_block
fill ~250 ~60 ~117 ~255 ~62 ~117 stone
fill ~250 ~63 ~117 ~255 ~65 ~117 dirt
fill ~250 ~66 ~117 ~255 ~66 ~117 grass_block
fill ~240 ~60 ~118 ~245 ~65 ~118 stone
fill ~240 ~66 ~118 ~245 ~68 ~118 dirt
fill ~240 ~69 ~118 ~245 ~69 ~118 grass_block
fill ~246 ~60 ~118 ~247 ~64 ~118 stone
fill ~246 ~65 ~118 ~247 ~67 ~118 dirt
fill ~246 ~68 ~118 ~247 ~68 ~118 grass_block
fill ~248 ~60 ~118 ~250 ~63 ~118 stone
fill ~248 ~64 ~118 ~250 ~66 ~118 dirt
fill ~248 ~67 ~118 ~250 ~67 ~118 grass_block
fill ~251 ~60 ~118 ~255 ~62 ~118 stone
fill ~251 ~63 ~118 ~255 ~65 ~118 dirt
fill ~251 ~66 ~118 ~255 ~66 ~118 grass_block
fill ~240 ~60 ~119 ~246 ~65 ~119 stone
fill ~240 ~66 ~119 ~246 ~68 ~119 dirt
fill ~240 ~69 ~119 ~246 ~69 ~119 grass_block
fill ~247 ~60 ~119 ~248 ~64 ~119 stone
fill ~247 ~65 ~119 ~248 ~67 ~119 dirt
fill ~247 ~68 ~119 ~248 ~68 ~119 grass_block
fill ~249 ~60 ~119 ~254 ~63 ~119 stone
fill ~249 ~64 ~119 ~254 ~66 ~119 dirt
fill ~249 ~67 ~119 ~254 ~67 ~119 grass_block
fill ~255 ~60 ~119 ~255 ~62 ~119 stone
fill ~255 ~63 ~119 ~255 ~65 ~119 dirt
fill ~255 ~66 ~119 ~255 ~66 ~119 grass_block
fill ~240 ~60 ~120 ~247 ~65 ~120 stone
fill ~240 ~66 ~120 ~247 ~68 ~120 dirt
fill ~240 ~69 ~120 ~247 ~69 ~120 grass_block
fill ~248 ~60 ~120 ~251 ~64 ~120 stone
fill ~248 ~65 ~120 ~251 ~67 ~120 dirt
fill ~248 ~68 ~120 ~251 ~68 ~120 grass_block
fill ~252 ~60 ~120 ~255 ~63 ~120 stone
fill ~252 ~64 ~120 ~255 ~66 ~120 dirt
fill ~252 ~67 ~120 ~255 ~67 ~120 grass_block
fill ~240 ~60 ~121 ~241 ~65 ~121 stone
fill ~240 ~66 ~121 ~241 ~68 ~121 dirt
fill ~240 ~69 ~121 ~241 ~69 ~121 grass_block
fill ~242 ~60 ~121 ~244 ~66 ~121 stone
fill ~242 ~67 ~121 ~244 ~69 ~121 dirt
fill ~242 ~70 ~121 ~244 ~70 ~121 grass_block
fill ~245 ~60 ~121 ~249 ~65 ~121 stone
fill ~245 ~66 ~121 ~249 ~68 ~121 dirt
fill ~245 ~69 ~121 ~249 ~69 ~121 grass_block
fill ~250 ~60 ~121 ~253 ~64 ~121 stone
fill ~250 ~65 ~121 ~253 ~67 ~121 dirt
fill ~250 ~68 ~121 ~253 ~68 ~121 grass_block
fill ~254 ~60 ~121 ~255 ~63 ~121 stone
fill ~254 ~64 ~121 ~255 ~66 ~121 dirt
fill ~254 ~67 ~121 ~255 ~67 ~121 grass_block
fill ~240 ~60 ~122 ~242 ~65 ~122 stone
fill ~240 ~66 ~122 ~242 ~68 ~122 dirt
fill ~240 ~69 ~122 ~242 ~69 ~122 grass_block
fill ~243 ~60 ~122 ~246 ~66 ~122 stone
fill ~243 ~67 ~122 ~246 ~69 ~122 dirt
fill ~243 ~70 ~122 ~246 ~70 ~122 grass_block
fill ~247 ~60 ~122 ~250 ~65 ~122 stone
fill ~247 ~66 ~122 ~250 ~68 ~122 dirt
fill ~247 ~69 ~122 ~250 ~69 ~122 grass_block
fill ~251 ~60 ~122 ~253 ~64 ~122 stone
fill ~251 ~65 ~122 ~253 ~67 ~122 dirt
fill ~251 ~68 ~122 ~253 ~68 ~122 grass_block
fill ~254 ~60 ~122 ~255 ~63 ~122 stone
fill ~254 ~64 ~122 ~255 ~66 ~122 dirt
fill ~254 ~67 ~122 ~255 ~67 ~122 grass_block
fill ~240 ~60 ~123 ~243 ~65 ~123 stone
fill ~240 ~66 ~123 ~243 ~68 ~123 dirt
fill ~240 ~69 ~123 ~243 ~69 ~123 grass_block
fill ~244 ~60 ~123 ~245 ~66 ~123 stone
fill ~244 ~67 ~123 ~245 ~69 ~123 dirt
fill ~244 ~70 ~123 ~245 ~70 ~123 grass_block
fill ~246 ~60 ~123 ~251 ~65 ~123 stone
fill ~246 ~66 ~123 ~251 ~68 ~123 dirt
fill ~246 ~69 ~123 ~251 ~69 ~123 grass_block
fill ~252 ~60 ~123 ~254 ~64 ~123 stone
fill ~252 ~65 ~123 ~254 ~67 ~123 dirt
fill ~252 ~68 ~123 ~254 ~68 ~123 grass_block
fill ~255 ~60 ~123 ~255 ~63 ~123 stone
fill ~255 ~64 ~123 ~255 ~66 ~123 dirt
fill ~255 ~67 ~123 ~255 ~67 ~123 grass_block
fill ~240 ~60 ~124 ~246 ~65 ~124 stone
fill ~240 ~66 ~124 ~246 ~68 ~124 dirt
fill ~240 ~69 ~124 ~246 ~69 ~124 grass_block
fill ~247 ~60 ~124 ~248 ~66 ~124 stone
fill ~247 ~67 ~124 ~248 ~69 ~124 dirt
fill ~247 ~70 ~124 ~248 ~70 ~124 grass_block
fill ~249 ~60 ~124 ~251 ~65 ~124 stone
fill ~249 ~66 ~124 ~251 ~68 ~124 dirt
fill ~249 ~69 ~124 ~251 ~69 ~124 grass_block
fill ~252 ~60 ~124 ~254 ~64 ~124 stone
fill ~252 ~65 ~124 ~254 ~67 ~124 dirt
fill ~252 ~68 ~124 ~254 ~68 ~124 grass_block
fill ~255 ~60 ~124 ~255 ~63 ~124 stone
fill ~255 ~64 ~124 ~255 ~66 ~124 dirt
fill ~255 ~67 ~124 ~255 ~67 ~124 grass_block
fill ~240 ~60 ~125 ~240 ~64 ~125 stone
fill ~240 ~65 ~125 ~240 ~67 ~125 dirt
fill ~240 ~68 ~125 ~240 ~68 ~125 grass_block
fill ~241 ~60 ~125 ~252 ~65 ~125 stone
fill ~241 ~66 ~125 ~252 ~68 ~125 dirt
fill ~241 ~69 ~125 ~252 ~69 ~125 grass_block
fill ~253 ~60 ~125 ~255 ~64 ~125 stone
fill ~253 ~65 ~125 ~255 ~67 ~125 dirt
fill ~253 ~68 ~125 ~255 ~68 ~125 grass_block
fill ~240 ~60 ~126 ~241 ~64 ~126 stone
fill ~240 ~65 ~126 ~241 ~67 ~126 dirt
fill ~240 ~68 ~126 ~241 ~68 ~126 grass_block
fill ~242 ~60 ~126 ~253 ~65 ~126 stone
fill ~242 ~66 ~126 ~253 ~68 ~126 dirt
fill ~242 ~69 ~126 ~253 ~69 ~126 grass_block
fill ~254 ~60 ~126 ~255 ~64 ~126 stone
fill ~254 ~65 ~126 ~255 ~67 ~126 dirt
fill ~254 ~68 ~126 ~255 ~68 ~126 grass_block
fill ~240 ~60 ~127 ~242 ~64 ~127 stone
fill ~240 ~65 ~127 ~242 ~67 ~127 dirt
fill ~240 ~68 ~127 ~242 ~68 ~127 grass_block
fill ~243 ~60 ~127 ~254 ~65 ~127 stone
fill ~243 ~66 ~127 ~254 ~68 ~127 dirt
fill ~243 ~69 ~127 ~254 ~69 ~127 grass_block
fill ~255 ~60 ~127 ~255 ~64 ~127 stone
fill ~255 ~65 ~127 ~255 ~67 ~127 dirt
fill ~255 ~68 ~127 ~255 ~68 ~127 grass_block