fill ~256 ~60 ~16 ~258 ~64 ~16 stone
fill ~256 ~65 ~16 ~258 ~67 ~16 dirt
fill ~256 ~68 ~16 ~258 ~68 ~16 grass_block
fill ~259 ~60 ~16 ~262 ~63 ~16 stone
fill ~259 ~64 ~16 ~262 ~66 ~16 dirt
fill ~259 ~67 ~16 ~262 ~67 ~16 grass_block
fill ~263 ~60 ~16 ~270 ~62 ~16 stone
fill ~263 ~63 ~16 ~270 ~65 ~16 dirt
fill ~263 ~66 ~16 ~270 ~66 ~16 grass_block
fill ~271 ~60 ~16 ~271 ~63 ~16 stone
fill ~271 ~64 ~16 ~271 ~66 ~16 dirt
fill ~271 ~67 ~16 ~271 ~67 ~16 grass_block
fill ~256 ~60 ~17 ~258 ~64 ~17 stone
fill ~256 ~65 ~17 ~258 ~67 ~17 dirt
fill ~256 ~68 ~17 ~258 ~68 ~17 grass_block
fill ~259 ~60 ~17 ~262 ~63 ~17 stone
fill ~259 ~64 ~17 ~262 ~66 ~17 dirt
fill ~259 ~67 ~17 ~262 ~67 ~17 grass_block
fill ~263 ~60 ~17 ~270 ~62 ~17 stone
fill ~263 ~63 ~17 ~270 ~65 ~17 dirt
fill ~263 ~66 ~17 ~270 ~66 ~17 grass_block
fill ~271 ~60 ~17 ~271 ~63 ~17 stone
fill ~271 ~64 ~17 ~271 ~66 ~17 dirt
fill ~271 ~67 ~17 ~271 ~67 ~17 grass_block
fill ~256 ~60 ~18 ~260 ~64 ~18 stone
fill ~256 ~65 ~18 ~260 ~67 ~18 dirt
fill ~256 ~68 ~18 ~260 ~68 ~18 grass_block
fill ~261 ~60 ~18 ~263 ~63 ~18 stone
fill ~261 ~64 ~18 ~263 ~66 ~18 dirt
fill ~261 ~67 ~18 ~263 ~67 ~18 grass_block
fill ~264 ~60 ~18 ~271 ~62 ~18 stone
fill ~264 ~63 ~18 ~271 ~65 ~18 dirt
fill ~264 ~66 ~18 ~271 ~66 ~18 grass_block
fill ~256 ~60 ~19 ~260 ~64 ~19 stone
fill ~256 ~65 ~19 ~260 ~67 ~19 dirt
fill ~256 ~68 ~19 ~260 ~68 ~19 grass_block
fill ~261 ~60 ~19 ~264 ~63 ~19 stone
fill ~261 ~64 ~19 ~264 ~66 ~19 dirt
fill ~261 ~67 ~19 ~264 ~67 ~19 grass_block
fill ~265 ~60 ~19 ~271 ~62 ~19 stone
fill ~265 ~63 ~19 ~271 ~65 ~19 dirt
fill ~265 ~66 ~19 ~271 ~66 ~19 grass_block
fill ~256 ~60 ~20 ~257 ~63 ~20 stone
fill ~256 ~64 ~20 ~257 ~66 ~20 dirt
fill ~256 ~67 ~20 ~257 ~67 ~20 grass_block
fill ~258 ~60 ~20 ~260 ~64 ~20 stone
fill ~258 ~65 ~20 ~260 ~67 ~20 dirt
fill ~258 ~68 ~20 ~260 ~68 ~20 grass_block
fill ~261 ~60 ~20 ~265 ~63 ~20 stone
fill ~261 ~64 ~20 ~265 ~66 ~20 dirt
fill ~261 ~67 ~20 ~265 ~67 ~20 grass_block
fill ~266 ~60 ~20 ~271 ~62 ~20 stone
fill ~266 ~63 ~20 ~271 ~65 ~20 dirt
fill ~266 ~66 ~20 ~271 ~66 ~20 grass_block
fill ~256 ~60 ~21 ~259 ~63 ~21 stone
fill ~256 ~64 ~21 ~259 ~66 ~21 dirt
fill ~256 ~67 ~21 ~259 ~67 ~21 grass_block
fill ~260 ~60 ~21 ~261 ~64 ~21 stone
fill ~260 ~65 ~21 ~261 ~67 ~21 dirt
fill ~260 ~68 ~21 ~261 ~68 ~21 grass_block
fill ~262 ~60 ~21 ~265 ~63 ~21 stone
fill ~262 ~64 ~21 ~265 ~66 ~21 dirt
fill ~262 ~67 ~21 ~265 ~67 ~21 grass_block
fill ~266 ~60 ~21 ~271 ~62 ~21 stone
fill ~266 ~63 ~21 ~271 ~65 ~21 dirt
fill ~266 ~66 ~21 ~271 ~66 ~21 grass_block
fill ~256 ~60 ~22 ~265 ~63 ~22 stone
fill ~256 ~64 ~22 ~265 ~66 ~22 dirt
fill ~256 ~67 ~22 ~265 ~67 ~22 grass_block
fill ~266 ~60 ~22 ~271 ~62 ~22 stone
fill ~266 ~63 ~22 ~271 ~65 ~22 dirt
fill ~266 ~66 ~22 ~271 ~66 ~22 grass_block
fill ~256 ~60 ~23 ~256 ~62 ~23 stone
fill ~256 ~63 ~23 ~256 ~65 ~23 dirt
fill ~256 ~66 ~23 ~256 ~66 ~23 grass_block
fill ~257 ~60 ~23 ~266 ~63 ~23 stone
fill ~257 ~64 ~23 ~266 ~66 ~23 dirt
fill ~257 ~67 ~23 ~266 ~67 ~23 grass_block
fill ~267 ~60 ~23 ~271 ~62 ~23 stone
fill ~267 ~63 ~23 ~271 ~65 ~23 dirt
fill ~267 ~66 ~23 ~271 ~66 ~23 grass_block
fill ~256 ~60 ~24 ~258 ~62 ~24 stone
fill ~256 ~63 ~24 ~258 ~65 ~24 dirt
fill ~256 ~66 ~24 ~258 ~66 ~24 grass_block
fill ~259 ~60 ~24 ~266 ~63 ~24 stone
fill ~259 ~64 ~24 ~266 ~66 ~24 dirt
fill ~259 ~67 ~24 ~266 ~67 ~24 grass_block
fill ~267 ~60 ~24 ~271 ~62 ~24 stone
fill ~267 ~63 ~24 ~271 ~65 ~24 dirt
fill ~267 ~66 ~24 ~271 ~66 ~24 grass_block
fill ~256 ~60 ~25 ~258 ~62 ~25 stone
fill ~256 ~63 ~25 ~258 ~65 ~25 dirt
fill ~256 ~66 ~25 ~258 ~66 ~25 grass_block
fill ~259 ~60 ~25 ~267 ~63 ~25 stone
fill ~259 ~64 ~25 ~267 ~66 ~25 dirt
fill ~259 ~67 ~25 ~267 ~67 ~25 grass_block
fill ~268 ~60 ~25 ~271 ~62 ~25 stone
fill ~268 ~63 ~25 ~271 ~65 ~25 dirt
fill ~268 ~66 ~25 ~271 ~66 ~25 grass_block
fill ~256 ~60 ~26 ~260 ~62 ~26 stone
fill ~256 ~63 ~26 ~260 ~65 ~26 dirt
fill ~256 ~66 ~26 ~260 ~66 ~26 grass_block
fill ~261 ~60 ~26 ~267 ~63 ~26 stone
fill ~261 ~64 ~26 ~267 ~66 ~26 dirt
fill ~261 ~67 ~26 ~267 ~67 ~26 grass_block
fill ~268 ~60 ~26 ~271 ~62 ~26 stone
fill ~268 ~63 ~26 ~271 ~65 ~26 dirt
fill ~268 ~66 ~26 ~271 ~66 ~26 grass_block
fill ~256 ~60 ~27 ~256 ~61 ~27 stone
fill ~256 ~62 ~27 ~256 ~64 ~27 dirt
fill ~256 ~65 ~27 ~256 ~65 ~27 grass_block
fill ~257 ~60 ~27 ~261 ~62 ~27 stone
fill ~257 ~63 ~27 ~261 ~65 ~27 dirt
fill ~257 ~66 ~27 ~261 ~66 ~27 grass_block
fill ~262 ~60 ~27 ~267 ~63 ~27 stone
fill ~262 ~64 ~27 ~267 ~66 ~27 dirt
fill ~262 ~67 ~27 ~267 ~67 ~27 grass_block
fill ~268 ~60 ~27 ~271 ~62 ~27 stone
fill ~268 ~63 ~27 ~271 ~65 ~27 dirt
fill ~268 ~66 ~27 ~271 ~66 ~27 grass_block
fill ~256 ~60 ~28 ~256 ~62 ~28 stone
fill ~256 ~63 ~28 ~256 ~65 ~28 dirt
fill ~256 ~66 ~28 ~256 ~66 ~28 grass_block
fill ~257 ~60 ~28 ~257 ~61 ~28 stone
fill ~257 ~62 ~28 ~257 ~64 ~28 dirt
fill ~257 ~65 ~28 ~257 ~65 ~28 grass_block
fill ~258 ~60 ~28 ~261 ~62 ~28 stone
fill ~258 ~63 ~28 ~261 ~65 ~28 dirt
fill ~258 ~66 ~28 ~261 ~66 ~28 grass_block
fill ~262 ~60 ~28 ~268 ~63 ~28 stone
fill ~262 ~64 ~28 ~268 ~66 ~28 dirt
fill ~262 ~67 ~28 ~268 ~67 ~28 grass_block
fill ~269 ~60 ~28 ~271 ~62 ~28 stone
fill ~269 ~63 ~28 ~271 ~65 ~28 dirt
fill ~269 ~66 ~28 ~271 ~66 ~28 grass_block
fill ~256 ~60 ~29 ~256 ~62 ~29 stone
fill ~256 ~63 ~29 ~256 ~65 ~29 dirt
fill ~256 ~66 ~29 ~256 ~66 ~29 grass_block
fill ~257 ~60 ~29 ~258 ~61 ~29 stone
fill ~257 ~62 ~29 ~258 ~64 ~29 dirt
fill ~257 ~65 ~29 ~258 ~65 ~29 grass_block
fill ~259 ~60 ~29 ~263 ~62 ~29 stone
fill ~259 ~63 ~29 ~263 ~65 ~29 dirt
fill ~259 ~66 ~29 ~263 ~66 ~29 grass_block
fill ~264 ~60 ~29 ~268 ~63 ~29 stone
fill ~264 ~64 ~29 ~268 ~66 ~29 dirt
fill ~264 ~67 ~29 ~268 ~67 ~29 grass_block
fill ~269 ~60 ~29 ~271 ~62 ~29 stone
fill ~269 ~63 ~29 ~271 ~65 ~29 dirt
fill ~269 ~66 ~29 ~271 ~66 ~29 grass_block
fill ~256 ~60 ~30 ~258 ~62 ~30 stone
fill ~256 ~63 ~30 ~258 ~65 ~30 dirt
fill ~256 ~66 ~30 ~258 ~66 ~30 grass_block
fill ~259 ~60 ~30 ~260 ~61 ~30 stone
fill ~259 ~62 ~30 ~260 ~64 ~30 dirt
fill ~259 ~65 ~30 ~260 ~65 ~30 grass_block
fill ~261 ~60 ~30 ~264 ~62 ~30 stone
fill ~261 ~63 ~30 ~264 ~65 ~30 dirt
fill ~261 ~66 ~30 ~264 ~66 ~30 grass_block
fill ~265 ~60 ~30 ~268 ~63 ~30 stone
fill ~265 ~64 ~30 ~268 ~66 ~30 dirt
fill ~265 ~67 ~30 ~268 ~67 ~30 grass_block
fill ~269 ~60 ~30 ~271 ~62 ~30 stone
fill ~269 ~63 ~30 ~271 ~65 ~30 dirt
fill ~269 ~66 ~30 ~271 ~66 ~30 grass_block
fill ~256 ~60 ~31 ~256 ~63 ~31 stone
fill ~256 ~64 ~31 ~256 ~66 ~31 dirt
fill ~256 ~67 ~31 ~256 ~67 ~31 grass_block
fill ~257 ~60 ~31 ~259 ~62 ~31 stone
fill ~257 ~63 ~31 ~259 ~65 ~31 dirt
fill ~257 ~66 ~31 ~259 ~66 ~31 grass_block
fill ~260 ~60 ~31 ~261 ~61 ~31 stone
fill ~260 ~62 ~31 ~261 ~64 ~31 dirt
fill ~260 ~65 ~31 ~261 ~65 ~31 grass_block
fill ~262 ~60 ~31 ~266 ~62 ~31 stone
fill ~262 ~63 ~31 ~266 ~65 ~31 dirt
fill ~262 ~66 ~31 ~266 ~66 ~31 grass_block
fill ~267 ~60 ~31 ~267 ~63 ~31 stone
fill ~267 ~64 ~31 ~267 ~66 ~31 dirt
fill ~267 ~67 ~31 ~267 ~67 ~31 grass_block
fill ~268 ~60 ~31 ~271 ~62 ~31 stone
fill ~268 ~63 ~31 ~271 ~65 ~31 dirt
fill ~268 ~66 ~31 ~271 ~66 ~31 grass_block