fill ~448 ~60 ~16 ~450 ~64 ~16 stone
fill ~448 ~65 ~16 ~450 ~67 ~16 dirt
fill ~448 ~68 ~16 ~450 ~68 ~16 grass_block
fill ~451 ~60 ~16 ~455 ~63 ~16 stone
fill ~451 ~64 ~16 ~455 ~66 ~16 dirt
fill ~451 ~67 ~16 ~455 ~67 ~16 grass_block
fill ~456 ~60 ~16 ~457 ~62 ~16 stone
fill ~456 ~63 ~16 ~457 ~65 ~16 dirt
fill ~456 ~66 ~16 ~457 ~66 ~16 grass_block
fill ~458 ~60 ~16 ~458 ~63 ~16 stone
fill ~458 ~64 ~16 ~458 ~66 ~16 dirt
fill ~458 ~67 ~16 ~458 ~67 ~16 grass_block
fill ~459 ~60 ~16 ~462 ~64 ~16 stone
fill ~459 ~65 ~16 ~462 ~67 ~16 dirt
fill ~459 ~68 ~16 ~462 ~68 ~16 grass_block
fill ~463 ~60 ~16 ~463 ~65 ~16 stone
fill ~463 ~66 ~16 ~463 ~68 ~16 dirt
fill ~463 ~69 ~16 ~463 ~69 ~16 grass_block
fill ~448 ~60 ~17 ~449 ~64 ~17 stone
fill ~448 ~65 ~17 ~449 ~67 ~17 dirt
fill ~448 ~68 ~17 ~449 ~68 ~17 grass_block
fill ~450 ~60 ~17 ~453 ~63 ~17 stone
fill ~450 ~64 ~17 ~453 ~66 ~17 dirt
fill ~450 ~67 ~17 ~453 ~67 ~17 grass_block
fill ~454 ~60 ~17 ~457 ~62 ~17 stone
fill ~454 ~63 ~17 ~457 ~65 ~17 dirt
fill ~454 ~66 ~17 ~457 ~66 ~17 grass_block
fill ~458 ~60 ~17 ~459 ~63 ~17 stone
fill ~458 ~64 ~17 ~459 ~66 ~17 dirt
fill ~458 ~67 ~17 ~459 ~67 ~17 grass_block
fill ~460 ~60 ~17 ~462 ~64 ~17 stone
fill ~460 ~65 ~17 ~462 ~67 ~17 dirt
fill ~460 ~68 ~17 ~462 ~68 ~17 grass_block
fill ~463 ~60 ~17 ~463 ~65 ~17 stone
fill ~463 ~66 ~17 ~463 ~68 ~17 dirt
fill ~463 ~69 ~17 ~463 ~69 ~17 grass_block
fill ~448 ~60 ~18 ~448 ~64 ~18 stone
fill ~448 ~65 ~18 ~448 ~67 ~18 dirt
fill ~448 ~68 ~18 ~448 ~68 ~18 grass_block
fill ~449 ~60 ~18 ~453 ~63 ~18 stone
fill ~449 ~64 ~18 ~453 ~66 ~18 dirt
fill ~449 ~67 ~18 ~453 ~67 ~18 grass_block
fill ~454 ~60 ~18 ~457 ~62 ~18 stone
fill ~454 ~63 ~18 ~457 ~65 ~18 dirt
fill ~454 ~66 ~18 ~457 ~66 ~18 grass_block
fill ~458 ~60 ~18 ~459 ~63 ~18 stone
fill ~458 ~64 ~18 ~459 ~66 ~18 dirt
fill ~458 ~67 ~18 ~459 ~67 ~18 grass_block
fill ~460 ~60 ~18 ~462 ~64 ~18 stone
fill ~460 ~65 ~18 ~462 ~67 ~18 dirt
fill ~460 ~68 ~18 ~462 ~68 ~18 grass_block
fill ~463 ~60 ~18 ~463 ~65 ~18 stone
fill ~463 ~66 ~18 ~463 ~68 ~18 dirt
fill ~463 ~69 ~18 ~463 ~69 ~18 grass_block
fill ~448 ~60 ~19 ~453 ~63 ~19 stone
fill ~448 ~64 ~19 ~453 ~66 ~19 dirt
fill ~448 ~67 ~19 ~453 ~67 ~19 grass_block
fill ~454 ~60 ~19 ~457 ~62 ~19 stone
fill ~454 ~63 ~19 ~457 ~65 ~19 dirt
fill ~454 ~66 ~19 ~457 ~66 ~19 grass_block
fill ~458 ~60 ~19 ~459 ~63 ~19 stone
fill ~458 ~64 ~19 ~459 ~66 ~19 dirt
fill ~458 ~67 ~19 ~459 ~67 ~19 grass_block
fill ~460 ~60 ~19 ~463 ~64 ~19 stone
fill ~460 ~65 ~19 ~463 ~67 ~19 dirt
fill ~460 ~68 ~19 ~463 ~68 ~19 grass_block
fill ~448 ~60 ~20 ~448 ~64 ~20 stone
fill ~448 ~65 ~20 ~448 ~67 ~20 dirt
fill ~448 ~68 ~20 ~448 ~68 ~20 grass_block
fill ~449 ~60 ~20 ~453 ~63 ~20 stone
fill ~449 ~64 ~20 ~453 ~66 ~20 dirt
fill ~449 ~67 ~20 ~453 ~67 ~20 grass_block
fill ~454 ~60 ~20 ~457 ~62 ~20 stone
fill ~454 ~63 ~20 ~457 ~65 ~20 dirt
fill ~454 ~66 ~20 ~457 ~66 ~20 grass_block
fill ~458 ~60 ~20 ~460 ~63 ~20 stone
fill ~458 ~64 ~20 ~460 ~66 ~20 dirt
fill ~458 ~67 ~20 ~460 ~67 ~20 grass_block
fill ~461 ~60 ~20 ~463 ~64 ~20 stone
fill ~461 ~65 ~20 ~463 ~67 ~20 dirt
fill ~461 ~68 ~20 ~463 ~68 ~20 grass_block
fill ~448 ~60 ~21 ~448 ~64 ~21 stone
fill ~448 ~65 ~21 ~448 ~67 ~21 dirt
fill ~448 ~68 ~21 ~448 ~68 ~21 grass_block
fill ~449 ~60 ~21 ~453 ~63 ~21 stone
fill ~449 ~64 ~21 ~453 ~66 ~21 dirt
fill ~449 ~67 ~21 ~453 ~67 ~21 grass_block
fill ~454 ~60 ~21 ~457 ~62 ~21 stone
fill ~454 ~63 ~21 ~457 ~65 ~21 dirt
fill ~454 ~66 ~21 ~457 ~66 ~21 grass_block
fill ~458 ~60 ~21 ~460 ~63 ~21 stone
fill ~458 ~64 ~21 ~460 ~66 ~21 dirt
fill ~458 ~67 ~21 ~460 ~67 ~21 grass_block
fill ~461 ~60 ~21 ~463 ~64 ~21 stone
fill ~461 ~65 ~21 ~463 ~67 ~21 dirt
fill ~461 ~68 ~21 ~463 ~68 ~21 grass_block
fill ~448 ~60 ~22 ~448 ~64 ~22 stone
fill ~448 ~65 ~22 ~448 ~67 ~22 dirt
fill ~448 ~68 ~22 ~448 ~68 ~22 grass_block
fill ~449 ~60 ~22 ~452 ~63 ~22 stone
fill ~449 ~64 ~22 ~452 ~66 ~22 dirt
fill ~449 ~67 ~22 ~452 ~67 ~22 grass_block
fill ~453 ~60 ~22 ~457 ~62 ~22 stone
fill ~453 ~63 ~22 ~457 ~65 ~22 dirt
fill ~453 ~66 ~22 ~457 ~66 ~22 grass_block
fill ~458 ~60 ~22 ~460 ~63 ~22 stone
fill ~458 ~64 ~22 ~460 ~66 ~22 dirt
fill ~458 ~67 ~22 ~460 ~67 ~22 grass_block
fill ~461 ~60 ~22 ~463 ~64 ~22 stone
fill ~461 ~65 ~22 ~463 ~67 ~22 dirt
fill ~461 ~68 ~22 ~463 ~68 ~22 grass_block
fill ~448 ~60 ~23 ~452 ~63 ~23 stone
fill ~448 ~64 ~23 ~452 ~66 ~23 dirt
fill ~448 ~67 ~23 ~452 ~67 ~23 grass_block
fill ~453 ~60 ~23 ~457 ~62 ~23 stone
fill ~453 ~63 ~23 ~457 ~65 ~23 dirt
fill ~453 ~66 ~23 ~457 ~66 ~23 grass_block
fill ~458 ~60 ~23 ~460 ~63 ~23 stone
fill ~458 ~64 ~23 ~460 ~66 ~23 dirt
fill ~458 ~67 ~23 ~460 ~67 ~23 grass_block
fill ~461 ~60 ~23 ~463 ~64 ~23 stone
fill ~461 ~65 ~23 ~463 ~67 ~23 dirt
fill ~461 ~68 ~23 ~463 ~68 ~23 grass_block
fill ~448 ~60 ~24 ~452 ~63 ~24 stone
fill ~448 ~64 ~24 ~452 ~66 ~24 dirt
fill ~448 ~67 ~24 ~452 ~67 ~24 grass_block
fill ~453 ~60 ~24 ~458 ~62 ~24 stone
fill ~453 ~63 ~24 ~458 ~65 ~24 dirt
fill ~453 ~66 ~24 ~458 ~66 ~24 grass_block
fill ~459 ~60 ~24 ~460 ~63 ~24 stone
fill ~459 ~64 ~24 ~460 ~66 ~24 dirt
fill ~459 ~67 ~24 ~460 ~67 ~24 grass_block
fill ~461 ~60 ~24 ~463 ~64 ~24 stone
fill ~461 ~65 ~24 ~463 ~67 ~24 dirt
fill ~461 ~68 ~24 ~463 ~68 ~24 grass_block
fill ~448 ~60 ~25 ~451 ~63 ~25 stone
fill ~448 ~64 ~25 ~451 ~66 ~25 dirt
fill ~448 ~67 ~25 ~451 ~67 ~25 grass_block
fill ~452 ~60 ~25 ~458 ~62 ~25 stone
fill ~452 ~63 ~25 ~458 ~65 ~25 dirt
fill ~452 ~66 ~25 ~458 ~66 ~25 grass_block
fill ~459 ~60 ~25 ~460 ~63 ~25 stone
fill ~459 ~64 ~25 ~460 ~66 ~25 dirt
fill ~459 ~67 ~25 ~460 ~67 ~25 grass_block
fill ~461 ~60 ~25 ~463 ~64 ~25 stone
fill ~461 ~65 ~25 ~463 ~67 ~25 dirt
fill ~461 ~68 ~25 ~463 ~68 ~25 grass_block
fill ~448 ~60 ~26 ~451 ~63 ~26 stone
fill ~448 ~64 ~26 ~451 ~66 ~26 dirt
fill ~448 ~67 ~26 ~451 ~67 ~26 grass_block
fill ~452 ~60 ~26 ~458 ~62 ~26 stone
fill ~452 ~63 ~26 ~458 ~65 ~26 dirt
fill ~452 ~66 ~26 ~458 ~66 ~26 grass_block
fill ~459 ~60 ~26 ~460 ~63 ~26 stone
fill ~459 ~64 ~26 ~460 ~66 ~26 dirt
fill ~459 ~67 ~26 ~460 ~67 ~26 grass_block
fill ~461 ~60 ~26 ~463 ~64 ~26 stone
fill ~461 ~65 ~26 ~463 ~67 ~26 dirt
fill ~461 ~68 ~26 ~463 ~68 ~26 grass_block
fill ~448 ~60 ~27 ~448 ~62 ~27 stone
fill ~448 ~63 ~27 ~448 ~65 ~27 dirt
fill ~448 ~66 ~27 ~448 ~66 ~27 grass_block
fill ~449 ~60 ~27 ~451 ~63 ~27 stone
fill ~449 ~64 ~27 ~451 ~66 ~27 dirt
fill ~449 ~67 ~27 ~451 ~67 ~27 grass_block
fill ~452 ~60 ~27 ~458 ~62 ~27 stone
fill ~452 ~63 ~27 ~458 ~65 ~27 dirt
fill ~452 ~66 ~27 ~458 ~66 ~27 grass_block
fill ~459 ~60 ~27 ~463 ~63 ~27 stone
fill ~459 ~64 ~27 ~463 ~66 ~27 dirt
fill ~459 ~67 ~27 ~463 ~67 ~27 grass_block
fill ~448 ~60 ~28 ~458 ~62 ~28 stone
fill ~448 ~63 ~28 ~458 ~65 ~28 dirt
fill ~448 ~66 ~28 ~458 ~66 ~28 grass_block
fill ~459 ~60 ~28 ~463 ~63 ~28 stone
fill ~459 ~64 ~28 ~463 ~66 ~28 dirt
fill ~459 ~67 ~28 ~463 ~67 ~28 grass_block
fill ~448 ~60 ~29 ~459 ~62 ~29 stone
fill ~448 ~63 ~29 ~459 ~65 ~29 dirt
fill ~448 ~66 ~29 ~459 ~66 ~29 grass_block
fill ~460 ~60 ~29 ~463 ~63 ~29 stone
fill ~460 ~64 ~29 ~463 ~66 ~29 dirt
fill ~460 ~67 ~29 ~463 ~67 ~29 grass_block
fill ~448 ~60 ~30 ~460 ~62 ~30 stone
fill ~448 ~63 ~30 ~460 ~65 ~30 dirt
fill ~448 ~66 ~30 ~460 ~66 ~30 grass_block
fill ~461 ~60 ~30 ~463 ~63 ~30 stone
fill ~461 ~64 ~30 ~463 ~66 ~30 dirt
fill ~461 ~67 ~30 ~463 ~67 ~30 grass_block
fill ~448 ~60 ~31 ~449 ~61 ~31 stone
fill ~448 ~62 ~31 ~449 ~64 ~31 dirt
fill ~448 ~65 ~31 ~449 ~65 ~31 grass_block
fill ~450 ~60 ~31 ~454 ~62 ~31 stone
fill ~450 ~63 ~31 ~454 ~65 ~31 dirt
fill ~450 ~66 ~31 ~454 ~66 ~31 grass_block
fill ~455 ~60 ~31 ~456 ~61 ~31 stone
fill ~455 ~62 ~31 ~456 ~64 ~31 dirt
fill ~455 ~65 ~31 ~456 ~65 ~31 grass_block
fill ~457 ~60 ~31 ~463 ~62 ~31 stone
fill ~457 ~63 ~31 ~463 ~65 ~31 dirt
fill ~457 ~66 ~31 ~463 ~66 ~31 grass_block