fill ~416 ~60 ~48 ~417 ~64 ~48 stone
fill ~416 ~65 ~48 ~417 ~67 ~48 dirt
fill ~416 ~68 ~48 ~417 ~68 ~48 grass_block
fill ~418 ~60 ~48 ~421 ~65 ~48 stone
fill ~418 ~66 ~48 ~421 ~68 ~48 dirt
fill ~418 ~69 ~48 ~421 ~69 ~48 grass_block
fill ~422 ~60 ~48 ~426 ~64 ~48 stone
fill ~422 ~65 ~48 ~426 ~67 ~48 dirt
fill ~422 ~68 ~48 ~426 ~68 ~48 grass_block
fill ~427 ~60 ~48 ~431 ~63 ~48 stone
fill ~427 ~64 ~48 ~431 ~66 ~48 dirt
fill ~427 ~67 ~48 ~431 ~67 ~48 grass_block
fill ~416 ~60 ~49 ~417 ~64 ~49 stone
fill ~416 ~65 ~49 ~417 ~67 ~49 dirt
fill ~416 ~68 ~49 ~417 ~68 ~49 grass_block
fill ~418 ~60 ~49 ~421 ~65 ~49 stone
fill ~418 ~66 ~49 ~421 ~68 ~49 dirt
fill ~418 ~69 ~49 ~421 ~69 ~49 grass_block
fill ~422 ~60 ~49 ~425 ~64 ~49 stone
fill ~422 ~65 ~49 ~425 ~67 ~49 dirt
fill ~422 ~68 ~49 ~425 ~68 ~49 grass_block
fill ~426 ~60 ~49 ~431 ~63 ~49 stone
fill ~426 ~64 ~49 ~431 ~66 ~49 dirt
fill ~426 ~67 ~49 ~431 ~67 ~49 grass_block
fill ~416 ~60 ~50 ~417 ~64 ~50 stone
fill ~416 ~65 ~50 ~417 ~67 ~50 dirt
fill ~416 ~68 ~50 ~417 ~68 ~50 grass_block
fill ~418 ~60 ~50 ~418 ~65 ~50 stone
fill ~418 ~66 ~50 ~418 ~68 ~50 dirt
fill ~418 ~69 ~50 ~418 ~69 ~50 grass_block
fill ~419 ~60 ~50 ~420 ~66 ~50 stone
fill ~419 ~67 ~50 ~420 ~69 ~50 dirt
fill ~419 ~70 ~50 ~420 ~70 ~50 grass_block
fill ~421 ~60 ~50 ~422 ~65 ~50 stone
fill ~421 ~66 ~50 ~422 ~68 ~50 dirt
fill ~421 ~69 ~50 ~422 ~69 ~50 grass_block
fill ~423 ~60 ~50 ~426 ~64 ~50 stone
fill ~423 ~65 ~50 ~426 ~67 ~50 dirt
fill ~423 ~68 ~50 ~426 ~68 ~50 grass_block
fill ~427 ~60 ~50 ~431 ~63 ~50 stone
fill ~427 ~64 ~50 ~431 ~66 ~50 dirt
fill ~427 ~67 ~50 ~431 ~67 ~50 grass_block
fill ~416 ~60 ~51 ~418 ~65 ~51 stone
fill ~416 ~66 ~51 ~418 ~68 ~51 dirt
fill ~416 ~69 ~51 ~418 ~69 ~51 grass_block
fill ~419 ~60 ~51 ~422 ~66 ~51 stone
fill ~419 ~67 ~51 ~422 ~69 ~51 dirt
fill ~419 ~70 ~51 ~422 ~70 ~51 grass_block
fill ~423 ~60 ~51 ~425 ~65 ~51 stone
fill ~423 ~66 ~51 ~425 ~68 ~51 dirt
fill ~423 ~69 ~51 ~425 ~69 ~51 grass_block
fill ~426 ~60 ~51 ~428 ~64 ~51 stone
fill ~426 ~65 ~51 ~428 ~67 ~51 dirt
fill ~426 ~68 ~51 ~428 ~68 ~51 grass_block
fill ~429 ~60 ~51 ~431 ~63 ~51 stone
fill ~429 ~64 ~51 ~431 ~66 ~51 dirt
fill ~429 ~67 ~51 ~431 ~67 ~51 grass_block
fill ~416 ~60 ~52 ~417 ~65 ~52 stone
fill ~416 ~66 ~52 ~417 ~68 ~52 dirt
fill ~416 ~69 ~52 ~417 ~69 ~52 grass_block
fill ~418 ~60 ~52 ~423 ~66 ~52 stone
fill ~418 ~67 ~52 ~423 ~69 ~52 dirt
fill ~418 ~70 ~52 ~423 ~70 ~52 grass_block
fill ~424 ~60 ~52 ~426 ~65 ~52 stone
fill ~424 ~66 ~52 ~426 ~68 ~52 dirt
fill ~424 ~69 ~52 ~426 ~69 ~52 grass_block
fill ~427 ~60 ~52 ~428 ~64 ~52 stone
fill ~427 ~65 ~52 ~428 ~67 ~52 dirt
fill ~427 ~68 ~52 ~428 ~68 ~52 grass_block
fill ~429 ~60 ~52 ~431 ~63 ~52 stone
fill ~429 ~64 ~52 ~431 ~66 ~52 dirt
fill ~429 ~67 ~52 ~431 ~67 ~52 grass_block
fill ~416 ~60 ~53 ~424 ~66 ~53 stone
fill ~416 ~67 ~53 ~424 ~69 ~53 dirt
fill ~416 ~70 ~53 ~424 ~70 ~53 grass_block
fill ~425 ~60 ~53 ~426 ~65 ~53 stone
fill ~425 ~66 ~53 ~426 ~68 ~53 dirt
fill ~425 ~69 ~53 ~426 ~69 ~53 grass_block
fill ~427 ~60 ~53 ~428 ~64 ~53 stone
fill ~427 ~65 ~53 ~428 ~67 ~53 dirt
fill ~427 ~68 ~53 ~428 ~68 ~53 grass_block
fill ~429 ~60 ~53 ~431 ~63 ~53 stone
fill ~429 ~64 ~53 ~431 ~66 ~53 dirt
fill ~429 ~67 ~53 ~431 ~67 ~53 grass_block
fill ~416 ~60 ~54 ~425 ~66 ~54 stone
fill ~416 ~67 ~54 ~425 ~69 ~54 dirt
fill ~416 ~70 ~54 ~425 ~70 ~54 grass_block
fill ~426 ~60 ~54 ~426 ~65 ~54 stone
fill ~426 ~66 ~54 ~426 ~68 ~54 dirt
fill ~426 ~69 ~54 ~426 ~69 ~54 grass_block
fill ~427 ~60 ~54 ~429 ~64 ~54 stone
fill ~427 ~65 ~54 ~429 ~67 ~54 dirt
fill ~427 ~68 ~54 ~429 ~68 ~54 grass_block
fill ~430 ~60 ~54 ~431 ~63 ~54 stone
fill ~430 ~64 ~54 ~431 ~66 ~54 dirt
fill ~430 ~67 ~54 ~431 ~67 ~54 grass_block
fill ~416 ~60 ~55 ~426 ~66 ~55 stone
fill ~416 ~67 ~55 ~426 ~69 ~55 dirt
fill ~416 ~70 ~55 ~426 ~70 ~55 grass_block
fill ~427 ~60 ~55 ~427 ~65 ~55 stone
fill ~427 ~66 ~55 ~427 ~68 ~55 dirt
fill ~427 ~69 ~55 ~427 ~69 ~55 grass_block
fill ~428 ~60 ~55 ~430 ~64 ~55 stone
fill ~428 ~65 ~55 ~430 ~67 ~55 dirt
fill ~428 ~68 ~55 ~430 ~68 ~55 grass_block
fill ~431 ~60 ~55 ~431 ~63 ~55 stone
fill ~431 ~64 ~55 ~431 ~66 ~55 dirt
fill ~431 ~67 ~55 ~431 ~67 ~55 grass_block
fill ~416 ~60 ~56 ~425 ~66 ~56 stone
fill ~416 ~67 ~56 ~425 ~69 ~56 dirt
fill ~416 ~70 ~56 ~425 ~70 ~56 grass_block
fill ~426 ~60 ~56 ~427 ~65 ~56 stone
fill ~426 ~66 ~56 ~427 ~68 ~56 dirt
fill ~426 ~69 ~56 ~427 ~69 ~56 grass_block
fill ~428 ~60 ~56 ~430 ~64 ~56 stone
fill ~428 ~65 ~56 ~430 ~67 ~56 dirt
fill ~428 ~68 ~56 ~430 ~68 ~56 grass_block
fill ~431 ~60 ~56 ~431 ~63 ~56 stone
fill ~431 ~64 ~56 ~431 ~66 ~56 dirt
fill ~431 ~67 ~56 ~431 ~67 ~56 grass_block
fill ~416 ~60 ~57 ~424 ~66 ~57 stone
fill ~416 ~67 ~57 ~424 ~69 ~57 dirt
fill ~416 ~70 ~57 ~424 ~70 ~57 grass_block
fill ~425 ~60 ~57 ~427 ~65 ~57 stone
fill ~425 ~66 ~57 ~427 ~68 ~57 dirt
fill ~425 ~69 ~57 ~427 ~69 ~57 grass_block
fill ~428 ~60 ~57 ~430 ~64 ~57 stone
fill ~428 ~65 ~57 ~430 ~67 ~57 dirt
fill ~428 ~68 ~57 ~430 ~68 ~57 grass_block
fill ~431 ~60 ~57 ~431 ~63 ~57 stone
fill ~431 ~64 ~57 ~431 ~66 ~57 dirt
fill ~431 ~67 ~57 ~431 ~67 ~57 grass_block
fill ~416 ~60 ~58 ~416 ~66 ~58 stone
fill ~416 ~67 ~58 ~416 ~69 ~58 dirt
fill ~416 ~70 ~58 ~416 ~70 ~58 grass_block
fill ~417 ~60 ~58 ~418 ~65 ~58 stone
fill ~417 ~66 ~58 ~418 ~68 ~58 dirt
fill ~417 ~69 ~58 ~418 ~69 ~58 grass_block
fill ~419 ~60 ~58 ~426 ~66 ~58 stone
fill ~419 ~67 ~58 ~426 ~69 ~58 dirt
fill ~419 ~70 ~58 ~426 ~70 ~58 grass_block
fill ~427 ~60 ~58 ~429 ~65 ~58 stone
fill ~427 ~66 ~58 ~429 ~68 ~58 dirt
fill ~427 ~69 ~58 ~429 ~69 ~58 grass_block
fill ~430 ~60 ~58 ~431 ~64 ~58 stone
fill ~430 ~65 ~58 ~431 ~67 ~58 dirt
fill ~430 ~68 ~58 ~431 ~68 ~58 grass_block
fill ~416 ~60 ~59 ~419 ~65 ~59 stone
fill ~416 ~66 ~59 ~419 ~68 ~59 dirt
fill ~416 ~69 ~59 ~419 ~69 ~59 grass_block
fill ~420 ~60 ~59 ~426 ~66 ~59 stone
fill ~420 ~67 ~59 ~426 ~69 ~59 dirt
fill ~420 ~70 ~59 ~426 ~70 ~59 grass_block
fill ~427 ~60 ~59 ~429 ~65 ~59 stone
fill ~427 ~66 ~59 ~429 ~68 ~59 dirt
fill ~427 ~69 ~59 ~429 ~69 ~59 grass_block
fill ~430 ~60 ~59 ~431 ~64 ~59 stone
fill ~430 ~65 ~59 ~431 ~67 ~59 dirt
fill ~430 ~68 ~59 ~431 ~68 ~59 grass_block
fill ~416 ~60 ~60 ~420 ~65 ~60 stone
fill ~416 ~66 ~60 ~420 ~68 ~60 dirt
fill ~416 ~69 ~60 ~420 ~69 ~60 grass_block
fill ~421 ~60 ~60 ~427 ~66 ~60 stone
fill ~421 ~67 ~60 ~427 ~69 ~60 dirt
fill ~421 ~70 ~60 ~427 ~70 ~60 grass_block
fill ~428 ~60 ~60 ~429 ~65 ~60 stone
fill ~428 ~66 ~60 ~429 ~68 ~60 dirt
fill ~428 ~69 ~60 ~429 ~69 ~60 grass_block
fill ~430 ~60 ~60 ~431 ~64 ~60 stone
fill ~430 ~65 ~60 ~431 ~67 ~60 dirt
fill ~430 ~68 ~60 ~431 ~68 ~60 grass_block
fill ~416 ~60 ~61 ~422 ~65 ~61 stone
fill ~416 ~66 ~61 ~422 ~68 ~61 dirt
fill ~416 ~69 ~61 ~422 ~69 ~61 grass_block
fill ~423 ~60 ~61 ~428 ~66 ~61 stone
fill ~423 ~67 ~61 ~428 ~69 ~61 dirt
fill ~423 ~70 ~61 ~428 ~70 ~61 grass_block
fill ~429 ~60 ~61 ~430 ~65 ~61 stone
fill ~429 ~66 ~61 ~430 ~68 ~61 dirt
fill ~429 ~69 ~61 ~430 ~69 ~61 grass_block
fill ~431 ~60 ~61 ~431 ~64 ~61 stone
fill ~431 ~65 ~61 ~431 ~67 ~61 dirt
fill ~431 ~68 ~61 ~431 ~68 ~61 grass_block
fill ~416 ~60 ~62 ~422 ~65 ~62 stone
fill ~416 ~66 ~62 ~422 ~68 ~62 dirt
fill ~416 ~69 ~62 ~422 ~69 ~62 grass_block
fill ~423 ~60 ~62 ~428 ~66 ~62 stone
fill ~423 ~67 ~62 ~428 ~69 ~62 dirt
fill ~423 ~70 ~62 ~428 ~70 ~62 grass_block
fill ~429 ~60 ~62 ~431 ~65 ~62 stone
fill ~429 ~66 ~62 ~431 ~68 ~62 dirt
fill ~429 ~69 ~62 ~431 ~69 ~62 grass_block
fill ~416 ~60 ~63 ~423 ~65 ~63 stone
fill ~416 ~66 ~63 ~423 ~68 ~63 dirt
fill ~416 ~69 ~63 ~423 ~69 ~63 grass_block
fill ~424 ~60 ~63 ~429 ~66 ~63 stone
fill ~424 ~67 ~63 ~429 ~69 ~63 dirt
fill ~424 ~70 ~63 ~429 ~70 ~63 grass_block
fill ~430 ~60 ~63 ~431 ~65 ~63 stone
fill ~430 ~66 ~63 ~431 ~68 ~63 dirt
fill ~430 ~69 ~63 ~431 ~69 ~63 grass_block