fill ~64 ~60 ~80 ~64 ~66 ~80 stone
fill ~64 ~67 ~80 ~64 ~69 ~80 dirt
fill ~64 ~70 ~80 ~64 ~70 ~80 grass_block
fill ~65 ~60 ~80 ~66 ~65 ~80 stone
fill ~65 ~66 ~80 ~66 ~68 ~80 dirt
fill ~65 ~69 ~80 ~66 ~69 ~80 grass_block
fill ~67 ~60 ~80 ~74 ~66 ~80 stone
fill ~67 ~67 ~80 ~74 ~69 ~80 dirt
fill ~67 ~70 ~80 ~74 ~70 ~80 grass_block
fill ~75 ~60 ~80 ~77 ~65 ~80 stone
fill ~75 ~66 ~80 ~77 ~68 ~80 dirt
fill ~75 ~69 ~80 ~77 ~69 ~80 grass_block
fill ~78 ~60 ~80 ~79 ~64 ~80 stone
fill ~78 ~65 ~80 ~79 ~67 ~80 dirt
fill ~78 ~68 ~80 ~79 ~68 ~80 grass_block
fill ~64 ~60 ~81 ~72 ~66 ~81 stone
fill ~64 ~67 ~81 ~72 ~69 ~81 dirt
fill ~64 ~70 ~81 ~72 ~70 ~81 grass_block
fill ~73 ~60 ~81 ~76 ~65 ~81 stone
fill ~73 ~66 ~81 ~76 ~68 ~81 dirt
fill ~73 ~69 ~81 ~76 ~69 ~81 grass_block
fill ~77 ~60 ~81 ~79 ~64 ~81 stone
fill ~77 ~65 ~81 ~79 ~67 ~81 dirt
fill ~77 ~68 ~81 ~79 ~68 ~81 grass_block
fill ~64 ~60 ~82 ~66 ~67 ~82 stone
fill ~64 ~68 ~82 ~66 ~70 ~82 dirt
fill ~64 ~71 ~82 ~66 ~71 ~82 grass_block
fill ~67 ~60 ~82 ~71 ~66 ~82 stone
fill ~67 ~67 ~82 ~71 ~69 ~82 dirt
fill ~67 ~70 ~82 ~71 ~70 ~82 grass_block
fill ~72 ~60 ~82 ~75 ~65 ~82 stone
fill ~72 ~66 ~82 ~75 ~68 ~82 dirt
fill ~72 ~69 ~82 ~75 ~69 ~82 grass_block
fill ~76 ~60 ~82 ~78 ~64 ~82 stone
fill ~76 ~65 ~82 ~78 ~67 ~82 dirt
fill ~76 ~68 ~82 ~78 ~68 ~82 grass_block
fill ~79 ~60 ~82 ~79 ~63 ~82 stone
fill ~79 ~64 ~82 ~79 ~66 ~82 dirt
fill ~79 ~67 ~82 ~79 ~67 ~82 grass_block
fill ~64 ~60 ~83 ~66 ~67 ~83 stone
fill ~64 ~68 ~83 ~66 ~70 ~83 dirt
fill ~64 ~71 ~83 ~66 ~71 ~83 grass_block
fill ~67 ~60 ~83 ~71 ~66 ~83 stone
fill ~67 ~67 ~83 ~71 ~69 ~83 dirt
fill ~67 ~70 ~83 ~71 ~70 ~83 grass_block
fill ~72 ~60 ~83 ~73 ~65 ~83 stone
fill ~72 ~66 ~83 ~73 ~68 ~83 dirt
fill ~72 ~69 ~83 ~73 ~69 ~83 grass_block
fill ~74 ~60 ~83 ~79 ~64 ~83 stone
fill ~74 ~65 ~83 ~79 ~67 ~83 dirt
fill ~74 ~68 ~83 ~79 ~68 ~83 grass_block
fill ~64 ~60 ~84 ~67 ~67 ~84 stone
fill ~64 ~68 ~84 ~67 ~70 ~84 dirt
fill ~64 ~71 ~84 ~67 ~71 ~84 grass_block
fill ~68 ~60 ~84 ~69 ~66 ~84 stone
fill ~68 ~67 ~84 ~69 ~69 ~84 dirt
fill ~68 ~70 ~84 ~69 ~70 ~84 grass_block
fill ~70 ~60 ~84 ~72 ~65 ~84 stone
fill ~70 ~66 ~84 ~72 ~68 ~84 dirt
fill ~70 ~69 ~84 ~72 ~69 ~84 grass_block
fill ~73 ~60 ~84 ~79 ~64 ~84 stone
fill ~73 ~65 ~84 ~79 ~67 ~84 dirt
fill ~73 ~68 ~84 ~79 ~68 ~84 grass_block
fill ~64 ~60 ~85 ~64 ~68 ~85 stone
fill ~64 ~69 ~85 ~64 ~71 ~85 dirt
fill ~64 ~72 ~85 ~64 ~72 ~85 grass_block
fill ~65 ~60 ~85 ~66 ~67 ~85 stone
fill ~65 ~68 ~85 ~66 ~70 ~85 dirt
fill ~65 ~71 ~85 ~66 ~71 ~85 grass_block
fill ~67 ~60 ~85 ~68 ~66 ~85 stone
fill ~67 ~67 ~85 ~68 ~69 ~85 dirt
fill ~67 ~70 ~85 ~68 ~70 ~85 grass_block
fill ~69 ~60 ~85 ~71 ~65 ~85 stone
fill ~69 ~66 ~85 ~71 ~68 ~85 dirt
fill ~69 ~69 ~85 ~71 ~69 ~85 grass_block
fill ~72 ~60 ~85 ~79 ~64 ~85 stone
fill ~72 ~65 ~85 ~79 ~67 ~85 dirt
fill ~72 ~68 ~85 ~79 ~68 ~85 grass_block
fill ~64 ~60 ~86 ~65 ~68 ~86 stone
fill ~64 ~69 ~86 ~65 ~71 ~86 dirt
fill ~64 ~72 ~86 ~65 ~72 ~86 grass_block
fill ~66 ~60 ~86 ~67 ~67 ~86 stone
fill ~66 ~68 ~86 ~67 ~70 ~86 dirt
fill ~66 ~71 ~86 ~67 ~71 ~86 grass_block
fill ~68 ~60 ~86 ~69 ~66 ~86 stone
fill ~68 ~67 ~86 ~69 ~69 ~86 dirt
fill ~68 ~70 ~86 ~69 ~70 ~86 grass_block
fill ~70 ~60 ~86 ~75 ~65 ~86 stone
fill ~70 ~66 ~86 ~75 ~68 ~86 dirt
fill ~70 ~69 ~86 ~75 ~69 ~86 grass_block
fill ~76 ~60 ~86 ~79 ~64 ~86 stone
fill ~76 ~65 ~86 ~79 ~67 ~86 dirt
fill ~76 ~68 ~86 ~79 ~68 ~86 grass_block
fill ~64 ~60 ~87 ~65 ~68 ~87 stone
fill ~64 ~69 ~87 ~65 ~71 ~87 dirt
fill ~64 ~72 ~87 ~65 ~72 ~87 grass_block
fill ~66 ~60 ~87 ~68 ~67 ~87 stone
fill ~66 ~68 ~87 ~68 ~70 ~87 dirt
fill ~66 ~71 ~87 ~68 ~71 ~87 grass_block
fill ~69 ~60 ~87 ~70 ~66 ~87 stone
fill ~69 ~67 ~87 ~70 ~69 ~87 dirt
fill ~69 ~70 ~87 ~70 ~70 ~87 grass_block
fill ~71 ~60 ~87 ~77 ~65 ~87 stone
fill ~71 ~66 ~87 ~77 ~68 ~87 dirt
fill ~71 ~69 ~87 ~77 ~69 ~87 grass_block
fill ~78 ~60 ~87 ~79 ~64 ~87 stone
fill ~78 ~65 ~87 ~79 ~67 ~87 dirt
fill ~78 ~68 ~87 ~79 ~68 ~87 grass_block
fill ~64 ~60 ~88 ~67 ~68 ~88 stone
fill ~64 ~69 ~88 ~67 ~71 ~88 dirt
fill ~64 ~72 ~88 ~67 ~72 ~88 grass_block
fill ~68 ~60 ~88 ~68 ~67 ~88 stone
fill ~68 ~68 ~88 ~68 ~70 ~88 dirt
fill ~68 ~71 ~88 ~68 ~71 ~88 grass_block
fill ~69 ~60 ~88 ~70 ~66 ~88 stone
fill ~69 ~67 ~88 ~70 ~69 ~88 dirt
fill ~69 ~70 ~88 ~70 ~70 ~88 grass_block
fill ~71 ~60 ~88 ~71 ~65 ~88 stone
fill ~71 ~66 ~88 ~71 ~68 ~88 dirt
fill ~71 ~69 ~88 ~71 ~69 ~88 grass_block
fill ~72 ~60 ~88 ~75 ~66 ~88 stone
fill ~72 ~67 ~88 ~75 ~69 ~88 dirt
fill ~72 ~70 ~88 ~75 ~70 ~88 grass_block
fill ~76 ~60 ~88 ~79 ~65 ~88 stone
fill ~76 ~66 ~88 ~79 ~68 ~88 dirt
fill ~76 ~69 ~88 ~79 ~69 ~88 grass_block
fill ~64 ~60 ~89 ~68 ~68 ~89 stone
fill ~64 ~69 ~89 ~68 ~71 ~89 dirt
fill ~64 ~72 ~89 ~68 ~72 ~89 grass_block
fill ~69 ~60 ~89 ~70 ~67 ~89 stone
fill ~69 ~68 ~89 ~70 ~70 ~89 dirt
fill ~69 ~71 ~89 ~70 ~71 ~89 grass_block
fill ~71 ~60 ~89 ~72 ~66 ~89 stone
fill ~71 ~67 ~89 ~72 ~69 ~89 dirt
fill ~71 ~70 ~89 ~72 ~70 ~89 grass_block
fill ~73 ~60 ~89 ~75 ~67 ~89 stone
fill ~73 ~68 ~89 ~75 ~70 ~89 dirt
fill ~73 ~71 ~89 ~75 ~71 ~89 grass_block
fill ~76 ~60 ~89 ~77 ~66 ~89 stone
fill ~76 ~67 ~89 ~77 ~69 ~89 dirt
fill ~76 ~70 ~89 ~77 ~70 ~89 grass_block
fill ~78 ~60 ~89 ~79 ~65 ~89 stone
fill ~78 ~66 ~89 ~79 ~68 ~89 dirt
fill ~78 ~69 ~89 ~79 ~69 ~89 grass_block
fill ~64 ~60 ~90 ~68 ~68 ~90 stone
fill ~64 ~69 ~90 ~68 ~71 ~90 dirt
fill ~64 ~72 ~90 ~68 ~72 ~90 grass_block
fill ~69 ~60 ~90 ~70 ~67 ~90 stone
fill ~69 ~68 ~90 ~70 ~70 ~90 dirt
fill ~69 ~71 ~90 ~70 ~71 ~90 grass_block
fill ~71 ~60 ~90 ~71 ~66 ~90 stone
fill ~71 ~67 ~90 ~71 ~69 ~90 dirt
fill ~71 ~70 ~90 ~71 ~70 ~90 grass_block
fill ~72 ~60 ~90 ~76 ~67 ~90 stone
fill ~72 ~68 ~90 ~76 ~70 ~90 dirt
fill ~72 ~71 ~90 ~76 ~71 ~90 grass_block
fill ~77 ~60 ~90 ~78 ~66 ~90 stone
fill ~77 ~67 ~90 ~78 ~69 ~90 dirt
fill ~77 ~70 ~90 ~78 ~70 ~90 grass_block
fill ~79 ~60 ~90 ~79 ~65 ~90 stone
fill ~79 ~66 ~90 ~79 ~68 ~90 dirt
fill ~79 ~69 ~90 ~79 ~69 ~90 grass_block
fill ~64 ~60 ~91 ~69 ~68 ~91 stone
fill ~64 ~69 ~91 ~69 ~71 ~91 dirt
fill ~64 ~72 ~91 ~69 ~72 ~91 grass_block
fill ~70 ~60 ~91 ~72 ~67 ~91 stone
fill ~70 ~68 ~91 ~72 ~70 ~91 dirt
fill ~70 ~71 ~91 ~72 ~71 ~91 grass_block
fill ~73 ~60 ~91 ~75 ~68 ~91 stone
fill ~73 ~69 ~91 ~75 ~71 ~91 dirt
fill ~73 ~72 ~91 ~75 ~72 ~91 grass_block
fill ~76 ~60 ~91 ~77 ~67 ~91 stone
fill ~76 ~68 ~91 ~77 ~70 ~91 dirt
fill ~76 ~71 ~91 ~77 ~71 ~91 grass_block
fill ~78 ~60 ~91 ~79 ~66 ~91 stone
fill ~78 ~67 ~91 ~79 ~69 ~91 dirt
fill ~78 ~70 ~91 ~79 ~70 ~91 grass_block
fill ~64 ~60 ~92 ~75 ~68 ~92 stone
fill ~64 ~69 ~92 ~75 ~71 ~92 dirt
fill ~64 ~72 ~92 ~75 ~72 ~92 grass_block
fill ~76 ~60 ~92 ~79 ~67 ~92 stone
fill ~76 ~68 ~92 ~79 ~70 ~92 dirt
fill ~76 ~71 ~92 ~79 ~71 ~92 grass_block
fill ~64 ~60 ~93 ~65 ~67 ~93 stone
fill ~64 ~68 ~93 ~65 ~70 ~93 dirt
fill ~64 ~71 ~93 ~65 ~71 ~93 grass_block
fill ~66 ~60 ~93 ~68 ~68 ~93 stone
fill ~66 ~69 ~93 ~68 ~71 ~93 dirt
fill ~66 ~72 ~93 ~68 ~72 ~93 grass_block
fill ~69 ~60 ~93 ~73 ~69 ~93 stone
fill ~69 ~70 ~93 ~73 ~72 ~93 dirt
fill ~69 ~73 ~93 ~73 ~73 ~93 grass_block
fill ~74 ~60 ~93 ~76 ~68 ~93 stone
fill ~74 ~69 ~93 ~76 ~71 ~93 dirt
fill ~74 ~72 ~93 ~76 ~72 ~93 grass_block
fill ~77 ~60 ~93 ~79 ~67 ~93 stone
fill ~77 ~68 ~93 ~79 ~70 ~93 dirt
fill ~77 ~71 ~93 ~79 ~71 ~93 grass_block
fill ~64 ~60 ~94 ~65 ~67 ~94 stone
fill ~64 ~68 ~94 ~65 ~70 ~94 dirt
fill ~64 ~71 ~94 ~65 ~71 ~94 grass_block
fill ~66 ~60 ~94 ~68 ~68 ~94 stone
fill ~66 ~69 ~94 ~68 ~71 ~94 dirt
fill ~66 ~72 ~94 ~68 ~72 ~94 grass_block
fill ~69 ~60 ~94 ~75 ~69 ~94 stone
fill ~69 ~70 ~94 ~75 ~72 ~94 dirt
fill ~69 ~73 ~94 ~75 ~73 ~94 grass_block
fill ~76 ~60 ~94 ~78 ~68 ~94 stone
fill ~76 ~69 ~94 ~78 ~71 ~94 dirt
fill ~76 ~72 ~94 ~78 ~72 ~94 grass_block
fill ~79 ~60 ~94 ~79 ~67 ~94 stone
fill ~79 ~68 ~94 ~79 ~70 ~94 dirt
fill ~79 ~71 ~94 ~79 ~71 ~94 grass_block
fill ~64 ~60 ~95 ~65 ~67 ~95 stone
fill ~64 ~68 ~95 ~65 ~70 ~95 dirt
fill ~64 ~71 ~95 ~65 ~71 ~95 grass_block
fill ~66 ~60 ~95 ~68 ~68 ~95 stone
fill ~66 ~69 ~95 ~68 ~71 ~95 dirt
fill ~66 ~72 ~95 ~68 ~72 ~95 grass_block
fill ~69 ~60 ~95 ~71 ~69 ~95 stone
fill ~69 ~70 ~95 ~71 ~72 ~95 dirt
fill ~69 ~73 ~95 ~71 ~73 ~95 grass_block
fill ~72 ~60 ~95 ~72 ~70 ~95 stone
fill ~72 ~71 ~95 ~72 ~73 ~95 dirt
fill ~72 ~74 ~95 ~72 ~74 ~95 grass_block
fill ~73 ~60 ~95 ~75 ~69 ~95 stone
fill ~73 ~70 ~95 ~75 ~72 ~95 dirt
fill ~73 ~73 ~95 ~75 ~73 ~95 grass_block
fill ~76 ~60 ~95 ~79 ~68 ~95 stone
fill ~76 ~69 ~95 ~79 ~71 ~95 dirt
fill ~76 ~72 ~95 ~79 ~72 ~95 grass_block