fill ~96 ~60 ~112 ~98 ~68 ~112 stone
fill ~96 ~69 ~112 ~98 ~71 ~112 dirt
fill ~96 ~72 ~112 ~98 ~72 ~112 grass_block
fill ~99 ~60 ~112 ~102 ~69 ~112 stone
fill ~99 ~70 ~112 ~102 ~72 ~112 dirt
fill ~99 ~73 ~112 ~102 ~73 ~112 grass_block
fill ~103 ~60 ~112 ~106 ~68 ~112 stone
fill ~103 ~69 ~112 ~106 ~71 ~112 dirt
fill ~103 ~72 ~112 ~106 ~72 ~112 grass_block
fill ~107 ~60 ~112 ~111 ~67 ~112 stone
fill ~107 ~68 ~112 ~111 ~70 ~112 dirt
fill ~107 ~71 ~112 ~111 ~71 ~112 grass_block
fill ~96 ~60 ~113 ~99 ~68 ~113 stone
fill ~96 ~69 ~113 ~99 ~71 ~113 dirt
fill ~96 ~72 ~113 ~99 ~72 ~113 grass_block
fill ~100 ~60 ~113 ~101 ~69 ~113 stone
fill ~100 ~70 ~113 ~101 ~72 ~113 dirt
fill ~100 ~73 ~113 ~101 ~73 ~113 grass_block
fill ~102 ~60 ~113 ~106 ~68 ~113 stone
fill ~102 ~69 ~113 ~106 ~71 ~113 dirt
fill ~102 ~72 ~113 ~106 ~72 ~113 grass_block
fill ~107 ~60 ~113 ~111 ~67 ~113 stone
fill ~107 ~68 ~113 ~111 ~70 ~113 dirt
fill ~107 ~71 ~113 ~111 ~71 ~113 grass_block
fill ~96 ~60 ~114 ~96 ~67 ~114 stone
fill ~96 ~68 ~114 ~96 ~70 ~114 dirt
fill ~96 ~71 ~114 ~96 ~71 ~114 grass_block
fill ~97 ~60 ~114 ~105 ~68 ~114 stone
fill ~97 ~69 ~114 ~105 ~71 ~114 dirt
fill ~97 ~72 ~114 ~105 ~72 ~114 grass_block
fill ~106 ~60 ~114 ~111 ~67 ~114 stone
fill ~106 ~68 ~114 ~111 ~70 ~114 dirt
fill ~106 ~71 ~114 ~111 ~71 ~114 grass_block
fill ~96 ~60 ~115 ~97 ~67 ~115 stone
fill ~96 ~68 ~115 ~97 ~70 ~115 dirt
fill ~96 ~71 ~115 ~97 ~71 ~115 grass_block
fill ~98 ~60 ~115 ~105 ~68 ~115 stone
fill ~98 ~69 ~115 ~105 ~71 ~115 dirt
fill ~98 ~72 ~115 ~105 ~72 ~115 grass_block
fill ~106 ~60 ~115 ~109 ~67 ~115 stone
fill ~106 ~68 ~115 ~109 ~70 ~115 dirt
fill ~106 ~71 ~115 ~109 ~71 ~115 grass_block
fill ~110 ~60 ~115 ~111 ~66 ~115 stone
fill ~110 ~67 ~115 ~111 ~69 ~115 dirt
fill ~110 ~70 ~115 ~111 ~70 ~115 grass_block
fill ~96 ~60 ~116 ~97 ~67 ~116 stone
fill ~96 ~68 ~116 ~97 ~70 ~116 dirt
fill ~96 ~71 ~116 ~97 ~71 ~116 grass_block
fill ~98 ~60 ~116 ~105 ~68 ~116 stone
fill ~98 ~69 ~116 ~105 ~71 ~116 dirt
fill ~98 ~72 ~116 ~105 ~72 ~116 grass_block
fill ~106 ~60 ~116 ~109 ~67 ~116 stone
fill ~106 ~68 ~116 ~109 ~70 ~116 dirt
fill ~106 ~71 ~116 ~109 ~71 ~116 grass_block
fill ~110 ~60 ~116 ~111 ~66 ~116 stone
fill ~110 ~67 ~116 ~111 ~69 ~116 dirt
fill ~110 ~70 ~116 ~111 ~70 ~116 grass_block
fill ~96 ~60 ~117 ~98 ~67 ~117 stone
fill ~96 ~68 ~117 ~98 ~70 ~117 dirt
fill ~96 ~71 ~117 ~98 ~71 ~117 grass_block
fill ~99 ~60 ~117 ~105 ~68 ~117 stone
fill ~99 ~69 ~117 ~105 ~71 ~117 dirt
fill ~99 ~72 ~117 ~105 ~72 ~117 grass_block
fill ~106 ~60 ~117 ~109 ~67 ~117 stone
fill ~106 ~68 ~117 ~109 ~70 ~117 dirt
fill ~106 ~71 ~117 ~109 ~71 ~117 grass_block
fill ~110 ~60 ~117 ~111 ~66 ~117 stone
fill ~110 ~67 ~117 ~111 ~69 ~117 dirt
fill ~110 ~70 ~117 ~111 ~70 ~117 grass_block
fill ~96 ~60 ~118 ~96 ~66 ~118 stone
fill ~96 ~67 ~118 ~96 ~69 ~118 dirt
fill ~96 ~70 ~118 ~96 ~70 ~118 grass_block
fill ~97 ~60 ~118 ~99 ~67 ~118 stone
fill ~97 ~68 ~118 ~99 ~70 ~118 dirt
fill ~97 ~71 ~118 ~99 ~71 ~118 grass_block
fill ~100 ~60 ~118 ~105 ~68 ~118 stone
fill ~100 ~69 ~118 ~105 ~71 ~118 dirt
fill ~100 ~72 ~118 ~105 ~72 ~118 grass_block
fill ~106 ~60 ~118 ~110 ~67 ~118 stone
fill ~106 ~68 ~118 ~110 ~70 ~118 dirt
fill ~106 ~71 ~118 ~110 ~71 ~118 grass_block
fill ~111 ~60 ~118 ~111 ~66 ~118 stone
fill ~111 ~67 ~118 ~111 ~69 ~118 dirt
fill ~111 ~70 ~118 ~111 ~70 ~118 grass_block
fill ~96 ~60 ~119 ~97 ~66 ~119 stone
fill ~96 ~67 ~119 ~97 ~69 ~119 dirt
fill ~96 ~70 ~119 ~97 ~70 ~119 grass_block
fill ~98 ~60 ~119 ~100 ~67 ~119 stone
fill ~98 ~68 ~119 ~100 ~70 ~119 dirt
fill ~98 ~71 ~119 ~100 ~71 ~119 grass_block
fill ~101 ~60 ~119 ~102 ~68 ~119 stone
fill ~101 ~69 ~119 ~102 ~71 ~119 dirt
fill ~101 ~72 ~119 ~102 ~72 ~119 grass_block
fill ~103 ~60 ~119 ~110 ~67 ~119 stone
fill ~103 ~68 ~119 ~110 ~70 ~119 dirt
fill ~103 ~71 ~119 ~110 ~71 ~119 grass_block
fill ~111 ~60 ~119 ~111 ~66 ~119 stone
fill ~111 ~67 ~119 ~111 ~69 ~119 dirt
fill ~111 ~70 ~119 ~111 ~70 ~119 grass_block
fill ~96 ~60 ~120 ~97 ~66 ~120 stone
fill ~96 ~67 ~120 ~97 ~69 ~120 dirt
fill ~96 ~70 ~120 ~97 ~70 ~120 grass_block
fill ~98 ~60 ~120 ~110 ~67 ~120 stone
fill ~98 ~68 ~120 ~110 ~70 ~120 dirt
fill ~98 ~71 ~120 ~110 ~71 ~120 grass_block
fill ~111 ~60 ~120 ~111 ~66 ~120 stone
fill ~111 ~67 ~120 ~111 ~69 ~120 dirt
fill ~111 ~70 ~120 ~111 ~70 ~120 grass_block
fill ~96 ~60 ~121 ~96 ~65 ~121 stone
fill ~96 ~66 ~121 ~96 ~68 ~121 dirt
fill ~96 ~69 ~121 ~96 ~69 ~121 grass_block
fill ~97 ~60 ~121 ~98 ~66 ~121 stone
fill ~97 ~67 ~121 ~98 ~69 ~121 dirt
fill ~97 ~70 ~121 ~98 ~70 ~121 grass_block
fill ~99 ~60 ~121 ~103 ~67 ~121 stone
fill ~99 ~68 ~121 ~103 ~70 ~121 dirt
fill ~99 ~71 ~121 ~103 ~71 ~121 grass_block
fill ~104 ~60 ~121 ~105 ~66 ~121 stone
fill ~104 ~67 ~121 ~105 ~69 ~121 dirt
fill ~104 ~70 ~121 ~105 ~70 ~121 grass_block
fill ~106 ~60 ~121 ~110 ~67 ~121 stone
fill ~106 ~68 ~121 ~110 ~70 ~121 dirt
fill ~106 ~71 ~121 ~110 ~71 ~121 grass_block
fill ~111 ~60 ~121 ~111 ~66 ~121 stone
fill ~111 ~67 ~121 ~111 ~69 ~121 dirt
fill ~111 ~70 ~121 ~111 ~70 ~121 grass_block
fill ~96 ~60 ~122 ~98 ~65 ~122 stone
fill ~96 ~66 ~122 ~98 ~68 ~122 dirt
fill ~96 ~69 ~122 ~98 ~69 ~122 grass_block
fill ~99 ~60 ~122 ~100 ~66 ~122 stone
fill ~99 ~67 ~122 ~100 ~69 ~122 dirt
fill ~99 ~70 ~122 ~100 ~70 ~122 grass_block
fill ~101 ~60 ~122 ~103 ~67 ~122 stone
fill ~101 ~68 ~122 ~103 ~70 ~122 dirt
fill ~101 ~71 ~122 ~103 ~71 ~122 grass_block
fill ~104 ~60 ~122 ~106 ~66 ~122 stone
fill ~104 ~67 ~122 ~106 ~69 ~122 dirt
fill ~104 ~70 ~122 ~106 ~70 ~122 grass_block
fill ~107 ~60 ~122 ~111 ~67 ~122 stone
fill ~107 ~68 ~122 ~111 ~70 ~122 dirt
fill ~107 ~71 ~122 ~111 ~71 ~122 grass_block
fill ~96 ~60 ~123 ~97 ~64 ~123 stone
fill ~96 ~65 ~123 ~97 ~67 ~123 dirt
fill ~96 ~68 ~123 ~97 ~68 ~123 grass_block
fill ~98 ~60 ~123 ~99 ~65 ~123 stone
fill ~98 ~66 ~123 ~99 ~68 ~123 dirt
fill ~98 ~69 ~123 ~99 ~69 ~123 grass_block
fill ~100 ~60 ~123 ~101 ~66 ~123 stone
fill ~100 ~67 ~123 ~101 ~69 ~123 dirt
fill ~100 ~70 ~123 ~101 ~70 ~123 grass_block
fill ~102 ~60 ~123 ~103 ~67 ~123 stone
fill ~102 ~68 ~123 ~103 ~70 ~123 dirt
fill ~102 ~71 ~123 ~103 ~71 ~123 grass_block
fill ~104 ~60 ~123 ~108 ~66 ~123 stone
fill ~104 ~67 ~123 ~108 ~69 ~123 dirt
fill ~104 ~70 ~123 ~108 ~70 ~123 grass_block
fill ~109 ~60 ~123 ~111 ~67 ~123 stone
fill ~109 ~68 ~123 ~111 ~70 ~123 dirt
fill ~109 ~71 ~123 ~111 ~71 ~123 grass_block
fill ~96 ~60 ~124 ~98 ~64 ~124 stone
fill ~96 ~65 ~124 ~98 ~67 ~124 dirt
fill ~96 ~68 ~124 ~98 ~68 ~124 grass_block
fill ~99 ~60 ~124 ~100 ~65 ~124 stone
fill ~99 ~66 ~124 ~100 ~68 ~124 dirt
fill ~99 ~69 ~124 ~100 ~69 ~124 grass_block
fill ~101 ~60 ~124 ~105 ~66 ~124 stone
fill ~101 ~67 ~124 ~105 ~69 ~124 dirt
fill ~101 ~70 ~124 ~105 ~70 ~124 grass_block
fill ~106 ~60 ~124 ~107 ~65 ~124 stone
fill ~106 ~66 ~124 ~107 ~68 ~124 dirt
fill ~106 ~69 ~124 ~107 ~69 ~124 grass_block
fill ~108 ~60 ~124 ~109 ~66 ~124 stone
fill ~108 ~67 ~124 ~109 ~69 ~124 dirt
fill ~108 ~70 ~124 ~109 ~70 ~124 grass_block
fill ~110 ~60 ~124 ~110 ~67 ~124 stone
fill ~110 ~68 ~124 ~110 ~70 ~124 dirt
fill ~110 ~71 ~124 ~110 ~71 ~124 grass_block
fill ~111 ~60 ~124 ~111 ~66 ~124 stone
fill ~111 ~67 ~124 ~111 ~69 ~124 dirt
fill ~111 ~70 ~124 ~111 ~70 ~124 grass_block
fill ~96 ~60 ~125 ~98 ~64 ~125 stone
fill ~96 ~65 ~125 ~98 ~67 ~125 dirt
fill ~96 ~68 ~125 ~98 ~68 ~125 grass_block
fill ~99 ~60 ~125 ~100 ~65 ~125 stone
fill ~99 ~66 ~125 ~100 ~68 ~125 dirt
fill ~99 ~69 ~125 ~100 ~69 ~125 grass_block
fill ~101 ~60 ~125 ~105 ~66 ~125 stone
fill ~101 ~67 ~125 ~105 ~69 ~125 dirt
fill ~101 ~70 ~125 ~105 ~70 ~125 grass_block
fill ~106 ~60 ~125 ~108 ~65 ~125 stone
fill ~106 ~66 ~125 ~108 ~68 ~125 dirt
fill ~106 ~69 ~125 ~108 ~69 ~125 grass_block
fill ~109 ~60 ~125 ~111 ~66 ~125 stone
fill ~109 ~67 ~125 ~111 ~69 ~125 dirt
fill ~109 ~70 ~125 ~111 ~70 ~125 grass_block
fill ~96 ~60 ~126 ~99 ~64 ~126 stone
fill ~96 ~65 ~126 ~99 ~67 ~126 dirt
fill ~96 ~68 ~126 ~99 ~68 ~126 grass_block
fill ~100 ~60 ~126 ~101 ~65 ~126 stone
fill ~100 ~66 ~126 ~101 ~68 ~126 dirt
fill ~100 ~69 ~126 ~101 ~69 ~126 grass_block
fill ~102 ~60 ~126 ~105 ~66 ~126 stone
fill ~102 ~67 ~126 ~105 ~69 ~126 dirt
fill ~102 ~70 ~126 ~105 ~70 ~126 grass_block
fill ~106 ~60 ~126 ~109 ~65 ~126 stone
fill ~106 ~66 ~126 ~109 ~68 ~126 dirt
fill ~106 ~69 ~126 ~109 ~69 ~126 grass_block
fill ~110 ~60 ~126 ~111 ~66 ~126 stone
fill ~110 ~67 ~126 ~111 ~69 ~126 dirt
fill ~110 ~70 ~126 ~111 ~70 ~126 grass_block
fill ~96 ~60 ~127 ~99 ~64 ~127 stone
fill ~96 ~65 ~127 ~99 ~67 ~127 dirt
fill ~96 ~68 ~127 ~99 ~68 ~127 grass_block
fill ~100 ~60 ~127 ~102 ~65 ~127 stone
fill ~100 ~66 ~127 ~102 ~68 ~127 dirt
fill ~100 ~69 ~127 ~102 ~69 ~127 grass_block
fill ~103 ~60 ~127 ~104 ~66 ~127 stone
fill ~103 ~67 ~127 ~104 ~69 ~127 dirt
fill ~103 ~70 ~127 ~104 ~70 ~127 grass_block
fill ~105 ~60 ~127 ~107 ~65 ~127 stone
fill ~105 ~66 ~127 ~107 ~68 ~127 dirt
fill ~105 ~69 ~127 ~107 ~69 ~127 grass_block
fill ~108 ~60 ~127 ~108 ~64 ~127 stone
fill ~108 ~65 ~127 ~108 ~67 ~127 dirt
fill ~108 ~68 ~127 ~108 ~68 ~127 grass_block
fill ~109 ~60 ~127 ~111 ~65 ~127 stone
fill ~109 ~66 ~127 ~111 ~68 ~127 dirt
fill ~109 ~69 ~127 ~111 ~69 ~127 grass_block