fill ~80 ~60 ~48 ~80 ~65 ~48 stone
fill ~80 ~66 ~48 ~80 ~68 ~48 dirt
fill ~80 ~69 ~48 ~80 ~69 ~48 grass_block
fill ~81 ~60 ~48 ~82 ~64 ~48 stone
fill ~81 ~65 ~48 ~82 ~67 ~48 dirt
fill ~81 ~68 ~48 ~82 ~68 ~48 grass_block
fill ~83 ~60 ~48 ~93 ~63 ~48 stone
fill ~83 ~64 ~48 ~93 ~66 ~48 dirt
fill ~83 ~67 ~48 ~93 ~67 ~48 grass_block
fill ~94 ~60 ~48 ~95 ~64 ~48 stone
fill ~94 ~65 ~48 ~95 ~67 ~48 dirt
fill ~94 ~68 ~48 ~95 ~68 ~48 grass_block
fill ~80 ~60 ~49 ~81 ~65 ~49 stone
fill ~80 ~66 ~49 ~81 ~68 ~49 dirt
fill ~80 ~69 ~49 ~81 ~69 ~49 grass_block
fill ~82 ~60 ~49 ~83 ~64 ~49 stone
fill ~82 ~65 ~49 ~83 ~67 ~49 dirt
fill ~82 ~68 ~49 ~83 ~68 ~49 grass_block
fill ~84 ~60 ~49 ~95 ~63 ~49 stone
fill ~84 ~64 ~49 ~95 ~66 ~49 dirt
fill ~84 ~67 ~49 ~95 ~67 ~49 grass_block
fill ~80 ~60 ~50 ~82 ~65 ~50 stone
fill ~80 ~66 ~50 ~82 ~68 ~50 dirt
fill ~80 ~69 ~50 ~82 ~69 ~50 grass_block
fill ~83 ~60 ~50 ~84 ~64 ~50 stone
fill ~83 ~65 ~50 ~84 ~67 ~50 dirt
fill ~83 ~68 ~50 ~84 ~68 ~50 grass_block
fill ~85 ~60 ~50 ~95 ~63 ~50 stone
fill ~85 ~64 ~50 ~95 ~66 ~50 dirt
fill ~85 ~67 ~50 ~95 ~67 ~50 grass_block
fill ~80 ~60 ~51 ~83 ~65 ~51 stone
fill ~80 ~66 ~51 ~83 ~68 ~51 dirt
fill ~80 ~69 ~51 ~83 ~69 ~51 grass_block
fill ~84 ~60 ~51 ~86 ~64 ~51 stone
fill ~84 ~65 ~51 ~86 ~67 ~51 dirt
fill ~84 ~68 ~51 ~86 ~68 ~51 grass_block
fill ~87 ~60 ~51 ~95 ~63 ~51 stone
fill ~87 ~64 ~51 ~95 ~66 ~51 dirt
fill ~87 ~67 ~51 ~95 ~67 ~51 grass_block
fill ~80 ~60 ~52 ~81 ~64 ~52 stone
fill ~80 ~65 ~52 ~81 ~67 ~52 dirt
fill ~80 ~68 ~52 ~81 ~68 ~52 grass_block
fill ~82 ~60 ~52 ~83 ~65 ~52 stone
fill ~82 ~66 ~52 ~83 ~68 ~52 dirt
fill ~82 ~69 ~52 ~83 ~69 ~52 grass_block
fill ~84 ~60 ~52 ~87 ~64 ~52 stone
fill ~84 ~65 ~52 ~87 ~67 ~52 dirt
fill ~84 ~68 ~52 ~87 ~68 ~52 grass_block
fill ~88 ~60 ~52 ~95 ~63 ~52 stone
fill ~88 ~64 ~52 ~95 ~66 ~52 dirt
fill ~88 ~67 ~52 ~95 ~67 ~52 grass_block
fill ~80 ~60 ~53 ~83 ~64 ~53 stone
fill ~80 ~65 ~53 ~83 ~67 ~53 dirt
fill ~80 ~68 ~53 ~83 ~68 ~53 grass_block
fill ~84 ~60 ~53 ~84 ~65 ~53 stone
fill ~84 ~66 ~53 ~84 ~68 ~53 dirt
fill ~84 ~69 ~53 ~84 ~69 ~53 grass_block
fill ~85 ~60 ~53 ~87 ~64 ~53 stone
fill ~85 ~65 ~53 ~87 ~67 ~53 dirt
fill ~85 ~68 ~53 ~87 ~68 ~53 grass_block
fill ~88 ~60 ~53 ~95 ~63 ~53 stone
fill ~88 ~64 ~53 ~95 ~66 ~53 dirt
fill ~88 ~67 ~53 ~95 ~67 ~53 grass_block
fill ~80 ~60 ~54 ~88 ~64 ~54 stone
fill ~80 ~65 ~54 ~88 ~67 ~54 dirt
fill ~80 ~68 ~54 ~88 ~68 ~54 grass_block
fill ~89 ~60 ~54 ~95 ~63 ~54 stone
fill ~89 ~64 ~54 ~95 ~66 ~54 dirt
fill ~89 ~67 ~54 ~95 ~67 ~54 grass_block
fill ~80 ~60 ~55 ~82 ~63 ~55 stone
fill ~80 ~64 ~55 ~82 ~66 ~55 dirt
fill ~80 ~67 ~55 ~82 ~67 ~55 grass_block
fill ~83 ~60 ~55 ~89 ~64 ~55 stone
fill ~83 ~65 ~55 ~89 ~67 ~55 dirt
fill ~83 ~68 ~55 ~89 ~68 ~55 grass_block
fill ~90 ~60 ~55 ~95 ~63 ~55 stone
fill ~90 ~64 ~55 ~95 ~66 ~55 dirt
fill ~90 ~67 ~55 ~95 ~67 ~55 grass_block
fill ~80 ~60 ~56 ~83 ~63 ~56 stone
fill ~80 ~64 ~56 ~83 ~66 ~56 dirt
fill ~80 ~67 ~56 ~83 ~67 ~56 grass_block
fill ~84 ~60 ~56 ~90 ~64 ~56 stone
fill ~84 ~65 ~56 ~90 ~67 ~56 dirt
fill ~84 ~68 ~56 ~90 ~68 ~56 grass_block
fill ~91 ~60 ~56 ~95 ~63 ~56 stone
fill ~91 ~64 ~56 ~95 ~66 ~56 dirt
fill ~91 ~67 ~56 ~95 ~67 ~56 grass_block
fill ~80 ~60 ~57 ~85 ~63 ~57 stone
fill ~80 ~64 ~57 ~85 ~66 ~57 dirt
fill ~80 ~67 ~57 ~85 ~67 ~57 grass_block
fill ~86 ~60 ~57 ~91 ~64 ~57 stone
fill ~86 ~65 ~57 ~91 ~67 ~57 dirt
fill ~86 ~68 ~57 ~91 ~68 ~57 grass_block
fill ~92 ~60 ~57 ~95 ~63 ~57 stone
fill ~92 ~64 ~57 ~95 ~66 ~57 dirt
fill ~92 ~67 ~57 ~95 ~67 ~57 grass_block
fill ~80 ~60 ~58 ~80 ~64 ~58 stone
fill ~80 ~65 ~58 ~80 ~67 ~58 dirt
fill ~80 ~68 ~58 ~80 ~68 ~58 grass_block
fill ~81 ~60 ~58 ~87 ~63 ~58 stone
fill ~81 ~64 ~58 ~87 ~66 ~58 dirt
fill ~81 ~67 ~58 ~87 ~67 ~58 grass_block
fill ~88 ~60 ~58 ~91 ~64 ~58 stone
fill ~88 ~65 ~58 ~91 ~67 ~58 dirt
fill ~88 ~68 ~58 ~91 ~68 ~58 grass_block
fill ~92 ~60 ~58 ~95 ~63 ~58 stone
fill ~92 ~64 ~58 ~95 ~66 ~58 dirt
fill ~92 ~67 ~58 ~95 ~67 ~58 grass_block
fill ~80 ~60 ~59 ~82 ~64 ~59 stone
fill ~80 ~65 ~59 ~82 ~67 ~59 dirt
fill ~80 ~68 ~59 ~82 ~68 ~59 grass_block
fill ~83 ~60 ~59 ~89 ~63 ~59 stone
fill ~83 ~64 ~59 ~89 ~66 ~59 dirt
fill ~83 ~67 ~59 ~89 ~67 ~59 grass_block
fill ~90 ~60 ~59 ~93 ~64 ~59 stone
fill ~90 ~65 ~59 ~93 ~67 ~59 dirt
fill ~90 ~68 ~59 ~93 ~68 ~59 grass_block
fill ~94 ~60 ~59 ~95 ~63 ~59 stone
fill ~94 ~64 ~59 ~95 ~66 ~59 dirt
fill ~94 ~67 ~59 ~95 ~67 ~59 grass_block
fill ~80 ~60 ~60 ~82 ~64 ~60 stone
fill ~80 ~65 ~60 ~82 ~67 ~60 dirt
fill ~80 ~68 ~60 ~82 ~68 ~60 grass_block
fill ~83 ~60 ~60 ~91 ~63 ~60 stone
fill ~83 ~64 ~60 ~91 ~66 ~60 dirt
fill ~83 ~67 ~60 ~91 ~67 ~60 grass_block
fill ~92 ~60 ~60 ~93 ~64 ~60 stone
fill ~92 ~65 ~60 ~93 ~67 ~60 dirt
fill ~92 ~68 ~60 ~93 ~68 ~60 grass_block
fill ~94 ~60 ~60 ~95 ~63 ~60 stone
fill ~94 ~64 ~60 ~95 ~66 ~60 dirt
fill ~94 ~67 ~60 ~95 ~67 ~60 grass_block
fill ~80 ~60 ~61 ~80 ~65 ~61 stone
fill ~80 ~66 ~61 ~80 ~68 ~61 dirt
fill ~80 ~69 ~61 ~80 ~69 ~61 grass_block
fill ~81 ~60 ~61 ~84 ~64 ~61 stone
fill ~81 ~65 ~61 ~84 ~67 ~61 dirt
fill ~81 ~68 ~61 ~84 ~68 ~61 grass_block
fill ~85 ~60 ~61 ~95 ~63 ~61 stone
fill ~85 ~64 ~61 ~95 ~66 ~61 dirt
fill ~85 ~67 ~61 ~95 ~67 ~61 grass_block
fill ~80 ~60 ~62 ~81 ~65 ~62 stone
fill ~80 ~66 ~62 ~81 ~68 ~62 dirt
fill ~80 ~69 ~62 ~81 ~69 ~62 grass_block
fill ~82 ~60 ~62 ~85 ~64 ~62 stone
fill ~82 ~65 ~62 ~85 ~67 ~62 dirt
fill ~82 ~68 ~62 ~85 ~68 ~62 grass_block
fill ~86 ~60 ~62 ~95 ~63 ~62 stone
fill ~86 ~64 ~62 ~95 ~66 ~62 dirt
fill ~86 ~67 ~62 ~95 ~67 ~62 grass_block
fill ~80 ~60 ~63 ~80 ~66 ~63 stone
fill ~80 ~67 ~63 ~80 ~69 ~63 dirt
fill ~80 ~70 ~63 ~80 ~70 ~63 grass_block
fill ~81 ~60 ~63 ~84 ~65 ~63 stone
fill ~81 ~66 ~63 ~84 ~68 ~63 dirt
fill ~81 ~69 ~63 ~84 ~69 ~63 grass_block
fill ~85 ~60 ~63 ~86 ~64 ~63 stone
fill ~85 ~65 ~63 ~86 ~67 ~63 dirt
fill ~85 ~68 ~63 ~86 ~68 ~63 grass_block
fill ~87 ~60 ~63 ~95 ~63 ~63 stone
fill ~87 ~64 ~63 ~95 ~66 ~63 dirt
fill ~87 ~67 ~63 ~95 ~67 ~63 grass_block