fill ~368 ~60 ~128 ~368 ~61 ~128 stone
fill ~368 ~62 ~128 ~368 ~64 ~128 dirt
fill ~368 ~65 ~128 ~368 ~65 ~128 grass_block
fill ~369 ~60 ~128 ~372 ~62 ~128 stone
fill ~369 ~63 ~128 ~372 ~65 ~128 dirt
fill ~369 ~66 ~128 ~372 ~66 ~128 grass_block
fill ~373 ~60 ~128 ~380 ~63 ~128 stone
fill ~373 ~64 ~128 ~380 ~66 ~128 dirt
fill ~373 ~67 ~128 ~380 ~67 ~128 grass_block
fill ~381 ~60 ~128 ~383 ~62 ~128 stone
fill ~381 ~63 ~128 ~383 ~65 ~128 dirt
fill ~381 ~66 ~128 ~383 ~66 ~128 grass_block
fill ~368 ~60 ~129 ~370 ~61 ~129 stone
fill ~368 ~62 ~129 ~370 ~64 ~129 dirt
fill ~368 ~65 ~129 ~370 ~65 ~129 grass_block
fill ~371 ~60 ~129 ~374 ~62 ~129 stone
fill ~371 ~63 ~129 ~374 ~65 ~129 dirt
fill ~371 ~66 ~129 ~374 ~66 ~129 grass_block
fill ~375 ~60 ~129 ~381 ~63 ~129 stone
fill ~375 ~64 ~129 ~381 ~66 ~129 dirt
fill ~375 ~67 ~129 ~381 ~67 ~129 grass_block
fill ~382 ~60 ~129 ~383 ~62 ~129 stone
fill ~382 ~63 ~129 ~383 ~65 ~129 dirt
fill ~382 ~66 ~129 ~383 ~66 ~129 grass_block
fill ~368 ~60 ~130 ~373 ~61 ~130 stone
fill ~368 ~62 ~130 ~373 ~64 ~130 dirt
fill ~368 ~65 ~130 ~373 ~65 ~130 grass_block
fill ~374 ~60 ~130 ~377 ~62 ~130 stone
fill ~374 ~63 ~130 ~377 ~65 ~130 dirt
fill ~374 ~66 ~130 ~377 ~66 ~130 grass_block
fill ~378 ~60 ~130 ~380 ~63 ~130 stone
fill ~378 ~64 ~130 ~380 ~66 ~130 dirt
fill ~378 ~67 ~130 ~380 ~67 ~130 grass_block
fill ~381 ~60 ~130 ~383 ~62 ~130 stone
fill ~381 ~63 ~130 ~383 ~65 ~130 dirt
fill ~381 ~66 ~130 ~383 ~66 ~130 grass_block
fill ~368 ~60 ~131 ~369 ~60 ~131 stone
fill ~368 ~61 ~131 ~369 ~63 ~131 dirt
fill ~368 ~64 ~131 ~369 ~64 ~131 grass_block
fill ~370 ~60 ~131 ~375 ~61 ~131 stone
fill ~370 ~62 ~131 ~375 ~64 ~131 dirt
fill ~370 ~65 ~131 ~375 ~65 ~131 grass_block
fill ~376 ~60 ~131 ~383 ~62 ~131 stone
fill ~376 ~63 ~131 ~383 ~65 ~131 dirt
fill ~376 ~66 ~131 ~383 ~66 ~131 grass_block
fill ~368 ~60 ~132 ~372 ~60 ~132 stone
fill ~368 ~61 ~132 ~372 ~63 ~132 dirt
fill ~368 ~64 ~132 ~372 ~64 ~132 grass_block
fill ~373 ~60 ~132 ~378 ~61 ~132 stone
fill ~373 ~62 ~132 ~378 ~64 ~132 dirt
fill ~373 ~65 ~132 ~378 ~65 ~132 grass_block
fill ~379 ~60 ~132 ~383 ~62 ~132 stone
fill ~379 ~63 ~132 ~383 ~65 ~132 dirt
fill ~379 ~66 ~132 ~383 ~66 ~132 grass_block
fill ~368 ~60 ~133 ~375 ~60 ~133 stone
fill ~368 ~61 ~133 ~375 ~63 ~133 dirt
fill ~368 ~64 ~133 ~375 ~64 ~133 grass_block
fill ~376 ~60 ~133 ~380 ~61 ~133 stone
fill ~376 ~62 ~133 ~380 ~64 ~133 dirt
fill ~376 ~65 ~133 ~380 ~65 ~133 grass_block
fill ~381 ~60 ~133 ~383 ~62 ~133 stone
fill ~381 ~63 ~133 ~383 ~65 ~133 dirt
fill ~381 ~66 ~133 ~383 ~66 ~133 grass_block
fill ~368 ~60 ~134 ~378 ~60 ~134 stone
fill ~368 ~61 ~134 ~378 ~63 ~134 dirt
fill ~368 ~64 ~134 ~378 ~64 ~134 grass_block
fill ~379 ~60 ~134 ~382 ~61 ~134 stone
fill ~379 ~62 ~134 ~382 ~64 ~134 dirt
fill ~379 ~65 ~134 ~382 ~65 ~134 grass_block
fill ~383 ~60 ~134 ~383 ~62 ~134 stone
fill ~383 ~63 ~134 ~383 ~65 ~134 dirt
fill ~383 ~66 ~134 ~383 ~66 ~134 grass_block
fill ~368 ~60 ~135 ~380 ~60 ~135 stone
fill ~368 ~61 ~135 ~380 ~63 ~135 dirt
fill ~368 ~64 ~135 ~380 ~64 ~135 grass_block
fill ~381 ~60 ~135 ~383 ~61 ~135 stone
fill ~381 ~62 ~135 ~383 ~64 ~135 dirt
fill ~381 ~65 ~135 ~383 ~65 ~135 grass_block
fill ~368 ~60 ~136 ~368 ~61 ~136 stone
fill ~368 ~62 ~136 ~368 ~64 ~136 dirt
fill ~368 ~65 ~136 ~368 ~65 ~136 grass_block
fill ~369 ~60 ~136 ~383 ~60 ~136 stone
fill ~369 ~61 ~136 ~383 ~63 ~136 dirt
fill ~369 ~64 ~136 ~383 ~64 ~136 grass_block
fill ~368 ~60 ~137 ~369 ~61 ~137 stone
fill ~368 ~62 ~137 ~369 ~64 ~137 dirt
fill ~368 ~65 ~137 ~369 ~65 ~137 grass_block
fill ~370 ~60 ~137 ~383 ~60 ~137 stone
fill ~370 ~61 ~137 ~383 ~63 ~137 dirt
fill ~370 ~64 ~137 ~383 ~64 ~137 grass_block
fill ~368 ~60 ~138 ~372 ~61 ~138 stone
fill ~368 ~62 ~138 ~372 ~64 ~138 dirt
fill ~368 ~65 ~138 ~372 ~65 ~138 grass_block
fill ~373 ~60 ~138 ~383 ~60 ~138 stone
fill ~373 ~61 ~138 ~383 ~63 ~138 dirt
fill ~373 ~64 ~138 ~383 ~64 ~138 grass_block
fill ~368 ~60 ~139 ~368 ~62 ~139 stone
fill ~368 ~63 ~139 ~368 ~65 ~139 dirt
fill ~368 ~66 ~139 ~368 ~66 ~139 grass_block
fill ~369 ~60 ~139 ~372 ~61 ~139 stone
fill ~369 ~62 ~139 ~372 ~64 ~139 dirt
fill ~369 ~65 ~139 ~372 ~65 ~139 grass_block
fill ~373 ~60 ~139 ~383 ~60 ~139 stone
fill ~373 ~61 ~139 ~383 ~63 ~139 dirt
fill ~373 ~64 ~139 ~383 ~64 ~139 grass_block
fill ~368 ~60 ~140 ~369 ~62 ~140 stone
fill ~368 ~63 ~140 ~369 ~65 ~140 dirt
fill ~368 ~66 ~140 ~369 ~66 ~140 grass_block
fill ~370 ~60 ~140 ~373 ~61 ~140 stone
fill ~370 ~62 ~140 ~373 ~64 ~140 dirt
fill ~370 ~65 ~140 ~373 ~65 ~140 grass_block
fill ~374 ~60 ~140 ~383 ~60 ~140 stone
fill ~374 ~61 ~140 ~383 ~63 ~140 dirt
fill ~374 ~64 ~140 ~383 ~64 ~140 grass_block
fill ~368 ~60 ~141 ~370 ~62 ~141 stone
fill ~368 ~63 ~141 ~370 ~65 ~141 dirt
fill ~368 ~66 ~141 ~370 ~66 ~141 grass_block
fill ~371 ~60 ~141 ~374 ~61 ~141 stone
fill ~371 ~62 ~141 ~374 ~64 ~141 dirt
fill ~371 ~65 ~141 ~374 ~65 ~141 grass_block
fill ~375 ~60 ~141 ~383 ~60 ~141 stone
fill ~375 ~61 ~141 ~383 ~63 ~141 dirt
fill ~375 ~64 ~141 ~383 ~64 ~141 grass_block
fill ~368 ~60 ~142 ~372 ~62 ~142 stone
fill ~368 ~63 ~142 ~372 ~65 ~142 dirt
fill ~368 ~66 ~142 ~372 ~66 ~142 grass_block
fill ~373 ~60 ~142 ~377 ~61 ~142 stone
fill ~373 ~62 ~142 ~377 ~64 ~142 dirt
fill ~373 ~65 ~142 ~377 ~65 ~142 grass_block
fill ~378 ~60 ~142 ~383 ~60 ~142 stone
fill ~378 ~61 ~142 ~383 ~63 ~142 dirt
fill ~378 ~64 ~142 ~383 ~64 ~142 grass_block
fill ~368 ~60 ~143 ~373 ~62 ~143 stone
fill ~368 ~63 ~143 ~373 ~65 ~143 dirt
fill ~368 ~66 ~143 ~373 ~66 ~143 grass_block
fill ~374 ~60 ~143 ~377 ~61 ~143 stone
fill ~374 ~62 ~143 ~377 ~64 ~143 dirt
fill ~374 ~65 ~143 ~377 ~65 ~143 grass_block
fill ~378 ~60 ~143 ~383 ~60 ~143 stone
fill ~378 ~61 ~143 ~383 ~63 ~143 dirt
fill ~378 ~64 ~143 ~383 ~64 ~143 grass_block