fill ~336 ~60 ~112 ~338 ~61 ~112 stone
fill ~336 ~62 ~112 ~338 ~64 ~112 dirt
fill ~336 ~65 ~112 ~338 ~65 ~112 grass_block
fill ~339 ~60 ~112 ~351 ~60 ~112 stone
fill ~339 ~61 ~112 ~351 ~63 ~112 dirt
fill ~339 ~64 ~112 ~351 ~64 ~112 grass_block
fill ~336 ~60 ~113 ~339 ~61 ~113 stone
fill ~336 ~62 ~113 ~339 ~64 ~113 dirt
fill ~336 ~65 ~113 ~339 ~65 ~113 grass_block
fill ~340 ~60 ~113 ~351 ~60 ~113 stone
fill ~340 ~61 ~113 ~351 ~63 ~113 dirt
fill ~340 ~64 ~113 ~351 ~64 ~113 grass_block
fill ~336 ~60 ~114 ~336 ~62 ~114 stone
fill ~336 ~63 ~114 ~336 ~65 ~114 dirt
fill ~336 ~66 ~114 ~336 ~66 ~114 grass_block
fill ~337 ~60 ~114 ~339 ~61 ~114 stone
fill ~337 ~62 ~114 ~339 ~64 ~114 dirt
fill ~337 ~65 ~114 ~339 ~65 ~114 grass_block
fill ~340 ~60 ~114 ~351 ~60 ~114 stone
fill ~340 ~61 ~114 ~351 ~63 ~114 dirt
fill ~340 ~64 ~114 ~351 ~64 ~114 grass_block
fill ~336 ~60 ~115 ~337 ~62 ~115 stone
fill ~336 ~63 ~115 ~337 ~65 ~115 dirt
fill ~336 ~66 ~115 ~337 ~66 ~115 grass_block
fill ~338 ~60 ~115 ~339 ~61 ~115 stone
fill ~338 ~62 ~115 ~339 ~64 ~115 dirt
fill ~338 ~65 ~115 ~339 ~65 ~115 grass_block
fill ~340 ~60 ~115 ~351 ~60 ~115 stone
fill ~340 ~61 ~115 ~351 ~63 ~115 dirt
fill ~340 ~64 ~115 ~351 ~64 ~115 grass_block
fill ~336 ~60 ~116 ~338 ~62 ~116 stone
fill ~336 ~63 ~116 ~338 ~65 ~116 dirt
fill ~336 ~66 ~116 ~338 ~66 ~116 grass_block
fill ~339 ~60 ~116 ~340 ~61 ~116 stone
fill ~339 ~62 ~116 ~340 ~64 ~116 dirt
fill ~339 ~65 ~116 ~340 ~65 ~116 grass_block
fill ~341 ~60 ~116 ~351 ~60 ~116 stone
fill ~341 ~61 ~116 ~351 ~63 ~116 dirt
fill ~341 ~64 ~116 ~351 ~64 ~116 grass_block
fill ~336 ~60 ~117 ~338 ~62 ~117 stone
fill ~336 ~63 ~117 ~338 ~65 ~117 dirt
fill ~336 ~66 ~117 ~338 ~66 ~117 grass_block
fill ~339 ~60 ~117 ~341 ~61 ~117 stone
fill ~339 ~62 ~117 ~341 ~64 ~117 dirt
fill ~339 ~65 ~117 ~341 ~65 ~117 grass_block
fill ~342 ~60 ~117 ~351 ~60 ~117 stone
fill ~342 ~61 ~117 ~351 ~63 ~117 dirt
fill ~342 ~64 ~117 ~351 ~64 ~117 grass_block
fill ~336 ~60 ~118 ~339 ~62 ~118 stone
fill ~336 ~63 ~118 ~339 ~65 ~118 dirt
fill ~336 ~66 ~118 ~339 ~66 ~118 grass_block
fill ~340 ~60 ~118 ~341 ~61 ~118 stone
fill ~340 ~62 ~118 ~341 ~64 ~118 dirt
fill ~340 ~65 ~118 ~341 ~65 ~118 grass_block
fill ~342 ~60 ~118 ~351 ~60 ~118 stone
fill ~342 ~61 ~118 ~351 ~63 ~118 dirt
fill ~342 ~64 ~118 ~351 ~64 ~118 grass_block
fill ~336 ~60 ~119 ~338 ~62 ~119 stone
fill ~336 ~63 ~119 ~338 ~65 ~119 dirt
fill ~336 ~66 ~119 ~338 ~66 ~119 grass_block
fill ~339 ~60 ~119 ~342 ~61 ~119 stone
fill ~339 ~62 ~119 ~342 ~64 ~119 dirt
fill ~339 ~65 ~119 ~342 ~65 ~119 grass_block
fill ~343 ~60 ~119 ~351 ~60 ~119 stone
fill ~343 ~61 ~119 ~351 ~63 ~119 dirt
fill ~343 ~64 ~119 ~351 ~64 ~119 grass_block
fill ~336 ~60 ~120 ~338 ~62 ~120 stone
fill ~336 ~63 ~120 ~338 ~65 ~120 dirt
fill ~336 ~66 ~120 ~338 ~66 ~120 grass_block
fill ~339 ~60 ~120 ~344 ~61 ~120 stone
fill ~339 ~62 ~120 ~344 ~64 ~120 dirt
fill ~339 ~65 ~120 ~344 ~65 ~120 grass_block
fill ~345 ~60 ~120 ~351 ~60 ~120 stone
fill ~345 ~61 ~120 ~351 ~63 ~120 dirt
fill ~345 ~64 ~120 ~351 ~64 ~120 grass_block
fill ~336 ~60 ~121 ~337 ~62 ~121 stone
fill ~336 ~63 ~121 ~337 ~65 ~121 dirt
fill ~336 ~66 ~121 ~337 ~66 ~121 grass_block
fill ~338 ~60 ~121 ~344 ~61 ~121 stone
fill ~338 ~62 ~121 ~344 ~64 ~121 dirt
fill ~338 ~65 ~121 ~344 ~65 ~121 grass_block
fill ~345 ~60 ~121 ~351 ~60 ~121 stone
fill ~345 ~61 ~121 ~351 ~63 ~121 dirt
fill ~345 ~64 ~121 ~351 ~64 ~121 grass_block
fill ~336 ~60 ~122 ~336 ~62 ~122 stone
fill ~336 ~63 ~122 ~336 ~65 ~122 dirt
fill ~336 ~66 ~122 ~336 ~66 ~122 grass_block
fill ~337 ~60 ~122 ~345 ~61 ~122 stone
fill ~337 ~62 ~122 ~345 ~64 ~122 dirt
fill ~337 ~65 ~122 ~345 ~65 ~122 grass_block
fill ~346 ~60 ~122 ~351 ~60 ~122 stone
fill ~346 ~61 ~122 ~351 ~63 ~122 dirt
fill ~346 ~64 ~122 ~351 ~64 ~122 grass_block
fill ~336 ~60 ~123 ~347 ~61 ~123 stone
fill ~336 ~62 ~123 ~347 ~64 ~123 dirt
fill ~336 ~65 ~123 ~347 ~65 ~123 grass_block
fill ~348 ~60 ~123 ~351 ~60 ~123 stone
fill ~348 ~61 ~123 ~351 ~63 ~123 dirt
fill ~348 ~64 ~123 ~351 ~64 ~123 grass_block
fill ~336 ~60 ~124 ~336 ~62 ~124 stone
fill ~336 ~63 ~124 ~336 ~65 ~124 dirt
fill ~336 ~66 ~124 ~336 ~66 ~124 grass_block
fill ~337 ~60 ~124 ~338 ~61 ~124 stone
fill ~337 ~62 ~124 ~338 ~64 ~124 dirt
fill ~337 ~65 ~124 ~338 ~65 ~124 grass_block
fill ~339 ~60 ~124 ~339 ~62 ~124 stone
fill ~339 ~63 ~124 ~339 ~65 ~124 dirt
fill ~339 ~66 ~124 ~339 ~66 ~124 grass_block
fill ~340 ~60 ~124 ~348 ~61 ~124 stone
fill ~340 ~62 ~124 ~348 ~64 ~124 dirt
fill ~340 ~65 ~124 ~348 ~65 ~124 grass_block
fill ~349 ~60 ~124 ~351 ~60 ~124 stone
fill ~349 ~61 ~124 ~351 ~63 ~124 dirt
fill ~349 ~64 ~124 ~351 ~64 ~124 grass_block
fill ~336 ~60 ~125 ~342 ~62 ~125 stone
fill ~336 ~63 ~125 ~342 ~65 ~125 dirt
fill ~336 ~66 ~125 ~342 ~66 ~125 grass_block
fill ~343 ~60 ~125 ~349 ~61 ~125 stone
fill ~343 ~62 ~125 ~349 ~64 ~125 dirt
fill ~343 ~65 ~125 ~349 ~65 ~125 grass_block
fill ~350 ~60 ~125 ~351 ~60 ~125 stone
fill ~350 ~61 ~125 ~351 ~63 ~125 dirt
fill ~350 ~64 ~125 ~351 ~64 ~125 grass_block
fill ~336 ~60 ~126 ~343 ~62 ~126 stone
fill ~336 ~63 ~126 ~343 ~65 ~126 dirt
fill ~336 ~66 ~126 ~343 ~66 ~126 grass_block
fill ~344 ~60 ~126 ~350 ~61 ~126 stone
fill ~344 ~62 ~126 ~350 ~64 ~126 dirt
fill ~344 ~65 ~126 ~350 ~65 ~126 grass_block
fill ~351 ~60 ~126 ~351 ~60 ~126 stone
fill ~351 ~61 ~126 ~351 ~63 ~126 dirt
fill ~351 ~64 ~126 ~351 ~64 ~126 grass_block
fill ~336 ~60 ~127 ~339 ~63 ~127 stone
fill ~336 ~64 ~127 ~339 ~66 ~127 dirt
fill ~336 ~67 ~127 ~339 ~67 ~127 grass_block
fill ~340 ~60 ~127 ~344 ~62 ~127 stone
fill ~340 ~63 ~127 ~344 ~65 ~127 dirt
fill ~340 ~66 ~127 ~344 ~66 ~127 grass_block
fill ~345 ~60 ~127 ~351 ~61 ~127 stone
fill ~345 ~62 ~127 ~351 ~64 ~127 dirt
fill ~345 ~65 ~127 ~351 ~65 ~127 grass_block