fill ~272 ~60 ~80 ~276 ~63 ~80 stone
fill ~272 ~64 ~80 ~276 ~66 ~80 dirt
fill ~272 ~67 ~80 ~276 ~67 ~80 grass_block
fill ~277 ~60 ~80 ~277 ~62 ~80 stone
fill ~277 ~63 ~80 ~277 ~65 ~80 dirt
fill ~277 ~66 ~80 ~277 ~66 ~80 grass_block
fill ~278 ~60 ~80 ~279 ~63 ~80 stone
fill ~278 ~64 ~80 ~279 ~66 ~80 dirt
fill ~278 ~67 ~80 ~279 ~67 ~80 grass_block
fill ~280 ~60 ~80 ~287 ~62 ~80 stone
fill ~280 ~63 ~80 ~287 ~65 ~80 dirt
fill ~280 ~66 ~80 ~287 ~66 ~80 grass_block
fill ~272 ~60 ~81 ~280 ~63 ~81 stone
fill ~272 ~64 ~81 ~280 ~66 ~81 dirt
fill ~272 ~67 ~81 ~280 ~67 ~81 grass_block
fill ~281 ~60 ~81 ~287 ~62 ~81 stone
fill ~281 ~63 ~81 ~287 ~65 ~81 dirt
fill ~281 ~66 ~81 ~287 ~66 ~81 grass_block
fill ~272 ~60 ~82 ~281 ~63 ~82 stone
fill ~272 ~64 ~82 ~281 ~66 ~82 dirt
fill ~272 ~67 ~82 ~281 ~67 ~82 grass_block
fill ~282 ~60 ~82 ~287 ~62 ~82 stone
fill ~282 ~63 ~82 ~287 ~65 ~82 dirt
fill ~282 ~66 ~82 ~287 ~66 ~82 grass_block
fill ~272 ~60 ~83 ~281 ~63 ~83 stone
fill ~272 ~64 ~83 ~281 ~66 ~83 dirt
fill ~272 ~67 ~83 ~281 ~67 ~83 grass_block
fill ~282 ~60 ~83 ~287 ~62 ~83 stone
fill ~282 ~63 ~83 ~287 ~65 ~83 dirt
fill ~282 ~66 ~83 ~287 ~66 ~83 grass_block
fill ~272 ~60 ~84 ~285 ~63 ~84 stone
fill ~272 ~64 ~84 ~285 ~66 ~84 dirt
fill ~272 ~67 ~84 ~285 ~67 ~84 grass_block
fill ~286 ~60 ~84 ~287 ~62 ~84 stone
fill ~286 ~63 ~84 ~287 ~65 ~84 dirt
fill ~286 ~66 ~84 ~287 ~66 ~84 grass_block
fill ~272 ~60 ~85 ~284 ~63 ~85 stone
fill ~272 ~64 ~85 ~284 ~66 ~85 dirt
fill ~272 ~67 ~85 ~284 ~67 ~85 grass_block
fill ~285 ~60 ~85 ~287 ~62 ~85 stone
fill ~285 ~63 ~85 ~287 ~65 ~85 dirt
fill ~285 ~66 ~85 ~287 ~66 ~85 grass_block
fill ~272 ~60 ~86 ~273 ~64 ~86 stone
fill ~272 ~65 ~86 ~273 ~67 ~86 dirt
fill ~272 ~68 ~86 ~273 ~68 ~86 grass_block
fill ~274 ~60 ~86 ~284 ~63 ~86 stone
fill ~274 ~64 ~86 ~284 ~66 ~86 dirt
fill ~274 ~67 ~86 ~284 ~67 ~86 grass_block
fill ~285 ~60 ~86 ~287 ~62 ~86 stone
fill ~285 ~63 ~86 ~287 ~65 ~86 dirt
fill ~285 ~66 ~86 ~287 ~66 ~86 grass_block
fill ~272 ~60 ~87 ~274 ~64 ~87 stone
fill ~272 ~65 ~87 ~274 ~67 ~87 dirt
fill ~272 ~68 ~87 ~274 ~68 ~87 grass_block
fill ~275 ~60 ~87 ~275 ~63 ~87 stone
fill ~275 ~64 ~87 ~275 ~66 ~87 dirt
fill ~275 ~67 ~87 ~275 ~67 ~87 grass_block
fill ~276 ~60 ~87 ~276 ~64 ~87 stone
fill ~276 ~65 ~87 ~276 ~67 ~87 dirt
fill ~276 ~68 ~87 ~276 ~68 ~87 grass_block
fill ~277 ~60 ~87 ~286 ~63 ~87 stone
fill ~277 ~64 ~87 ~286 ~66 ~87 dirt
fill ~277 ~67 ~87 ~286 ~67 ~87 grass_block
fill ~287 ~60 ~87 ~287 ~62 ~87 stone
fill ~287 ~63 ~87 ~287 ~65 ~87 dirt
fill ~287 ~66 ~87 ~287 ~66 ~87 grass_block
fill ~272 ~60 ~88 ~276 ~64 ~88 stone
fill ~272 ~65 ~88 ~276 ~67 ~88 dirt
fill ~272 ~68 ~88 ~276 ~68 ~88 grass_block
fill ~277 ~60 ~88 ~286 ~63 ~88 stone
fill ~277 ~64 ~88 ~286 ~66 ~88 dirt
fill ~277 ~67 ~88 ~286 ~67 ~88 grass_block
fill ~287 ~60 ~88 ~287 ~62 ~88 stone
fill ~287 ~63 ~88 ~287 ~65 ~88 dirt
fill ~287 ~66 ~88 ~287 ~66 ~88 grass_block
fill ~272 ~60 ~89 ~277 ~64 ~89 stone
fill ~272 ~65 ~89 ~277 ~67 ~89 dirt
fill ~272 ~68 ~89 ~277 ~68 ~89 grass_block
fill ~278 ~60 ~89 ~287 ~63 ~89 stone
fill ~278 ~64 ~89 ~287 ~66 ~89 dirt
fill ~278 ~67 ~89 ~287 ~67 ~89 grass_block
fill ~272 ~60 ~90 ~278 ~64 ~90 stone
fill ~272 ~65 ~90 ~278 ~67 ~90 dirt
fill ~272 ~68 ~90 ~278 ~68 ~90 grass_block
fill ~279 ~60 ~90 ~280 ~63 ~90 stone
fill ~279 ~64 ~90 ~280 ~66 ~90 dirt
fill ~279 ~67 ~90 ~280 ~67 ~90 grass_block
fill ~281 ~60 ~90 ~281 ~64 ~90 stone
fill ~281 ~65 ~90 ~281 ~67 ~90 dirt
fill ~281 ~68 ~90 ~281 ~68 ~90 grass_block
fill ~282 ~60 ~90 ~287 ~63 ~90 stone
fill ~282 ~64 ~90 ~287 ~66 ~90 dirt
fill ~282 ~67 ~90 ~287 ~67 ~90 grass_block
fill ~272 ~60 ~91 ~279 ~64 ~91 stone
fill ~272 ~65 ~91 ~279 ~67 ~91 dirt
fill ~272 ~68 ~91 ~279 ~68 ~91 grass_block
fill ~280 ~60 ~91 ~281 ~63 ~91 stone
fill ~280 ~64 ~91 ~281 ~66 ~91 dirt
fill ~280 ~67 ~91 ~281 ~67 ~91 grass_block
fill ~282 ~60 ~91 ~282 ~64 ~91 stone
fill ~282 ~65 ~91 ~282 ~67 ~91 dirt
fill ~282 ~68 ~91 ~282 ~68 ~91 grass_block
fill ~283 ~60 ~91 ~287 ~63 ~91 stone
fill ~283 ~64 ~91 ~287 ~66 ~91 dirt
fill ~283 ~67 ~91 ~287 ~67 ~91 grass_block
fill ~272 ~60 ~92 ~272 ~65 ~92 stone
fill ~272 ~66 ~92 ~272 ~68 ~92 dirt
fill ~272 ~69 ~92 ~272 ~69 ~92 grass_block
fill ~273 ~60 ~92 ~281 ~64 ~92 stone
fill ~273 ~65 ~92 ~281 ~67 ~92 dirt
fill ~273 ~68 ~92 ~281 ~68 ~92 grass_block
fill ~282 ~60 ~92 ~287 ~63 ~92 stone
fill ~282 ~64 ~92 ~287 ~66 ~92 dirt
fill ~282 ~67 ~92 ~287 ~67 ~92 grass_block
fill ~272 ~60 ~93 ~272 ~65 ~93 stone
fill ~272 ~66 ~93 ~272 ~68 ~93 dirt
fill ~272 ~69 ~93 ~272 ~69 ~93 grass_block
fill ~273 ~60 ~93 ~282 ~64 ~93 stone
fill ~273 ~65 ~93 ~282 ~67 ~93 dirt
fill ~273 ~68 ~93 ~282 ~68 ~93 grass_block
fill ~283 ~60 ~93 ~287 ~63 ~93 stone
fill ~283 ~64 ~93 ~287 ~66 ~93 dirt
fill ~283 ~67 ~93 ~287 ~67 ~93 grass_block
fill ~272 ~60 ~94 ~274 ~65 ~94 stone
fill ~272 ~66 ~94 ~274 ~68 ~94 dirt
fill ~272 ~69 ~94 ~274 ~69 ~94 grass_block
fill ~275 ~60 ~94 ~284 ~64 ~94 stone
fill ~275 ~65 ~94 ~284 ~67 ~94 dirt
fill ~275 ~68 ~94 ~284 ~68 ~94 grass_block
fill ~285 ~60 ~94 ~287 ~63 ~94 stone
fill ~285 ~64 ~94 ~287 ~66 ~94 dirt
fill ~285 ~67 ~94 ~287 ~67 ~94 grass_block
fill ~272 ~60 ~95 ~276 ~65 ~95 stone
fill ~272 ~66 ~95 ~276 ~68 ~95 dirt
fill ~272 ~69 ~95 ~276 ~69 ~95 grass_block
fill ~277 ~60 ~95 ~283 ~64 ~95 stone
fill ~277 ~65 ~95 ~283 ~67 ~95 dirt
fill ~277 ~68 ~95 ~283 ~68 ~95 grass_block
fill ~284 ~60 ~95 ~287 ~63 ~95 stone
fill ~284 ~64 ~95 ~287 ~66 ~95 dirt
fill ~284 ~67 ~95 ~287 ~67 ~95 grass_block