fill ~240 ~60 ~96 ~241 ~65 ~96 stone
fill ~240 ~66 ~96 ~241 ~68 ~96 dirt
fill ~240 ~69 ~96 ~241 ~69 ~96 grass_block
fill ~242 ~60 ~96 ~245 ~64 ~96 stone
fill ~242 ~65 ~96 ~245 ~67 ~96 dirt
fill ~242 ~68 ~96 ~245 ~68 ~96 grass_block
fill ~246 ~60 ~96 ~253 ~63 ~96 stone
fill ~246 ~64 ~96 ~253 ~66 ~96 dirt
fill ~246 ~67 ~96 ~253 ~67 ~96 grass_block
fill ~254 ~60 ~96 ~255 ~64 ~96 stone
fill ~254 ~65 ~96 ~255 ~67 ~96 dirt
fill ~254 ~68 ~96 ~255 ~68 ~96 grass_block
fill ~240 ~60 ~97 ~242 ~65 ~97 stone
fill ~240 ~66 ~97 ~242 ~68 ~97 dirt
fill ~240 ~69 ~97 ~242 ~69 ~97 grass_block
fill ~243 ~60 ~97 ~245 ~64 ~97 stone
fill ~243 ~65 ~97 ~245 ~67 ~97 dirt
fill ~243 ~68 ~97 ~245 ~68 ~97 grass_block
fill ~246 ~60 ~97 ~253 ~63 ~97 stone
fill ~246 ~64 ~97 ~253 ~66 ~97 dirt
fill ~246 ~67 ~97 ~253 ~67 ~97 grass_block
fill ~254 ~60 ~97 ~255 ~64 ~97 stone
fill ~254 ~65 ~97 ~255 ~67 ~97 dirt
fill ~254 ~68 ~97 ~255 ~68 ~97 grass_block
fill ~240 ~60 ~98 ~242 ~65 ~98 stone
fill ~240 ~66 ~98 ~242 ~68 ~98 dirt
fill ~240 ~69 ~98 ~242 ~69 ~98 grass_block
fill ~243 ~60 ~98 ~246 ~64 ~98 stone
fill ~243 ~65 ~98 ~246 ~67 ~98 dirt
fill ~243 ~68 ~98 ~246 ~68 ~98 grass_block
fill ~247 ~60 ~98 ~253 ~63 ~98 stone
fill ~247 ~64 ~98 ~253 ~66 ~98 dirt
fill ~247 ~67 ~98 ~253 ~67 ~98 grass_block
fill ~254 ~60 ~98 ~255 ~64 ~98 stone
fill ~254 ~65 ~98 ~255 ~67 ~98 dirt
fill ~254 ~68 ~98 ~255 ~68 ~98 grass_block
fill ~240 ~60 ~99 ~243 ~65 ~99 stone
fill ~240 ~66 ~99 ~243 ~68 ~99 dirt
fill ~240 ~69 ~99 ~243 ~69 ~99 grass_block
fill ~244 ~60 ~99 ~246 ~64 ~99 stone
fill ~244 ~65 ~99 ~246 ~67 ~99 dirt
fill ~244 ~68 ~99 ~246 ~68 ~99 grass_block
fill ~247 ~60 ~99 ~254 ~63 ~99 stone
fill ~247 ~64 ~99 ~254 ~66 ~99 dirt
fill ~247 ~67 ~99 ~254 ~67 ~99 grass_block
fill ~255 ~60 ~99 ~255 ~64 ~99 stone
fill ~255 ~65 ~99 ~255 ~67 ~99 dirt
fill ~255 ~68 ~99 ~255 ~68 ~99 grass_block
fill ~240 ~60 ~100 ~243 ~65 ~100 stone
fill ~240 ~66 ~100 ~243 ~68 ~100 dirt
fill ~240 ~69 ~100 ~243 ~69 ~100 grass_block
fill ~244 ~60 ~100 ~247 ~64 ~100 stone
fill ~244 ~65 ~100 ~247 ~67 ~100 dirt
fill ~244 ~68 ~100 ~247 ~68 ~100 grass_block
fill ~248 ~60 ~100 ~254 ~63 ~100 stone
fill ~248 ~64 ~100 ~254 ~66 ~100 dirt
fill ~248 ~67 ~100 ~254 ~67 ~100 grass_block
fill ~255 ~60 ~100 ~255 ~64 ~100 stone
fill ~255 ~65 ~100 ~255 ~67 ~100 dirt
fill ~255 ~68 ~100 ~255 ~68 ~100 grass_block
fill ~240 ~60 ~101 ~244 ~65 ~101 stone
fill ~240 ~66 ~101 ~244 ~68 ~101 dirt
fill ~240 ~69 ~101 ~244 ~69 ~101 grass_block
fill ~245 ~60 ~101 ~248 ~64 ~101 stone
fill ~245 ~65 ~101 ~248 ~67 ~101 dirt
fill ~245 ~68 ~101 ~248 ~68 ~101 grass_block
fill ~249 ~60 ~101 ~251 ~63 ~101 stone
fill ~249 ~64 ~101 ~251 ~66 ~101 dirt
fill ~249 ~67 ~101 ~251 ~67 ~101 grass_block
fill ~252 ~60 ~101 ~252 ~62 ~101 stone
fill ~252 ~63 ~101 ~252 ~65 ~101 dirt
fill ~252 ~66 ~101 ~252 ~66 ~101 grass_block
fill ~253 ~60 ~101 ~255 ~63 ~101 stone
fill ~253 ~64 ~101 ~255 ~66 ~101 dirt
fill ~253 ~67 ~101 ~255 ~67 ~101 grass_block
fill ~240 ~60 ~102 ~240 ~64 ~102 stone
fill ~240 ~65 ~102 ~240 ~67 ~102 dirt
fill ~240 ~68 ~102 ~240 ~68 ~102 grass_block
fill ~241 ~60 ~102 ~245 ~65 ~102 stone
fill ~241 ~66 ~102 ~245 ~68 ~102 dirt
fill ~241 ~69 ~102 ~245 ~69 ~102 grass_block
fill ~246 ~60 ~102 ~248 ~64 ~102 stone
fill ~246 ~65 ~102 ~248 ~67 ~102 dirt
fill ~246 ~68 ~102 ~248 ~68 ~102 grass_block
fill ~249 ~60 ~102 ~251 ~63 ~102 stone
fill ~249 ~64 ~102 ~251 ~66 ~102 dirt
fill ~249 ~67 ~102 ~251 ~67 ~102 grass_block
fill ~252 ~60 ~102 ~252 ~62 ~102 stone
fill ~252 ~63 ~102 ~252 ~65 ~102 dirt
fill ~252 ~66 ~102 ~252 ~66 ~102 grass_block
fill ~253 ~60 ~102 ~255 ~63 ~102 stone
fill ~253 ~64 ~102 ~255 ~66 ~102 dirt
fill ~253 ~67 ~102 ~255 ~67 ~102 grass_block
fill ~240 ~60 ~103 ~241 ~64 ~103 stone
fill ~240 ~65 ~103 ~241 ~67 ~103 dirt
fill ~240 ~68 ~103 ~241 ~68 ~103 grass_block
fill ~242 ~60 ~103 ~246 ~65 ~103 stone
fill ~242 ~66 ~103 ~246 ~68 ~103 dirt
fill ~242 ~69 ~103 ~246 ~69 ~103 grass_block
fill ~247 ~60 ~103 ~249 ~64 ~103 stone
fill ~247 ~65 ~103 ~249 ~67 ~103 dirt
fill ~247 ~68 ~103 ~249 ~68 ~103 grass_block
fill ~250 ~60 ~103 ~252 ~63 ~103 stone
fill ~250 ~64 ~103 ~252 ~66 ~103 dirt
fill ~250 ~67 ~103 ~252 ~67 ~103 grass_block
fill ~253 ~60 ~103 ~254 ~62 ~103 stone
fill ~253 ~63 ~103 ~254 ~65 ~103 dirt
fill ~253 ~66 ~103 ~254 ~66 ~103 grass_block
fill ~255 ~60 ~103 ~255 ~63 ~103 stone
fill ~255 ~64 ~103 ~255 ~66 ~103 dirt
fill ~255 ~67 ~103 ~255 ~67 ~103 grass_block
fill ~240 ~60 ~104 ~242 ~64 ~104 stone
fill ~240 ~65 ~104 ~242 ~67 ~104 dirt
fill ~240 ~68 ~104 ~242 ~68 ~104 grass_block
fill ~243 ~60 ~104 ~246 ~65 ~104 stone
fill ~243 ~66 ~104 ~246 ~68 ~104 dirt
fill ~243 ~69 ~104 ~246 ~69 ~104 grass_block
fill ~247 ~60 ~104 ~249 ~64 ~104 stone
fill ~247 ~65 ~104 ~249 ~67 ~104 dirt
fill ~247 ~68 ~104 ~249 ~68 ~104 grass_block
fill ~250 ~60 ~104 ~253 ~63 ~104 stone
fill ~250 ~64 ~104 ~253 ~66 ~104 dirt
fill ~250 ~67 ~104 ~253 ~67 ~104 grass_block
fill ~254 ~60 ~104 ~254 ~62 ~104 stone
fill ~254 ~63 ~104 ~254 ~65 ~104 dirt
fill ~254 ~66 ~104 ~254 ~66 ~104 grass_block
fill ~255 ~60 ~104 ~255 ~63 ~104 stone
fill ~255 ~64 ~104 ~255 ~66 ~104 dirt
fill ~255 ~67 ~104 ~255 ~67 ~104 grass_block
fill ~240 ~60 ~105 ~243 ~64 ~105 stone
fill ~240 ~65 ~105 ~243 ~67 ~105 dirt
fill ~240 ~68 ~105 ~243 ~68 ~105 grass_block
fill ~244 ~60 ~105 ~246 ~65 ~105 stone
fill ~244 ~66 ~105 ~246 ~68 ~105 dirt
fill ~244 ~69 ~105 ~246 ~69 ~105 grass_block
fill ~247 ~60 ~105 ~249 ~64 ~105 stone
fill ~247 ~65 ~105 ~249 ~67 ~105 dirt
fill ~247 ~68 ~105 ~249 ~68 ~105 grass_block
fill ~250 ~60 ~105 ~253 ~63 ~105 stone
fill ~250 ~64 ~105 ~253 ~66 ~105 dirt
fill ~250 ~67 ~105 ~253 ~67 ~105 grass_block
fill ~254 ~60 ~105 ~255 ~62 ~105 stone
fill ~254 ~63 ~105 ~255 ~65 ~105 dirt
fill ~254 ~66 ~105 ~255 ~66 ~105 grass_block
fill ~240 ~60 ~106 ~245 ~64 ~106 stone
fill ~240 ~65 ~106 ~245 ~67 ~106 dirt
fill ~240 ~68 ~106 ~245 ~68 ~106 grass_block
fill ~246 ~60 ~106 ~246 ~65 ~106 stone
fill ~246 ~66 ~106 ~246 ~68 ~106 dirt
fill ~246 ~69 ~106 ~246 ~69 ~106 grass_block
fill ~247 ~60 ~106 ~250 ~64 ~106 stone
fill ~247 ~65 ~106 ~250 ~67 ~106 dirt
fill ~247 ~68 ~106 ~250 ~68 ~106 grass_block
fill ~251 ~60 ~106 ~253 ~63 ~106 stone
fill ~251 ~64 ~106 ~253 ~66 ~106 dirt
fill ~251 ~67 ~106 ~253 ~67 ~106 grass_block
fill ~254 ~60 ~106 ~255 ~62 ~106 stone
fill ~254 ~63 ~106 ~255 ~65 ~106 dirt
fill ~254 ~66 ~106 ~255 ~66 ~106 grass_block
fill ~240 ~60 ~107 ~240 ~63 ~107 stone
fill ~240 ~64 ~107 ~240 ~66 ~107 dirt
fill ~240 ~67 ~107 ~240 ~67 ~107 grass_block
fill ~241 ~60 ~107 ~251 ~64 ~107 stone
fill ~241 ~65 ~107 ~251 ~67 ~107 dirt
fill ~241 ~68 ~107 ~251 ~68 ~107 grass_block
fill ~252 ~60 ~107 ~254 ~63 ~107 stone
fill ~252 ~64 ~107 ~254 ~66 ~107 dirt
fill ~252 ~67 ~107 ~254 ~67 ~107 grass_block
fill ~255 ~60 ~107 ~255 ~62 ~107 stone
fill ~255 ~63 ~107 ~255 ~65 ~107 dirt
fill ~255 ~66 ~107 ~255 ~66 ~107 grass_block
fill ~240 ~60 ~108 ~243 ~63 ~108 stone
fill ~240 ~64 ~108 ~243 ~66 ~108 dirt
fill ~240 ~67 ~108 ~243 ~67 ~108 grass_block
fill ~244 ~60 ~108 ~252 ~64 ~108 stone
fill ~244 ~65 ~108 ~252 ~67 ~108 dirt
fill ~244 ~68 ~108 ~252 ~68 ~108 grass_block
fill ~253 ~60 ~108 ~254 ~63 ~108 stone
fill ~253 ~64 ~108 ~254 ~66 ~108 dirt
fill ~253 ~67 ~108 ~254 ~67 ~108 grass_block
fill ~255 ~60 ~108 ~255 ~62 ~108 stone
fill ~255 ~63 ~108 ~255 ~65 ~108 dirt
fill ~255 ~66 ~108 ~255 ~66 ~108 grass_block
fill ~240 ~60 ~109 ~244 ~63 ~109 stone
fill ~240 ~64 ~109 ~244 ~66 ~109 dirt
fill ~240 ~67 ~109 ~244 ~67 ~109 grass_block
fill ~245 ~60 ~109 ~252 ~64 ~109 stone
fill ~245 ~65 ~109 ~252 ~67 ~109 dirt
fill ~245 ~68 ~109 ~252 ~68 ~109 grass_block
fill ~253 ~60 ~109 ~255 ~63 ~109 stone
fill ~253 ~64 ~109 ~255 ~66 ~109 dirt
fill ~253 ~67 ~109 ~255 ~67 ~109 grass_block
fill ~240 ~60 ~110 ~246 ~63 ~110 stone
fill ~240 ~64 ~110 ~246 ~66 ~110 dirt
fill ~240 ~67 ~110 ~246 ~67 ~110 grass_block
fill ~247 ~60 ~110 ~253 ~64 ~110 stone
fill ~247 ~65 ~110 ~253 ~67 ~110 dirt
fill ~247 ~68 ~110 ~253 ~68 ~110 grass_block
fill ~254 ~60 ~110 ~255 ~63 ~110 stone
fill ~254 ~64 ~110 ~255 ~66 ~110 dirt
fill ~254 ~67 ~110 ~255 ~67 ~110 grass_block
fill ~240 ~60 ~111 ~242 ~62 ~111 stone
fill ~240 ~63 ~111 ~242 ~65 ~111 dirt
fill ~240 ~66 ~111 ~242 ~66 ~111 grass_block
fill ~243 ~60 ~111 ~247 ~63 ~111 stone
fill ~243 ~64 ~111 ~247 ~66 ~111 dirt
fill ~243 ~67 ~111 ~247 ~67 ~111 grass_block
fill ~248 ~60 ~111 ~253 ~64 ~111 stone
fill ~248 ~65 ~111 ~253 ~67 ~111 dirt
fill ~248 ~68 ~111 ~253 ~68 ~111 grass_block
fill ~254 ~60 ~111 ~255 ~63 ~111 stone
fill ~254 ~64 ~111 ~255 ~66 ~111 dirt
fill ~254 ~67 ~111 ~255 ~67 ~111 grass_block