fill ~96 ~60 ~64 ~103 ~63 ~64 stone
fill ~96 ~64 ~64 ~103 ~66 ~64 dirt
fill ~96 ~67 ~64 ~103 ~67 ~64 grass_block
fill ~104 ~60 ~64 ~106 ~62 ~64 stone
fill ~104 ~63 ~64 ~106 ~65 ~64 dirt
fill ~104 ~66 ~64 ~106 ~66 ~64 grass_block
fill ~107 ~60 ~64 ~111 ~63 ~64 stone
fill ~107 ~64 ~64 ~111 ~66 ~64 dirt
fill ~107 ~67 ~64 ~111 ~67 ~64 grass_block
fill ~96 ~60 ~65 ~104 ~63 ~65 stone
fill ~96 ~64 ~65 ~104 ~66 ~65 dirt
fill ~96 ~67 ~65 ~104 ~67 ~65 grass_block
fill ~105 ~60 ~65 ~106 ~62 ~65 stone
fill ~105 ~63 ~65 ~106 ~65 ~65 dirt
fill ~105 ~66 ~65 ~106 ~66 ~65 grass_block
fill ~107 ~60 ~65 ~111 ~63 ~65 stone
fill ~107 ~64 ~65 ~111 ~66 ~65 dirt
fill ~107 ~67 ~65 ~111 ~67 ~65 grass_block
fill ~96 ~60 ~66 ~105 ~63 ~66 stone
fill ~96 ~64 ~66 ~105 ~66 ~66 dirt
fill ~96 ~67 ~66 ~105 ~67 ~66 grass_block
fill ~106 ~60 ~66 ~107 ~62 ~66 stone
fill ~106 ~63 ~66 ~107 ~65 ~66 dirt
fill ~106 ~66 ~66 ~107 ~66 ~66 grass_block
fill ~108 ~60 ~66 ~111 ~63 ~66 stone
fill ~108 ~64 ~66 ~111 ~66 ~66 dirt
fill ~108 ~67 ~66 ~111 ~67 ~66 grass_block
fill ~96 ~60 ~67 ~107 ~63 ~67 stone
fill ~96 ~64 ~67 ~107 ~66 ~67 dirt
fill ~96 ~67 ~67 ~107 ~67 ~67 grass_block
fill ~108 ~60 ~67 ~108 ~62 ~67 stone
fill ~108 ~63 ~67 ~108 ~65 ~67 dirt
fill ~108 ~66 ~67 ~108 ~66 ~67 grass_block
fill ~109 ~60 ~67 ~111 ~63 ~67 stone
fill ~109 ~64 ~67 ~111 ~66 ~67 dirt
fill ~109 ~67 ~67 ~111 ~67 ~67 grass_block
fill ~96 ~60 ~68 ~108 ~63 ~68 stone
fill ~96 ~64 ~68 ~108 ~66 ~68 dirt
fill ~96 ~67 ~68 ~108 ~67 ~68 grass_block
fill ~109 ~60 ~68 ~110 ~62 ~68 stone
fill ~109 ~63 ~68 ~110 ~65 ~68 dirt
fill ~109 ~66 ~68 ~110 ~66 ~68 grass_block
fill ~111 ~60 ~68 ~111 ~63 ~68 stone
fill ~111 ~64 ~68 ~111 ~66 ~68 dirt
fill ~111 ~67 ~68 ~111 ~67 ~68 grass_block
fill ~96 ~60 ~69 ~96 ~64 ~69 stone
fill ~96 ~65 ~69 ~96 ~67 ~69 dirt
fill ~96 ~68 ~69 ~96 ~68 ~69 grass_block
fill ~97 ~60 ~69 ~100 ~63 ~69 stone
fill ~97 ~64 ~69 ~100 ~66 ~69 dirt
fill ~97 ~67 ~69 ~100 ~67 ~69 grass_block
fill ~101 ~60 ~69 ~101 ~62 ~69 stone
fill ~101 ~63 ~69 ~101 ~65 ~69 dirt
fill ~101 ~66 ~69 ~101 ~66 ~69 grass_block
fill ~102 ~60 ~69 ~108 ~63 ~69 stone
fill ~102 ~64 ~69 ~108 ~66 ~69 dirt
fill ~102 ~67 ~69 ~108 ~67 ~69 grass_block
fill ~109 ~60 ~69 ~111 ~62 ~69 stone
fill ~109 ~63 ~69 ~111 ~65 ~69 dirt
fill ~109 ~66 ~69 ~111 ~66 ~69 grass_block
fill ~96 ~60 ~70 ~97 ~64 ~70 stone
fill ~96 ~65 ~70 ~97 ~67 ~70 dirt
fill ~96 ~68 ~70 ~97 ~68 ~70 grass_block
fill ~98 ~60 ~70 ~103 ~63 ~70 stone
fill ~98 ~64 ~70 ~103 ~66 ~70 dirt
fill ~98 ~67 ~70 ~103 ~67 ~70 grass_block
fill ~104 ~60 ~70 ~104 ~62 ~70 stone
fill ~104 ~63 ~70 ~104 ~65 ~70 dirt
fill ~104 ~66 ~70 ~104 ~66 ~70 grass_block
fill ~105 ~60 ~70 ~108 ~63 ~70 stone
fill ~105 ~64 ~70 ~108 ~66 ~70 dirt
fill ~105 ~67 ~70 ~108 ~67 ~70 grass_block
fill ~109 ~60 ~70 ~110 ~62 ~70 stone
fill ~109 ~63 ~70 ~110 ~65 ~70 dirt
fill ~109 ~66 ~70 ~110 ~66 ~70 grass_block
fill ~111 ~60 ~70 ~111 ~63 ~70 stone
fill ~111 ~64 ~70 ~111 ~66 ~70 dirt
fill ~111 ~67 ~70 ~111 ~67 ~70 grass_block
fill ~96 ~60 ~71 ~96 ~65 ~71 stone
fill ~96 ~66 ~71 ~96 ~68 ~71 dirt
fill ~96 ~69 ~71 ~96 ~69 ~71 grass_block
fill ~97 ~60 ~71 ~100 ~64 ~71 stone
fill ~97 ~65 ~71 ~100 ~67 ~71 dirt
fill ~97 ~68 ~71 ~100 ~68 ~71 grass_block
fill ~101 ~60 ~71 ~109 ~63 ~71 stone
fill ~101 ~64 ~71 ~109 ~66 ~71 dirt
fill ~101 ~67 ~71 ~109 ~67 ~71 grass_block
fill ~110 ~60 ~71 ~111 ~62 ~71 stone
fill ~110 ~63 ~71 ~111 ~65 ~71 dirt
fill ~110 ~66 ~71 ~111 ~66 ~71 grass_block
fill ~96 ~60 ~72 ~100 ~65 ~72 stone
fill ~96 ~66 ~72 ~100 ~68 ~72 dirt
fill ~96 ~69 ~72 ~100 ~69 ~72 grass_block
fill ~101 ~60 ~72 ~103 ~64 ~72 stone
fill ~101 ~65 ~72 ~103 ~67 ~72 dirt
fill ~101 ~68 ~72 ~103 ~68 ~72 grass_block
fill ~104 ~60 ~72 ~108 ~63 ~72 stone
fill ~104 ~64 ~72 ~108 ~66 ~72 dirt
fill ~104 ~67 ~72 ~108 ~67 ~72 grass_block
fill ~109 ~60 ~72 ~111 ~62 ~72 stone
fill ~109 ~63 ~72 ~111 ~65 ~72 dirt
fill ~109 ~66 ~72 ~111 ~66 ~72 grass_block
fill ~96 ~60 ~73 ~99 ~66 ~73 stone
fill ~96 ~67 ~73 ~99 ~69 ~73 dirt
fill ~96 ~70 ~73 ~99 ~70 ~73 grass_block
fill ~100 ~60 ~73 ~102 ~65 ~73 stone
fill ~100 ~66 ~73 ~102 ~68 ~73 dirt
fill ~100 ~69 ~73 ~102 ~69 ~73 grass_block
fill ~103 ~60 ~73 ~105 ~64 ~73 stone
fill ~103 ~65 ~73 ~105 ~67 ~73 dirt
fill ~103 ~68 ~73 ~105 ~68 ~73 grass_block
fill ~106 ~60 ~73 ~111 ~63 ~73 stone
fill ~106 ~64 ~73 ~111 ~66 ~73 dirt
fill ~106 ~67 ~73 ~111 ~67 ~73 grass_block
fill ~96 ~60 ~74 ~100 ~66 ~74 stone
fill ~96 ~67 ~74 ~100 ~69 ~74 dirt
fill ~96 ~70 ~74 ~100 ~70 ~74 grass_block
fill ~101 ~60 ~74 ~103 ~65 ~74 stone
fill ~101 ~66 ~74 ~103 ~68 ~74 dirt
fill ~101 ~69 ~74 ~103 ~69 ~74 grass_block
fill ~104 ~60 ~74 ~108 ~64 ~74 stone
fill ~104 ~65 ~74 ~108 ~67 ~74 dirt
fill ~104 ~68 ~74 ~108 ~68 ~74 grass_block
fill ~109 ~60 ~74 ~111 ~63 ~74 stone
fill ~109 ~64 ~74 ~111 ~66 ~74 dirt
fill ~109 ~67 ~74 ~111 ~67 ~74 grass_block
fill ~96 ~60 ~75 ~101 ~66 ~75 stone
fill ~96 ~67 ~75 ~101 ~69 ~75 dirt
fill ~96 ~70 ~75 ~101 ~70 ~75 grass_block
fill ~102 ~60 ~75 ~104 ~65 ~75 stone
fill ~102 ~66 ~75 ~104 ~68 ~75 dirt
fill ~102 ~69 ~75 ~104 ~69 ~75 grass_block
fill ~105 ~60 ~75 ~109 ~64 ~75 stone
fill ~105 ~65 ~75 ~109 ~67 ~75 dirt
fill ~105 ~68 ~75 ~109 ~68 ~75 grass_block
fill ~110 ~60 ~75 ~111 ~63 ~75 stone
fill ~110 ~64 ~75 ~111 ~66 ~75 dirt
fill ~110 ~67 ~75 ~111 ~67 ~75 grass_block
fill ~96 ~60 ~76 ~96 ~65 ~76 stone
fill ~96 ~66 ~76 ~96 ~68 ~76 dirt
fill ~96 ~69 ~76 ~96 ~69 ~76 grass_block
fill ~97 ~60 ~76 ~102 ~66 ~76 stone
fill ~97 ~67 ~76 ~102 ~69 ~76 dirt
fill ~97 ~70 ~76 ~102 ~70 ~76 grass_block
fill ~103 ~60 ~76 ~105 ~65 ~76 stone
fill ~103 ~66 ~76 ~105 ~68 ~76 dirt
fill ~103 ~69 ~76 ~105 ~69 ~76 grass_block
fill ~106 ~60 ~76 ~110 ~64 ~76 stone
fill ~106 ~65 ~76 ~110 ~67 ~76 dirt
fill ~106 ~68 ~76 ~110 ~68 ~76 grass_block
fill ~111 ~60 ~76 ~111 ~63 ~76 stone
fill ~111 ~64 ~76 ~111 ~66 ~76 dirt
fill ~111 ~67 ~76 ~111 ~67 ~76 grass_block
fill ~96 ~60 ~77 ~98 ~65 ~77 stone
fill ~96 ~66 ~77 ~98 ~68 ~77 dirt
fill ~96 ~69 ~77 ~98 ~69 ~77 grass_block
fill ~99 ~60 ~77 ~103 ~66 ~77 stone
fill ~99 ~67 ~77 ~103 ~69 ~77 dirt
fill ~99 ~70 ~77 ~103 ~70 ~77 grass_block
fill ~104 ~60 ~77 ~106 ~65 ~77 stone
fill ~104 ~66 ~77 ~106 ~68 ~77 dirt
fill ~104 ~69 ~77 ~106 ~69 ~77 grass_block
fill ~107 ~60 ~77 ~110 ~64 ~77 stone
fill ~107 ~65 ~77 ~110 ~67 ~77 dirt
fill ~107 ~68 ~77 ~110 ~68 ~77 grass_block
fill ~111 ~60 ~77 ~111 ~63 ~77 stone
fill ~111 ~64 ~77 ~111 ~66 ~77 dirt
fill ~111 ~67 ~77 ~111 ~67 ~77 grass_block
fill ~96 ~60 ~78 ~99 ~65 ~78 stone
fill ~96 ~66 ~78 ~99 ~68 ~78 dirt
fill ~96 ~69 ~78 ~99 ~69 ~78 grass_block
fill ~100 ~60 ~78 ~104 ~66 ~78 stone
fill ~100 ~67 ~78 ~104 ~69 ~78 dirt
fill ~100 ~70 ~78 ~104 ~70 ~78 grass_block
fill ~105 ~60 ~78 ~107 ~65 ~78 stone
fill ~105 ~66 ~78 ~107 ~68 ~78 dirt
fill ~105 ~69 ~78 ~107 ~69 ~78 grass_block
fill ~108 ~60 ~78 ~110 ~64 ~78 stone
fill ~108 ~65 ~78 ~110 ~67 ~78 dirt
fill ~108 ~68 ~78 ~110 ~68 ~78 grass_block
fill ~111 ~60 ~78 ~111 ~63 ~78 stone
fill ~111 ~64 ~78 ~111 ~66 ~78 dirt
fill ~111 ~67 ~78 ~111 ~67 ~78 grass_block
fill ~96 ~60 ~79 ~102 ~65 ~79 stone
fill ~96 ~66 ~79 ~102 ~68 ~79 dirt
fill ~96 ~69 ~79 ~102 ~69 ~79 grass_block
fill ~103 ~60 ~79 ~105 ~66 ~79 stone
fill ~103 ~67 ~79 ~105 ~69 ~79 dirt
fill ~103 ~70 ~79 ~105 ~70 ~79 grass_block
fill ~106 ~60 ~79 ~108 ~65 ~79 stone
fill ~106 ~66 ~79 ~108 ~68 ~79 dirt
fill ~106 ~69 ~79 ~108 ~69 ~79 grass_block
fill ~109 ~60 ~79 ~111 ~64 ~79 stone
fill ~109 ~65 ~79 ~111 ~67 ~79 dirt
fill ~109 ~68 ~79 ~111 ~68 ~79 grass_block