fill ~464 ~60 ~48 ~464 ~61 ~48 stone
fill ~464 ~62 ~48 ~464 ~64 ~48 dirt
fill ~464 ~65 ~48 ~464 ~65 ~48 grass_block
fill ~465 ~60 ~48 ~467 ~62 ~48 stone
fill ~465 ~63 ~48 ~467 ~65 ~48 dirt
fill ~465 ~66 ~48 ~467 ~66 ~48 grass_block
fill ~468 ~60 ~48 ~469 ~63 ~48 stone
fill ~468 ~64 ~48 ~469 ~66 ~48 dirt
fill ~468 ~67 ~48 ~469 ~67 ~48 grass_block
fill ~464 ~60 ~49 ~467 ~62 ~49 stone
fill ~464 ~63 ~49 ~467 ~65 ~49 dirt
fill ~464 ~66 ~49 ~467 ~66 ~49 grass_block
fill ~468 ~60 ~49 ~468 ~63 ~49 stone
fill ~468 ~64 ~49 ~468 ~66 ~49 dirt
fill ~468 ~67 ~49 ~468 ~67 ~49 grass_block
fill ~469 ~60 ~49 ~469 ~64 ~49 stone
fill ~469 ~65 ~49 ~469 ~67 ~49 dirt
fill ~469 ~68 ~49 ~469 ~68 ~49 grass_block
fill ~464 ~60 ~50 ~466 ~62 ~50 stone
fill ~464 ~63 ~50 ~466 ~65 ~50 dirt
fill ~464 ~66 ~50 ~466 ~66 ~50 grass_block
fill ~467 ~60 ~50 ~469 ~63 ~50 stone
fill ~467 ~64 ~50 ~469 ~66 ~50 dirt
fill ~467 ~67 ~50 ~469 ~67 ~50 grass_block
fill ~464 ~60 ~51 ~464 ~62 ~51 stone
fill ~464 ~63 ~51 ~464 ~65 ~51 dirt
fill ~464 ~66 ~51 ~464 ~66 ~51 grass_block
fill ~465 ~60 ~51 ~468 ~63 ~51 stone
fill ~465 ~64 ~51 ~468 ~66 ~51 dirt
fill ~465 ~67 ~51 ~468 ~67 ~51 grass_block
fill ~469 ~60 ~51 ~469 ~64 ~51 stone
fill ~469 ~65 ~51 ~469 ~67 ~51 dirt
fill ~469 ~68 ~51 ~469 ~68 ~51 grass_block
fill ~464 ~60 ~52 ~464 ~62 ~52 stone
fill ~464 ~63 ~52 ~464 ~65 ~52 dirt
fill ~464 ~66 ~52 ~464 ~66 ~52 grass_block
fill ~465 ~60 ~52 ~467 ~63 ~52 stone
fill ~465 ~64 ~52 ~467 ~66 ~52 dirt
fill ~465 ~67 ~52 ~467 ~67 ~52 grass_block
fill ~468 ~60 ~52 ~469 ~64 ~52 stone
fill ~468 ~65 ~52 ~469 ~67 ~52 dirt
fill ~468 ~68 ~52 ~469 ~68 ~52 grass_block
fill ~464 ~60 ~53 ~466 ~63 ~53 stone
fill ~464 ~64 ~53 ~466 ~66 ~53 dirt
fill ~464 ~67 ~53 ~466 ~67 ~53 grass_block
fill ~467 ~60 ~53 ~468 ~64 ~53 stone
fill ~467 ~65 ~53 ~468 ~67 ~53 dirt
fill ~467 ~68 ~53 ~468 ~68 ~53 grass_block
fill ~469 ~60 ~53 ~469 ~65 ~53 stone
fill ~469 ~66 ~53 ~469 ~68 ~53 dirt
fill ~469 ~69 ~53 ~469 ~69 ~53 grass_block
fill ~464 ~60 ~54 ~464 ~63 ~54 stone
fill ~464 ~64 ~54 ~464 ~66 ~54 dirt
fill ~464 ~67 ~54 ~464 ~67 ~54 grass_block
fill ~465 ~60 ~54 ~467 ~64 ~54 stone
fill ~465 ~65 ~54 ~467 ~67 ~54 dirt
fill ~465 ~68 ~54 ~467 ~68 ~54 grass_block
fill ~468 ~60 ~54 ~469 ~65 ~54 stone
fill ~468 ~66 ~54 ~469 ~68 ~54 dirt
fill ~468 ~69 ~54 ~469 ~69 ~54 grass_block
fill ~464 ~60 ~55 ~465 ~64 ~55 stone
fill ~464 ~65 ~55 ~465 ~67 ~55 dirt
fill ~464 ~68 ~55 ~465 ~68 ~55 grass_block
fill ~466 ~60 ~55 ~468 ~65 ~55 stone
fill ~466 ~66 ~55 ~468 ~68 ~55 dirt
fill ~466 ~69 ~55 ~468 ~69 ~55 grass_block
fill ~469 ~60 ~55 ~469 ~66 ~55 stone
fill ~469 ~67 ~55 ~469 ~69 ~55 dirt
fill ~469 ~70 ~55 ~469 ~70 ~55 grass_block
fill ~464 ~60 ~56 ~464 ~64 ~56 stone
fill ~464 ~65 ~56 ~464 ~67 ~56 dirt
fill ~464 ~68 ~56 ~464 ~68 ~56 grass_block
fill ~465 ~60 ~56 ~468 ~65 ~56 stone
fill ~465 ~66 ~56 ~468 ~68 ~56 dirt
fill ~465 ~69 ~56 ~468 ~69 ~56 grass_block
fill ~469 ~60 ~56 ~469 ~66 ~56 stone
fill ~469 ~67 ~56 ~469 ~69 ~56 dirt
fill ~469 ~70 ~56 ~469 ~70 ~56 grass_block
fill ~464 ~60 ~57 ~464 ~64 ~57 stone
fill ~464 ~65 ~57 ~464 ~67 ~57 dirt
fill ~464 ~68 ~57 ~464 ~68 ~57 grass_block
fill ~465 ~60 ~57 ~468 ~65 ~57 stone
fill ~465 ~66 ~57 ~468 ~68 ~57 dirt
fill ~465 ~69 ~57 ~468 ~69 ~57 grass_block
fill ~469 ~60 ~57 ~469 ~66 ~57 stone
fill ~469 ~67 ~57 ~469 ~69 ~57 dirt
fill ~469 ~70 ~57 ~469 ~70 ~57 grass_block
fill ~464 ~60 ~58 ~464 ~64 ~58 stone
fill ~464 ~65 ~58 ~464 ~67 ~58 dirt
fill ~464 ~68 ~58 ~464 ~68 ~58 grass_block
fill ~465 ~60 ~58 ~469 ~65 ~58 stone
fill ~465 ~66 ~58 ~469 ~68 ~58 dirt
fill ~465 ~69 ~58 ~469 ~69 ~58 grass_block
fill ~464 ~60 ~59 ~464 ~64 ~59 stone
fill ~464 ~65 ~59 ~464 ~67 ~59 dirt
fill ~464 ~68 ~59 ~464 ~68 ~59 grass_block
fill ~465 ~60 ~59 ~468 ~65 ~59 stone
fill ~465 ~66 ~59 ~468 ~68 ~59 dirt
fill ~465 ~69 ~59 ~468 ~69 ~59 grass_block
fill ~469 ~60 ~59 ~469 ~66 ~59 stone
fill ~469 ~67 ~59 ~469 ~69 ~59 dirt
fill ~469 ~70 ~59 ~469 ~70 ~59 grass_block
fill ~464 ~60 ~60 ~469 ~65 ~60 stone
fill ~464 ~66 ~60 ~469 ~68 ~60 dirt
fill ~464 ~69 ~60 ~469 ~69 ~60 grass_block
fill ~464 ~60 ~61 ~469 ~65 ~61 stone
fill ~464 ~66 ~61 ~469 ~68 ~61 dirt
fill ~464 ~69 ~61 ~469 ~69 ~61 grass_block
fill ~464 ~60 ~62 ~464 ~64 ~62 stone
fill ~464 ~65 ~62 ~464 ~67 ~62 dirt
fill ~464 ~68 ~62 ~464 ~68 ~62 grass_block
fill ~465 ~60 ~62 ~469 ~65 ~62 stone
fill ~465 ~66 ~62 ~469 ~68 ~62 dirt
fill ~465 ~69 ~62 ~469 ~69 ~62 grass_block
fill ~464 ~60 ~63 ~469 ~65 ~63 stone
fill ~464 ~66 ~63 ~469 ~68 ~63 dirt
fill ~464 ~69 ~63 ~469 ~69 ~63 grass_block