fill ~320 ~60 ~80 ~329 ~61 ~80 stone
fill ~320 ~62 ~80 ~329 ~64 ~80 dirt
fill ~320 ~65 ~80 ~329 ~65 ~80 grass_block
fill ~330 ~60 ~80 ~334 ~62 ~80 stone
fill ~330 ~63 ~80 ~334 ~65 ~80 dirt
fill ~330 ~66 ~80 ~334 ~66 ~80 grass_block
fill ~335 ~60 ~80 ~335 ~63 ~80 stone
fill ~335 ~64 ~80 ~335 ~66 ~80 dirt
fill ~335 ~67 ~80 ~335 ~67 ~80 grass_block
fill ~320 ~60 ~81 ~333 ~61 ~81 stone
fill ~320 ~62 ~81 ~333 ~64 ~81 dirt
fill ~320 ~65 ~81 ~333 ~65 ~81 grass_block
fill ~334 ~60 ~81 ~334 ~62 ~81 stone
fill ~334 ~63 ~81 ~334 ~65 ~81 dirt
fill ~334 ~66 ~81 ~334 ~66 ~81 grass_block
fill ~335 ~60 ~81 ~335 ~63 ~81 stone
fill ~335 ~64 ~81 ~335 ~66 ~81 dirt
fill ~335 ~67 ~81 ~335 ~67 ~81 grass_block
fill ~320 ~60 ~82 ~333 ~61 ~82 stone
fill ~320 ~62 ~82 ~333 ~64 ~82 dirt
fill ~320 ~65 ~82 ~333 ~65 ~82 grass_block
fill ~334 ~60 ~82 ~334 ~62 ~82 stone
fill ~334 ~63 ~82 ~334 ~65 ~82 dirt
fill ~334 ~66 ~82 ~334 ~66 ~82 grass_block
fill ~335 ~60 ~82 ~335 ~63 ~82 stone
fill ~335 ~64 ~82 ~335 ~66 ~82 dirt
fill ~335 ~67 ~82 ~335 ~67 ~82 grass_block
fill ~320 ~60 ~83 ~330 ~61 ~83 stone
fill ~320 ~62 ~83 ~330 ~64 ~83 dirt
fill ~320 ~65 ~83 ~330 ~65 ~83 grass_block
fill ~331 ~60 ~83 ~333 ~62 ~83 stone
fill ~331 ~63 ~83 ~333 ~65 ~83 dirt
fill ~331 ~66 ~83 ~333 ~66 ~83 grass_block
fill ~334 ~60 ~83 ~335 ~63 ~83 stone
fill ~334 ~64 ~83 ~335 ~66 ~83 dirt
fill ~334 ~67 ~83 ~335 ~67 ~83 grass_block
fill ~320 ~60 ~84 ~328 ~61 ~84 stone
fill ~320 ~62 ~84 ~328 ~64 ~84 dirt
fill ~320 ~65 ~84 ~328 ~65 ~84 grass_block
fill ~329 ~60 ~84 ~333 ~62 ~84 stone
fill ~329 ~63 ~84 ~333 ~65 ~84 dirt
fill ~329 ~66 ~84 ~333 ~66 ~84 grass_block
fill ~334 ~60 ~84 ~335 ~63 ~84 stone
fill ~334 ~64 ~84 ~335 ~66 ~84 dirt
fill ~334 ~67 ~84 ~335 ~67 ~84 grass_block
fill ~320 ~60 ~85 ~320 ~61 ~85 stone
fill ~320 ~62 ~85 ~320 ~64 ~85 dirt
fill ~320 ~65 ~85 ~320 ~65 ~85 grass_block
fill ~321 ~60 ~85 ~321 ~60 ~85 stone
fill ~321 ~61 ~85 ~321 ~63 ~85 dirt
fill ~321 ~64 ~85 ~321 ~64 ~85 grass_block
fill ~322 ~60 ~85 ~328 ~61 ~85 stone
fill ~322 ~62 ~85 ~328 ~64 ~85 dirt
fill ~322 ~65 ~85 ~328 ~65 ~85 grass_block
fill ~329 ~60 ~85 ~333 ~62 ~85 stone
fill ~329 ~63 ~85 ~333 ~65 ~85 dirt
fill ~329 ~66 ~85 ~333 ~66 ~85 grass_block
fill ~334 ~60 ~85 ~335 ~63 ~85 stone
fill ~334 ~64 ~85 ~335 ~66 ~85 dirt
fill ~334 ~67 ~85 ~335 ~67 ~85 grass_block
fill ~320 ~60 ~86 ~328 ~61 ~86 stone
fill ~320 ~62 ~86 ~328 ~64 ~86 dirt
fill ~320 ~65 ~86 ~328 ~65 ~86 grass_block
fill ~329 ~60 ~86 ~333 ~62 ~86 stone
fill ~329 ~63 ~86 ~333 ~65 ~86 dirt
fill ~329 ~66 ~86 ~333 ~66 ~86 grass_block
fill ~334 ~60 ~86 ~335 ~63 ~86 stone
fill ~334 ~64 ~86 ~335 ~66 ~86 dirt
fill ~334 ~67 ~86 ~335 ~67 ~86 grass_block
fill ~320 ~60 ~87 ~322 ~61 ~87 stone
fill ~320 ~62 ~87 ~322 ~64 ~87 dirt
fill ~320 ~65 ~87 ~322 ~65 ~87 grass_block
fill ~323 ~60 ~87 ~323 ~60 ~87 stone
fill ~323 ~61 ~87 ~323 ~63 ~87 dirt
fill ~323 ~64 ~87 ~323 ~64 ~87 grass_block
fill ~324 ~60 ~87 ~329 ~61 ~87 stone
fill ~324 ~62 ~87 ~329 ~64 ~87 dirt
fill ~324 ~65 ~87 ~329 ~65 ~87 grass_block
fill ~330 ~60 ~87 ~334 ~62 ~87 stone
fill ~330 ~63 ~87 ~334 ~65 ~87 dirt
fill ~330 ~66 ~87 ~334 ~66 ~87 grass_block
fill ~335 ~60 ~87 ~335 ~63 ~87 stone
fill ~335 ~64 ~87 ~335 ~66 ~87 dirt
fill ~335 ~67 ~87 ~335 ~67 ~87 grass_block
fill ~320 ~60 ~88 ~320 ~61 ~88 stone
fill ~320 ~62 ~88 ~320 ~64 ~88 dirt
fill ~320 ~65 ~88 ~320 ~65 ~88 grass_block
fill ~321 ~60 ~88 ~324 ~60 ~88 stone
fill ~321 ~61 ~88 ~324 ~63 ~88 dirt
fill ~321 ~64 ~88 ~324 ~64 ~88 grass_block
fill ~325 ~60 ~88 ~330 ~61 ~88 stone
fill ~325 ~62 ~88 ~330 ~64 ~88 dirt
fill ~325 ~65 ~88 ~330 ~65 ~88 grass_block
fill ~331 ~60 ~88 ~335 ~62 ~88 stone
fill ~331 ~63 ~88 ~335 ~65 ~88 dirt
fill ~331 ~66 ~88 ~335 ~66 ~88 grass_block
fill ~320 ~60 ~89 ~321 ~60 ~89 stone
fill ~320 ~61 ~89 ~321 ~63 ~89 dirt
fill ~320 ~64 ~89 ~321 ~64 ~89 grass_block
fill ~322 ~60 ~89 ~332 ~61 ~89 stone
fill ~322 ~62 ~89 ~332 ~64 ~89 dirt
fill ~322 ~65 ~89 ~332 ~65 ~89 grass_block
fill ~333 ~60 ~89 ~335 ~62 ~89 stone
fill ~333 ~63 ~89 ~335 ~65 ~89 dirt
fill ~333 ~66 ~89 ~335 ~66 ~89 grass_block
fill ~320 ~60 ~90 ~320 ~61 ~90 stone
fill ~320 ~62 ~90 ~320 ~64 ~90 dirt
fill ~320 ~65 ~90 ~320 ~65 ~90 grass_block
fill ~321 ~60 ~90 ~325 ~60 ~90 stone
fill ~321 ~61 ~90 ~325 ~63 ~90 dirt
fill ~321 ~64 ~90 ~325 ~64 ~90 grass_block
fill ~326 ~60 ~90 ~326 ~61 ~90 stone
fill ~326 ~62 ~90 ~326 ~64 ~90 dirt
fill ~326 ~65 ~90 ~326 ~65 ~90 grass_block
fill ~327 ~60 ~90 ~328 ~60 ~90 stone
fill ~327 ~61 ~90 ~328 ~63 ~90 dirt
fill ~327 ~64 ~90 ~328 ~64 ~90 grass_block
fill ~329 ~60 ~90 ~335 ~61 ~90 stone
fill ~329 ~62 ~90 ~335 ~64 ~90 dirt
fill ~329 ~65 ~90 ~335 ~65 ~90 grass_block
fill ~320 ~60 ~91 ~320 ~61 ~91 stone
fill ~320 ~62 ~91 ~320 ~64 ~91 dirt
fill ~320 ~65 ~91 ~320 ~65 ~91 grass_block
fill ~321 ~60 ~91 ~323 ~60 ~91 stone
fill ~321 ~61 ~91 ~323 ~63 ~91 dirt
fill ~321 ~64 ~91 ~323 ~64 ~91 grass_block
fill ~324 ~60 ~91 ~324 ~61 ~91 stone
fill ~324 ~62 ~91 ~324 ~64 ~91 dirt
fill ~324 ~65 ~91 ~324 ~65 ~91 grass_block
fill ~325 ~60 ~91 ~330 ~60 ~91 stone
fill ~325 ~61 ~91 ~330 ~63 ~91 dirt
fill ~325 ~64 ~91 ~330 ~64 ~91 grass_block
fill ~331 ~60 ~91 ~335 ~61 ~91 stone
fill ~331 ~62 ~91 ~335 ~64 ~91 dirt
fill ~331 ~65 ~91 ~335 ~65 ~91 grass_block
fill ~320 ~60 ~92 ~320 ~61 ~92 stone
fill ~320 ~62 ~92 ~320 ~64 ~92 dirt
fill ~320 ~65 ~92 ~320 ~65 ~92 grass_block
fill ~321 ~60 ~92 ~321 ~60 ~92 stone
fill ~321 ~61 ~92 ~321 ~63 ~92 dirt
fill ~321 ~64 ~92 ~321 ~64 ~92 grass_block
fill ~322 ~60 ~92 ~323 ~61 ~92 stone
fill ~322 ~62 ~92 ~323 ~64 ~92 dirt
fill ~322 ~65 ~92 ~323 ~65 ~92 grass_block
fill ~324 ~60 ~92 ~331 ~60 ~92 stone
fill ~324 ~61 ~92 ~331 ~63 ~92 dirt
fill ~324 ~64 ~92 ~331 ~64 ~92 grass_block
fill ~332 ~60 ~92 ~335 ~61 ~92 stone
fill ~332 ~62 ~92 ~335 ~64 ~92 dirt
fill ~332 ~65 ~92 ~335 ~65 ~92 grass_block
fill ~320 ~60 ~93 ~322 ~61 ~93 stone
fill ~320 ~62 ~93 ~322 ~64 ~93 dirt
fill ~320 ~65 ~93 ~322 ~65 ~93 grass_block
fill ~323 ~60 ~93 ~323 ~60 ~93 stone
fill ~323 ~61 ~93 ~323 ~63 ~93 dirt
fill ~323 ~64 ~93 ~323 ~64 ~93 grass_block
fill ~324 ~60 ~93 ~324 ~61 ~93 stone
fill ~324 ~62 ~93 ~324 ~64 ~93 dirt
fill ~324 ~65 ~93 ~324 ~65 ~93 grass_block
fill ~325 ~60 ~93 ~332 ~60 ~93 stone
fill ~325 ~61 ~93 ~332 ~63 ~93 dirt
fill ~325 ~64 ~93 ~332 ~64 ~93 grass_block
fill ~333 ~60 ~93 ~333 ~61 ~93 stone
fill ~333 ~62 ~93 ~333 ~64 ~93 dirt
fill ~333 ~65 ~93 ~333 ~65 ~93 grass_block
fill ~334 ~60 ~93 ~334 ~60 ~93 stone
fill ~334 ~61 ~93 ~334 ~63 ~93 dirt
fill ~334 ~64 ~93 ~334 ~64 ~93 grass_block
fill ~335 ~60 ~93 ~335 ~61 ~93 stone
fill ~335 ~62 ~93 ~335 ~64 ~93 dirt
fill ~335 ~65 ~93 ~335 ~65 ~93 grass_block
fill ~320 ~60 ~94 ~323 ~61 ~94 stone
fill ~320 ~62 ~94 ~323 ~64 ~94 dirt
fill ~320 ~65 ~94 ~323 ~65 ~94 grass_block
fill ~324 ~60 ~94 ~333 ~60 ~94 stone
fill ~324 ~61 ~94 ~333 ~63 ~94 dirt
fill ~324 ~64 ~94 ~333 ~64 ~94 grass_block
fill ~334 ~60 ~94 ~334 ~61 ~94 stone
fill ~334 ~62 ~94 ~334 ~64 ~94 dirt
fill ~334 ~65 ~94 ~334 ~65 ~94 grass_block
fill ~335 ~60 ~94 ~335 ~60 ~94 stone
fill ~335 ~61 ~94 ~335 ~63 ~94 dirt
fill ~335 ~64 ~94 ~335 ~64 ~94 grass_block
fill ~320 ~60 ~95 ~323 ~61 ~95 stone
fill ~320 ~62 ~95 ~323 ~64 ~95 dirt
fill ~320 ~65 ~95 ~323 ~65 ~95 grass_block
fill ~324 ~60 ~95 ~335 ~60 ~95 stone
fill ~324 ~61 ~95 ~335 ~63 ~95 dirt
fill ~324 ~64 ~95 ~335 ~64 ~95 grass_block