fill ~208 ~60 ~64 ~208 ~66 ~64 stone
fill ~208 ~67 ~64 ~208 ~69 ~64 dirt
fill ~208 ~70 ~64 ~208 ~70 ~64 grass_block
fill ~209 ~60 ~64 ~210 ~65 ~64 stone
fill ~209 ~66 ~64 ~210 ~68 ~64 dirt
fill ~209 ~69 ~64 ~210 ~69 ~64 grass_block
fill ~211 ~60 ~64 ~214 ~64 ~64 stone
fill ~211 ~65 ~64 ~214 ~67 ~64 dirt
fill ~211 ~68 ~64 ~214 ~68 ~64 grass_block
fill ~215 ~60 ~64 ~220 ~63 ~64 stone
fill ~215 ~64 ~64 ~220 ~66 ~64 dirt
fill ~215 ~67 ~64 ~220 ~67 ~64 grass_block
fill ~221 ~60 ~64 ~222 ~62 ~64 stone
fill ~221 ~63 ~64 ~222 ~65 ~64 dirt
fill ~221 ~66 ~64 ~222 ~66 ~64 grass_block
fill ~223 ~60 ~64 ~223 ~63 ~64 stone
fill ~223 ~64 ~64 ~223 ~66 ~64 dirt
fill ~223 ~67 ~64 ~223 ~67 ~64 grass_block
fill ~208 ~60 ~65 ~209 ~66 ~65 stone
fill ~208 ~67 ~65 ~209 ~69 ~65 dirt
fill ~208 ~70 ~65 ~209 ~70 ~65 grass_block
fill ~210 ~60 ~65 ~211 ~65 ~65 stone
fill ~210 ~66 ~65 ~211 ~68 ~65 dirt
fill ~210 ~69 ~65 ~211 ~69 ~65 grass_block
fill ~212 ~60 ~65 ~215 ~64 ~65 stone
fill ~212 ~65 ~65 ~215 ~67 ~65 dirt
fill ~212 ~68 ~65 ~215 ~68 ~65 grass_block
fill ~216 ~60 ~65 ~220 ~63 ~65 stone
fill ~216 ~64 ~65 ~220 ~66 ~65 dirt
fill ~216 ~67 ~65 ~220 ~67 ~65 grass_block
fill ~221 ~60 ~65 ~222 ~62 ~65 stone
fill ~221 ~63 ~65 ~222 ~65 ~65 dirt
fill ~221 ~66 ~65 ~222 ~66 ~65 grass_block
fill ~223 ~60 ~65 ~223 ~63 ~65 stone
fill ~223 ~64 ~65 ~223 ~66 ~65 dirt
fill ~223 ~67 ~65 ~223 ~67 ~65 grass_block
fill ~208 ~60 ~66 ~210 ~66 ~66 stone
fill ~208 ~67 ~66 ~210 ~69 ~66 dirt
fill ~208 ~70 ~66 ~210 ~70 ~66 grass_block
fill ~211 ~60 ~66 ~213 ~65 ~66 stone
fill ~211 ~66 ~66 ~213 ~68 ~66 dirt
fill ~211 ~69 ~66 ~213 ~69 ~66 grass_block
fill ~214 ~60 ~66 ~216 ~64 ~66 stone
fill ~214 ~65 ~66 ~216 ~67 ~66 dirt
fill ~214 ~68 ~66 ~216 ~68 ~66 grass_block
fill ~217 ~60 ~66 ~223 ~63 ~66 stone
fill ~217 ~64 ~66 ~223 ~66 ~66 dirt
fill ~217 ~67 ~66 ~223 ~67 ~66 grass_block
fill ~208 ~60 ~67 ~210 ~66 ~67 stone
fill ~208 ~67 ~67 ~210 ~69 ~67 dirt
fill ~208 ~70 ~67 ~210 ~70 ~67 grass_block
fill ~211 ~60 ~67 ~214 ~65 ~67 stone
fill ~211 ~66 ~67 ~214 ~68 ~67 dirt
fill ~211 ~69 ~67 ~214 ~69 ~67 grass_block
fill ~215 ~60 ~67 ~217 ~64 ~67 stone
fill ~215 ~65 ~67 ~217 ~67 ~67 dirt
fill ~215 ~68 ~67 ~217 ~68 ~67 grass_block
fill ~218 ~60 ~67 ~223 ~63 ~67 stone
fill ~218 ~64 ~67 ~223 ~66 ~67 dirt
fill ~218 ~67 ~67 ~223 ~67 ~67 grass_block
fill ~208 ~60 ~68 ~210 ~66 ~68 stone
fill ~208 ~67 ~68 ~210 ~69 ~68 dirt
fill ~208 ~70 ~68 ~210 ~70 ~68 grass_block
fill ~211 ~60 ~68 ~215 ~65 ~68 stone
fill ~211 ~66 ~68 ~215 ~68 ~68 dirt
fill ~211 ~69 ~68 ~215 ~69 ~68 grass_block
fill ~216 ~60 ~68 ~218 ~64 ~68 stone
fill ~216 ~65 ~68 ~218 ~67 ~68 dirt
fill ~216 ~68 ~68 ~218 ~68 ~68 grass_block
fill ~219 ~60 ~68 ~223 ~63 ~68 stone
fill ~219 ~64 ~68 ~223 ~66 ~68 dirt
fill ~219 ~67 ~68 ~223 ~67 ~68 grass_block
fill ~208 ~60 ~69 ~209 ~66 ~69 stone
fill ~208 ~67 ~69 ~209 ~69 ~69 dirt
fill ~208 ~70 ~69 ~209 ~70 ~69 grass_block
fill ~210 ~60 ~69 ~215 ~65 ~69 stone
fill ~210 ~66 ~69 ~215 ~68 ~69 dirt
fill ~210 ~69 ~69 ~215 ~69 ~69 grass_block
fill ~216 ~60 ~69 ~218 ~64 ~69 stone
fill ~216 ~65 ~69 ~218 ~67 ~69 dirt
fill ~216 ~68 ~69 ~218 ~68 ~69 grass_block
fill ~219 ~60 ~69 ~223 ~63 ~69 stone
fill ~219 ~64 ~69 ~223 ~66 ~69 dirt
fill ~219 ~67 ~69 ~223 ~67 ~69 grass_block
fill ~208 ~60 ~70 ~208 ~66 ~70 stone
fill ~208 ~67 ~70 ~208 ~69 ~70 dirt
fill ~208 ~70 ~70 ~208 ~70 ~70 grass_block
fill ~209 ~60 ~70 ~211 ~65 ~70 stone
fill ~209 ~66 ~70 ~211 ~68 ~70 dirt
fill ~209 ~69 ~70 ~211 ~69 ~70 grass_block
fill ~212 ~60 ~70 ~218 ~64 ~70 stone
fill ~212 ~65 ~70 ~218 ~67 ~70 dirt
fill ~212 ~68 ~70 ~218 ~68 ~70 grass_block
fill ~219 ~60 ~70 ~222 ~63 ~70 stone
fill ~219 ~64 ~70 ~222 ~66 ~70 dirt
fill ~219 ~67 ~70 ~222 ~67 ~70 grass_block
fill ~223 ~60 ~70 ~223 ~64 ~70 stone
fill ~223 ~65 ~70 ~223 ~67 ~70 dirt
fill ~223 ~68 ~70 ~223 ~68 ~70 grass_block
fill ~208 ~60 ~71 ~208 ~66 ~71 stone
fill ~208 ~67 ~71 ~208 ~69 ~71 dirt
fill ~208 ~70 ~71 ~208 ~70 ~71 grass_block
fill ~209 ~60 ~71 ~210 ~65 ~71 stone
fill ~209 ~66 ~71 ~210 ~68 ~71 dirt
fill ~209 ~69 ~71 ~210 ~69 ~71 grass_block
fill ~211 ~60 ~71 ~216 ~64 ~71 stone
fill ~211 ~65 ~71 ~216 ~67 ~71 dirt
fill ~211 ~68 ~71 ~216 ~68 ~71 grass_block
fill ~217 ~60 ~71 ~222 ~63 ~71 stone
fill ~217 ~64 ~71 ~222 ~66 ~71 dirt
fill ~217 ~67 ~71 ~222 ~67 ~71 grass_block
fill ~223 ~60 ~71 ~223 ~64 ~71 stone
fill ~223 ~65 ~71 ~223 ~67 ~71 dirt
fill ~223 ~68 ~71 ~223 ~68 ~71 grass_block
fill ~208 ~60 ~72 ~208 ~66 ~72 stone
fill ~208 ~67 ~72 ~208 ~69 ~72 dirt
fill ~208 ~70 ~72 ~208 ~70 ~72 grass_block
fill ~209 ~60 ~72 ~212 ~65 ~72 stone
fill ~209 ~66 ~72 ~212 ~68 ~72 dirt
fill ~209 ~69 ~72 ~212 ~69 ~72 grass_block
fill ~213 ~60 ~72 ~216 ~64 ~72 stone
fill ~213 ~65 ~72 ~216 ~67 ~72 dirt
fill ~213 ~68 ~72 ~216 ~68 ~72 grass_block
fill ~217 ~60 ~72 ~221 ~63 ~72 stone
fill ~217 ~64 ~72 ~221 ~66 ~72 dirt
fill ~217 ~67 ~72 ~221 ~67 ~72 grass_block
fill ~222 ~60 ~72 ~223 ~64 ~72 stone
fill ~222 ~65 ~72 ~223 ~67 ~72 dirt
fill ~222 ~68 ~72 ~223 ~68 ~72 grass_block
fill ~208 ~60 ~73 ~208 ~67 ~73 stone
fill ~208 ~68 ~73 ~208 ~70 ~73 dirt
fill ~208 ~71 ~73 ~208 ~71 ~73 grass_block
fill ~209 ~60 ~73 ~210 ~66 ~73 stone
fill ~209 ~67 ~73 ~210 ~69 ~73 dirt
fill ~209 ~70 ~73 ~210 ~70 ~73 grass_block
fill ~211 ~60 ~73 ~213 ~65 ~73 stone
fill ~211 ~66 ~73 ~213 ~68 ~73 dirt
fill ~211 ~69 ~73 ~213 ~69 ~73 grass_block
fill ~214 ~60 ~73 ~217 ~64 ~73 stone
fill ~214 ~65 ~73 ~217 ~67 ~73 dirt
fill ~214 ~68 ~73 ~217 ~68 ~73 grass_block
fill ~218 ~60 ~73 ~219 ~63 ~73 stone
fill ~218 ~64 ~73 ~219 ~66 ~73 dirt
fill ~218 ~67 ~73 ~219 ~67 ~73 grass_block
fill ~220 ~60 ~73 ~220 ~64 ~73 stone
fill ~220 ~65 ~73 ~220 ~67 ~73 dirt
fill ~220 ~68 ~73 ~220 ~68 ~73 grass_block
fill ~221 ~60 ~73 ~221 ~63 ~73 stone
fill ~221 ~64 ~73 ~221 ~66 ~73 dirt
fill ~221 ~67 ~73 ~221 ~67 ~73 grass_block
fill ~222 ~60 ~73 ~223 ~64 ~73 stone
fill ~222 ~65 ~73 ~223 ~67 ~73 dirt
fill ~222 ~68 ~73 ~223 ~68 ~73 grass_block
fill ~208 ~60 ~74 ~210 ~67 ~74 stone
fill ~208 ~68 ~74 ~210 ~70 ~74 dirt
fill ~208 ~71 ~74 ~210 ~71 ~74 grass_block
fill ~211 ~60 ~74 ~211 ~66 ~74 stone
fill ~211 ~67 ~74 ~211 ~69 ~74 dirt
fill ~211 ~70 ~74 ~211 ~70 ~74 grass_block
fill ~212 ~60 ~74 ~215 ~65 ~74 stone
fill ~212 ~66 ~74 ~215 ~68 ~74 dirt
fill ~212 ~69 ~74 ~215 ~69 ~74 grass_block
fill ~216 ~60 ~74 ~223 ~64 ~74 stone
fill ~216 ~65 ~74 ~223 ~67 ~74 dirt
fill ~216 ~68 ~74 ~223 ~68 ~74 grass_block
fill ~208 ~60 ~75 ~211 ~67 ~75 stone
fill ~208 ~68 ~75 ~211 ~70 ~75 dirt
fill ~208 ~71 ~75 ~211 ~71 ~75 grass_block
fill ~212 ~60 ~75 ~212 ~66 ~75 stone
fill ~212 ~67 ~75 ~212 ~69 ~75 dirt
fill ~212 ~70 ~75 ~212 ~70 ~75 grass_block
fill ~213 ~60 ~75 ~215 ~65 ~75 stone
fill ~213 ~66 ~75 ~215 ~68 ~75 dirt
fill ~213 ~69 ~75 ~215 ~69 ~75 grass_block
fill ~216 ~60 ~75 ~218 ~64 ~75 stone
fill ~216 ~65 ~75 ~218 ~67 ~75 dirt
fill ~216 ~68 ~75 ~218 ~68 ~75 grass_block
fill ~219 ~60 ~75 ~219 ~65 ~75 stone
fill ~219 ~66 ~75 ~219 ~68 ~75 dirt
fill ~219 ~69 ~75 ~219 ~69 ~75 grass_block
fill ~220 ~60 ~75 ~223 ~64 ~75 stone
fill ~220 ~65 ~75 ~223 ~67 ~75 dirt
fill ~220 ~68 ~75 ~223 ~68 ~75 grass_block
fill ~208 ~60 ~76 ~211 ~67 ~76 stone
fill ~208 ~68 ~76 ~211 ~70 ~76 dirt
fill ~208 ~71 ~76 ~211 ~71 ~76 grass_block
fill ~212 ~60 ~76 ~213 ~66 ~76 stone
fill ~212 ~67 ~76 ~213 ~69 ~76 dirt
fill ~212 ~70 ~76 ~213 ~70 ~76 grass_block
fill ~214 ~60 ~76 ~221 ~65 ~76 stone
fill ~214 ~66 ~76 ~221 ~68 ~76 dirt
fill ~214 ~69 ~76 ~221 ~69 ~76 grass_block
fill ~222 ~60 ~76 ~223 ~64 ~76 stone
fill ~222 ~65 ~76 ~223 ~67 ~76 dirt
fill ~222 ~68 ~76 ~223 ~68 ~76 grass_block
fill ~208 ~60 ~77 ~212 ~67 ~77 stone
fill ~208 ~68 ~77 ~212 ~70 ~77 dirt
fill ~208 ~71 ~77 ~212 ~71 ~77 grass_block
fill ~213 ~60 ~77 ~213 ~66 ~77 stone
fill ~213 ~67 ~77 ~213 ~69 ~77 dirt
fill ~213 ~70 ~77 ~213 ~70 ~77 grass_block
fill ~214 ~60 ~77 ~217 ~65 ~77 stone
fill ~214 ~66 ~77 ~217 ~68 ~77 dirt
fill ~214 ~69 ~77 ~217 ~69 ~77 grass_block
fill ~218 ~60 ~77 ~219 ~66 ~77 stone
fill ~218 ~67 ~77 ~219 ~69 ~77 dirt
fill ~218 ~70 ~77 ~219 ~70 ~77 grass_block
fill ~220 ~60 ~77 ~223 ~65 ~77 stone
fill ~220 ~66 ~77 ~223 ~68 ~77 dirt
fill ~220 ~69 ~77 ~223 ~69 ~77 grass_block
fill ~208 ~60 ~78 ~208 ~66 ~78 stone
fill ~208 ~67 ~78 ~208 ~69 ~78 dirt
fill ~208 ~70 ~78 ~208 ~70 ~78 grass_block
fill ~209 ~60 ~78 ~213 ~67 ~78 stone
fill ~209 ~68 ~78 ~213 ~70 ~78 dirt
fill ~209 ~71 ~78 ~213 ~71 ~78 grass_block
fill ~214 ~60 ~78 ~214 ~66 ~78 stone
fill ~214 ~67 ~78 ~214 ~69 ~78 dirt
fill ~214 ~70 ~78 ~214 ~70 ~78 grass_block
fill ~215 ~60 ~78 ~216 ~65 ~78 stone
fill ~215 ~66 ~78 ~216 ~68 ~78 dirt
fill ~215 ~69 ~78 ~216 ~69 ~78 grass_block
fill ~217 ~60 ~78 ~217 ~66 ~78 stone
fill ~217 ~67 ~78 ~217 ~69 ~78 dirt
fill ~217 ~70 ~78 ~217 ~70 ~78 grass_block
fill ~218 ~60 ~78 ~218 ~67 ~78 stone
fill ~218 ~68 ~78 ~218 ~70 ~78 dirt
fill ~218 ~71 ~78 ~218 ~71 ~78 grass_block
fill ~219 ~60 ~78 ~222 ~66 ~78 stone
fill ~219 ~67 ~78 ~222 ~69 ~78 dirt
fill ~219 ~70 ~78 ~222 ~70 ~78 grass_block
fill ~223 ~60 ~78 ~223 ~65 ~78 stone
fill ~223 ~66 ~78 ~223 ~68 ~78 dirt
fill ~223 ~69 ~78 ~223 ~69 ~78 grass_block
fill ~208 ~60 ~79 ~210 ~66 ~79 stone
fill ~208 ~67 ~79 ~210 ~69 ~79 dirt
fill ~208 ~70 ~79 ~210 ~70 ~79 grass_block
fill ~211 ~60 ~79 ~213 ~67 ~79 stone
fill ~211 ~68 ~79 ~213 ~70 ~79 dirt
fill ~211 ~71 ~79 ~213 ~71 ~79 grass_block
fill ~214 ~60 ~79 ~217 ~66 ~79 stone
fill ~214 ~67 ~79 ~217 ~69 ~79 dirt
fill ~214 ~70 ~79 ~217 ~70 ~79 grass_block
fill ~218 ~60 ~79 ~221 ~67 ~79 stone
fill ~218 ~68 ~79 ~221 ~70 ~79 dirt
fill ~218 ~71 ~79 ~221 ~71 ~79 grass_block
fill ~222 ~60 ~79 ~223 ~66 ~79 stone
fill ~222 ~67 ~79 ~223 ~69 ~79 dirt
fill ~222 ~70 ~79 ~223 ~70 ~79 grass_block