fill ~256 ~60 ~96 ~259 ~65 ~96 stone
fill ~256 ~66 ~96 ~259 ~68 ~96 dirt
fill ~256 ~69 ~96 ~259 ~69 ~96 grass_block
fill ~260 ~60 ~96 ~261 ~66 ~96 stone
fill ~260 ~67 ~96 ~261 ~69 ~96 dirt
fill ~260 ~70 ~96 ~261 ~70 ~96 grass_block
fill ~262 ~60 ~96 ~271 ~65 ~96 stone
fill ~262 ~66 ~96 ~271 ~68 ~96 dirt
fill ~262 ~69 ~96 ~271 ~69 ~96 grass_block
fill ~256 ~60 ~97 ~264 ~65 ~97 stone
fill ~256 ~66 ~97 ~264 ~68 ~97 dirt
fill ~256 ~69 ~97 ~264 ~69 ~97 grass_block
fill ~265 ~60 ~97 ~266 ~64 ~97 stone
fill ~265 ~65 ~97 ~266 ~67 ~97 dirt
fill ~265 ~68 ~97 ~266 ~68 ~97 grass_block
fill ~267 ~60 ~97 ~271 ~65 ~97 stone
fill ~267 ~66 ~97 ~271 ~68 ~97 dirt
fill ~267 ~69 ~97 ~271 ~69 ~97 grass_block
fill ~256 ~60 ~98 ~256 ~64 ~98 stone
fill ~256 ~65 ~98 ~256 ~67 ~98 dirt
fill ~256 ~68 ~98 ~256 ~68 ~98 grass_block
fill ~257 ~60 ~98 ~263 ~65 ~98 stone
fill ~257 ~66 ~98 ~263 ~68 ~98 dirt
fill ~257 ~69 ~98 ~263 ~69 ~98 grass_block
fill ~264 ~60 ~98 ~267 ~64 ~98 stone
fill ~264 ~65 ~98 ~267 ~67 ~98 dirt
fill ~264 ~68 ~98 ~267 ~68 ~98 grass_block
fill ~268 ~60 ~98 ~269 ~65 ~98 stone
fill ~268 ~66 ~98 ~269 ~68 ~98 dirt
fill ~268 ~69 ~98 ~269 ~69 ~98 grass_block
fill ~270 ~60 ~98 ~270 ~66 ~98 stone
fill ~270 ~67 ~98 ~270 ~69 ~98 dirt
fill ~270 ~70 ~98 ~270 ~70 ~98 grass_block
fill ~271 ~60 ~98 ~271 ~65 ~98 stone
fill ~271 ~66 ~98 ~271 ~68 ~98 dirt
fill ~271 ~69 ~98 ~271 ~69 ~98 grass_block
fill ~256 ~60 ~99 ~257 ~64 ~99 stone
fill ~256 ~65 ~99 ~257 ~67 ~99 dirt
fill ~256 ~68 ~99 ~257 ~68 ~99 grass_block
fill ~258 ~60 ~99 ~261 ~65 ~99 stone
fill ~258 ~66 ~99 ~261 ~68 ~99 dirt
fill ~258 ~69 ~99 ~261 ~69 ~99 grass_block
fill ~262 ~60 ~99 ~265 ~64 ~99 stone
fill ~262 ~65 ~99 ~265 ~67 ~99 dirt
fill ~262 ~68 ~99 ~265 ~68 ~99 grass_block
fill ~266 ~60 ~99 ~266 ~63 ~99 stone
fill ~266 ~64 ~99 ~266 ~66 ~99 dirt
fill ~266 ~67 ~99 ~266 ~67 ~99 grass_block
fill ~267 ~60 ~99 ~268 ~64 ~99 stone
fill ~267 ~65 ~99 ~268 ~67 ~99 dirt
fill ~267 ~68 ~99 ~268 ~68 ~99 grass_block
fill ~269 ~60 ~99 ~271 ~65 ~99 stone
fill ~269 ~66 ~99 ~271 ~68 ~99 dirt
fill ~269 ~69 ~99 ~271 ~69 ~99 grass_block
fill ~256 ~60 ~100 ~258 ~64 ~100 stone
fill ~256 ~65 ~100 ~258 ~67 ~100 dirt
fill ~256 ~68 ~100 ~258 ~68 ~100 grass_block
fill ~259 ~60 ~100 ~260 ~65 ~100 stone
fill ~259 ~66 ~100 ~260 ~68 ~100 dirt
fill ~259 ~69 ~100 ~260 ~69 ~100 grass_block
fill ~261 ~60 ~100 ~264 ~64 ~100 stone
fill ~261 ~65 ~100 ~264 ~67 ~100 dirt
fill ~261 ~68 ~100 ~264 ~68 ~100 grass_block
fill ~265 ~60 ~100 ~266 ~63 ~100 stone
fill ~265 ~64 ~100 ~266 ~66 ~100 dirt
fill ~265 ~67 ~100 ~266 ~67 ~100 grass_block
fill ~267 ~60 ~100 ~268 ~64 ~100 stone
fill ~267 ~65 ~100 ~268 ~67 ~100 dirt
fill ~267 ~68 ~100 ~268 ~68 ~100 grass_block
fill ~269 ~60 ~100 ~270 ~65 ~100 stone
fill ~269 ~66 ~100 ~270 ~68 ~100 dirt
fill ~269 ~69 ~100 ~270 ~69 ~100 grass_block
fill ~271 ~60 ~100 ~271 ~66 ~100 stone
fill ~271 ~67 ~100 ~271 ~69 ~100 dirt
fill ~271 ~70 ~100 ~271 ~70 ~100 grass_block
fill ~256 ~60 ~101 ~258 ~64 ~101 stone
fill ~256 ~65 ~101 ~258 ~67 ~101 dirt
fill ~256 ~68 ~101 ~258 ~68 ~101 grass_block
fill ~259 ~60 ~101 ~259 ~65 ~101 stone
fill ~259 ~66 ~101 ~259 ~68 ~101 dirt
fill ~259 ~69 ~101 ~259 ~69 ~101 grass_block
fill ~260 ~60 ~101 ~263 ~64 ~101 stone
fill ~260 ~65 ~101 ~263 ~67 ~101 dirt
fill ~260 ~68 ~101 ~263 ~68 ~101 grass_block
fill ~264 ~60 ~101 ~266 ~63 ~101 stone
fill ~264 ~64 ~101 ~266 ~66 ~101 dirt
fill ~264 ~67 ~101 ~266 ~67 ~101 grass_block
fill ~267 ~60 ~101 ~268 ~64 ~101 stone
fill ~267 ~65 ~101 ~268 ~67 ~101 dirt
fill ~267 ~68 ~101 ~268 ~68 ~101 grass_block
fill ~269 ~60 ~101 ~271 ~65 ~101 stone
fill ~269 ~66 ~101 ~271 ~68 ~101 dirt
fill ~269 ~69 ~101 ~271 ~69 ~101 grass_block
fill ~256 ~60 ~102 ~256 ~63 ~102 stone
fill ~256 ~64 ~102 ~256 ~66 ~102 dirt
fill ~256 ~67 ~102 ~256 ~67 ~102 grass_block
fill ~257 ~60 ~102 ~262 ~64 ~102 stone
fill ~257 ~65 ~102 ~262 ~67 ~102 dirt
fill ~257 ~68 ~102 ~262 ~68 ~102 grass_block
fill ~263 ~60 ~102 ~265 ~63 ~102 stone
fill ~263 ~64 ~102 ~265 ~66 ~102 dirt
fill ~263 ~67 ~102 ~265 ~67 ~102 grass_block
fill ~266 ~60 ~102 ~268 ~64 ~102 stone
fill ~266 ~65 ~102 ~268 ~67 ~102 dirt
fill ~266 ~68 ~102 ~268 ~68 ~102 grass_block
fill ~269 ~60 ~102 ~271 ~65 ~102 stone
fill ~269 ~66 ~102 ~271 ~68 ~102 dirt
fill ~269 ~69 ~102 ~271 ~69 ~102 grass_block
fill ~256 ~60 ~103 ~256 ~63 ~103 stone
fill ~256 ~64 ~103 ~256 ~66 ~103 dirt
fill ~256 ~67 ~103 ~256 ~67 ~103 grass_block
fill ~257 ~60 ~103 ~261 ~64 ~103 stone
fill ~257 ~65 ~103 ~261 ~67 ~103 dirt
fill ~257 ~68 ~103 ~261 ~68 ~103 grass_block
fill ~262 ~60 ~103 ~265 ~63 ~103 stone
fill ~262 ~64 ~103 ~265 ~66 ~103 dirt
fill ~262 ~67 ~103 ~265 ~67 ~103 grass_block
fill ~266 ~60 ~103 ~268 ~64 ~103 stone
fill ~266 ~65 ~103 ~268 ~67 ~103 dirt
fill ~266 ~68 ~103 ~268 ~68 ~103 grass_block
fill ~269 ~60 ~103 ~271 ~65 ~103 stone
fill ~269 ~66 ~103 ~271 ~68 ~103 dirt
fill ~269 ~69 ~103 ~271 ~69 ~103 grass_block
fill ~256 ~60 ~104 ~257 ~63 ~104 stone
fill ~256 ~64 ~104 ~257 ~66 ~104 dirt
fill ~256 ~67 ~104 ~257 ~67 ~104 grass_block
fill ~258 ~60 ~104 ~259 ~64 ~104 stone
fill ~258 ~65 ~104 ~259 ~67 ~104 dirt
fill ~258 ~68 ~104 ~259 ~68 ~104 grass_block
fill ~260 ~60 ~104 ~266 ~63 ~104 stone
fill ~260 ~64 ~104 ~266 ~66 ~104 dirt
fill ~260 ~67 ~104 ~266 ~67 ~104 grass_block
fill ~267 ~60 ~104 ~268 ~64 ~104 stone
fill ~267 ~65 ~104 ~268 ~67 ~104 dirt
fill ~267 ~68 ~104 ~268 ~68 ~104 grass_block
fill ~269 ~60 ~104 ~271 ~65 ~104 stone
fill ~269 ~66 ~104 ~271 ~68 ~104 dirt
fill ~269 ~69 ~104 ~271 ~69 ~104 grass_block
fill ~256 ~60 ~105 ~265 ~63 ~105 stone
fill ~256 ~64 ~105 ~265 ~66 ~105 dirt
fill ~256 ~67 ~105 ~265 ~67 ~105 grass_block
fill ~266 ~60 ~105 ~269 ~64 ~105 stone
fill ~266 ~65 ~105 ~269 ~67 ~105 dirt
fill ~266 ~68 ~105 ~269 ~68 ~105 grass_block
fill ~270 ~60 ~105 ~271 ~65 ~105 stone
fill ~270 ~66 ~105 ~271 ~68 ~105 dirt
fill ~270 ~69 ~105 ~271 ~69 ~105 grass_block
fill ~256 ~60 ~106 ~256 ~62 ~106 stone
fill ~256 ~63 ~106 ~256 ~65 ~106 dirt
fill ~256 ~66 ~106 ~256 ~66 ~106 grass_block
fill ~257 ~60 ~106 ~266 ~63 ~106 stone
fill ~257 ~64 ~106 ~266 ~66 ~106 dirt
fill ~257 ~67 ~106 ~266 ~67 ~106 grass_block
fill ~267 ~60 ~106 ~271 ~64 ~106 stone
fill ~267 ~65 ~106 ~271 ~67 ~106 dirt
fill ~267 ~68 ~106 ~271 ~68 ~106 grass_block
fill ~256 ~60 ~107 ~256 ~62 ~107 stone
fill ~256 ~63 ~107 ~256 ~65 ~107 dirt
fill ~256 ~66 ~107 ~256 ~66 ~107 grass_block
fill ~257 ~60 ~107 ~266 ~63 ~107 stone
fill ~257 ~64 ~107 ~266 ~66 ~107 dirt
fill ~257 ~67 ~107 ~266 ~67 ~107 grass_block
fill ~267 ~60 ~107 ~271 ~64 ~107 stone
fill ~267 ~65 ~107 ~271 ~67 ~107 dirt
fill ~267 ~68 ~107 ~271 ~68 ~107 grass_block
fill ~256 ~60 ~108 ~257 ~62 ~108 stone
fill ~256 ~63 ~108 ~257 ~65 ~108 dirt
fill ~256 ~66 ~108 ~257 ~66 ~108 grass_block
fill ~258 ~60 ~108 ~261 ~63 ~108 stone
fill ~258 ~64 ~108 ~261 ~66 ~108 dirt
fill ~258 ~67 ~108 ~261 ~67 ~108 grass_block
fill ~262 ~60 ~108 ~262 ~62 ~108 stone
fill ~262 ~63 ~108 ~262 ~65 ~108 dirt
fill ~262 ~66 ~108 ~262 ~66 ~108 grass_block
fill ~263 ~60 ~108 ~265 ~63 ~108 stone
fill ~263 ~64 ~108 ~265 ~66 ~108 dirt
fill ~263 ~67 ~108 ~265 ~67 ~108 grass_block
fill ~266 ~60 ~108 ~269 ~64 ~108 stone
fill ~266 ~65 ~108 ~269 ~67 ~108 dirt
fill ~266 ~68 ~108 ~269 ~68 ~108 grass_block
fill ~270 ~60 ~108 ~271 ~63 ~108 stone
fill ~270 ~64 ~108 ~271 ~66 ~108 dirt
fill ~270 ~67 ~108 ~271 ~67 ~108 grass_block
fill ~256 ~60 ~109 ~258 ~62 ~109 stone
fill ~256 ~63 ~109 ~258 ~65 ~109 dirt
fill ~256 ~66 ~109 ~258 ~66 ~109 grass_block
fill ~259 ~60 ~109 ~260 ~63 ~109 stone
fill ~259 ~64 ~109 ~260 ~66 ~109 dirt
fill ~259 ~67 ~109 ~260 ~67 ~109 grass_block
fill ~261 ~60 ~109 ~262 ~62 ~109 stone
fill ~261 ~63 ~109 ~262 ~65 ~109 dirt
fill ~261 ~66 ~109 ~262 ~66 ~109 grass_block
fill ~263 ~60 ~109 ~271 ~63 ~109 stone
fill ~263 ~64 ~109 ~271 ~66 ~109 dirt
fill ~263 ~67 ~109 ~271 ~67 ~109 grass_block
fill ~256 ~60 ~110 ~256 ~63 ~110 stone
fill ~256 ~64 ~110 ~256 ~66 ~110 dirt
fill ~256 ~67 ~110 ~256 ~67 ~110 grass_block
fill ~257 ~60 ~110 ~261 ~62 ~110 stone
fill ~257 ~63 ~110 ~261 ~65 ~110 dirt
fill ~257 ~66 ~110 ~261 ~66 ~110 grass_block
fill ~262 ~60 ~110 ~271 ~63 ~110 stone
fill ~262 ~64 ~110 ~271 ~66 ~110 dirt
fill ~262 ~67 ~110 ~271 ~67 ~110 grass_block
fill ~256 ~60 ~111 ~256 ~63 ~111 stone
fill ~256 ~64 ~111 ~256 ~66 ~111 dirt
fill ~256 ~67 ~111 ~256 ~67 ~111 grass_block
fill ~257 ~60 ~111 ~261 ~62 ~111 stone
fill ~257 ~63 ~111 ~261 ~65 ~111 dirt
fill ~257 ~66 ~111 ~261 ~66 ~111 grass_block
fill ~262 ~60 ~111 ~271 ~63 ~111 stone
fill ~262 ~64 ~111 ~271 ~66 ~111 dirt
fill ~262 ~67 ~111 ~271 ~67 ~111 grass_block