fill ~464 ~60 ~112 ~466 ~61 ~112 stone
fill ~464 ~62 ~112 ~466 ~64 ~112 dirt
fill ~464 ~65 ~112 ~466 ~65 ~112 grass_block
fill ~467 ~60 ~112 ~469 ~62 ~112 stone
fill ~467 ~63 ~112 ~469 ~65 ~112 dirt
fill ~467 ~66 ~112 ~469 ~66 ~112 grass_block
fill ~464 ~60 ~113 ~467 ~61 ~113 stone
fill ~464 ~62 ~113 ~467 ~64 ~113 dirt
fill ~464 ~65 ~113 ~467 ~65 ~113 grass_block
fill ~468 ~60 ~113 ~469 ~62 ~113 stone
fill ~468 ~63 ~113 ~469 ~65 ~113 dirt
fill ~468 ~66 ~113 ~469 ~66 ~113 grass_block
fill ~464 ~60 ~114 ~468 ~61 ~114 stone
fill ~464 ~62 ~114 ~468 ~64 ~114 dirt
fill ~464 ~65 ~114 ~468 ~65 ~114 grass_block
fill ~469 ~60 ~114 ~469 ~62 ~114 stone
fill ~469 ~63 ~114 ~469 ~65 ~114 dirt
fill ~469 ~66 ~114 ~469 ~66 ~114 grass_block
fill ~464 ~60 ~115 ~469 ~61 ~115 stone
fill ~464 ~62 ~115 ~469 ~64 ~115 dirt
fill ~464 ~65 ~115 ~469 ~65 ~115 grass_block
fill ~464 ~60 ~116 ~469 ~61 ~116 stone
fill ~464 ~62 ~116 ~469 ~64 ~116 dirt
fill ~464 ~65 ~116 ~469 ~65 ~116 grass_block
fill ~464 ~60 ~117 ~469 ~61 ~117 stone
fill ~464 ~62 ~117 ~469 ~64 ~117 dirt
fill ~464 ~65 ~117 ~469 ~65 ~117 grass_block
fill ~464 ~60 ~118 ~469 ~61 ~118 stone
fill ~464 ~62 ~118 ~469 ~64 ~118 dirt
fill ~464 ~65 ~118 ~469 ~65 ~118 grass_block
fill ~464 ~60 ~119 ~465 ~62 ~119 stone
fill ~464 ~63 ~119 ~465 ~65 ~119 dirt
fill ~464 ~66 ~119 ~465 ~66 ~119 grass_block
fill ~466 ~60 ~119 ~469 ~61 ~119 stone
fill ~466 ~62 ~119 ~469 ~64 ~119 dirt
fill ~466 ~65 ~119 ~469 ~65 ~119 grass_block
fill ~464 ~60 ~120 ~466 ~62 ~120 stone
fill ~464 ~63 ~120 ~466 ~65 ~120 dirt
fill ~464 ~66 ~120 ~466 ~66 ~120 grass_block
fill ~467 ~60 ~120 ~469 ~61 ~120 stone
fill ~467 ~62 ~120 ~469 ~64 ~120 dirt
fill ~467 ~65 ~120 ~469 ~65 ~120 grass_block
fill ~464 ~60 ~121 ~464 ~63 ~121 stone
fill ~464 ~64 ~121 ~464 ~66 ~121 dirt
fill ~464 ~67 ~121 ~464 ~67 ~121 grass_block
fill ~465 ~60 ~121 ~468 ~62 ~121 stone
fill ~465 ~63 ~121 ~468 ~65 ~121 dirt
fill ~465 ~66 ~121 ~468 ~66 ~121 grass_block
fill ~469 ~60 ~121 ~469 ~61 ~121 stone
fill ~469 ~62 ~121 ~469 ~64 ~121 dirt
fill ~469 ~65 ~121 ~469 ~65 ~121 grass_block
fill ~464 ~60 ~122 ~466 ~63 ~122 stone
fill ~464 ~64 ~122 ~466 ~66 ~122 dirt
fill ~464 ~67 ~122 ~466 ~67 ~122 grass_block
fill ~467 ~60 ~122 ~469 ~62 ~122 stone
fill ~467 ~63 ~122 ~469 ~65 ~122 dirt
fill ~467 ~66 ~122 ~469 ~66 ~122 grass_block
fill ~464 ~60 ~123 ~468 ~63 ~123 stone
fill ~464 ~64 ~123 ~468 ~66 ~123 dirt
fill ~464 ~67 ~123 ~468 ~67 ~123 grass_block
fill ~469 ~60 ~123 ~469 ~62 ~123 stone
fill ~469 ~63 ~123 ~469 ~65 ~123 dirt
fill ~469 ~66 ~123 ~469 ~66 ~123 grass_block
fill ~464 ~60 ~124 ~465 ~64 ~124 stone
fill ~464 ~65 ~124 ~465 ~67 ~124 dirt
fill ~464 ~68 ~124 ~465 ~68 ~124 grass_block
fill ~466 ~60 ~124 ~469 ~63 ~124 stone
fill ~466 ~64 ~124 ~469 ~66 ~124 dirt
fill ~466 ~67 ~124 ~469 ~67 ~124 grass_block
fill ~464 ~60 ~125 ~467 ~64 ~125 stone
fill ~464 ~65 ~125 ~467 ~67 ~125 dirt
fill ~464 ~68 ~125 ~467 ~68 ~125 grass_block
fill ~468 ~60 ~125 ~469 ~63 ~125 stone
fill ~468 ~64 ~125 ~469 ~66 ~125 dirt
fill ~468 ~67 ~125 ~469 ~67 ~125 grass_block
fill ~464 ~60 ~126 ~467 ~64 ~126 stone
fill ~464 ~65 ~126 ~467 ~67 ~126 dirt
fill ~464 ~68 ~126 ~467 ~68 ~126 grass_block
fill ~468 ~60 ~126 ~469 ~63 ~126 stone
fill ~468 ~64 ~126 ~469 ~66 ~126 dirt
fill ~468 ~67 ~126 ~469 ~67 ~126 grass_block
fill ~464 ~60 ~127 ~467 ~64 ~127 stone
fill ~464 ~65 ~127 ~467 ~67 ~127 dirt
fill ~464 ~68 ~127 ~467 ~68 ~127 grass_block
fill ~468 ~60 ~127 ~469 ~63 ~127 stone
fill ~468 ~64 ~127 ~469 ~66 ~127 dirt
fill ~468 ~67 ~127 ~469 ~67 ~127 grass_block