fill ~64 ~60 ~32 ~64 ~66 ~32 stone
fill ~64 ~67 ~32 ~64 ~69 ~32 dirt
fill ~64 ~70 ~32 ~64 ~70 ~32 grass_block
fill ~65 ~60 ~32 ~66 ~65 ~32 stone
fill ~65 ~66 ~32 ~66 ~68 ~32 dirt
fill ~65 ~69 ~32 ~66 ~69 ~32 grass_block
fill ~67 ~60 ~32 ~69 ~64 ~32 stone
fill ~67 ~65 ~32 ~69 ~67 ~32 dirt
fill ~67 ~68 ~32 ~69 ~68 ~32 grass_block
fill ~70 ~60 ~32 ~79 ~63 ~32 stone
fill ~70 ~64 ~32 ~79 ~66 ~32 dirt
fill ~70 ~67 ~32 ~79 ~67 ~32 grass_block
fill ~64 ~60 ~33 ~64 ~66 ~33 stone
fill ~64 ~67 ~33 ~64 ~69 ~33 dirt
fill ~64 ~70 ~33 ~64 ~70 ~33 grass_block
fill ~65 ~60 ~33 ~66 ~65 ~33 stone
fill ~65 ~66 ~33 ~66 ~68 ~33 dirt
fill ~65 ~69 ~33 ~66 ~69 ~33 grass_block
fill ~67 ~60 ~33 ~69 ~64 ~33 stone
fill ~67 ~65 ~33 ~69 ~67 ~33 dirt
fill ~67 ~68 ~33 ~69 ~68 ~33 grass_block
fill ~70 ~60 ~33 ~79 ~63 ~33 stone
fill ~70 ~64 ~33 ~79 ~66 ~33 dirt
fill ~70 ~67 ~33 ~79 ~67 ~33 grass_block
fill ~64 ~60 ~34 ~64 ~66 ~34 stone
fill ~64 ~67 ~34 ~64 ~69 ~34 dirt
fill ~64 ~70 ~34 ~64 ~70 ~34 grass_block
fill ~65 ~60 ~34 ~67 ~65 ~34 stone
fill ~65 ~66 ~34 ~67 ~68 ~34 dirt
fill ~65 ~69 ~34 ~67 ~69 ~34 grass_block
fill ~68 ~60 ~34 ~69 ~64 ~34 stone
fill ~68 ~65 ~34 ~69 ~67 ~34 dirt
fill ~68 ~68 ~34 ~69 ~68 ~34 grass_block
fill ~70 ~60 ~34 ~79 ~63 ~34 stone
fill ~70 ~64 ~34 ~79 ~66 ~34 dirt
fill ~70 ~67 ~34 ~79 ~67 ~34 grass_block
fill ~64 ~60 ~35 ~66 ~66 ~35 stone
fill ~64 ~67 ~35 ~66 ~69 ~35 dirt
fill ~64 ~70 ~35 ~66 ~70 ~35 grass_block
fill ~67 ~60 ~35 ~69 ~65 ~35 stone
fill ~67 ~66 ~35 ~69 ~68 ~35 dirt
fill ~67 ~69 ~35 ~69 ~69 ~35 grass_block
fill ~70 ~60 ~35 ~73 ~64 ~35 stone
fill ~70 ~65 ~35 ~73 ~67 ~35 dirt
fill ~70 ~68 ~35 ~73 ~68 ~35 grass_block
fill ~74 ~60 ~35 ~79 ~63 ~35 stone
fill ~74 ~64 ~35 ~79 ~66 ~35 dirt
fill ~74 ~67 ~35 ~79 ~67 ~35 grass_block
fill ~64 ~60 ~36 ~65 ~67 ~36 stone
fill ~64 ~68 ~36 ~65 ~70 ~36 dirt
fill ~64 ~71 ~36 ~65 ~71 ~36 grass_block
fill ~66 ~60 ~36 ~69 ~66 ~36 stone
fill ~66 ~67 ~36 ~69 ~69 ~36 dirt
fill ~66 ~70 ~36 ~69 ~70 ~36 grass_block
fill ~70 ~60 ~36 ~72 ~65 ~36 stone
fill ~70 ~66 ~36 ~72 ~68 ~36 dirt
fill ~70 ~69 ~36 ~72 ~69 ~36 grass_block
fill ~73 ~60 ~36 ~74 ~64 ~36 stone
fill ~73 ~65 ~36 ~74 ~67 ~36 dirt
fill ~73 ~68 ~36 ~74 ~68 ~36 grass_block
fill ~75 ~60 ~36 ~79 ~63 ~36 stone
fill ~75 ~64 ~36 ~79 ~66 ~36 dirt
fill ~75 ~67 ~36 ~79 ~67 ~36 grass_block
fill ~64 ~60 ~37 ~68 ~67 ~37 stone
fill ~64 ~68 ~37 ~68 ~70 ~37 dirt
fill ~64 ~71 ~37 ~68 ~71 ~37 grass_block
fill ~69 ~60 ~37 ~71 ~66 ~37 stone
fill ~69 ~67 ~37 ~71 ~69 ~37 dirt
fill ~69 ~70 ~37 ~71 ~70 ~37 grass_block
fill ~72 ~60 ~37 ~73 ~65 ~37 stone
fill ~72 ~66 ~37 ~73 ~68 ~37 dirt
fill ~72 ~69 ~37 ~73 ~69 ~37 grass_block
fill ~74 ~60 ~37 ~75 ~64 ~37 stone
fill ~74 ~65 ~37 ~75 ~67 ~37 dirt
fill ~74 ~68 ~37 ~75 ~68 ~37 grass_block
fill ~76 ~60 ~37 ~79 ~63 ~37 stone
fill ~76 ~64 ~37 ~79 ~66 ~37 dirt
fill ~76 ~67 ~37 ~79 ~67 ~37 grass_block
fill ~64 ~60 ~38 ~64 ~66 ~38 stone
fill ~64 ~67 ~38 ~64 ~69 ~38 dirt
fill ~64 ~70 ~38 ~64 ~70 ~38 grass_block
fill ~65 ~60 ~38 ~69 ~67 ~38 stone
fill ~65 ~68 ~38 ~69 ~70 ~38 dirt
fill ~65 ~71 ~38 ~69 ~71 ~38 grass_block
fill ~70 ~60 ~38 ~71 ~66 ~38 stone
fill ~70 ~67 ~38 ~71 ~69 ~38 dirt
fill ~70 ~70 ~38 ~71 ~70 ~38 grass_block
fill ~72 ~60 ~38 ~73 ~65 ~38 stone
fill ~72 ~66 ~38 ~73 ~68 ~38 dirt
fill ~72 ~69 ~38 ~73 ~69 ~38 grass_block
fill ~74 ~60 ~38 ~76 ~64 ~38 stone
fill ~74 ~65 ~38 ~76 ~67 ~38 dirt
fill ~74 ~68 ~38 ~76 ~68 ~38 grass_block
fill ~77 ~60 ~38 ~79 ~63 ~38 stone
fill ~77 ~64 ~38 ~79 ~66 ~38 dirt
fill ~77 ~67 ~38 ~79 ~67 ~38 grass_block
fill ~64 ~60 ~39 ~65 ~66 ~39 stone
fill ~64 ~67 ~39 ~65 ~69 ~39 dirt
fill ~64 ~70 ~39 ~65 ~70 ~39 grass_block
fill ~66 ~60 ~39 ~70 ~67 ~39 stone
fill ~66 ~68 ~39 ~70 ~70 ~39 dirt
fill ~66 ~71 ~39 ~70 ~71 ~39 grass_block
fill ~71 ~60 ~39 ~72 ~66 ~39 stone
fill ~71 ~67 ~39 ~72 ~69 ~39 dirt
fill ~71 ~70 ~39 ~72 ~70 ~39 grass_block
fill ~73 ~60 ~39 ~75 ~65 ~39 stone
fill ~73 ~66 ~39 ~75 ~68 ~39 dirt
fill ~73 ~69 ~39 ~75 ~69 ~39 grass_block
fill ~76 ~60 ~39 ~77 ~64 ~39 stone
fill ~76 ~65 ~39 ~77 ~67 ~39 dirt
fill ~76 ~68 ~39 ~77 ~68 ~39 grass_block
fill ~78 ~60 ~39 ~79 ~63 ~39 stone
fill ~78 ~64 ~39 ~79 ~66 ~39 dirt
fill ~78 ~67 ~39 ~79 ~67 ~39 grass_block
fill ~64 ~60 ~40 ~67 ~66 ~40 stone
fill ~64 ~67 ~40 ~67 ~69 ~40 dirt
fill ~64 ~70 ~40 ~67 ~70 ~40 grass_block
fill ~68 ~60 ~40 ~68 ~67 ~40 stone
fill ~68 ~68 ~40 ~68 ~70 ~40 dirt
fill ~68 ~71 ~40 ~68 ~71 ~40 grass_block
fill ~69 ~60 ~40 ~73 ~66 ~40 stone
fill ~69 ~67 ~40 ~73 ~69 ~40 dirt
fill ~69 ~70 ~40 ~73 ~70 ~40 grass_block
fill ~74 ~60 ~40 ~76 ~65 ~40 stone
fill ~74 ~66 ~40 ~76 ~68 ~40 dirt
fill ~74 ~69 ~40 ~76 ~69 ~40 grass_block
fill ~77 ~60 ~40 ~77 ~64 ~40 stone
fill ~77 ~65 ~40 ~77 ~67 ~40 dirt
fill ~77 ~68 ~40 ~77 ~68 ~40 grass_block
fill ~78 ~60 ~40 ~79 ~63 ~40 stone
fill ~78 ~64 ~40 ~79 ~66 ~40 dirt
fill ~78 ~67 ~40 ~79 ~67 ~40 grass_block
fill ~64 ~60 ~41 ~65 ~65 ~41 stone
fill ~64 ~66 ~41 ~65 ~68 ~41 dirt
fill ~64 ~69 ~41 ~65 ~69 ~41 grass_block
fill ~66 ~60 ~41 ~74 ~66 ~41 stone
fill ~66 ~67 ~41 ~74 ~69 ~41 dirt
fill ~66 ~70 ~41 ~74 ~70 ~41 grass_block
fill ~75 ~60 ~41 ~77 ~65 ~41 stone
fill ~75 ~66 ~41 ~77 ~68 ~41 dirt
fill ~75 ~69 ~41 ~77 ~69 ~41 grass_block
fill ~78 ~60 ~41 ~78 ~64 ~41 stone
fill ~78 ~65 ~41 ~78 ~67 ~41 dirt
fill ~78 ~68 ~41 ~78 ~68 ~41 grass_block
fill ~79 ~60 ~41 ~79 ~63 ~41 stone
fill ~79 ~64 ~41 ~79 ~66 ~41 dirt
fill ~79 ~67 ~41 ~79 ~67 ~41 grass_block
fill ~64 ~60 ~42 ~66 ~65 ~42 stone
fill ~64 ~66 ~42 ~66 ~68 ~42 dirt
fill ~64 ~69 ~42 ~66 ~69 ~42 grass_block
fill ~67 ~60 ~42 ~68 ~66 ~42 stone
fill ~67 ~67 ~42 ~68 ~69 ~42 dirt
fill ~67 ~70 ~42 ~68 ~70 ~42 grass_block
fill ~69 ~60 ~42 ~70 ~65 ~42 stone
fill ~69 ~66 ~42 ~70 ~68 ~42 dirt
fill ~69 ~69 ~42 ~70 ~69 ~42 grass_block
fill ~71 ~60 ~42 ~75 ~66 ~42 stone
fill ~71 ~67 ~42 ~75 ~69 ~42 dirt
fill ~71 ~70 ~42 ~75 ~70 ~42 grass_block
fill ~76 ~60 ~42 ~77 ~65 ~42 stone
fill ~76 ~66 ~42 ~77 ~68 ~42 dirt
fill ~76 ~69 ~42 ~77 ~69 ~42 grass_block
fill ~78 ~60 ~42 ~79 ~64 ~42 stone
fill ~78 ~65 ~42 ~79 ~67 ~42 dirt
fill ~78 ~68 ~42 ~79 ~68 ~42 grass_block
fill ~64 ~60 ~43 ~72 ~65 ~43 stone
fill ~64 ~66 ~43 ~72 ~68 ~43 dirt
fill ~64 ~69 ~43 ~72 ~69 ~43 grass_block
fill ~73 ~60 ~43 ~76 ~66 ~43 stone
fill ~73 ~67 ~43 ~76 ~69 ~43 dirt
fill ~73 ~70 ~43 ~76 ~70 ~43 grass_block
fill ~77 ~60 ~43 ~78 ~65 ~43 stone
fill ~77 ~66 ~43 ~78 ~68 ~43 dirt
fill ~77 ~69 ~43 ~78 ~69 ~43 grass_block
fill ~79 ~60 ~43 ~79 ~64 ~43 stone
fill ~79 ~65 ~43 ~79 ~67 ~43 dirt
fill ~79 ~68 ~43 ~79 ~68 ~43 grass_block
fill ~64 ~60 ~44 ~64 ~64 ~44 stone
fill ~64 ~65 ~44 ~64 ~67 ~44 dirt
fill ~64 ~68 ~44 ~64 ~68 ~44 grass_block
fill ~65 ~60 ~44 ~68 ~65 ~44 stone
fill ~65 ~66 ~44 ~68 ~68 ~44 dirt
fill ~65 ~69 ~44 ~68 ~69 ~44 grass_block
fill ~69 ~60 ~44 ~71 ~64 ~44 stone
fill ~69 ~65 ~44 ~71 ~67 ~44 dirt
fill ~69 ~68 ~44 ~71 ~68 ~44 grass_block
fill ~72 ~60 ~44 ~72 ~65 ~44 stone
fill ~72 ~66 ~44 ~72 ~68 ~44 dirt
fill ~72 ~69 ~44 ~72 ~69 ~44 grass_block
fill ~73 ~60 ~44 ~77 ~66 ~44 stone
fill ~73 ~67 ~44 ~77 ~69 ~44 dirt
fill ~73 ~70 ~44 ~77 ~70 ~44 grass_block
fill ~78 ~60 ~44 ~79 ~65 ~44 stone
fill ~78 ~66 ~44 ~79 ~68 ~44 dirt
fill ~78 ~69 ~44 ~79 ~69 ~44 grass_block
fill ~64 ~60 ~45 ~66 ~64 ~45 stone
fill ~64 ~65 ~45 ~66 ~67 ~45 dirt
fill ~64 ~68 ~45 ~66 ~68 ~45 grass_block
fill ~67 ~60 ~45 ~67 ~65 ~45 stone
fill ~67 ~66 ~45 ~67 ~68 ~45 dirt
fill ~67 ~69 ~45 ~67 ~69 ~45 grass_block
fill ~68 ~60 ~45 ~71 ~64 ~45 stone
fill ~68 ~65 ~45 ~71 ~67 ~45 dirt
fill ~68 ~68 ~45 ~71 ~68 ~45 grass_block
fill ~72 ~60 ~45 ~73 ~65 ~45 stone
fill ~72 ~66 ~45 ~73 ~68 ~45 dirt
fill ~72 ~69 ~45 ~73 ~69 ~45 grass_block
fill ~74 ~60 ~45 ~77 ~66 ~45 stone
fill ~74 ~67 ~45 ~77 ~69 ~45 dirt
fill ~74 ~70 ~45 ~77 ~70 ~45 grass_block
fill ~78 ~60 ~45 ~79 ~65 ~45 stone
fill ~78 ~66 ~45 ~79 ~68 ~45 dirt
fill ~78 ~69 ~45 ~79 ~69 ~45 grass_block
fill ~64 ~60 ~46 ~71 ~64 ~46 stone
fill ~64 ~65 ~46 ~71 ~67 ~46 dirt
fill ~64 ~68 ~46 ~71 ~68 ~46 grass_block
fill ~72 ~60 ~46 ~75 ~65 ~46 stone
fill ~72 ~66 ~46 ~75 ~68 ~46 dirt
fill ~72 ~69 ~46 ~75 ~69 ~46 grass_block
fill ~76 ~60 ~46 ~78 ~66 ~46 stone
fill ~76 ~67 ~46 ~78 ~69 ~46 dirt
fill ~76 ~70 ~46 ~78 ~70 ~46 grass_block
fill ~79 ~60 ~46 ~79 ~65 ~46 stone
fill ~79 ~66 ~46 ~79 ~68 ~46 dirt
fill ~79 ~69 ~46 ~79 ~69 ~46 grass_block
fill ~64 ~60 ~47 ~66 ~63 ~47 stone
fill ~64 ~64 ~47 ~66 ~66 ~47 dirt
fill ~64 ~67 ~47 ~66 ~67 ~47 grass_block
fill ~67 ~60 ~47 ~68 ~64 ~47 stone
fill ~67 ~65 ~47 ~68 ~67 ~47 dirt
fill ~67 ~68 ~47 ~68 ~68 ~47 grass_block
fill ~69 ~60 ~47 ~69 ~63 ~47 stone
fill ~69 ~64 ~47 ~69 ~66 ~47 dirt
fill ~69 ~67 ~47 ~69 ~67 ~47 grass_block
fill ~70 ~60 ~47 ~71 ~64 ~47 stone
fill ~70 ~65 ~47 ~71 ~67 ~47 dirt
fill ~70 ~68 ~47 ~71 ~68 ~47 grass_block
fill ~72 ~60 ~47 ~76 ~65 ~47 stone
fill ~72 ~66 ~47 ~76 ~68 ~47 dirt
fill ~72 ~69 ~47 ~76 ~69 ~47 grass_block
fill ~77 ~60 ~47 ~78 ~66 ~47 stone
fill ~77 ~67 ~47 ~78 ~69 ~47 dirt
fill ~77 ~70 ~47 ~78 ~70 ~47 grass_block
fill ~79 ~60 ~47 ~79 ~65 ~47 stone
fill ~79 ~66 ~47 ~79 ~68 ~47 dirt
fill ~79 ~69 ~47 ~79 ~69 ~47 grass_block