fill ~416 ~60 ~0 ~419 ~64 ~0 stone
fill ~416 ~65 ~0 ~419 ~67 ~0 dirt
fill ~416 ~68 ~0 ~419 ~68 ~0 grass_block
fill ~420 ~60 ~0 ~431 ~65 ~0 stone
fill ~420 ~66 ~0 ~431 ~68 ~0 dirt
fill ~420 ~69 ~0 ~431 ~69 ~0 grass_block
fill ~416 ~60 ~1 ~418 ~64 ~1 stone
fill ~416 ~65 ~1 ~418 ~67 ~1 dirt
fill ~416 ~68 ~1 ~418 ~68 ~1 grass_block
fill ~419 ~60 ~1 ~423 ~65 ~1 stone
fill ~419 ~66 ~1 ~423 ~68 ~1 dirt
fill ~419 ~69 ~1 ~423 ~69 ~1 grass_block
fill ~424 ~60 ~1 ~427 ~64 ~1 stone
fill ~424 ~65 ~1 ~427 ~67 ~1 dirt
fill ~424 ~68 ~1 ~427 ~68 ~1 grass_block
fill ~428 ~60 ~1 ~431 ~65 ~1 stone
fill ~428 ~66 ~1 ~431 ~68 ~1 dirt
fill ~428 ~69 ~1 ~431 ~69 ~1 grass_block
fill ~416 ~60 ~2 ~418 ~64 ~2 stone
fill ~416 ~65 ~2 ~418 ~67 ~2 dirt
fill ~416 ~68 ~2 ~418 ~68 ~2 grass_block
fill ~419 ~60 ~2 ~422 ~65 ~2 stone
fill ~419 ~66 ~2 ~422 ~68 ~2 dirt
fill ~419 ~69 ~2 ~422 ~69 ~2 grass_block
fill ~423 ~60 ~2 ~428 ~64 ~2 stone
fill ~423 ~65 ~2 ~428 ~67 ~2 dirt
fill ~423 ~68 ~2 ~428 ~68 ~2 grass_block
fill ~429 ~60 ~2 ~431 ~65 ~2 stone
fill ~429 ~66 ~2 ~431 ~68 ~2 dirt
fill ~429 ~69 ~2 ~431 ~69 ~2 grass_block
fill ~416 ~60 ~3 ~417 ~64 ~3 stone
fill ~416 ~65 ~3 ~417 ~67 ~3 dirt
fill ~416 ~68 ~3 ~417 ~68 ~3 grass_block
fill ~418 ~60 ~3 ~421 ~65 ~3 stone
fill ~418 ~66 ~3 ~421 ~68 ~3 dirt
fill ~418 ~69 ~3 ~421 ~69 ~3 grass_block
fill ~422 ~60 ~3 ~429 ~64 ~3 stone
fill ~422 ~65 ~3 ~429 ~67 ~3 dirt
fill ~422 ~68 ~3 ~429 ~68 ~3 grass_block
fill ~430 ~60 ~3 ~431 ~65 ~3 stone
fill ~430 ~66 ~3 ~431 ~68 ~3 dirt
fill ~430 ~69 ~3 ~431 ~69 ~3 grass_block
fill ~416 ~60 ~4 ~417 ~64 ~4 stone
fill ~416 ~65 ~4 ~417 ~67 ~4 dirt
fill ~416 ~68 ~4 ~417 ~68 ~4 grass_block
fill ~418 ~60 ~4 ~421 ~65 ~4 stone
fill ~418 ~66 ~4 ~421 ~68 ~4 dirt
fill ~418 ~69 ~4 ~421 ~69 ~4 grass_block
fill ~422 ~60 ~4 ~430 ~64 ~4 stone
fill ~422 ~65 ~4 ~430 ~67 ~4 dirt
fill ~422 ~68 ~4 ~430 ~68 ~4 grass_block
fill ~431 ~60 ~4 ~431 ~65 ~4 stone
fill ~431 ~66 ~4 ~431 ~68 ~4 dirt
fill ~431 ~69 ~4 ~431 ~69 ~4 grass_block
fill ~416 ~60 ~5 ~417 ~64 ~5 stone
fill ~416 ~65 ~5 ~417 ~67 ~5 dirt
fill ~416 ~68 ~5 ~417 ~68 ~5 grass_block
fill ~418 ~60 ~5 ~420 ~65 ~5 stone
fill ~418 ~66 ~5 ~420 ~68 ~5 dirt
fill ~418 ~69 ~5 ~420 ~69 ~5 grass_block
fill ~421 ~60 ~5 ~425 ~64 ~5 stone
fill ~421 ~65 ~5 ~425 ~67 ~5 dirt
fill ~421 ~68 ~5 ~425 ~68 ~5 grass_block
fill ~426 ~60 ~5 ~426 ~63 ~5 stone
fill ~426 ~64 ~5 ~426 ~66 ~5 dirt
fill ~426 ~67 ~5 ~426 ~67 ~5 grass_block
fill ~427 ~60 ~5 ~431 ~64 ~5 stone
fill ~427 ~65 ~5 ~431 ~67 ~5 dirt
fill ~427 ~68 ~5 ~431 ~68 ~5 grass_block
fill ~416 ~60 ~6 ~417 ~64 ~6 stone
fill ~416 ~65 ~6 ~417 ~67 ~6 dirt
fill ~416 ~68 ~6 ~417 ~68 ~6 grass_block
fill ~418 ~60 ~6 ~419 ~65 ~6 stone
fill ~418 ~66 ~6 ~419 ~68 ~6 dirt
fill ~418 ~69 ~6 ~419 ~69 ~6 grass_block
fill ~420 ~60 ~6 ~424 ~64 ~6 stone
fill ~420 ~65 ~6 ~424 ~67 ~6 dirt
fill ~420 ~68 ~6 ~424 ~68 ~6 grass_block
fill ~425 ~60 ~6 ~427 ~63 ~6 stone
fill ~425 ~64 ~6 ~427 ~66 ~6 dirt
fill ~425 ~67 ~6 ~427 ~67 ~6 grass_block
fill ~428 ~60 ~6 ~431 ~64 ~6 stone
fill ~428 ~65 ~6 ~431 ~67 ~6 dirt
fill ~428 ~68 ~6 ~431 ~68 ~6 grass_block
fill ~416 ~60 ~7 ~417 ~64 ~7 stone
fill ~416 ~65 ~7 ~417 ~67 ~7 dirt
fill ~416 ~68 ~7 ~417 ~68 ~7 grass_block
fill ~418 ~60 ~7 ~419 ~65 ~7 stone
fill ~418 ~66 ~7 ~419 ~68 ~7 dirt
fill ~418 ~69 ~7 ~419 ~69 ~7 grass_block
fill ~420 ~60 ~7 ~424 ~64 ~7 stone
fill ~420 ~65 ~7 ~424 ~67 ~7 dirt
fill ~420 ~68 ~7 ~424 ~68 ~7 grass_block
fill ~425 ~60 ~7 ~427 ~63 ~7 stone
fill ~425 ~64 ~7 ~427 ~66 ~7 dirt
fill ~425 ~67 ~7 ~427 ~67 ~7 grass_block
fill ~428 ~60 ~7 ~431 ~64 ~7 stone
fill ~428 ~65 ~7 ~431 ~67 ~7 dirt
fill ~428 ~68 ~7 ~431 ~68 ~7 grass_block
fill ~416 ~60 ~8 ~423 ~64 ~8 stone
fill ~416 ~65 ~8 ~423 ~67 ~8 dirt
fill ~416 ~68 ~8 ~423 ~68 ~8 grass_block
fill ~424 ~60 ~8 ~428 ~63 ~8 stone
fill ~424 ~64 ~8 ~428 ~66 ~8 dirt
fill ~424 ~67 ~8 ~428 ~67 ~8 grass_block
fill ~429 ~60 ~8 ~431 ~64 ~8 stone
fill ~429 ~65 ~8 ~431 ~67 ~8 dirt
fill ~429 ~68 ~8 ~431 ~68 ~8 grass_block
fill ~416 ~60 ~9 ~422 ~64 ~9 stone
fill ~416 ~65 ~9 ~422 ~67 ~9 dirt
fill ~416 ~68 ~9 ~422 ~68 ~9 grass_block
fill ~423 ~60 ~9 ~428 ~63 ~9 stone
fill ~423 ~64 ~9 ~428 ~66 ~9 dirt
fill ~423 ~67 ~9 ~428 ~67 ~9 grass_block
fill ~429 ~60 ~9 ~431 ~64 ~9 stone
fill ~429 ~65 ~9 ~431 ~67 ~9 dirt
fill ~429 ~68 ~9 ~431 ~68 ~9 grass_block
fill ~416 ~60 ~10 ~422 ~64 ~10 stone
fill ~416 ~65 ~10 ~422 ~67 ~10 dirt
fill ~416 ~68 ~10 ~422 ~68 ~10 grass_block
fill ~423 ~60 ~10 ~429 ~63 ~10 stone
fill ~423 ~64 ~10 ~429 ~66 ~10 dirt
fill ~423 ~67 ~10 ~429 ~67 ~10 grass_block
fill ~430 ~60 ~10 ~431 ~64 ~10 stone
fill ~430 ~65 ~10 ~431 ~67 ~10 dirt
fill ~430 ~68 ~10 ~431 ~68 ~10 grass_block
fill ~416 ~60 ~11 ~422 ~64 ~11 stone
fill ~416 ~65 ~11 ~422 ~67 ~11 dirt
fill ~416 ~68 ~11 ~422 ~68 ~11 grass_block
fill ~423 ~60 ~11 ~429 ~63 ~11 stone
fill ~423 ~64 ~11 ~429 ~66 ~11 dirt
fill ~423 ~67 ~11 ~429 ~67 ~11 grass_block
fill ~430 ~60 ~11 ~431 ~64 ~11 stone
fill ~430 ~65 ~11 ~431 ~67 ~11 dirt
fill ~430 ~68 ~11 ~431 ~68 ~11 grass_block
fill ~416 ~60 ~12 ~422 ~64 ~12 stone
fill ~416 ~65 ~12 ~422 ~67 ~12 dirt
fill ~416 ~68 ~12 ~422 ~68 ~12 grass_block
fill ~423 ~60 ~12 ~429 ~63 ~12 stone
fill ~423 ~64 ~12 ~429 ~66 ~12 dirt
fill ~423 ~67 ~12 ~429 ~67 ~12 grass_block
fill ~430 ~60 ~12 ~431 ~64 ~12 stone
fill ~430 ~65 ~12 ~431 ~67 ~12 dirt
fill ~430 ~68 ~12 ~431 ~68 ~12 grass_block
fill ~416 ~60 ~13 ~416 ~63 ~13 stone
fill ~416 ~64 ~13 ~416 ~66 ~13 dirt
fill ~416 ~67 ~13 ~416 ~67 ~13 grass_block
fill ~417 ~60 ~13 ~422 ~64 ~13 stone
fill ~417 ~65 ~13 ~422 ~67 ~13 dirt
fill ~417 ~68 ~13 ~422 ~68 ~13 grass_block
fill ~423 ~60 ~13 ~431 ~63 ~13 stone
fill ~423 ~64 ~13 ~431 ~66 ~13 dirt
fill ~423 ~67 ~13 ~431 ~67 ~13 grass_block
fill ~416 ~60 ~14 ~418 ~63 ~14 stone
fill ~416 ~64 ~14 ~418 ~66 ~14 dirt
fill ~416 ~67 ~14 ~418 ~67 ~14 grass_block
fill ~419 ~60 ~14 ~422 ~64 ~14 stone
fill ~419 ~65 ~14 ~422 ~67 ~14 dirt
fill ~419 ~68 ~14 ~422 ~68 ~14 grass_block
fill ~423 ~60 ~14 ~430 ~63 ~14 stone
fill ~423 ~64 ~14 ~430 ~66 ~14 dirt
fill ~423 ~67 ~14 ~430 ~67 ~14 grass_block
fill ~431 ~60 ~14 ~431 ~64 ~14 stone
fill ~431 ~65 ~14 ~431 ~67 ~14 dirt
fill ~431 ~68 ~14 ~431 ~68 ~14 grass_block
fill ~416 ~60 ~15 ~419 ~63 ~15 stone
fill ~416 ~64 ~15 ~419 ~66 ~15 dirt
fill ~416 ~67 ~15 ~419 ~67 ~15 grass_block
fill ~420 ~60 ~15 ~422 ~64 ~15 stone
fill ~420 ~65 ~15 ~422 ~67 ~15 dirt
fill ~420 ~68 ~15 ~422 ~68 ~15 grass_block
fill ~423 ~60 ~15 ~430 ~63 ~15 stone
fill ~423 ~64 ~15 ~430 ~66 ~15 dirt
fill ~423 ~67 ~15 ~430 ~67 ~15 grass_block
fill ~431 ~60 ~15 ~431 ~64 ~15 stone
fill ~431 ~65 ~15 ~431 ~67 ~15 dirt
fill ~431 ~68 ~15 ~431 ~68 ~15 grass_block