fill ~16 ~60 ~128 ~16 ~67 ~128 stone
fill ~16 ~68 ~128 ~16 ~70 ~128 dirt
fill ~16 ~71 ~128 ~16 ~71 ~128 grass_block
fill ~17 ~60 ~128 ~18 ~66 ~128 stone
fill ~17 ~67 ~128 ~18 ~69 ~128 dirt
fill ~17 ~70 ~128 ~18 ~70 ~128 grass_block
fill ~19 ~60 ~128 ~29 ~65 ~128 stone
fill ~19 ~66 ~128 ~29 ~68 ~128 dirt
fill ~19 ~69 ~128 ~29 ~69 ~128 grass_block
fill ~30 ~60 ~128 ~31 ~64 ~128 stone
fill ~30 ~65 ~128 ~31 ~67 ~128 dirt
fill ~30 ~68 ~128 ~31 ~68 ~128 grass_block
fill ~16 ~60 ~129 ~17 ~67 ~129 stone
fill ~16 ~68 ~129 ~17 ~70 ~129 dirt
fill ~16 ~71 ~129 ~17 ~71 ~129 grass_block
fill ~18 ~60 ~129 ~19 ~66 ~129 stone
fill ~18 ~67 ~129 ~19 ~69 ~129 dirt
fill ~18 ~70 ~129 ~19 ~70 ~129 grass_block
fill ~20 ~60 ~129 ~23 ~65 ~129 stone
fill ~20 ~66 ~129 ~23 ~68 ~129 dirt
fill ~20 ~69 ~129 ~23 ~69 ~129 grass_block
fill ~24 ~60 ~129 ~27 ~66 ~129 stone
fill ~24 ~67 ~129 ~27 ~69 ~129 dirt
fill ~24 ~70 ~129 ~27 ~70 ~129 grass_block
fill ~28 ~60 ~129 ~31 ~65 ~129 stone
fill ~28 ~66 ~129 ~31 ~68 ~129 dirt
fill ~28 ~69 ~129 ~31 ~69 ~129 grass_block
fill ~16 ~60 ~130 ~17 ~67 ~130 stone
fill ~16 ~68 ~130 ~17 ~70 ~130 dirt
fill ~16 ~71 ~130 ~17 ~71 ~130 grass_block
fill ~18 ~60 ~130 ~21 ~66 ~130 stone
fill ~18 ~67 ~130 ~21 ~69 ~130 dirt
fill ~18 ~70 ~130 ~21 ~70 ~130 grass_block
fill ~22 ~60 ~130 ~22 ~65 ~130 stone
fill ~22 ~66 ~130 ~22 ~68 ~130 dirt
fill ~22 ~69 ~130 ~22 ~69 ~130 grass_block
fill ~23 ~60 ~130 ~29 ~66 ~130 stone
fill ~23 ~67 ~130 ~29 ~69 ~130 dirt
fill ~23 ~70 ~130 ~29 ~70 ~130 grass_block
fill ~30 ~60 ~130 ~31 ~65 ~130 stone
fill ~30 ~66 ~130 ~31 ~68 ~130 dirt
fill ~30 ~69 ~130 ~31 ~69 ~130 grass_block
fill ~16 ~60 ~131 ~18 ~67 ~131 stone
fill ~16 ~68 ~131 ~18 ~70 ~131 dirt
fill ~16 ~71 ~131 ~18 ~71 ~131 grass_block
fill ~19 ~60 ~131 ~24 ~66 ~131 stone
fill ~19 ~67 ~131 ~24 ~69 ~131 dirt
fill ~19 ~70 ~131 ~24 ~70 ~131 grass_block
fill ~25 ~60 ~131 ~27 ~67 ~131 stone
fill ~25 ~68 ~131 ~27 ~70 ~131 dirt
fill ~25 ~71 ~131 ~27 ~71 ~131 grass_block
fill ~28 ~60 ~131 ~29 ~66 ~131 stone
fill ~28 ~67 ~131 ~29 ~69 ~131 dirt
fill ~28 ~70 ~131 ~29 ~70 ~131 grass_block
fill ~30 ~60 ~131 ~31 ~65 ~131 stone
fill ~30 ~66 ~131 ~31 ~68 ~131 dirt
fill ~30 ~69 ~131 ~31 ~69 ~131 grass_block
fill ~16 ~60 ~132 ~16 ~68 ~132 stone
fill ~16 ~69 ~132 ~16 ~71 ~132 dirt
fill ~16 ~72 ~132 ~16 ~72 ~132 grass_block
fill ~17 ~60 ~132 ~19 ~67 ~132 stone
fill ~17 ~68 ~132 ~19 ~70 ~132 dirt
fill ~17 ~71 ~132 ~19 ~71 ~132 grass_block
fill ~20 ~60 ~132 ~22 ~66 ~132 stone
fill ~20 ~67 ~132 ~22 ~69 ~132 dirt
fill ~20 ~70 ~132 ~22 ~70 ~132 grass_block
fill ~23 ~60 ~132 ~26 ~67 ~132 stone
fill ~23 ~68 ~132 ~26 ~70 ~132 dirt
fill ~23 ~71 ~132 ~26 ~71 ~132 grass_block
fill ~27 ~60 ~132 ~29 ~66 ~132 stone
fill ~27 ~67 ~132 ~29 ~69 ~132 dirt
fill ~27 ~70 ~132 ~29 ~70 ~132 grass_block
fill ~30 ~60 ~132 ~31 ~65 ~132 stone
fill ~30 ~66 ~132 ~31 ~68 ~132 dirt
fill ~30 ~69 ~132 ~31 ~69 ~132 grass_block
fill ~16 ~60 ~133 ~17 ~68 ~133 stone
fill ~16 ~69 ~133 ~17 ~71 ~133 dirt
fill ~16 ~72 ~133 ~17 ~72 ~133 grass_block
fill ~18 ~60 ~133 ~22 ~67 ~133 stone
fill ~18 ~68 ~133 ~22 ~70 ~133 dirt
fill ~18 ~71 ~133 ~22 ~71 ~133 grass_block
fill ~23 ~60 ~133 ~24 ~68 ~133 stone
fill ~23 ~69 ~133 ~24 ~71 ~133 dirt
fill ~23 ~72 ~133 ~24 ~72 ~133 grass_block
fill ~25 ~60 ~133 ~27 ~67 ~133 stone
fill ~25 ~68 ~133 ~27 ~70 ~133 dirt
fill ~25 ~71 ~133 ~27 ~71 ~133 grass_block
fill ~28 ~60 ~133 ~29 ~66 ~133 stone
fill ~28 ~67 ~133 ~29 ~69 ~133 dirt
fill ~28 ~70 ~133 ~29 ~70 ~133 grass_block
fill ~30 ~60 ~133 ~31 ~65 ~133 stone
fill ~30 ~66 ~133 ~31 ~68 ~133 dirt
fill ~30 ~69 ~133 ~31 ~69 ~133 grass_block
fill ~16 ~60 ~134 ~25 ~68 ~134 stone
fill ~16 ~69 ~134 ~25 ~71 ~134 dirt
fill ~16 ~72 ~134 ~25 ~72 ~134 grass_block
fill ~26 ~60 ~134 ~28 ~67 ~134 stone
fill ~26 ~68 ~134 ~28 ~70 ~134 dirt
fill ~26 ~71 ~134 ~28 ~71 ~134 grass_block
fill ~29 ~60 ~134 ~30 ~66 ~134 stone
fill ~29 ~67 ~134 ~30 ~69 ~134 dirt
fill ~29 ~70 ~134 ~30 ~70 ~134 grass_block
fill ~31 ~60 ~134 ~31 ~65 ~134 stone
fill ~31 ~66 ~134 ~31 ~68 ~134 dirt
fill ~31 ~69 ~134 ~31 ~69 ~134 grass_block
fill ~16 ~60 ~135 ~21 ~69 ~135 stone
fill ~16 ~70 ~135 ~21 ~72 ~135 dirt
fill ~16 ~73 ~135 ~21 ~73 ~135 grass_block
fill ~22 ~60 ~135 ~25 ~68 ~135 stone
fill ~22 ~69 ~135 ~25 ~71 ~135 dirt
fill ~22 ~72 ~135 ~25 ~72 ~135 grass_block
fill ~26 ~60 ~135 ~28 ~67 ~135 stone
fill ~26 ~68 ~135 ~28 ~70 ~135 dirt
fill ~26 ~71 ~135 ~28 ~71 ~135 grass_block
fill ~29 ~60 ~135 ~31 ~66 ~135 stone
fill ~29 ~67 ~135 ~31 ~69 ~135 dirt
fill ~29 ~70 ~135 ~31 ~70 ~135 grass_block
fill ~16 ~60 ~136 ~22 ~69 ~136 stone
fill ~16 ~70 ~136 ~22 ~72 ~136 dirt
fill ~16 ~73 ~136 ~22 ~73 ~136 grass_block
fill ~23 ~60 ~136 ~25 ~68 ~136 stone
fill ~23 ~69 ~136 ~25 ~71 ~136 dirt
fill ~23 ~72 ~136 ~25 ~72 ~136 grass_block
fill ~26 ~60 ~136 ~29 ~67 ~136 stone
fill ~26 ~68 ~136 ~29 ~70 ~136 dirt
fill ~26 ~71 ~136 ~29 ~71 ~136 grass_block
fill ~30 ~60 ~136 ~31 ~66 ~136 stone
fill ~30 ~67 ~136 ~31 ~69 ~136 dirt
fill ~30 ~70 ~136 ~31 ~70 ~136 grass_block
fill ~16 ~60 ~137 ~19 ~70 ~137 stone
fill ~16 ~71 ~137 ~19 ~73 ~137 dirt
fill ~16 ~74 ~137 ~19 ~74 ~137 grass_block
fill ~20 ~60 ~137 ~23 ~69 ~137 stone
fill ~20 ~70 ~137 ~23 ~72 ~137 dirt
fill ~20 ~73 ~137 ~23 ~73 ~137 grass_block
fill ~24 ~60 ~137 ~27 ~68 ~137 stone
fill ~24 ~69 ~137 ~27 ~71 ~137 dirt
fill ~24 ~72 ~137 ~27 ~72 ~137 grass_block
fill ~28 ~60 ~137 ~29 ~67 ~137 stone
fill ~28 ~68 ~137 ~29 ~70 ~137 dirt
fill ~28 ~71 ~137 ~29 ~71 ~137 grass_block
fill ~30 ~60 ~137 ~31 ~66 ~137 stone
fill ~30 ~67 ~137 ~31 ~69 ~137 dirt
fill ~30 ~70 ~137 ~31 ~70 ~137 grass_block
fill ~16 ~60 ~138 ~20 ~70 ~138 stone
fill ~16 ~71 ~138 ~20 ~73 ~138 dirt
fill ~16 ~74 ~138 ~20 ~74 ~138 grass_block
fill ~21 ~60 ~138 ~23 ~69 ~138 stone
fill ~21 ~70 ~138 ~23 ~72 ~138 dirt
fill ~21 ~73 ~138 ~23 ~73 ~138 grass_block
fill ~24 ~60 ~138 ~27 ~68 ~138 stone
fill ~24 ~69 ~138 ~27 ~71 ~138 dirt
fill ~24 ~72 ~138 ~27 ~72 ~138 grass_block
fill ~28 ~60 ~138 ~31 ~67 ~138 stone
fill ~28 ~68 ~138 ~31 ~70 ~138 dirt
fill ~28 ~71 ~138 ~31 ~71 ~138 grass_block
fill ~16 ~60 ~139 ~21 ~70 ~139 stone
fill ~16 ~71 ~139 ~21 ~73 ~139 dirt
fill ~16 ~74 ~139 ~21 ~74 ~139 grass_block
fill ~22 ~60 ~139 ~24 ~69 ~139 stone
fill ~22 ~70 ~139 ~24 ~72 ~139 dirt
fill ~22 ~73 ~139 ~24 ~73 ~139 grass_block
fill ~25 ~60 ~139 ~31 ~68 ~139 stone
fill ~25 ~69 ~139 ~31 ~71 ~139 dirt
fill ~25 ~72 ~139 ~31 ~72 ~139 grass_block
fill ~16 ~60 ~140 ~21 ~70 ~140 stone
fill ~16 ~71 ~140 ~21 ~73 ~140 dirt
fill ~16 ~74 ~140 ~21 ~74 ~140 grass_block
fill ~22 ~60 ~140 ~24 ~69 ~140 stone
fill ~22 ~70 ~140 ~24 ~72 ~140 dirt
fill ~22 ~73 ~140 ~24 ~73 ~140 grass_block
fill ~25 ~60 ~140 ~31 ~68 ~140 stone
fill ~25 ~69 ~140 ~31 ~71 ~140 dirt
fill ~25 ~72 ~140 ~31 ~72 ~140 grass_block
fill ~16 ~60 ~141 ~16 ~69 ~141 stone
fill ~16 ~70 ~141 ~16 ~72 ~141 dirt
fill ~16 ~73 ~141 ~16 ~73 ~141 grass_block
fill ~17 ~60 ~141 ~22 ~70 ~141 stone
fill ~17 ~71 ~141 ~22 ~73 ~141 dirt
fill ~17 ~74 ~141 ~22 ~74 ~141 grass_block
fill ~23 ~60 ~141 ~28 ~69 ~141 stone
fill ~23 ~70 ~141 ~28 ~72 ~141 dirt
fill ~23 ~73 ~141 ~28 ~73 ~141 grass_block
fill ~29 ~60 ~141 ~29 ~68 ~141 stone
fill ~29 ~69 ~141 ~29 ~71 ~141 dirt
fill ~29 ~72 ~141 ~29 ~72 ~141 grass_block
fill ~30 ~60 ~141 ~31 ~69 ~141 stone
fill ~30 ~70 ~141 ~31 ~72 ~141 dirt
fill ~30 ~73 ~141 ~31 ~73 ~141 grass_block
fill ~16 ~60 ~142 ~16 ~69 ~142 stone
fill ~16 ~70 ~142 ~16 ~72 ~142 dirt
fill ~16 ~73 ~142 ~16 ~73 ~142 grass_block
fill ~17 ~60 ~142 ~27 ~70 ~142 stone
fill ~17 ~71 ~142 ~27 ~73 ~142 dirt
fill ~17 ~74 ~142 ~27 ~74 ~142 grass_block
fill ~28 ~60 ~142 ~31 ~69 ~142 stone
fill ~28 ~70 ~142 ~31 ~72 ~142 dirt
fill ~28 ~73 ~142 ~31 ~73 ~142 grass_block
fill ~16 ~60 ~143 ~18 ~69 ~143 stone
fill ~16 ~70 ~143 ~18 ~72 ~143 dirt
fill ~16 ~73 ~143 ~18 ~73 ~143 grass_block
fill ~19 ~60 ~143 ~31 ~70 ~143 stone
fill ~19 ~71 ~143 ~31 ~73 ~143 dirt
fill ~19 ~74 ~143 ~31 ~74 ~143 grass_block