fill ~288 ~60 ~0 ~288 ~65 ~0 stone
fill ~288 ~66 ~0 ~288 ~68 ~0 dirt
fill ~288 ~69 ~0 ~288 ~69 ~0 grass_block
fill ~289 ~60 ~0 ~291 ~66 ~0 stone
fill ~289 ~67 ~0 ~291 ~69 ~0 dirt
fill ~289 ~70 ~0 ~291 ~70 ~0 grass_block
fill ~292 ~60 ~0 ~292 ~65 ~0 stone
fill ~292 ~66 ~0 ~292 ~68 ~0 dirt
fill ~292 ~69 ~0 ~292 ~69 ~0 grass_block
fill ~293 ~60 ~0 ~294 ~66 ~0 stone
fill ~293 ~67 ~0 ~294 ~69 ~0 dirt
fill ~293 ~70 ~0 ~294 ~70 ~0 grass_block
fill ~295 ~60 ~0 ~299 ~65 ~0 stone
fill ~295 ~66 ~0 ~299 ~68 ~0 dirt
fill ~295 ~69 ~0 ~299 ~69 ~0 grass_block
fill ~300 ~60 ~0 ~302 ~64 ~0 stone
fill ~300 ~65 ~0 ~302 ~67 ~0 dirt
fill ~300 ~68 ~0 ~302 ~68 ~0 grass_block
fill ~303 ~60 ~0 ~303 ~63 ~0 stone
fill ~303 ~64 ~0 ~303 ~66 ~0 dirt
fill ~303 ~67 ~0 ~303 ~67 ~0 grass_block
fill ~288 ~60 ~1 ~294 ~65 ~1 stone
fill ~288 ~66 ~1 ~294 ~68 ~1 dirt
fill ~288 ~69 ~1 ~294 ~69 ~1 grass_block
fill ~295 ~60 ~1 ~296 ~66 ~1 stone
fill ~295 ~67 ~1 ~296 ~69 ~1 dirt
fill ~295 ~70 ~1 ~296 ~70 ~1 grass_block
fill ~297 ~60 ~1 ~298 ~65 ~1 stone
fill ~297 ~66 ~1 ~298 ~68 ~1 dirt
fill ~297 ~69 ~1 ~298 ~69 ~1 grass_block
fill ~299 ~60 ~1 ~303 ~64 ~1 stone
fill ~299 ~65 ~1 ~303 ~67 ~1 dirt
fill ~299 ~68 ~1 ~303 ~68 ~1 grass_block
fill ~288 ~60 ~2 ~300 ~65 ~2 stone
fill ~288 ~66 ~2 ~300 ~68 ~2 dirt
fill ~288 ~69 ~2 ~300 ~69 ~2 grass_block
fill ~301 ~60 ~2 ~301 ~64 ~2 stone
fill ~301 ~65 ~2 ~301 ~67 ~2 dirt
fill ~301 ~68 ~2 ~301 ~68 ~2 grass_block
fill ~302 ~60 ~2 ~303 ~65 ~2 stone
fill ~302 ~66 ~2 ~303 ~68 ~2 dirt
fill ~302 ~69 ~2 ~303 ~69 ~2 grass_block
fill ~288 ~60 ~3 ~288 ~64 ~3 stone
fill ~288 ~65 ~3 ~288 ~67 ~3 dirt
fill ~288 ~68 ~3 ~288 ~68 ~3 grass_block
fill ~289 ~60 ~3 ~297 ~65 ~3 stone
fill ~289 ~66 ~3 ~297 ~68 ~3 dirt
fill ~289 ~69 ~3 ~297 ~69 ~3 grass_block
fill ~298 ~60 ~3 ~298 ~66 ~3 stone
fill ~298 ~67 ~3 ~298 ~69 ~3 dirt
fill ~298 ~70 ~3 ~298 ~70 ~3 grass_block
fill ~299 ~60 ~3 ~303 ~65 ~3 stone
fill ~299 ~66 ~3 ~303 ~68 ~3 dirt
fill ~299 ~69 ~3 ~303 ~69 ~3 grass_block
fill ~288 ~60 ~4 ~290 ~64 ~4 stone
fill ~288 ~65 ~4 ~290 ~67 ~4 dirt
fill ~288 ~68 ~4 ~290 ~68 ~4 grass_block
fill ~291 ~60 ~4 ~303 ~65 ~4 stone
fill ~291 ~66 ~4 ~303 ~68 ~4 dirt
fill ~291 ~69 ~4 ~303 ~69 ~4 grass_block
fill ~288 ~60 ~5 ~291 ~64 ~5 stone
fill ~288 ~65 ~5 ~291 ~67 ~5 dirt
fill ~288 ~68 ~5 ~291 ~68 ~5 grass_block
fill ~292 ~60 ~5 ~303 ~65 ~5 stone
fill ~292 ~66 ~5 ~303 ~68 ~5 dirt
fill ~292 ~69 ~5 ~303 ~69 ~5 grass_block
fill ~288 ~60 ~6 ~292 ~64 ~6 stone
fill ~288 ~65 ~6 ~292 ~67 ~6 dirt
fill ~288 ~68 ~6 ~292 ~68 ~6 grass_block
fill ~293 ~60 ~6 ~303 ~65 ~6 stone
fill ~293 ~66 ~6 ~303 ~68 ~6 dirt
fill ~293 ~69 ~6 ~303 ~69 ~6 grass_block
fill ~288 ~60 ~7 ~291 ~64 ~7 stone
fill ~288 ~65 ~7 ~291 ~67 ~7 dirt
fill ~288 ~68 ~7 ~291 ~68 ~7 grass_block
fill ~292 ~60 ~7 ~303 ~65 ~7 stone
fill ~292 ~66 ~7 ~303 ~68 ~7 dirt
fill ~292 ~69 ~7 ~303 ~69 ~7 grass_block
fill ~288 ~60 ~8 ~293 ~64 ~8 stone
fill ~288 ~65 ~8 ~293 ~67 ~8 dirt
fill ~288 ~68 ~8 ~293 ~68 ~8 grass_block
fill ~294 ~60 ~8 ~303 ~65 ~8 stone
fill ~294 ~66 ~8 ~303 ~68 ~8 dirt
fill ~294 ~69 ~8 ~303 ~69 ~8 grass_block
fill ~288 ~60 ~9 ~294 ~64 ~9 stone
fill ~288 ~65 ~9 ~294 ~67 ~9 dirt
fill ~288 ~68 ~9 ~294 ~68 ~9 grass_block
fill ~295 ~60 ~9 ~300 ~65 ~9 stone
fill ~295 ~66 ~9 ~300 ~68 ~9 dirt
fill ~295 ~69 ~9 ~300 ~69 ~9 grass_block
fill ~301 ~60 ~9 ~302 ~64 ~9 stone
fill ~301 ~65 ~9 ~302 ~67 ~9 dirt
fill ~301 ~68 ~9 ~302 ~68 ~9 grass_block
fill ~303 ~60 ~9 ~303 ~65 ~9 stone
fill ~303 ~66 ~9 ~303 ~68 ~9 dirt
fill ~303 ~69 ~9 ~303 ~69 ~9 grass_block
fill ~288 ~60 ~10 ~297 ~64 ~10 stone
fill ~288 ~65 ~10 ~297 ~67 ~10 dirt
fill ~288 ~68 ~10 ~297 ~68 ~10 grass_block
fill ~298 ~60 ~10 ~298 ~65 ~10 stone
fill ~298 ~66 ~10 ~298 ~68 ~10 dirt
fill ~298 ~69 ~10 ~298 ~69 ~10 grass_block
fill ~299 ~60 ~10 ~303 ~64 ~10 stone
fill ~299 ~65 ~10 ~303 ~67 ~10 dirt
fill ~299 ~68 ~10 ~303 ~68 ~10 grass_block
fill ~288 ~60 ~11 ~303 ~64 ~11 stone
fill ~288 ~65 ~11 ~303 ~67 ~11 dirt
fill ~288 ~68 ~11 ~303 ~68 ~11 grass_block
fill ~288 ~60 ~12 ~302 ~64 ~12 stone
fill ~288 ~65 ~12 ~302 ~67 ~12 dirt
fill ~288 ~68 ~12 ~302 ~68 ~12 grass_block
fill ~303 ~60 ~12 ~303 ~65 ~12 stone
fill ~303 ~66 ~12 ~303 ~68 ~12 dirt
fill ~303 ~69 ~12 ~303 ~69 ~12 grass_block
fill ~288 ~60 ~13 ~299 ~64 ~13 stone
fill ~288 ~65 ~13 ~299 ~67 ~13 dirt
fill ~288 ~68 ~13 ~299 ~68 ~13 grass_block
fill ~300 ~60 ~13 ~300 ~63 ~13 stone
fill ~300 ~64 ~13 ~300 ~66 ~13 dirt
fill ~300 ~67 ~13 ~300 ~67 ~13 grass_block
fill ~301 ~60 ~13 ~303 ~64 ~13 stone
fill ~301 ~65 ~13 ~303 ~67 ~13 dirt
fill ~301 ~68 ~13 ~303 ~68 ~13 grass_block
fill ~288 ~60 ~14 ~288 ~63 ~14 stone
fill ~288 ~64 ~14 ~288 ~66 ~14 dirt
fill ~288 ~67 ~14 ~288 ~67 ~14 grass_block
fill ~289 ~60 ~14 ~295 ~64 ~14 stone
fill ~289 ~65 ~14 ~295 ~67 ~14 dirt
fill ~289 ~68 ~14 ~295 ~68 ~14 grass_block
fill ~296 ~60 ~14 ~299 ~63 ~14 stone
fill ~296 ~64 ~14 ~299 ~66 ~14 dirt
fill ~296 ~67 ~14 ~299 ~67 ~14 grass_block
fill ~300 ~60 ~14 ~303 ~64 ~14 stone
fill ~300 ~65 ~14 ~303 ~67 ~14 dirt
fill ~300 ~68 ~14 ~303 ~68 ~14 grass_block
fill ~288 ~60 ~15 ~294 ~64 ~15 stone
fill ~288 ~65 ~15 ~294 ~67 ~15 dirt
fill ~288 ~68 ~15 ~294 ~68 ~15 grass_block
fill ~295 ~60 ~15 ~299 ~63 ~15 stone
fill ~295 ~64 ~15 ~299 ~66 ~15 dirt
fill ~295 ~67 ~15 ~299 ~67 ~15 grass_block
fill ~300 ~60 ~15 ~303 ~64 ~15 stone
fill ~300 ~65 ~15 ~303 ~67 ~15 dirt
fill ~300 ~68 ~15 ~303 ~68 ~15 grass_block