fill ~64 ~60 ~16 ~65 ~65 ~16 stone
fill ~64 ~66 ~16 ~65 ~68 ~16 dirt
fill ~64 ~69 ~16 ~65 ~69 ~16 grass_block
fill ~66 ~60 ~16 ~72 ~64 ~16 stone
fill ~66 ~65 ~16 ~72 ~67 ~16 dirt
fill ~66 ~68 ~16 ~72 ~68 ~16 grass_block
fill ~73 ~60 ~16 ~74 ~65 ~16 stone
fill ~73 ~66 ~16 ~74 ~68 ~16 dirt
fill ~73 ~69 ~16 ~74 ~69 ~16 grass_block
fill ~75 ~60 ~16 ~76 ~66 ~16 stone
fill ~75 ~67 ~16 ~76 ~69 ~16 dirt
fill ~75 ~70 ~16 ~76 ~70 ~16 grass_block
fill ~77 ~60 ~16 ~79 ~67 ~16 stone
fill ~77 ~68 ~16 ~79 ~70 ~16 dirt
fill ~77 ~71 ~16 ~79 ~71 ~16 grass_block
fill ~64 ~60 ~17 ~65 ~65 ~17 stone
fill ~64 ~66 ~17 ~65 ~68 ~17 dirt
fill ~64 ~69 ~17 ~65 ~69 ~17 grass_block
fill ~66 ~60 ~17 ~72 ~64 ~17 stone
fill ~66 ~65 ~17 ~72 ~67 ~17 dirt
fill ~66 ~68 ~17 ~72 ~68 ~17 grass_block
fill ~73 ~60 ~17 ~74 ~65 ~17 stone
fill ~73 ~66 ~17 ~74 ~68 ~17 dirt
fill ~73 ~69 ~17 ~74 ~69 ~17 grass_block
fill ~75 ~60 ~17 ~79 ~66 ~17 stone
fill ~75 ~67 ~17 ~79 ~69 ~17 dirt
fill ~75 ~70 ~17 ~79 ~70 ~17 grass_block
fill ~64 ~60 ~18 ~65 ~65 ~18 stone
fill ~64 ~66 ~18 ~65 ~68 ~18 dirt
fill ~64 ~69 ~18 ~65 ~69 ~18 grass_block
fill ~66 ~60 ~18 ~72 ~64 ~18 stone
fill ~66 ~65 ~18 ~72 ~67 ~18 dirt
fill ~66 ~68 ~18 ~72 ~68 ~18 grass_block
fill ~73 ~60 ~18 ~75 ~65 ~18 stone
fill ~73 ~66 ~18 ~75 ~68 ~18 dirt
fill ~73 ~69 ~18 ~75 ~69 ~18 grass_block
fill ~76 ~60 ~18 ~79 ~66 ~18 stone
fill ~76 ~67 ~18 ~79 ~69 ~18 dirt
fill ~76 ~70 ~18 ~79 ~70 ~18 grass_block
fill ~64 ~60 ~19 ~65 ~64 ~19 stone
fill ~64 ~65 ~19 ~65 ~67 ~19 dirt
fill ~64 ~68 ~19 ~65 ~68 ~19 grass_block
fill ~66 ~60 ~19 ~66 ~65 ~19 stone
fill ~66 ~66 ~19 ~66 ~68 ~19 dirt
fill ~66 ~69 ~19 ~66 ~69 ~19 grass_block
fill ~67 ~60 ~19 ~73 ~64 ~19 stone
fill ~67 ~65 ~19 ~73 ~67 ~19 dirt
fill ~67 ~68 ~19 ~73 ~68 ~19 grass_block
fill ~74 ~60 ~19 ~79 ~65 ~19 stone
fill ~74 ~66 ~19 ~79 ~68 ~19 dirt
fill ~74 ~69 ~19 ~79 ~69 ~19 grass_block
fill ~64 ~60 ~20 ~69 ~64 ~20 stone
fill ~64 ~65 ~20 ~69 ~67 ~20 dirt
fill ~64 ~68 ~20 ~69 ~68 ~20 grass_block
fill ~70 ~60 ~20 ~71 ~63 ~20 stone
fill ~70 ~64 ~20 ~71 ~66 ~20 dirt
fill ~70 ~67 ~20 ~71 ~67 ~20 grass_block
fill ~72 ~60 ~20 ~77 ~64 ~20 stone
fill ~72 ~65 ~20 ~77 ~67 ~20 dirt
fill ~72 ~68 ~20 ~77 ~68 ~20 grass_block
fill ~78 ~60 ~20 ~79 ~65 ~20 stone
fill ~78 ~66 ~20 ~79 ~68 ~20 dirt
fill ~78 ~69 ~20 ~79 ~69 ~20 grass_block
fill ~64 ~60 ~21 ~70 ~64 ~21 stone
fill ~64 ~65 ~21 ~70 ~67 ~21 dirt
fill ~64 ~68 ~21 ~70 ~68 ~21 grass_block
fill ~71 ~60 ~21 ~72 ~63 ~21 stone
fill ~71 ~64 ~21 ~72 ~66 ~21 dirt
fill ~71 ~67 ~21 ~72 ~67 ~21 grass_block
fill ~73 ~60 ~21 ~76 ~64 ~21 stone
fill ~73 ~65 ~21 ~76 ~67 ~21 dirt
fill ~73 ~68 ~21 ~76 ~68 ~21 grass_block
fill ~77 ~60 ~21 ~79 ~65 ~21 stone
fill ~77 ~66 ~21 ~79 ~68 ~21 dirt
fill ~77 ~69 ~21 ~79 ~69 ~21 grass_block
fill ~64 ~60 ~22 ~66 ~63 ~22 stone
fill ~64 ~64 ~22 ~66 ~66 ~22 dirt
fill ~64 ~67 ~22 ~66 ~67 ~22 grass_block
fill ~67 ~60 ~22 ~70 ~64 ~22 stone
fill ~67 ~65 ~22 ~70 ~67 ~22 dirt
fill ~67 ~68 ~22 ~70 ~68 ~22 grass_block
fill ~71 ~60 ~22 ~73 ~63 ~22 stone
fill ~71 ~64 ~22 ~73 ~66 ~22 dirt
fill ~71 ~67 ~22 ~73 ~67 ~22 grass_block
fill ~74 ~60 ~22 ~76 ~64 ~22 stone
fill ~74 ~65 ~22 ~76 ~67 ~22 dirt
fill ~74 ~68 ~22 ~76 ~68 ~22 grass_block
fill ~77 ~60 ~22 ~79 ~65 ~22 stone
fill ~77 ~66 ~22 ~79 ~68 ~22 dirt
fill ~77 ~69 ~22 ~79 ~69 ~22 grass_block
fill ~64 ~60 ~23 ~67 ~63 ~23 stone
fill ~64 ~64 ~23 ~67 ~66 ~23 dirt
fill ~64 ~67 ~23 ~67 ~67 ~23 grass_block
fill ~68 ~60 ~23 ~70 ~64 ~23 stone
fill ~68 ~65 ~23 ~70 ~67 ~23 dirt
fill ~68 ~68 ~23 ~70 ~68 ~23 grass_block
fill ~71 ~60 ~23 ~73 ~63 ~23 stone
fill ~71 ~64 ~23 ~73 ~66 ~23 dirt
fill ~71 ~67 ~23 ~73 ~67 ~23 grass_block
fill ~74 ~60 ~23 ~75 ~64 ~23 stone
fill ~74 ~65 ~23 ~75 ~67 ~23 dirt
fill ~74 ~68 ~23 ~75 ~68 ~23 grass_block
fill ~76 ~60 ~23 ~79 ~65 ~23 stone
fill ~76 ~66 ~23 ~79 ~68 ~23 dirt
fill ~76 ~69 ~23 ~79 ~69 ~23 grass_block
fill ~64 ~60 ~24 ~69 ~63 ~24 stone
fill ~64 ~64 ~24 ~69 ~66 ~24 dirt
fill ~64 ~67 ~24 ~69 ~67 ~24 grass_block
fill ~70 ~60 ~24 ~70 ~64 ~24 stone
fill ~70 ~65 ~24 ~70 ~67 ~24 dirt
fill ~70 ~68 ~24 ~70 ~68 ~24 grass_block
fill ~71 ~60 ~24 ~73 ~63 ~24 stone
fill ~71 ~64 ~24 ~73 ~66 ~24 dirt
fill ~71 ~67 ~24 ~73 ~67 ~24 grass_block
fill ~74 ~60 ~24 ~75 ~64 ~24 stone
fill ~74 ~65 ~24 ~75 ~67 ~24 dirt
fill ~74 ~68 ~24 ~75 ~68 ~24 grass_block
fill ~76 ~60 ~24 ~79 ~65 ~24 stone
fill ~76 ~66 ~24 ~79 ~68 ~24 dirt
fill ~76 ~69 ~24 ~79 ~69 ~24 grass_block
fill ~64 ~60 ~25 ~74 ~63 ~25 stone
fill ~64 ~64 ~25 ~74 ~66 ~25 dirt
fill ~64 ~67 ~25 ~74 ~67 ~25 grass_block
fill ~75 ~60 ~25 ~75 ~64 ~25 stone
fill ~75 ~65 ~25 ~75 ~67 ~25 dirt
fill ~75 ~68 ~25 ~75 ~68 ~25 grass_block
fill ~76 ~60 ~25 ~79 ~65 ~25 stone
fill ~76 ~66 ~25 ~79 ~68 ~25 dirt
fill ~76 ~69 ~25 ~79 ~69 ~25 grass_block
fill ~64 ~60 ~26 ~64 ~64 ~26 stone
fill ~64 ~65 ~26 ~64 ~67 ~26 dirt
fill ~64 ~68 ~26 ~64 ~68 ~26 grass_block
fill ~65 ~60 ~26 ~74 ~63 ~26 stone
fill ~65 ~64 ~26 ~74 ~66 ~26 dirt
fill ~65 ~67 ~26 ~74 ~67 ~26 grass_block
fill ~75 ~60 ~26 ~76 ~64 ~26 stone
fill ~75 ~65 ~26 ~76 ~67 ~26 dirt
fill ~75 ~68 ~26 ~76 ~68 ~26 grass_block
fill ~77 ~60 ~26 ~79 ~65 ~26 stone
fill ~77 ~66 ~26 ~79 ~68 ~26 dirt
fill ~77 ~69 ~26 ~79 ~69 ~26 grass_block
fill ~64 ~60 ~27 ~65 ~64 ~27 stone
fill ~64 ~65 ~27 ~65 ~67 ~27 dirt
fill ~64 ~68 ~27 ~65 ~68 ~27 grass_block
fill ~66 ~60 ~27 ~74 ~63 ~27 stone
fill ~66 ~64 ~27 ~74 ~66 ~27 dirt
fill ~66 ~67 ~27 ~74 ~67 ~27 grass_block
fill ~75 ~60 ~27 ~77 ~64 ~27 stone
fill ~75 ~65 ~27 ~77 ~67 ~27 dirt
fill ~75 ~68 ~27 ~77 ~68 ~27 grass_block
fill ~78 ~60 ~27 ~78 ~65 ~27 stone
fill ~78 ~66 ~27 ~78 ~68 ~27 dirt
fill ~78 ~69 ~27 ~78 ~69 ~27 grass_block
fill ~79 ~60 ~27 ~79 ~64 ~27 stone
fill ~79 ~65 ~27 ~79 ~67 ~27 dirt
fill ~79 ~68 ~27 ~79 ~68 ~27 grass_block
fill ~64 ~60 ~28 ~65 ~64 ~28 stone
fill ~64 ~65 ~28 ~65 ~67 ~28 dirt
fill ~64 ~68 ~28 ~65 ~68 ~28 grass_block
fill ~66 ~60 ~28 ~75 ~63 ~28 stone
fill ~66 ~64 ~28 ~75 ~66 ~28 dirt
fill ~66 ~67 ~28 ~75 ~67 ~28 grass_block
fill ~76 ~60 ~28 ~79 ~64 ~28 stone
fill ~76 ~65 ~28 ~79 ~67 ~28 dirt
fill ~76 ~68 ~28 ~79 ~68 ~28 grass_block
fill ~64 ~60 ~29 ~66 ~64 ~29 stone
fill ~64 ~65 ~29 ~66 ~67 ~29 dirt
fill ~64 ~68 ~29 ~66 ~68 ~29 grass_block
fill ~67 ~60 ~29 ~75 ~63 ~29 stone
fill ~67 ~64 ~29 ~75 ~66 ~29 dirt
fill ~67 ~67 ~29 ~75 ~67 ~29 grass_block
fill ~76 ~60 ~29 ~79 ~64 ~29 stone
fill ~76 ~65 ~29 ~79 ~67 ~29 dirt
fill ~76 ~68 ~29 ~79 ~68 ~29 grass_block
fill ~64 ~60 ~30 ~64 ~65 ~30 stone
fill ~64 ~66 ~30 ~64 ~68 ~30 dirt
fill ~64 ~69 ~30 ~64 ~69 ~30 grass_block
fill ~65 ~60 ~30 ~67 ~64 ~30 stone
fill ~65 ~65 ~30 ~67 ~67 ~30 dirt
fill ~65 ~68 ~30 ~67 ~68 ~30 grass_block
fill ~68 ~60 ~30 ~75 ~63 ~30 stone
fill ~68 ~64 ~30 ~75 ~66 ~30 dirt
fill ~68 ~67 ~30 ~75 ~67 ~30 grass_block
fill ~76 ~60 ~30 ~79 ~64 ~30 stone
fill ~76 ~65 ~30 ~79 ~67 ~30 dirt
fill ~76 ~68 ~30 ~79 ~68 ~30 grass_block
fill ~64 ~60 ~31 ~65 ~65 ~31 stone
fill ~64 ~66 ~31 ~65 ~68 ~31 dirt
fill ~64 ~69 ~31 ~65 ~69 ~31 grass_block
fill ~66 ~60 ~31 ~68 ~64 ~31 stone
fill ~66 ~65 ~31 ~68 ~67 ~31 dirt
fill ~66 ~68 ~31 ~68 ~68 ~31 grass_block
fill ~69 ~60 ~31 ~78 ~63 ~31 stone
fill ~69 ~64 ~31 ~78 ~66 ~31 dirt
fill ~69 ~67 ~31 ~78 ~67 ~31 grass_block
fill ~79 ~60 ~31 ~79 ~64 ~31 stone
fill ~79 ~65 ~31 ~79 ~67 ~31 dirt
fill ~79 ~68 ~31 ~79 ~68 ~31 grass_block