fill ~400 ~60 ~128 ~406 ~63 ~128 stone
fill ~400 ~64 ~128 ~406 ~66 ~128 dirt
fill ~400 ~67 ~128 ~406 ~67 ~128 grass_block
fill ~407 ~60 ~128 ~411 ~62 ~128 stone
fill ~407 ~63 ~128 ~411 ~65 ~128 dirt
fill ~407 ~66 ~128 ~411 ~66 ~128 grass_block
fill ~412 ~60 ~128 ~414 ~63 ~128 stone
fill ~412 ~64 ~128 ~414 ~66 ~128 dirt
fill ~412 ~67 ~128 ~414 ~67 ~128 grass_block
fill ~415 ~60 ~128 ~415 ~64 ~128 stone
fill ~415 ~65 ~128 ~415 ~67 ~128 dirt
fill ~415 ~68 ~128 ~415 ~68 ~128 grass_block
fill ~400 ~60 ~129 ~404 ~63 ~129 stone
fill ~400 ~64 ~129 ~404 ~66 ~129 dirt
fill ~400 ~67 ~129 ~404 ~67 ~129 grass_block
fill ~405 ~60 ~129 ~411 ~62 ~129 stone
fill ~405 ~63 ~129 ~411 ~65 ~129 dirt
fill ~405 ~66 ~129 ~411 ~66 ~129 grass_block
fill ~412 ~60 ~129 ~415 ~63 ~129 stone
fill ~412 ~64 ~129 ~415 ~66 ~129 dirt
fill ~412 ~67 ~129 ~415 ~67 ~129 grass_block
fill ~400 ~60 ~130 ~403 ~63 ~130 stone
fill ~400 ~64 ~130 ~403 ~66 ~130 dirt
fill ~400 ~67 ~130 ~403 ~67 ~130 grass_block
fill ~404 ~60 ~130 ~412 ~62 ~130 stone
fill ~404 ~63 ~130 ~412 ~65 ~130 dirt
fill ~404 ~66 ~130 ~412 ~66 ~130 grass_block
fill ~413 ~60 ~130 ~415 ~63 ~130 stone
fill ~413 ~64 ~130 ~415 ~66 ~130 dirt
fill ~413 ~67 ~130 ~415 ~67 ~130 grass_block
fill ~400 ~60 ~131 ~403 ~63 ~131 stone
fill ~400 ~64 ~131 ~403 ~66 ~131 dirt
fill ~400 ~67 ~131 ~403 ~67 ~131 grass_block
fill ~404 ~60 ~131 ~407 ~62 ~131 stone
fill ~404 ~63 ~131 ~407 ~65 ~131 dirt
fill ~404 ~66 ~131 ~407 ~66 ~131 grass_block
fill ~408 ~60 ~131 ~408 ~61 ~131 stone
fill ~408 ~62 ~131 ~408 ~64 ~131 dirt
fill ~408 ~65 ~131 ~408 ~65 ~131 grass_block
fill ~409 ~60 ~131 ~412 ~62 ~131 stone
fill ~409 ~63 ~131 ~412 ~65 ~131 dirt
fill ~409 ~66 ~131 ~412 ~66 ~131 grass_block
fill ~413 ~60 ~131 ~415 ~63 ~131 stone
fill ~413 ~64 ~131 ~415 ~66 ~131 dirt
fill ~413 ~67 ~131 ~415 ~67 ~131 grass_block
fill ~400 ~60 ~132 ~402 ~63 ~132 stone
fill ~400 ~64 ~132 ~402 ~66 ~132 dirt
fill ~400 ~67 ~132 ~402 ~67 ~132 grass_block
fill ~403 ~60 ~132 ~406 ~62 ~132 stone
fill ~403 ~63 ~132 ~406 ~65 ~132 dirt
fill ~403 ~66 ~132 ~406 ~66 ~132 grass_block
fill ~407 ~60 ~132 ~409 ~61 ~132 stone
fill ~407 ~62 ~132 ~409 ~64 ~132 dirt
fill ~407 ~65 ~132 ~409 ~65 ~132 grass_block
fill ~410 ~60 ~132 ~412 ~62 ~132 stone
fill ~410 ~63 ~132 ~412 ~65 ~132 dirt
fill ~410 ~66 ~132 ~412 ~66 ~132 grass_block
fill ~413 ~60 ~132 ~415 ~63 ~132 stone
fill ~413 ~64 ~132 ~415 ~66 ~132 dirt
fill ~413 ~67 ~132 ~415 ~67 ~132 grass_block
fill ~400 ~60 ~133 ~401 ~63 ~133 stone
fill ~400 ~64 ~133 ~401 ~66 ~133 dirt
fill ~400 ~67 ~133 ~401 ~67 ~133 grass_block
fill ~402 ~60 ~133 ~405 ~62 ~133 stone
fill ~402 ~63 ~133 ~405 ~65 ~133 dirt
fill ~402 ~66 ~133 ~405 ~66 ~133 grass_block
fill ~406 ~60 ~133 ~409 ~61 ~133 stone
fill ~406 ~62 ~133 ~409 ~64 ~133 dirt
fill ~406 ~65 ~133 ~409 ~65 ~133 grass_block
fill ~410 ~60 ~133 ~414 ~62 ~133 stone
fill ~410 ~63 ~133 ~414 ~65 ~133 dirt
fill ~410 ~66 ~133 ~414 ~66 ~133 grass_block
fill ~415 ~60 ~133 ~415 ~63 ~133 stone
fill ~415 ~64 ~133 ~415 ~66 ~133 dirt
fill ~415 ~67 ~133 ~415 ~67 ~133 grass_block
fill ~400 ~60 ~134 ~405 ~62 ~134 stone
fill ~400 ~63 ~134 ~405 ~65 ~134 dirt
fill ~400 ~66 ~134 ~405 ~66 ~134 grass_block
fill ~406 ~60 ~134 ~410 ~61 ~134 stone
fill ~406 ~62 ~134 ~410 ~64 ~134 dirt
fill ~406 ~65 ~134 ~410 ~65 ~134 grass_block
fill ~411 ~60 ~134 ~415 ~62 ~134 stone
fill ~411 ~63 ~134 ~415 ~65 ~134 dirt
fill ~411 ~66 ~134 ~415 ~66 ~134 grass_block
fill ~400 ~60 ~135 ~404 ~62 ~135 stone
fill ~400 ~63 ~135 ~404 ~65 ~135 dirt
fill ~400 ~66 ~135 ~404 ~66 ~135 grass_block
fill ~405 ~60 ~135 ~413 ~61 ~135 stone
fill ~405 ~62 ~135 ~413 ~64 ~135 dirt
fill ~405 ~65 ~135 ~413 ~65 ~135 grass_block
fill ~414 ~60 ~135 ~415 ~62 ~135 stone
fill ~414 ~63 ~135 ~415 ~65 ~135 dirt
fill ~414 ~66 ~135 ~415 ~66 ~135 grass_block
fill ~400 ~60 ~136 ~400 ~62 ~136 stone
fill ~400 ~63 ~136 ~400 ~65 ~136 dirt
fill ~400 ~66 ~136 ~400 ~66 ~136 grass_block
fill ~401 ~60 ~136 ~415 ~61 ~136 stone
fill ~401 ~62 ~136 ~415 ~64 ~136 dirt
fill ~401 ~65 ~136 ~415 ~65 ~136 grass_block
fill ~400 ~60 ~137 ~407 ~61 ~137 stone
fill ~400 ~62 ~137 ~407 ~64 ~137 dirt
fill ~400 ~65 ~137 ~407 ~65 ~137 grass_block
fill ~408 ~60 ~137 ~413 ~60 ~137 stone
fill ~408 ~61 ~137 ~413 ~63 ~137 dirt
fill ~408 ~64 ~137 ~413 ~64 ~137 grass_block
fill ~414 ~60 ~137 ~414 ~61 ~137 stone
fill ~414 ~62 ~137 ~414 ~64 ~137 dirt
fill ~414 ~65 ~137 ~414 ~65 ~137 grass_block
fill ~415 ~60 ~137 ~415 ~60 ~137 stone
fill ~415 ~61 ~137 ~415 ~63 ~137 dirt
fill ~415 ~64 ~137 ~415 ~64 ~137 grass_block
fill ~400 ~60 ~138 ~415 ~60 ~138 stone
fill ~400 ~61 ~138 ~415 ~63 ~138 dirt
fill ~400 ~64 ~138 ~415 ~64 ~138 grass_block
fill ~400 ~60 ~139 ~415 ~60 ~139 stone
fill ~400 ~61 ~139 ~415 ~63 ~139 dirt
fill ~400 ~64 ~139 ~415 ~64 ~139 grass_block
fill ~400 ~60 ~140 ~415 ~60 ~140 stone
fill ~400 ~61 ~140 ~415 ~63 ~140 dirt
fill ~400 ~64 ~140 ~415 ~64 ~140 grass_block
fill ~400 ~60 ~141 ~415 ~60 ~141 stone
fill ~400 ~61 ~141 ~415 ~63 ~141 dirt
fill ~400 ~64 ~141 ~415 ~64 ~141 grass_block
fill ~400 ~60 ~142 ~415 ~60 ~142 stone
fill ~400 ~61 ~142 ~415 ~63 ~142 dirt
fill ~400 ~64 ~142 ~415 ~64 ~142 grass_block
fill ~400 ~60 ~143 ~415 ~60 ~143 stone
fill ~400 ~61 ~143 ~415 ~63 ~143 dirt
fill ~400 ~64 ~143 ~415 ~64 ~143 grass_block