fill ~352 ~60 ~112 ~354 ~60 ~112 stone
fill ~352 ~61 ~112 ~354 ~63 ~112 dirt
fill ~352 ~64 ~112 ~354 ~64 ~112 grass_block
fill ~355 ~60 ~112 ~359 ~61 ~112 stone
fill ~355 ~62 ~112 ~359 ~64 ~112 dirt
fill ~355 ~65 ~112 ~359 ~65 ~112 grass_block
fill ~360 ~60 ~112 ~361 ~62 ~112 stone
fill ~360 ~63 ~112 ~361 ~65 ~112 dirt
fill ~360 ~66 ~112 ~361 ~66 ~112 grass_block
fill ~362 ~60 ~112 ~365 ~63 ~112 stone
fill ~362 ~64 ~112 ~365 ~66 ~112 dirt
fill ~362 ~67 ~112 ~365 ~67 ~112 grass_block
fill ~366 ~60 ~112 ~367 ~64 ~112 stone
fill ~366 ~65 ~112 ~367 ~67 ~112 dirt
fill ~366 ~68 ~112 ~367 ~68 ~112 grass_block
fill ~352 ~60 ~113 ~355 ~60 ~113 stone
fill ~352 ~61 ~113 ~355 ~63 ~113 dirt
fill ~352 ~64 ~113 ~355 ~64 ~113 grass_block
fill ~356 ~60 ~113 ~359 ~61 ~113 stone
fill ~356 ~62 ~113 ~359 ~64 ~113 dirt
fill ~356 ~65 ~113 ~359 ~65 ~113 grass_block
fill ~360 ~60 ~113 ~361 ~62 ~113 stone
fill ~360 ~63 ~113 ~361 ~65 ~113 dirt
fill ~360 ~66 ~113 ~361 ~66 ~113 grass_block
fill ~362 ~60 ~113 ~365 ~63 ~113 stone
fill ~362 ~64 ~113 ~365 ~66 ~113 dirt
fill ~362 ~67 ~113 ~365 ~67 ~113 grass_block
fill ~366 ~60 ~113 ~367 ~64 ~113 stone
fill ~366 ~65 ~113 ~367 ~67 ~113 dirt
fill ~366 ~68 ~113 ~367 ~68 ~113 grass_block
fill ~352 ~60 ~114 ~355 ~60 ~114 stone
fill ~352 ~61 ~114 ~355 ~63 ~114 dirt
fill ~352 ~64 ~114 ~355 ~64 ~114 grass_block
fill ~356 ~60 ~114 ~359 ~61 ~114 stone
fill ~356 ~62 ~114 ~359 ~64 ~114 dirt
fill ~356 ~65 ~114 ~359 ~65 ~114 grass_block
fill ~360 ~60 ~114 ~361 ~62 ~114 stone
fill ~360 ~63 ~114 ~361 ~65 ~114 dirt
fill ~360 ~66 ~114 ~361 ~66 ~114 grass_block
fill ~362 ~60 ~114 ~366 ~63 ~114 stone
fill ~362 ~64 ~114 ~366 ~66 ~114 dirt
fill ~362 ~67 ~114 ~366 ~67 ~114 grass_block
fill ~367 ~60 ~114 ~367 ~64 ~114 stone
fill ~367 ~65 ~114 ~367 ~67 ~114 dirt
fill ~367 ~68 ~114 ~367 ~68 ~114 grass_block
fill ~352 ~60 ~115 ~355 ~60 ~115 stone
fill ~352 ~61 ~115 ~355 ~63 ~115 dirt
fill ~352 ~64 ~115 ~355 ~64 ~115 grass_block
fill ~356 ~60 ~115 ~359 ~61 ~115 stone
fill ~356 ~62 ~115 ~359 ~64 ~115 dirt
fill ~356 ~65 ~115 ~359 ~65 ~115 grass_block
fill ~360 ~60 ~115 ~361 ~62 ~115 stone
fill ~360 ~63 ~115 ~361 ~65 ~115 dirt
fill ~360 ~66 ~115 ~361 ~66 ~115 grass_block
fill ~362 ~60 ~115 ~366 ~63 ~115 stone
fill ~362 ~64 ~115 ~366 ~66 ~115 dirt
fill ~362 ~67 ~115 ~366 ~67 ~115 grass_block
fill ~367 ~60 ~115 ~367 ~64 ~115 stone
fill ~367 ~65 ~115 ~367 ~67 ~115 dirt
fill ~367 ~68 ~115 ~367 ~68 ~115 grass_block
fill ~352 ~60 ~116 ~354 ~60 ~116 stone
fill ~352 ~61 ~116 ~354 ~63 ~116 dirt
fill ~352 ~64 ~116 ~354 ~64 ~116 grass_block
fill ~355 ~60 ~116 ~359 ~61 ~116 stone
fill ~355 ~62 ~116 ~359 ~64 ~116 dirt
fill ~355 ~65 ~116 ~359 ~65 ~116 grass_block
fill ~360 ~60 ~116 ~361 ~62 ~116 stone
fill ~360 ~63 ~116 ~361 ~65 ~116 dirt
fill ~360 ~66 ~116 ~361 ~66 ~116 grass_block
fill ~362 ~60 ~116 ~366 ~63 ~116 stone
fill ~362 ~64 ~116 ~366 ~66 ~116 dirt
fill ~362 ~67 ~116 ~366 ~67 ~116 grass_block
fill ~367 ~60 ~116 ~367 ~64 ~116 stone
fill ~367 ~65 ~116 ~367 ~67 ~116 dirt
fill ~367 ~68 ~116 ~367 ~68 ~116 grass_block
fill ~352 ~60 ~117 ~356 ~60 ~117 stone
fill ~352 ~61 ~117 ~356 ~63 ~117 dirt
fill ~352 ~64 ~117 ~356 ~64 ~117 grass_block
fill ~357 ~60 ~117 ~359 ~61 ~117 stone
fill ~357 ~62 ~117 ~359 ~64 ~117 dirt
fill ~357 ~65 ~117 ~359 ~65 ~117 grass_block
fill ~360 ~60 ~117 ~361 ~62 ~117 stone
fill ~360 ~63 ~117 ~361 ~65 ~117 dirt
fill ~360 ~66 ~117 ~361 ~66 ~117 grass_block
fill ~362 ~60 ~117 ~367 ~63 ~117 stone
fill ~362 ~64 ~117 ~367 ~66 ~117 dirt
fill ~362 ~67 ~117 ~367 ~67 ~117 grass_block
fill ~352 ~60 ~118 ~356 ~60 ~118 stone
fill ~352 ~61 ~118 ~356 ~63 ~118 dirt
fill ~352 ~64 ~118 ~356 ~64 ~118 grass_block
fill ~357 ~60 ~118 ~359 ~61 ~118 stone
fill ~357 ~62 ~118 ~359 ~64 ~118 dirt
fill ~357 ~65 ~118 ~359 ~65 ~118 grass_block
fill ~360 ~60 ~118 ~361 ~62 ~118 stone
fill ~360 ~63 ~118 ~361 ~65 ~118 dirt
fill ~360 ~66 ~118 ~361 ~66 ~118 grass_block
fill ~362 ~60 ~118 ~367 ~63 ~118 stone
fill ~362 ~64 ~118 ~367 ~66 ~118 dirt
fill ~362 ~67 ~118 ~367 ~67 ~118 grass_block
fill ~352 ~60 ~119 ~357 ~60 ~119 stone
fill ~352 ~61 ~119 ~357 ~63 ~119 dirt
fill ~352 ~64 ~119 ~357 ~64 ~119 grass_block
fill ~358 ~60 ~119 ~359 ~61 ~119 stone
fill ~358 ~62 ~119 ~359 ~64 ~119 dirt
fill ~358 ~65 ~119 ~359 ~65 ~119 grass_block
fill ~360 ~60 ~119 ~363 ~62 ~119 stone
fill ~360 ~63 ~119 ~363 ~65 ~119 dirt
fill ~360 ~66 ~119 ~363 ~66 ~119 grass_block
fill ~364 ~60 ~119 ~367 ~63 ~119 stone
fill ~364 ~64 ~119 ~367 ~66 ~119 dirt
fill ~364 ~67 ~119 ~367 ~67 ~119 grass_block
fill ~352 ~60 ~120 ~356 ~60 ~120 stone
fill ~352 ~61 ~120 ~356 ~63 ~120 dirt
fill ~352 ~64 ~120 ~356 ~64 ~120 grass_block
fill ~357 ~60 ~120 ~360 ~61 ~120 stone
fill ~357 ~62 ~120 ~360 ~64 ~120 dirt
fill ~357 ~65 ~120 ~360 ~65 ~120 grass_block
fill ~361 ~60 ~120 ~364 ~62 ~120 stone
fill ~361 ~63 ~120 ~364 ~65 ~120 dirt
fill ~361 ~66 ~120 ~364 ~66 ~120 grass_block
fill ~365 ~60 ~120 ~367 ~63 ~120 stone
fill ~365 ~64 ~120 ~367 ~66 ~120 dirt
fill ~365 ~67 ~120 ~367 ~67 ~120 grass_block
fill ~352 ~60 ~121 ~357 ~60 ~121 stone
fill ~352 ~61 ~121 ~357 ~63 ~121 dirt
fill ~352 ~64 ~121 ~357 ~64 ~121 grass_block
fill ~358 ~60 ~121 ~361 ~61 ~121 stone
fill ~358 ~62 ~121 ~361 ~64 ~121 dirt
fill ~358 ~65 ~121 ~361 ~65 ~121 grass_block
fill ~362 ~60 ~121 ~364 ~62 ~121 stone
fill ~362 ~63 ~121 ~364 ~65 ~121 dirt
fill ~362 ~66 ~121 ~364 ~66 ~121 grass_block
fill ~365 ~60 ~121 ~367 ~63 ~121 stone
fill ~365 ~64 ~121 ~367 ~66 ~121 dirt
fill ~365 ~67 ~121 ~367 ~67 ~121 grass_block
fill ~352 ~60 ~122 ~358 ~60 ~122 stone
fill ~352 ~61 ~122 ~358 ~63 ~122 dirt
fill ~352 ~64 ~122 ~358 ~64 ~122 grass_block
fill ~359 ~60 ~122 ~361 ~61 ~122 stone
fill ~359 ~62 ~122 ~361 ~64 ~122 dirt
fill ~359 ~65 ~122 ~361 ~65 ~122 grass_block
fill ~362 ~60 ~122 ~364 ~62 ~122 stone
fill ~362 ~63 ~122 ~364 ~65 ~122 dirt
fill ~362 ~66 ~122 ~364 ~66 ~122 grass_block
fill ~365 ~60 ~122 ~367 ~63 ~122 stone
fill ~365 ~64 ~122 ~367 ~66 ~122 dirt
fill ~365 ~67 ~122 ~367 ~67 ~122 grass_block
fill ~352 ~60 ~123 ~359 ~60 ~123 stone
fill ~352 ~61 ~123 ~359 ~63 ~123 dirt
fill ~352 ~64 ~123 ~359 ~64 ~123 grass_block
fill ~360 ~60 ~123 ~362 ~61 ~123 stone
fill ~360 ~62 ~123 ~362 ~64 ~123 dirt
fill ~360 ~65 ~123 ~362 ~65 ~123 grass_block
fill ~363 ~60 ~123 ~365 ~62 ~123 stone
fill ~363 ~63 ~123 ~365 ~65 ~123 dirt
fill ~363 ~66 ~123 ~365 ~66 ~123 grass_block
fill ~366 ~60 ~123 ~367 ~63 ~123 stone
fill ~366 ~64 ~123 ~367 ~66 ~123 dirt
fill ~366 ~67 ~123 ~367 ~67 ~123 grass_block
fill ~352 ~60 ~124 ~360 ~60 ~124 stone
fill ~352 ~61 ~124 ~360 ~63 ~124 dirt
fill ~352 ~64 ~124 ~360 ~64 ~124 grass_block
fill ~361 ~60 ~124 ~362 ~61 ~124 stone
fill ~361 ~62 ~124 ~362 ~64 ~124 dirt
fill ~361 ~65 ~124 ~362 ~65 ~124 grass_block
fill ~363 ~60 ~124 ~366 ~62 ~124 stone
fill ~363 ~63 ~124 ~366 ~65 ~124 dirt
fill ~363 ~66 ~124 ~366 ~66 ~124 grass_block
fill ~367 ~60 ~124 ~367 ~63 ~124 stone
fill ~367 ~64 ~124 ~367 ~66 ~124 dirt
fill ~367 ~67 ~124 ~367 ~67 ~124 grass_block
fill ~352 ~60 ~125 ~360 ~60 ~125 stone
fill ~352 ~61 ~125 ~360 ~63 ~125 dirt
fill ~352 ~64 ~125 ~360 ~64 ~125 grass_block
fill ~361 ~60 ~125 ~364 ~61 ~125 stone
fill ~361 ~62 ~125 ~364 ~64 ~125 dirt
fill ~361 ~65 ~125 ~364 ~65 ~125 grass_block
fill ~365 ~60 ~125 ~366 ~62 ~125 stone
fill ~365 ~63 ~125 ~366 ~65 ~125 dirt
fill ~365 ~66 ~125 ~366 ~66 ~125 grass_block
fill ~367 ~60 ~125 ~367 ~63 ~125 stone
fill ~367 ~64 ~125 ~367 ~66 ~125 dirt
fill ~367 ~67 ~125 ~367 ~67 ~125 grass_block
fill ~352 ~60 ~126 ~361 ~60 ~126 stone
fill ~352 ~61 ~126 ~361 ~63 ~126 dirt
fill ~352 ~64 ~126 ~361 ~64 ~126 grass_block
fill ~362 ~60 ~126 ~364 ~61 ~126 stone
fill ~362 ~62 ~126 ~364 ~64 ~126 dirt
fill ~362 ~65 ~126 ~364 ~65 ~126 grass_block
fill ~365 ~60 ~126 ~367 ~62 ~126 stone
fill ~365 ~63 ~126 ~367 ~65 ~126 dirt
fill ~365 ~66 ~126 ~367 ~66 ~126 grass_block
fill ~352 ~60 ~127 ~362 ~60 ~127 stone
fill ~352 ~61 ~127 ~362 ~63 ~127 dirt
fill ~352 ~64 ~127 ~362 ~64 ~127 grass_block
fill ~363 ~60 ~127 ~366 ~61 ~127 stone
fill ~363 ~62 ~127 ~366 ~64 ~127 dirt
fill ~363 ~65 ~127 ~366 ~65 ~127 grass_block
fill ~367 ~60 ~127 ~367 ~62 ~127 stone
fill ~367 ~63 ~127 ~367 ~65 ~127 dirt
fill ~367 ~66 ~127 ~367 ~66 ~127 grass_block