fill ~208 ~60 ~0 ~209 ~63 ~0 stone
fill ~208 ~64 ~0 ~209 ~66 ~0 dirt
fill ~208 ~67 ~0 ~209 ~67 ~0 grass_block
fill ~210 ~60 ~0 ~214 ~64 ~0 stone
fill ~210 ~65 ~0 ~214 ~67 ~0 dirt
fill ~210 ~68 ~0 ~214 ~68 ~0 grass_block
fill ~215 ~60 ~0 ~220 ~65 ~0 stone
fill ~215 ~66 ~0 ~220 ~68 ~0 dirt
fill ~215 ~69 ~0 ~220 ~69 ~0 grass_block
fill ~221 ~60 ~0 ~223 ~64 ~0 stone
fill ~221 ~65 ~0 ~223 ~67 ~0 dirt
fill ~221 ~68 ~0 ~223 ~68 ~0 grass_block
fill ~208 ~60 ~1 ~209 ~63 ~1 stone
fill ~208 ~64 ~1 ~209 ~66 ~1 dirt
fill ~208 ~67 ~1 ~209 ~67 ~1 grass_block
fill ~210 ~60 ~1 ~211 ~64 ~1 stone
fill ~210 ~65 ~1 ~211 ~67 ~1 dirt
fill ~210 ~68 ~1 ~211 ~68 ~1 grass_block
fill ~212 ~60 ~1 ~221 ~65 ~1 stone
fill ~212 ~66 ~1 ~221 ~68 ~1 dirt
fill ~212 ~69 ~1 ~221 ~69 ~1 grass_block
fill ~222 ~60 ~1 ~223 ~64 ~1 stone
fill ~222 ~65 ~1 ~223 ~67 ~1 dirt
fill ~222 ~68 ~1 ~223 ~68 ~1 grass_block
fill ~208 ~60 ~2 ~211 ~64 ~2 stone
fill ~208 ~65 ~2 ~211 ~67 ~2 dirt
fill ~208 ~68 ~2 ~211 ~68 ~2 grass_block
fill ~212 ~60 ~2 ~222 ~65 ~2 stone
fill ~212 ~66 ~2 ~222 ~68 ~2 dirt
fill ~212 ~69 ~2 ~222 ~69 ~2 grass_block
fill ~223 ~60 ~2 ~223 ~64 ~2 stone
fill ~223 ~65 ~2 ~223 ~67 ~2 dirt
fill ~223 ~68 ~2 ~223 ~68 ~2 grass_block
fill ~208 ~60 ~3 ~212 ~64 ~3 stone
fill ~208 ~65 ~3 ~212 ~67 ~3 dirt
fill ~208 ~68 ~3 ~212 ~68 ~3 grass_block
fill ~213 ~60 ~3 ~222 ~65 ~3 stone
fill ~213 ~66 ~3 ~222 ~68 ~3 dirt
fill ~213 ~69 ~3 ~222 ~69 ~3 grass_block
fill ~223 ~60 ~3 ~223 ~64 ~3 stone
fill ~223 ~65 ~3 ~223 ~67 ~3 dirt
fill ~223 ~68 ~3 ~223 ~68 ~3 grass_block
fill ~208 ~60 ~4 ~215 ~64 ~4 stone
fill ~208 ~65 ~4 ~215 ~67 ~4 dirt
fill ~208 ~68 ~4 ~215 ~68 ~4 grass_block
fill ~216 ~60 ~4 ~223 ~65 ~4 stone
fill ~216 ~66 ~4 ~223 ~68 ~4 dirt
fill ~216 ~69 ~4 ~223 ~69 ~4 grass_block
fill ~208 ~60 ~5 ~216 ~64 ~5 stone
fill ~208 ~65 ~5 ~216 ~67 ~5 dirt
fill ~208 ~68 ~5 ~216 ~68 ~5 grass_block
fill ~217 ~60 ~5 ~223 ~65 ~5 stone
fill ~217 ~66 ~5 ~223 ~68 ~5 dirt
fill ~217 ~69 ~5 ~223 ~69 ~5 grass_block
fill ~208 ~60 ~6 ~217 ~64 ~6 stone
fill ~208 ~65 ~6 ~217 ~67 ~6 dirt
fill ~208 ~68 ~6 ~217 ~68 ~6 grass_block
fill ~218 ~60 ~6 ~223 ~65 ~6 stone
fill ~218 ~66 ~6 ~223 ~68 ~6 dirt
fill ~218 ~69 ~6 ~223 ~69 ~6 grass_block
fill ~208 ~60 ~7 ~218 ~64 ~7 stone
fill ~208 ~65 ~7 ~218 ~67 ~7 dirt
fill ~208 ~68 ~7 ~218 ~68 ~7 grass_block
fill ~219 ~60 ~7 ~223 ~65 ~7 stone
fill ~219 ~66 ~7 ~223 ~68 ~7 dirt
fill ~219 ~69 ~7 ~223 ~69 ~7 grass_block
fill ~208 ~60 ~8 ~212 ~64 ~8 stone
fill ~208 ~65 ~8 ~212 ~67 ~8 dirt
fill ~208 ~68 ~8 ~212 ~68 ~8 grass_block
fill ~213 ~60 ~8 ~215 ~63 ~8 stone
fill ~213 ~64 ~8 ~215 ~66 ~8 dirt
fill ~213 ~67 ~8 ~215 ~67 ~8 grass_block
fill ~216 ~60 ~8 ~219 ~64 ~8 stone
fill ~216 ~65 ~8 ~219 ~67 ~8 dirt
fill ~216 ~68 ~8 ~219 ~68 ~8 grass_block
fill ~220 ~60 ~8 ~223 ~65 ~8 stone
fill ~220 ~66 ~8 ~223 ~68 ~8 dirt
fill ~220 ~69 ~8 ~223 ~69 ~8 grass_block
fill ~208 ~60 ~9 ~210 ~64 ~9 stone
fill ~208 ~65 ~9 ~210 ~67 ~9 dirt
fill ~208 ~68 ~9 ~210 ~68 ~9 grass_block
fill ~211 ~60 ~9 ~215 ~63 ~9 stone
fill ~211 ~64 ~9 ~215 ~66 ~9 dirt
fill ~211 ~67 ~9 ~215 ~67 ~9 grass_block
fill ~216 ~60 ~9 ~219 ~64 ~9 stone
fill ~216 ~65 ~9 ~219 ~67 ~9 dirt
fill ~216 ~68 ~9 ~219 ~68 ~9 grass_block
fill ~220 ~60 ~9 ~223 ~65 ~9 stone
fill ~220 ~66 ~9 ~223 ~68 ~9 dirt
fill ~220 ~69 ~9 ~223 ~69 ~9 grass_block
fill ~208 ~60 ~10 ~215 ~63 ~10 stone
fill ~208 ~64 ~10 ~215 ~66 ~10 dirt
fill ~208 ~67 ~10 ~215 ~67 ~10 grass_block
fill ~216 ~60 ~10 ~223 ~64 ~10 stone
fill ~216 ~65 ~10 ~223 ~67 ~10 dirt
fill ~216 ~68 ~10 ~223 ~68 ~10 grass_block
fill ~208 ~60 ~11 ~215 ~63 ~11 stone
fill ~208 ~64 ~11 ~215 ~66 ~11 dirt
fill ~208 ~67 ~11 ~215 ~67 ~11 grass_block
fill ~216 ~60 ~11 ~223 ~64 ~11 stone
fill ~216 ~65 ~11 ~223 ~67 ~11 dirt
fill ~216 ~68 ~11 ~223 ~68 ~11 grass_block
fill ~208 ~60 ~12 ~216 ~63 ~12 stone
fill ~208 ~64 ~12 ~216 ~66 ~12 dirt
fill ~208 ~67 ~12 ~216 ~67 ~12 grass_block
fill ~217 ~60 ~12 ~223 ~64 ~12 stone
fill ~217 ~65 ~12 ~223 ~67 ~12 dirt
fill ~217 ~68 ~12 ~223 ~68 ~12 grass_block
fill ~208 ~60 ~13 ~208 ~62 ~13 stone
fill ~208 ~63 ~13 ~208 ~65 ~13 dirt
fill ~208 ~66 ~13 ~208 ~66 ~13 grass_block
fill ~209 ~60 ~13 ~210 ~63 ~13 stone
fill ~209 ~64 ~13 ~210 ~66 ~13 dirt
fill ~209 ~67 ~13 ~210 ~67 ~13 grass_block
fill ~211 ~60 ~13 ~212 ~62 ~13 stone
fill ~211 ~63 ~13 ~212 ~65 ~13 dirt
fill ~211 ~66 ~13 ~212 ~66 ~13 grass_block
fill ~213 ~60 ~13 ~216 ~63 ~13 stone
fill ~213 ~64 ~13 ~216 ~66 ~13 dirt
fill ~213 ~67 ~13 ~216 ~67 ~13 grass_block
fill ~217 ~60 ~13 ~223 ~64 ~13 stone
fill ~217 ~65 ~13 ~223 ~67 ~13 dirt
fill ~217 ~68 ~13 ~223 ~68 ~13 grass_block
fill ~208 ~60 ~14 ~213 ~62 ~14 stone
fill ~208 ~63 ~14 ~213 ~65 ~14 dirt
fill ~208 ~66 ~14 ~213 ~66 ~14 grass_block
fill ~214 ~60 ~14 ~216 ~63 ~14 stone
fill ~214 ~64 ~14 ~216 ~66 ~14 dirt
fill ~214 ~67 ~14 ~216 ~67 ~14 grass_block
fill ~217 ~60 ~14 ~223 ~64 ~14 stone
fill ~217 ~65 ~14 ~223 ~67 ~14 dirt
fill ~217 ~68 ~14 ~223 ~68 ~14 grass_block
fill ~208 ~60 ~15 ~208 ~61 ~15 stone
fill ~208 ~62 ~15 ~208 ~64 ~15 dirt
fill ~208 ~65 ~15 ~208 ~65 ~15 grass_block
fill ~209 ~60 ~15 ~212 ~62 ~15 stone
fill ~209 ~63 ~15 ~212 ~65 ~15 dirt
fill ~209 ~66 ~15 ~212 ~66 ~15 grass_block
fill ~213 ~60 ~15 ~217 ~63 ~15 stone
fill ~213 ~64 ~15 ~217 ~66 ~15 dirt
fill ~213 ~67 ~15 ~217 ~67 ~15 grass_block
fill ~218 ~60 ~15 ~223 ~64 ~15 stone
fill ~218 ~65 ~15 ~223 ~67 ~15 dirt
fill ~218 ~68 ~15 ~223 ~68 ~15 grass_block