fill ~304 ~60 ~112 ~307 ~64 ~112 stone
fill ~304 ~65 ~112 ~307 ~67 ~112 dirt
fill ~304 ~68 ~112 ~307 ~68 ~112 grass_block
fill ~308 ~60 ~112 ~319 ~63 ~112 stone
fill ~308 ~64 ~112 ~319 ~66 ~112 dirt
fill ~308 ~67 ~112 ~319 ~67 ~112 grass_block
fill ~304 ~60 ~113 ~309 ~64 ~113 stone
fill ~304 ~65 ~113 ~309 ~67 ~113 dirt
fill ~304 ~68 ~113 ~309 ~68 ~113 grass_block
fill ~310 ~60 ~113 ~319 ~63 ~113 stone
fill ~310 ~64 ~113 ~319 ~66 ~113 dirt
fill ~310 ~67 ~113 ~319 ~67 ~113 grass_block
fill ~304 ~60 ~114 ~310 ~64 ~114 stone
fill ~304 ~65 ~114 ~310 ~67 ~114 dirt
fill ~304 ~68 ~114 ~310 ~68 ~114 grass_block
fill ~311 ~60 ~114 ~319 ~63 ~114 stone
fill ~311 ~64 ~114 ~319 ~66 ~114 dirt
fill ~311 ~67 ~114 ~319 ~67 ~114 grass_block
fill ~304 ~60 ~115 ~311 ~64 ~115 stone
fill ~304 ~65 ~115 ~311 ~67 ~115 dirt
fill ~304 ~68 ~115 ~311 ~68 ~115 grass_block
fill ~312 ~60 ~115 ~319 ~63 ~115 stone
fill ~312 ~64 ~115 ~319 ~66 ~115 dirt
fill ~312 ~67 ~115 ~319 ~67 ~115 grass_block
fill ~304 ~60 ~116 ~312 ~64 ~116 stone
fill ~304 ~65 ~116 ~312 ~67 ~116 dirt
fill ~304 ~68 ~116 ~312 ~68 ~116 grass_block
fill ~313 ~60 ~116 ~319 ~63 ~116 stone
fill ~313 ~64 ~116 ~319 ~66 ~116 dirt
fill ~313 ~67 ~116 ~319 ~67 ~116 grass_block
fill ~304 ~60 ~117 ~305 ~65 ~117 stone
fill ~304 ~66 ~117 ~305 ~68 ~117 dirt
fill ~304 ~69 ~117 ~305 ~69 ~117 grass_block
fill ~306 ~60 ~117 ~313 ~64 ~117 stone
fill ~306 ~65 ~117 ~313 ~67 ~117 dirt
fill ~306 ~68 ~117 ~313 ~68 ~117 grass_block
fill ~314 ~60 ~117 ~319 ~63 ~117 stone
fill ~314 ~64 ~117 ~319 ~66 ~117 dirt
fill ~314 ~67 ~117 ~319 ~67 ~117 grass_block
fill ~304 ~60 ~118 ~305 ~65 ~118 stone
fill ~304 ~66 ~118 ~305 ~68 ~118 dirt
fill ~304 ~69 ~118 ~305 ~69 ~118 grass_block
fill ~306 ~60 ~118 ~314 ~64 ~118 stone
fill ~306 ~65 ~118 ~314 ~67 ~118 dirt
fill ~306 ~68 ~118 ~314 ~68 ~118 grass_block
fill ~315 ~60 ~118 ~319 ~63 ~118 stone
fill ~315 ~64 ~118 ~319 ~66 ~118 dirt
fill ~315 ~67 ~118 ~319 ~67 ~118 grass_block
fill ~304 ~60 ~119 ~306 ~65 ~119 stone
fill ~304 ~66 ~119 ~306 ~68 ~119 dirt
fill ~304 ~69 ~119 ~306 ~69 ~119 grass_block
fill ~307 ~60 ~119 ~314 ~64 ~119 stone
fill ~307 ~65 ~119 ~314 ~67 ~119 dirt
fill ~307 ~68 ~119 ~314 ~68 ~119 grass_block
fill ~315 ~60 ~119 ~319 ~63 ~119 stone
fill ~315 ~64 ~119 ~319 ~66 ~119 dirt
fill ~315 ~67 ~119 ~319 ~67 ~119 grass_block
fill ~304 ~60 ~120 ~307 ~65 ~120 stone
fill ~304 ~66 ~120 ~307 ~68 ~120 dirt
fill ~304 ~69 ~120 ~307 ~69 ~120 grass_block
fill ~308 ~60 ~120 ~315 ~64 ~120 stone
fill ~308 ~65 ~120 ~315 ~67 ~120 dirt
fill ~308 ~68 ~120 ~315 ~68 ~120 grass_block
fill ~316 ~60 ~120 ~319 ~63 ~120 stone
fill ~316 ~64 ~120 ~319 ~66 ~120 dirt
fill ~316 ~67 ~120 ~319 ~67 ~120 grass_block
fill ~304 ~60 ~121 ~308 ~65 ~121 stone
fill ~304 ~66 ~121 ~308 ~68 ~121 dirt
fill ~304 ~69 ~121 ~308 ~69 ~121 grass_block
fill ~309 ~60 ~121 ~318 ~64 ~121 stone
fill ~309 ~65 ~121 ~318 ~67 ~121 dirt
fill ~309 ~68 ~121 ~318 ~68 ~121 grass_block
fill ~319 ~60 ~121 ~319 ~63 ~121 stone
fill ~319 ~64 ~121 ~319 ~66 ~121 dirt
fill ~319 ~67 ~121 ~319 ~67 ~121 grass_block
fill ~304 ~60 ~122 ~309 ~65 ~122 stone
fill ~304 ~66 ~122 ~309 ~68 ~122 dirt
fill ~304 ~69 ~122 ~309 ~69 ~122 grass_block
fill ~310 ~60 ~122 ~319 ~64 ~122 stone
fill ~310 ~65 ~122 ~319 ~67 ~122 dirt
fill ~310 ~68 ~122 ~319 ~68 ~122 grass_block
fill ~304 ~60 ~123 ~310 ~65 ~123 stone
fill ~304 ~66 ~123 ~310 ~68 ~123 dirt
fill ~304 ~69 ~123 ~310 ~69 ~123 grass_block
fill ~311 ~60 ~123 ~319 ~64 ~123 stone
fill ~311 ~65 ~123 ~319 ~67 ~123 dirt
fill ~311 ~68 ~123 ~319 ~68 ~123 grass_block
fill ~304 ~60 ~124 ~311 ~65 ~124 stone
fill ~304 ~66 ~124 ~311 ~68 ~124 dirt
fill ~304 ~69 ~124 ~311 ~69 ~124 grass_block
fill ~312 ~60 ~124 ~319 ~64 ~124 stone
fill ~312 ~65 ~124 ~319 ~67 ~124 dirt
fill ~312 ~68 ~124 ~319 ~68 ~124 grass_block
fill ~304 ~60 ~125 ~312 ~65 ~125 stone
fill ~304 ~66 ~125 ~312 ~68 ~125 dirt
fill ~304 ~69 ~125 ~312 ~69 ~125 grass_block
fill ~313 ~60 ~125 ~319 ~64 ~125 stone
fill ~313 ~65 ~125 ~319 ~67 ~125 dirt
fill ~313 ~68 ~125 ~319 ~68 ~125 grass_block
fill ~304 ~60 ~126 ~313 ~65 ~126 stone
fill ~304 ~66 ~126 ~313 ~68 ~126 dirt
fill ~304 ~69 ~126 ~313 ~69 ~126 grass_block
fill ~314 ~60 ~126 ~319 ~64 ~126 stone
fill ~314 ~65 ~126 ~319 ~67 ~126 dirt
fill ~314 ~68 ~126 ~319 ~68 ~126 grass_block
fill ~304 ~60 ~127 ~316 ~65 ~127 stone
fill ~304 ~66 ~127 ~316 ~68 ~127 dirt
fill ~304 ~69 ~127 ~316 ~69 ~127 grass_block
fill ~317 ~60 ~127 ~319 ~64 ~127 stone
fill ~317 ~65 ~127 ~319 ~67 ~127 dirt
fill ~317 ~68 ~127 ~319 ~68 ~127 grass_block