fill ~416 ~60 ~128 ~416 ~64 ~128 stone
fill ~416 ~65 ~128 ~416 ~67 ~128 dirt
fill ~416 ~68 ~128 ~416 ~68 ~128 grass_block
fill ~417 ~60 ~128 ~421 ~63 ~128 stone
fill ~417 ~64 ~128 ~421 ~66 ~128 dirt
fill ~417 ~67 ~128 ~421 ~67 ~128 grass_block
fill ~422 ~60 ~128 ~430 ~62 ~128 stone
fill ~422 ~63 ~128 ~430 ~65 ~128 dirt
fill ~422 ~66 ~128 ~430 ~66 ~128 grass_block
fill ~431 ~60 ~128 ~431 ~63 ~128 stone
fill ~431 ~64 ~128 ~431 ~66 ~128 dirt
fill ~431 ~67 ~128 ~431 ~67 ~128 grass_block
fill ~416 ~60 ~129 ~421 ~63 ~129 stone
fill ~416 ~64 ~129 ~421 ~66 ~129 dirt
fill ~416 ~67 ~129 ~421 ~67 ~129 grass_block
fill ~422 ~60 ~129 ~425 ~62 ~129 stone
fill ~422 ~63 ~129 ~425 ~65 ~129 dirt
fill ~422 ~66 ~129 ~425 ~66 ~129 grass_block
fill ~426 ~60 ~129 ~426 ~61 ~129 stone
fill ~426 ~62 ~129 ~426 ~64 ~129 dirt
fill ~426 ~65 ~129 ~426 ~65 ~129 grass_block
fill ~427 ~60 ~129 ~430 ~62 ~129 stone
fill ~427 ~63 ~129 ~430 ~65 ~129 dirt
fill ~427 ~66 ~129 ~430 ~66 ~129 grass_block
fill ~431 ~60 ~129 ~431 ~63 ~129 stone
fill ~431 ~64 ~129 ~431 ~66 ~129 dirt
fill ~431 ~67 ~129 ~431 ~67 ~129 grass_block
fill ~416 ~60 ~130 ~421 ~63 ~130 stone
fill ~416 ~64 ~130 ~421 ~66 ~130 dirt
fill ~416 ~67 ~130 ~421 ~67 ~130 grass_block
fill ~422 ~60 ~130 ~425 ~62 ~130 stone
fill ~422 ~63 ~130 ~425 ~65 ~130 dirt
fill ~422 ~66 ~130 ~425 ~66 ~130 grass_block
fill ~426 ~60 ~130 ~427 ~61 ~130 stone
fill ~426 ~62 ~130 ~427 ~64 ~130 dirt
fill ~426 ~65 ~130 ~427 ~65 ~130 grass_block
fill ~428 ~60 ~130 ~431 ~62 ~130 stone
fill ~428 ~63 ~130 ~431 ~65 ~130 dirt
fill ~428 ~66 ~130 ~431 ~66 ~130 grass_block
fill ~416 ~60 ~131 ~421 ~63 ~131 stone
fill ~416 ~64 ~131 ~421 ~66 ~131 dirt
fill ~416 ~67 ~131 ~421 ~67 ~131 grass_block
fill ~422 ~60 ~131 ~426 ~62 ~131 stone
fill ~422 ~63 ~131 ~426 ~65 ~131 dirt
fill ~422 ~66 ~131 ~426 ~66 ~131 grass_block
fill ~427 ~60 ~131 ~428 ~61 ~131 stone
fill ~427 ~62 ~131 ~428 ~64 ~131 dirt
fill ~427 ~65 ~131 ~428 ~65 ~131 grass_block
fill ~429 ~60 ~131 ~431 ~62 ~131 stone
fill ~429 ~63 ~131 ~431 ~65 ~131 dirt
fill ~429 ~66 ~131 ~431 ~66 ~131 grass_block
fill ~416 ~60 ~132 ~422 ~63 ~132 stone
fill ~416 ~64 ~132 ~422 ~66 ~132 dirt
fill ~416 ~67 ~132 ~422 ~67 ~132 grass_block
fill ~423 ~60 ~132 ~426 ~62 ~132 stone
fill ~423 ~63 ~132 ~426 ~65 ~132 dirt
fill ~423 ~66 ~132 ~426 ~66 ~132 grass_block
fill ~427 ~60 ~132 ~429 ~61 ~132 stone
fill ~427 ~62 ~132 ~429 ~64 ~132 dirt
fill ~427 ~65 ~132 ~429 ~65 ~132 grass_block
fill ~430 ~60 ~132 ~431 ~62 ~132 stone
fill ~430 ~63 ~132 ~431 ~65 ~132 dirt
fill ~430 ~66 ~132 ~431 ~66 ~132 grass_block
fill ~416 ~60 ~133 ~422 ~63 ~133 stone
fill ~416 ~64 ~133 ~422 ~66 ~133 dirt
fill ~416 ~67 ~133 ~422 ~67 ~133 grass_block
fill ~423 ~60 ~133 ~426 ~62 ~133 stone
fill ~423 ~63 ~133 ~426 ~65 ~133 dirt
fill ~423 ~66 ~133 ~426 ~66 ~133 grass_block
fill ~427 ~60 ~133 ~429 ~61 ~133 stone
fill ~427 ~62 ~133 ~429 ~64 ~133 dirt
fill ~427 ~65 ~133 ~429 ~65 ~133 grass_block
fill ~430 ~60 ~133 ~431 ~62 ~133 stone
fill ~430 ~63 ~133 ~431 ~65 ~133 dirt
fill ~430 ~66 ~133 ~431 ~66 ~133 grass_block
fill ~416 ~60 ~134 ~416 ~62 ~134 stone
fill ~416 ~63 ~134 ~416 ~65 ~134 dirt
fill ~416 ~66 ~134 ~416 ~66 ~134 grass_block
fill ~417 ~60 ~134 ~422 ~63 ~134 stone
fill ~417 ~64 ~134 ~422 ~66 ~134 dirt
fill ~417 ~67 ~134 ~422 ~67 ~134 grass_block
fill ~423 ~60 ~134 ~426 ~62 ~134 stone
fill ~423 ~63 ~134 ~426 ~65 ~134 dirt
fill ~423 ~66 ~134 ~426 ~66 ~134 grass_block
fill ~427 ~60 ~134 ~431 ~61 ~134 stone
fill ~427 ~62 ~134 ~431 ~64 ~134 dirt
fill ~427 ~65 ~134 ~431 ~65 ~134 grass_block
fill ~416 ~60 ~135 ~420 ~62 ~135 stone
fill ~416 ~63 ~135 ~420 ~65 ~135 dirt
fill ~416 ~66 ~135 ~420 ~66 ~135 grass_block
fill ~421 ~60 ~135 ~421 ~63 ~135 stone
fill ~421 ~64 ~135 ~421 ~66 ~135 dirt
fill ~421 ~67 ~135 ~421 ~67 ~135 grass_block
fill ~422 ~60 ~135 ~427 ~62 ~135 stone
fill ~422 ~63 ~135 ~427 ~65 ~135 dirt
fill ~422 ~66 ~135 ~427 ~66 ~135 grass_block
fill ~428 ~60 ~135 ~431 ~61 ~135 stone
fill ~428 ~62 ~135 ~431 ~64 ~135 dirt
fill ~428 ~65 ~135 ~431 ~65 ~135 grass_block
fill ~416 ~60 ~136 ~418 ~61 ~136 stone
fill ~416 ~62 ~136 ~418 ~64 ~136 dirt
fill ~416 ~65 ~136 ~418 ~65 ~136 grass_block
fill ~419 ~60 ~136 ~427 ~62 ~136 stone
fill ~419 ~63 ~136 ~427 ~65 ~136 dirt
fill ~419 ~66 ~136 ~427 ~66 ~136 grass_block
fill ~428 ~60 ~136 ~431 ~61 ~136 stone
fill ~428 ~62 ~136 ~431 ~64 ~136 dirt
fill ~428 ~65 ~136 ~431 ~65 ~136 grass_block
fill ~416 ~60 ~137 ~421 ~61 ~137 stone
fill ~416 ~62 ~137 ~421 ~64 ~137 dirt
fill ~416 ~65 ~137 ~421 ~65 ~137 grass_block
fill ~422 ~60 ~137 ~427 ~62 ~137 stone
fill ~422 ~63 ~137 ~427 ~65 ~137 dirt
fill ~422 ~66 ~137 ~427 ~66 ~137 grass_block
fill ~428 ~60 ~137 ~431 ~61 ~137 stone
fill ~428 ~62 ~137 ~431 ~64 ~137 dirt
fill ~428 ~65 ~137 ~431 ~65 ~137 grass_block
fill ~416 ~60 ~138 ~418 ~60 ~138 stone
fill ~416 ~61 ~138 ~418 ~63 ~138 dirt
fill ~416 ~64 ~138 ~418 ~64 ~138 grass_block
fill ~419 ~60 ~138 ~425 ~61 ~138 stone
fill ~419 ~62 ~138 ~425 ~64 ~138 dirt
fill ~419 ~65 ~138 ~425 ~65 ~138 grass_block
fill ~426 ~60 ~138 ~427 ~62 ~138 stone
fill ~426 ~63 ~138 ~427 ~65 ~138 dirt
fill ~426 ~66 ~138 ~427 ~66 ~138 grass_block
fill ~428 ~60 ~138 ~431 ~61 ~138 stone
fill ~428 ~62 ~138 ~431 ~64 ~138 dirt
fill ~428 ~65 ~138 ~431 ~65 ~138 grass_block
fill ~416 ~60 ~139 ~424 ~60 ~139 stone
fill ~416 ~61 ~139 ~424 ~63 ~139 dirt
fill ~416 ~64 ~139 ~424 ~64 ~139 grass_block
fill ~425 ~60 ~139 ~431 ~61 ~139 stone
fill ~425 ~62 ~139 ~431 ~64 ~139 dirt
fill ~425 ~65 ~139 ~431 ~65 ~139 grass_block
fill ~416 ~60 ~140 ~426 ~60 ~140 stone
fill ~416 ~61 ~140 ~426 ~63 ~140 dirt
fill ~416 ~64 ~140 ~426 ~64 ~140 grass_block
fill ~427 ~60 ~140 ~431 ~61 ~140 stone
fill ~427 ~62 ~140 ~431 ~64 ~140 dirt
fill ~427 ~65 ~140 ~431 ~65 ~140 grass_block
fill ~416 ~60 ~141 ~431 ~60 ~141 stone
fill ~416 ~61 ~141 ~431 ~63 ~141 dirt
fill ~416 ~64 ~141 ~431 ~64 ~141 grass_block
fill ~416 ~60 ~142 ~431 ~60 ~142 stone
fill ~416 ~61 ~142 ~431 ~63 ~142 dirt
fill ~416 ~64 ~142 ~431 ~64 ~142 grass_block
fill ~416 ~60 ~143 ~431 ~60 ~143 stone
fill ~416 ~61 ~143 ~431 ~63 ~143 dirt
fill ~416 ~64 ~143 ~431 ~64 ~143 grass_block