fill ~352 ~60 ~0 ~355 ~65 ~0 stone
fill ~352 ~66 ~0 ~355 ~68 ~0 dirt
fill ~352 ~69 ~0 ~355 ~69 ~0 grass_block
fill ~356 ~60 ~0 ~360 ~64 ~0 stone
fill ~356 ~65 ~0 ~360 ~67 ~0 dirt
fill ~356 ~68 ~0 ~360 ~68 ~0 grass_block
fill ~361 ~60 ~0 ~366 ~63 ~0 stone
fill ~361 ~64 ~0 ~366 ~66 ~0 dirt
fill ~361 ~67 ~0 ~366 ~67 ~0 grass_block
fill ~367 ~60 ~0 ~367 ~64 ~0 stone
fill ~367 ~65 ~0 ~367 ~67 ~0 dirt
fill ~367 ~68 ~0 ~367 ~68 ~0 grass_block
fill ~352 ~60 ~1 ~355 ~65 ~1 stone
fill ~352 ~66 ~1 ~355 ~68 ~1 dirt
fill ~352 ~69 ~1 ~355 ~69 ~1 grass_block
fill ~356 ~60 ~1 ~360 ~64 ~1 stone
fill ~356 ~65 ~1 ~360 ~67 ~1 dirt
fill ~356 ~68 ~1 ~360 ~68 ~1 grass_block
fill ~361 ~60 ~1 ~367 ~63 ~1 stone
fill ~361 ~64 ~1 ~367 ~66 ~1 dirt
fill ~361 ~67 ~1 ~367 ~67 ~1 grass_block
fill ~352 ~60 ~2 ~356 ~65 ~2 stone
fill ~352 ~66 ~2 ~356 ~68 ~2 dirt
fill ~352 ~69 ~2 ~356 ~69 ~2 grass_block
fill ~357 ~60 ~2 ~360 ~64 ~2 stone
fill ~357 ~65 ~2 ~360 ~67 ~2 dirt
fill ~357 ~68 ~2 ~360 ~68 ~2 grass_block
fill ~361 ~60 ~2 ~367 ~63 ~2 stone
fill ~361 ~64 ~2 ~367 ~66 ~2 dirt
fill ~361 ~67 ~2 ~367 ~67 ~2 grass_block
fill ~352 ~60 ~3 ~356 ~65 ~3 stone
fill ~352 ~66 ~3 ~356 ~68 ~3 dirt
fill ~352 ~69 ~3 ~356 ~69 ~3 grass_block
fill ~357 ~60 ~3 ~361 ~64 ~3 stone
fill ~357 ~65 ~3 ~361 ~67 ~3 dirt
fill ~357 ~68 ~3 ~361 ~68 ~3 grass_block
fill ~362 ~60 ~3 ~367 ~63 ~3 stone
fill ~362 ~64 ~3 ~367 ~66 ~3 dirt
fill ~362 ~67 ~3 ~367 ~67 ~3 grass_block
fill ~352 ~60 ~4 ~356 ~65 ~4 stone
fill ~352 ~66 ~4 ~356 ~68 ~4 dirt
fill ~352 ~69 ~4 ~356 ~69 ~4 grass_block
fill ~357 ~60 ~4 ~361 ~64 ~4 stone
fill ~357 ~65 ~4 ~361 ~67 ~4 dirt
fill ~357 ~68 ~4 ~361 ~68 ~4 grass_block
fill ~362 ~60 ~4 ~366 ~63 ~4 stone
fill ~362 ~64 ~4 ~366 ~66 ~4 dirt
fill ~362 ~67 ~4 ~366 ~67 ~4 grass_block
fill ~367 ~60 ~4 ~367 ~62 ~4 stone
fill ~367 ~63 ~4 ~367 ~65 ~4 dirt
fill ~367 ~66 ~4 ~367 ~66 ~4 grass_block
fill ~352 ~60 ~5 ~362 ~64 ~5 stone
fill ~352 ~65 ~5 ~362 ~67 ~5 dirt
fill ~352 ~68 ~5 ~362 ~68 ~5 grass_block
fill ~363 ~60 ~5 ~366 ~63 ~5 stone
fill ~363 ~64 ~5 ~366 ~66 ~5 dirt
fill ~363 ~67 ~5 ~366 ~67 ~5 grass_block
fill ~367 ~60 ~5 ~367 ~62 ~5 stone
fill ~367 ~63 ~5 ~367 ~65 ~5 dirt
fill ~367 ~66 ~5 ~367 ~66 ~5 grass_block
fill ~352 ~60 ~6 ~363 ~64 ~6 stone
fill ~352 ~65 ~6 ~363 ~67 ~6 dirt
fill ~352 ~68 ~6 ~363 ~68 ~6 grass_block
fill ~364 ~60 ~6 ~366 ~63 ~6 stone
fill ~364 ~64 ~6 ~366 ~66 ~6 dirt
fill ~364 ~67 ~6 ~366 ~67 ~6 grass_block
fill ~367 ~60 ~6 ~367 ~62 ~6 stone
fill ~367 ~63 ~6 ~367 ~65 ~6 dirt
fill ~367 ~66 ~6 ~367 ~66 ~6 grass_block
fill ~352 ~60 ~7 ~363 ~64 ~7 stone
fill ~352 ~65 ~7 ~363 ~67 ~7 dirt
fill ~352 ~68 ~7 ~363 ~68 ~7 grass_block
fill ~364 ~60 ~7 ~367 ~63 ~7 stone
fill ~364 ~64 ~7 ~367 ~66 ~7 dirt
fill ~364 ~67 ~7 ~367 ~67 ~7 grass_block
fill ~352 ~60 ~8 ~354 ~64 ~8 stone
fill ~352 ~65 ~8 ~354 ~67 ~8 dirt
fill ~352 ~68 ~8 ~354 ~68 ~8 grass_block
fill ~355 ~60 ~8 ~357 ~63 ~8 stone
fill ~355 ~64 ~8 ~357 ~66 ~8 dirt
fill ~355 ~67 ~8 ~357 ~67 ~8 grass_block
fill ~358 ~60 ~8 ~363 ~64 ~8 stone
fill ~358 ~65 ~8 ~363 ~67 ~8 dirt
fill ~358 ~68 ~8 ~363 ~68 ~8 grass_block
fill ~364 ~60 ~8 ~367 ~63 ~8 stone
fill ~364 ~64 ~8 ~367 ~66 ~8 dirt
fill ~364 ~67 ~8 ~367 ~67 ~8 grass_block
fill ~352 ~60 ~9 ~360 ~63 ~9 stone
fill ~352 ~64 ~9 ~360 ~66 ~9 dirt
fill ~352 ~67 ~9 ~360 ~67 ~9 grass_block
fill ~361 ~60 ~9 ~364 ~64 ~9 stone
fill ~361 ~65 ~9 ~364 ~67 ~9 dirt
fill ~361 ~68 ~9 ~364 ~68 ~9 grass_block
fill ~365 ~60 ~9 ~367 ~63 ~9 stone
fill ~365 ~64 ~9 ~367 ~66 ~9 dirt
fill ~365 ~67 ~9 ~367 ~67 ~9 grass_block
fill ~352 ~60 ~10 ~367 ~63 ~10 stone
fill ~352 ~64 ~10 ~367 ~66 ~10 dirt
fill ~352 ~67 ~10 ~367 ~67 ~10 grass_block
fill ~352 ~60 ~11 ~367 ~63 ~11 stone
fill ~352 ~64 ~11 ~367 ~66 ~11 dirt
fill ~352 ~67 ~11 ~367 ~67 ~11 grass_block
fill ~352 ~60 ~12 ~352 ~62 ~12 stone
fill ~352 ~63 ~12 ~352 ~65 ~12 dirt
fill ~352 ~66 ~12 ~352 ~66 ~12 grass_block
fill ~353 ~60 ~12 ~367 ~63 ~12 stone
fill ~353 ~64 ~12 ~367 ~66 ~12 dirt
fill ~353 ~67 ~12 ~367 ~67 ~12 grass_block
fill ~352 ~60 ~13 ~361 ~62 ~13 stone
fill ~352 ~63 ~13 ~361 ~65 ~13 dirt
fill ~352 ~66 ~13 ~361 ~66 ~13 grass_block
fill ~362 ~60 ~13 ~367 ~63 ~13 stone
fill ~362 ~64 ~13 ~367 ~66 ~13 dirt
fill ~362 ~67 ~13 ~367 ~67 ~13 grass_block
fill ~352 ~60 ~14 ~367 ~62 ~14 stone
fill ~352 ~63 ~14 ~367 ~65 ~14 dirt
fill ~352 ~66 ~14 ~367 ~66 ~14 grass_block
fill ~352 ~60 ~15 ~353 ~63 ~15 stone
fill ~352 ~64 ~15 ~353 ~66 ~15 dirt
fill ~352 ~67 ~15 ~353 ~67 ~15 grass_block
fill ~354 ~60 ~15 ~367 ~62 ~15 stone
fill ~354 ~63 ~15 ~367 ~65 ~15 dirt
fill ~354 ~66 ~15 ~367 ~66 ~15 grass_block