fill ~144 ~60 ~48 ~144 ~66 ~48 stone
fill ~144 ~67 ~48 ~144 ~69 ~48 dirt
fill ~144 ~70 ~48 ~144 ~70 ~48 grass_block
fill ~145 ~60 ~48 ~148 ~67 ~48 stone
fill ~145 ~68 ~48 ~148 ~70 ~48 dirt
fill ~145 ~71 ~48 ~148 ~71 ~48 grass_block
fill ~149 ~60 ~48 ~152 ~68 ~48 stone
fill ~149 ~69 ~48 ~152 ~71 ~48 dirt
fill ~149 ~72 ~48 ~152 ~72 ~48 grass_block
fill ~153 ~60 ~48 ~159 ~67 ~48 stone
fill ~153 ~68 ~48 ~159 ~70 ~48 dirt
fill ~153 ~71 ~48 ~159 ~71 ~48 grass_block
fill ~144 ~60 ~49 ~144 ~66 ~49 stone
fill ~144 ~67 ~49 ~144 ~69 ~49 dirt
fill ~144 ~70 ~49 ~144 ~70 ~49 grass_block
fill ~145 ~60 ~49 ~151 ~67 ~49 stone
fill ~145 ~68 ~49 ~151 ~70 ~49 dirt
fill ~145 ~71 ~49 ~151 ~71 ~49 grass_block
fill ~152 ~60 ~49 ~153 ~68 ~49 stone
fill ~152 ~69 ~49 ~153 ~71 ~49 dirt
fill ~152 ~72 ~49 ~153 ~72 ~49 grass_block
fill ~154 ~60 ~49 ~159 ~67 ~49 stone
fill ~154 ~68 ~49 ~159 ~70 ~49 dirt
fill ~154 ~71 ~49 ~159 ~71 ~49 grass_block
fill ~144 ~60 ~50 ~145 ~66 ~50 stone
fill ~144 ~67 ~50 ~145 ~69 ~50 dirt
fill ~144 ~70 ~50 ~145 ~70 ~50 grass_block
fill ~146 ~60 ~50 ~159 ~67 ~50 stone
fill ~146 ~68 ~50 ~159 ~70 ~50 dirt
fill ~146 ~71 ~50 ~159 ~71 ~50 grass_block
fill ~144 ~60 ~51 ~145 ~66 ~51 stone
fill ~144 ~67 ~51 ~145 ~69 ~51 dirt
fill ~144 ~70 ~51 ~145 ~70 ~51 grass_block
fill ~146 ~60 ~51 ~159 ~67 ~51 stone
fill ~146 ~68 ~51 ~159 ~70 ~51 dirt
fill ~146 ~71 ~51 ~159 ~71 ~51 grass_block
fill ~144 ~60 ~52 ~145 ~66 ~52 stone
fill ~144 ~67 ~52 ~145 ~69 ~52 dirt
fill ~144 ~70 ~52 ~145 ~70 ~52 grass_block
fill ~146 ~60 ~52 ~159 ~67 ~52 stone
fill ~146 ~68 ~52 ~159 ~70 ~52 dirt
fill ~146 ~71 ~52 ~159 ~71 ~52 grass_block
fill ~144 ~60 ~53 ~146 ~66 ~53 stone
fill ~144 ~67 ~53 ~146 ~69 ~53 dirt
fill ~144 ~70 ~53 ~146 ~70 ~53 grass_block
fill ~147 ~60 ~53 ~159 ~67 ~53 stone
fill ~147 ~68 ~53 ~159 ~70 ~53 dirt
fill ~147 ~71 ~53 ~159 ~71 ~53 grass_block
fill ~144 ~60 ~54 ~146 ~66 ~54 stone
fill ~144 ~67 ~54 ~146 ~69 ~54 dirt
fill ~144 ~70 ~54 ~146 ~70 ~54 grass_block
fill ~147 ~60 ~54 ~159 ~67 ~54 stone
fill ~147 ~68 ~54 ~159 ~70 ~54 dirt
fill ~147 ~71 ~54 ~159 ~71 ~54 grass_block
fill ~144 ~60 ~55 ~144 ~65 ~55 stone
fill ~144 ~66 ~55 ~144 ~68 ~55 dirt
fill ~144 ~69 ~55 ~144 ~69 ~55 grass_block
fill ~145 ~60 ~55 ~147 ~66 ~55 stone
fill ~145 ~67 ~55 ~147 ~69 ~55 dirt
fill ~145 ~70 ~55 ~147 ~70 ~55 grass_block
fill ~148 ~60 ~55 ~156 ~67 ~55 stone
fill ~148 ~68 ~55 ~156 ~70 ~55 dirt
fill ~148 ~71 ~55 ~156 ~71 ~55 grass_block
fill ~157 ~60 ~55 ~159 ~66 ~55 stone
fill ~157 ~67 ~55 ~159 ~69 ~55 dirt
fill ~157 ~70 ~55 ~159 ~70 ~55 grass_block
fill ~144 ~60 ~56 ~144 ~65 ~56 stone
fill ~144 ~66 ~56 ~144 ~68 ~56 dirt
fill ~144 ~69 ~56 ~144 ~69 ~56 grass_block
fill ~145 ~60 ~56 ~147 ~66 ~56 stone
fill ~145 ~67 ~56 ~147 ~69 ~56 dirt
fill ~145 ~70 ~56 ~147 ~70 ~56 grass_block
fill ~148 ~60 ~56 ~156 ~67 ~56 stone
fill ~148 ~68 ~56 ~156 ~70 ~56 dirt
fill ~148 ~71 ~56 ~156 ~71 ~56 grass_block
fill ~157 ~60 ~56 ~159 ~66 ~56 stone
fill ~157 ~67 ~56 ~159 ~69 ~56 dirt
fill ~157 ~70 ~56 ~159 ~70 ~56 grass_block
fill ~144 ~60 ~57 ~145 ~65 ~57 stone
fill ~144 ~66 ~57 ~145 ~68 ~57 dirt
fill ~144 ~69 ~57 ~145 ~69 ~57 grass_block
fill ~146 ~60 ~57 ~149 ~66 ~57 stone
fill ~146 ~67 ~57 ~149 ~69 ~57 dirt
fill ~146 ~70 ~57 ~149 ~70 ~57 grass_block
fill ~150 ~60 ~57 ~156 ~67 ~57 stone
fill ~150 ~68 ~57 ~156 ~70 ~57 dirt
fill ~150 ~71 ~57 ~156 ~71 ~57 grass_block
fill ~157 ~60 ~57 ~159 ~66 ~57 stone
fill ~157 ~67 ~57 ~159 ~69 ~57 dirt
fill ~157 ~70 ~57 ~159 ~70 ~57 grass_block
fill ~144 ~60 ~58 ~146 ~65 ~58 stone
fill ~144 ~66 ~58 ~146 ~68 ~58 dirt
fill ~144 ~69 ~58 ~146 ~69 ~58 grass_block
fill ~147 ~60 ~58 ~153 ~66 ~58 stone
fill ~147 ~67 ~58 ~153 ~69 ~58 dirt
fill ~147 ~70 ~58 ~153 ~70 ~58 grass_block
fill ~154 ~60 ~58 ~156 ~67 ~58 stone
fill ~154 ~68 ~58 ~156 ~70 ~58 dirt
fill ~154 ~71 ~58 ~156 ~71 ~58 grass_block
fill ~157 ~60 ~58 ~159 ~66 ~58 stone
fill ~157 ~67 ~58 ~159 ~69 ~58 dirt
fill ~157 ~70 ~58 ~159 ~70 ~58 grass_block
fill ~144 ~60 ~59 ~144 ~64 ~59 stone
fill ~144 ~65 ~59 ~144 ~67 ~59 dirt
fill ~144 ~68 ~59 ~144 ~68 ~59 grass_block
fill ~145 ~60 ~59 ~147 ~65 ~59 stone
fill ~145 ~66 ~59 ~147 ~68 ~59 dirt
fill ~145 ~69 ~59 ~147 ~69 ~59 grass_block
fill ~148 ~60 ~59 ~150 ~66 ~59 stone
fill ~148 ~67 ~59 ~150 ~69 ~59 dirt
fill ~148 ~70 ~59 ~150 ~70 ~59 grass_block
fill ~151 ~60 ~59 ~151 ~65 ~59 stone
fill ~151 ~66 ~59 ~151 ~68 ~59 dirt
fill ~151 ~69 ~59 ~151 ~69 ~59 grass_block
fill ~152 ~60 ~59 ~154 ~66 ~59 stone
fill ~152 ~67 ~59 ~154 ~69 ~59 dirt
fill ~152 ~70 ~59 ~154 ~70 ~59 grass_block
fill ~155 ~60 ~59 ~156 ~67 ~59 stone
fill ~155 ~68 ~59 ~156 ~70 ~59 dirt
fill ~155 ~71 ~59 ~156 ~71 ~59 grass_block
fill ~157 ~60 ~59 ~159 ~66 ~59 stone
fill ~157 ~67 ~59 ~159 ~69 ~59 dirt
fill ~157 ~70 ~59 ~159 ~70 ~59 grass_block
fill ~144 ~60 ~60 ~145 ~64 ~60 stone
fill ~144 ~65 ~60 ~145 ~67 ~60 dirt
fill ~144 ~68 ~60 ~145 ~68 ~60 grass_block
fill ~146 ~60 ~60 ~153 ~65 ~60 stone
fill ~146 ~66 ~60 ~153 ~68 ~60 dirt
fill ~146 ~69 ~60 ~153 ~69 ~60 grass_block
fill ~154 ~60 ~60 ~154 ~66 ~60 stone
fill ~154 ~67 ~60 ~154 ~69 ~60 dirt
fill ~154 ~70 ~60 ~154 ~70 ~60 grass_block
fill ~155 ~60 ~60 ~156 ~67 ~60 stone
fill ~155 ~68 ~60 ~156 ~70 ~60 dirt
fill ~155 ~71 ~60 ~156 ~71 ~60 grass_block
fill ~157 ~60 ~60 ~159 ~66 ~60 stone
fill ~157 ~67 ~60 ~159 ~69 ~60 dirt
fill ~157 ~70 ~60 ~159 ~70 ~60 grass_block
fill ~144 ~60 ~61 ~146 ~64 ~61 stone
fill ~144 ~65 ~61 ~146 ~67 ~61 dirt
fill ~144 ~68 ~61 ~146 ~68 ~61 grass_block
fill ~147 ~60 ~61 ~152 ~65 ~61 stone
fill ~147 ~66 ~61 ~152 ~68 ~61 dirt
fill ~147 ~69 ~61 ~152 ~69 ~61 grass_block
fill ~153 ~60 ~61 ~154 ~66 ~61 stone
fill ~153 ~67 ~61 ~154 ~69 ~61 dirt
fill ~153 ~70 ~61 ~154 ~70 ~61 grass_block
fill ~155 ~60 ~61 ~156 ~67 ~61 stone
fill ~155 ~68 ~61 ~156 ~70 ~61 dirt
fill ~155 ~71 ~61 ~156 ~71 ~61 grass_block
fill ~157 ~60 ~61 ~159 ~66 ~61 stone
fill ~157 ~67 ~61 ~159 ~69 ~61 dirt
fill ~157 ~70 ~61 ~159 ~70 ~61 grass_block
fill ~144 ~60 ~62 ~149 ~64 ~62 stone
fill ~144 ~65 ~62 ~149 ~67 ~62 dirt
fill ~144 ~68 ~62 ~149 ~68 ~62 grass_block
fill ~150 ~60 ~62 ~151 ~65 ~62 stone
fill ~150 ~66 ~62 ~151 ~68 ~62 dirt
fill ~150 ~69 ~62 ~151 ~69 ~62 grass_block
fill ~152 ~60 ~62 ~154 ~66 ~62 stone
fill ~152 ~67 ~62 ~154 ~69 ~62 dirt
fill ~152 ~70 ~62 ~154 ~70 ~62 grass_block
fill ~155 ~60 ~62 ~155 ~67 ~62 stone
fill ~155 ~68 ~62 ~155 ~70 ~62 dirt
fill ~155 ~71 ~62 ~155 ~71 ~62 grass_block
fill ~156 ~60 ~62 ~159 ~66 ~62 stone
fill ~156 ~67 ~62 ~159 ~69 ~62 dirt
fill ~156 ~70 ~62 ~159 ~70 ~62 grass_block
fill ~144 ~60 ~63 ~148 ~64 ~63 stone
fill ~144 ~65 ~63 ~148 ~67 ~63 dirt
fill ~144 ~68 ~63 ~148 ~68 ~63 grass_block
fill ~149 ~60 ~63 ~151 ~65 ~63 stone
fill ~149 ~66 ~63 ~151 ~68 ~63 dirt
fill ~149 ~69 ~63 ~151 ~69 ~63 grass_block
fill ~152 ~60 ~63 ~159 ~66 ~63 stone
fill ~152 ~67 ~63 ~159 ~69 ~63 dirt
fill ~152 ~70 ~63 ~159 ~70 ~63 grass_block