fill ~192 ~60 ~64 ~193 ~65 ~64 stone
fill ~192 ~66 ~64 ~193 ~68 ~64 dirt
fill ~192 ~69 ~64 ~193 ~69 ~64 grass_block
fill ~194 ~60 ~64 ~201 ~64 ~64 stone
fill ~194 ~65 ~64 ~201 ~67 ~64 dirt
fill ~194 ~68 ~64 ~201 ~68 ~64 grass_block
fill ~202 ~60 ~64 ~203 ~65 ~64 stone
fill ~202 ~66 ~64 ~203 ~68 ~64 dirt
fill ~202 ~69 ~64 ~203 ~69 ~64 grass_block
fill ~204 ~60 ~64 ~207 ~66 ~64 stone
fill ~204 ~67 ~64 ~207 ~69 ~64 dirt
fill ~204 ~70 ~64 ~207 ~70 ~64 grass_block
fill ~192 ~60 ~65 ~192 ~66 ~65 stone
fill ~192 ~67 ~65 ~192 ~69 ~65 dirt
fill ~192 ~70 ~65 ~192 ~70 ~65 grass_block
fill ~193 ~60 ~65 ~194 ~65 ~65 stone
fill ~193 ~66 ~65 ~194 ~68 ~65 dirt
fill ~193 ~69 ~65 ~194 ~69 ~65 grass_block
fill ~195 ~60 ~65 ~201 ~64 ~65 stone
fill ~195 ~65 ~65 ~201 ~67 ~65 dirt
fill ~195 ~68 ~65 ~201 ~68 ~65 grass_block
fill ~202 ~60 ~65 ~203 ~65 ~65 stone
fill ~202 ~66 ~65 ~203 ~68 ~65 dirt
fill ~202 ~69 ~65 ~203 ~69 ~65 grass_block
fill ~204 ~60 ~65 ~207 ~66 ~65 stone
fill ~204 ~67 ~65 ~207 ~69 ~65 dirt
fill ~204 ~70 ~65 ~207 ~70 ~65 grass_block
fill ~192 ~60 ~66 ~192 ~66 ~66 stone
fill ~192 ~67 ~66 ~192 ~69 ~66 dirt
fill ~192 ~70 ~66 ~192 ~70 ~66 grass_block
fill ~193 ~60 ~66 ~197 ~65 ~66 stone
fill ~193 ~66 ~66 ~197 ~68 ~66 dirt
fill ~193 ~69 ~66 ~197 ~69 ~66 grass_block
fill ~198 ~60 ~66 ~201 ~64 ~66 stone
fill ~198 ~65 ~66 ~201 ~67 ~66 dirt
fill ~198 ~68 ~66 ~201 ~68 ~66 grass_block
fill ~202 ~60 ~66 ~203 ~65 ~66 stone
fill ~202 ~66 ~66 ~203 ~68 ~66 dirt
fill ~202 ~69 ~66 ~203 ~69 ~66 grass_block
fill ~204 ~60 ~66 ~207 ~66 ~66 stone
fill ~204 ~67 ~66 ~207 ~69 ~66 dirt
fill ~204 ~70 ~66 ~207 ~70 ~66 grass_block
fill ~192 ~60 ~67 ~193 ~66 ~67 stone
fill ~192 ~67 ~67 ~193 ~69 ~67 dirt
fill ~192 ~70 ~67 ~193 ~70 ~67 grass_block
fill ~194 ~60 ~67 ~197 ~65 ~67 stone
fill ~194 ~66 ~67 ~197 ~68 ~67 dirt
fill ~194 ~69 ~67 ~197 ~69 ~67 grass_block
fill ~198 ~60 ~67 ~201 ~64 ~67 stone
fill ~198 ~65 ~67 ~201 ~67 ~67 dirt
fill ~198 ~68 ~67 ~201 ~68 ~67 grass_block
fill ~202 ~60 ~67 ~203 ~65 ~67 stone
fill ~202 ~66 ~67 ~203 ~68 ~67 dirt
fill ~202 ~69 ~67 ~203 ~69 ~67 grass_block
fill ~204 ~60 ~67 ~207 ~66 ~67 stone
fill ~204 ~67 ~67 ~207 ~69 ~67 dirt
fill ~204 ~70 ~67 ~207 ~70 ~67 grass_block
fill ~192 ~60 ~68 ~195 ~66 ~68 stone
fill ~192 ~67 ~68 ~195 ~69 ~68 dirt
fill ~192 ~70 ~68 ~195 ~70 ~68 grass_block
fill ~196 ~60 ~68 ~199 ~65 ~68 stone
fill ~196 ~66 ~68 ~199 ~68 ~68 dirt
fill ~196 ~69 ~68 ~199 ~69 ~68 grass_block
fill ~200 ~60 ~68 ~200 ~64 ~68 stone
fill ~200 ~65 ~68 ~200 ~67 ~68 dirt
fill ~200 ~68 ~68 ~200 ~68 ~68 grass_block
fill ~201 ~60 ~68 ~203 ~65 ~68 stone
fill ~201 ~66 ~68 ~203 ~68 ~68 dirt
fill ~201 ~69 ~68 ~203 ~69 ~68 grass_block
fill ~204 ~60 ~68 ~207 ~66 ~68 stone
fill ~204 ~67 ~68 ~207 ~69 ~68 dirt
fill ~204 ~70 ~68 ~207 ~70 ~68 grass_block
fill ~192 ~60 ~69 ~192 ~67 ~69 stone
fill ~192 ~68 ~69 ~192 ~70 ~69 dirt
fill ~192 ~71 ~69 ~192 ~71 ~69 grass_block
fill ~193 ~60 ~69 ~196 ~66 ~69 stone
fill ~193 ~67 ~69 ~196 ~69 ~69 dirt
fill ~193 ~70 ~69 ~196 ~70 ~69 grass_block
fill ~197 ~60 ~69 ~203 ~65 ~69 stone
fill ~197 ~66 ~69 ~203 ~68 ~69 dirt
fill ~197 ~69 ~69 ~203 ~69 ~69 grass_block
fill ~204 ~60 ~69 ~207 ~66 ~69 stone
fill ~204 ~67 ~69 ~207 ~69 ~69 dirt
fill ~204 ~70 ~69 ~207 ~70 ~69 grass_block
fill ~192 ~60 ~70 ~192 ~67 ~70 stone
fill ~192 ~68 ~70 ~192 ~70 ~70 dirt
fill ~192 ~71 ~70 ~192 ~71 ~70 grass_block
fill ~193 ~60 ~70 ~197 ~66 ~70 stone
fill ~193 ~67 ~70 ~197 ~69 ~70 dirt
fill ~193 ~70 ~70 ~197 ~70 ~70 grass_block
fill ~198 ~60 ~70 ~203 ~65 ~70 stone
fill ~198 ~66 ~70 ~203 ~68 ~70 dirt
fill ~198 ~69 ~70 ~203 ~69 ~70 grass_block
fill ~204 ~60 ~70 ~207 ~66 ~70 stone
fill ~204 ~67 ~70 ~207 ~69 ~70 dirt
fill ~204 ~70 ~70 ~207 ~70 ~70 grass_block
fill ~192 ~60 ~71 ~192 ~66 ~71 stone
fill ~192 ~67 ~71 ~192 ~69 ~71 dirt
fill ~192 ~70 ~71 ~192 ~70 ~71 grass_block
fill ~193 ~60 ~71 ~194 ~67 ~71 stone
fill ~193 ~68 ~71 ~194 ~70 ~71 dirt
fill ~193 ~71 ~71 ~194 ~71 ~71 grass_block
fill ~195 ~60 ~71 ~199 ~66 ~71 stone
fill ~195 ~67 ~71 ~199 ~69 ~71 dirt
fill ~195 ~70 ~71 ~199 ~70 ~71 grass_block
fill ~200 ~60 ~71 ~200 ~65 ~71 stone
fill ~200 ~66 ~71 ~200 ~68 ~71 dirt
fill ~200 ~69 ~71 ~200 ~69 ~71 grass_block
fill ~201 ~60 ~71 ~207 ~66 ~71 stone
fill ~201 ~67 ~71 ~207 ~69 ~71 dirt
fill ~201 ~70 ~71 ~207 ~70 ~71 grass_block
fill ~192 ~60 ~72 ~192 ~66 ~72 stone
fill ~192 ~67 ~72 ~192 ~69 ~72 dirt
fill ~192 ~70 ~72 ~192 ~70 ~72 grass_block
fill ~193 ~60 ~72 ~194 ~67 ~72 stone
fill ~193 ~68 ~72 ~194 ~70 ~72 dirt
fill ~193 ~71 ~72 ~194 ~71 ~72 grass_block
fill ~195 ~60 ~72 ~207 ~66 ~72 stone
fill ~195 ~67 ~72 ~207 ~69 ~72 dirt
fill ~195 ~70 ~72 ~207 ~70 ~72 grass_block
fill ~192 ~60 ~73 ~194 ~67 ~73 stone
fill ~192 ~68 ~73 ~194 ~70 ~73 dirt
fill ~192 ~71 ~73 ~194 ~71 ~73 grass_block
fill ~195 ~60 ~73 ~206 ~66 ~73 stone
fill ~195 ~67 ~73 ~206 ~69 ~73 dirt
fill ~195 ~70 ~73 ~206 ~70 ~73 grass_block
fill ~207 ~60 ~73 ~207 ~67 ~73 stone
fill ~207 ~68 ~73 ~207 ~70 ~73 dirt
fill ~207 ~71 ~73 ~207 ~71 ~73 grass_block
fill ~192 ~60 ~74 ~192 ~66 ~74 stone
fill ~192 ~67 ~74 ~192 ~69 ~74 dirt
fill ~192 ~70 ~74 ~192 ~70 ~74 grass_block
fill ~193 ~60 ~74 ~194 ~67 ~74 stone
fill ~193 ~68 ~74 ~194 ~70 ~74 dirt
fill ~193 ~71 ~74 ~194 ~71 ~74 grass_block
fill ~195 ~60 ~74 ~205 ~66 ~74 stone
fill ~195 ~67 ~74 ~205 ~69 ~74 dirt
fill ~195 ~70 ~74 ~205 ~70 ~74 grass_block
fill ~206 ~60 ~74 ~207 ~67 ~74 stone
fill ~206 ~68 ~74 ~207 ~70 ~74 dirt
fill ~206 ~71 ~74 ~207 ~71 ~74 grass_block
fill ~192 ~60 ~75 ~204 ~66 ~75 stone
fill ~192 ~67 ~75 ~204 ~69 ~75 dirt
fill ~192 ~70 ~75 ~204 ~70 ~75 grass_block
fill ~205 ~60 ~75 ~207 ~67 ~75 stone
fill ~205 ~68 ~75 ~207 ~70 ~75 dirt
fill ~205 ~71 ~75 ~207 ~71 ~75 grass_block
fill ~192 ~60 ~76 ~196 ~66 ~76 stone
fill ~192 ~67 ~76 ~196 ~69 ~76 dirt
fill ~192 ~70 ~76 ~196 ~70 ~76 grass_block
fill ~197 ~60 ~76 ~202 ~65 ~76 stone
fill ~197 ~66 ~76 ~202 ~68 ~76 dirt
fill ~197 ~69 ~76 ~202 ~69 ~76 grass_block
fill ~203 ~60 ~76 ~205 ~66 ~76 stone
fill ~203 ~67 ~76 ~205 ~69 ~76 dirt
fill ~203 ~70 ~76 ~205 ~70 ~76 grass_block
fill ~206 ~60 ~76 ~207 ~67 ~76 stone
fill ~206 ~68 ~76 ~207 ~70 ~76 dirt
fill ~206 ~71 ~76 ~207 ~71 ~76 grass_block
fill ~192 ~60 ~77 ~195 ~66 ~77 stone
fill ~192 ~67 ~77 ~195 ~69 ~77 dirt
fill ~192 ~70 ~77 ~195 ~70 ~77 grass_block
fill ~196 ~60 ~77 ~203 ~65 ~77 stone
fill ~196 ~66 ~77 ~203 ~68 ~77 dirt
fill ~196 ~69 ~77 ~203 ~69 ~77 grass_block
fill ~204 ~60 ~77 ~206 ~66 ~77 stone
fill ~204 ~67 ~77 ~206 ~69 ~77 dirt
fill ~204 ~70 ~77 ~206 ~70 ~77 grass_block
fill ~207 ~60 ~77 ~207 ~67 ~77 stone
fill ~207 ~68 ~77 ~207 ~70 ~77 dirt
fill ~207 ~71 ~77 ~207 ~71 ~77 grass_block
fill ~192 ~60 ~78 ~194 ~66 ~78 stone
fill ~192 ~67 ~78 ~194 ~69 ~78 dirt
fill ~192 ~70 ~78 ~194 ~70 ~78 grass_block
fill ~195 ~60 ~78 ~197 ~65 ~78 stone
fill ~195 ~66 ~78 ~197 ~68 ~78 dirt
fill ~195 ~69 ~78 ~197 ~69 ~78 grass_block
fill ~198 ~60 ~78 ~201 ~64 ~78 stone
fill ~198 ~65 ~78 ~201 ~67 ~78 dirt
fill ~198 ~68 ~78 ~201 ~68 ~78 grass_block
fill ~202 ~60 ~78 ~204 ~65 ~78 stone
fill ~202 ~66 ~78 ~204 ~68 ~78 dirt
fill ~202 ~69 ~78 ~204 ~69 ~78 grass_block
fill ~205 ~60 ~78 ~207 ~66 ~78 stone
fill ~205 ~67 ~78 ~207 ~69 ~78 dirt
fill ~205 ~70 ~78 ~207 ~70 ~78 grass_block
fill ~192 ~60 ~79 ~196 ~65 ~79 stone
fill ~192 ~66 ~79 ~196 ~68 ~79 dirt
fill ~192 ~69 ~79 ~196 ~69 ~79 grass_block
fill ~197 ~60 ~79 ~201 ~64 ~79 stone
fill ~197 ~65 ~79 ~201 ~67 ~79 dirt
fill ~197 ~68 ~79 ~201 ~68 ~79 grass_block
fill ~202 ~60 ~79 ~206 ~65 ~79 stone
fill ~202 ~66 ~79 ~206 ~68 ~79 dirt
fill ~202 ~69 ~79 ~206 ~69 ~79 grass_block
fill ~207 ~60 ~79 ~207 ~66 ~79 stone
fill ~207 ~67 ~79 ~207 ~69 ~79 dirt
fill ~207 ~70 ~79 ~207 ~70 ~79 grass_block