fill ~96 ~60 ~128 ~97 ~64 ~128 stone
fill ~96 ~65 ~128 ~97 ~67 ~128 dirt
fill ~96 ~68 ~128 ~97 ~68 ~128 grass_block
fill ~98 ~60 ~128 ~98 ~63 ~128 stone
fill ~98 ~64 ~128 ~98 ~66 ~128 dirt
fill ~98 ~67 ~128 ~98 ~67 ~128 grass_block
fill ~99 ~60 ~128 ~100 ~64 ~128 stone
fill ~99 ~65 ~128 ~100 ~67 ~128 dirt
fill ~99 ~68 ~128 ~100 ~68 ~128 grass_block
fill ~101 ~60 ~128 ~102 ~65 ~128 stone
fill ~101 ~66 ~128 ~102 ~68 ~128 dirt
fill ~101 ~69 ~128 ~102 ~69 ~128 grass_block
fill ~103 ~60 ~128 ~105 ~66 ~128 stone
fill ~103 ~67 ~128 ~105 ~69 ~128 dirt
fill ~103 ~70 ~128 ~105 ~70 ~128 grass_block
fill ~106 ~60 ~128 ~107 ~65 ~128 stone
fill ~106 ~66 ~128 ~107 ~68 ~128 dirt
fill ~106 ~69 ~128 ~107 ~69 ~128 grass_block
fill ~108 ~60 ~128 ~109 ~64 ~128 stone
fill ~108 ~65 ~128 ~109 ~67 ~128 dirt
fill ~108 ~68 ~128 ~109 ~68 ~128 grass_block
fill ~110 ~60 ~128 ~111 ~65 ~128 stone
fill ~110 ~66 ~128 ~111 ~68 ~128 dirt
fill ~110 ~69 ~128 ~111 ~69 ~128 grass_block
fill ~96 ~60 ~129 ~97 ~64 ~129 stone
fill ~96 ~65 ~129 ~97 ~67 ~129 dirt
fill ~96 ~68 ~129 ~97 ~68 ~129 grass_block
fill ~98 ~60 ~129 ~98 ~63 ~129 stone
fill ~98 ~64 ~129 ~98 ~66 ~129 dirt
fill ~98 ~67 ~129 ~98 ~67 ~129 grass_block
fill ~99 ~60 ~129 ~101 ~64 ~129 stone
fill ~99 ~65 ~129 ~101 ~67 ~129 dirt
fill ~99 ~68 ~129 ~101 ~68 ~129 grass_block
fill ~102 ~60 ~129 ~103 ~65 ~129 stone
fill ~102 ~66 ~129 ~103 ~68 ~129 dirt
fill ~102 ~69 ~129 ~103 ~69 ~129 grass_block
fill ~104 ~60 ~129 ~105 ~66 ~129 stone
fill ~104 ~67 ~129 ~105 ~69 ~129 dirt
fill ~104 ~70 ~129 ~105 ~70 ~129 grass_block
fill ~106 ~60 ~129 ~107 ~65 ~129 stone
fill ~106 ~66 ~129 ~107 ~68 ~129 dirt
fill ~106 ~69 ~129 ~107 ~69 ~129 grass_block
fill ~108 ~60 ~129 ~110 ~64 ~129 stone
fill ~108 ~65 ~129 ~110 ~67 ~129 dirt
fill ~108 ~68 ~129 ~110 ~68 ~129 grass_block
fill ~111 ~60 ~129 ~111 ~65 ~129 stone
fill ~111 ~66 ~129 ~111 ~68 ~129 dirt
fill ~111 ~69 ~129 ~111 ~69 ~129 grass_block
fill ~96 ~60 ~130 ~96 ~63 ~130 stone
fill ~96 ~64 ~130 ~96 ~66 ~130 dirt
fill ~96 ~67 ~130 ~96 ~67 ~130 grass_block
fill ~97 ~60 ~130 ~98 ~64 ~130 stone
fill ~97 ~65 ~130 ~98 ~67 ~130 dirt
fill ~97 ~68 ~130 ~98 ~68 ~130 grass_block
fill ~99 ~60 ~130 ~99 ~63 ~130 stone
fill ~99 ~64 ~130 ~99 ~66 ~130 dirt
fill ~99 ~67 ~130 ~99 ~67 ~130 grass_block
fill ~100 ~60 ~130 ~102 ~64 ~130 stone
fill ~100 ~65 ~130 ~102 ~67 ~130 dirt
fill ~100 ~68 ~130 ~102 ~68 ~130 grass_block
fill ~103 ~60 ~130 ~104 ~65 ~130 stone
fill ~103 ~66 ~130 ~104 ~68 ~130 dirt
fill ~103 ~69 ~130 ~104 ~69 ~130 grass_block
fill ~105 ~60 ~130 ~106 ~66 ~130 stone
fill ~105 ~67 ~130 ~106 ~69 ~130 dirt
fill ~105 ~70 ~130 ~106 ~70 ~130 grass_block
fill ~107 ~60 ~130 ~108 ~65 ~130 stone
fill ~107 ~66 ~130 ~108 ~68 ~130 dirt
fill ~107 ~69 ~130 ~108 ~69 ~130 grass_block
fill ~109 ~60 ~130 ~111 ~64 ~130 stone
fill ~109 ~65 ~130 ~111 ~67 ~130 dirt
fill ~109 ~68 ~130 ~111 ~68 ~130 grass_block
fill ~96 ~60 ~131 ~100 ~63 ~131 stone
fill ~96 ~64 ~131 ~100 ~66 ~131 dirt
fill ~96 ~67 ~131 ~100 ~67 ~131 grass_block
fill ~101 ~60 ~131 ~103 ~64 ~131 stone
fill ~101 ~65 ~131 ~103 ~67 ~131 dirt
fill ~101 ~68 ~131 ~103 ~68 ~131 grass_block
fill ~104 ~60 ~131 ~109 ~65 ~131 stone
fill ~104 ~66 ~131 ~109 ~68 ~131 dirt
fill ~104 ~69 ~131 ~109 ~69 ~131 grass_block
fill ~110 ~60 ~131 ~111 ~64 ~131 stone
fill ~110 ~65 ~131 ~111 ~67 ~131 dirt
fill ~110 ~68 ~131 ~111 ~68 ~131 grass_block
fill ~96 ~60 ~132 ~101 ~63 ~132 stone
fill ~96 ~64 ~132 ~101 ~66 ~132 dirt
fill ~96 ~67 ~132 ~101 ~67 ~132 grass_block
fill ~102 ~60 ~132 ~104 ~64 ~132 stone
fill ~102 ~65 ~132 ~104 ~67 ~132 dirt
fill ~102 ~68 ~132 ~104 ~68 ~132 grass_block
fill ~105 ~60 ~132 ~109 ~65 ~132 stone
fill ~105 ~66 ~132 ~109 ~68 ~132 dirt
fill ~105 ~69 ~132 ~109 ~69 ~132 grass_block
fill ~110 ~60 ~132 ~111 ~64 ~132 stone
fill ~110 ~65 ~132 ~111 ~67 ~132 dirt
fill ~110 ~68 ~132 ~111 ~68 ~132 grass_block
fill ~96 ~60 ~133 ~102 ~63 ~133 stone
fill ~96 ~64 ~133 ~102 ~66 ~133 dirt
fill ~96 ~67 ~133 ~102 ~67 ~133 grass_block
fill ~103 ~60 ~133 ~105 ~64 ~133 stone
fill ~103 ~65 ~133 ~105 ~67 ~133 dirt
fill ~103 ~68 ~133 ~105 ~68 ~133 grass_block
fill ~106 ~60 ~133 ~109 ~65 ~133 stone
fill ~106 ~66 ~133 ~109 ~68 ~133 dirt
fill ~106 ~69 ~133 ~109 ~69 ~133 grass_block
fill ~110 ~60 ~133 ~111 ~64 ~133 stone
fill ~110 ~65 ~133 ~111 ~67 ~133 dirt
fill ~110 ~68 ~133 ~111 ~68 ~133 grass_block
fill ~96 ~60 ~134 ~103 ~63 ~134 stone
fill ~96 ~64 ~134 ~103 ~66 ~134 dirt
fill ~96 ~67 ~134 ~103 ~67 ~134 grass_block
fill ~104 ~60 ~134 ~106 ~64 ~134 stone
fill ~104 ~65 ~134 ~106 ~67 ~134 dirt
fill ~104 ~68 ~134 ~106 ~68 ~134 grass_block
fill ~107 ~60 ~134 ~110 ~65 ~134 stone
fill ~107 ~66 ~134 ~110 ~68 ~134 dirt
fill ~107 ~69 ~134 ~110 ~69 ~134 grass_block
fill ~111 ~60 ~134 ~111 ~64 ~134 stone
fill ~111 ~65 ~134 ~111 ~67 ~134 dirt
fill ~111 ~68 ~134 ~111 ~68 ~134 grass_block
fill ~96 ~60 ~135 ~103 ~63 ~135 stone
fill ~96 ~64 ~135 ~103 ~66 ~135 dirt
fill ~96 ~67 ~135 ~103 ~67 ~135 grass_block
fill ~104 ~60 ~135 ~107 ~64 ~135 stone
fill ~104 ~65 ~135 ~107 ~67 ~135 dirt
fill ~104 ~68 ~135 ~107 ~68 ~135 grass_block
fill ~108 ~60 ~135 ~110 ~65 ~135 stone
fill ~108 ~66 ~135 ~110 ~68 ~135 dirt
fill ~108 ~69 ~135 ~110 ~69 ~135 grass_block
fill ~111 ~60 ~135 ~111 ~64 ~135 stone
fill ~111 ~65 ~135 ~111 ~67 ~135 dirt
fill ~111 ~68 ~135 ~111 ~68 ~135 grass_block
fill ~96 ~60 ~136 ~104 ~63 ~136 stone
fill ~96 ~64 ~136 ~104 ~66 ~136 dirt
fill ~96 ~67 ~136 ~104 ~67 ~136 grass_block
fill ~105 ~60 ~136 ~108 ~64 ~136 stone
fill ~105 ~65 ~136 ~108 ~67 ~136 dirt
fill ~105 ~68 ~136 ~108 ~68 ~136 grass_block
fill ~109 ~60 ~136 ~110 ~65 ~136 stone
fill ~109 ~66 ~136 ~110 ~68 ~136 dirt
fill ~109 ~69 ~136 ~110 ~69 ~136 grass_block
fill ~111 ~60 ~136 ~111 ~64 ~136 stone
fill ~111 ~65 ~136 ~111 ~67 ~136 dirt
fill ~111 ~68 ~136 ~111 ~68 ~136 grass_block
fill ~96 ~60 ~137 ~105 ~63 ~137 stone
fill ~96 ~64 ~137 ~105 ~66 ~137 dirt
fill ~96 ~67 ~137 ~105 ~67 ~137 grass_block
fill ~106 ~60 ~137 ~111 ~64 ~137 stone
fill ~106 ~65 ~137 ~111 ~67 ~137 dirt
fill ~106 ~68 ~137 ~111 ~68 ~137 grass_block
fill ~96 ~60 ~138 ~107 ~63 ~138 stone
fill ~96 ~64 ~138 ~107 ~66 ~138 dirt
fill ~96 ~67 ~138 ~107 ~67 ~138 grass_block
fill ~108 ~60 ~138 ~111 ~64 ~138 stone
fill ~108 ~65 ~138 ~111 ~67 ~138 dirt
fill ~108 ~68 ~138 ~111 ~68 ~138 grass_block
fill ~96 ~60 ~139 ~109 ~63 ~139 stone
fill ~96 ~64 ~139 ~109 ~66 ~139 dirt
fill ~96 ~67 ~139 ~109 ~67 ~139 grass_block
fill ~110 ~60 ~139 ~111 ~64 ~139 stone
fill ~110 ~65 ~139 ~111 ~67 ~139 dirt
fill ~110 ~68 ~139 ~111 ~68 ~139 grass_block
fill ~96 ~60 ~140 ~111 ~63 ~140 stone
fill ~96 ~64 ~140 ~111 ~66 ~140 dirt
fill ~96 ~67 ~140 ~111 ~67 ~140 grass_block
fill ~96 ~60 ~141 ~111 ~63 ~141 stone
fill ~96 ~64 ~141 ~111 ~66 ~141 dirt
fill ~96 ~67 ~141 ~111 ~67 ~141 grass_block
fill ~96 ~60 ~142 ~111 ~63 ~142 stone
fill ~96 ~64 ~142 ~111 ~66 ~142 dirt
fill ~96 ~67 ~142 ~111 ~67 ~142 grass_block
fill ~96 ~60 ~143 ~107 ~63 ~143 stone
fill ~96 ~64 ~143 ~107 ~66 ~143 dirt
fill ~96 ~67 ~143 ~107 ~67 ~143 grass_block
fill ~108 ~60 ~143 ~109 ~62 ~143 stone
fill ~108 ~63 ~143 ~109 ~65 ~143 dirt
fill ~108 ~66 ~143 ~109 ~66 ~143 grass_block
fill ~110 ~60 ~143 ~111 ~63 ~143 stone
fill ~110 ~64 ~143 ~111 ~66 ~143 dirt
fill ~110 ~67 ~143 ~111 ~67 ~143 grass_block