fill ~176 ~60 ~32 ~176 ~65 ~32 stone
fill ~176 ~66 ~32 ~176 ~68 ~32 dirt
fill ~176 ~69 ~32 ~176 ~69 ~32 grass_block
fill ~177 ~60 ~32 ~185 ~66 ~32 stone
fill ~177 ~67 ~32 ~185 ~69 ~32 dirt
fill ~177 ~70 ~32 ~185 ~70 ~32 grass_block
fill ~186 ~60 ~32 ~189 ~65 ~32 stone
fill ~186 ~66 ~32 ~189 ~68 ~32 dirt
fill ~186 ~69 ~32 ~189 ~69 ~32 grass_block
fill ~190 ~60 ~32 ~191 ~64 ~32 stone
fill ~190 ~65 ~32 ~191 ~67 ~32 dirt
fill ~190 ~68 ~32 ~191 ~68 ~32 grass_block
fill ~176 ~60 ~33 ~185 ~66 ~33 stone
fill ~176 ~67 ~33 ~185 ~69 ~33 dirt
fill ~176 ~70 ~33 ~185 ~70 ~33 grass_block
fill ~186 ~60 ~33 ~190 ~65 ~33 stone
fill ~186 ~66 ~33 ~190 ~68 ~33 dirt
fill ~186 ~69 ~33 ~190 ~69 ~33 grass_block
fill ~191 ~60 ~33 ~191 ~64 ~33 stone
fill ~191 ~65 ~33 ~191 ~67 ~33 dirt
fill ~191 ~68 ~33 ~191 ~68 ~33 grass_block
fill ~176 ~60 ~34 ~176 ~65 ~34 stone
fill ~176 ~66 ~34 ~176 ~68 ~34 dirt
fill ~176 ~69 ~34 ~176 ~69 ~34 grass_block
fill ~177 ~60 ~34 ~186 ~66 ~34 stone
fill ~177 ~67 ~34 ~186 ~69 ~34 dirt
fill ~177 ~70 ~34 ~186 ~70 ~34 grass_block
fill ~187 ~60 ~34 ~191 ~65 ~34 stone
fill ~187 ~66 ~34 ~191 ~68 ~34 dirt
fill ~187 ~69 ~34 ~191 ~69 ~34 grass_block
fill ~176 ~60 ~35 ~177 ~65 ~35 stone
fill ~176 ~66 ~35 ~177 ~68 ~35 dirt
fill ~176 ~69 ~35 ~177 ~69 ~35 grass_block
fill ~178 ~60 ~35 ~186 ~66 ~35 stone
fill ~178 ~67 ~35 ~186 ~69 ~35 dirt
fill ~178 ~70 ~35 ~186 ~70 ~35 grass_block
fill ~187 ~60 ~35 ~191 ~65 ~35 stone
fill ~187 ~66 ~35 ~191 ~68 ~35 dirt
fill ~187 ~69 ~35 ~191 ~69 ~35 grass_block
fill ~176 ~60 ~36 ~182 ~65 ~36 stone
fill ~176 ~66 ~36 ~182 ~68 ~36 dirt
fill ~176 ~69 ~36 ~182 ~69 ~36 grass_block
fill ~183 ~60 ~36 ~185 ~66 ~36 stone
fill ~183 ~67 ~36 ~185 ~69 ~36 dirt
fill ~183 ~70 ~36 ~185 ~70 ~36 grass_block
fill ~186 ~60 ~36 ~191 ~65 ~36 stone
fill ~186 ~66 ~36 ~191 ~68 ~36 dirt
fill ~186 ~69 ~36 ~191 ~69 ~36 grass_block
fill ~176 ~60 ~37 ~191 ~65 ~37 stone
fill ~176 ~66 ~37 ~191 ~68 ~37 dirt
fill ~176 ~69 ~37 ~191 ~69 ~37 grass_block
fill ~176 ~60 ~38 ~191 ~65 ~38 stone
fill ~176 ~66 ~38 ~191 ~68 ~38 dirt
fill ~176 ~69 ~38 ~191 ~69 ~38 grass_block
fill ~176 ~60 ~39 ~176 ~65 ~39 stone
fill ~176 ~66 ~39 ~176 ~68 ~39 dirt
fill ~176 ~69 ~39 ~176 ~69 ~39 grass_block
fill ~177 ~60 ~39 ~179 ~64 ~39 stone
fill ~177 ~65 ~39 ~179 ~67 ~39 dirt
fill ~177 ~68 ~39 ~179 ~68 ~39 grass_block
fill ~180 ~60 ~39 ~180 ~65 ~39 stone
fill ~180 ~66 ~39 ~180 ~68 ~39 dirt
fill ~180 ~69 ~39 ~180 ~69 ~39 grass_block
fill ~181 ~60 ~39 ~184 ~64 ~39 stone
fill ~181 ~65 ~39 ~184 ~67 ~39 dirt
fill ~181 ~68 ~39 ~184 ~68 ~39 grass_block
fill ~185 ~60 ~39 ~191 ~65 ~39 stone
fill ~185 ~66 ~39 ~191 ~68 ~39 dirt
fill ~185 ~69 ~39 ~191 ~69 ~39 grass_block
fill ~176 ~60 ~40 ~190 ~64 ~40 stone
fill ~176 ~65 ~40 ~190 ~67 ~40 dirt
fill ~176 ~68 ~40 ~190 ~68 ~40 grass_block
fill ~191 ~60 ~40 ~191 ~65 ~40 stone
fill ~191 ~66 ~40 ~191 ~68 ~40 dirt
fill ~191 ~69 ~40 ~191 ~69 ~40 grass_block
fill ~176 ~60 ~41 ~176 ~65 ~41 stone
fill ~176 ~66 ~41 ~176 ~68 ~41 dirt
fill ~176 ~69 ~41 ~176 ~69 ~41 grass_block
fill ~177 ~60 ~41 ~191 ~64 ~41 stone
fill ~177 ~65 ~41 ~191 ~67 ~41 dirt
fill ~177 ~68 ~41 ~191 ~68 ~41 grass_block
fill ~176 ~60 ~42 ~176 ~65 ~42 stone
fill ~176 ~66 ~42 ~176 ~68 ~42 dirt
fill ~176 ~69 ~42 ~176 ~69 ~42 grass_block
fill ~177 ~60 ~42 ~178 ~64 ~42 stone
fill ~177 ~65 ~42 ~178 ~67 ~42 dirt
fill ~177 ~68 ~42 ~178 ~68 ~42 grass_block
fill ~179 ~60 ~42 ~181 ~65 ~42 stone
fill ~179 ~66 ~42 ~181 ~68 ~42 dirt
fill ~179 ~69 ~42 ~181 ~69 ~42 grass_block
fill ~182 ~60 ~42 ~184 ~64 ~42 stone
fill ~182 ~65 ~42 ~184 ~67 ~42 dirt
fill ~182 ~68 ~42 ~184 ~68 ~42 grass_block
fill ~185 ~60 ~42 ~185 ~63 ~42 stone
fill ~185 ~64 ~42 ~185 ~66 ~42 dirt
fill ~185 ~67 ~42 ~185 ~67 ~42 grass_block
fill ~186 ~60 ~42 ~191 ~64 ~42 stone
fill ~186 ~65 ~42 ~191 ~67 ~42 dirt
fill ~186 ~68 ~42 ~191 ~68 ~42 grass_block
fill ~176 ~60 ~43 ~182 ~65 ~43 stone
fill ~176 ~66 ~43 ~182 ~68 ~43 dirt
fill ~176 ~69 ~43 ~182 ~69 ~43 grass_block
fill ~183 ~60 ~43 ~186 ~64 ~43 stone
fill ~183 ~65 ~43 ~186 ~67 ~43 dirt
fill ~183 ~68 ~43 ~186 ~68 ~43 grass_block
fill ~187 ~60 ~43 ~188 ~63 ~43 stone
fill ~187 ~64 ~43 ~188 ~66 ~43 dirt
fill ~187 ~67 ~43 ~188 ~67 ~43 grass_block
fill ~189 ~60 ~43 ~191 ~64 ~43 stone
fill ~189 ~65 ~43 ~191 ~67 ~43 dirt
fill ~189 ~68 ~43 ~191 ~68 ~43 grass_block
fill ~176 ~60 ~44 ~179 ~65 ~44 stone
fill ~176 ~66 ~44 ~179 ~68 ~44 dirt
fill ~176 ~69 ~44 ~179 ~69 ~44 grass_block
fill ~180 ~60 ~44 ~181 ~66 ~44 stone
fill ~180 ~67 ~44 ~181 ~69 ~44 dirt
fill ~180 ~70 ~44 ~181 ~70 ~44 grass_block
fill ~182 ~60 ~44 ~184 ~65 ~44 stone
fill ~182 ~66 ~44 ~184 ~68 ~44 dirt
fill ~182 ~69 ~44 ~184 ~69 ~44 grass_block
fill ~185 ~60 ~44 ~188 ~64 ~44 stone
fill ~185 ~65 ~44 ~188 ~67 ~44 dirt
fill ~185 ~68 ~44 ~188 ~68 ~44 grass_block
fill ~189 ~60 ~44 ~191 ~63 ~44 stone
fill ~189 ~64 ~44 ~191 ~66 ~44 dirt
fill ~189 ~67 ~44 ~191 ~67 ~44 grass_block
fill ~176 ~60 ~45 ~177 ~65 ~45 stone
fill ~176 ~66 ~45 ~177 ~68 ~45 dirt
fill ~176 ~69 ~45 ~177 ~69 ~45 grass_block
fill ~178 ~60 ~45 ~181 ~66 ~45 stone
fill ~178 ~67 ~45 ~181 ~69 ~45 dirt
fill ~178 ~70 ~45 ~181 ~70 ~45 grass_block
fill ~182 ~60 ~45 ~186 ~65 ~45 stone
fill ~182 ~66 ~45 ~186 ~68 ~45 dirt
fill ~182 ~69 ~45 ~186 ~69 ~45 grass_block
fill ~187 ~60 ~45 ~189 ~64 ~45 stone
fill ~187 ~65 ~45 ~189 ~67 ~45 dirt
fill ~187 ~68 ~45 ~189 ~68 ~45 grass_block
fill ~190 ~60 ~45 ~191 ~63 ~45 stone
fill ~190 ~64 ~45 ~191 ~66 ~45 dirt
fill ~190 ~67 ~45 ~191 ~67 ~45 grass_block
fill ~176 ~60 ~46 ~177 ~65 ~46 stone
fill ~176 ~66 ~46 ~177 ~68 ~46 dirt
fill ~176 ~69 ~46 ~177 ~69 ~46 grass_block
fill ~178 ~60 ~46 ~182 ~66 ~46 stone
fill ~178 ~67 ~46 ~182 ~69 ~46 dirt
fill ~178 ~70 ~46 ~182 ~70 ~46 grass_block
fill ~183 ~60 ~46 ~186 ~65 ~46 stone
fill ~183 ~66 ~46 ~186 ~68 ~46 dirt
fill ~183 ~69 ~46 ~186 ~69 ~46 grass_block
fill ~187 ~60 ~46 ~189 ~64 ~46 stone
fill ~187 ~65 ~46 ~189 ~67 ~46 dirt
fill ~187 ~68 ~46 ~189 ~68 ~46 grass_block
fill ~190 ~60 ~46 ~191 ~63 ~46 stone
fill ~190 ~64 ~46 ~191 ~66 ~46 dirt
fill ~190 ~67 ~46 ~191 ~67 ~46 grass_block
fill ~176 ~60 ~47 ~182 ~66 ~47 stone
fill ~176 ~67 ~47 ~182 ~69 ~47 dirt
fill ~176 ~70 ~47 ~182 ~70 ~47 grass_block
fill ~183 ~60 ~47 ~186 ~65 ~47 stone
fill ~183 ~66 ~47 ~186 ~68 ~47 dirt
fill ~183 ~69 ~47 ~186 ~69 ~47 grass_block
fill ~187 ~60 ~47 ~188 ~64 ~47 stone
fill ~187 ~65 ~47 ~188 ~67 ~47 dirt
fill ~187 ~68 ~47 ~188 ~68 ~47 grass_block
fill ~189 ~60 ~47 ~190 ~63 ~47 stone
fill ~189 ~64 ~47 ~190 ~66 ~47 dirt
fill ~189 ~67 ~47 ~190 ~67 ~47 grass_block
fill ~191 ~60 ~47 ~191 ~64 ~47 stone
fill ~191 ~65 ~47 ~191 ~67 ~47 dirt
fill ~191 ~68 ~47 ~191 ~68 ~47 grass_block