fill ~384 ~60 ~16 ~397 ~62 ~16 stone
fill ~384 ~63 ~16 ~397 ~65 ~16 dirt
fill ~384 ~66 ~16 ~397 ~66 ~16 grass_block
fill ~398 ~60 ~16 ~398 ~63 ~16 stone
fill ~398 ~64 ~16 ~398 ~66 ~16 dirt
fill ~398 ~67 ~16 ~398 ~67 ~16 grass_block
fill ~399 ~60 ~16 ~399 ~62 ~16 stone
fill ~399 ~63 ~16 ~399 ~65 ~16 dirt
fill ~399 ~66 ~16 ~399 ~66 ~16 grass_block
fill ~384 ~60 ~17 ~399 ~62 ~17 stone
fill ~384 ~63 ~17 ~399 ~65 ~17 dirt
fill ~384 ~66 ~17 ~399 ~66 ~17 grass_block
fill ~384 ~60 ~18 ~399 ~62 ~18 stone
fill ~384 ~63 ~18 ~399 ~65 ~18 dirt
fill ~384 ~66 ~18 ~399 ~66 ~18 grass_block
fill ~384 ~60 ~19 ~393 ~62 ~19 stone
fill ~384 ~63 ~19 ~393 ~65 ~19 dirt
fill ~384 ~66 ~19 ~393 ~66 ~19 grass_block
fill ~394 ~60 ~19 ~396 ~61 ~19 stone
fill ~394 ~62 ~19 ~396 ~64 ~19 dirt
fill ~394 ~65 ~19 ~396 ~65 ~19 grass_block
fill ~397 ~60 ~19 ~399 ~62 ~19 stone
fill ~397 ~63 ~19 ~399 ~65 ~19 dirt
fill ~397 ~66 ~19 ~399 ~66 ~19 grass_block
fill ~384 ~60 ~20 ~393 ~62 ~20 stone
fill ~384 ~63 ~20 ~393 ~65 ~20 dirt
fill ~384 ~66 ~20 ~393 ~66 ~20 grass_block
fill ~394 ~60 ~20 ~394 ~61 ~20 stone
fill ~394 ~62 ~20 ~394 ~64 ~20 dirt
fill ~394 ~65 ~20 ~394 ~65 ~20 grass_block
fill ~395 ~60 ~20 ~396 ~62 ~20 stone
fill ~395 ~63 ~20 ~396 ~65 ~20 dirt
fill ~395 ~66 ~20 ~396 ~66 ~20 grass_block
fill ~397 ~60 ~20 ~399 ~61 ~20 stone
fill ~397 ~62 ~20 ~399 ~64 ~20 dirt
fill ~397 ~65 ~20 ~399 ~65 ~20 grass_block
fill ~384 ~60 ~21 ~391 ~62 ~21 stone
fill ~384 ~63 ~21 ~391 ~65 ~21 dirt
fill ~384 ~66 ~21 ~391 ~66 ~21 grass_block
fill ~392 ~60 ~21 ~392 ~61 ~21 stone
fill ~392 ~62 ~21 ~392 ~64 ~21 dirt
fill ~392 ~65 ~21 ~392 ~65 ~21 grass_block
fill ~393 ~60 ~21 ~399 ~62 ~21 stone
fill ~393 ~63 ~21 ~399 ~65 ~21 dirt
fill ~393 ~66 ~21 ~399 ~66 ~21 grass_block
fill ~384 ~60 ~22 ~395 ~62 ~22 stone
fill ~384 ~63 ~22 ~395 ~65 ~22 dirt
fill ~384 ~66 ~22 ~395 ~66 ~22 grass_block
fill ~396 ~60 ~22 ~399 ~63 ~22 stone
fill ~396 ~64 ~22 ~399 ~66 ~22 dirt
fill ~396 ~67 ~22 ~399 ~67 ~22 grass_block
fill ~384 ~60 ~23 ~385 ~62 ~23 stone
fill ~384 ~63 ~23 ~385 ~65 ~23 dirt
fill ~384 ~66 ~23 ~385 ~66 ~23 grass_block
fill ~386 ~60 ~23 ~389 ~63 ~23 stone
fill ~386 ~64 ~23 ~389 ~66 ~23 dirt
fill ~386 ~67 ~23 ~389 ~67 ~23 grass_block
fill ~390 ~60 ~23 ~392 ~62 ~23 stone
fill ~390 ~63 ~23 ~392 ~65 ~23 dirt
fill ~390 ~66 ~23 ~392 ~66 ~23 grass_block
fill ~393 ~60 ~23 ~399 ~63 ~23 stone
fill ~393 ~64 ~23 ~399 ~66 ~23 dirt
fill ~393 ~67 ~23 ~399 ~67 ~23 grass_block
fill ~384 ~60 ~24 ~385 ~62 ~24 stone
fill ~384 ~63 ~24 ~385 ~65 ~24 dirt
fill ~384 ~66 ~24 ~385 ~66 ~24 grass_block
fill ~386 ~60 ~24 ~387 ~63 ~24 stone
fill ~386 ~64 ~24 ~387 ~66 ~24 dirt
fill ~386 ~67 ~24 ~387 ~67 ~24 grass_block
fill ~388 ~60 ~24 ~388 ~64 ~24 stone
fill ~388 ~65 ~24 ~388 ~67 ~24 dirt
fill ~388 ~68 ~24 ~388 ~68 ~24 grass_block
fill ~389 ~60 ~24 ~393 ~63 ~24 stone
fill ~389 ~64 ~24 ~393 ~66 ~24 dirt
fill ~389 ~67 ~24 ~393 ~67 ~24 grass_block
fill ~394 ~60 ~24 ~396 ~64 ~24 stone
fill ~394 ~65 ~24 ~396 ~67 ~24 dirt
fill ~394 ~68 ~24 ~396 ~68 ~24 grass_block
fill ~397 ~60 ~24 ~399 ~63 ~24 stone
fill ~397 ~64 ~24 ~399 ~66 ~24 dirt
fill ~397 ~67 ~24 ~399 ~67 ~24 grass_block
fill ~384 ~60 ~25 ~386 ~62 ~25 stone
fill ~384 ~63 ~25 ~386 ~65 ~25 dirt
fill ~384 ~66 ~25 ~386 ~66 ~25 grass_block
fill ~387 ~60 ~25 ~388 ~63 ~25 stone
fill ~387 ~64 ~25 ~388 ~66 ~25 dirt
fill ~387 ~67 ~25 ~388 ~67 ~25 grass_block
fill ~389 ~60 ~25 ~396 ~64 ~25 stone
fill ~389 ~65 ~25 ~396 ~67 ~25 dirt
fill ~389 ~68 ~25 ~396 ~68 ~25 grass_block
fill ~397 ~60 ~25 ~399 ~63 ~25 stone
fill ~397 ~64 ~25 ~399 ~66 ~25 dirt
fill ~397 ~67 ~25 ~399 ~67 ~25 grass_block
fill ~384 ~60 ~26 ~384 ~62 ~26 stone
fill ~384 ~63 ~26 ~384 ~65 ~26 dirt
fill ~384 ~66 ~26 ~384 ~66 ~26 grass_block
fill ~385 ~60 ~26 ~386 ~63 ~26 stone
fill ~385 ~64 ~26 ~386 ~66 ~26 dirt
fill ~385 ~67 ~26 ~386 ~67 ~26 grass_block
fill ~387 ~60 ~26 ~387 ~62 ~26 stone
fill ~387 ~63 ~26 ~387 ~65 ~26 dirt
fill ~387 ~66 ~26 ~387 ~66 ~26 grass_block
fill ~388 ~60 ~26 ~389 ~63 ~26 stone
fill ~388 ~64 ~26 ~389 ~66 ~26 dirt
fill ~388 ~67 ~26 ~389 ~67 ~26 grass_block
fill ~390 ~60 ~26 ~390 ~64 ~26 stone
fill ~390 ~65 ~26 ~390 ~67 ~26 dirt
fill ~390 ~68 ~26 ~390 ~68 ~26 grass_block
fill ~391 ~60 ~26 ~391 ~65 ~26 stone
fill ~391 ~66 ~26 ~391 ~68 ~26 dirt
fill ~391 ~69 ~26 ~391 ~69 ~26 grass_block
fill ~392 ~60 ~26 ~396 ~64 ~26 stone
fill ~392 ~65 ~26 ~396 ~67 ~26 dirt
fill ~392 ~68 ~26 ~396 ~68 ~26 grass_block
fill ~397 ~60 ~26 ~399 ~63 ~26 stone
fill ~397 ~64 ~26 ~399 ~66 ~26 dirt
fill ~397 ~67 ~26 ~399 ~67 ~26 grass_block
fill ~384 ~60 ~27 ~384 ~63 ~27 stone
fill ~384 ~64 ~27 ~384 ~66 ~27 dirt
fill ~384 ~67 ~27 ~384 ~67 ~27 grass_block
fill ~385 ~60 ~27 ~385 ~64 ~27 stone
fill ~385 ~65 ~27 ~385 ~67 ~27 dirt
fill ~385 ~68 ~27 ~385 ~68 ~27 grass_block
fill ~386 ~60 ~27 ~389 ~63 ~27 stone
fill ~386 ~64 ~27 ~389 ~66 ~27 dirt
fill ~386 ~67 ~27 ~389 ~67 ~27 grass_block
fill ~390 ~60 ~27 ~391 ~64 ~27 stone
fill ~390 ~65 ~27 ~391 ~67 ~27 dirt
fill ~390 ~68 ~27 ~391 ~68 ~27 grass_block
fill ~392 ~60 ~27 ~392 ~65 ~27 stone
fill ~392 ~66 ~27 ~392 ~68 ~27 dirt
fill ~392 ~69 ~27 ~392 ~69 ~27 grass_block
fill ~393 ~60 ~27 ~396 ~64 ~27 stone
fill ~393 ~65 ~27 ~396 ~67 ~27 dirt
fill ~393 ~68 ~27 ~396 ~68 ~27 grass_block
fill ~397 ~60 ~27 ~399 ~63 ~27 stone
fill ~397 ~64 ~27 ~399 ~66 ~27 dirt
fill ~397 ~67 ~27 ~399 ~67 ~27 grass_block
fill ~384 ~60 ~28 ~388 ~64 ~28 stone
fill ~384 ~65 ~28 ~388 ~67 ~28 dirt
fill ~384 ~68 ~28 ~388 ~68 ~28 grass_block
fill ~389 ~60 ~28 ~389 ~63 ~28 stone
fill ~389 ~64 ~28 ~389 ~66 ~28 dirt
fill ~389 ~67 ~28 ~389 ~67 ~28 grass_block
fill ~390 ~60 ~28 ~391 ~64 ~28 stone
fill ~390 ~65 ~28 ~391 ~67 ~28 dirt
fill ~390 ~68 ~28 ~391 ~68 ~28 grass_block
fill ~392 ~60 ~28 ~393 ~65 ~28 stone
fill ~392 ~66 ~28 ~393 ~68 ~28 dirt
fill ~392 ~69 ~28 ~393 ~69 ~28 grass_block
fill ~394 ~60 ~28 ~397 ~64 ~28 stone
fill ~394 ~65 ~28 ~397 ~67 ~28 dirt
fill ~394 ~68 ~28 ~397 ~68 ~28 grass_block
fill ~398 ~60 ~28 ~399 ~63 ~28 stone
fill ~398 ~64 ~28 ~399 ~66 ~28 dirt
fill ~398 ~67 ~28 ~399 ~67 ~28 grass_block
fill ~384 ~60 ~29 ~384 ~64 ~29 stone
fill ~384 ~65 ~29 ~384 ~67 ~29 dirt
fill ~384 ~68 ~29 ~384 ~68 ~29 grass_block
fill ~385 ~60 ~29 ~388 ~65 ~29 stone
fill ~385 ~66 ~29 ~388 ~68 ~29 dirt
fill ~385 ~69 ~29 ~388 ~69 ~29 grass_block
fill ~389 ~60 ~29 ~390 ~64 ~29 stone
fill ~389 ~65 ~29 ~390 ~67 ~29 dirt
fill ~389 ~68 ~29 ~390 ~68 ~29 grass_block
fill ~391 ~60 ~29 ~393 ~65 ~29 stone
fill ~391 ~66 ~29 ~393 ~68 ~29 dirt
fill ~391 ~69 ~29 ~393 ~69 ~29 grass_block
fill ~394 ~60 ~29 ~397 ~64 ~29 stone
fill ~394 ~65 ~29 ~397 ~67 ~29 dirt
fill ~394 ~68 ~29 ~397 ~68 ~29 grass_block
fill ~398 ~60 ~29 ~399 ~63 ~29 stone
fill ~398 ~64 ~29 ~399 ~66 ~29 dirt
fill ~398 ~67 ~29 ~399 ~67 ~29 grass_block
fill ~384 ~60 ~30 ~392 ~65 ~30 stone
fill ~384 ~66 ~30 ~392 ~68 ~30 dirt
fill ~384 ~69 ~30 ~392 ~69 ~30 grass_block
fill ~393 ~60 ~30 ~396 ~64 ~30 stone
fill ~393 ~65 ~30 ~396 ~67 ~30 dirt
fill ~393 ~68 ~30 ~396 ~68 ~30 grass_block
fill ~397 ~60 ~30 ~399 ~63 ~30 stone
fill ~397 ~64 ~30 ~399 ~66 ~30 dirt
fill ~397 ~67 ~30 ~399 ~67 ~30 grass_block
fill ~384 ~60 ~31 ~384 ~65 ~31 stone
fill ~384 ~66 ~31 ~384 ~68 ~31 dirt
fill ~384 ~69 ~31 ~384 ~69 ~31 grass_block
fill ~385 ~60 ~31 ~394 ~64 ~31 stone
fill ~385 ~65 ~31 ~394 ~67 ~31 dirt
fill ~385 ~68 ~31 ~394 ~68 ~31 grass_block
fill ~395 ~60 ~31 ~398 ~63 ~31 stone
fill ~395 ~64 ~31 ~398 ~66 ~31 dirt
fill ~395 ~67 ~31 ~398 ~67 ~31 grass_block
fill ~399 ~60 ~31 ~399 ~62 ~31 stone
fill ~399 ~63 ~31 ~399 ~65 ~31 dirt
fill ~399 ~66 ~31 ~399 ~66 ~31 grass_block