fill ~304 ~60 ~128 ~315 ~65 ~128 stone
fill ~304 ~66 ~128 ~315 ~68 ~128 dirt
fill ~304 ~69 ~128 ~315 ~69 ~128 grass_block
fill ~316 ~60 ~128 ~319 ~64 ~128 stone
fill ~316 ~65 ~128 ~319 ~67 ~128 dirt
fill ~316 ~68 ~128 ~319 ~68 ~128 grass_block
fill ~304 ~60 ~129 ~305 ~64 ~129 stone
fill ~304 ~65 ~129 ~305 ~67 ~129 dirt
fill ~304 ~68 ~129 ~305 ~68 ~129 grass_block
fill ~306 ~60 ~129 ~315 ~65 ~129 stone
fill ~306 ~66 ~129 ~315 ~68 ~129 dirt
fill ~306 ~69 ~129 ~315 ~69 ~129 grass_block
fill ~316 ~60 ~129 ~319 ~64 ~129 stone
fill ~316 ~65 ~129 ~319 ~67 ~129 dirt
fill ~316 ~68 ~129 ~319 ~68 ~129 grass_block
fill ~304 ~60 ~130 ~306 ~64 ~130 stone
fill ~304 ~65 ~130 ~306 ~67 ~130 dirt
fill ~304 ~68 ~130 ~306 ~68 ~130 grass_block
fill ~307 ~60 ~130 ~316 ~65 ~130 stone
fill ~307 ~66 ~130 ~316 ~68 ~130 dirt
fill ~307 ~69 ~130 ~316 ~69 ~130 grass_block
fill ~317 ~60 ~130 ~319 ~64 ~130 stone
fill ~317 ~65 ~130 ~319 ~67 ~130 dirt
fill ~317 ~68 ~130 ~319 ~68 ~130 grass_block
fill ~304 ~60 ~131 ~308 ~64 ~131 stone
fill ~304 ~65 ~131 ~308 ~67 ~131 dirt
fill ~304 ~68 ~131 ~308 ~68 ~131 grass_block
fill ~309 ~60 ~131 ~316 ~65 ~131 stone
fill ~309 ~66 ~131 ~316 ~68 ~131 dirt
fill ~309 ~69 ~131 ~316 ~69 ~131 grass_block
fill ~317 ~60 ~131 ~319 ~64 ~131 stone
fill ~317 ~65 ~131 ~319 ~67 ~131 dirt
fill ~317 ~68 ~131 ~319 ~68 ~131 grass_block
fill ~304 ~60 ~132 ~304 ~64 ~132 stone
fill ~304 ~65 ~132 ~304 ~67 ~132 dirt
fill ~304 ~68 ~132 ~304 ~68 ~132 grass_block
fill ~305 ~60 ~132 ~305 ~63 ~132 stone
fill ~305 ~64 ~132 ~305 ~66 ~132 dirt
fill ~305 ~67 ~132 ~305 ~67 ~132 grass_block
fill ~306 ~60 ~132 ~309 ~64 ~132 stone
fill ~306 ~65 ~132 ~309 ~67 ~132 dirt
fill ~306 ~68 ~132 ~309 ~68 ~132 grass_block
fill ~310 ~60 ~132 ~316 ~65 ~132 stone
fill ~310 ~66 ~132 ~316 ~68 ~132 dirt
fill ~310 ~69 ~132 ~316 ~69 ~132 grass_block
fill ~317 ~60 ~132 ~319 ~64 ~132 stone
fill ~317 ~65 ~132 ~319 ~67 ~132 dirt
fill ~317 ~68 ~132 ~319 ~68 ~132 grass_block
fill ~304 ~60 ~133 ~304 ~64 ~133 stone
fill ~304 ~65 ~133 ~304 ~67 ~133 dirt
fill ~304 ~68 ~133 ~304 ~68 ~133 grass_block
fill ~305 ~60 ~133 ~307 ~63 ~133 stone
fill ~305 ~64 ~133 ~307 ~66 ~133 dirt
fill ~305 ~67 ~133 ~307 ~67 ~133 grass_block
fill ~308 ~60 ~133 ~311 ~64 ~133 stone
fill ~308 ~65 ~133 ~311 ~67 ~133 dirt
fill ~308 ~68 ~133 ~311 ~68 ~133 grass_block
fill ~312 ~60 ~133 ~316 ~65 ~133 stone
fill ~312 ~66 ~133 ~316 ~68 ~133 dirt
fill ~312 ~69 ~133 ~316 ~69 ~133 grass_block
fill ~317 ~60 ~133 ~319 ~64 ~133 stone
fill ~317 ~65 ~133 ~319 ~67 ~133 dirt
fill ~317 ~68 ~133 ~319 ~68 ~133 grass_block
fill ~304 ~60 ~134 ~306 ~64 ~134 stone
fill ~304 ~65 ~134 ~306 ~67 ~134 dirt
fill ~304 ~68 ~134 ~306 ~68 ~134 grass_block
fill ~307 ~60 ~134 ~309 ~63 ~134 stone
fill ~307 ~64 ~134 ~309 ~66 ~134 dirt
fill ~307 ~67 ~134 ~309 ~67 ~134 grass_block
fill ~310 ~60 ~134 ~312 ~64 ~134 stone
fill ~310 ~65 ~134 ~312 ~67 ~134 dirt
fill ~310 ~68 ~134 ~312 ~68 ~134 grass_block
fill ~313 ~60 ~134 ~315 ~65 ~134 stone
fill ~313 ~66 ~134 ~315 ~68 ~134 dirt
fill ~313 ~69 ~134 ~315 ~69 ~134 grass_block
fill ~316 ~60 ~134 ~319 ~64 ~134 stone
fill ~316 ~65 ~134 ~319 ~67 ~134 dirt
fill ~316 ~68 ~134 ~319 ~68 ~134 grass_block
fill ~304 ~60 ~135 ~306 ~64 ~135 stone
fill ~304 ~65 ~135 ~306 ~67 ~135 dirt
fill ~304 ~68 ~135 ~306 ~68 ~135 grass_block
fill ~307 ~60 ~135 ~310 ~63 ~135 stone
fill ~307 ~64 ~135 ~310 ~66 ~135 dirt
fill ~307 ~67 ~135 ~310 ~67 ~135 grass_block
fill ~311 ~60 ~135 ~315 ~64 ~135 stone
fill ~311 ~65 ~135 ~315 ~67 ~135 dirt
fill ~311 ~68 ~135 ~315 ~68 ~135 grass_block
fill ~316 ~60 ~135 ~316 ~65 ~135 stone
fill ~316 ~66 ~135 ~316 ~68 ~135 dirt
fill ~316 ~69 ~135 ~316 ~69 ~135 grass_block
fill ~317 ~60 ~135 ~319 ~64 ~135 stone
fill ~317 ~65 ~135 ~319 ~67 ~135 dirt
fill ~317 ~68 ~135 ~319 ~68 ~135 grass_block
fill ~304 ~60 ~136 ~307 ~64 ~136 stone
fill ~304 ~65 ~136 ~307 ~67 ~136 dirt
fill ~304 ~68 ~136 ~307 ~68 ~136 grass_block
fill ~308 ~60 ~136 ~311 ~63 ~136 stone
fill ~308 ~64 ~136 ~311 ~66 ~136 dirt
fill ~308 ~67 ~136 ~311 ~67 ~136 grass_block
fill ~312 ~60 ~136 ~319 ~64 ~136 stone
fill ~312 ~65 ~136 ~319 ~67 ~136 dirt
fill ~312 ~68 ~136 ~319 ~68 ~136 grass_block
fill ~304 ~60 ~137 ~307 ~64 ~137 stone
fill ~304 ~65 ~137 ~307 ~67 ~137 dirt
fill ~304 ~68 ~137 ~307 ~68 ~137 grass_block
fill ~308 ~60 ~137 ~312 ~63 ~137 stone
fill ~308 ~64 ~137 ~312 ~66 ~137 dirt
fill ~308 ~67 ~137 ~312 ~67 ~137 grass_block
fill ~313 ~60 ~137 ~319 ~64 ~137 stone
fill ~313 ~65 ~137 ~319 ~67 ~137 dirt
fill ~313 ~68 ~137 ~319 ~68 ~137 grass_block
fill ~304 ~60 ~138 ~308 ~64 ~138 stone
fill ~304 ~65 ~138 ~308 ~67 ~138 dirt
fill ~304 ~68 ~138 ~308 ~68 ~138 grass_block
fill ~309 ~60 ~138 ~313 ~63 ~138 stone
fill ~309 ~64 ~138 ~313 ~66 ~138 dirt
fill ~309 ~67 ~138 ~313 ~67 ~138 grass_block
fill ~314 ~60 ~138 ~319 ~64 ~138 stone
fill ~314 ~65 ~138 ~319 ~67 ~138 dirt
fill ~314 ~68 ~138 ~319 ~68 ~138 grass_block
fill ~304 ~60 ~139 ~309 ~64 ~139 stone
fill ~304 ~65 ~139 ~309 ~67 ~139 dirt
fill ~304 ~68 ~139 ~309 ~68 ~139 grass_block
fill ~310 ~60 ~139 ~314 ~63 ~139 stone
fill ~310 ~64 ~139 ~314 ~66 ~139 dirt
fill ~310 ~67 ~139 ~314 ~67 ~139 grass_block
fill ~315 ~60 ~139 ~319 ~64 ~139 stone
fill ~315 ~65 ~139 ~319 ~67 ~139 dirt
fill ~315 ~68 ~139 ~319 ~68 ~139 grass_block
fill ~304 ~60 ~140 ~309 ~64 ~140 stone
fill ~304 ~65 ~140 ~309 ~67 ~140 dirt
fill ~304 ~68 ~140 ~309 ~68 ~140 grass_block
fill ~310 ~60 ~140 ~315 ~63 ~140 stone
fill ~310 ~64 ~140 ~315 ~66 ~140 dirt
fill ~310 ~67 ~140 ~315 ~67 ~140 grass_block
fill ~316 ~60 ~140 ~319 ~64 ~140 stone
fill ~316 ~65 ~140 ~319 ~67 ~140 dirt
fill ~316 ~68 ~140 ~319 ~68 ~140 grass_block
fill ~304 ~60 ~141 ~309 ~64 ~141 stone
fill ~304 ~65 ~141 ~309 ~67 ~141 dirt
fill ~304 ~68 ~141 ~309 ~68 ~141 grass_block
fill ~310 ~60 ~141 ~312 ~63 ~141 stone
fill ~310 ~64 ~141 ~312 ~66 ~141 dirt
fill ~310 ~67 ~141 ~312 ~67 ~141 grass_block
fill ~313 ~60 ~141 ~313 ~62 ~141 stone
fill ~313 ~63 ~141 ~313 ~65 ~141 dirt
fill ~313 ~66 ~141 ~313 ~66 ~141 grass_block
fill ~314 ~60 ~141 ~316 ~63 ~141 stone
fill ~314 ~64 ~141 ~316 ~66 ~141 dirt
fill ~314 ~67 ~141 ~316 ~67 ~141 grass_block
fill ~317 ~60 ~141 ~319 ~64 ~141 stone
fill ~317 ~65 ~141 ~319 ~67 ~141 dirt
fill ~317 ~68 ~141 ~319 ~68 ~141 grass_block
fill ~304 ~60 ~142 ~309 ~64 ~142 stone
fill ~304 ~65 ~142 ~309 ~67 ~142 dirt
fill ~304 ~68 ~142 ~309 ~68 ~142 grass_block
fill ~310 ~60 ~142 ~312 ~63 ~142 stone
fill ~310 ~64 ~142 ~312 ~66 ~142 dirt
fill ~310 ~67 ~142 ~312 ~67 ~142 grass_block
fill ~313 ~60 ~142 ~314 ~62 ~142 stone
fill ~313 ~63 ~142 ~314 ~65 ~142 dirt
fill ~313 ~66 ~142 ~314 ~66 ~142 grass_block
fill ~315 ~60 ~142 ~319 ~63 ~142 stone
fill ~315 ~64 ~142 ~319 ~66 ~142 dirt
fill ~315 ~67 ~142 ~319 ~67 ~142 grass_block
fill ~304 ~60 ~143 ~310 ~64 ~143 stone
fill ~304 ~65 ~143 ~310 ~67 ~143 dirt
fill ~304 ~68 ~143 ~310 ~68 ~143 grass_block
fill ~311 ~60 ~143 ~313 ~63 ~143 stone
fill ~311 ~64 ~143 ~313 ~66 ~143 dirt
fill ~311 ~67 ~143 ~313 ~67 ~143 grass_block
fill ~314 ~60 ~143 ~315 ~62 ~143 stone
fill ~314 ~63 ~143 ~315 ~65 ~143 dirt
fill ~314 ~66 ~143 ~315 ~66 ~143 grass_block
fill ~316 ~60 ~143 ~319 ~63 ~143 stone
fill ~316 ~64 ~143 ~319 ~66 ~143 dirt
fill ~316 ~67 ~143 ~319 ~67 ~143 grass_block