fill ~352 ~60 ~96 ~358 ~62 ~96 stone
fill ~352 ~63 ~96 ~358 ~65 ~96 dirt
fill ~352 ~66 ~96 ~358 ~66 ~96 grass_block
fill ~359 ~60 ~96 ~361 ~63 ~96 stone
fill ~359 ~64 ~96 ~361 ~66 ~96 dirt
fill ~359 ~67 ~96 ~361 ~67 ~96 grass_block
fill ~362 ~60 ~96 ~364 ~64 ~96 stone
fill ~362 ~65 ~96 ~364 ~67 ~96 dirt
fill ~362 ~68 ~96 ~364 ~68 ~96 grass_block
fill ~365 ~60 ~96 ~367 ~65 ~96 stone
fill ~365 ~66 ~96 ~367 ~68 ~96 dirt
fill ~365 ~69 ~96 ~367 ~69 ~96 grass_block
fill ~352 ~60 ~97 ~358 ~62 ~97 stone
fill ~352 ~63 ~97 ~358 ~65 ~97 dirt
fill ~352 ~66 ~97 ~358 ~66 ~97 grass_block
fill ~359 ~60 ~97 ~361 ~63 ~97 stone
fill ~359 ~64 ~97 ~361 ~66 ~97 dirt
fill ~359 ~67 ~97 ~361 ~67 ~97 grass_block
fill ~362 ~60 ~97 ~364 ~64 ~97 stone
fill ~362 ~65 ~97 ~364 ~67 ~97 dirt
fill ~362 ~68 ~97 ~364 ~68 ~97 grass_block
fill ~365 ~60 ~97 ~367 ~65 ~97 stone
fill ~365 ~66 ~97 ~367 ~68 ~97 dirt
fill ~365 ~69 ~97 ~367 ~69 ~97 grass_block
fill ~352 ~60 ~98 ~354 ~62 ~98 stone
fill ~352 ~63 ~98 ~354 ~65 ~98 dirt
fill ~352 ~66 ~98 ~354 ~66 ~98 grass_block
fill ~355 ~60 ~98 ~355 ~61 ~98 stone
fill ~355 ~62 ~98 ~355 ~64 ~98 dirt
fill ~355 ~65 ~98 ~355 ~65 ~98 grass_block
fill ~356 ~60 ~98 ~358 ~62 ~98 stone
fill ~356 ~63 ~98 ~358 ~65 ~98 dirt
fill ~356 ~66 ~98 ~358 ~66 ~98 grass_block
fill ~359 ~60 ~98 ~361 ~63 ~98 stone
fill ~359 ~64 ~98 ~361 ~66 ~98 dirt
fill ~359 ~67 ~98 ~361 ~67 ~98 grass_block
fill ~362 ~60 ~98 ~364 ~64 ~98 stone
fill ~362 ~65 ~98 ~364 ~67 ~98 dirt
fill ~362 ~68 ~98 ~364 ~68 ~98 grass_block
fill ~365 ~60 ~98 ~367 ~65 ~98 stone
fill ~365 ~66 ~98 ~367 ~68 ~98 dirt
fill ~365 ~69 ~98 ~367 ~69 ~98 grass_block
fill ~352 ~60 ~99 ~354 ~62 ~99 stone
fill ~352 ~63 ~99 ~354 ~65 ~99 dirt
fill ~352 ~66 ~99 ~354 ~66 ~99 grass_block
fill ~355 ~60 ~99 ~356 ~61 ~99 stone
fill ~355 ~62 ~99 ~356 ~64 ~99 dirt
fill ~355 ~65 ~99 ~356 ~65 ~99 grass_block
fill ~357 ~60 ~99 ~358 ~62 ~99 stone
fill ~357 ~63 ~99 ~358 ~65 ~99 dirt
fill ~357 ~66 ~99 ~358 ~66 ~99 grass_block
fill ~359 ~60 ~99 ~361 ~63 ~99 stone
fill ~359 ~64 ~99 ~361 ~66 ~99 dirt
fill ~359 ~67 ~99 ~361 ~67 ~99 grass_block
fill ~362 ~60 ~99 ~364 ~64 ~99 stone
fill ~362 ~65 ~99 ~364 ~67 ~99 dirt
fill ~362 ~68 ~99 ~364 ~68 ~99 grass_block
fill ~365 ~60 ~99 ~367 ~65 ~99 stone
fill ~365 ~66 ~99 ~367 ~68 ~99 dirt
fill ~365 ~69 ~99 ~367 ~69 ~99 grass_block
fill ~352 ~60 ~100 ~353 ~62 ~100 stone
fill ~352 ~63 ~100 ~353 ~65 ~100 dirt
fill ~352 ~66 ~100 ~353 ~66 ~100 grass_block
fill ~354 ~60 ~100 ~355 ~61 ~100 stone
fill ~354 ~62 ~100 ~355 ~64 ~100 dirt
fill ~354 ~65 ~100 ~355 ~65 ~100 grass_block
fill ~356 ~60 ~100 ~358 ~62 ~100 stone
fill ~356 ~63 ~100 ~358 ~65 ~100 dirt
fill ~356 ~66 ~100 ~358 ~66 ~100 grass_block
fill ~359 ~60 ~100 ~361 ~63 ~100 stone
fill ~359 ~64 ~100 ~361 ~66 ~100 dirt
fill ~359 ~67 ~100 ~361 ~67 ~100 grass_block
fill ~362 ~60 ~100 ~363 ~64 ~100 stone
fill ~362 ~65 ~100 ~363 ~67 ~100 dirt
fill ~362 ~68 ~100 ~363 ~68 ~100 grass_block
fill ~364 ~60 ~100 ~367 ~65 ~100 stone
fill ~364 ~66 ~100 ~367 ~68 ~100 dirt
fill ~364 ~69 ~100 ~367 ~69 ~100 grass_block
fill ~352 ~60 ~101 ~354 ~62 ~101 stone
fill ~352 ~63 ~101 ~354 ~65 ~101 dirt
fill ~352 ~66 ~101 ~354 ~66 ~101 grass_block
fill ~355 ~60 ~101 ~356 ~61 ~101 stone
fill ~355 ~62 ~101 ~356 ~64 ~101 dirt
fill ~355 ~65 ~101 ~356 ~65 ~101 grass_block
fill ~357 ~60 ~101 ~358 ~62 ~101 stone
fill ~357 ~63 ~101 ~358 ~65 ~101 dirt
fill ~357 ~66 ~101 ~358 ~66 ~101 grass_block
fill ~359 ~60 ~101 ~361 ~63 ~101 stone
fill ~359 ~64 ~101 ~361 ~66 ~101 dirt
fill ~359 ~67 ~101 ~361 ~67 ~101 grass_block
fill ~362 ~60 ~101 ~364 ~64 ~101 stone
fill ~362 ~65 ~101 ~364 ~67 ~101 dirt
fill ~362 ~68 ~101 ~364 ~68 ~101 grass_block
fill ~365 ~60 ~101 ~367 ~65 ~101 stone
fill ~365 ~66 ~101 ~367 ~68 ~101 dirt
fill ~365 ~69 ~101 ~367 ~69 ~101 grass_block
fill ~352 ~60 ~102 ~354 ~62 ~102 stone
fill ~352 ~63 ~102 ~354 ~65 ~102 dirt
fill ~352 ~66 ~102 ~354 ~66 ~102 grass_block
fill ~355 ~60 ~102 ~356 ~61 ~102 stone
fill ~355 ~62 ~102 ~356 ~64 ~102 dirt
fill ~355 ~65 ~102 ~356 ~65 ~102 grass_block
fill ~357 ~60 ~102 ~359 ~62 ~102 stone
fill ~357 ~63 ~102 ~359 ~65 ~102 dirt
fill ~357 ~66 ~102 ~359 ~66 ~102 grass_block
fill ~360 ~60 ~102 ~362 ~63 ~102 stone
fill ~360 ~64 ~102 ~362 ~66 ~102 dirt
fill ~360 ~67 ~102 ~362 ~67 ~102 grass_block
fill ~363 ~60 ~102 ~364 ~64 ~102 stone
fill ~363 ~65 ~102 ~364 ~67 ~102 dirt
fill ~363 ~68 ~102 ~364 ~68 ~102 grass_block
fill ~365 ~60 ~102 ~367 ~65 ~102 stone
fill ~365 ~66 ~102 ~367 ~68 ~102 dirt
fill ~365 ~69 ~102 ~367 ~69 ~102 grass_block
fill ~352 ~60 ~103 ~352 ~61 ~103 stone
fill ~352 ~62 ~103 ~352 ~64 ~103 dirt
fill ~352 ~65 ~103 ~352 ~65 ~103 grass_block
fill ~353 ~60 ~103 ~353 ~62 ~103 stone
fill ~353 ~63 ~103 ~353 ~65 ~103 dirt
fill ~353 ~66 ~103 ~353 ~66 ~103 grass_block
fill ~354 ~60 ~103 ~356 ~61 ~103 stone
fill ~354 ~62 ~103 ~356 ~64 ~103 dirt
fill ~354 ~65 ~103 ~356 ~65 ~103 grass_block
fill ~357 ~60 ~103 ~359 ~62 ~103 stone
fill ~357 ~63 ~103 ~359 ~65 ~103 dirt
fill ~357 ~66 ~103 ~359 ~66 ~103 grass_block
fill ~360 ~60 ~103 ~362 ~63 ~103 stone
fill ~360 ~64 ~103 ~362 ~66 ~103 dirt
fill ~360 ~67 ~103 ~362 ~67 ~103 grass_block
fill ~363 ~60 ~103 ~364 ~64 ~103 stone
fill ~363 ~65 ~103 ~364 ~67 ~103 dirt
fill ~363 ~68 ~103 ~364 ~68 ~103 grass_block
fill ~365 ~60 ~103 ~367 ~65 ~103 stone
fill ~365 ~66 ~103 ~367 ~68 ~103 dirt
fill ~365 ~69 ~103 ~367 ~69 ~103 grass_block
fill ~352 ~60 ~104 ~356 ~61 ~104 stone
fill ~352 ~62 ~104 ~356 ~64 ~104 dirt
fill ~352 ~65 ~104 ~356 ~65 ~104 grass_block
fill ~357 ~60 ~104 ~359 ~62 ~104 stone
fill ~357 ~63 ~104 ~359 ~65 ~104 dirt
fill ~357 ~66 ~104 ~359 ~66 ~104 grass_block
fill ~360 ~60 ~104 ~362 ~63 ~104 stone
fill ~360 ~64 ~104 ~362 ~66 ~104 dirt
fill ~360 ~67 ~104 ~362 ~67 ~104 grass_block
fill ~363 ~60 ~104 ~365 ~64 ~104 stone
fill ~363 ~65 ~104 ~365 ~67 ~104 dirt
fill ~363 ~68 ~104 ~365 ~68 ~104 grass_block
fill ~366 ~60 ~104 ~367 ~65 ~104 stone
fill ~366 ~66 ~104 ~367 ~68 ~104 dirt
fill ~366 ~69 ~104 ~367 ~69 ~104 grass_block
fill ~352 ~60 ~105 ~356 ~61 ~105 stone
fill ~352 ~62 ~105 ~356 ~64 ~105 dirt
fill ~352 ~65 ~105 ~356 ~65 ~105 grass_block
fill ~357 ~60 ~105 ~359 ~62 ~105 stone
fill ~357 ~63 ~105 ~359 ~65 ~105 dirt
fill ~357 ~66 ~105 ~359 ~66 ~105 grass_block
fill ~360 ~60 ~105 ~362 ~63 ~105 stone
fill ~360 ~64 ~105 ~362 ~66 ~105 dirt
fill ~360 ~67 ~105 ~362 ~67 ~105 grass_block
fill ~363 ~60 ~105 ~366 ~64 ~105 stone
fill ~363 ~65 ~105 ~366 ~67 ~105 dirt
fill ~363 ~68 ~105 ~366 ~68 ~105 grass_block
fill ~367 ~60 ~105 ~367 ~65 ~105 stone
fill ~367 ~66 ~105 ~367 ~68 ~105 dirt
fill ~367 ~69 ~105 ~367 ~69 ~105 grass_block
fill ~352 ~60 ~106 ~357 ~61 ~106 stone
fill ~352 ~62 ~106 ~357 ~64 ~106 dirt
fill ~352 ~65 ~106 ~357 ~65 ~106 grass_block
fill ~358 ~60 ~106 ~359 ~62 ~106 stone
fill ~358 ~63 ~106 ~359 ~65 ~106 dirt
fill ~358 ~66 ~106 ~359 ~66 ~106 grass_block
fill ~360 ~60 ~106 ~362 ~63 ~106 stone
fill ~360 ~64 ~106 ~362 ~66 ~106 dirt
fill ~360 ~67 ~106 ~362 ~67 ~106 grass_block
fill ~363 ~60 ~106 ~367 ~64 ~106 stone
fill ~363 ~65 ~106 ~367 ~67 ~106 dirt
fill ~363 ~68 ~106 ~367 ~68 ~106 grass_block
fill ~352 ~60 ~107 ~357 ~61 ~107 stone
fill ~352 ~62 ~107 ~357 ~64 ~107 dirt
fill ~352 ~65 ~107 ~357 ~65 ~107 grass_block
fill ~358 ~60 ~107 ~360 ~62 ~107 stone
fill ~358 ~63 ~107 ~360 ~65 ~107 dirt
fill ~358 ~66 ~107 ~360 ~66 ~107 grass_block
fill ~361 ~60 ~107 ~363 ~63 ~107 stone
fill ~361 ~64 ~107 ~363 ~66 ~107 dirt
fill ~361 ~67 ~107 ~363 ~67 ~107 grass_block
fill ~364 ~60 ~107 ~367 ~64 ~107 stone
fill ~364 ~65 ~107 ~367 ~67 ~107 dirt
fill ~364 ~68 ~107 ~367 ~68 ~107 grass_block
fill ~352 ~60 ~108 ~358 ~61 ~108 stone
fill ~352 ~62 ~108 ~358 ~64 ~108 dirt
fill ~352 ~65 ~108 ~358 ~65 ~108 grass_block
fill ~359 ~60 ~108 ~360 ~62 ~108 stone
fill ~359 ~63 ~108 ~360 ~65 ~108 dirt
fill ~359 ~66 ~108 ~360 ~66 ~108 grass_block
fill ~361 ~60 ~108 ~364 ~63 ~108 stone
fill ~361 ~64 ~108 ~364 ~66 ~108 dirt
fill ~361 ~67 ~108 ~364 ~67 ~108 grass_block
fill ~365 ~60 ~108 ~367 ~64 ~108 stone
fill ~365 ~65 ~108 ~367 ~67 ~108 dirt
fill ~365 ~68 ~108 ~367 ~68 ~108 grass_block
fill ~352 ~60 ~109 ~352 ~60 ~109 stone
fill ~352 ~61 ~109 ~352 ~63 ~109 dirt
fill ~352 ~64 ~109 ~352 ~64 ~109 grass_block
fill ~353 ~60 ~109 ~358 ~61 ~109 stone
fill ~353 ~62 ~109 ~358 ~64 ~109 dirt
fill ~353 ~65 ~109 ~358 ~65 ~109 grass_block
fill ~359 ~60 ~109 ~361 ~62 ~109 stone
fill ~359 ~63 ~109 ~361 ~65 ~109 dirt
fill ~359 ~66 ~109 ~361 ~66 ~109 grass_block
fill ~362 ~60 ~109 ~364 ~63 ~109 stone
fill ~362 ~64 ~109 ~364 ~66 ~109 dirt
fill ~362 ~67 ~109 ~364 ~67 ~109 grass_block
fill ~365 ~60 ~109 ~367 ~64 ~109 stone
fill ~365 ~65 ~109 ~367 ~67 ~109 dirt
fill ~365 ~68 ~109 ~367 ~68 ~109 grass_block
fill ~352 ~60 ~110 ~352 ~60 ~110 stone
fill ~352 ~61 ~110 ~352 ~63 ~110 dirt
fill ~352 ~64 ~110 ~352 ~64 ~110 grass_block
fill ~353 ~60 ~110 ~358 ~61 ~110 stone
fill ~353 ~62 ~110 ~358 ~64 ~110 dirt
fill ~353 ~65 ~110 ~358 ~65 ~110 grass_block
fill ~359 ~60 ~110 ~361 ~62 ~110 stone
fill ~359 ~63 ~110 ~361 ~65 ~110 dirt
fill ~359 ~66 ~110 ~361 ~66 ~110 grass_block
fill ~362 ~60 ~110 ~365 ~63 ~110 stone
fill ~362 ~64 ~110 ~365 ~66 ~110 dirt
fill ~362 ~67 ~110 ~365 ~67 ~110 grass_block
fill ~366 ~60 ~110 ~367 ~64 ~110 stone
fill ~366 ~65 ~110 ~367 ~67 ~110 dirt
fill ~366 ~68 ~110 ~367 ~68 ~110 grass_block
fill ~352 ~60 ~111 ~353 ~60 ~111 stone
fill ~352 ~61 ~111 ~353 ~63 ~111 dirt
fill ~352 ~64 ~111 ~353 ~64 ~111 grass_block
fill ~354 ~60 ~111 ~359 ~61 ~111 stone
fill ~354 ~62 ~111 ~359 ~64 ~111 dirt
fill ~354 ~65 ~111 ~359 ~65 ~111 grass_block
fill ~360 ~60 ~111 ~361 ~62 ~111 stone
fill ~360 ~63 ~111 ~361 ~65 ~111 dirt
fill ~360 ~66 ~111 ~361 ~66 ~111 grass_block
fill ~362 ~60 ~111 ~365 ~63 ~111 stone
fill ~362 ~64 ~111 ~365 ~66 ~111 dirt
fill ~362 ~67 ~111 ~365 ~67 ~111 grass_block
fill ~366 ~60 ~111 ~367 ~64 ~111 stone
fill ~366 ~65 ~111 ~367 ~67 ~111 dirt
fill ~366 ~68 ~111 ~367 ~68 ~111 grass_block