fill ~448 ~60 ~48 ~449 ~65 ~48 stone
fill ~448 ~66 ~48 ~449 ~68 ~48 dirt
fill ~448 ~69 ~48 ~449 ~69 ~48 grass_block
fill ~450 ~60 ~48 ~453 ~64 ~48 stone
fill ~450 ~65 ~48 ~453 ~67 ~48 dirt
fill ~450 ~68 ~48 ~453 ~68 ~48 grass_block
fill ~454 ~60 ~48 ~456 ~63 ~48 stone
fill ~454 ~64 ~48 ~456 ~66 ~48 dirt
fill ~454 ~67 ~48 ~456 ~67 ~48 grass_block
fill ~457 ~60 ~48 ~459 ~62 ~48 stone
fill ~457 ~63 ~48 ~459 ~65 ~48 dirt
fill ~457 ~66 ~48 ~459 ~66 ~48 grass_block
fill ~460 ~60 ~48 ~463 ~61 ~48 stone
fill ~460 ~62 ~48 ~463 ~64 ~48 dirt
fill ~460 ~65 ~48 ~463 ~65 ~48 grass_block
fill ~448 ~60 ~49 ~452 ~64 ~49 stone
fill ~448 ~65 ~49 ~452 ~67 ~49 dirt
fill ~448 ~68 ~49 ~452 ~68 ~49 grass_block
fill ~453 ~60 ~49 ~456 ~63 ~49 stone
fill ~453 ~64 ~49 ~456 ~66 ~49 dirt
fill ~453 ~67 ~49 ~456 ~67 ~49 grass_block
fill ~457 ~60 ~49 ~460 ~62 ~49 stone
fill ~457 ~63 ~49 ~460 ~65 ~49 dirt
fill ~457 ~66 ~49 ~460 ~66 ~49 grass_block
fill ~461 ~60 ~49 ~463 ~61 ~49 stone
fill ~461 ~62 ~49 ~463 ~64 ~49 dirt
fill ~461 ~65 ~49 ~463 ~65 ~49 grass_block
fill ~448 ~60 ~50 ~448 ~64 ~50 stone
fill ~448 ~65 ~50 ~448 ~67 ~50 dirt
fill ~448 ~68 ~50 ~448 ~68 ~50 grass_block
fill ~449 ~60 ~50 ~456 ~63 ~50 stone
fill ~449 ~64 ~50 ~456 ~66 ~50 dirt
fill ~449 ~67 ~50 ~456 ~67 ~50 grass_block
fill ~457 ~60 ~50 ~460 ~62 ~50 stone
fill ~457 ~63 ~50 ~460 ~65 ~50 dirt
fill ~457 ~66 ~50 ~460 ~66 ~50 grass_block
fill ~461 ~60 ~50 ~463 ~61 ~50 stone
fill ~461 ~62 ~50 ~463 ~64 ~50 dirt
fill ~461 ~65 ~50 ~463 ~65 ~50 grass_block
fill ~448 ~60 ~51 ~452 ~63 ~51 stone
fill ~448 ~64 ~51 ~452 ~66 ~51 dirt
fill ~448 ~67 ~51 ~452 ~67 ~51 grass_block
fill ~453 ~60 ~51 ~459 ~62 ~51 stone
fill ~453 ~63 ~51 ~459 ~65 ~51 dirt
fill ~453 ~66 ~51 ~459 ~66 ~51 grass_block
fill ~460 ~60 ~51 ~462 ~61 ~51 stone
fill ~460 ~62 ~51 ~462 ~64 ~51 dirt
fill ~460 ~65 ~51 ~462 ~65 ~51 grass_block
fill ~463 ~60 ~51 ~463 ~62 ~51 stone
fill ~463 ~63 ~51 ~463 ~65 ~51 dirt
fill ~463 ~66 ~51 ~463 ~66 ~51 grass_block
fill ~448 ~60 ~52 ~448 ~64 ~52 stone
fill ~448 ~65 ~52 ~448 ~67 ~52 dirt
fill ~448 ~68 ~52 ~448 ~68 ~52 grass_block
fill ~449 ~60 ~52 ~454 ~63 ~52 stone
fill ~449 ~64 ~52 ~454 ~66 ~52 dirt
fill ~449 ~67 ~52 ~454 ~67 ~52 grass_block
fill ~455 ~60 ~52 ~459 ~62 ~52 stone
fill ~455 ~63 ~52 ~459 ~65 ~52 dirt
fill ~455 ~66 ~52 ~459 ~66 ~52 grass_block
fill ~460 ~60 ~52 ~461 ~61 ~52 stone
fill ~460 ~62 ~52 ~461 ~64 ~52 dirt
fill ~460 ~65 ~52 ~461 ~65 ~52 grass_block
fill ~462 ~60 ~52 ~463 ~62 ~52 stone
fill ~462 ~63 ~52 ~463 ~65 ~52 dirt
fill ~462 ~66 ~52 ~463 ~66 ~52 grass_block
fill ~448 ~60 ~53 ~453 ~64 ~53 stone
fill ~448 ~65 ~53 ~453 ~67 ~53 dirt
fill ~448 ~68 ~53 ~453 ~68 ~53 grass_block
fill ~454 ~60 ~53 ~455 ~63 ~53 stone
fill ~454 ~64 ~53 ~455 ~66 ~53 dirt
fill ~454 ~67 ~53 ~455 ~67 ~53 grass_block
fill ~456 ~60 ~53 ~460 ~62 ~53 stone
fill ~456 ~63 ~53 ~460 ~65 ~53 dirt
fill ~456 ~66 ~53 ~460 ~66 ~53 grass_block
fill ~461 ~60 ~53 ~461 ~61 ~53 stone
fill ~461 ~62 ~53 ~461 ~64 ~53 dirt
fill ~461 ~65 ~53 ~461 ~65 ~53 grass_block
fill ~462 ~60 ~53 ~463 ~62 ~53 stone
fill ~462 ~63 ~53 ~463 ~65 ~53 dirt
fill ~462 ~66 ~53 ~463 ~66 ~53 grass_block
fill ~448 ~60 ~54 ~450 ~65 ~54 stone
fill ~448 ~66 ~54 ~450 ~68 ~54 dirt
fill ~448 ~69 ~54 ~450 ~69 ~54 grass_block
fill ~451 ~60 ~54 ~453 ~64 ~54 stone
fill ~451 ~65 ~54 ~453 ~67 ~54 dirt
fill ~451 ~68 ~54 ~453 ~68 ~54 grass_block
fill ~454 ~60 ~54 ~457 ~63 ~54 stone
fill ~454 ~64 ~54 ~457 ~66 ~54 dirt
fill ~454 ~67 ~54 ~457 ~67 ~54 grass_block
fill ~458 ~60 ~54 ~462 ~62 ~54 stone
fill ~458 ~63 ~54 ~462 ~65 ~54 dirt
fill ~458 ~66 ~54 ~462 ~66 ~54 grass_block
fill ~463 ~60 ~54 ~463 ~63 ~54 stone
fill ~463 ~64 ~54 ~463 ~66 ~54 dirt
fill ~463 ~67 ~54 ~463 ~67 ~54 grass_block
fill ~448 ~60 ~55 ~451 ~65 ~55 stone
fill ~448 ~66 ~55 ~451 ~68 ~55 dirt
fill ~448 ~69 ~55 ~451 ~69 ~55 grass_block
fill ~452 ~60 ~55 ~453 ~64 ~55 stone
fill ~452 ~65 ~55 ~453 ~67 ~55 dirt
fill ~452 ~68 ~55 ~453 ~68 ~55 grass_block
fill ~454 ~60 ~55 ~454 ~63 ~55 stone
fill ~454 ~64 ~55 ~454 ~66 ~55 dirt
fill ~454 ~67 ~55 ~454 ~67 ~55 grass_block
fill ~455 ~60 ~55 ~455 ~64 ~55 stone
fill ~455 ~65 ~55 ~455 ~67 ~55 dirt
fill ~455 ~68 ~55 ~455 ~68 ~55 grass_block
fill ~456 ~60 ~55 ~457 ~63 ~55 stone
fill ~456 ~64 ~55 ~457 ~66 ~55 dirt
fill ~456 ~67 ~55 ~457 ~67 ~55 grass_block
fill ~458 ~60 ~55 ~461 ~62 ~55 stone
fill ~458 ~63 ~55 ~461 ~65 ~55 dirt
fill ~458 ~66 ~55 ~461 ~66 ~55 grass_block
fill ~462 ~60 ~55 ~463 ~63 ~55 stone
fill ~462 ~64 ~55 ~463 ~66 ~55 dirt
fill ~462 ~67 ~55 ~463 ~67 ~55 grass_block
fill ~448 ~60 ~56 ~451 ~65 ~56 stone
fill ~448 ~66 ~56 ~451 ~68 ~56 dirt
fill ~448 ~69 ~56 ~451 ~69 ~56 grass_block
fill ~452 ~60 ~56 ~455 ~64 ~56 stone
fill ~452 ~65 ~56 ~455 ~67 ~56 dirt
fill ~452 ~68 ~56 ~455 ~68 ~56 grass_block
fill ~456 ~60 ~56 ~457 ~63 ~56 stone
fill ~456 ~64 ~56 ~457 ~66 ~56 dirt
fill ~456 ~67 ~56 ~457 ~67 ~56 grass_block
fill ~458 ~60 ~56 ~461 ~62 ~56 stone
fill ~458 ~63 ~56 ~461 ~65 ~56 dirt
fill ~458 ~66 ~56 ~461 ~66 ~56 grass_block
fill ~462 ~60 ~56 ~463 ~63 ~56 stone
fill ~462 ~64 ~56 ~463 ~66 ~56 dirt
fill ~462 ~67 ~56 ~463 ~67 ~56 grass_block
fill ~448 ~60 ~57 ~451 ~65 ~57 stone
fill ~448 ~66 ~57 ~451 ~68 ~57 dirt
fill ~448 ~69 ~57 ~451 ~69 ~57 grass_block
fill ~452 ~60 ~57 ~454 ~64 ~57 stone
fill ~452 ~65 ~57 ~454 ~67 ~57 dirt
fill ~452 ~68 ~57 ~454 ~68 ~57 grass_block
fill ~455 ~60 ~57 ~457 ~63 ~57 stone
fill ~455 ~64 ~57 ~457 ~66 ~57 dirt
fill ~455 ~67 ~57 ~457 ~67 ~57 grass_block
fill ~458 ~60 ~57 ~460 ~62 ~57 stone
fill ~458 ~63 ~57 ~460 ~65 ~57 dirt
fill ~458 ~66 ~57 ~460 ~66 ~57 grass_block
fill ~461 ~60 ~57 ~462 ~63 ~57 stone
fill ~461 ~64 ~57 ~462 ~66 ~57 dirt
fill ~461 ~67 ~57 ~462 ~67 ~57 grass_block
fill ~463 ~60 ~57 ~463 ~64 ~57 stone
fill ~463 ~65 ~57 ~463 ~67 ~57 dirt
fill ~463 ~68 ~57 ~463 ~68 ~57 grass_block
fill ~448 ~60 ~58 ~449 ~66 ~58 stone
fill ~448 ~67 ~58 ~449 ~69 ~58 dirt
fill ~448 ~70 ~58 ~449 ~70 ~58 grass_block
fill ~450 ~60 ~58 ~451 ~65 ~58 stone
fill ~450 ~66 ~58 ~451 ~68 ~58 dirt
fill ~450 ~69 ~58 ~451 ~69 ~58 grass_block
fill ~452 ~60 ~58 ~453 ~64 ~58 stone
fill ~452 ~65 ~58 ~453 ~67 ~58 dirt
fill ~452 ~68 ~58 ~453 ~68 ~58 grass_block
fill ~454 ~60 ~58 ~456 ~63 ~58 stone
fill ~454 ~64 ~58 ~456 ~66 ~58 dirt
fill ~454 ~67 ~58 ~456 ~67 ~58 grass_block
fill ~457 ~60 ~58 ~460 ~62 ~58 stone
fill ~457 ~63 ~58 ~460 ~65 ~58 dirt
fill ~457 ~66 ~58 ~460 ~66 ~58 grass_block
fill ~461 ~60 ~58 ~461 ~63 ~58 stone
fill ~461 ~64 ~58 ~461 ~66 ~58 dirt
fill ~461 ~67 ~58 ~461 ~67 ~58 grass_block
fill ~462 ~60 ~58 ~463 ~64 ~58 stone
fill ~462 ~65 ~58 ~463 ~67 ~58 dirt
fill ~462 ~68 ~58 ~463 ~68 ~58 grass_block
fill ~448 ~60 ~59 ~450 ~66 ~59 stone
fill ~448 ~67 ~59 ~450 ~69 ~59 dirt
fill ~448 ~70 ~59 ~450 ~70 ~59 grass_block
fill ~451 ~60 ~59 ~451 ~65 ~59 stone
fill ~451 ~66 ~59 ~451 ~68 ~59 dirt
fill ~451 ~69 ~59 ~451 ~69 ~59 grass_block
fill ~452 ~60 ~59 ~453 ~64 ~59 stone
fill ~452 ~65 ~59 ~453 ~67 ~59 dirt
fill ~452 ~68 ~59 ~453 ~68 ~59 grass_block
fill ~454 ~60 ~59 ~456 ~63 ~59 stone
fill ~454 ~64 ~59 ~456 ~66 ~59 dirt
fill ~454 ~67 ~59 ~456 ~67 ~59 grass_block
fill ~457 ~60 ~59 ~457 ~62 ~59 stone
fill ~457 ~63 ~59 ~457 ~65 ~59 dirt
fill ~457 ~66 ~59 ~457 ~66 ~59 grass_block
fill ~458 ~60 ~59 ~458 ~63 ~59 stone
fill ~458 ~64 ~59 ~458 ~66 ~59 dirt
fill ~458 ~67 ~59 ~458 ~67 ~59 grass_block
fill ~459 ~60 ~59 ~459 ~62 ~59 stone
fill ~459 ~63 ~59 ~459 ~65 ~59 dirt
fill ~459 ~66 ~59 ~459 ~66 ~59 grass_block
fill ~460 ~60 ~59 ~462 ~63 ~59 stone
fill ~460 ~64 ~59 ~462 ~66 ~59 dirt
fill ~460 ~67 ~59 ~462 ~67 ~59 grass_block
fill ~463 ~60 ~59 ~463 ~64 ~59 stone
fill ~463 ~65 ~59 ~463 ~67 ~59 dirt
fill ~463 ~68 ~59 ~463 ~68 ~59 grass_block
fill ~448 ~60 ~60 ~450 ~66 ~60 stone
fill ~448 ~67 ~60 ~450 ~69 ~60 dirt
fill ~448 ~70 ~60 ~450 ~70 ~60 grass_block
fill ~451 ~60 ~60 ~452 ~65 ~60 stone
fill ~451 ~66 ~60 ~452 ~68 ~60 dirt
fill ~451 ~69 ~60 ~452 ~69 ~60 grass_block
fill ~453 ~60 ~60 ~454 ~64 ~60 stone
fill ~453 ~65 ~60 ~454 ~67 ~60 dirt
fill ~453 ~68 ~60 ~454 ~68 ~60 grass_block
fill ~455 ~60 ~60 ~462 ~63 ~60 stone
fill ~455 ~64 ~60 ~462 ~66 ~60 dirt
fill ~455 ~67 ~60 ~462 ~67 ~60 grass_block
fill ~463 ~60 ~60 ~463 ~64 ~60 stone
fill ~463 ~65 ~60 ~463 ~67 ~60 dirt
fill ~463 ~68 ~60 ~463 ~68 ~60 grass_block
fill ~448 ~60 ~61 ~448 ~65 ~61 stone
fill ~448 ~66 ~61 ~448 ~68 ~61 dirt
fill ~448 ~69 ~61 ~448 ~69 ~61 grass_block
fill ~449 ~60 ~61 ~450 ~66 ~61 stone
fill ~449 ~67 ~61 ~450 ~69 ~61 dirt
fill ~449 ~70 ~61 ~450 ~70 ~61 grass_block
fill ~451 ~60 ~61 ~452 ~65 ~61 stone
fill ~451 ~66 ~61 ~452 ~68 ~61 dirt
fill ~451 ~69 ~61 ~452 ~69 ~61 grass_block
fill ~453 ~60 ~61 ~454 ~64 ~61 stone
fill ~453 ~65 ~61 ~454 ~67 ~61 dirt
fill ~453 ~68 ~61 ~454 ~68 ~61 grass_block
fill ~455 ~60 ~61 ~457 ~63 ~61 stone
fill ~455 ~64 ~61 ~457 ~66 ~61 dirt
fill ~455 ~67 ~61 ~457 ~67 ~61 grass_block
fill ~458 ~60 ~61 ~459 ~64 ~61 stone
fill ~458 ~65 ~61 ~459 ~67 ~61 dirt
fill ~458 ~68 ~61 ~459 ~68 ~61 grass_block
fill ~460 ~60 ~61 ~462 ~63 ~61 stone
fill ~460 ~64 ~61 ~462 ~66 ~61 dirt
fill ~460 ~67 ~61 ~462 ~67 ~61 grass_block
fill ~463 ~60 ~61 ~463 ~64 ~61 stone
fill ~463 ~65 ~61 ~463 ~67 ~61 dirt
fill ~463 ~68 ~61 ~463 ~68 ~61 grass_block
fill ~448 ~60 ~62 ~452 ~65 ~62 stone
fill ~448 ~66 ~62 ~452 ~68 ~62 dirt
fill ~448 ~69 ~62 ~452 ~69 ~62 grass_block
fill ~453 ~60 ~62 ~453 ~64 ~62 stone
fill ~453 ~65 ~62 ~453 ~67 ~62 dirt
fill ~453 ~68 ~62 ~453 ~68 ~62 grass_block
fill ~454 ~60 ~62 ~456 ~63 ~62 stone
fill ~454 ~64 ~62 ~456 ~66 ~62 dirt
fill ~454 ~67 ~62 ~456 ~67 ~62 grass_block
fill ~457 ~60 ~62 ~458 ~64 ~62 stone
fill ~457 ~65 ~62 ~458 ~67 ~62 dirt
fill ~457 ~68 ~62 ~458 ~68 ~62 grass_block
fill ~459 ~60 ~62 ~459 ~65 ~62 stone
fill ~459 ~66 ~62 ~459 ~68 ~62 dirt
fill ~459 ~69 ~62 ~459 ~69 ~62 grass_block
fill ~460 ~60 ~62 ~463 ~64 ~62 stone
fill ~460 ~65 ~62 ~463 ~67 ~62 dirt
fill ~460 ~68 ~62 ~463 ~68 ~62 grass_block
fill ~448 ~60 ~63 ~454 ~65 ~63 stone
fill ~448 ~66 ~63 ~454 ~68 ~63 dirt
fill ~448 ~69 ~63 ~454 ~69 ~63 grass_block
fill ~455 ~60 ~63 ~458 ~64 ~63 stone
fill ~455 ~65 ~63 ~458 ~67 ~63 dirt
fill ~455 ~68 ~63 ~458 ~68 ~63 grass_block
fill ~459 ~60 ~63 ~461 ~65 ~63 stone
fill ~459 ~66 ~63 ~461 ~68 ~63 dirt
fill ~459 ~69 ~63 ~461 ~69 ~63 grass_block
fill ~462 ~60 ~63 ~463 ~64 ~63 stone
fill ~462 ~65 ~63 ~463 ~67 ~63 dirt
fill ~462 ~68 ~63 ~463 ~68 ~63 grass_block