fill ~368 ~60 ~64 ~381 ~63 ~64 stone
fill ~368 ~64 ~64 ~381 ~66 ~64 dirt
fill ~368 ~67 ~64 ~381 ~67 ~64 grass_block
fill ~382 ~60 ~64 ~383 ~64 ~64 stone
fill ~382 ~65 ~64 ~383 ~67 ~64 dirt
fill ~382 ~68 ~64 ~383 ~68 ~64 grass_block
fill ~368 ~60 ~65 ~369 ~63 ~65 stone
fill ~368 ~64 ~65 ~369 ~66 ~65 dirt
fill ~368 ~67 ~65 ~369 ~67 ~65 grass_block
fill ~370 ~60 ~65 ~370 ~62 ~65 stone
fill ~370 ~63 ~65 ~370 ~65 ~65 dirt
fill ~370 ~66 ~65 ~370 ~66 ~65 grass_block
fill ~371 ~60 ~65 ~374 ~63 ~65 stone
fill ~371 ~64 ~65 ~374 ~66 ~65 dirt
fill ~371 ~67 ~65 ~374 ~67 ~65 grass_block
fill ~375 ~60 ~65 ~375 ~62 ~65 stone
fill ~375 ~63 ~65 ~375 ~65 ~65 dirt
fill ~375 ~66 ~65 ~375 ~66 ~65 grass_block
fill ~376 ~60 ~65 ~377 ~63 ~65 stone
fill ~376 ~64 ~65 ~377 ~66 ~65 dirt
fill ~376 ~67 ~65 ~377 ~67 ~65 grass_block
fill ~378 ~60 ~65 ~382 ~64 ~65 stone
fill ~378 ~65 ~65 ~382 ~67 ~65 dirt
fill ~378 ~68 ~65 ~382 ~68 ~65 grass_block
fill ~383 ~60 ~65 ~383 ~65 ~65 stone
fill ~383 ~66 ~65 ~383 ~68 ~65 dirt
fill ~383 ~69 ~65 ~383 ~69 ~65 grass_block
fill ~368 ~60 ~66 ~370 ~63 ~66 stone
fill ~368 ~64 ~66 ~370 ~66 ~66 dirt
fill ~368 ~67 ~66 ~370 ~67 ~66 grass_block
fill ~371 ~60 ~66 ~372 ~62 ~66 stone
fill ~371 ~63 ~66 ~372 ~65 ~66 dirt
fill ~371 ~66 ~66 ~372 ~66 ~66 grass_block
fill ~373 ~60 ~66 ~373 ~63 ~66 stone
fill ~373 ~64 ~66 ~373 ~66 ~66 dirt
fill ~373 ~67 ~66 ~373 ~67 ~66 grass_block
fill ~374 ~60 ~66 ~375 ~62 ~66 stone
fill ~374 ~63 ~66 ~375 ~65 ~66 dirt
fill ~374 ~66 ~66 ~375 ~66 ~66 grass_block
fill ~376 ~60 ~66 ~376 ~63 ~66 stone
fill ~376 ~64 ~66 ~376 ~66 ~66 dirt
fill ~376 ~67 ~66 ~376 ~67 ~66 grass_block
fill ~377 ~60 ~66 ~379 ~64 ~66 stone
fill ~377 ~65 ~66 ~379 ~67 ~66 dirt
fill ~377 ~68 ~66 ~379 ~68 ~66 grass_block
fill ~380 ~60 ~66 ~383 ~65 ~66 stone
fill ~380 ~66 ~66 ~383 ~68 ~66 dirt
fill ~380 ~69 ~66 ~383 ~69 ~66 grass_block
fill ~368 ~60 ~67 ~370 ~63 ~67 stone
fill ~368 ~64 ~67 ~370 ~66 ~67 dirt
fill ~368 ~67 ~67 ~370 ~67 ~67 grass_block
fill ~371 ~60 ~67 ~374 ~62 ~67 stone
fill ~371 ~63 ~67 ~374 ~65 ~67 dirt
fill ~371 ~66 ~67 ~374 ~66 ~67 grass_block
fill ~375 ~60 ~67 ~376 ~63 ~67 stone
fill ~375 ~64 ~67 ~376 ~66 ~67 dirt
fill ~375 ~67 ~67 ~376 ~67 ~67 grass_block
fill ~377 ~60 ~67 ~379 ~64 ~67 stone
fill ~377 ~65 ~67 ~379 ~67 ~67 dirt
fill ~377 ~68 ~67 ~379 ~68 ~67 grass_block
fill ~380 ~60 ~67 ~383 ~65 ~67 stone
fill ~380 ~66 ~67 ~383 ~68 ~67 dirt
fill ~380 ~69 ~67 ~383 ~69 ~67 grass_block
fill ~368 ~60 ~68 ~368 ~64 ~68 stone
fill ~368 ~65 ~68 ~368 ~67 ~68 dirt
fill ~368 ~68 ~68 ~368 ~68 ~68 grass_block
fill ~369 ~60 ~68 ~371 ~63 ~68 stone
fill ~369 ~64 ~68 ~371 ~66 ~68 dirt
fill ~369 ~67 ~68 ~371 ~67 ~68 grass_block
fill ~372 ~60 ~68 ~374 ~62 ~68 stone
fill ~372 ~63 ~68 ~374 ~65 ~68 dirt
fill ~372 ~66 ~68 ~374 ~66 ~68 grass_block
fill ~375 ~60 ~68 ~376 ~63 ~68 stone
fill ~375 ~64 ~68 ~376 ~66 ~68 dirt
fill ~375 ~67 ~68 ~376 ~67 ~68 grass_block
fill ~377 ~60 ~68 ~379 ~64 ~68 stone
fill ~377 ~65 ~68 ~379 ~67 ~68 dirt
fill ~377 ~68 ~68 ~379 ~68 ~68 grass_block
fill ~380 ~60 ~68 ~383 ~65 ~68 stone
fill ~380 ~66 ~68 ~383 ~68 ~68 dirt
fill ~380 ~69 ~68 ~383 ~69 ~68 grass_block
fill ~368 ~60 ~69 ~369 ~64 ~69 stone
fill ~368 ~65 ~69 ~369 ~67 ~69 dirt
fill ~368 ~68 ~69 ~369 ~68 ~69 grass_block
fill ~370 ~60 ~69 ~372 ~63 ~69 stone
fill ~370 ~64 ~69 ~372 ~66 ~69 dirt
fill ~370 ~67 ~69 ~372 ~67 ~69 grass_block
fill ~373 ~60 ~69 ~374 ~62 ~69 stone
fill ~373 ~63 ~69 ~374 ~65 ~69 dirt
fill ~373 ~66 ~69 ~374 ~66 ~69 grass_block
fill ~375 ~60 ~69 ~377 ~63 ~69 stone
fill ~375 ~64 ~69 ~377 ~66 ~69 dirt
fill ~375 ~67 ~69 ~377 ~67 ~69 grass_block
fill ~378 ~60 ~69 ~379 ~64 ~69 stone
fill ~378 ~65 ~69 ~379 ~67 ~69 dirt
fill ~378 ~68 ~69 ~379 ~68 ~69 grass_block
fill ~380 ~60 ~69 ~383 ~65 ~69 stone
fill ~380 ~66 ~69 ~383 ~68 ~69 dirt
fill ~380 ~69 ~69 ~383 ~69 ~69 grass_block
fill ~368 ~60 ~70 ~369 ~64 ~70 stone
fill ~368 ~65 ~70 ~369 ~67 ~70 dirt
fill ~368 ~68 ~70 ~369 ~68 ~70 grass_block
fill ~370 ~60 ~70 ~372 ~63 ~70 stone
fill ~370 ~64 ~70 ~372 ~66 ~70 dirt
fill ~370 ~67 ~70 ~372 ~67 ~70 grass_block
fill ~373 ~60 ~70 ~375 ~62 ~70 stone
fill ~373 ~63 ~70 ~375 ~65 ~70 dirt
fill ~373 ~66 ~70 ~375 ~66 ~70 grass_block
fill ~376 ~60 ~70 ~378 ~63 ~70 stone
fill ~376 ~64 ~70 ~378 ~66 ~70 dirt
fill ~376 ~67 ~70 ~378 ~67 ~70 grass_block
fill ~379 ~60 ~70 ~380 ~64 ~70 stone
fill ~379 ~65 ~70 ~380 ~67 ~70 dirt
fill ~379 ~68 ~70 ~380 ~68 ~70 grass_block
fill ~381 ~60 ~70 ~383 ~65 ~70 stone
fill ~381 ~66 ~70 ~383 ~68 ~70 dirt
fill ~381 ~69 ~70 ~383 ~69 ~70 grass_block
fill ~368 ~60 ~71 ~370 ~64 ~71 stone
fill ~368 ~65 ~71 ~370 ~67 ~71 dirt
fill ~368 ~68 ~71 ~370 ~68 ~71 grass_block
fill ~371 ~60 ~71 ~373 ~63 ~71 stone
fill ~371 ~64 ~71 ~373 ~66 ~71 dirt
fill ~371 ~67 ~71 ~373 ~67 ~71 grass_block
fill ~374 ~60 ~71 ~376 ~62 ~71 stone
fill ~374 ~63 ~71 ~376 ~65 ~71 dirt
fill ~374 ~66 ~71 ~376 ~66 ~71 grass_block
fill ~377 ~60 ~71 ~379 ~63 ~71 stone
fill ~377 ~64 ~71 ~379 ~66 ~71 dirt
fill ~377 ~67 ~71 ~379 ~67 ~71 grass_block
fill ~380 ~60 ~71 ~382 ~64 ~71 stone
fill ~380 ~65 ~71 ~382 ~67 ~71 dirt
fill ~380 ~68 ~71 ~382 ~68 ~71 grass_block
fill ~383 ~60 ~71 ~383 ~65 ~71 stone
fill ~383 ~66 ~71 ~383 ~68 ~71 dirt
fill ~383 ~69 ~71 ~383 ~69 ~71 grass_block
fill ~368 ~60 ~72 ~369 ~63 ~72 stone
fill ~368 ~64 ~72 ~369 ~66 ~72 dirt
fill ~368 ~67 ~72 ~369 ~67 ~72 grass_block
fill ~370 ~60 ~72 ~370 ~64 ~72 stone
fill ~370 ~65 ~72 ~370 ~67 ~72 dirt
fill ~370 ~68 ~72 ~370 ~68 ~72 grass_block
fill ~371 ~60 ~72 ~374 ~63 ~72 stone
fill ~371 ~64 ~72 ~374 ~66 ~72 dirt
fill ~371 ~67 ~72 ~374 ~67 ~72 grass_block
fill ~375 ~60 ~72 ~377 ~62 ~72 stone
fill ~375 ~63 ~72 ~377 ~65 ~72 dirt
fill ~375 ~66 ~72 ~377 ~66 ~72 grass_block
fill ~378 ~60 ~72 ~379 ~63 ~72 stone
fill ~378 ~64 ~72 ~379 ~66 ~72 dirt
fill ~378 ~67 ~72 ~379 ~67 ~72 grass_block
fill ~380 ~60 ~72 ~383 ~64 ~72 stone
fill ~380 ~65 ~72 ~383 ~67 ~72 dirt
fill ~380 ~68 ~72 ~383 ~68 ~72 grass_block
fill ~368 ~60 ~73 ~374 ~63 ~73 stone
fill ~368 ~64 ~73 ~374 ~66 ~73 dirt
fill ~368 ~67 ~73 ~374 ~67 ~73 grass_block
fill ~375 ~60 ~73 ~378 ~62 ~73 stone
fill ~375 ~63 ~73 ~378 ~65 ~73 dirt
fill ~375 ~66 ~73 ~378 ~66 ~73 grass_block
fill ~379 ~60 ~73 ~380 ~63 ~73 stone
fill ~379 ~64 ~73 ~380 ~66 ~73 dirt
fill ~379 ~67 ~73 ~380 ~67 ~73 grass_block
fill ~381 ~60 ~73 ~383 ~64 ~73 stone
fill ~381 ~65 ~73 ~383 ~67 ~73 dirt
fill ~381 ~68 ~73 ~383 ~68 ~73 grass_block
fill ~368 ~60 ~74 ~368 ~62 ~74 stone
fill ~368 ~63 ~74 ~368 ~65 ~74 dirt
fill ~368 ~66 ~74 ~368 ~66 ~74 grass_block
fill ~369 ~60 ~74 ~375 ~63 ~74 stone
fill ~369 ~64 ~74 ~375 ~66 ~74 dirt
fill ~369 ~67 ~74 ~375 ~67 ~74 grass_block
fill ~376 ~60 ~74 ~379 ~62 ~74 stone
fill ~376 ~63 ~74 ~379 ~65 ~74 dirt
fill ~376 ~66 ~74 ~379 ~66 ~74 grass_block
fill ~380 ~60 ~74 ~381 ~63 ~74 stone
fill ~380 ~64 ~74 ~381 ~66 ~74 dirt
fill ~380 ~67 ~74 ~381 ~67 ~74 grass_block
fill ~382 ~60 ~74 ~383 ~64 ~74 stone
fill ~382 ~65 ~74 ~383 ~67 ~74 dirt
fill ~382 ~68 ~74 ~383 ~68 ~74 grass_block
fill ~368 ~60 ~75 ~368 ~63 ~75 stone
fill ~368 ~64 ~75 ~368 ~66 ~75 dirt
fill ~368 ~67 ~75 ~368 ~67 ~75 grass_block
fill ~369 ~60 ~75 ~370 ~62 ~75 stone
fill ~369 ~63 ~75 ~370 ~65 ~75 dirt
fill ~369 ~66 ~75 ~370 ~66 ~75 grass_block
fill ~371 ~60 ~75 ~375 ~63 ~75 stone
fill ~371 ~64 ~75 ~375 ~66 ~75 dirt
fill ~371 ~67 ~75 ~375 ~67 ~75 grass_block
fill ~376 ~60 ~75 ~380 ~62 ~75 stone
fill ~376 ~63 ~75 ~380 ~65 ~75 dirt
fill ~376 ~66 ~75 ~380 ~66 ~75 grass_block
fill ~381 ~60 ~75 ~382 ~63 ~75 stone
fill ~381 ~64 ~75 ~382 ~66 ~75 dirt
fill ~381 ~67 ~75 ~382 ~67 ~75 grass_block
fill ~383 ~60 ~75 ~383 ~64 ~75 stone
fill ~383 ~65 ~75 ~383 ~67 ~75 dirt
fill ~383 ~68 ~75 ~383 ~68 ~75 grass_block
fill ~368 ~60 ~76 ~369 ~63 ~76 stone
fill ~368 ~64 ~76 ~369 ~66 ~76 dirt
fill ~368 ~67 ~76 ~369 ~67 ~76 grass_block
fill ~370 ~60 ~76 ~372 ~62 ~76 stone
fill ~370 ~63 ~76 ~372 ~65 ~76 dirt
fill ~370 ~66 ~76 ~372 ~66 ~76 grass_block
fill ~373 ~60 ~76 ~376 ~63 ~76 stone
fill ~373 ~64 ~76 ~376 ~66 ~76 dirt
fill ~373 ~67 ~76 ~376 ~67 ~76 grass_block
fill ~377 ~60 ~76 ~380 ~62 ~76 stone
fill ~377 ~63 ~76 ~380 ~65 ~76 dirt
fill ~377 ~66 ~76 ~380 ~66 ~76 grass_block
fill ~381 ~60 ~76 ~383 ~63 ~76 stone
fill ~381 ~64 ~76 ~383 ~66 ~76 dirt
fill ~381 ~67 ~76 ~383 ~67 ~76 grass_block
fill ~368 ~60 ~77 ~370 ~63 ~77 stone
fill ~368 ~64 ~77 ~370 ~66 ~77 dirt
fill ~368 ~67 ~77 ~370 ~67 ~77 grass_block
fill ~371 ~60 ~77 ~380 ~62 ~77 stone
fill ~371 ~63 ~77 ~380 ~65 ~77 dirt
fill ~371 ~66 ~77 ~380 ~66 ~77 grass_block
fill ~381 ~60 ~77 ~383 ~63 ~77 stone
fill ~381 ~64 ~77 ~383 ~66 ~77 dirt
fill ~381 ~67 ~77 ~383 ~67 ~77 grass_block
fill ~368 ~60 ~78 ~368 ~64 ~78 stone
fill ~368 ~65 ~78 ~368 ~67 ~78 dirt
fill ~368 ~68 ~78 ~368 ~68 ~78 grass_block
fill ~369 ~60 ~78 ~372 ~63 ~78 stone
fill ~369 ~64 ~78 ~372 ~66 ~78 dirt
fill ~369 ~67 ~78 ~372 ~67 ~78 grass_block
fill ~373 ~60 ~78 ~381 ~62 ~78 stone
fill ~373 ~63 ~78 ~381 ~65 ~78 dirt
fill ~373 ~66 ~78 ~381 ~66 ~78 grass_block
fill ~382 ~60 ~78 ~383 ~63 ~78 stone
fill ~382 ~64 ~78 ~383 ~66 ~78 dirt
fill ~382 ~67 ~78 ~383 ~67 ~78 grass_block
fill ~368 ~60 ~79 ~371 ~64 ~79 stone
fill ~368 ~65 ~79 ~371 ~67 ~79 dirt
fill ~368 ~68 ~79 ~371 ~68 ~79 grass_block
fill ~372 ~60 ~79 ~374 ~63 ~79 stone
fill ~372 ~64 ~79 ~374 ~66 ~79 dirt
fill ~372 ~67 ~79 ~374 ~67 ~79 grass_block
fill ~375 ~60 ~79 ~383 ~62 ~79 stone
fill ~375 ~63 ~79 ~383 ~65 ~79 dirt
fill ~375 ~66 ~79 ~383 ~66 ~79 grass_block