fill ~320 ~60 ~16 ~320 ~64 ~16 stone
fill ~320 ~65 ~16 ~320 ~67 ~16 dirt
fill ~320 ~68 ~16 ~320 ~68 ~16 grass_block
fill ~321 ~60 ~16 ~329 ~65 ~16 stone
fill ~321 ~66 ~16 ~329 ~68 ~16 dirt
fill ~321 ~69 ~16 ~329 ~69 ~16 grass_block
fill ~330 ~60 ~16 ~332 ~66 ~16 stone
fill ~330 ~67 ~16 ~332 ~69 ~16 dirt
fill ~330 ~70 ~16 ~332 ~70 ~16 grass_block
fill ~333 ~60 ~16 ~335 ~65 ~16 stone
fill ~333 ~66 ~16 ~335 ~68 ~16 dirt
fill ~333 ~69 ~16 ~335 ~69 ~16 grass_block
fill ~320 ~60 ~17 ~321 ~64 ~17 stone
fill ~320 ~65 ~17 ~321 ~67 ~17 dirt
fill ~320 ~68 ~17 ~321 ~68 ~17 grass_block
fill ~322 ~60 ~17 ~330 ~65 ~17 stone
fill ~322 ~66 ~17 ~330 ~68 ~17 dirt
fill ~322 ~69 ~17 ~330 ~69 ~17 grass_block
fill ~331 ~60 ~17 ~333 ~66 ~17 stone
fill ~331 ~67 ~17 ~333 ~69 ~17 dirt
fill ~331 ~70 ~17 ~333 ~70 ~17 grass_block
fill ~334 ~60 ~17 ~335 ~65 ~17 stone
fill ~334 ~66 ~17 ~335 ~68 ~17 dirt
fill ~334 ~69 ~17 ~335 ~69 ~17 grass_block
fill ~320 ~60 ~18 ~324 ~64 ~18 stone
fill ~320 ~65 ~18 ~324 ~67 ~18 dirt
fill ~320 ~68 ~18 ~324 ~68 ~18 grass_block
fill ~325 ~60 ~18 ~326 ~65 ~18 stone
fill ~325 ~66 ~18 ~326 ~68 ~18 dirt
fill ~325 ~69 ~18 ~326 ~69 ~18 grass_block
fill ~327 ~60 ~18 ~328 ~64 ~18 stone
fill ~327 ~65 ~18 ~328 ~67 ~18 dirt
fill ~327 ~68 ~18 ~328 ~68 ~18 grass_block
fill ~329 ~60 ~18 ~331 ~65 ~18 stone
fill ~329 ~66 ~18 ~331 ~68 ~18 dirt
fill ~329 ~69 ~18 ~331 ~69 ~18 grass_block
fill ~332 ~60 ~18 ~333 ~66 ~18 stone
fill ~332 ~67 ~18 ~333 ~69 ~18 dirt
fill ~332 ~70 ~18 ~333 ~70 ~18 grass_block
fill ~334 ~60 ~18 ~335 ~65 ~18 stone
fill ~334 ~66 ~18 ~335 ~68 ~18 dirt
fill ~334 ~69 ~18 ~335 ~69 ~18 grass_block
fill ~320 ~60 ~19 ~328 ~64 ~19 stone
fill ~320 ~65 ~19 ~328 ~67 ~19 dirt
fill ~320 ~68 ~19 ~328 ~68 ~19 grass_block
fill ~329 ~60 ~19 ~332 ~65 ~19 stone
fill ~329 ~66 ~19 ~332 ~68 ~19 dirt
fill ~329 ~69 ~19 ~332 ~69 ~19 grass_block
fill ~333 ~60 ~19 ~334 ~66 ~19 stone
fill ~333 ~67 ~19 ~334 ~69 ~19 dirt
fill ~333 ~70 ~19 ~334 ~70 ~19 grass_block
fill ~335 ~60 ~19 ~335 ~65 ~19 stone
fill ~335 ~66 ~19 ~335 ~68 ~19 dirt
fill ~335 ~69 ~19 ~335 ~69 ~19 grass_block
fill ~320 ~60 ~20 ~321 ~63 ~20 stone
fill ~320 ~64 ~20 ~321 ~66 ~20 dirt
fill ~320 ~67 ~20 ~321 ~67 ~20 grass_block
fill ~322 ~60 ~20 ~329 ~64 ~20 stone
fill ~322 ~65 ~20 ~329 ~67 ~20 dirt
fill ~322 ~68 ~20 ~329 ~68 ~20 grass_block
fill ~330 ~60 ~20 ~335 ~65 ~20 stone
fill ~330 ~66 ~20 ~335 ~68 ~20 dirt
fill ~330 ~69 ~20 ~335 ~69 ~20 grass_block
fill ~320 ~60 ~21 ~325 ~63 ~21 stone
fill ~320 ~64 ~21 ~325 ~66 ~21 dirt
fill ~320 ~67 ~21 ~325 ~67 ~21 grass_block
fill ~326 ~60 ~21 ~329 ~64 ~21 stone
fill ~326 ~65 ~21 ~329 ~67 ~21 dirt
fill ~326 ~68 ~21 ~329 ~68 ~21 grass_block
fill ~330 ~60 ~21 ~335 ~65 ~21 stone
fill ~330 ~66 ~21 ~335 ~68 ~21 dirt
fill ~330 ~69 ~21 ~335 ~69 ~21 grass_block
fill ~320 ~60 ~22 ~322 ~63 ~22 stone
fill ~320 ~64 ~22 ~322 ~66 ~22 dirt
fill ~320 ~67 ~22 ~322 ~67 ~22 grass_block
fill ~323 ~60 ~22 ~329 ~64 ~22 stone
fill ~323 ~65 ~22 ~329 ~67 ~22 dirt
fill ~323 ~68 ~22 ~329 ~68 ~22 grass_block
fill ~330 ~60 ~22 ~335 ~65 ~22 stone
fill ~330 ~66 ~22 ~335 ~68 ~22 dirt
fill ~330 ~69 ~22 ~335 ~69 ~22 grass_block
fill ~320 ~60 ~23 ~321 ~63 ~23 stone
fill ~320 ~64 ~23 ~321 ~66 ~23 dirt
fill ~320 ~67 ~23 ~321 ~67 ~23 grass_block
fill ~322 ~60 ~23 ~330 ~64 ~23 stone
fill ~322 ~65 ~23 ~330 ~67 ~23 dirt
fill ~322 ~68 ~23 ~330 ~68 ~23 grass_block
fill ~331 ~60 ~23 ~335 ~65 ~23 stone
fill ~331 ~66 ~23 ~335 ~68 ~23 dirt
fill ~331 ~69 ~23 ~335 ~69 ~23 grass_block
fill ~320 ~60 ~24 ~321 ~63 ~24 stone
fill ~320 ~64 ~24 ~321 ~66 ~24 dirt
fill ~320 ~67 ~24 ~321 ~67 ~24 grass_block
fill ~322 ~60 ~24 ~331 ~64 ~24 stone
fill ~322 ~65 ~24 ~331 ~67 ~24 dirt
fill ~322 ~68 ~24 ~331 ~68 ~24 grass_block
fill ~332 ~60 ~24 ~335 ~65 ~24 stone
fill ~332 ~66 ~24 ~335 ~68 ~24 dirt
fill ~332 ~69 ~24 ~335 ~69 ~24 grass_block
fill ~320 ~60 ~25 ~321 ~63 ~25 stone
fill ~320 ~64 ~25 ~321 ~66 ~25 dirt
fill ~320 ~67 ~25 ~321 ~67 ~25 grass_block
fill ~322 ~60 ~25 ~332 ~64 ~25 stone
fill ~322 ~65 ~25 ~332 ~67 ~25 dirt
fill ~322 ~68 ~25 ~332 ~68 ~25 grass_block
fill ~333 ~60 ~25 ~335 ~65 ~25 stone
fill ~333 ~66 ~25 ~335 ~68 ~25 dirt
fill ~333 ~69 ~25 ~335 ~69 ~25 grass_block
fill ~320 ~60 ~26 ~321 ~63 ~26 stone
fill ~320 ~64 ~26 ~321 ~66 ~26 dirt
fill ~320 ~67 ~26 ~321 ~67 ~26 grass_block
fill ~322 ~60 ~26 ~333 ~64 ~26 stone
fill ~322 ~65 ~26 ~333 ~67 ~26 dirt
fill ~322 ~68 ~26 ~333 ~68 ~26 grass_block
fill ~334 ~60 ~26 ~335 ~65 ~26 stone
fill ~334 ~66 ~26 ~335 ~68 ~26 dirt
fill ~334 ~69 ~26 ~335 ~69 ~26 grass_block
fill ~320 ~60 ~27 ~321 ~63 ~27 stone
fill ~320 ~64 ~27 ~321 ~66 ~27 dirt
fill ~320 ~67 ~27 ~321 ~67 ~27 grass_block
fill ~322 ~60 ~27 ~333 ~64 ~27 stone
fill ~322 ~65 ~27 ~333 ~67 ~27 dirt
fill ~322 ~68 ~27 ~333 ~68 ~27 grass_block
fill ~334 ~60 ~27 ~335 ~65 ~27 stone
fill ~334 ~66 ~27 ~335 ~68 ~27 dirt
fill ~334 ~69 ~27 ~335 ~69 ~27 grass_block
fill ~320 ~60 ~28 ~320 ~63 ~28 stone
fill ~320 ~64 ~28 ~320 ~66 ~28 dirt
fill ~320 ~67 ~28 ~320 ~67 ~28 grass_block
fill ~321 ~60 ~28 ~334 ~64 ~28 stone
fill ~321 ~65 ~28 ~334 ~67 ~28 dirt
fill ~321 ~68 ~28 ~334 ~68 ~28 grass_block
fill ~335 ~60 ~28 ~335 ~65 ~28 stone
fill ~335 ~66 ~28 ~335 ~68 ~28 dirt
fill ~335 ~69 ~28 ~335 ~69 ~28 grass_block
fill ~320 ~60 ~29 ~320 ~63 ~29 stone
fill ~320 ~64 ~29 ~320 ~66 ~29 dirt
fill ~320 ~67 ~29 ~320 ~67 ~29 grass_block
fill ~321 ~60 ~29 ~327 ~64 ~29 stone
fill ~321 ~65 ~29 ~327 ~67 ~29 dirt
fill ~321 ~68 ~29 ~327 ~68 ~29 grass_block
fill ~328 ~60 ~29 ~330 ~63 ~29 stone
fill ~328 ~64 ~29 ~330 ~66 ~29 dirt
fill ~328 ~67 ~29 ~330 ~67 ~29 grass_block
fill ~331 ~60 ~29 ~335 ~64 ~29 stone
fill ~331 ~65 ~29 ~335 ~67 ~29 dirt
fill ~331 ~68 ~29 ~335 ~68 ~29 grass_block
fill ~320 ~60 ~30 ~320 ~63 ~30 stone
fill ~320 ~64 ~30 ~320 ~66 ~30 dirt
fill ~320 ~67 ~30 ~320 ~67 ~30 grass_block
fill ~321 ~60 ~30 ~327 ~64 ~30 stone
fill ~321 ~65 ~30 ~327 ~67 ~30 dirt
fill ~321 ~68 ~30 ~327 ~68 ~30 grass_block
fill ~328 ~60 ~30 ~331 ~63 ~30 stone
fill ~328 ~64 ~30 ~331 ~66 ~30 dirt
fill ~328 ~67 ~30 ~331 ~67 ~30 grass_block
fill ~332 ~60 ~30 ~335 ~64 ~30 stone
fill ~332 ~65 ~30 ~335 ~67 ~30 dirt
fill ~332 ~68 ~30 ~335 ~68 ~30 grass_block
fill ~320 ~60 ~31 ~321 ~63 ~31 stone
fill ~320 ~64 ~31 ~321 ~66 ~31 dirt
fill ~320 ~67 ~31 ~321 ~67 ~31 grass_block
fill ~322 ~60 ~31 ~326 ~64 ~31 stone
fill ~322 ~65 ~31 ~326 ~67 ~31 dirt
fill ~322 ~68 ~31 ~326 ~68 ~31 grass_block
fill ~327 ~60 ~31 ~334 ~63 ~31 stone
fill ~327 ~64 ~31 ~334 ~66 ~31 dirt
fill ~327 ~67 ~31 ~334 ~67 ~31 grass_block
fill ~335 ~60 ~31 ~335 ~64 ~31 stone
fill ~335 ~65 ~31 ~335 ~67 ~31 dirt
fill ~335 ~68 ~31 ~335 ~68 ~31 grass_block