fill ~160 ~60 ~16 ~166 ~63 ~16 stone
fill ~160 ~64 ~16 ~166 ~66 ~16 dirt
fill ~160 ~67 ~16 ~166 ~67 ~16 grass_block
fill ~167 ~60 ~16 ~175 ~62 ~16 stone
fill ~167 ~63 ~16 ~175 ~65 ~16 dirt
fill ~167 ~66 ~16 ~175 ~66 ~16 grass_block
fill ~160 ~60 ~17 ~166 ~63 ~17 stone
fill ~160 ~64 ~17 ~166 ~66 ~17 dirt
fill ~160 ~67 ~17 ~166 ~67 ~17 grass_block
fill ~167 ~60 ~17 ~175 ~62 ~17 stone
fill ~167 ~63 ~17 ~175 ~65 ~17 dirt
fill ~167 ~66 ~17 ~175 ~66 ~17 grass_block
fill ~160 ~60 ~18 ~167 ~63 ~18 stone
fill ~160 ~64 ~18 ~167 ~66 ~18 dirt
fill ~160 ~67 ~18 ~167 ~67 ~18 grass_block
fill ~168 ~60 ~18 ~175 ~62 ~18 stone
fill ~168 ~63 ~18 ~175 ~65 ~18 dirt
fill ~168 ~66 ~18 ~175 ~66 ~18 grass_block
fill ~160 ~60 ~19 ~166 ~63 ~19 stone
fill ~160 ~64 ~19 ~166 ~66 ~19 dirt
fill ~160 ~67 ~19 ~166 ~67 ~19 grass_block
fill ~167 ~60 ~19 ~175 ~62 ~19 stone
fill ~167 ~63 ~19 ~175 ~65 ~19 dirt
fill ~167 ~66 ~19 ~175 ~66 ~19 grass_block
fill ~160 ~60 ~20 ~165 ~63 ~20 stone
fill ~160 ~64 ~20 ~165 ~66 ~20 dirt
fill ~160 ~67 ~20 ~165 ~67 ~20 grass_block
fill ~166 ~60 ~20 ~175 ~62 ~20 stone
fill ~166 ~63 ~20 ~175 ~65 ~20 dirt
fill ~166 ~66 ~20 ~175 ~66 ~20 grass_block
fill ~160 ~60 ~21 ~165 ~63 ~21 stone
fill ~160 ~64 ~21 ~165 ~66 ~21 dirt
fill ~160 ~67 ~21 ~165 ~67 ~21 grass_block
fill ~166 ~60 ~21 ~175 ~62 ~21 stone
fill ~166 ~63 ~21 ~175 ~65 ~21 dirt
fill ~166 ~66 ~21 ~175 ~66 ~21 grass_block
fill ~160 ~60 ~22 ~164 ~63 ~22 stone
fill ~160 ~64 ~22 ~164 ~66 ~22 dirt
fill ~160 ~67 ~22 ~164 ~67 ~22 grass_block
fill ~165 ~60 ~22 ~175 ~62 ~22 stone
fill ~165 ~63 ~22 ~175 ~65 ~22 dirt
fill ~165 ~66 ~22 ~175 ~66 ~22 grass_block
fill ~160 ~60 ~23 ~164 ~63 ~23 stone
fill ~160 ~64 ~23 ~164 ~66 ~23 dirt
fill ~160 ~67 ~23 ~164 ~67 ~23 grass_block
fill ~165 ~60 ~23 ~175 ~62 ~23 stone
fill ~165 ~63 ~23 ~175 ~65 ~23 dirt
fill ~165 ~66 ~23 ~175 ~66 ~23 grass_block
fill ~160 ~60 ~24 ~164 ~63 ~24 stone
fill ~160 ~64 ~24 ~164 ~66 ~24 dirt
fill ~160 ~67 ~24 ~164 ~67 ~24 grass_block
fill ~165 ~60 ~24 ~171 ~62 ~24 stone
fill ~165 ~63 ~24 ~171 ~65 ~24 dirt
fill ~165 ~66 ~24 ~171 ~66 ~24 grass_block
fill ~172 ~60 ~24 ~175 ~63 ~24 stone
fill ~172 ~64 ~24 ~175 ~66 ~24 dirt
fill ~172 ~67 ~24 ~175 ~67 ~24 grass_block
fill ~160 ~60 ~25 ~160 ~63 ~25 stone
fill ~160 ~64 ~25 ~160 ~66 ~25 dirt
fill ~160 ~67 ~25 ~160 ~67 ~25 grass_block
fill ~161 ~60 ~25 ~161 ~62 ~25 stone
fill ~161 ~63 ~25 ~161 ~65 ~25 dirt
fill ~161 ~66 ~25 ~161 ~66 ~25 grass_block
fill ~162 ~60 ~25 ~163 ~63 ~25 stone
fill ~162 ~64 ~25 ~163 ~66 ~25 dirt
fill ~162 ~67 ~25 ~163 ~67 ~25 grass_block
fill ~164 ~60 ~25 ~169 ~62 ~25 stone
fill ~164 ~63 ~25 ~169 ~65 ~25 dirt
fill ~164 ~66 ~25 ~169 ~66 ~25 grass_block
fill ~170 ~60 ~25 ~172 ~63 ~25 stone
fill ~170 ~64 ~25 ~172 ~66 ~25 dirt
fill ~170 ~67 ~25 ~172 ~67 ~25 grass_block
fill ~173 ~60 ~25 ~175 ~64 ~25 stone
fill ~173 ~65 ~25 ~175 ~67 ~25 dirt
fill ~173 ~68 ~25 ~175 ~68 ~25 grass_block
fill ~160 ~60 ~26 ~162 ~62 ~26 stone
fill ~160 ~63 ~26 ~162 ~65 ~26 dirt
fill ~160 ~66 ~26 ~162 ~66 ~26 grass_block
fill ~163 ~60 ~26 ~164 ~63 ~26 stone
fill ~163 ~64 ~26 ~164 ~66 ~26 dirt
fill ~163 ~67 ~26 ~164 ~67 ~26 grass_block
fill ~165 ~60 ~26 ~167 ~62 ~26 stone
fill ~165 ~63 ~26 ~167 ~65 ~26 dirt
fill ~165 ~66 ~26 ~167 ~66 ~26 grass_block
fill ~168 ~60 ~26 ~171 ~63 ~26 stone
fill ~168 ~64 ~26 ~171 ~66 ~26 dirt
fill ~168 ~67 ~26 ~171 ~67 ~26 grass_block
fill ~172 ~60 ~26 ~174 ~64 ~26 stone
fill ~172 ~65 ~26 ~174 ~67 ~26 dirt
fill ~172 ~68 ~26 ~174 ~68 ~26 grass_block
fill ~175 ~60 ~26 ~175 ~65 ~26 stone
fill ~175 ~66 ~26 ~175 ~68 ~26 dirt
fill ~175 ~69 ~26 ~175 ~69 ~26 grass_block
fill ~160 ~60 ~27 ~170 ~63 ~27 stone
fill ~160 ~64 ~27 ~170 ~66 ~27 dirt
fill ~160 ~67 ~27 ~170 ~67 ~27 grass_block
fill ~171 ~60 ~27 ~173 ~64 ~27 stone
fill ~171 ~65 ~27 ~173 ~67 ~27 dirt
fill ~171 ~68 ~27 ~173 ~68 ~27 grass_block
fill ~174 ~60 ~27 ~175 ~65 ~27 stone
fill ~174 ~66 ~27 ~175 ~68 ~27 dirt
fill ~174 ~69 ~27 ~175 ~69 ~27 grass_block
fill ~160 ~60 ~28 ~170 ~63 ~28 stone
fill ~160 ~64 ~28 ~170 ~66 ~28 dirt
fill ~160 ~67 ~28 ~170 ~67 ~28 grass_block
fill ~171 ~60 ~28 ~173 ~64 ~28 stone
fill ~171 ~65 ~28 ~173 ~67 ~28 dirt
fill ~171 ~68 ~28 ~173 ~68 ~28 grass_block
fill ~174 ~60 ~28 ~175 ~65 ~28 stone
fill ~174 ~66 ~28 ~175 ~68 ~28 dirt
fill ~174 ~69 ~28 ~175 ~69 ~28 grass_block
fill ~160 ~60 ~29 ~162 ~63 ~29 stone
fill ~160 ~64 ~29 ~162 ~66 ~29 dirt
fill ~160 ~67 ~29 ~162 ~67 ~29 grass_block
fill ~163 ~60 ~29 ~166 ~64 ~29 stone
fill ~163 ~65 ~29 ~166 ~67 ~29 dirt
fill ~163 ~68 ~29 ~166 ~68 ~29 grass_block
fill ~167 ~60 ~29 ~170 ~63 ~29 stone
fill ~167 ~64 ~29 ~170 ~66 ~29 dirt
fill ~167 ~67 ~29 ~170 ~67 ~29 grass_block
fill ~171 ~60 ~29 ~173 ~64 ~29 stone
fill ~171 ~65 ~29 ~173 ~67 ~29 dirt
fill ~171 ~68 ~29 ~173 ~68 ~29 grass_block
fill ~174 ~60 ~29 ~175 ~65 ~29 stone
fill ~174 ~66 ~29 ~175 ~68 ~29 dirt
fill ~174 ~69 ~29 ~175 ~69 ~29 grass_block
fill ~160 ~60 ~30 ~161 ~63 ~30 stone
fill ~160 ~64 ~30 ~161 ~66 ~30 dirt
fill ~160 ~67 ~30 ~161 ~67 ~30 grass_block
fill ~162 ~60 ~30 ~168 ~64 ~30 stone
fill ~162 ~65 ~30 ~168 ~67 ~30 dirt
fill ~162 ~68 ~30 ~168 ~68 ~30 grass_block
fill ~169 ~60 ~30 ~169 ~63 ~30 stone
fill ~169 ~64 ~30 ~169 ~66 ~30 dirt
fill ~169 ~67 ~30 ~169 ~67 ~30 grass_block
fill ~170 ~60 ~30 ~173 ~64 ~30 stone
fill ~170 ~65 ~30 ~173 ~67 ~30 dirt
fill ~170 ~68 ~30 ~173 ~68 ~30 grass_block
fill ~174 ~60 ~30 ~175 ~65 ~30 stone
fill ~174 ~66 ~30 ~175 ~68 ~30 dirt
fill ~174 ~69 ~30 ~175 ~69 ~30 grass_block
fill ~160 ~60 ~31 ~161 ~63 ~31 stone
fill ~160 ~64 ~31 ~161 ~66 ~31 dirt
fill ~160 ~67 ~31 ~161 ~67 ~31 grass_block
fill ~162 ~60 ~31 ~163 ~64 ~31 stone
fill ~162 ~65 ~31 ~163 ~67 ~31 dirt
fill ~162 ~68 ~31 ~163 ~68 ~31 grass_block
fill ~164 ~60 ~31 ~165 ~65 ~31 stone
fill ~164 ~66 ~31 ~165 ~68 ~31 dirt
fill ~164 ~69 ~31 ~165 ~69 ~31 grass_block
fill ~166 ~60 ~31 ~172 ~64 ~31 stone
fill ~166 ~65 ~31 ~172 ~67 ~31 dirt
fill ~166 ~68 ~31 ~172 ~68 ~31 grass_block
fill ~173 ~60 ~31 ~175 ~65 ~31 stone
fill ~173 ~66 ~31 ~175 ~68 ~31 dirt
fill ~173 ~69 ~31 ~175 ~69 ~31 grass_block