fill ~224 ~60 ~0 ~224 ~64 ~0 stone
fill ~224 ~65 ~0 ~224 ~67 ~0 dirt
fill ~224 ~68 ~0 ~224 ~68 ~0 grass_block
fill ~225 ~60 ~0 ~227 ~63 ~0 stone
fill ~225 ~64 ~0 ~227 ~66 ~0 dirt
fill ~225 ~67 ~0 ~227 ~67 ~0 grass_block
fill ~228 ~60 ~0 ~229 ~64 ~0 stone
fill ~228 ~65 ~0 ~229 ~67 ~0 dirt
fill ~228 ~68 ~0 ~229 ~68 ~0 grass_block
fill ~230 ~60 ~0 ~232 ~63 ~0 stone
fill ~230 ~64 ~0 ~232 ~66 ~0 dirt
fill ~230 ~67 ~0 ~232 ~67 ~0 grass_block
fill ~233 ~60 ~0 ~234 ~64 ~0 stone
fill ~233 ~65 ~0 ~234 ~67 ~0 dirt
fill ~233 ~68 ~0 ~234 ~68 ~0 grass_block
fill ~235 ~60 ~0 ~238 ~65 ~0 stone
fill ~235 ~66 ~0 ~238 ~68 ~0 dirt
fill ~235 ~69 ~0 ~238 ~69 ~0 grass_block
fill ~239 ~60 ~0 ~239 ~66 ~0 stone
fill ~239 ~67 ~0 ~239 ~69 ~0 dirt
fill ~239 ~70 ~0 ~239 ~70 ~0 grass_block
fill ~224 ~60 ~1 ~225 ~64 ~1 stone
fill ~224 ~65 ~1 ~225 ~67 ~1 dirt
fill ~224 ~68 ~1 ~225 ~68 ~1 grass_block
fill ~226 ~60 ~1 ~232 ~63 ~1 stone
fill ~226 ~64 ~1 ~232 ~66 ~1 dirt
fill ~226 ~67 ~1 ~232 ~67 ~1 grass_block
fill ~233 ~60 ~1 ~234 ~64 ~1 stone
fill ~233 ~65 ~1 ~234 ~67 ~1 dirt
fill ~233 ~68 ~1 ~234 ~68 ~1 grass_block
fill ~235 ~60 ~1 ~238 ~65 ~1 stone
fill ~235 ~66 ~1 ~238 ~68 ~1 dirt
fill ~235 ~69 ~1 ~238 ~69 ~1 grass_block
fill ~239 ~60 ~1 ~239 ~66 ~1 stone
fill ~239 ~67 ~1 ~239 ~69 ~1 dirt
fill ~239 ~70 ~1 ~239 ~70 ~1 grass_block
fill ~224 ~60 ~2 ~225 ~64 ~2 stone
fill ~224 ~65 ~2 ~225 ~67 ~2 dirt
fill ~224 ~68 ~2 ~225 ~68 ~2 grass_block
fill ~226 ~60 ~2 ~231 ~63 ~2 stone
fill ~226 ~64 ~2 ~231 ~66 ~2 dirt
fill ~226 ~67 ~2 ~231 ~67 ~2 grass_block
fill ~232 ~60 ~2 ~235 ~64 ~2 stone
fill ~232 ~65 ~2 ~235 ~67 ~2 dirt
fill ~232 ~68 ~2 ~235 ~68 ~2 grass_block
fill ~236 ~60 ~2 ~239 ~65 ~2 stone
fill ~236 ~66 ~2 ~239 ~68 ~2 dirt
fill ~236 ~69 ~2 ~239 ~69 ~2 grass_block
fill ~224 ~60 ~3 ~226 ~64 ~3 stone
fill ~224 ~65 ~3 ~226 ~67 ~3 dirt
fill ~224 ~68 ~3 ~226 ~68 ~3 grass_block
fill ~227 ~60 ~3 ~231 ~63 ~3 stone
fill ~227 ~64 ~3 ~231 ~66 ~3 dirt
fill ~227 ~67 ~3 ~231 ~67 ~3 grass_block
fill ~232 ~60 ~3 ~235 ~64 ~3 stone
fill ~232 ~65 ~3 ~235 ~67 ~3 dirt
fill ~232 ~68 ~3 ~235 ~68 ~3 grass_block
fill ~236 ~60 ~3 ~239 ~65 ~3 stone
fill ~236 ~66 ~3 ~239 ~68 ~3 dirt
fill ~236 ~69 ~3 ~239 ~69 ~3 grass_block
fill ~224 ~60 ~4 ~226 ~64 ~4 stone
fill ~224 ~65 ~4 ~226 ~67 ~4 dirt
fill ~224 ~68 ~4 ~226 ~68 ~4 grass_block
fill ~227 ~60 ~4 ~232 ~63 ~4 stone
fill ~227 ~64 ~4 ~232 ~66 ~4 dirt
fill ~227 ~67 ~4 ~232 ~67 ~4 grass_block
fill ~233 ~60 ~4 ~236 ~64 ~4 stone
fill ~233 ~65 ~4 ~236 ~67 ~4 dirt
fill ~233 ~68 ~4 ~236 ~68 ~4 grass_block
fill ~237 ~60 ~4 ~239 ~65 ~4 stone
fill ~237 ~66 ~4 ~239 ~68 ~4 dirt
fill ~237 ~69 ~4 ~239 ~69 ~4 grass_block
fill ~224 ~60 ~5 ~224 ~65 ~5 stone
fill ~224 ~66 ~5 ~224 ~68 ~5 dirt
fill ~224 ~69 ~5 ~224 ~69 ~5 grass_block
fill ~225 ~60 ~5 ~227 ~64 ~5 stone
fill ~225 ~65 ~5 ~227 ~67 ~5 dirt
fill ~225 ~68 ~5 ~227 ~68 ~5 grass_block
fill ~228 ~60 ~5 ~233 ~63 ~5 stone
fill ~228 ~64 ~5 ~233 ~66 ~5 dirt
fill ~228 ~67 ~5 ~233 ~67 ~5 grass_block
fill ~234 ~60 ~5 ~237 ~64 ~5 stone
fill ~234 ~65 ~5 ~237 ~67 ~5 dirt
fill ~234 ~68 ~5 ~237 ~68 ~5 grass_block
fill ~238 ~60 ~5 ~239 ~65 ~5 stone
fill ~238 ~66 ~5 ~239 ~68 ~5 dirt
fill ~238 ~69 ~5 ~239 ~69 ~5 grass_block
fill ~224 ~60 ~6 ~224 ~65 ~6 stone
fill ~224 ~66 ~6 ~224 ~68 ~6 dirt
fill ~224 ~69 ~6 ~224 ~69 ~6 grass_block
fill ~225 ~60 ~6 ~228 ~64 ~6 stone
fill ~225 ~65 ~6 ~228 ~67 ~6 dirt
fill ~225 ~68 ~6 ~228 ~68 ~6 grass_block
fill ~229 ~60 ~6 ~234 ~63 ~6 stone
fill ~229 ~64 ~6 ~234 ~66 ~6 dirt
fill ~229 ~67 ~6 ~234 ~67 ~6 grass_block
fill ~235 ~60 ~6 ~238 ~64 ~6 stone
fill ~235 ~65 ~6 ~238 ~67 ~6 dirt
fill ~235 ~68 ~6 ~238 ~68 ~6 grass_block
fill ~239 ~60 ~6 ~239 ~65 ~6 stone
fill ~239 ~66 ~6 ~239 ~68 ~6 dirt
fill ~239 ~69 ~6 ~239 ~69 ~6 grass_block
fill ~224 ~60 ~7 ~224 ~65 ~7 stone
fill ~224 ~66 ~7 ~224 ~68 ~7 dirt
fill ~224 ~69 ~7 ~224 ~69 ~7 grass_block
fill ~225 ~60 ~7 ~228 ~64 ~7 stone
fill ~225 ~65 ~7 ~228 ~67 ~7 dirt
fill ~225 ~68 ~7 ~228 ~68 ~7 grass_block
fill ~229 ~60 ~7 ~235 ~63 ~7 stone
fill ~229 ~64 ~7 ~235 ~66 ~7 dirt
fill ~229 ~67 ~7 ~235 ~67 ~7 grass_block
fill ~236 ~60 ~7 ~239 ~64 ~7 stone
fill ~236 ~65 ~7 ~239 ~67 ~7 dirt
fill ~236 ~68 ~7 ~239 ~68 ~7 grass_block
fill ~224 ~60 ~8 ~225 ~65 ~8 stone
fill ~224 ~66 ~8 ~225 ~68 ~8 dirt
fill ~224 ~69 ~8 ~225 ~69 ~8 grass_block
fill ~226 ~60 ~8 ~229 ~64 ~8 stone
fill ~226 ~65 ~8 ~229 ~67 ~8 dirt
fill ~226 ~68 ~8 ~229 ~68 ~8 grass_block
fill ~230 ~60 ~8 ~237 ~63 ~8 stone
fill ~230 ~64 ~8 ~237 ~66 ~8 dirt
fill ~230 ~67 ~8 ~237 ~67 ~8 grass_block
fill ~238 ~60 ~8 ~239 ~64 ~8 stone
fill ~238 ~65 ~8 ~239 ~67 ~8 dirt
fill ~238 ~68 ~8 ~239 ~68 ~8 grass_block
fill ~224 ~60 ~9 ~225 ~65 ~9 stone
fill ~224 ~66 ~9 ~225 ~68 ~9 dirt
fill ~224 ~69 ~9 ~225 ~69 ~9 grass_block
fill ~226 ~60 ~9 ~229 ~64 ~9 stone
fill ~226 ~65 ~9 ~229 ~67 ~9 dirt
fill ~226 ~68 ~9 ~229 ~68 ~9 grass_block
fill ~230 ~60 ~9 ~232 ~63 ~9 stone
fill ~230 ~64 ~9 ~232 ~66 ~9 dirt
fill ~230 ~67 ~9 ~232 ~67 ~9 grass_block
fill ~233 ~60 ~9 ~233 ~62 ~9 stone
fill ~233 ~63 ~9 ~233 ~65 ~9 dirt
fill ~233 ~66 ~9 ~233 ~66 ~9 grass_block
fill ~234 ~60 ~9 ~237 ~63 ~9 stone
fill ~234 ~64 ~9 ~237 ~66 ~9 dirt
fill ~234 ~67 ~9 ~237 ~67 ~9 grass_block
fill ~238 ~60 ~9 ~239 ~64 ~9 stone
fill ~238 ~65 ~9 ~239 ~67 ~9 dirt
fill ~238 ~68 ~9 ~239 ~68 ~9 grass_block
fill ~224 ~60 ~10 ~230 ~64 ~10 stone
fill ~224 ~65 ~10 ~230 ~67 ~10 dirt
fill ~224 ~68 ~10 ~230 ~68 ~10 grass_block
fill ~231 ~60 ~10 ~233 ~63 ~10 stone
fill ~231 ~64 ~10 ~233 ~66 ~10 dirt
fill ~231 ~67 ~10 ~233 ~67 ~10 grass_block
fill ~234 ~60 ~10 ~234 ~62 ~10 stone
fill ~234 ~63 ~10 ~234 ~65 ~10 dirt
fill ~234 ~66 ~10 ~234 ~66 ~10 grass_block
fill ~235 ~60 ~10 ~237 ~63 ~10 stone
fill ~235 ~64 ~10 ~237 ~66 ~10 dirt
fill ~235 ~67 ~10 ~237 ~67 ~10 grass_block
fill ~238 ~60 ~10 ~239 ~64 ~10 stone
fill ~238 ~65 ~10 ~239 ~67 ~10 dirt
fill ~238 ~68 ~10 ~239 ~68 ~10 grass_block
fill ~224 ~60 ~11 ~230 ~64 ~11 stone
fill ~224 ~65 ~11 ~230 ~67 ~11 dirt
fill ~224 ~68 ~11 ~230 ~68 ~11 grass_block
fill ~231 ~60 ~11 ~234 ~63 ~11 stone
fill ~231 ~64 ~11 ~234 ~66 ~11 dirt
fill ~231 ~67 ~11 ~234 ~67 ~11 grass_block
fill ~235 ~60 ~11 ~235 ~62 ~11 stone
fill ~235 ~63 ~11 ~235 ~65 ~11 dirt
fill ~235 ~66 ~11 ~235 ~66 ~11 grass_block
fill ~236 ~60 ~11 ~237 ~63 ~11 stone
fill ~236 ~64 ~11 ~237 ~66 ~11 dirt
fill ~236 ~67 ~11 ~237 ~67 ~11 grass_block
fill ~238 ~60 ~11 ~239 ~64 ~11 stone
fill ~238 ~65 ~11 ~239 ~67 ~11 dirt
fill ~238 ~68 ~11 ~239 ~68 ~11 grass_block
fill ~224 ~60 ~12 ~225 ~64 ~12 stone
fill ~224 ~65 ~12 ~225 ~67 ~12 dirt
fill ~224 ~68 ~12 ~225 ~68 ~12 grass_block
fill ~226 ~60 ~12 ~226 ~63 ~12 stone
fill ~226 ~64 ~12 ~226 ~66 ~12 dirt
fill ~226 ~67 ~12 ~226 ~67 ~12 grass_block
fill ~227 ~60 ~12 ~231 ~64 ~12 stone
fill ~227 ~65 ~12 ~231 ~67 ~12 dirt
fill ~227 ~68 ~12 ~231 ~68 ~12 grass_block
fill ~232 ~60 ~12 ~234 ~63 ~12 stone
fill ~232 ~64 ~12 ~234 ~66 ~12 dirt
fill ~232 ~67 ~12 ~234 ~67 ~12 grass_block
fill ~235 ~60 ~12 ~235 ~62 ~12 stone
fill ~235 ~63 ~12 ~235 ~65 ~12 dirt
fill ~235 ~66 ~12 ~235 ~66 ~12 grass_block
fill ~236 ~60 ~12 ~238 ~63 ~12 stone
fill ~236 ~64 ~12 ~238 ~66 ~12 dirt
fill ~236 ~67 ~12 ~238 ~67 ~12 grass_block
fill ~239 ~60 ~12 ~239 ~64 ~12 stone
fill ~239 ~65 ~12 ~239 ~67 ~12 dirt
fill ~239 ~68 ~12 ~239 ~68 ~12 grass_block
fill ~224 ~60 ~13 ~226 ~64 ~13 stone
fill ~224 ~65 ~13 ~226 ~67 ~13 dirt
fill ~224 ~68 ~13 ~226 ~68 ~13 grass_block
fill ~227 ~60 ~13 ~239 ~63 ~13 stone
fill ~227 ~64 ~13 ~239 ~66 ~13 dirt
fill ~227 ~67 ~13 ~239 ~67 ~13 grass_block
fill ~224 ~60 ~14 ~227 ~64 ~14 stone
fill ~224 ~65 ~14 ~227 ~67 ~14 dirt
fill ~224 ~68 ~14 ~227 ~68 ~14 grass_block
fill ~228 ~60 ~14 ~235 ~63 ~14 stone
fill ~228 ~64 ~14 ~235 ~66 ~14 dirt
fill ~228 ~67 ~14 ~235 ~67 ~14 grass_block
fill ~236 ~60 ~14 ~236 ~62 ~14 stone
fill ~236 ~63 ~14 ~236 ~65 ~14 dirt
fill ~236 ~66 ~14 ~236 ~66 ~14 grass_block
fill ~237 ~60 ~14 ~239 ~63 ~14 stone
fill ~237 ~64 ~14 ~239 ~66 ~14 dirt
fill ~237 ~67 ~14 ~239 ~67 ~14 grass_block
fill ~224 ~60 ~15 ~228 ~64 ~15 stone
fill ~224 ~65 ~15 ~228 ~67 ~15 dirt
fill ~224 ~68 ~15 ~228 ~68 ~15 grass_block
fill ~229 ~60 ~15 ~235 ~63 ~15 stone
fill ~229 ~64 ~15 ~235 ~66 ~15 dirt
fill ~229 ~67 ~15 ~235 ~67 ~15 grass_block
fill ~236 ~60 ~15 ~237 ~62 ~15 stone
fill ~236 ~63 ~15 ~237 ~65 ~15 dirt
fill ~236 ~66 ~15 ~237 ~66 ~15 grass_block
fill ~238 ~60 ~15 ~239 ~63 ~15 stone
fill ~238 ~64 ~15 ~239 ~66 ~15 dirt
fill ~238 ~67 ~15 ~239 ~67 ~15 grass_block