fill ~48 ~60 ~96 ~50 ~64 ~96 stone
fill ~48 ~65 ~96 ~50 ~67 ~96 dirt
fill ~48 ~68 ~96 ~50 ~68 ~96 grass_block
fill ~51 ~60 ~96 ~53 ~65 ~96 stone
fill ~51 ~66 ~96 ~53 ~68 ~96 dirt
fill ~51 ~69 ~96 ~53 ~69 ~96 grass_block
fill ~54 ~60 ~96 ~54 ~66 ~96 stone
fill ~54 ~67 ~96 ~54 ~69 ~96 dirt
fill ~54 ~70 ~96 ~54 ~70 ~96 grass_block
fill ~55 ~60 ~96 ~56 ~65 ~96 stone
fill ~55 ~66 ~96 ~56 ~68 ~96 dirt
fill ~55 ~69 ~96 ~56 ~69 ~96 grass_block
fill ~57 ~60 ~96 ~63 ~66 ~96 stone
fill ~57 ~67 ~96 ~63 ~69 ~96 dirt
fill ~57 ~70 ~96 ~63 ~70 ~96 grass_block
fill ~48 ~60 ~97 ~51 ~64 ~97 stone
fill ~48 ~65 ~97 ~51 ~67 ~97 dirt
fill ~48 ~68 ~97 ~51 ~68 ~97 grass_block
fill ~52 ~60 ~97 ~53 ~65 ~97 stone
fill ~52 ~66 ~97 ~53 ~68 ~97 dirt
fill ~52 ~69 ~97 ~53 ~69 ~97 grass_block
fill ~54 ~60 ~97 ~54 ~66 ~97 stone
fill ~54 ~67 ~97 ~54 ~69 ~97 dirt
fill ~54 ~70 ~97 ~54 ~70 ~97 grass_block
fill ~55 ~60 ~97 ~57 ~65 ~97 stone
fill ~55 ~66 ~97 ~57 ~68 ~97 dirt
fill ~55 ~69 ~97 ~57 ~69 ~97 grass_block
fill ~58 ~60 ~97 ~63 ~66 ~97 stone
fill ~58 ~67 ~97 ~63 ~69 ~97 dirt
fill ~58 ~70 ~97 ~63 ~70 ~97 grass_block
fill ~48 ~60 ~98 ~48 ~65 ~98 stone
fill ~48 ~66 ~98 ~48 ~68 ~98 dirt
fill ~48 ~69 ~98 ~48 ~69 ~98 grass_block
fill ~49 ~60 ~98 ~52 ~64 ~98 stone
fill ~49 ~65 ~98 ~52 ~67 ~98 dirt
fill ~49 ~68 ~98 ~52 ~68 ~98 grass_block
fill ~53 ~60 ~98 ~54 ~65 ~98 stone
fill ~53 ~66 ~98 ~54 ~68 ~98 dirt
fill ~53 ~69 ~98 ~54 ~69 ~98 grass_block
fill ~55 ~60 ~98 ~55 ~66 ~98 stone
fill ~55 ~67 ~98 ~55 ~69 ~98 dirt
fill ~55 ~70 ~98 ~55 ~70 ~98 grass_block
fill ~56 ~60 ~98 ~58 ~65 ~98 stone
fill ~56 ~66 ~98 ~58 ~68 ~98 dirt
fill ~56 ~69 ~98 ~58 ~69 ~98 grass_block
fill ~59 ~60 ~98 ~61 ~66 ~98 stone
fill ~59 ~67 ~98 ~61 ~69 ~98 dirt
fill ~59 ~70 ~98 ~61 ~70 ~98 grass_block
fill ~62 ~60 ~98 ~63 ~65 ~98 stone
fill ~62 ~66 ~98 ~63 ~68 ~98 dirt
fill ~62 ~69 ~98 ~63 ~69 ~98 grass_block
fill ~48 ~60 ~99 ~49 ~65 ~99 stone
fill ~48 ~66 ~99 ~49 ~68 ~99 dirt
fill ~48 ~69 ~99 ~49 ~69 ~99 grass_block
fill ~50 ~60 ~99 ~53 ~64 ~99 stone
fill ~50 ~65 ~99 ~53 ~67 ~99 dirt
fill ~50 ~68 ~99 ~53 ~68 ~99 grass_block
fill ~54 ~60 ~99 ~63 ~65 ~99 stone
fill ~54 ~66 ~99 ~63 ~68 ~99 dirt
fill ~54 ~69 ~99 ~63 ~69 ~99 grass_block
fill ~48 ~60 ~100 ~49 ~65 ~100 stone
fill ~48 ~66 ~100 ~49 ~68 ~100 dirt
fill ~48 ~69 ~100 ~49 ~69 ~100 grass_block
fill ~50 ~60 ~100 ~53 ~64 ~100 stone
fill ~50 ~65 ~100 ~53 ~67 ~100 dirt
fill ~50 ~68 ~100 ~53 ~68 ~100 grass_block
fill ~54 ~60 ~100 ~62 ~65 ~100 stone
fill ~54 ~66 ~100 ~62 ~68 ~100 dirt
fill ~54 ~69 ~100 ~62 ~69 ~100 grass_block
fill ~63 ~60 ~100 ~63 ~66 ~100 stone
fill ~63 ~67 ~100 ~63 ~69 ~100 dirt
fill ~63 ~70 ~100 ~63 ~70 ~100 grass_block
fill ~48 ~60 ~101 ~49 ~65 ~101 stone
fill ~48 ~66 ~101 ~49 ~68 ~101 dirt
fill ~48 ~69 ~101 ~49 ~69 ~101 grass_block
fill ~50 ~60 ~101 ~54 ~64 ~101 stone
fill ~50 ~65 ~101 ~54 ~67 ~101 dirt
fill ~50 ~68 ~101 ~54 ~68 ~101 grass_block
fill ~55 ~60 ~101 ~62 ~65 ~101 stone
fill ~55 ~66 ~101 ~62 ~68 ~101 dirt
fill ~55 ~69 ~101 ~62 ~69 ~101 grass_block
fill ~63 ~60 ~101 ~63 ~66 ~101 stone
fill ~63 ~67 ~101 ~63 ~69 ~101 dirt
fill ~63 ~70 ~101 ~63 ~70 ~101 grass_block
fill ~48 ~60 ~102 ~54 ~64 ~102 stone
fill ~48 ~65 ~102 ~54 ~67 ~102 dirt
fill ~48 ~68 ~102 ~54 ~68 ~102 grass_block
fill ~55 ~60 ~102 ~58 ~65 ~102 stone
fill ~55 ~66 ~102 ~58 ~68 ~102 dirt
fill ~55 ~69 ~102 ~58 ~69 ~102 grass_block
fill ~59 ~60 ~102 ~59 ~64 ~102 stone
fill ~59 ~65 ~102 ~59 ~67 ~102 dirt
fill ~59 ~68 ~102 ~59 ~68 ~102 grass_block
fill ~60 ~60 ~102 ~62 ~65 ~102 stone
fill ~60 ~66 ~102 ~62 ~68 ~102 dirt
fill ~60 ~69 ~102 ~62 ~69 ~102 grass_block
fill ~63 ~60 ~102 ~63 ~66 ~102 stone
fill ~63 ~67 ~102 ~63 ~69 ~102 dirt
fill ~63 ~70 ~102 ~63 ~70 ~102 grass_block
fill ~48 ~60 ~103 ~55 ~64 ~103 stone
fill ~48 ~65 ~103 ~55 ~67 ~103 dirt
fill ~48 ~68 ~103 ~55 ~68 ~103 grass_block
fill ~56 ~60 ~103 ~58 ~65 ~103 stone
fill ~56 ~66 ~103 ~58 ~68 ~103 dirt
fill ~56 ~69 ~103 ~58 ~69 ~103 grass_block
fill ~59 ~60 ~103 ~60 ~64 ~103 stone
fill ~59 ~65 ~103 ~60 ~67 ~103 dirt
fill ~59 ~68 ~103 ~60 ~68 ~103 grass_block
fill ~61 ~60 ~103 ~62 ~65 ~103 stone
fill ~61 ~66 ~103 ~62 ~68 ~103 dirt
fill ~61 ~69 ~103 ~62 ~69 ~103 grass_block
fill ~63 ~60 ~103 ~63 ~66 ~103 stone
fill ~63 ~67 ~103 ~63 ~69 ~103 dirt
fill ~63 ~70 ~103 ~63 ~70 ~103 grass_block
fill ~48 ~60 ~104 ~48 ~63 ~104 stone
fill ~48 ~64 ~104 ~48 ~66 ~104 dirt
fill ~48 ~67 ~104 ~48 ~67 ~104 grass_block
fill ~49 ~60 ~104 ~52 ~64 ~104 stone
fill ~49 ~65 ~104 ~52 ~67 ~104 dirt
fill ~49 ~68 ~104 ~52 ~68 ~104 grass_block
fill ~53 ~60 ~104 ~53 ~63 ~104 stone
fill ~53 ~64 ~104 ~53 ~66 ~104 dirt
fill ~53 ~67 ~104 ~53 ~67 ~104 grass_block
fill ~54 ~60 ~104 ~55 ~64 ~104 stone
fill ~54 ~65 ~104 ~55 ~67 ~104 dirt
fill ~54 ~68 ~104 ~55 ~68 ~104 grass_block
fill ~56 ~60 ~104 ~58 ~65 ~104 stone
fill ~56 ~66 ~104 ~58 ~68 ~104 dirt
fill ~56 ~69 ~104 ~58 ~69 ~104 grass_block
fill ~59 ~60 ~104 ~61 ~64 ~104 stone
fill ~59 ~65 ~104 ~61 ~67 ~104 dirt
fill ~59 ~68 ~104 ~61 ~68 ~104 grass_block
fill ~62 ~60 ~104 ~63 ~65 ~104 stone
fill ~62 ~66 ~104 ~63 ~68 ~104 dirt
fill ~62 ~69 ~104 ~63 ~69 ~104 grass_block
fill ~48 ~60 ~105 ~49 ~63 ~105 stone
fill ~48 ~64 ~105 ~49 ~66 ~105 dirt
fill ~48 ~67 ~105 ~49 ~67 ~105 grass_block
fill ~50 ~60 ~105 ~52 ~64 ~105 stone
fill ~50 ~65 ~105 ~52 ~67 ~105 dirt
fill ~50 ~68 ~105 ~52 ~68 ~105 grass_block
fill ~53 ~60 ~105 ~53 ~63 ~105 stone
fill ~53 ~64 ~105 ~53 ~66 ~105 dirt
fill ~53 ~67 ~105 ~53 ~67 ~105 grass_block
fill ~54 ~60 ~105 ~55 ~64 ~105 stone
fill ~54 ~65 ~105 ~55 ~67 ~105 dirt
fill ~54 ~68 ~105 ~55 ~68 ~105 grass_block
fill ~56 ~60 ~105 ~58 ~65 ~105 stone
fill ~56 ~66 ~105 ~58 ~68 ~105 dirt
fill ~56 ~69 ~105 ~58 ~69 ~105 grass_block
fill ~59 ~60 ~105 ~61 ~64 ~105 stone
fill ~59 ~65 ~105 ~61 ~67 ~105 dirt
fill ~59 ~68 ~105 ~61 ~68 ~105 grass_block
fill ~62 ~60 ~105 ~63 ~65 ~105 stone
fill ~62 ~66 ~105 ~63 ~68 ~105 dirt
fill ~62 ~69 ~105 ~63 ~69 ~105 grass_block
fill ~48 ~60 ~106 ~54 ~63 ~106 stone
fill ~48 ~64 ~106 ~54 ~66 ~106 dirt
fill ~48 ~67 ~106 ~54 ~67 ~106 grass_block
fill ~55 ~60 ~106 ~57 ~64 ~106 stone
fill ~55 ~65 ~106 ~57 ~67 ~106 dirt
fill ~55 ~68 ~106 ~57 ~68 ~106 grass_block
fill ~58 ~60 ~106 ~59 ~65 ~106 stone
fill ~58 ~66 ~106 ~59 ~68 ~106 dirt
fill ~58 ~69 ~106 ~59 ~69 ~106 grass_block
fill ~60 ~60 ~106 ~61 ~64 ~106 stone
fill ~60 ~65 ~106 ~61 ~67 ~106 dirt
fill ~60 ~68 ~106 ~61 ~68 ~106 grass_block
fill ~62 ~60 ~106 ~63 ~65 ~106 stone
fill ~62 ~66 ~106 ~63 ~68 ~106 dirt
fill ~62 ~69 ~106 ~63 ~69 ~106 grass_block
fill ~48 ~60 ~107 ~56 ~63 ~107 stone
fill ~48 ~64 ~107 ~56 ~66 ~107 dirt
fill ~48 ~67 ~107 ~56 ~67 ~107 grass_block
fill ~57 ~60 ~107 ~58 ~64 ~107 stone
fill ~57 ~65 ~107 ~58 ~67 ~107 dirt
fill ~57 ~68 ~107 ~58 ~68 ~107 grass_block
fill ~59 ~60 ~107 ~59 ~65 ~107 stone
fill ~59 ~66 ~107 ~59 ~68 ~107 dirt
fill ~59 ~69 ~107 ~59 ~69 ~107 grass_block
fill ~60 ~60 ~107 ~62 ~64 ~107 stone
fill ~60 ~65 ~107 ~62 ~67 ~107 dirt
fill ~60 ~68 ~107 ~62 ~68 ~107 grass_block
fill ~63 ~60 ~107 ~63 ~65 ~107 stone
fill ~63 ~66 ~107 ~63 ~68 ~107 dirt
fill ~63 ~69 ~107 ~63 ~69 ~107 grass_block
fill ~48 ~60 ~108 ~57 ~63 ~108 stone
fill ~48 ~64 ~108 ~57 ~66 ~108 dirt
fill ~48 ~67 ~108 ~57 ~67 ~108 grass_block
fill ~58 ~60 ~108 ~63 ~64 ~108 stone
fill ~58 ~65 ~108 ~63 ~67 ~108 dirt
fill ~58 ~68 ~108 ~63 ~68 ~108 grass_block
fill ~48 ~60 ~109 ~59 ~63 ~109 stone
fill ~48 ~64 ~109 ~59 ~66 ~109 dirt
fill ~48 ~67 ~109 ~59 ~67 ~109 grass_block
fill ~60 ~60 ~109 ~63 ~64 ~109 stone
fill ~60 ~65 ~109 ~63 ~67 ~109 dirt
fill ~60 ~68 ~109 ~63 ~68 ~109 grass_block
fill ~48 ~60 ~110 ~60 ~63 ~110 stone
fill ~48 ~64 ~110 ~60 ~66 ~110 dirt
fill ~48 ~67 ~110 ~60 ~67 ~110 grass_block
fill ~61 ~60 ~110 ~63 ~64 ~110 stone
fill ~61 ~65 ~110 ~63 ~67 ~110 dirt
fill ~61 ~68 ~110 ~63 ~68 ~110 grass_block
fill ~48 ~60 ~111 ~60 ~63 ~111 stone
fill ~48 ~64 ~111 ~60 ~66 ~111 dirt
fill ~48 ~67 ~111 ~60 ~67 ~111 grass_block
fill ~61 ~60 ~111 ~63 ~64 ~111 stone
fill ~61 ~65 ~111 ~63 ~67 ~111 dirt
fill ~61 ~68 ~111 ~63 ~68 ~111 grass_block