fill ~416 ~60 ~80 ~419 ~63 ~80 stone
fill ~416 ~64 ~80 ~419 ~66 ~80 dirt
fill ~416 ~67 ~80 ~419 ~67 ~80 grass_block
fill ~420 ~60 ~80 ~421 ~64 ~80 stone
fill ~420 ~65 ~80 ~421 ~67 ~80 dirt
fill ~420 ~68 ~80 ~421 ~68 ~80 grass_block
fill ~422 ~60 ~80 ~425 ~63 ~80 stone
fill ~422 ~64 ~80 ~425 ~66 ~80 dirt
fill ~422 ~67 ~80 ~425 ~67 ~80 grass_block
fill ~426 ~60 ~80 ~426 ~62 ~80 stone
fill ~426 ~63 ~80 ~426 ~65 ~80 dirt
fill ~426 ~66 ~80 ~426 ~66 ~80 grass_block
fill ~427 ~60 ~80 ~431 ~63 ~80 stone
fill ~427 ~64 ~80 ~431 ~66 ~80 dirt
fill ~427 ~67 ~80 ~431 ~67 ~80 grass_block
fill ~416 ~60 ~81 ~420 ~63 ~81 stone
fill ~416 ~64 ~81 ~420 ~66 ~81 dirt
fill ~416 ~67 ~81 ~420 ~67 ~81 grass_block
fill ~421 ~60 ~81 ~421 ~64 ~81 stone
fill ~421 ~65 ~81 ~421 ~67 ~81 dirt
fill ~421 ~68 ~81 ~421 ~68 ~81 grass_block
fill ~422 ~60 ~81 ~425 ~63 ~81 stone
fill ~422 ~64 ~81 ~425 ~66 ~81 dirt
fill ~422 ~67 ~81 ~425 ~67 ~81 grass_block
fill ~426 ~60 ~81 ~427 ~62 ~81 stone
fill ~426 ~63 ~81 ~427 ~65 ~81 dirt
fill ~426 ~66 ~81 ~427 ~66 ~81 grass_block
fill ~428 ~60 ~81 ~431 ~63 ~81 stone
fill ~428 ~64 ~81 ~431 ~66 ~81 dirt
fill ~428 ~67 ~81 ~431 ~67 ~81 grass_block
fill ~416 ~60 ~82 ~425 ~63 ~82 stone
fill ~416 ~64 ~82 ~425 ~66 ~82 dirt
fill ~416 ~67 ~82 ~425 ~67 ~82 grass_block
fill ~426 ~60 ~82 ~429 ~62 ~82 stone
fill ~426 ~63 ~82 ~429 ~65 ~82 dirt
fill ~426 ~66 ~82 ~429 ~66 ~82 grass_block
fill ~430 ~60 ~82 ~431 ~63 ~82 stone
fill ~430 ~64 ~82 ~431 ~66 ~82 dirt
fill ~430 ~67 ~82 ~431 ~67 ~82 grass_block
fill ~416 ~60 ~83 ~417 ~62 ~83 stone
fill ~416 ~63 ~83 ~417 ~65 ~83 dirt
fill ~416 ~66 ~83 ~417 ~66 ~83 grass_block
fill ~418 ~60 ~83 ~425 ~63 ~83 stone
fill ~418 ~64 ~83 ~425 ~66 ~83 dirt
fill ~418 ~67 ~83 ~425 ~67 ~83 grass_block
fill ~426 ~60 ~83 ~429 ~62 ~83 stone
fill ~426 ~63 ~83 ~429 ~65 ~83 dirt
fill ~426 ~66 ~83 ~429 ~66 ~83 grass_block
fill ~430 ~60 ~83 ~431 ~63 ~83 stone
fill ~430 ~64 ~83 ~431 ~66 ~83 dirt
fill ~430 ~67 ~83 ~431 ~67 ~83 grass_block
fill ~416 ~60 ~84 ~418 ~62 ~84 stone
fill ~416 ~63 ~84 ~418 ~65 ~84 dirt
fill ~416 ~66 ~84 ~418 ~66 ~84 grass_block
fill ~419 ~60 ~84 ~425 ~63 ~84 stone
fill ~419 ~64 ~84 ~425 ~66 ~84 dirt
fill ~419 ~67 ~84 ~425 ~67 ~84 grass_block
fill ~426 ~60 ~84 ~429 ~62 ~84 stone
fill ~426 ~63 ~84 ~429 ~65 ~84 dirt
fill ~426 ~66 ~84 ~429 ~66 ~84 grass_block
fill ~430 ~60 ~84 ~431 ~63 ~84 stone
fill ~430 ~64 ~84 ~431 ~66 ~84 dirt
fill ~430 ~67 ~84 ~431 ~67 ~84 grass_block
fill ~416 ~60 ~85 ~419 ~62 ~85 stone
fill ~416 ~63 ~85 ~419 ~65 ~85 dirt
fill ~416 ~66 ~85 ~419 ~66 ~85 grass_block
fill ~420 ~60 ~85 ~425 ~63 ~85 stone
fill ~420 ~64 ~85 ~425 ~66 ~85 dirt
fill ~420 ~67 ~85 ~425 ~67 ~85 grass_block
fill ~426 ~60 ~85 ~429 ~62 ~85 stone
fill ~426 ~63 ~85 ~429 ~65 ~85 dirt
fill ~426 ~66 ~85 ~429 ~66 ~85 grass_block
fill ~430 ~60 ~85 ~431 ~63 ~85 stone
fill ~430 ~64 ~85 ~431 ~66 ~85 dirt
fill ~430 ~67 ~85 ~431 ~67 ~85 grass_block
fill ~416 ~60 ~86 ~416 ~61 ~86 stone
fill ~416 ~62 ~86 ~416 ~64 ~86 dirt
fill ~416 ~65 ~86 ~416 ~65 ~86 grass_block
fill ~417 ~60 ~86 ~420 ~62 ~86 stone
fill ~417 ~63 ~86 ~420 ~65 ~86 dirt
fill ~417 ~66 ~86 ~420 ~66 ~86 grass_block
fill ~421 ~60 ~86 ~424 ~63 ~86 stone
fill ~421 ~64 ~86 ~424 ~66 ~86 dirt
fill ~421 ~67 ~86 ~424 ~67 ~86 grass_block
fill ~425 ~60 ~86 ~429 ~62 ~86 stone
fill ~425 ~63 ~86 ~429 ~65 ~86 dirt
fill ~425 ~66 ~86 ~429 ~66 ~86 grass_block
fill ~430 ~60 ~86 ~431 ~63 ~86 stone
fill ~430 ~64 ~86 ~431 ~66 ~86 dirt
fill ~430 ~67 ~86 ~431 ~67 ~86 grass_block
fill ~416 ~60 ~87 ~418 ~61 ~87 stone
fill ~416 ~62 ~87 ~418 ~64 ~87 dirt
fill ~416 ~65 ~87 ~418 ~65 ~87 grass_block
fill ~419 ~60 ~87 ~430 ~62 ~87 stone
fill ~419 ~63 ~87 ~430 ~65 ~87 dirt
fill ~419 ~66 ~87 ~430 ~66 ~87 grass_block
fill ~431 ~60 ~87 ~431 ~63 ~87 stone
fill ~431 ~64 ~87 ~431 ~66 ~87 dirt
fill ~431 ~67 ~87 ~431 ~67 ~87 grass_block
fill ~416 ~60 ~88 ~418 ~61 ~88 stone
fill ~416 ~62 ~88 ~418 ~64 ~88 dirt
fill ~416 ~65 ~88 ~418 ~65 ~88 grass_block
fill ~419 ~60 ~88 ~431 ~62 ~88 stone
fill ~419 ~63 ~88 ~431 ~65 ~88 dirt
fill ~419 ~66 ~88 ~431 ~66 ~88 grass_block
fill ~416 ~60 ~89 ~420 ~61 ~89 stone
fill ~416 ~62 ~89 ~420 ~64 ~89 dirt
fill ~416 ~65 ~89 ~420 ~65 ~89 grass_block
fill ~421 ~60 ~89 ~431 ~62 ~89 stone
fill ~421 ~63 ~89 ~431 ~65 ~89 dirt
fill ~421 ~66 ~89 ~431 ~66 ~89 grass_block
fill ~416 ~60 ~90 ~422 ~61 ~90 stone
fill ~416 ~62 ~90 ~422 ~64 ~90 dirt
fill ~416 ~65 ~90 ~422 ~65 ~90 grass_block
fill ~423 ~60 ~90 ~428 ~62 ~90 stone
fill ~423 ~63 ~90 ~428 ~65 ~90 dirt
fill ~423 ~66 ~90 ~428 ~66 ~90 grass_block
fill ~429 ~60 ~90 ~429 ~61 ~90 stone
fill ~429 ~62 ~90 ~429 ~64 ~90 dirt
fill ~429 ~65 ~90 ~429 ~65 ~90 grass_block
fill ~430 ~60 ~90 ~431 ~62 ~90 stone
fill ~430 ~63 ~90 ~431 ~65 ~90 dirt
fill ~430 ~66 ~90 ~431 ~66 ~90 grass_block
fill ~416 ~60 ~91 ~425 ~61 ~91 stone
fill ~416 ~62 ~91 ~425 ~64 ~91 dirt
fill ~416 ~65 ~91 ~425 ~65 ~91 grass_block
fill ~426 ~60 ~91 ~427 ~62 ~91 stone
fill ~426 ~63 ~91 ~427 ~65 ~91 dirt
fill ~426 ~66 ~91 ~427 ~66 ~91 grass_block
fill ~428 ~60 ~91 ~429 ~61 ~91 stone
fill ~428 ~62 ~91 ~429 ~64 ~91 dirt
fill ~428 ~65 ~91 ~429 ~65 ~91 grass_block
fill ~430 ~60 ~91 ~431 ~62 ~91 stone
fill ~430 ~63 ~91 ~431 ~65 ~91 dirt
fill ~430 ~66 ~91 ~431 ~66 ~91 grass_block
fill ~416 ~60 ~92 ~416 ~62 ~92 stone
fill ~416 ~63 ~92 ~416 ~65 ~92 dirt
fill ~416 ~66 ~92 ~416 ~66 ~92 grass_block
fill ~417 ~60 ~92 ~430 ~61 ~92 stone
fill ~417 ~62 ~92 ~430 ~64 ~92 dirt
fill ~417 ~65 ~92 ~430 ~65 ~92 grass_block
fill ~431 ~60 ~92 ~431 ~62 ~92 stone
fill ~431 ~63 ~92 ~431 ~65 ~92 dirt
fill ~431 ~66 ~92 ~431 ~66 ~92 grass_block
fill ~416 ~60 ~93 ~418 ~62 ~93 stone
fill ~416 ~63 ~93 ~418 ~65 ~93 dirt
fill ~416 ~66 ~93 ~418 ~66 ~93 grass_block
fill ~419 ~60 ~93 ~430 ~61 ~93 stone
fill ~419 ~62 ~93 ~430 ~64 ~93 dirt
fill ~419 ~65 ~93 ~430 ~65 ~93 grass_block
fill ~431 ~60 ~93 ~431 ~62 ~93 stone
fill ~431 ~63 ~93 ~431 ~65 ~93 dirt
fill ~431 ~66 ~93 ~431 ~66 ~93 grass_block
fill ~416 ~60 ~94 ~417 ~63 ~94 stone
fill ~416 ~64 ~94 ~417 ~66 ~94 dirt
fill ~416 ~67 ~94 ~417 ~67 ~94 grass_block
fill ~418 ~60 ~94 ~422 ~62 ~94 stone
fill ~418 ~63 ~94 ~422 ~65 ~94 dirt
fill ~418 ~66 ~94 ~422 ~66 ~94 grass_block
fill ~423 ~60 ~94 ~430 ~61 ~94 stone
fill ~423 ~62 ~94 ~430 ~64 ~94 dirt
fill ~423 ~65 ~94 ~430 ~65 ~94 grass_block
fill ~431 ~60 ~94 ~431 ~62 ~94 stone
fill ~431 ~63 ~94 ~431 ~65 ~94 dirt
fill ~431 ~66 ~94 ~431 ~66 ~94 grass_block
fill ~416 ~60 ~95 ~418 ~63 ~95 stone
fill ~416 ~64 ~95 ~418 ~66 ~95 dirt
fill ~416 ~67 ~95 ~418 ~67 ~95 grass_block
fill ~419 ~60 ~95 ~422 ~62 ~95 stone
fill ~419 ~63 ~95 ~422 ~65 ~95 dirt
fill ~419 ~66 ~95 ~422 ~66 ~95 grass_block
fill ~423 ~60 ~95 ~431 ~61 ~95 stone
fill ~423 ~62 ~95 ~431 ~64 ~95 dirt
fill ~423 ~65 ~95 ~431 ~65 ~95 grass_block