fill ~16 ~60 ~32 ~16 ~67 ~32 stone
fill ~16 ~68 ~32 ~16 ~70 ~32 dirt
fill ~16 ~71 ~32 ~16 ~71 ~32 grass_block
fill ~17 ~60 ~32 ~24 ~66 ~32 stone
fill ~17 ~67 ~32 ~24 ~69 ~32 dirt
fill ~17 ~70 ~32 ~24 ~70 ~32 grass_block
fill ~25 ~60 ~32 ~31 ~65 ~32 stone
fill ~25 ~66 ~32 ~31 ~68 ~32 dirt
fill ~25 ~69 ~32 ~31 ~69 ~32 grass_block
fill ~16 ~60 ~33 ~17 ~67 ~33 stone
fill ~16 ~68 ~33 ~17 ~70 ~33 dirt
fill ~16 ~71 ~33 ~17 ~71 ~33 grass_block
fill ~18 ~60 ~33 ~20 ~66 ~33 stone
fill ~18 ~67 ~33 ~20 ~69 ~33 dirt
fill ~18 ~70 ~33 ~20 ~70 ~33 grass_block
fill ~21 ~60 ~33 ~23 ~67 ~33 stone
fill ~21 ~68 ~33 ~23 ~70 ~33 dirt
fill ~21 ~71 ~33 ~23 ~71 ~33 grass_block
fill ~24 ~60 ~33 ~28 ~66 ~33 stone
fill ~24 ~67 ~33 ~28 ~69 ~33 dirt
fill ~24 ~70 ~33 ~28 ~70 ~33 grass_block
fill ~29 ~60 ~33 ~31 ~65 ~33 stone
fill ~29 ~66 ~33 ~31 ~68 ~33 dirt
fill ~29 ~69 ~33 ~31 ~69 ~33 grass_block
fill ~16 ~60 ~34 ~18 ~68 ~34 stone
fill ~16 ~69 ~34 ~18 ~71 ~34 dirt
fill ~16 ~72 ~34 ~18 ~72 ~34 grass_block
fill ~19 ~60 ~34 ~20 ~67 ~34 stone
fill ~19 ~68 ~34 ~20 ~70 ~34 dirt
fill ~19 ~71 ~34 ~20 ~71 ~34 grass_block
fill ~21 ~60 ~34 ~22 ~68 ~34 stone
fill ~21 ~69 ~34 ~22 ~71 ~34 dirt
fill ~21 ~72 ~34 ~22 ~72 ~34 grass_block
fill ~23 ~60 ~34 ~26 ~67 ~34 stone
fill ~23 ~68 ~34 ~26 ~70 ~34 dirt
fill ~23 ~71 ~34 ~26 ~71 ~34 grass_block
fill ~27 ~60 ~34 ~28 ~66 ~34 stone
fill ~27 ~67 ~34 ~28 ~69 ~34 dirt
fill ~27 ~70 ~34 ~28 ~70 ~34 grass_block
fill ~29 ~60 ~34 ~31 ~65 ~34 stone
fill ~29 ~66 ~34 ~31 ~68 ~34 dirt
fill ~29 ~69 ~34 ~31 ~69 ~34 grass_block
fill ~16 ~60 ~35 ~23 ~68 ~35 stone
fill ~16 ~69 ~35 ~23 ~71 ~35 dirt
fill ~16 ~72 ~35 ~23 ~72 ~35 grass_block
fill ~24 ~60 ~35 ~27 ~67 ~35 stone
fill ~24 ~68 ~35 ~27 ~70 ~35 dirt
fill ~24 ~71 ~35 ~27 ~71 ~35 grass_block
fill ~28 ~60 ~35 ~31 ~66 ~35 stone
fill ~28 ~67 ~35 ~31 ~69 ~35 dirt
fill ~28 ~70 ~35 ~31 ~70 ~35 grass_block
fill ~16 ~60 ~36 ~16 ~69 ~36 stone
fill ~16 ~70 ~36 ~16 ~72 ~36 dirt
fill ~16 ~73 ~36 ~16 ~73 ~36 grass_block
fill ~17 ~60 ~36 ~20 ~68 ~36 stone
fill ~17 ~69 ~36 ~20 ~71 ~36 dirt
fill ~17 ~72 ~36 ~20 ~72 ~36 grass_block
fill ~21 ~60 ~36 ~22 ~69 ~36 stone
fill ~21 ~70 ~36 ~22 ~72 ~36 dirt
fill ~21 ~73 ~36 ~22 ~73 ~36 grass_block
fill ~23 ~60 ~36 ~25 ~68 ~36 stone
fill ~23 ~69 ~36 ~25 ~71 ~36 dirt
fill ~23 ~72 ~36 ~25 ~72 ~36 grass_block
fill ~26 ~60 ~36 ~31 ~67 ~36 stone
fill ~26 ~68 ~36 ~31 ~70 ~36 dirt
fill ~26 ~71 ~36 ~31 ~71 ~36 grass_block
fill ~16 ~60 ~37 ~17 ~69 ~37 stone
fill ~16 ~70 ~37 ~17 ~72 ~37 dirt
fill ~16 ~73 ~37 ~17 ~73 ~37 grass_block
fill ~18 ~60 ~37 ~20 ~68 ~37 stone
fill ~18 ~69 ~37 ~20 ~71 ~37 dirt
fill ~18 ~72 ~37 ~20 ~72 ~37 grass_block
fill ~21 ~60 ~37 ~25 ~69 ~37 stone
fill ~21 ~70 ~37 ~25 ~72 ~37 dirt
fill ~21 ~73 ~37 ~25 ~73 ~37 grass_block
fill ~26 ~60 ~37 ~27 ~68 ~37 stone
fill ~26 ~69 ~37 ~27 ~71 ~37 dirt
fill ~26 ~72 ~37 ~27 ~72 ~37 grass_block
fill ~28 ~60 ~37 ~31 ~67 ~37 stone
fill ~28 ~68 ~37 ~31 ~70 ~37 dirt
fill ~28 ~71 ~37 ~31 ~71 ~37 grass_block
fill ~16 ~60 ~38 ~17 ~68 ~38 stone
fill ~16 ~69 ~38 ~17 ~71 ~38 dirt
fill ~16 ~72 ~38 ~17 ~72 ~38 grass_block
fill ~18 ~60 ~38 ~18 ~69 ~38 stone
fill ~18 ~70 ~38 ~18 ~72 ~38 dirt
fill ~18 ~73 ~38 ~18 ~73 ~38 grass_block
fill ~19 ~60 ~38 ~20 ~68 ~38 stone
fill ~19 ~69 ~38 ~20 ~71 ~38 dirt
fill ~19 ~72 ~38 ~20 ~72 ~38 grass_block
fill ~21 ~60 ~38 ~28 ~69 ~38 stone
fill ~21 ~70 ~38 ~28 ~72 ~38 dirt
fill ~21 ~73 ~38 ~28 ~73 ~38 grass_block
fill ~29 ~60 ~38 ~31 ~68 ~38 stone
fill ~29 ~69 ~38 ~31 ~71 ~38 dirt
fill ~29 ~72 ~38 ~31 ~72 ~38 grass_block
fill ~16 ~60 ~39 ~20 ~68 ~39 stone
fill ~16 ~69 ~39 ~20 ~71 ~39 dirt
fill ~16 ~72 ~39 ~20 ~72 ~39 grass_block
fill ~21 ~60 ~39 ~31 ~69 ~39 stone
fill ~21 ~70 ~39 ~31 ~72 ~39 dirt
fill ~21 ~73 ~39 ~31 ~73 ~39 grass_block
fill ~16 ~60 ~40 ~16 ~67 ~40 stone
fill ~16 ~68 ~40 ~16 ~70 ~40 dirt
fill ~16 ~71 ~40 ~16 ~71 ~40 grass_block
fill ~17 ~60 ~40 ~22 ~68 ~40 stone
fill ~17 ~69 ~40 ~22 ~71 ~40 dirt
fill ~17 ~72 ~40 ~22 ~72 ~40 grass_block
fill ~23 ~60 ~40 ~30 ~69 ~40 stone
fill ~23 ~70 ~40 ~30 ~72 ~40 dirt
fill ~23 ~73 ~40 ~30 ~73 ~40 grass_block
fill ~31 ~60 ~40 ~31 ~68 ~40 stone
fill ~31 ~69 ~40 ~31 ~71 ~40 dirt
fill ~31 ~72 ~40 ~31 ~72 ~40 grass_block
fill ~16 ~60 ~41 ~18 ~67 ~41 stone
fill ~16 ~68 ~41 ~18 ~70 ~41 dirt
fill ~16 ~71 ~41 ~18 ~71 ~41 grass_block
fill ~19 ~60 ~41 ~23 ~68 ~41 stone
fill ~19 ~69 ~41 ~23 ~71 ~41 dirt
fill ~19 ~72 ~41 ~23 ~72 ~41 grass_block
fill ~24 ~60 ~41 ~28 ~69 ~41 stone
fill ~24 ~70 ~41 ~28 ~72 ~41 dirt
fill ~24 ~73 ~41 ~28 ~73 ~41 grass_block
fill ~29 ~60 ~41 ~31 ~68 ~41 stone
fill ~29 ~69 ~41 ~31 ~71 ~41 dirt
fill ~29 ~72 ~41 ~31 ~72 ~41 grass_block
fill ~16 ~60 ~42 ~20 ~67 ~42 stone
fill ~16 ~68 ~42 ~20 ~70 ~42 dirt
fill ~16 ~71 ~42 ~20 ~71 ~42 grass_block
fill ~21 ~60 ~42 ~31 ~68 ~42 stone
fill ~21 ~69 ~42 ~31 ~71 ~42 dirt
fill ~21 ~72 ~42 ~31 ~72 ~42 grass_block
fill ~16 ~60 ~43 ~16 ~66 ~43 stone
fill ~16 ~67 ~43 ~16 ~69 ~43 dirt
fill ~16 ~70 ~43 ~16 ~70 ~43 grass_block
fill ~17 ~60 ~43 ~21 ~67 ~43 stone
fill ~17 ~68 ~43 ~21 ~70 ~43 dirt
fill ~17 ~71 ~43 ~21 ~71 ~43 grass_block
fill ~22 ~60 ~43 ~31 ~68 ~43 stone
fill ~22 ~69 ~43 ~31 ~71 ~43 dirt
fill ~22 ~72 ~43 ~31 ~72 ~43 grass_block
fill ~16 ~60 ~44 ~17 ~66 ~44 stone
fill ~16 ~67 ~44 ~17 ~69 ~44 dirt
fill ~16 ~70 ~44 ~17 ~70 ~44 grass_block
fill ~18 ~60 ~44 ~18 ~67 ~44 stone
fill ~18 ~68 ~44 ~18 ~70 ~44 dirt
fill ~18 ~71 ~44 ~18 ~71 ~44 grass_block
fill ~19 ~60 ~44 ~19 ~66 ~44 stone
fill ~19 ~67 ~44 ~19 ~69 ~44 dirt
fill ~19 ~70 ~44 ~19 ~70 ~44 grass_block
fill ~20 ~60 ~44 ~24 ~67 ~44 stone
fill ~20 ~68 ~44 ~24 ~70 ~44 dirt
fill ~20 ~71 ~44 ~24 ~71 ~44 grass_block
fill ~25 ~60 ~44 ~30 ~68 ~44 stone
fill ~25 ~69 ~44 ~30 ~71 ~44 dirt
fill ~25 ~72 ~44 ~30 ~72 ~44 grass_block
fill ~31 ~60 ~44 ~31 ~67 ~44 stone
fill ~31 ~68 ~44 ~31 ~70 ~44 dirt
fill ~31 ~71 ~44 ~31 ~71 ~44 grass_block
fill ~16 ~60 ~45 ~20 ~66 ~45 stone
fill ~16 ~67 ~45 ~20 ~69 ~45 dirt
fill ~16 ~70 ~45 ~20 ~70 ~45 grass_block
fill ~21 ~60 ~45 ~31 ~67 ~45 stone
fill ~21 ~68 ~45 ~31 ~70 ~45 dirt
fill ~21 ~71 ~45 ~31 ~71 ~45 grass_block
fill ~16 ~60 ~46 ~16 ~65 ~46 stone
fill ~16 ~66 ~46 ~16 ~68 ~46 dirt
fill ~16 ~69 ~46 ~16 ~69 ~46 grass_block
fill ~17 ~60 ~46 ~23 ~66 ~46 stone
fill ~17 ~67 ~46 ~23 ~69 ~46 dirt
fill ~17 ~70 ~46 ~23 ~70 ~46 grass_block
fill ~24 ~60 ~46 ~31 ~67 ~46 stone
fill ~24 ~68 ~46 ~31 ~70 ~46 dirt
fill ~24 ~71 ~46 ~31 ~71 ~46 grass_block
fill ~16 ~60 ~47 ~16 ~66 ~47 stone
fill ~16 ~67 ~47 ~16 ~69 ~47 dirt
fill ~16 ~70 ~47 ~16 ~70 ~47 grass_block
fill ~17 ~60 ~47 ~18 ~65 ~47 stone
fill ~17 ~66 ~47 ~18 ~68 ~47 dirt
fill ~17 ~69 ~47 ~18 ~69 ~47 grass_block
fill ~19 ~60 ~47 ~30 ~66 ~47 stone
fill ~19 ~67 ~47 ~30 ~69 ~47 dirt
fill ~19 ~70 ~47 ~30 ~70 ~47 grass_block
fill ~31 ~60 ~47 ~31 ~67 ~47 stone
fill ~31 ~68 ~47 ~31 ~70 ~47 dirt
fill ~31 ~71 ~47 ~31 ~71 ~47 grass_block