fill ~144 ~60 ~112 ~144 ~65 ~112 stone
fill ~144 ~66 ~112 ~144 ~68 ~112 dirt
fill ~144 ~69 ~112 ~144 ~69 ~112 grass_block
fill ~145 ~60 ~112 ~150 ~64 ~112 stone
fill ~145 ~65 ~112 ~150 ~67 ~112 dirt
fill ~145 ~68 ~112 ~150 ~68 ~112 grass_block
fill ~151 ~60 ~112 ~154 ~63 ~112 stone
fill ~151 ~64 ~112 ~154 ~66 ~112 dirt
fill ~151 ~67 ~112 ~154 ~67 ~112 grass_block
fill ~155 ~60 ~112 ~159 ~62 ~112 stone
fill ~155 ~63 ~112 ~159 ~65 ~112 dirt
fill ~155 ~66 ~112 ~159 ~66 ~112 grass_block
fill ~144 ~60 ~113 ~144 ~65 ~113 stone
fill ~144 ~66 ~113 ~144 ~68 ~113 dirt
fill ~144 ~69 ~113 ~144 ~69 ~113 grass_block
fill ~145 ~60 ~113 ~150 ~64 ~113 stone
fill ~145 ~65 ~113 ~150 ~67 ~113 dirt
fill ~145 ~68 ~113 ~150 ~68 ~113 grass_block
fill ~151 ~60 ~113 ~155 ~63 ~113 stone
fill ~151 ~64 ~113 ~155 ~66 ~113 dirt
fill ~151 ~67 ~113 ~155 ~67 ~113 grass_block
fill ~156 ~60 ~113 ~159 ~62 ~113 stone
fill ~156 ~63 ~113 ~159 ~65 ~113 dirt
fill ~156 ~66 ~113 ~159 ~66 ~113 grass_block
fill ~144 ~60 ~114 ~144 ~65 ~114 stone
fill ~144 ~66 ~114 ~144 ~68 ~114 dirt
fill ~144 ~69 ~114 ~144 ~69 ~114 grass_block
fill ~145 ~60 ~114 ~147 ~64 ~114 stone
fill ~145 ~65 ~114 ~147 ~67 ~114 dirt
fill ~145 ~68 ~114 ~147 ~68 ~114 grass_block
fill ~148 ~60 ~114 ~155 ~63 ~114 stone
fill ~148 ~64 ~114 ~155 ~66 ~114 dirt
fill ~148 ~67 ~114 ~155 ~67 ~114 grass_block
fill ~156 ~60 ~114 ~159 ~62 ~114 stone
fill ~156 ~63 ~114 ~159 ~65 ~114 dirt
fill ~156 ~66 ~114 ~159 ~66 ~114 grass_block
fill ~144 ~60 ~115 ~146 ~64 ~115 stone
fill ~144 ~65 ~115 ~146 ~67 ~115 dirt
fill ~144 ~68 ~115 ~146 ~68 ~115 grass_block
fill ~147 ~60 ~115 ~151 ~63 ~115 stone
fill ~147 ~64 ~115 ~151 ~66 ~115 dirt
fill ~147 ~67 ~115 ~151 ~67 ~115 grass_block
fill ~152 ~60 ~115 ~152 ~62 ~115 stone
fill ~152 ~63 ~115 ~152 ~65 ~115 dirt
fill ~152 ~66 ~115 ~152 ~66 ~115 grass_block
fill ~153 ~60 ~115 ~155 ~63 ~115 stone
fill ~153 ~64 ~115 ~155 ~66 ~115 dirt
fill ~153 ~67 ~115 ~155 ~67 ~115 grass_block
fill ~156 ~60 ~115 ~156 ~62 ~115 stone
fill ~156 ~63 ~115 ~156 ~65 ~115 dirt
fill ~156 ~66 ~115 ~156 ~66 ~115 grass_block
fill ~157 ~60 ~115 ~157 ~63 ~115 stone
fill ~157 ~64 ~115 ~157 ~66 ~115 dirt
fill ~157 ~67 ~115 ~157 ~67 ~115 grass_block
fill ~158 ~60 ~115 ~159 ~62 ~115 stone
fill ~158 ~63 ~115 ~159 ~65 ~115 dirt
fill ~158 ~66 ~115 ~159 ~66 ~115 grass_block
fill ~144 ~60 ~116 ~159 ~63 ~116 stone
fill ~144 ~64 ~116 ~159 ~66 ~116 dirt
fill ~144 ~67 ~116 ~159 ~67 ~116 grass_block
fill ~144 ~60 ~117 ~144 ~64 ~117 stone
fill ~144 ~65 ~117 ~144 ~67 ~117 dirt
fill ~144 ~68 ~117 ~144 ~68 ~117 grass_block
fill ~145 ~60 ~117 ~147 ~63 ~117 stone
fill ~145 ~64 ~117 ~147 ~66 ~117 dirt
fill ~145 ~67 ~117 ~147 ~67 ~117 grass_block
fill ~148 ~60 ~117 ~157 ~64 ~117 stone
fill ~148 ~65 ~117 ~157 ~67 ~117 dirt
fill ~148 ~68 ~117 ~157 ~68 ~117 grass_block
fill ~158 ~60 ~117 ~159 ~63 ~117 stone
fill ~158 ~64 ~117 ~159 ~66 ~117 dirt
fill ~158 ~67 ~117 ~159 ~67 ~117 grass_block
fill ~144 ~60 ~118 ~144 ~64 ~118 stone
fill ~144 ~65 ~118 ~144 ~67 ~118 dirt
fill ~144 ~68 ~118 ~144 ~68 ~118 grass_block
fill ~145 ~60 ~118 ~147 ~63 ~118 stone
fill ~145 ~64 ~118 ~147 ~66 ~118 dirt
fill ~145 ~67 ~118 ~147 ~67 ~118 grass_block
fill ~148 ~60 ~118 ~150 ~64 ~118 stone
fill ~148 ~65 ~118 ~150 ~67 ~118 dirt
fill ~148 ~68 ~118 ~150 ~68 ~118 grass_block
fill ~151 ~60 ~118 ~151 ~65 ~118 stone
fill ~151 ~66 ~118 ~151 ~68 ~118 dirt
fill ~151 ~69 ~118 ~151 ~69 ~118 grass_block
fill ~152 ~60 ~118 ~158 ~64 ~118 stone
fill ~152 ~65 ~118 ~158 ~67 ~118 dirt
fill ~152 ~68 ~118 ~158 ~68 ~118 grass_block
fill ~159 ~60 ~118 ~159 ~63 ~118 stone
fill ~159 ~64 ~118 ~159 ~66 ~118 dirt
fill ~159 ~67 ~118 ~159 ~67 ~118 grass_block
fill ~144 ~60 ~119 ~145 ~64 ~119 stone
fill ~144 ~65 ~119 ~145 ~67 ~119 dirt
fill ~144 ~68 ~119 ~145 ~68 ~119 grass_block
fill ~146 ~60 ~119 ~147 ~63 ~119 stone
fill ~146 ~64 ~119 ~147 ~66 ~119 dirt
fill ~146 ~67 ~119 ~147 ~67 ~119 grass_block
fill ~148 ~60 ~119 ~151 ~64 ~119 stone
fill ~148 ~65 ~119 ~151 ~67 ~119 dirt
fill ~148 ~68 ~119 ~151 ~68 ~119 grass_block
fill ~152 ~60 ~119 ~154 ~65 ~119 stone
fill ~152 ~66 ~119 ~154 ~68 ~119 dirt
fill ~152 ~69 ~119 ~154 ~69 ~119 grass_block
fill ~155 ~60 ~119 ~159 ~64 ~119 stone
fill ~155 ~65 ~119 ~159 ~67 ~119 dirt
fill ~155 ~68 ~119 ~159 ~68 ~119 grass_block
fill ~144 ~60 ~120 ~144 ~65 ~120 stone
fill ~144 ~66 ~120 ~144 ~68 ~120 dirt
fill ~144 ~69 ~120 ~144 ~69 ~120 grass_block
fill ~145 ~60 ~120 ~148 ~64 ~120 stone
fill ~145 ~65 ~120 ~148 ~67 ~120 dirt
fill ~145 ~68 ~120 ~148 ~68 ~120 grass_block
fill ~149 ~60 ~120 ~155 ~65 ~120 stone
fill ~149 ~66 ~120 ~155 ~68 ~120 dirt
fill ~149 ~69 ~120 ~155 ~69 ~120 grass_block
fill ~156 ~60 ~120 ~159 ~64 ~120 stone
fill ~156 ~65 ~120 ~159 ~67 ~120 dirt
fill ~156 ~68 ~120 ~159 ~68 ~120 grass_block
fill ~144 ~60 ~121 ~145 ~65 ~121 stone
fill ~144 ~66 ~121 ~145 ~68 ~121 dirt
fill ~144 ~69 ~121 ~145 ~69 ~121 grass_block
fill ~146 ~60 ~121 ~148 ~64 ~121 stone
fill ~146 ~65 ~121 ~148 ~67 ~121 dirt
fill ~146 ~68 ~121 ~148 ~68 ~121 grass_block
fill ~149 ~60 ~121 ~155 ~65 ~121 stone
fill ~149 ~66 ~121 ~155 ~68 ~121 dirt
fill ~149 ~69 ~121 ~155 ~69 ~121 grass_block
fill ~156 ~60 ~121 ~159 ~64 ~121 stone
fill ~156 ~65 ~121 ~159 ~67 ~121 dirt
fill ~156 ~68 ~121 ~159 ~68 ~121 grass_block
fill ~144 ~60 ~122 ~144 ~66 ~122 stone
fill ~144 ~67 ~122 ~144 ~69 ~122 dirt
fill ~144 ~70 ~122 ~144 ~70 ~122 grass_block
fill ~145 ~60 ~122 ~146 ~65 ~122 stone
fill ~145 ~66 ~122 ~146 ~68 ~122 dirt
fill ~145 ~69 ~122 ~146 ~69 ~122 grass_block
fill ~147 ~60 ~122 ~149 ~64 ~122 stone
fill ~147 ~65 ~122 ~149 ~67 ~122 dirt
fill ~147 ~68 ~122 ~149 ~68 ~122 grass_block
fill ~150 ~60 ~122 ~154 ~65 ~122 stone
fill ~150 ~66 ~122 ~154 ~68 ~122 dirt
fill ~150 ~69 ~122 ~154 ~69 ~122 grass_block
fill ~155 ~60 ~122 ~159 ~64 ~122 stone
fill ~155 ~65 ~122 ~159 ~67 ~122 dirt
fill ~155 ~68 ~122 ~159 ~68 ~122 grass_block
fill ~144 ~60 ~123 ~145 ~66 ~123 stone
fill ~144 ~67 ~123 ~145 ~69 ~123 dirt
fill ~144 ~70 ~123 ~145 ~70 ~123 grass_block
fill ~146 ~60 ~123 ~155 ~65 ~123 stone
fill ~146 ~66 ~123 ~155 ~68 ~123 dirt
fill ~146 ~69 ~123 ~155 ~69 ~123 grass_block
fill ~156 ~60 ~123 ~159 ~64 ~123 stone
fill ~156 ~65 ~123 ~159 ~67 ~123 dirt
fill ~156 ~68 ~123 ~159 ~68 ~123 grass_block
fill ~144 ~60 ~124 ~144 ~67 ~124 stone
fill ~144 ~68 ~124 ~144 ~70 ~124 dirt
fill ~144 ~71 ~124 ~144 ~71 ~124 grass_block
fill ~145 ~60 ~124 ~148 ~66 ~124 stone
fill ~145 ~67 ~124 ~148 ~69 ~124 dirt
fill ~145 ~70 ~124 ~148 ~70 ~124 grass_block
fill ~149 ~60 ~124 ~154 ~65 ~124 stone
fill ~149 ~66 ~124 ~154 ~68 ~124 dirt
fill ~149 ~69 ~124 ~154 ~69 ~124 grass_block
fill ~155 ~60 ~124 ~159 ~64 ~124 stone
fill ~155 ~65 ~124 ~159 ~67 ~124 dirt
fill ~155 ~68 ~124 ~159 ~68 ~124 grass_block
fill ~144 ~60 ~125 ~145 ~67 ~125 stone
fill ~144 ~68 ~125 ~145 ~70 ~125 dirt
fill ~144 ~71 ~125 ~145 ~71 ~125 grass_block
fill ~146 ~60 ~125 ~149 ~66 ~125 stone
fill ~146 ~67 ~125 ~149 ~69 ~125 dirt
fill ~146 ~70 ~125 ~149 ~70 ~125 grass_block
fill ~150 ~60 ~125 ~155 ~65 ~125 stone
fill ~150 ~66 ~125 ~155 ~68 ~125 dirt
fill ~150 ~69 ~125 ~155 ~69 ~125 grass_block
fill ~156 ~60 ~125 ~159 ~64 ~125 stone
fill ~156 ~65 ~125 ~159 ~67 ~125 dirt
fill ~156 ~68 ~125 ~159 ~68 ~125 grass_block
fill ~144 ~60 ~126 ~146 ~67 ~126 stone
fill ~144 ~68 ~126 ~146 ~70 ~126 dirt
fill ~144 ~71 ~126 ~146 ~71 ~126 grass_block
fill ~147 ~60 ~126 ~149 ~66 ~126 stone
fill ~147 ~67 ~126 ~149 ~69 ~126 dirt
fill ~147 ~70 ~126 ~149 ~70 ~126 grass_block
fill ~150 ~60 ~126 ~156 ~65 ~126 stone
fill ~150 ~66 ~126 ~156 ~68 ~126 dirt
fill ~150 ~69 ~126 ~156 ~69 ~126 grass_block
fill ~157 ~60 ~126 ~159 ~64 ~126 stone
fill ~157 ~65 ~126 ~159 ~67 ~126 dirt
fill ~157 ~68 ~126 ~159 ~68 ~126 grass_block
fill ~144 ~60 ~127 ~146 ~67 ~127 stone
fill ~144 ~68 ~127 ~146 ~70 ~127 dirt
fill ~144 ~71 ~127 ~146 ~71 ~127 grass_block
fill ~147 ~60 ~127 ~150 ~66 ~127 stone
fill ~147 ~67 ~127 ~150 ~69 ~127 dirt
fill ~147 ~70 ~127 ~150 ~70 ~127 grass_block
fill ~151 ~60 ~127 ~156 ~65 ~127 stone
fill ~151 ~66 ~127 ~156 ~68 ~127 dirt
fill ~151 ~69 ~127 ~156 ~69 ~127 grass_block
fill ~157 ~60 ~127 ~159 ~64 ~127 stone
fill ~157 ~65 ~127 ~159 ~67 ~127 dirt
fill ~157 ~68 ~127 ~159 ~68 ~127 grass_block