fill ~224 ~60 ~64 ~231 ~63 ~64 stone
fill ~224 ~64 ~64 ~231 ~66 ~64 dirt
fill ~224 ~67 ~64 ~231 ~67 ~64 grass_block
fill ~232 ~60 ~64 ~239 ~62 ~64 stone
fill ~232 ~63 ~64 ~239 ~65 ~64 dirt
fill ~232 ~66 ~64 ~239 ~66 ~64 grass_block
fill ~224 ~60 ~65 ~224 ~63 ~65 stone
fill ~224 ~64 ~65 ~224 ~66 ~65 dirt
fill ~224 ~67 ~65 ~224 ~67 ~65 grass_block
fill ~225 ~60 ~65 ~228 ~64 ~65 stone
fill ~225 ~65 ~65 ~228 ~67 ~65 dirt
fill ~225 ~68 ~65 ~228 ~68 ~65 grass_block
fill ~229 ~60 ~65 ~238 ~63 ~65 stone
fill ~229 ~64 ~65 ~238 ~66 ~65 dirt
fill ~229 ~67 ~65 ~238 ~67 ~65 grass_block
fill ~239 ~60 ~65 ~239 ~62 ~65 stone
fill ~239 ~63 ~65 ~239 ~65 ~65 dirt
fill ~239 ~66 ~65 ~239 ~66 ~65 grass_block
fill ~224 ~60 ~66 ~226 ~64 ~66 stone
fill ~224 ~65 ~66 ~226 ~67 ~66 dirt
fill ~224 ~68 ~66 ~226 ~68 ~66 grass_block
fill ~227 ~60 ~66 ~227 ~65 ~66 stone
fill ~227 ~66 ~66 ~227 ~68 ~66 dirt
fill ~227 ~69 ~66 ~227 ~69 ~66 grass_block
fill ~228 ~60 ~66 ~233 ~64 ~66 stone
fill ~228 ~65 ~66 ~233 ~67 ~66 dirt
fill ~228 ~68 ~66 ~233 ~68 ~66 grass_block
fill ~234 ~60 ~66 ~239 ~63 ~66 stone
fill ~234 ~64 ~66 ~239 ~66 ~66 dirt
fill ~234 ~67 ~66 ~239 ~67 ~66 grass_block
fill ~224 ~60 ~67 ~225 ~64 ~67 stone
fill ~224 ~65 ~67 ~225 ~67 ~67 dirt
fill ~224 ~68 ~67 ~225 ~68 ~67 grass_block
fill ~226 ~60 ~67 ~231 ~65 ~67 stone
fill ~226 ~66 ~67 ~231 ~68 ~67 dirt
fill ~226 ~69 ~67 ~231 ~69 ~67 grass_block
fill ~232 ~60 ~67 ~238 ~64 ~67 stone
fill ~232 ~65 ~67 ~238 ~67 ~67 dirt
fill ~232 ~68 ~67 ~238 ~68 ~67 grass_block
fill ~239 ~60 ~67 ~239 ~63 ~67 stone
fill ~239 ~64 ~67 ~239 ~66 ~67 dirt
fill ~239 ~67 ~67 ~239 ~67 ~67 grass_block
fill ~224 ~60 ~68 ~225 ~64 ~68 stone
fill ~224 ~65 ~68 ~225 ~67 ~68 dirt
fill ~224 ~68 ~68 ~225 ~68 ~68 grass_block
fill ~226 ~60 ~68 ~227 ~65 ~68 stone
fill ~226 ~66 ~68 ~227 ~68 ~68 dirt
fill ~226 ~69 ~68 ~227 ~69 ~68 grass_block
fill ~228 ~60 ~68 ~228 ~66 ~68 stone
fill ~228 ~67 ~68 ~228 ~69 ~68 dirt
fill ~228 ~70 ~68 ~228 ~70 ~68 grass_block
fill ~229 ~60 ~68 ~232 ~65 ~68 stone
fill ~229 ~66 ~68 ~232 ~68 ~68 dirt
fill ~229 ~69 ~68 ~232 ~69 ~68 grass_block
fill ~233 ~60 ~68 ~239 ~64 ~68 stone
fill ~233 ~65 ~68 ~239 ~67 ~68 dirt
fill ~233 ~68 ~68 ~239 ~68 ~68 grass_block
fill ~224 ~60 ~69 ~225 ~64 ~69 stone
fill ~224 ~65 ~69 ~225 ~67 ~69 dirt
fill ~224 ~68 ~69 ~225 ~68 ~69 grass_block
fill ~226 ~60 ~69 ~226 ~65 ~69 stone
fill ~226 ~66 ~69 ~226 ~68 ~69 dirt
fill ~226 ~69 ~69 ~226 ~69 ~69 grass_block
fill ~227 ~60 ~69 ~229 ~66 ~69 stone
fill ~227 ~67 ~69 ~229 ~69 ~69 dirt
fill ~227 ~70 ~69 ~229 ~70 ~69 grass_block
fill ~230 ~60 ~69 ~238 ~65 ~69 stone
fill ~230 ~66 ~69 ~238 ~68 ~69 dirt
fill ~230 ~69 ~69 ~238 ~69 ~69 grass_block
fill ~239 ~60 ~69 ~239 ~64 ~69 stone
fill ~239 ~65 ~69 ~239 ~67 ~69 dirt
fill ~239 ~68 ~69 ~239 ~68 ~69 grass_block
fill ~224 ~60 ~70 ~226 ~64 ~70 stone
fill ~224 ~65 ~70 ~226 ~67 ~70 dirt
fill ~224 ~68 ~70 ~226 ~68 ~70 grass_block
fill ~227 ~60 ~70 ~227 ~65 ~70 stone
fill ~227 ~66 ~70 ~227 ~68 ~70 dirt
fill ~227 ~69 ~70 ~227 ~69 ~70 grass_block
fill ~228 ~60 ~70 ~230 ~66 ~70 stone
fill ~228 ~67 ~70 ~230 ~69 ~70 dirt
fill ~228 ~70 ~70 ~230 ~70 ~70 grass_block
fill ~231 ~60 ~70 ~238 ~65 ~70 stone
fill ~231 ~66 ~70 ~238 ~68 ~70 dirt
fill ~231 ~69 ~70 ~238 ~69 ~70 grass_block
fill ~239 ~60 ~70 ~239 ~64 ~70 stone
fill ~239 ~65 ~70 ~239 ~67 ~70 dirt
fill ~239 ~68 ~70 ~239 ~68 ~70 grass_block
fill ~224 ~60 ~71 ~224 ~64 ~71 stone
fill ~224 ~65 ~71 ~224 ~67 ~71 dirt
fill ~224 ~68 ~71 ~224 ~68 ~71 grass_block
fill ~225 ~60 ~71 ~227 ~65 ~71 stone
fill ~225 ~66 ~71 ~227 ~68 ~71 dirt
fill ~225 ~69 ~71 ~227 ~69 ~71 grass_block
fill ~228 ~60 ~71 ~231 ~66 ~71 stone
fill ~228 ~67 ~71 ~231 ~69 ~71 dirt
fill ~228 ~70 ~71 ~231 ~70 ~71 grass_block
fill ~232 ~60 ~71 ~238 ~65 ~71 stone
fill ~232 ~66 ~71 ~238 ~68 ~71 dirt
fill ~232 ~69 ~71 ~238 ~69 ~71 grass_block
fill ~239 ~60 ~71 ~239 ~64 ~71 stone
fill ~239 ~65 ~71 ~239 ~67 ~71 dirt
fill ~239 ~68 ~71 ~239 ~68 ~71 grass_block
fill ~224 ~60 ~72 ~225 ~65 ~72 stone
fill ~224 ~66 ~72 ~225 ~68 ~72 dirt
fill ~224 ~69 ~72 ~225 ~69 ~72 grass_block
fill ~226 ~60 ~72 ~232 ~66 ~72 stone
fill ~226 ~67 ~72 ~232 ~69 ~72 dirt
fill ~226 ~70 ~72 ~232 ~70 ~72 grass_block
fill ~233 ~60 ~72 ~238 ~65 ~72 stone
fill ~233 ~66 ~72 ~238 ~68 ~72 dirt
fill ~233 ~69 ~72 ~238 ~69 ~72 grass_block
fill ~239 ~60 ~72 ~239 ~64 ~72 stone
fill ~239 ~65 ~72 ~239 ~67 ~72 dirt
fill ~239 ~68 ~72 ~239 ~68 ~72 grass_block
fill ~224 ~60 ~73 ~225 ~65 ~73 stone
fill ~224 ~66 ~73 ~225 ~68 ~73 dirt
fill ~224 ~69 ~73 ~225 ~69 ~73 grass_block
fill ~226 ~60 ~73 ~235 ~66 ~73 stone
fill ~226 ~67 ~73 ~235 ~69 ~73 dirt
fill ~226 ~70 ~73 ~235 ~70 ~73 grass_block
fill ~236 ~60 ~73 ~239 ~65 ~73 stone
fill ~236 ~66 ~73 ~239 ~68 ~73 dirt
fill ~236 ~69 ~73 ~239 ~69 ~73 grass_block
fill ~224 ~60 ~74 ~224 ~64 ~74 stone
fill ~224 ~65 ~74 ~224 ~67 ~74 dirt
fill ~224 ~68 ~74 ~224 ~68 ~74 grass_block
fill ~225 ~60 ~74 ~225 ~65 ~74 stone
fill ~225 ~66 ~74 ~225 ~68 ~74 dirt
fill ~225 ~69 ~74 ~225 ~69 ~74 grass_block
fill ~226 ~60 ~74 ~228 ~66 ~74 stone
fill ~226 ~67 ~74 ~228 ~69 ~74 dirt
fill ~226 ~70 ~74 ~228 ~70 ~74 grass_block
fill ~229 ~60 ~74 ~229 ~67 ~74 stone
fill ~229 ~68 ~74 ~229 ~70 ~74 dirt
fill ~229 ~71 ~74 ~229 ~71 ~74 grass_block
fill ~230 ~60 ~74 ~235 ~66 ~74 stone
fill ~230 ~67 ~74 ~235 ~69 ~74 dirt
fill ~230 ~70 ~74 ~235 ~70 ~74 grass_block
fill ~236 ~60 ~74 ~236 ~65 ~74 stone
fill ~236 ~66 ~74 ~236 ~68 ~74 dirt
fill ~236 ~69 ~74 ~236 ~69 ~74 grass_block
fill ~237 ~60 ~74 ~238 ~66 ~74 stone
fill ~237 ~67 ~74 ~238 ~69 ~74 dirt
fill ~237 ~70 ~74 ~238 ~70 ~74 grass_block
fill ~239 ~60 ~74 ~239 ~65 ~74 stone
fill ~239 ~66 ~74 ~239 ~68 ~74 dirt
fill ~239 ~69 ~74 ~239 ~69 ~74 grass_block
fill ~224 ~60 ~75 ~224 ~64 ~75 stone
fill ~224 ~65 ~75 ~224 ~67 ~75 dirt
fill ~224 ~68 ~75 ~224 ~68 ~75 grass_block
fill ~225 ~60 ~75 ~226 ~65 ~75 stone
fill ~225 ~66 ~75 ~226 ~68 ~75 dirt
fill ~225 ~69 ~75 ~226 ~69 ~75 grass_block
fill ~227 ~60 ~75 ~229 ~66 ~75 stone
fill ~227 ~67 ~75 ~229 ~69 ~75 dirt
fill ~227 ~70 ~75 ~229 ~70 ~75 grass_block
fill ~230 ~60 ~75 ~230 ~67 ~75 stone
fill ~230 ~68 ~75 ~230 ~70 ~75 dirt
fill ~230 ~71 ~75 ~230 ~71 ~75 grass_block
fill ~231 ~60 ~75 ~238 ~66 ~75 stone
fill ~231 ~67 ~75 ~238 ~69 ~75 dirt
fill ~231 ~70 ~75 ~238 ~70 ~75 grass_block
fill ~239 ~60 ~75 ~239 ~65 ~75 stone
fill ~239 ~66 ~75 ~239 ~68 ~75 dirt
fill ~239 ~69 ~75 ~239 ~69 ~75 grass_block
fill ~224 ~60 ~76 ~224 ~64 ~76 stone
fill ~224 ~65 ~76 ~224 ~67 ~76 dirt
fill ~224 ~68 ~76 ~224 ~68 ~76 grass_block
fill ~225 ~60 ~76 ~226 ~65 ~76 stone
fill ~225 ~66 ~76 ~226 ~68 ~76 dirt
fill ~225 ~69 ~76 ~226 ~69 ~76 grass_block
fill ~227 ~60 ~76 ~230 ~66 ~76 stone
fill ~227 ~67 ~76 ~230 ~69 ~76 dirt
fill ~227 ~70 ~76 ~230 ~70 ~76 grass_block
fill ~231 ~60 ~76 ~231 ~67 ~76 stone
fill ~231 ~68 ~76 ~231 ~70 ~76 dirt
fill ~231 ~71 ~76 ~231 ~71 ~76 grass_block
fill ~232 ~60 ~76 ~239 ~66 ~76 stone
fill ~232 ~67 ~76 ~239 ~69 ~76 dirt
fill ~232 ~70 ~76 ~239 ~70 ~76 grass_block
fill ~224 ~60 ~77 ~224 ~64 ~77 stone
fill ~224 ~65 ~77 ~224 ~67 ~77 dirt
fill ~224 ~68 ~77 ~224 ~68 ~77 grass_block
fill ~225 ~60 ~77 ~226 ~65 ~77 stone
fill ~225 ~66 ~77 ~226 ~68 ~77 dirt
fill ~225 ~69 ~77 ~226 ~69 ~77 grass_block
fill ~227 ~60 ~77 ~239 ~66 ~77 stone
fill ~227 ~67 ~77 ~239 ~69 ~77 dirt
fill ~227 ~70 ~77 ~239 ~70 ~77 grass_block
fill ~224 ~60 ~78 ~226 ~65 ~78 stone
fill ~224 ~66 ~78 ~226 ~68 ~78 dirt
fill ~224 ~69 ~78 ~226 ~69 ~78 grass_block
fill ~227 ~60 ~78 ~239 ~66 ~78 stone
fill ~227 ~67 ~78 ~239 ~69 ~78 dirt
fill ~227 ~70 ~78 ~239 ~70 ~78 grass_block
fill ~224 ~60 ~79 ~224 ~66 ~79 stone
fill ~224 ~67 ~79 ~224 ~69 ~79 dirt
fill ~224 ~70 ~79 ~224 ~70 ~79 grass_block
fill ~225 ~60 ~79 ~227 ~65 ~79 stone
fill ~225 ~66 ~79 ~227 ~68 ~79 dirt
fill ~225 ~69 ~79 ~227 ~69 ~79 grass_block
fill ~228 ~60 ~79 ~239 ~66 ~79 stone
fill ~228 ~67 ~79 ~239 ~69 ~79 dirt
fill ~228 ~70 ~79 ~239 ~70 ~79 grass_block