fill ~16 ~60 ~80 ~17 ~65 ~80 stone
fill ~16 ~66 ~80 ~17 ~68 ~80 dirt
fill ~16 ~69 ~80 ~17 ~69 ~80 grass_block
fill ~18 ~60 ~80 ~19 ~66 ~80 stone
fill ~18 ~67 ~80 ~19 ~69 ~80 dirt
fill ~18 ~70 ~80 ~19 ~70 ~80 grass_block
fill ~20 ~60 ~80 ~21 ~65 ~80 stone
fill ~20 ~66 ~80 ~21 ~68 ~80 dirt
fill ~20 ~69 ~80 ~21 ~69 ~80 grass_block
fill ~22 ~60 ~80 ~24 ~66 ~80 stone
fill ~22 ~67 ~80 ~24 ~69 ~80 dirt
fill ~22 ~70 ~80 ~24 ~70 ~80 grass_block
fill ~25 ~60 ~80 ~28 ~67 ~80 stone
fill ~25 ~68 ~80 ~28 ~70 ~80 dirt
fill ~25 ~71 ~80 ~28 ~71 ~80 grass_block
fill ~29 ~60 ~80 ~31 ~68 ~80 stone
fill ~29 ~69 ~80 ~31 ~71 ~80 dirt
fill ~29 ~72 ~80 ~31 ~72 ~80 grass_block
fill ~16 ~60 ~81 ~22 ~65 ~81 stone
fill ~16 ~66 ~81 ~22 ~68 ~81 dirt
fill ~16 ~69 ~81 ~22 ~69 ~81 grass_block
fill ~23 ~60 ~81 ~25 ~66 ~81 stone
fill ~23 ~67 ~81 ~25 ~69 ~81 dirt
fill ~23 ~70 ~81 ~25 ~70 ~81 grass_block
fill ~26 ~60 ~81 ~28 ~67 ~81 stone
fill ~26 ~68 ~81 ~28 ~70 ~81 dirt
fill ~26 ~71 ~81 ~28 ~71 ~81 grass_block
fill ~29 ~60 ~81 ~31 ~68 ~81 stone
fill ~29 ~69 ~81 ~31 ~71 ~81 dirt
fill ~29 ~72 ~81 ~31 ~72 ~81 grass_block
fill ~16 ~60 ~82 ~16 ~64 ~82 stone
fill ~16 ~65 ~82 ~16 ~67 ~82 dirt
fill ~16 ~68 ~82 ~16 ~68 ~82 grass_block
fill ~17 ~60 ~82 ~23 ~65 ~82 stone
fill ~17 ~66 ~82 ~23 ~68 ~82 dirt
fill ~17 ~69 ~82 ~23 ~69 ~82 grass_block
fill ~24 ~60 ~82 ~26 ~66 ~82 stone
fill ~24 ~67 ~82 ~26 ~69 ~82 dirt
fill ~24 ~70 ~82 ~26 ~70 ~82 grass_block
fill ~27 ~60 ~82 ~28 ~67 ~82 stone
fill ~27 ~68 ~82 ~28 ~70 ~82 dirt
fill ~27 ~71 ~82 ~28 ~71 ~82 grass_block
fill ~29 ~60 ~82 ~31 ~68 ~82 stone
fill ~29 ~69 ~82 ~31 ~71 ~82 dirt
fill ~29 ~72 ~82 ~31 ~72 ~82 grass_block
fill ~16 ~60 ~83 ~17 ~64 ~83 stone
fill ~16 ~65 ~83 ~17 ~67 ~83 dirt
fill ~16 ~68 ~83 ~17 ~68 ~83 grass_block
fill ~18 ~60 ~83 ~24 ~65 ~83 stone
fill ~18 ~66 ~83 ~24 ~68 ~83 dirt
fill ~18 ~69 ~83 ~24 ~69 ~83 grass_block
fill ~25 ~60 ~83 ~26 ~66 ~83 stone
fill ~25 ~67 ~83 ~26 ~69 ~83 dirt
fill ~25 ~70 ~83 ~26 ~70 ~83 grass_block
fill ~27 ~60 ~83 ~28 ~67 ~83 stone
fill ~27 ~68 ~83 ~28 ~70 ~83 dirt
fill ~27 ~71 ~83 ~28 ~71 ~83 grass_block
fill ~29 ~60 ~83 ~30 ~68 ~83 stone
fill ~29 ~69 ~83 ~30 ~71 ~83 dirt
fill ~29 ~72 ~83 ~30 ~72 ~83 grass_block
fill ~31 ~60 ~83 ~31 ~67 ~83 stone
fill ~31 ~68 ~83 ~31 ~70 ~83 dirt
fill ~31 ~71 ~83 ~31 ~71 ~83 grass_block
fill ~16 ~60 ~84 ~17 ~64 ~84 stone
fill ~16 ~65 ~84 ~17 ~67 ~84 dirt
fill ~16 ~68 ~84 ~17 ~68 ~84 grass_block
fill ~18 ~60 ~84 ~20 ~65 ~84 stone
fill ~18 ~66 ~84 ~20 ~68 ~84 dirt
fill ~18 ~69 ~84 ~20 ~69 ~84 grass_block
fill ~21 ~60 ~84 ~22 ~64 ~84 stone
fill ~21 ~65 ~84 ~22 ~67 ~84 dirt
fill ~21 ~68 ~84 ~22 ~68 ~84 grass_block
fill ~23 ~60 ~84 ~25 ~65 ~84 stone
fill ~23 ~66 ~84 ~25 ~68 ~84 dirt
fill ~23 ~69 ~84 ~25 ~69 ~84 grass_block
fill ~26 ~60 ~84 ~26 ~66 ~84 stone
fill ~26 ~67 ~84 ~26 ~69 ~84 dirt
fill ~26 ~70 ~84 ~26 ~70 ~84 grass_block
fill ~27 ~60 ~84 ~31 ~67 ~84 stone
fill ~27 ~68 ~84 ~31 ~70 ~84 dirt
fill ~27 ~71 ~84 ~31 ~71 ~84 grass_block
fill ~16 ~60 ~85 ~18 ~64 ~85 stone
fill ~16 ~65 ~85 ~18 ~67 ~85 dirt
fill ~16 ~68 ~85 ~18 ~68 ~85 grass_block
fill ~19 ~60 ~85 ~20 ~65 ~85 stone
fill ~19 ~66 ~85 ~20 ~68 ~85 dirt
fill ~19 ~69 ~85 ~20 ~69 ~85 grass_block
fill ~21 ~60 ~85 ~22 ~64 ~85 stone
fill ~21 ~65 ~85 ~22 ~67 ~85 dirt
fill ~21 ~68 ~85 ~22 ~68 ~85 grass_block
fill ~23 ~60 ~85 ~25 ~65 ~85 stone
fill ~23 ~66 ~85 ~25 ~68 ~85 dirt
fill ~23 ~69 ~85 ~25 ~69 ~85 grass_block
fill ~26 ~60 ~85 ~27 ~66 ~85 stone
fill ~26 ~67 ~85 ~27 ~69 ~85 dirt
fill ~26 ~70 ~85 ~27 ~70 ~85 grass_block
fill ~28 ~60 ~85 ~31 ~67 ~85 stone
fill ~28 ~68 ~85 ~31 ~70 ~85 dirt
fill ~28 ~71 ~85 ~31 ~71 ~85 grass_block
fill ~16 ~60 ~86 ~17 ~63 ~86 stone
fill ~16 ~64 ~86 ~17 ~66 ~86 dirt
fill ~16 ~67 ~86 ~17 ~67 ~86 grass_block
fill ~18 ~60 ~86 ~23 ~64 ~86 stone
fill ~18 ~65 ~86 ~23 ~67 ~86 dirt
fill ~18 ~68 ~86 ~23 ~68 ~86 grass_block
fill ~24 ~60 ~86 ~25 ~65 ~86 stone
fill ~24 ~66 ~86 ~25 ~68 ~86 dirt
fill ~24 ~69 ~86 ~25 ~69 ~86 grass_block
fill ~26 ~60 ~86 ~27 ~66 ~86 stone
fill ~26 ~67 ~86 ~27 ~69 ~86 dirt
fill ~26 ~70 ~86 ~27 ~70 ~86 grass_block
fill ~28 ~60 ~86 ~30 ~67 ~86 stone
fill ~28 ~68 ~86 ~30 ~70 ~86 dirt
fill ~28 ~71 ~86 ~30 ~71 ~86 grass_block
fill ~31 ~60 ~86 ~31 ~66 ~86 stone
fill ~31 ~67 ~86 ~31 ~69 ~86 dirt
fill ~31 ~70 ~86 ~31 ~70 ~86 grass_block
fill ~16 ~60 ~87 ~17 ~63 ~87 stone
fill ~16 ~64 ~87 ~17 ~66 ~87 dirt
fill ~16 ~67 ~87 ~17 ~67 ~87 grass_block
fill ~18 ~60 ~87 ~23 ~64 ~87 stone
fill ~18 ~65 ~87 ~23 ~67 ~87 dirt
fill ~18 ~68 ~87 ~23 ~68 ~87 grass_block
fill ~24 ~60 ~87 ~26 ~65 ~87 stone
fill ~24 ~66 ~87 ~26 ~68 ~87 dirt
fill ~24 ~69 ~87 ~26 ~69 ~87 grass_block
fill ~27 ~60 ~87 ~28 ~66 ~87 stone
fill ~27 ~67 ~87 ~28 ~69 ~87 dirt
fill ~27 ~70 ~87 ~28 ~70 ~87 grass_block
fill ~29 ~60 ~87 ~29 ~67 ~87 stone
fill ~29 ~68 ~87 ~29 ~70 ~87 dirt
fill ~29 ~71 ~87 ~29 ~71 ~87 grass_block
fill ~30 ~60 ~87 ~31 ~66 ~87 stone
fill ~30 ~67 ~87 ~31 ~69 ~87 dirt
fill ~30 ~70 ~87 ~31 ~70 ~87 grass_block
fill ~16 ~60 ~88 ~18 ~63 ~88 stone
fill ~16 ~64 ~88 ~18 ~66 ~88 dirt
fill ~16 ~67 ~88 ~18 ~67 ~88 grass_block
fill ~19 ~60 ~88 ~24 ~64 ~88 stone
fill ~19 ~65 ~88 ~24 ~67 ~88 dirt
fill ~19 ~68 ~88 ~24 ~68 ~88 grass_block
fill ~25 ~60 ~88 ~27 ~65 ~88 stone
fill ~25 ~66 ~88 ~27 ~68 ~88 dirt
fill ~25 ~69 ~88 ~27 ~69 ~88 grass_block
fill ~28 ~60 ~88 ~31 ~66 ~88 stone
fill ~28 ~67 ~88 ~31 ~69 ~88 dirt
fill ~28 ~70 ~88 ~31 ~70 ~88 grass_block
fill ~16 ~60 ~89 ~21 ~63 ~89 stone
fill ~16 ~64 ~89 ~21 ~66 ~89 dirt
fill ~16 ~67 ~89 ~21 ~67 ~89 grass_block
fill ~22 ~60 ~89 ~25 ~64 ~89 stone
fill ~22 ~65 ~89 ~25 ~67 ~89 dirt
fill ~22 ~68 ~89 ~25 ~68 ~89 grass_block
fill ~26 ~60 ~89 ~28 ~65 ~89 stone
fill ~26 ~66 ~89 ~28 ~68 ~89 dirt
fill ~26 ~69 ~89 ~28 ~69 ~89 grass_block
fill ~29 ~60 ~89 ~31 ~66 ~89 stone
fill ~29 ~67 ~89 ~31 ~69 ~89 dirt
fill ~29 ~70 ~89 ~31 ~70 ~89 grass_block
fill ~16 ~60 ~90 ~23 ~63 ~90 stone
fill ~16 ~64 ~90 ~23 ~66 ~90 dirt
fill ~16 ~67 ~90 ~23 ~67 ~90 grass_block
fill ~24 ~60 ~90 ~27 ~64 ~90 stone
fill ~24 ~65 ~90 ~27 ~67 ~90 dirt
fill ~24 ~68 ~90 ~27 ~68 ~90 grass_block
fill ~28 ~60 ~90 ~29 ~65 ~90 stone
fill ~28 ~66 ~90 ~29 ~68 ~90 dirt
fill ~28 ~69 ~90 ~29 ~69 ~90 grass_block
fill ~30 ~60 ~90 ~31 ~66 ~90 stone
fill ~30 ~67 ~90 ~31 ~69 ~90 dirt
fill ~30 ~70 ~90 ~31 ~70 ~90 grass_block
fill ~16 ~60 ~91 ~25 ~63 ~91 stone
fill ~16 ~64 ~91 ~25 ~66 ~91 dirt
fill ~16 ~67 ~91 ~25 ~67 ~91 grass_block
fill ~26 ~60 ~91 ~28 ~64 ~91 stone
fill ~26 ~65 ~91 ~28 ~67 ~91 dirt
fill ~26 ~68 ~91 ~28 ~68 ~91 grass_block
fill ~29 ~60 ~91 ~31 ~65 ~91 stone
fill ~29 ~66 ~91 ~31 ~68 ~91 dirt
fill ~29 ~69 ~91 ~31 ~69 ~91 grass_block
fill ~16 ~60 ~92 ~27 ~63 ~92 stone
fill ~16 ~64 ~92 ~27 ~66 ~92 dirt
fill ~16 ~67 ~92 ~27 ~67 ~92 grass_block
fill ~28 ~60 ~92 ~29 ~64 ~92 stone
fill ~28 ~65 ~92 ~29 ~67 ~92 dirt
fill ~28 ~68 ~92 ~29 ~68 ~92 grass_block
fill ~30 ~60 ~92 ~31 ~65 ~92 stone
fill ~30 ~66 ~92 ~31 ~68 ~92 dirt
fill ~30 ~69 ~92 ~31 ~69 ~92 grass_block
fill ~16 ~60 ~93 ~16 ~64 ~93 stone
fill ~16 ~65 ~93 ~16 ~67 ~93 dirt
fill ~16 ~68 ~93 ~16 ~68 ~93 grass_block
fill ~17 ~60 ~93 ~28 ~63 ~93 stone
fill ~17 ~64 ~93 ~28 ~66 ~93 dirt
fill ~17 ~67 ~93 ~28 ~67 ~93 grass_block
fill ~29 ~60 ~93 ~31 ~64 ~93 stone
fill ~29 ~65 ~93 ~31 ~67 ~93 dirt
fill ~29 ~68 ~93 ~31 ~68 ~93 grass_block
fill ~16 ~60 ~94 ~19 ~64 ~94 stone
fill ~16 ~65 ~94 ~19 ~67 ~94 dirt
fill ~16 ~68 ~94 ~19 ~68 ~94 grass_block
fill ~20 ~60 ~94 ~28 ~63 ~94 stone
fill ~20 ~64 ~94 ~28 ~66 ~94 dirt
fill ~20 ~67 ~94 ~28 ~67 ~94 grass_block
fill ~29 ~60 ~94 ~31 ~64 ~94 stone
fill ~29 ~65 ~94 ~31 ~67 ~94 dirt
fill ~29 ~68 ~94 ~31 ~68 ~94 grass_block
fill ~16 ~60 ~95 ~20 ~64 ~95 stone
fill ~16 ~65 ~95 ~20 ~67 ~95 dirt
fill ~16 ~68 ~95 ~20 ~68 ~95 grass_block
fill ~21 ~60 ~95 ~31 ~63 ~95 stone
fill ~21 ~64 ~95 ~31 ~66 ~95 dirt
fill ~21 ~67 ~95 ~31 ~67 ~95 grass_block