fill ~464 ~60 ~64 ~469 ~65 ~64 stone
fill ~464 ~66 ~64 ~469 ~68 ~64 dirt
fill ~464 ~69 ~64 ~469 ~69 ~64 grass_block
fill ~464 ~60 ~65 ~469 ~65 ~65 stone
fill ~464 ~66 ~65 ~469 ~68 ~65 dirt
fill ~464 ~69 ~65 ~469 ~69 ~65 grass_block
fill ~464 ~60 ~66 ~469 ~65 ~66 stone
fill ~464 ~66 ~66 ~469 ~68 ~66 dirt
fill ~464 ~69 ~66 ~469 ~69 ~66 grass_block
fill ~464 ~60 ~67 ~469 ~65 ~67 stone
fill ~464 ~66 ~67 ~469 ~68 ~67 dirt
fill ~464 ~69 ~67 ~469 ~69 ~67 grass_block
fill ~464 ~60 ~68 ~465 ~65 ~68 stone
fill ~464 ~66 ~68 ~465 ~68 ~68 dirt
fill ~464 ~69 ~68 ~465 ~69 ~68 grass_block
fill ~466 ~60 ~68 ~468 ~64 ~68 stone
fill ~466 ~65 ~68 ~468 ~67 ~68 dirt
fill ~466 ~68 ~68 ~468 ~68 ~68 grass_block
fill ~469 ~60 ~68 ~469 ~65 ~68 stone
fill ~469 ~66 ~68 ~469 ~68 ~68 dirt
fill ~469 ~69 ~68 ~469 ~69 ~68 grass_block
fill ~464 ~60 ~69 ~465 ~65 ~69 stone
fill ~464 ~66 ~69 ~465 ~68 ~69 dirt
fill ~464 ~69 ~69 ~465 ~69 ~69 grass_block
fill ~466 ~60 ~69 ~469 ~64 ~69 stone
fill ~466 ~65 ~69 ~469 ~67 ~69 dirt
fill ~466 ~68 ~69 ~469 ~68 ~69 grass_block
fill ~464 ~60 ~70 ~465 ~65 ~70 stone
fill ~464 ~66 ~70 ~465 ~68 ~70 dirt
fill ~464 ~69 ~70 ~465 ~69 ~70 grass_block
fill ~466 ~60 ~70 ~469 ~64 ~70 stone
fill ~466 ~65 ~70 ~469 ~67 ~70 dirt
fill ~466 ~68 ~70 ~469 ~68 ~70 grass_block
fill ~464 ~60 ~71 ~464 ~65 ~71 stone
fill ~464 ~66 ~71 ~464 ~68 ~71 dirt
fill ~464 ~69 ~71 ~464 ~69 ~71 grass_block
fill ~465 ~60 ~71 ~469 ~64 ~71 stone
fill ~465 ~65 ~71 ~469 ~67 ~71 dirt
fill ~465 ~68 ~71 ~469 ~68 ~71 grass_block
fill ~464 ~60 ~72 ~464 ~65 ~72 stone
fill ~464 ~66 ~72 ~464 ~68 ~72 dirt
fill ~464 ~69 ~72 ~464 ~69 ~72 grass_block
fill ~465 ~60 ~72 ~469 ~64 ~72 stone
fill ~465 ~65 ~72 ~469 ~67 ~72 dirt
fill ~465 ~68 ~72 ~469 ~68 ~72 grass_block
fill ~464 ~60 ~73 ~469 ~64 ~73 stone
fill ~464 ~65 ~73 ~469 ~67 ~73 dirt
fill ~464 ~68 ~73 ~469 ~68 ~73 grass_block
fill ~464 ~60 ~74 ~469 ~64 ~74 stone
fill ~464 ~65 ~74 ~469 ~67 ~74 dirt
fill ~464 ~68 ~74 ~469 ~68 ~74 grass_block
fill ~464 ~60 ~75 ~468 ~64 ~75 stone
fill ~464 ~65 ~75 ~468 ~67 ~75 dirt
fill ~464 ~68 ~75 ~468 ~68 ~75 grass_block
fill ~469 ~60 ~75 ~469 ~63 ~75 stone
fill ~469 ~64 ~75 ~469 ~66 ~75 dirt
fill ~469 ~67 ~75 ~469 ~67 ~75 grass_block
fill ~464 ~60 ~76 ~468 ~64 ~76 stone
fill ~464 ~65 ~76 ~468 ~67 ~76 dirt
fill ~464 ~68 ~76 ~468 ~68 ~76 grass_block
fill ~469 ~60 ~76 ~469 ~63 ~76 stone
fill ~469 ~64 ~76 ~469 ~66 ~76 dirt
fill ~469 ~67 ~76 ~469 ~67 ~76 grass_block
fill ~464 ~60 ~77 ~467 ~64 ~77 stone
fill ~464 ~65 ~77 ~467 ~67 ~77 dirt
fill ~464 ~68 ~77 ~467 ~68 ~77 grass_block
fill ~468 ~60 ~77 ~469 ~63 ~77 stone
fill ~468 ~64 ~77 ~469 ~66 ~77 dirt
fill ~468 ~67 ~77 ~469 ~67 ~77 grass_block
fill ~464 ~60 ~78 ~467 ~64 ~78 stone
fill ~464 ~65 ~78 ~467 ~67 ~78 dirt
fill ~464 ~68 ~78 ~467 ~68 ~78 grass_block
fill ~468 ~60 ~78 ~469 ~63 ~78 stone
fill ~468 ~64 ~78 ~469 ~66 ~78 dirt
fill ~468 ~67 ~78 ~469 ~67 ~78 grass_block
fill ~464 ~60 ~79 ~464 ~63 ~79 stone
fill ~464 ~64 ~79 ~464 ~66 ~79 dirt
fill ~464 ~67 ~79 ~464 ~67 ~79 grass_block
fill ~465 ~60 ~79 ~466 ~64 ~79 stone
fill ~465 ~65 ~79 ~466 ~67 ~79 dirt
fill ~465 ~68 ~79 ~466 ~68 ~79 grass_block
fill ~467 ~60 ~79 ~469 ~63 ~79 stone
fill ~467 ~64 ~79 ~469 ~66 ~79 dirt
fill ~467 ~67 ~79 ~469 ~67 ~79 grass_block