fill ~288 ~60 ~16 ~288 ~63 ~16 stone
fill ~288 ~64 ~16 ~288 ~66 ~16 dirt
fill ~288 ~67 ~16 ~288 ~67 ~16 grass_block
fill ~289 ~60 ~16 ~293 ~64 ~16 stone
fill ~289 ~65 ~16 ~293 ~67 ~16 dirt
fill ~289 ~68 ~16 ~293 ~68 ~16 grass_block
fill ~294 ~60 ~16 ~298 ~63 ~16 stone
fill ~294 ~64 ~16 ~298 ~66 ~16 dirt
fill ~294 ~67 ~16 ~298 ~67 ~16 grass_block
fill ~299 ~60 ~16 ~303 ~64 ~16 stone
fill ~299 ~65 ~16 ~303 ~67 ~16 dirt
fill ~299 ~68 ~16 ~303 ~68 ~16 grass_block
fill ~288 ~60 ~17 ~288 ~63 ~17 stone
fill ~288 ~64 ~17 ~288 ~66 ~17 dirt
fill ~288 ~67 ~17 ~288 ~67 ~17 grass_block
fill ~289 ~60 ~17 ~294 ~64 ~17 stone
fill ~289 ~65 ~17 ~294 ~67 ~17 dirt
fill ~289 ~68 ~17 ~294 ~68 ~17 grass_block
fill ~295 ~60 ~17 ~298 ~63 ~17 stone
fill ~295 ~64 ~17 ~298 ~66 ~17 dirt
fill ~295 ~67 ~17 ~298 ~67 ~17 grass_block
fill ~299 ~60 ~17 ~303 ~64 ~17 stone
fill ~299 ~65 ~17 ~303 ~67 ~17 dirt
fill ~299 ~68 ~17 ~303 ~68 ~17 grass_block
fill ~288 ~60 ~18 ~288 ~63 ~18 stone
fill ~288 ~64 ~18 ~288 ~66 ~18 dirt
fill ~288 ~67 ~18 ~288 ~67 ~18 grass_block
fill ~289 ~60 ~18 ~292 ~64 ~18 stone
fill ~289 ~65 ~18 ~292 ~67 ~18 dirt
fill ~289 ~68 ~18 ~292 ~68 ~18 grass_block
fill ~293 ~60 ~18 ~298 ~63 ~18 stone
fill ~293 ~64 ~18 ~298 ~66 ~18 dirt
fill ~293 ~67 ~18 ~298 ~67 ~18 grass_block
fill ~299 ~60 ~18 ~303 ~64 ~18 stone
fill ~299 ~65 ~18 ~303 ~67 ~18 dirt
fill ~299 ~68 ~18 ~303 ~68 ~18 grass_block
fill ~288 ~60 ~19 ~288 ~63 ~19 stone
fill ~288 ~64 ~19 ~288 ~66 ~19 dirt
fill ~288 ~67 ~19 ~288 ~67 ~19 grass_block
fill ~289 ~60 ~19 ~292 ~64 ~19 stone
fill ~289 ~65 ~19 ~292 ~67 ~19 dirt
fill ~289 ~68 ~19 ~292 ~68 ~19 grass_block
fill ~293 ~60 ~19 ~298 ~63 ~19 stone
fill ~293 ~64 ~19 ~298 ~66 ~19 dirt
fill ~293 ~67 ~19 ~298 ~67 ~19 grass_block
fill ~299 ~60 ~19 ~302 ~64 ~19 stone
fill ~299 ~65 ~19 ~302 ~67 ~19 dirt
fill ~299 ~68 ~19 ~302 ~68 ~19 grass_block
fill ~303 ~60 ~19 ~303 ~65 ~19 stone
fill ~303 ~66 ~19 ~303 ~68 ~19 dirt
fill ~303 ~69 ~19 ~303 ~69 ~19 grass_block
fill ~288 ~60 ~20 ~288 ~63 ~20 stone
fill ~288 ~64 ~20 ~288 ~66 ~20 dirt
fill ~288 ~67 ~20 ~288 ~67 ~20 grass_block
fill ~289 ~60 ~20 ~291 ~64 ~20 stone
fill ~289 ~65 ~20 ~291 ~67 ~20 dirt
fill ~289 ~68 ~20 ~291 ~68 ~20 grass_block
fill ~292 ~60 ~20 ~298 ~63 ~20 stone
fill ~292 ~64 ~20 ~298 ~66 ~20 dirt
fill ~292 ~67 ~20 ~298 ~67 ~20 grass_block
fill ~299 ~60 ~20 ~302 ~64 ~20 stone
fill ~299 ~65 ~20 ~302 ~67 ~20 dirt
fill ~299 ~68 ~20 ~302 ~68 ~20 grass_block
fill ~303 ~60 ~20 ~303 ~65 ~20 stone
fill ~303 ~66 ~20 ~303 ~68 ~20 dirt
fill ~303 ~69 ~20 ~303 ~69 ~20 grass_block
fill ~288 ~60 ~21 ~291 ~64 ~21 stone
fill ~288 ~65 ~21 ~291 ~67 ~21 dirt
fill ~288 ~68 ~21 ~291 ~68 ~21 grass_block
fill ~292 ~60 ~21 ~298 ~63 ~21 stone
fill ~292 ~64 ~21 ~298 ~66 ~21 dirt
fill ~292 ~67 ~21 ~298 ~67 ~21 grass_block
fill ~299 ~60 ~21 ~302 ~64 ~21 stone
fill ~299 ~65 ~21 ~302 ~67 ~21 dirt
fill ~299 ~68 ~21 ~302 ~68 ~21 grass_block
fill ~303 ~60 ~21 ~303 ~65 ~21 stone
fill ~303 ~66 ~21 ~303 ~68 ~21 dirt
fill ~303 ~69 ~21 ~303 ~69 ~21 grass_block
fill ~288 ~60 ~22 ~291 ~64 ~22 stone
fill ~288 ~65 ~22 ~291 ~67 ~22 dirt
fill ~288 ~68 ~22 ~291 ~68 ~22 grass_block
fill ~292 ~60 ~22 ~298 ~63 ~22 stone
fill ~292 ~64 ~22 ~298 ~66 ~22 dirt
fill ~292 ~67 ~22 ~298 ~67 ~22 grass_block
fill ~299 ~60 ~22 ~303 ~64 ~22 stone
fill ~299 ~65 ~22 ~303 ~67 ~22 dirt
fill ~299 ~68 ~22 ~303 ~68 ~22 grass_block
fill ~288 ~60 ~23 ~290 ~64 ~23 stone
fill ~288 ~65 ~23 ~290 ~67 ~23 dirt
fill ~288 ~68 ~23 ~290 ~68 ~23 grass_block
fill ~291 ~60 ~23 ~302 ~63 ~23 stone
fill ~291 ~64 ~23 ~302 ~66 ~23 dirt
fill ~291 ~67 ~23 ~302 ~67 ~23 grass_block
fill ~303 ~60 ~23 ~303 ~64 ~23 stone
fill ~303 ~65 ~23 ~303 ~67 ~23 dirt
fill ~303 ~68 ~23 ~303 ~68 ~23 grass_block
fill ~288 ~60 ~24 ~290 ~64 ~24 stone
fill ~288 ~65 ~24 ~290 ~67 ~24 dirt
fill ~288 ~68 ~24 ~290 ~68 ~24 grass_block
fill ~291 ~60 ~24 ~301 ~63 ~24 stone
fill ~291 ~64 ~24 ~301 ~66 ~24 dirt
fill ~291 ~67 ~24 ~301 ~67 ~24 grass_block
fill ~302 ~60 ~24 ~303 ~64 ~24 stone
fill ~302 ~65 ~24 ~303 ~67 ~24 dirt
fill ~302 ~68 ~24 ~303 ~68 ~24 grass_block
fill ~288 ~60 ~25 ~290 ~64 ~25 stone
fill ~288 ~65 ~25 ~290 ~67 ~25 dirt
fill ~288 ~68 ~25 ~290 ~68 ~25 grass_block
fill ~291 ~60 ~25 ~295 ~63 ~25 stone
fill ~291 ~64 ~25 ~295 ~66 ~25 dirt
fill ~291 ~67 ~25 ~295 ~67 ~25 grass_block
fill ~296 ~60 ~25 ~296 ~62 ~25 stone
fill ~296 ~63 ~25 ~296 ~65 ~25 dirt
fill ~296 ~66 ~25 ~296 ~66 ~25 grass_block
fill ~297 ~60 ~25 ~298 ~63 ~25 stone
fill ~297 ~64 ~25 ~298 ~66 ~25 dirt
fill ~297 ~67 ~25 ~298 ~67 ~25 grass_block
fill ~299 ~60 ~25 ~303 ~64 ~25 stone
fill ~299 ~65 ~25 ~303 ~67 ~25 dirt
fill ~299 ~68 ~25 ~303 ~68 ~25 grass_block
fill ~288 ~60 ~26 ~289 ~64 ~26 stone
fill ~288 ~65 ~26 ~289 ~67 ~26 dirt
fill ~288 ~68 ~26 ~289 ~68 ~26 grass_block
fill ~290 ~60 ~26 ~298 ~63 ~26 stone
fill ~290 ~64 ~26 ~298 ~66 ~26 dirt
fill ~290 ~67 ~26 ~298 ~67 ~26 grass_block
fill ~299 ~60 ~26 ~303 ~64 ~26 stone
fill ~299 ~65 ~26 ~303 ~67 ~26 dirt
fill ~299 ~68 ~26 ~303 ~68 ~26 grass_block
fill ~288 ~60 ~27 ~288 ~63 ~27 stone
fill ~288 ~64 ~27 ~288 ~66 ~27 dirt
fill ~288 ~67 ~27 ~288 ~67 ~27 grass_block
fill ~289 ~60 ~27 ~289 ~64 ~27 stone
fill ~289 ~65 ~27 ~289 ~67 ~27 dirt
fill ~289 ~68 ~27 ~289 ~68 ~27 grass_block
fill ~290 ~60 ~27 ~298 ~63 ~27 stone
fill ~290 ~64 ~27 ~298 ~66 ~27 dirt
fill ~290 ~67 ~27 ~298 ~67 ~27 grass_block
fill ~299 ~60 ~27 ~302 ~64 ~27 stone
fill ~299 ~65 ~27 ~302 ~67 ~27 dirt
fill ~299 ~68 ~27 ~302 ~68 ~27 grass_block
fill ~303 ~60 ~27 ~303 ~65 ~27 stone
fill ~303 ~66 ~27 ~303 ~68 ~27 dirt
fill ~303 ~69 ~27 ~303 ~69 ~27 grass_block
fill ~288 ~60 ~28 ~295 ~63 ~28 stone
fill ~288 ~64 ~28 ~295 ~66 ~28 dirt
fill ~288 ~67 ~28 ~295 ~67 ~28 grass_block
fill ~296 ~60 ~28 ~296 ~62 ~28 stone
fill ~296 ~63 ~28 ~296 ~65 ~28 dirt
fill ~296 ~66 ~28 ~296 ~66 ~28 grass_block
fill ~297 ~60 ~28 ~298 ~63 ~28 stone
fill ~297 ~64 ~28 ~298 ~66 ~28 dirt
fill ~297 ~67 ~28 ~298 ~67 ~28 grass_block
fill ~299 ~60 ~28 ~303 ~64 ~28 stone
fill ~299 ~65 ~28 ~303 ~67 ~28 dirt
fill ~299 ~68 ~28 ~303 ~68 ~28 grass_block
fill ~288 ~60 ~29 ~294 ~63 ~29 stone
fill ~288 ~64 ~29 ~294 ~66 ~29 dirt
fill ~288 ~67 ~29 ~294 ~67 ~29 grass_block
fill ~295 ~60 ~29 ~297 ~62 ~29 stone
fill ~295 ~63 ~29 ~297 ~65 ~29 dirt
fill ~295 ~66 ~29 ~297 ~66 ~29 grass_block
fill ~298 ~60 ~29 ~300 ~63 ~29 stone
fill ~298 ~64 ~29 ~300 ~66 ~29 dirt
fill ~298 ~67 ~29 ~300 ~67 ~29 grass_block
fill ~301 ~60 ~29 ~303 ~64 ~29 stone
fill ~301 ~65 ~29 ~303 ~67 ~29 dirt
fill ~301 ~68 ~29 ~303 ~68 ~29 grass_block
fill ~288 ~60 ~30 ~295 ~63 ~30 stone
fill ~288 ~64 ~30 ~295 ~66 ~30 dirt
fill ~288 ~67 ~30 ~295 ~67 ~30 grass_block
fill ~296 ~60 ~30 ~296 ~62 ~30 stone
fill ~296 ~63 ~30 ~296 ~65 ~30 dirt
fill ~296 ~66 ~30 ~296 ~66 ~30 grass_block
fill ~297 ~60 ~30 ~301 ~63 ~30 stone
fill ~297 ~64 ~30 ~301 ~66 ~30 dirt
fill ~297 ~67 ~30 ~301 ~67 ~30 grass_block
fill ~302 ~60 ~30 ~303 ~64 ~30 stone
fill ~302 ~65 ~30 ~303 ~67 ~30 dirt
fill ~302 ~68 ~30 ~303 ~68 ~30 grass_block
fill ~288 ~60 ~31 ~293 ~63 ~31 stone
fill ~288 ~64 ~31 ~293 ~66 ~31 dirt
fill ~288 ~67 ~31 ~293 ~67 ~31 grass_block
fill ~294 ~60 ~31 ~295 ~62 ~31 stone
fill ~294 ~63 ~31 ~295 ~65 ~31 dirt
fill ~294 ~66 ~31 ~295 ~66 ~31 grass_block
fill ~296 ~60 ~31 ~297 ~63 ~31 stone
fill ~296 ~64 ~31 ~297 ~66 ~31 dirt
fill ~296 ~67 ~31 ~297 ~67 ~31 grass_block
fill ~298 ~60 ~31 ~299 ~64 ~31 stone
fill ~298 ~65 ~31 ~299 ~67 ~31 dirt
fill ~298 ~68 ~31 ~299 ~68 ~31 grass_block
fill ~300 ~60 ~31 ~301 ~63 ~31 stone
fill ~300 ~64 ~31 ~301 ~66 ~31 dirt
fill ~300 ~67 ~31 ~301 ~67 ~31 grass_block
fill ~302 ~60 ~31 ~303 ~64 ~31 stone
fill ~302 ~65 ~31 ~303 ~67 ~31 dirt
fill ~302 ~68 ~31 ~303 ~68 ~31 grass_block