fill ~176 ~60 ~64 ~177 ~66 ~64 stone
fill ~176 ~67 ~64 ~177 ~69 ~64 dirt
fill ~176 ~70 ~64 ~177 ~70 ~64 grass_block
fill ~178 ~60 ~64 ~187 ~67 ~64 stone
fill ~178 ~68 ~64 ~187 ~70 ~64 dirt
fill ~178 ~71 ~64 ~187 ~71 ~64 grass_block
fill ~188 ~60 ~64 ~191 ~66 ~64 stone
fill ~188 ~67 ~64 ~191 ~69 ~64 dirt
fill ~188 ~70 ~64 ~191 ~70 ~64 grass_block
fill ~176 ~60 ~65 ~180 ~66 ~65 stone
fill ~176 ~67 ~65 ~180 ~69 ~65 dirt
fill ~176 ~70 ~65 ~180 ~70 ~65 grass_block
fill ~181 ~60 ~65 ~186 ~67 ~65 stone
fill ~181 ~68 ~65 ~186 ~70 ~65 dirt
fill ~181 ~71 ~65 ~186 ~71 ~65 grass_block
fill ~187 ~60 ~65 ~191 ~66 ~65 stone
fill ~187 ~67 ~65 ~191 ~69 ~65 dirt
fill ~187 ~70 ~65 ~191 ~70 ~65 grass_block
fill ~176 ~60 ~66 ~191 ~66 ~66 stone
fill ~176 ~67 ~66 ~191 ~69 ~66 dirt
fill ~176 ~70 ~66 ~191 ~70 ~66 grass_block
fill ~176 ~60 ~67 ~176 ~65 ~67 stone
fill ~176 ~66 ~67 ~176 ~68 ~67 dirt
fill ~176 ~69 ~67 ~176 ~69 ~67 grass_block
fill ~177 ~60 ~67 ~191 ~66 ~67 stone
fill ~177 ~67 ~67 ~191 ~69 ~67 dirt
fill ~177 ~70 ~67 ~191 ~70 ~67 grass_block
fill ~176 ~60 ~68 ~178 ~65 ~68 stone
fill ~176 ~66 ~68 ~178 ~68 ~68 dirt
fill ~176 ~69 ~68 ~178 ~69 ~68 grass_block
fill ~179 ~60 ~68 ~191 ~66 ~68 stone
fill ~179 ~67 ~68 ~191 ~69 ~68 dirt
fill ~179 ~70 ~68 ~191 ~70 ~68 grass_block
fill ~176 ~60 ~69 ~182 ~65 ~69 stone
fill ~176 ~66 ~69 ~182 ~68 ~69 dirt
fill ~176 ~69 ~69 ~182 ~69 ~69 grass_block
fill ~183 ~60 ~69 ~183 ~66 ~69 stone
fill ~183 ~67 ~69 ~183 ~69 ~69 dirt
fill ~183 ~70 ~69 ~183 ~70 ~69 grass_block
fill ~184 ~60 ~69 ~188 ~65 ~69 stone
fill ~184 ~66 ~69 ~188 ~68 ~69 dirt
fill ~184 ~69 ~69 ~188 ~69 ~69 grass_block
fill ~189 ~60 ~69 ~190 ~66 ~69 stone
fill ~189 ~67 ~69 ~190 ~69 ~69 dirt
fill ~189 ~70 ~69 ~190 ~70 ~69 grass_block
fill ~191 ~60 ~69 ~191 ~67 ~69 stone
fill ~191 ~68 ~69 ~191 ~70 ~69 dirt
fill ~191 ~71 ~69 ~191 ~71 ~69 grass_block
fill ~176 ~60 ~70 ~177 ~65 ~70 stone
fill ~176 ~66 ~70 ~177 ~68 ~70 dirt
fill ~176 ~69 ~70 ~177 ~69 ~70 grass_block
fill ~178 ~60 ~70 ~178 ~64 ~70 stone
fill ~178 ~65 ~70 ~178 ~67 ~70 dirt
fill ~178 ~68 ~70 ~178 ~68 ~70 grass_block
fill ~179 ~60 ~70 ~189 ~65 ~70 stone
fill ~179 ~66 ~70 ~189 ~68 ~70 dirt
fill ~179 ~69 ~70 ~189 ~69 ~70 grass_block
fill ~190 ~60 ~70 ~191 ~66 ~70 stone
fill ~190 ~67 ~70 ~191 ~69 ~70 dirt
fill ~190 ~70 ~70 ~191 ~70 ~70 grass_block
fill ~176 ~60 ~71 ~177 ~65 ~71 stone
fill ~176 ~66 ~71 ~177 ~68 ~71 dirt
fill ~176 ~69 ~71 ~177 ~69 ~71 grass_block
fill ~178 ~60 ~71 ~179 ~64 ~71 stone
fill ~178 ~65 ~71 ~179 ~67 ~71 dirt
fill ~178 ~68 ~71 ~179 ~68 ~71 grass_block
fill ~180 ~60 ~71 ~184 ~65 ~71 stone
fill ~180 ~66 ~71 ~184 ~68 ~71 dirt
fill ~180 ~69 ~71 ~184 ~69 ~71 grass_block
fill ~185 ~60 ~71 ~188 ~64 ~71 stone
fill ~185 ~65 ~71 ~188 ~67 ~71 dirt
fill ~185 ~68 ~71 ~188 ~68 ~71 grass_block
fill ~189 ~60 ~71 ~190 ~65 ~71 stone
fill ~189 ~66 ~71 ~190 ~68 ~71 dirt
fill ~189 ~69 ~71 ~190 ~69 ~71 grass_block
fill ~191 ~60 ~71 ~191 ~66 ~71 stone
fill ~191 ~67 ~71 ~191 ~69 ~71 dirt
fill ~191 ~70 ~71 ~191 ~70 ~71 grass_block
fill ~176 ~60 ~72 ~177 ~65 ~72 stone
fill ~176 ~66 ~72 ~177 ~68 ~72 dirt
fill ~176 ~69 ~72 ~177 ~69 ~72 grass_block
fill ~178 ~60 ~72 ~188 ~64 ~72 stone
fill ~178 ~65 ~72 ~188 ~67 ~72 dirt
fill ~178 ~68 ~72 ~188 ~68 ~72 grass_block
fill ~189 ~60 ~72 ~191 ~65 ~72 stone
fill ~189 ~66 ~72 ~191 ~68 ~72 dirt
fill ~189 ~69 ~72 ~191 ~69 ~72 grass_block
fill ~176 ~60 ~73 ~177 ~65 ~73 stone
fill ~176 ~66 ~73 ~177 ~68 ~73 dirt
fill ~176 ~69 ~73 ~177 ~69 ~73 grass_block
fill ~178 ~60 ~73 ~188 ~64 ~73 stone
fill ~178 ~65 ~73 ~188 ~67 ~73 dirt
fill ~178 ~68 ~73 ~188 ~68 ~73 grass_block
fill ~189 ~60 ~73 ~190 ~65 ~73 stone
fill ~189 ~66 ~73 ~190 ~68 ~73 dirt
fill ~189 ~69 ~73 ~190 ~69 ~73 grass_block
fill ~191 ~60 ~73 ~191 ~66 ~73 stone
fill ~191 ~67 ~73 ~191 ~69 ~73 dirt
fill ~191 ~70 ~73 ~191 ~70 ~73 grass_block
fill ~176 ~60 ~74 ~178 ~65 ~74 stone
fill ~176 ~66 ~74 ~178 ~68 ~74 dirt
fill ~176 ~69 ~74 ~178 ~69 ~74 grass_block
fill ~179 ~60 ~74 ~183 ~64 ~74 stone
fill ~179 ~65 ~74 ~183 ~67 ~74 dirt
fill ~179 ~68 ~74 ~183 ~68 ~74 grass_block
fill ~184 ~60 ~74 ~185 ~63 ~74 stone
fill ~184 ~64 ~74 ~185 ~66 ~74 dirt
fill ~184 ~67 ~74 ~185 ~67 ~74 grass_block
fill ~186 ~60 ~74 ~188 ~64 ~74 stone
fill ~186 ~65 ~74 ~188 ~67 ~74 dirt
fill ~186 ~68 ~74 ~188 ~68 ~74 grass_block
fill ~189 ~60 ~74 ~190 ~65 ~74 stone
fill ~189 ~66 ~74 ~190 ~68 ~74 dirt
fill ~189 ~69 ~74 ~190 ~69 ~74 grass_block
fill ~191 ~60 ~74 ~191 ~66 ~74 stone
fill ~191 ~67 ~74 ~191 ~69 ~74 dirt
fill ~191 ~70 ~74 ~191 ~70 ~74 grass_block
fill ~176 ~60 ~75 ~177 ~65 ~75 stone
fill ~176 ~66 ~75 ~177 ~68 ~75 dirt
fill ~176 ~69 ~75 ~177 ~69 ~75 grass_block
fill ~178 ~60 ~75 ~180 ~64 ~75 stone
fill ~178 ~65 ~75 ~180 ~67 ~75 dirt
fill ~178 ~68 ~75 ~180 ~68 ~75 grass_block
fill ~181 ~60 ~75 ~184 ~63 ~75 stone
fill ~181 ~64 ~75 ~184 ~66 ~75 dirt
fill ~181 ~67 ~75 ~184 ~67 ~75 grass_block
fill ~185 ~60 ~75 ~187 ~64 ~75 stone
fill ~185 ~65 ~75 ~187 ~67 ~75 dirt
fill ~185 ~68 ~75 ~187 ~68 ~75 grass_block
fill ~188 ~60 ~75 ~189 ~65 ~75 stone
fill ~188 ~66 ~75 ~189 ~68 ~75 dirt
fill ~188 ~69 ~75 ~189 ~69 ~75 grass_block
fill ~190 ~60 ~75 ~191 ~66 ~75 stone
fill ~190 ~67 ~75 ~191 ~69 ~75 dirt
fill ~190 ~70 ~75 ~191 ~70 ~75 grass_block
fill ~176 ~60 ~76 ~176 ~64 ~76 stone
fill ~176 ~65 ~76 ~176 ~67 ~76 dirt
fill ~176 ~68 ~76 ~176 ~68 ~76 grass_block
fill ~177 ~60 ~76 ~177 ~65 ~76 stone
fill ~177 ~66 ~76 ~177 ~68 ~76 dirt
fill ~177 ~69 ~76 ~177 ~69 ~76 grass_block
fill ~178 ~60 ~76 ~180 ~64 ~76 stone
fill ~178 ~65 ~76 ~180 ~67 ~76 dirt
fill ~178 ~68 ~76 ~180 ~68 ~76 grass_block
fill ~181 ~60 ~76 ~184 ~63 ~76 stone
fill ~181 ~64 ~76 ~184 ~66 ~76 dirt
fill ~181 ~67 ~76 ~184 ~67 ~76 grass_block
fill ~185 ~60 ~76 ~186 ~64 ~76 stone
fill ~185 ~65 ~76 ~186 ~67 ~76 dirt
fill ~185 ~68 ~76 ~186 ~68 ~76 grass_block
fill ~187 ~60 ~76 ~189 ~65 ~76 stone
fill ~187 ~66 ~76 ~189 ~68 ~76 dirt
fill ~187 ~69 ~76 ~189 ~69 ~76 grass_block
fill ~190 ~60 ~76 ~191 ~66 ~76 stone
fill ~190 ~67 ~76 ~191 ~69 ~76 dirt
fill ~190 ~70 ~76 ~191 ~70 ~76 grass_block
fill ~176 ~60 ~77 ~181 ~64 ~77 stone
fill ~176 ~65 ~77 ~181 ~67 ~77 dirt
fill ~176 ~68 ~77 ~181 ~68 ~77 grass_block
fill ~182 ~60 ~77 ~183 ~63 ~77 stone
fill ~182 ~64 ~77 ~183 ~66 ~77 dirt
fill ~182 ~67 ~77 ~183 ~67 ~77 grass_block
fill ~184 ~60 ~77 ~186 ~64 ~77 stone
fill ~184 ~65 ~77 ~186 ~67 ~77 dirt
fill ~184 ~68 ~77 ~186 ~68 ~77 grass_block
fill ~187 ~60 ~77 ~190 ~65 ~77 stone
fill ~187 ~66 ~77 ~190 ~68 ~77 dirt
fill ~187 ~69 ~77 ~190 ~69 ~77 grass_block
fill ~191 ~60 ~77 ~191 ~66 ~77 stone
fill ~191 ~67 ~77 ~191 ~69 ~77 dirt
fill ~191 ~70 ~77 ~191 ~70 ~77 grass_block
fill ~176 ~60 ~78 ~180 ~64 ~78 stone
fill ~176 ~65 ~78 ~180 ~67 ~78 dirt
fill ~176 ~68 ~78 ~180 ~68 ~78 grass_block
fill ~181 ~60 ~78 ~183 ~63 ~78 stone
fill ~181 ~64 ~78 ~183 ~66 ~78 dirt
fill ~181 ~67 ~78 ~183 ~67 ~78 grass_block
fill ~184 ~60 ~78 ~185 ~64 ~78 stone
fill ~184 ~65 ~78 ~185 ~67 ~78 dirt
fill ~184 ~68 ~78 ~185 ~68 ~78 grass_block
fill ~186 ~60 ~78 ~190 ~65 ~78 stone
fill ~186 ~66 ~78 ~190 ~68 ~78 dirt
fill ~186 ~69 ~78 ~190 ~69 ~78 grass_block
fill ~191 ~60 ~78 ~191 ~66 ~78 stone
fill ~191 ~67 ~78 ~191 ~69 ~78 dirt
fill ~191 ~70 ~78 ~191 ~70 ~78 grass_block
fill ~176 ~60 ~79 ~180 ~64 ~79 stone
fill ~176 ~65 ~79 ~180 ~67 ~79 dirt
fill ~176 ~68 ~79 ~180 ~68 ~79 grass_block
fill ~181 ~60 ~79 ~184 ~63 ~79 stone
fill ~181 ~64 ~79 ~184 ~66 ~79 dirt
fill ~181 ~67 ~79 ~184 ~67 ~79 grass_block
fill ~185 ~60 ~79 ~185 ~64 ~79 stone
fill ~185 ~65 ~79 ~185 ~67 ~79 dirt
fill ~185 ~68 ~79 ~185 ~68 ~79 grass_block
fill ~186 ~60 ~79 ~191 ~65 ~79 stone
fill ~186 ~66 ~79 ~191 ~68 ~79 dirt
fill ~186 ~69 ~79 ~191 ~69 ~79 grass_block