fill ~64 ~60 ~112 ~65 ~64 ~112 stone
fill ~64 ~65 ~112 ~65 ~67 ~112 dirt
fill ~64 ~68 ~112 ~65 ~68 ~112 grass_block
fill ~66 ~60 ~112 ~68 ~65 ~112 stone
fill ~66 ~66 ~112 ~68 ~68 ~112 dirt
fill ~66 ~69 ~112 ~68 ~69 ~112 grass_block
fill ~69 ~60 ~112 ~71 ~66 ~112 stone
fill ~69 ~67 ~112 ~71 ~69 ~112 dirt
fill ~69 ~70 ~112 ~71 ~70 ~112 grass_block
fill ~72 ~60 ~112 ~79 ~67 ~112 stone
fill ~72 ~68 ~112 ~79 ~70 ~112 dirt
fill ~72 ~71 ~112 ~79 ~71 ~112 grass_block
fill ~64 ~60 ~113 ~66 ~64 ~113 stone
fill ~64 ~65 ~113 ~66 ~67 ~113 dirt
fill ~64 ~68 ~113 ~66 ~68 ~113 grass_block
fill ~67 ~60 ~113 ~68 ~65 ~113 stone
fill ~67 ~66 ~113 ~68 ~68 ~113 dirt
fill ~67 ~69 ~113 ~68 ~69 ~113 grass_block
fill ~69 ~60 ~113 ~72 ~66 ~113 stone
fill ~69 ~67 ~113 ~72 ~69 ~113 dirt
fill ~69 ~70 ~113 ~72 ~70 ~113 grass_block
fill ~73 ~60 ~113 ~79 ~67 ~113 stone
fill ~73 ~68 ~113 ~79 ~70 ~113 dirt
fill ~73 ~71 ~113 ~79 ~71 ~113 grass_block
fill ~64 ~60 ~114 ~66 ~64 ~114 stone
fill ~64 ~65 ~114 ~66 ~67 ~114 dirt
fill ~64 ~68 ~114 ~66 ~68 ~114 grass_block
fill ~67 ~60 ~114 ~69 ~65 ~114 stone
fill ~67 ~66 ~114 ~69 ~68 ~114 dirt
fill ~67 ~69 ~114 ~69 ~69 ~114 grass_block
fill ~70 ~60 ~114 ~73 ~66 ~114 stone
fill ~70 ~67 ~114 ~73 ~69 ~114 dirt
fill ~70 ~70 ~114 ~73 ~70 ~114 grass_block
fill ~74 ~60 ~114 ~79 ~67 ~114 stone
fill ~74 ~68 ~114 ~79 ~70 ~114 dirt
fill ~74 ~71 ~114 ~79 ~71 ~114 grass_block
fill ~64 ~60 ~115 ~67 ~64 ~115 stone
fill ~64 ~65 ~115 ~67 ~67 ~115 dirt
fill ~64 ~68 ~115 ~67 ~68 ~115 grass_block
fill ~68 ~60 ~115 ~70 ~65 ~115 stone
fill ~68 ~66 ~115 ~70 ~68 ~115 dirt
fill ~68 ~69 ~115 ~70 ~69 ~115 grass_block
fill ~71 ~60 ~115 ~76 ~66 ~115 stone
fill ~71 ~67 ~115 ~76 ~69 ~115 dirt
fill ~71 ~70 ~115 ~76 ~70 ~115 grass_block
fill ~77 ~60 ~115 ~79 ~67 ~115 stone
fill ~77 ~68 ~115 ~79 ~70 ~115 dirt
fill ~77 ~71 ~115 ~79 ~71 ~115 grass_block
fill ~64 ~60 ~116 ~68 ~64 ~116 stone
fill ~64 ~65 ~116 ~68 ~67 ~116 dirt
fill ~64 ~68 ~116 ~68 ~68 ~116 grass_block
fill ~69 ~60 ~116 ~71 ~65 ~116 stone
fill ~69 ~66 ~116 ~71 ~68 ~116 dirt
fill ~69 ~69 ~116 ~71 ~69 ~116 grass_block
fill ~72 ~60 ~116 ~79 ~66 ~116 stone
fill ~72 ~67 ~116 ~79 ~69 ~116 dirt
fill ~72 ~70 ~116 ~79 ~70 ~116 grass_block
fill ~64 ~60 ~117 ~66 ~63 ~117 stone
fill ~64 ~64 ~117 ~66 ~66 ~117 dirt
fill ~64 ~67 ~117 ~66 ~67 ~117 grass_block
fill ~67 ~60 ~117 ~70 ~64 ~117 stone
fill ~67 ~65 ~117 ~70 ~67 ~117 dirt
fill ~67 ~68 ~117 ~70 ~68 ~117 grass_block
fill ~71 ~60 ~117 ~75 ~65 ~117 stone
fill ~71 ~66 ~117 ~75 ~68 ~117 dirt
fill ~71 ~69 ~117 ~75 ~69 ~117 grass_block
fill ~76 ~60 ~117 ~76 ~66 ~117 stone
fill ~76 ~67 ~117 ~76 ~69 ~117 dirt
fill ~76 ~70 ~117 ~76 ~70 ~117 grass_block
fill ~77 ~60 ~117 ~79 ~65 ~117 stone
fill ~77 ~66 ~117 ~79 ~68 ~117 dirt
fill ~77 ~69 ~117 ~79 ~69 ~117 grass_block
fill ~64 ~60 ~118 ~68 ~63 ~118 stone
fill ~64 ~64 ~118 ~68 ~66 ~118 dirt
fill ~64 ~67 ~118 ~68 ~67 ~118 grass_block
fill ~69 ~60 ~118 ~71 ~64 ~118 stone
fill ~69 ~65 ~118 ~71 ~67 ~118 dirt
fill ~69 ~68 ~118 ~71 ~68 ~118 grass_block
fill ~72 ~60 ~118 ~79 ~65 ~118 stone
fill ~72 ~66 ~118 ~79 ~68 ~118 dirt
fill ~72 ~69 ~118 ~79 ~69 ~118 grass_block
fill ~64 ~60 ~119 ~70 ~63 ~119 stone
fill ~64 ~64 ~119 ~70 ~66 ~119 dirt
fill ~64 ~67 ~119 ~70 ~67 ~119 grass_block
fill ~71 ~60 ~119 ~72 ~64 ~119 stone
fill ~71 ~65 ~119 ~72 ~67 ~119 dirt
fill ~71 ~68 ~119 ~72 ~68 ~119 grass_block
fill ~73 ~60 ~119 ~75 ~65 ~119 stone
fill ~73 ~66 ~119 ~75 ~68 ~119 dirt
fill ~73 ~69 ~119 ~75 ~69 ~119 grass_block
fill ~76 ~60 ~119 ~77 ~64 ~119 stone
fill ~76 ~65 ~119 ~77 ~67 ~119 dirt
fill ~76 ~68 ~119 ~77 ~68 ~119 grass_block
fill ~78 ~60 ~119 ~79 ~65 ~119 stone
fill ~78 ~66 ~119 ~79 ~68 ~119 dirt
fill ~78 ~69 ~119 ~79 ~69 ~119 grass_block
fill ~64 ~60 ~120 ~70 ~63 ~120 stone
fill ~64 ~64 ~120 ~70 ~66 ~120 dirt
fill ~64 ~67 ~120 ~70 ~67 ~120 grass_block
fill ~71 ~60 ~120 ~79 ~64 ~120 stone
fill ~71 ~65 ~120 ~79 ~67 ~120 dirt
fill ~71 ~68 ~120 ~79 ~68 ~120 grass_block
fill ~64 ~60 ~121 ~71 ~63 ~121 stone
fill ~64 ~64 ~121 ~71 ~66 ~121 dirt
fill ~64 ~67 ~121 ~71 ~67 ~121 grass_block
fill ~72 ~60 ~121 ~79 ~64 ~121 stone
fill ~72 ~65 ~121 ~79 ~67 ~121 dirt
fill ~72 ~68 ~121 ~79 ~68 ~121 grass_block
fill ~64 ~60 ~122 ~72 ~63 ~122 stone
fill ~64 ~64 ~122 ~72 ~66 ~122 dirt
fill ~64 ~67 ~122 ~72 ~67 ~122 grass_block
fill ~73 ~60 ~122 ~79 ~64 ~122 stone
fill ~73 ~65 ~122 ~79 ~67 ~122 dirt
fill ~73 ~68 ~122 ~79 ~68 ~122 grass_block
fill ~64 ~60 ~123 ~76 ~63 ~123 stone
fill ~64 ~64 ~123 ~76 ~66 ~123 dirt
fill ~64 ~67 ~123 ~76 ~67 ~123 grass_block
fill ~77 ~60 ~123 ~79 ~64 ~123 stone
fill ~77 ~65 ~123 ~79 ~67 ~123 dirt
fill ~77 ~68 ~123 ~79 ~68 ~123 grass_block
fill ~64 ~60 ~124 ~78 ~63 ~124 stone
fill ~64 ~64 ~124 ~78 ~66 ~124 dirt
fill ~64 ~67 ~124 ~78 ~67 ~124 grass_block
fill ~79 ~60 ~124 ~79 ~64 ~124 stone
fill ~79 ~65 ~124 ~79 ~67 ~124 dirt
fill ~79 ~68 ~124 ~79 ~68 ~124 grass_block
fill ~64 ~60 ~125 ~79 ~63 ~125 stone
fill ~64 ~64 ~125 ~79 ~66 ~125 dirt
fill ~64 ~67 ~125 ~79 ~67 ~125 grass_block
fill ~64 ~60 ~126 ~79 ~63 ~126 stone
fill ~64 ~64 ~126 ~79 ~66 ~126 dirt
fill ~64 ~67 ~126 ~79 ~67 ~126 grass_block
fill ~64 ~60 ~127 ~64 ~64 ~127 stone
fill ~64 ~65 ~127 ~64 ~67 ~127 dirt
fill ~64 ~68 ~127 ~64 ~68 ~127 grass_block
fill ~65 ~60 ~127 ~79 ~63 ~127 stone
fill ~65 ~64 ~127 ~79 ~66 ~127 dirt
fill ~65 ~67 ~127 ~79 ~67 ~127 grass_block