fill ~336 ~60 ~0 ~336 ~65 ~0 stone
fill ~336 ~66 ~0 ~336 ~68 ~0 dirt
fill ~336 ~69 ~0 ~336 ~69 ~0 grass_block
fill ~337 ~60 ~0 ~338 ~64 ~0 stone
fill ~337 ~65 ~0 ~338 ~67 ~0 dirt
fill ~337 ~68 ~0 ~338 ~68 ~0 grass_block
fill ~339 ~60 ~0 ~345 ~65 ~0 stone
fill ~339 ~66 ~0 ~345 ~68 ~0 dirt
fill ~339 ~69 ~0 ~345 ~69 ~0 grass_block
fill ~346 ~60 ~0 ~349 ~66 ~0 stone
fill ~346 ~67 ~0 ~349 ~69 ~0 dirt
fill ~346 ~70 ~0 ~349 ~70 ~0 grass_block
fill ~350 ~60 ~0 ~351 ~65 ~0 stone
fill ~350 ~66 ~0 ~351 ~68 ~0 dirt
fill ~350 ~69 ~0 ~351 ~69 ~0 grass_block
fill ~336 ~60 ~1 ~339 ~64 ~1 stone
fill ~336 ~65 ~1 ~339 ~67 ~1 dirt
fill ~336 ~68 ~1 ~339 ~68 ~1 grass_block
fill ~340 ~60 ~1 ~351 ~65 ~1 stone
fill ~340 ~66 ~1 ~351 ~68 ~1 dirt
fill ~340 ~69 ~1 ~351 ~69 ~1 grass_block
fill ~336 ~60 ~2 ~340 ~64 ~2 stone
fill ~336 ~65 ~2 ~340 ~67 ~2 dirt
fill ~336 ~68 ~2 ~340 ~68 ~2 grass_block
fill ~341 ~60 ~2 ~351 ~65 ~2 stone
fill ~341 ~66 ~2 ~351 ~68 ~2 dirt
fill ~341 ~69 ~2 ~351 ~69 ~2 grass_block
fill ~336 ~60 ~3 ~341 ~64 ~3 stone
fill ~336 ~65 ~3 ~341 ~67 ~3 dirt
fill ~336 ~68 ~3 ~341 ~68 ~3 grass_block
fill ~342 ~60 ~3 ~351 ~65 ~3 stone
fill ~342 ~66 ~3 ~351 ~68 ~3 dirt
fill ~342 ~69 ~3 ~351 ~69 ~3 grass_block
fill ~336 ~60 ~4 ~342 ~64 ~4 stone
fill ~336 ~65 ~4 ~342 ~67 ~4 dirt
fill ~336 ~68 ~4 ~342 ~68 ~4 grass_block
fill ~343 ~60 ~4 ~347 ~65 ~4 stone
fill ~343 ~66 ~4 ~347 ~68 ~4 dirt
fill ~343 ~69 ~4 ~347 ~69 ~4 grass_block
fill ~348 ~60 ~4 ~349 ~64 ~4 stone
fill ~348 ~65 ~4 ~349 ~67 ~4 dirt
fill ~348 ~68 ~4 ~349 ~68 ~4 grass_block
fill ~350 ~60 ~4 ~351 ~65 ~4 stone
fill ~350 ~66 ~4 ~351 ~68 ~4 dirt
fill ~350 ~69 ~4 ~351 ~69 ~4 grass_block
fill ~336 ~60 ~5 ~343 ~64 ~5 stone
fill ~336 ~65 ~5 ~343 ~67 ~5 dirt
fill ~336 ~68 ~5 ~343 ~68 ~5 grass_block
fill ~344 ~60 ~5 ~346 ~65 ~5 stone
fill ~344 ~66 ~5 ~346 ~68 ~5 dirt
fill ~344 ~69 ~5 ~346 ~69 ~5 grass_block
fill ~347 ~60 ~5 ~351 ~64 ~5 stone
fill ~347 ~65 ~5 ~351 ~67 ~5 dirt
fill ~347 ~68 ~5 ~351 ~68 ~5 grass_block
fill ~336 ~60 ~6 ~336 ~64 ~6 stone
fill ~336 ~65 ~6 ~336 ~67 ~6 dirt
fill ~336 ~68 ~6 ~336 ~68 ~6 grass_block
fill ~337 ~60 ~6 ~338 ~63 ~6 stone
fill ~337 ~64 ~6 ~338 ~66 ~6 dirt
fill ~337 ~67 ~6 ~338 ~67 ~6 grass_block
fill ~339 ~60 ~6 ~344 ~64 ~6 stone
fill ~339 ~65 ~6 ~344 ~67 ~6 dirt
fill ~339 ~68 ~6 ~344 ~68 ~6 grass_block
fill ~345 ~60 ~6 ~345 ~65 ~6 stone
fill ~345 ~66 ~6 ~345 ~68 ~6 dirt
fill ~345 ~69 ~6 ~345 ~69 ~6 grass_block
fill ~346 ~60 ~6 ~351 ~64 ~6 stone
fill ~346 ~65 ~6 ~351 ~67 ~6 dirt
fill ~346 ~68 ~6 ~351 ~68 ~6 grass_block
fill ~336 ~60 ~7 ~337 ~64 ~7 stone
fill ~336 ~65 ~7 ~337 ~67 ~7 dirt
fill ~336 ~68 ~7 ~337 ~68 ~7 grass_block
fill ~338 ~60 ~7 ~339 ~63 ~7 stone
fill ~338 ~64 ~7 ~339 ~66 ~7 dirt
fill ~338 ~67 ~7 ~339 ~67 ~7 grass_block
fill ~340 ~60 ~7 ~348 ~64 ~7 stone
fill ~340 ~65 ~7 ~348 ~67 ~7 dirt
fill ~340 ~68 ~7 ~348 ~68 ~7 grass_block
fill ~349 ~60 ~7 ~350 ~63 ~7 stone
fill ~349 ~64 ~7 ~350 ~66 ~7 dirt
fill ~349 ~67 ~7 ~350 ~67 ~7 grass_block
fill ~351 ~60 ~7 ~351 ~64 ~7 stone
fill ~351 ~65 ~7 ~351 ~67 ~7 dirt
fill ~351 ~68 ~7 ~351 ~68 ~7 grass_block
fill ~336 ~60 ~8 ~340 ~63 ~8 stone
fill ~336 ~64 ~8 ~340 ~66 ~8 dirt
fill ~336 ~67 ~8 ~340 ~67 ~8 grass_block
fill ~341 ~60 ~8 ~348 ~64 ~8 stone
fill ~341 ~65 ~8 ~348 ~67 ~8 dirt
fill ~341 ~68 ~8 ~348 ~68 ~8 grass_block
fill ~349 ~60 ~8 ~351 ~63 ~8 stone
fill ~349 ~64 ~8 ~351 ~66 ~8 dirt
fill ~349 ~67 ~8 ~351 ~67 ~8 grass_block
fill ~336 ~60 ~9 ~351 ~63 ~9 stone
fill ~336 ~64 ~9 ~351 ~66 ~9 dirt
fill ~336 ~67 ~9 ~351 ~67 ~9 grass_block
fill ~336 ~60 ~10 ~351 ~63 ~10 stone
fill ~336 ~64 ~10 ~351 ~66 ~10 dirt
fill ~336 ~67 ~10 ~351 ~67 ~10 grass_block
fill ~336 ~60 ~11 ~337 ~62 ~11 stone
fill ~336 ~63 ~11 ~337 ~65 ~11 dirt
fill ~336 ~66 ~11 ~337 ~66 ~11 grass_block
fill ~338 ~60 ~11 ~351 ~63 ~11 stone
fill ~338 ~64 ~11 ~351 ~66 ~11 dirt
fill ~338 ~67 ~11 ~351 ~67 ~11 grass_block
fill ~336 ~60 ~12 ~336 ~63 ~12 stone
fill ~336 ~64 ~12 ~336 ~66 ~12 dirt
fill ~336 ~67 ~12 ~336 ~67 ~12 grass_block
fill ~337 ~60 ~12 ~340 ~62 ~12 stone
fill ~337 ~63 ~12 ~340 ~65 ~12 dirt
fill ~337 ~66 ~12 ~340 ~66 ~12 grass_block
fill ~341 ~60 ~12 ~343 ~63 ~12 stone
fill ~341 ~64 ~12 ~343 ~66 ~12 dirt
fill ~341 ~67 ~12 ~343 ~67 ~12 grass_block
fill ~344 ~60 ~12 ~351 ~62 ~12 stone
fill ~344 ~63 ~12 ~351 ~65 ~12 dirt
fill ~344 ~66 ~12 ~351 ~66 ~12 grass_block
fill ~336 ~60 ~13 ~339 ~63 ~13 stone
fill ~336 ~64 ~13 ~339 ~66 ~13 dirt
fill ~336 ~67 ~13 ~339 ~67 ~13 grass_block
fill ~340 ~60 ~13 ~351 ~62 ~13 stone
fill ~340 ~63 ~13 ~351 ~65 ~13 dirt
fill ~340 ~66 ~13 ~351 ~66 ~13 grass_block
fill ~336 ~60 ~14 ~336 ~64 ~14 stone
fill ~336 ~65 ~14 ~336 ~67 ~14 dirt
fill ~336 ~68 ~14 ~336 ~68 ~14 grass_block
fill ~337 ~60 ~14 ~350 ~63 ~14 stone
fill ~337 ~64 ~14 ~350 ~66 ~14 dirt
fill ~337 ~67 ~14 ~350 ~67 ~14 grass_block
fill ~351 ~60 ~14 ~351 ~62 ~14 stone
fill ~351 ~63 ~14 ~351 ~65 ~14 dirt
fill ~351 ~66 ~14 ~351 ~66 ~14 grass_block
fill ~336 ~60 ~15 ~338 ~64 ~15 stone
fill ~336 ~65 ~15 ~338 ~67 ~15 dirt
fill ~336 ~68 ~15 ~338 ~68 ~15 grass_block
fill ~339 ~60 ~15 ~340 ~63 ~15 stone
fill ~339 ~64 ~15 ~340 ~66 ~15 dirt
fill ~339 ~67 ~15 ~340 ~67 ~15 grass_block
fill ~341 ~60 ~15 ~348 ~64 ~15 stone
fill ~341 ~65 ~15 ~348 ~67 ~15 dirt
fill ~341 ~68 ~15 ~348 ~68 ~15 grass_block
fill ~349 ~60 ~15 ~351 ~63 ~15 stone
fill ~349 ~64 ~15 ~351 ~66 ~15 dirt
fill ~349 ~67 ~15 ~351 ~67 ~15 grass_block