fill ~256 ~60 ~32 ~257 ~63 ~32 stone
fill ~256 ~64 ~32 ~257 ~66 ~32 dirt
fill ~256 ~67 ~32 ~257 ~67 ~32 grass_block
fill ~258 ~60 ~32 ~259 ~62 ~32 stone
fill ~258 ~63 ~32 ~259 ~65 ~32 dirt
fill ~258 ~66 ~32 ~259 ~66 ~32 grass_block
fill ~260 ~60 ~32 ~262 ~61 ~32 stone
fill ~260 ~62 ~32 ~262 ~64 ~32 dirt
fill ~260 ~65 ~32 ~262 ~65 ~32 grass_block
fill ~263 ~60 ~32 ~271 ~62 ~32 stone
fill ~263 ~63 ~32 ~271 ~65 ~32 dirt
fill ~263 ~66 ~32 ~271 ~66 ~32 grass_block
fill ~256 ~60 ~33 ~256 ~62 ~33 stone
fill ~256 ~63 ~33 ~256 ~65 ~33 dirt
fill ~256 ~66 ~33 ~256 ~66 ~33 grass_block
fill ~257 ~60 ~33 ~257 ~63 ~33 stone
fill ~257 ~64 ~33 ~257 ~66 ~33 dirt
fill ~257 ~67 ~33 ~257 ~67 ~33 grass_block
fill ~258 ~60 ~33 ~260 ~62 ~33 stone
fill ~258 ~63 ~33 ~260 ~65 ~33 dirt
fill ~258 ~66 ~33 ~260 ~66 ~33 grass_block
fill ~261 ~60 ~33 ~263 ~61 ~33 stone
fill ~261 ~62 ~33 ~263 ~64 ~33 dirt
fill ~261 ~65 ~33 ~263 ~65 ~33 grass_block
fill ~264 ~60 ~33 ~271 ~62 ~33 stone
fill ~264 ~63 ~33 ~271 ~65 ~33 dirt
fill ~264 ~66 ~33 ~271 ~66 ~33 grass_block
fill ~256 ~60 ~34 ~257 ~62 ~34 stone
fill ~256 ~63 ~34 ~257 ~65 ~34 dirt
fill ~256 ~66 ~34 ~257 ~66 ~34 grass_block
fill ~258 ~60 ~34 ~258 ~63 ~34 stone
fill ~258 ~64 ~34 ~258 ~66 ~34 dirt
fill ~258 ~67 ~34 ~258 ~67 ~34 grass_block
fill ~259 ~60 ~34 ~260 ~62 ~34 stone
fill ~259 ~63 ~34 ~260 ~65 ~34 dirt
fill ~259 ~66 ~34 ~260 ~66 ~34 grass_block
fill ~261 ~60 ~34 ~264 ~61 ~34 stone
fill ~261 ~62 ~34 ~264 ~64 ~34 dirt
fill ~261 ~65 ~34 ~264 ~65 ~34 grass_block
fill ~265 ~60 ~34 ~271 ~62 ~34 stone
fill ~265 ~63 ~34 ~271 ~65 ~34 dirt
fill ~265 ~66 ~34 ~271 ~66 ~34 grass_block
fill ~256 ~60 ~35 ~258 ~62 ~35 stone
fill ~256 ~63 ~35 ~258 ~65 ~35 dirt
fill ~256 ~66 ~35 ~258 ~66 ~35 grass_block
fill ~259 ~60 ~35 ~259 ~63 ~35 stone
fill ~259 ~64 ~35 ~259 ~66 ~35 dirt
fill ~259 ~67 ~35 ~259 ~67 ~35 grass_block
fill ~260 ~60 ~35 ~261 ~62 ~35 stone
fill ~260 ~63 ~35 ~261 ~65 ~35 dirt
fill ~260 ~66 ~35 ~261 ~66 ~35 grass_block
fill ~262 ~60 ~35 ~266 ~61 ~35 stone
fill ~262 ~62 ~35 ~266 ~64 ~35 dirt
fill ~262 ~65 ~35 ~266 ~65 ~35 grass_block
fill ~267 ~60 ~35 ~271 ~62 ~35 stone
fill ~267 ~63 ~35 ~271 ~65 ~35 dirt
fill ~267 ~66 ~35 ~271 ~66 ~35 grass_block
fill ~256 ~60 ~36 ~262 ~62 ~36 stone
fill ~256 ~63 ~36 ~262 ~65 ~36 dirt
fill ~256 ~66 ~36 ~262 ~66 ~36 grass_block
fill ~263 ~60 ~36 ~267 ~61 ~36 stone
fill ~263 ~62 ~36 ~267 ~64 ~36 dirt
fill ~263 ~65 ~36 ~267 ~65 ~36 grass_block
fill ~268 ~60 ~36 ~271 ~62 ~36 stone
fill ~268 ~63 ~36 ~271 ~65 ~36 dirt
fill ~268 ~66 ~36 ~271 ~66 ~36 grass_block
fill ~256 ~60 ~37 ~258 ~61 ~37 stone
fill ~256 ~62 ~37 ~258 ~64 ~37 dirt
fill ~256 ~65 ~37 ~258 ~65 ~37 grass_block
fill ~259 ~60 ~37 ~263 ~62 ~37 stone
fill ~259 ~63 ~37 ~263 ~65 ~37 dirt
fill ~259 ~66 ~37 ~263 ~66 ~37 grass_block
fill ~264 ~60 ~37 ~268 ~61 ~37 stone
fill ~264 ~62 ~37 ~268 ~64 ~37 dirt
fill ~264 ~65 ~37 ~268 ~65 ~37 grass_block
fill ~269 ~60 ~37 ~271 ~62 ~37 stone
fill ~269 ~63 ~37 ~271 ~65 ~37 dirt
fill ~269 ~66 ~37 ~271 ~66 ~37 grass_block
fill ~256 ~60 ~38 ~260 ~61 ~38 stone
fill ~256 ~62 ~38 ~260 ~64 ~38 dirt
fill ~256 ~65 ~38 ~260 ~65 ~38 grass_block
fill ~261 ~60 ~38 ~263 ~62 ~38 stone
fill ~261 ~63 ~38 ~263 ~65 ~38 dirt
fill ~261 ~66 ~38 ~263 ~66 ~38 grass_block
fill ~264 ~60 ~38 ~271 ~61 ~38 stone
fill ~264 ~62 ~38 ~271 ~64 ~38 dirt
fill ~264 ~65 ~38 ~271 ~65 ~38 grass_block
fill ~256 ~60 ~39 ~271 ~61 ~39 stone
fill ~256 ~62 ~39 ~271 ~64 ~39 dirt
fill ~256 ~65 ~39 ~271 ~65 ~39 grass_block
fill ~256 ~60 ~40 ~271 ~61 ~40 stone
fill ~256 ~62 ~40 ~271 ~64 ~40 dirt
fill ~256 ~65 ~40 ~271 ~65 ~40 grass_block
fill ~256 ~60 ~41 ~269 ~61 ~41 stone
fill ~256 ~62 ~41 ~269 ~64 ~41 dirt
fill ~256 ~65 ~41 ~269 ~65 ~41 grass_block
fill ~270 ~60 ~41 ~271 ~62 ~41 stone
fill ~270 ~63 ~41 ~271 ~65 ~41 dirt
fill ~270 ~66 ~41 ~271 ~66 ~41 grass_block
fill ~256 ~60 ~42 ~271 ~61 ~42 stone
fill ~256 ~62 ~42 ~271 ~64 ~42 dirt
fill ~256 ~65 ~42 ~271 ~65 ~42 grass_block
fill ~256 ~60 ~43 ~271 ~61 ~43 stone
fill ~256 ~62 ~43 ~271 ~64 ~43 dirt
fill ~256 ~65 ~43 ~271 ~65 ~43 grass_block
fill ~256 ~60 ~44 ~271 ~61 ~44 stone
fill ~256 ~62 ~44 ~271 ~64 ~44 dirt
fill ~256 ~65 ~44 ~271 ~65 ~44 grass_block
fill ~256 ~60 ~45 ~271 ~61 ~45 stone
fill ~256 ~62 ~45 ~271 ~64 ~45 dirt
fill ~256 ~65 ~45 ~271 ~65 ~45 grass_block
fill ~256 ~60 ~46 ~258 ~61 ~46 stone
fill ~256 ~62 ~46 ~258 ~64 ~46 dirt
fill ~256 ~65 ~46 ~258 ~65 ~46 grass_block
fill ~259 ~60 ~46 ~260 ~62 ~46 stone
fill ~259 ~63 ~46 ~260 ~65 ~46 dirt
fill ~259 ~66 ~46 ~260 ~66 ~46 grass_block
fill ~261 ~60 ~46 ~271 ~61 ~46 stone
fill ~261 ~62 ~46 ~271 ~64 ~46 dirt
fill ~261 ~65 ~46 ~271 ~65 ~46 grass_block
fill ~256 ~60 ~47 ~260 ~61 ~47 stone
fill ~256 ~62 ~47 ~260 ~64 ~47 dirt
fill ~256 ~65 ~47 ~260 ~65 ~47 grass_block
fill ~261 ~60 ~47 ~261 ~62 ~47 stone
fill ~261 ~63 ~47 ~261 ~65 ~47 dirt
fill ~261 ~66 ~47 ~261 ~66 ~47 grass_block
fill ~262 ~60 ~47 ~271 ~61 ~47 stone
fill ~262 ~62 ~47 ~271 ~64 ~47 dirt
fill ~262 ~65 ~47 ~271 ~65 ~47 grass_block