fill ~48 ~60 ~32 ~52 ~65 ~32 stone
fill ~48 ~66 ~32 ~52 ~68 ~32 dirt
fill ~48 ~69 ~32 ~52 ~69 ~32 grass_block
fill ~53 ~60 ~32 ~54 ~66 ~32 stone
fill ~53 ~67 ~32 ~54 ~69 ~32 dirt
fill ~53 ~70 ~32 ~54 ~70 ~32 grass_block
fill ~55 ~60 ~32 ~58 ~67 ~32 stone
fill ~55 ~68 ~32 ~58 ~70 ~32 dirt
fill ~55 ~71 ~32 ~58 ~71 ~32 grass_block
fill ~59 ~60 ~32 ~59 ~68 ~32 stone
fill ~59 ~69 ~32 ~59 ~71 ~32 dirt
fill ~59 ~72 ~32 ~59 ~72 ~32 grass_block
fill ~60 ~60 ~32 ~62 ~67 ~32 stone
fill ~60 ~68 ~32 ~62 ~70 ~32 dirt
fill ~60 ~71 ~32 ~62 ~71 ~32 grass_block
fill ~63 ~60 ~32 ~63 ~66 ~32 stone
fill ~63 ~67 ~32 ~63 ~69 ~32 dirt
fill ~63 ~70 ~32 ~63 ~70 ~32 grass_block
fill ~48 ~60 ~33 ~52 ~65 ~33 stone
fill ~48 ~66 ~33 ~52 ~68 ~33 dirt
fill ~48 ~69 ~33 ~52 ~69 ~33 grass_block
fill ~53 ~60 ~33 ~54 ~66 ~33 stone
fill ~53 ~67 ~33 ~54 ~69 ~33 dirt
fill ~53 ~70 ~33 ~54 ~70 ~33 grass_block
fill ~55 ~60 ~33 ~62 ~67 ~33 stone
fill ~55 ~68 ~33 ~62 ~70 ~33 dirt
fill ~55 ~71 ~33 ~62 ~71 ~33 grass_block
fill ~63 ~60 ~33 ~63 ~66 ~33 stone
fill ~63 ~67 ~33 ~63 ~69 ~33 dirt
fill ~63 ~70 ~33 ~63 ~70 ~33 grass_block
fill ~48 ~60 ~34 ~50 ~64 ~34 stone
fill ~48 ~65 ~34 ~50 ~67 ~34 dirt
fill ~48 ~68 ~34 ~50 ~68 ~34 grass_block
fill ~51 ~60 ~34 ~52 ~65 ~34 stone
fill ~51 ~66 ~34 ~52 ~68 ~34 dirt
fill ~51 ~69 ~34 ~52 ~69 ~34 grass_block
fill ~53 ~60 ~34 ~55 ~66 ~34 stone
fill ~53 ~67 ~34 ~55 ~69 ~34 dirt
fill ~53 ~70 ~34 ~55 ~70 ~34 grass_block
fill ~56 ~60 ~34 ~63 ~67 ~34 stone
fill ~56 ~68 ~34 ~63 ~70 ~34 dirt
fill ~56 ~71 ~34 ~63 ~71 ~34 grass_block
fill ~48 ~60 ~35 ~48 ~63 ~35 stone
fill ~48 ~64 ~35 ~48 ~66 ~35 dirt
fill ~48 ~67 ~35 ~48 ~67 ~35 grass_block
fill ~49 ~60 ~35 ~50 ~64 ~35 stone
fill ~49 ~65 ~35 ~50 ~67 ~35 dirt
fill ~49 ~68 ~35 ~50 ~68 ~35 grass_block
fill ~51 ~60 ~35 ~53 ~65 ~35 stone
fill ~51 ~66 ~35 ~53 ~68 ~35 dirt
fill ~51 ~69 ~35 ~53 ~69 ~35 grass_block
fill ~54 ~60 ~35 ~60 ~66 ~35 stone
fill ~54 ~67 ~35 ~60 ~69 ~35 dirt
fill ~54 ~70 ~35 ~60 ~70 ~35 grass_block
fill ~61 ~60 ~35 ~63 ~67 ~35 stone
fill ~61 ~68 ~35 ~63 ~70 ~35 dirt
fill ~61 ~71 ~35 ~63 ~71 ~35 grass_block
fill ~48 ~60 ~36 ~49 ~63 ~36 stone
fill ~48 ~64 ~36 ~49 ~66 ~36 dirt
fill ~48 ~67 ~36 ~49 ~67 ~36 grass_block
fill ~50 ~60 ~36 ~51 ~64 ~36 stone
fill ~50 ~65 ~36 ~51 ~67 ~36 dirt
fill ~50 ~68 ~36 ~51 ~68 ~36 grass_block
fill ~52 ~60 ~36 ~54 ~65 ~36 stone
fill ~52 ~66 ~36 ~54 ~68 ~36 dirt
fill ~52 ~69 ~36 ~54 ~69 ~36 grass_block
fill ~55 ~60 ~36 ~58 ~66 ~36 stone
fill ~55 ~67 ~36 ~58 ~69 ~36 dirt
fill ~55 ~70 ~36 ~58 ~70 ~36 grass_block
fill ~59 ~60 ~36 ~60 ~65 ~36 stone
fill ~59 ~66 ~36 ~60 ~68 ~36 dirt
fill ~59 ~69 ~36 ~60 ~69 ~36 grass_block
fill ~61 ~60 ~36 ~62 ~66 ~36 stone
fill ~61 ~67 ~36 ~62 ~69 ~36 dirt
fill ~61 ~70 ~36 ~62 ~70 ~36 grass_block
fill ~63 ~60 ~36 ~63 ~67 ~36 stone
fill ~63 ~68 ~36 ~63 ~70 ~36 dirt
fill ~63 ~71 ~36 ~63 ~71 ~36 grass_block
fill ~48 ~60 ~37 ~48 ~64 ~37 stone
fill ~48 ~65 ~37 ~48 ~67 ~37 dirt
fill ~48 ~68 ~37 ~48 ~68 ~37 grass_block
fill ~49 ~60 ~37 ~50 ~63 ~37 stone
fill ~49 ~64 ~37 ~50 ~66 ~37 dirt
fill ~49 ~67 ~37 ~50 ~67 ~37 grass_block
fill ~51 ~60 ~37 ~52 ~64 ~37 stone
fill ~51 ~65 ~37 ~52 ~67 ~37 dirt
fill ~51 ~68 ~37 ~52 ~68 ~37 grass_block
fill ~53 ~60 ~37 ~61 ~65 ~37 stone
fill ~53 ~66 ~37 ~61 ~68 ~37 dirt
fill ~53 ~69 ~37 ~61 ~69 ~37 grass_block
fill ~62 ~60 ~37 ~63 ~66 ~37 stone
fill ~62 ~67 ~37 ~63 ~69 ~37 dirt
fill ~62 ~70 ~37 ~63 ~70 ~37 grass_block
fill ~48 ~60 ~38 ~48 ~64 ~38 stone
fill ~48 ~65 ~38 ~48 ~67 ~38 dirt
fill ~48 ~68 ~38 ~48 ~68 ~38 grass_block
fill ~49 ~60 ~38 ~50 ~63 ~38 stone
fill ~49 ~64 ~38 ~50 ~66 ~38 dirt
fill ~49 ~67 ~38 ~50 ~67 ~38 grass_block
fill ~51 ~60 ~38 ~53 ~64 ~38 stone
fill ~51 ~65 ~38 ~53 ~67 ~38 dirt
fill ~51 ~68 ~38 ~53 ~68 ~38 grass_block
fill ~54 ~60 ~38 ~61 ~65 ~38 stone
fill ~54 ~66 ~38 ~61 ~68 ~38 dirt
fill ~54 ~69 ~38 ~61 ~69 ~38 grass_block
fill ~62 ~60 ~38 ~63 ~66 ~38 stone
fill ~62 ~67 ~38 ~63 ~69 ~38 dirt
fill ~62 ~70 ~38 ~63 ~70 ~38 grass_block
fill ~48 ~60 ~39 ~54 ~64 ~39 stone
fill ~48 ~65 ~39 ~54 ~67 ~39 dirt
fill ~48 ~68 ~39 ~54 ~68 ~39 grass_block
fill ~55 ~60 ~39 ~58 ~65 ~39 stone
fill ~55 ~66 ~39 ~58 ~68 ~39 dirt
fill ~55 ~69 ~39 ~58 ~69 ~39 grass_block
fill ~59 ~60 ~39 ~60 ~64 ~39 stone
fill ~59 ~65 ~39 ~60 ~67 ~39 dirt
fill ~59 ~68 ~39 ~60 ~68 ~39 grass_block
fill ~61 ~60 ~39 ~62 ~65 ~39 stone
fill ~61 ~66 ~39 ~62 ~68 ~39 dirt
fill ~61 ~69 ~39 ~62 ~69 ~39 grass_block
fill ~63 ~60 ~39 ~63 ~66 ~39 stone
fill ~63 ~67 ~39 ~63 ~69 ~39 dirt
fill ~63 ~70 ~39 ~63 ~70 ~39 grass_block
fill ~48 ~60 ~40 ~51 ~64 ~40 stone
fill ~48 ~65 ~40 ~51 ~67 ~40 dirt
fill ~48 ~68 ~40 ~51 ~68 ~40 grass_block
fill ~52 ~60 ~40 ~53 ~63 ~40 stone
fill ~52 ~64 ~40 ~53 ~66 ~40 dirt
fill ~52 ~67 ~40 ~53 ~67 ~40 grass_block
fill ~54 ~60 ~40 ~60 ~64 ~40 stone
fill ~54 ~65 ~40 ~60 ~67 ~40 dirt
fill ~54 ~68 ~40 ~60 ~68 ~40 grass_block
fill ~61 ~60 ~40 ~63 ~65 ~40 stone
fill ~61 ~66 ~40 ~63 ~68 ~40 dirt
fill ~61 ~69 ~40 ~63 ~69 ~40 grass_block
fill ~48 ~60 ~41 ~48 ~65 ~41 stone
fill ~48 ~66 ~41 ~48 ~68 ~41 dirt
fill ~48 ~69 ~41 ~48 ~69 ~41 grass_block
fill ~49 ~60 ~41 ~60 ~64 ~41 stone
fill ~49 ~65 ~41 ~60 ~67 ~41 dirt
fill ~49 ~68 ~41 ~60 ~68 ~41 grass_block
fill ~61 ~60 ~41 ~63 ~65 ~41 stone
fill ~61 ~66 ~41 ~63 ~68 ~41 dirt
fill ~61 ~69 ~41 ~63 ~69 ~41 grass_block
fill ~48 ~60 ~42 ~49 ~65 ~42 stone
fill ~48 ~66 ~42 ~49 ~68 ~42 dirt
fill ~48 ~69 ~42 ~49 ~69 ~42 grass_block
fill ~50 ~60 ~42 ~61 ~64 ~42 stone
fill ~50 ~65 ~42 ~61 ~67 ~42 dirt
fill ~50 ~68 ~42 ~61 ~68 ~42 grass_block
fill ~62 ~60 ~42 ~63 ~65 ~42 stone
fill ~62 ~66 ~42 ~63 ~68 ~42 dirt
fill ~62 ~69 ~42 ~63 ~69 ~42 grass_block
fill ~48 ~60 ~43 ~48 ~66 ~43 stone
fill ~48 ~67 ~43 ~48 ~69 ~43 dirt
fill ~48 ~70 ~43 ~48 ~70 ~43 grass_block
fill ~49 ~60 ~43 ~50 ~65 ~43 stone
fill ~49 ~66 ~43 ~50 ~68 ~43 dirt
fill ~49 ~69 ~43 ~50 ~69 ~43 grass_block
fill ~51 ~60 ~43 ~56 ~64 ~43 stone
fill ~51 ~65 ~43 ~56 ~67 ~43 dirt
fill ~51 ~68 ~43 ~56 ~68 ~43 grass_block
fill ~57 ~60 ~43 ~57 ~63 ~43 stone
fill ~57 ~64 ~43 ~57 ~66 ~43 dirt
fill ~57 ~67 ~43 ~57 ~67 ~43 grass_block
fill ~58 ~60 ~43 ~62 ~64 ~43 stone
fill ~58 ~65 ~43 ~62 ~67 ~43 dirt
fill ~58 ~68 ~43 ~62 ~68 ~43 grass_block
fill ~63 ~60 ~43 ~63 ~65 ~43 stone
fill ~63 ~66 ~43 ~63 ~68 ~43 dirt
fill ~63 ~69 ~43 ~63 ~69 ~43 grass_block
fill ~48 ~60 ~44 ~49 ~66 ~44 stone
fill ~48 ~67 ~44 ~49 ~69 ~44 dirt
fill ~48 ~70 ~44 ~49 ~70 ~44 grass_block
fill ~50 ~60 ~44 ~52 ~65 ~44 stone
fill ~50 ~66 ~44 ~52 ~68 ~44 dirt
fill ~50 ~69 ~44 ~52 ~69 ~44 grass_block
fill ~53 ~60 ~44 ~58 ~64 ~44 stone
fill ~53 ~65 ~44 ~58 ~67 ~44 dirt
fill ~53 ~68 ~44 ~58 ~68 ~44 grass_block
fill ~59 ~60 ~44 ~60 ~63 ~44 stone
fill ~59 ~64 ~44 ~60 ~66 ~44 dirt
fill ~59 ~67 ~44 ~60 ~67 ~44 grass_block
fill ~61 ~60 ~44 ~63 ~64 ~44 stone
fill ~61 ~65 ~44 ~63 ~67 ~44 dirt
fill ~61 ~68 ~44 ~63 ~68 ~44 grass_block
fill ~48 ~60 ~45 ~49 ~66 ~45 stone
fill ~48 ~67 ~45 ~49 ~69 ~45 dirt
fill ~48 ~70 ~45 ~49 ~70 ~45 grass_block
fill ~50 ~60 ~45 ~53 ~65 ~45 stone
fill ~50 ~66 ~45 ~53 ~68 ~45 dirt
fill ~50 ~69 ~45 ~53 ~69 ~45 grass_block
fill ~54 ~60 ~45 ~58 ~64 ~45 stone
fill ~54 ~65 ~45 ~58 ~67 ~45 dirt
fill ~54 ~68 ~45 ~58 ~68 ~45 grass_block
fill ~59 ~60 ~45 ~59 ~63 ~45 stone
fill ~59 ~64 ~45 ~59 ~66 ~45 dirt
fill ~59 ~67 ~45 ~59 ~67 ~45 grass_block
fill ~60 ~60 ~45 ~60 ~64 ~45 stone
fill ~60 ~65 ~45 ~60 ~67 ~45 dirt
fill ~60 ~68 ~45 ~60 ~68 ~45 grass_block
fill ~61 ~60 ~45 ~61 ~63 ~45 stone
fill ~61 ~64 ~45 ~61 ~66 ~45 dirt
fill ~61 ~67 ~45 ~61 ~67 ~45 grass_block
fill ~62 ~60 ~45 ~63 ~64 ~45 stone
fill ~62 ~65 ~45 ~63 ~67 ~45 dirt
fill ~62 ~68 ~45 ~63 ~68 ~45 grass_block
fill ~48 ~60 ~46 ~48 ~67 ~46 stone
fill ~48 ~68 ~46 ~48 ~70 ~46 dirt
fill ~48 ~71 ~46 ~48 ~71 ~46 grass_block
fill ~49 ~60 ~46 ~50 ~66 ~46 stone
fill ~49 ~67 ~46 ~50 ~69 ~46 dirt
fill ~49 ~70 ~46 ~50 ~70 ~46 grass_block
fill ~51 ~60 ~46 ~56 ~65 ~46 stone
fill ~51 ~66 ~46 ~56 ~68 ~46 dirt
fill ~51 ~69 ~46 ~56 ~69 ~46 grass_block
fill ~57 ~60 ~46 ~60 ~64 ~46 stone
fill ~57 ~65 ~46 ~60 ~67 ~46 dirt
fill ~57 ~68 ~46 ~60 ~68 ~46 grass_block
fill ~61 ~60 ~46 ~63 ~63 ~46 stone
fill ~61 ~64 ~46 ~63 ~66 ~46 dirt
fill ~61 ~67 ~46 ~63 ~67 ~46 grass_block
fill ~48 ~60 ~47 ~49 ~67 ~47 stone
fill ~48 ~68 ~47 ~49 ~70 ~47 dirt
fill ~48 ~71 ~47 ~49 ~71 ~47 grass_block
fill ~50 ~60 ~47 ~53 ~66 ~47 stone
fill ~50 ~67 ~47 ~53 ~69 ~47 dirt
fill ~50 ~70 ~47 ~53 ~70 ~47 grass_block
fill ~54 ~60 ~47 ~57 ~65 ~47 stone
fill ~54 ~66 ~47 ~57 ~68 ~47 dirt
fill ~54 ~69 ~47 ~57 ~69 ~47 grass_block
fill ~58 ~60 ~47 ~61 ~64 ~47 stone
fill ~58 ~65 ~47 ~61 ~67 ~47 dirt
fill ~58 ~68 ~47 ~61 ~68 ~47 grass_block
fill ~62 ~60 ~47 ~63 ~63 ~47 stone
fill ~62 ~64 ~47 ~63 ~66 ~47 dirt
fill ~62 ~67 ~47 ~63 ~67 ~47 grass_block