fill ~208 ~60 ~16 ~209 ~61 ~16 stone
fill ~208 ~62 ~16 ~209 ~64 ~16 dirt
fill ~208 ~65 ~16 ~209 ~65 ~16 grass_block
fill ~210 ~60 ~16 ~213 ~62 ~16 stone
fill ~210 ~63 ~16 ~213 ~65 ~16 dirt
fill ~210 ~66 ~16 ~213 ~66 ~16 grass_block
fill ~214 ~60 ~16 ~217 ~63 ~16 stone
fill ~214 ~64 ~16 ~217 ~66 ~16 dirt
fill ~214 ~67 ~16 ~217 ~67 ~16 grass_block
fill ~218 ~60 ~16 ~223 ~64 ~16 stone
fill ~218 ~65 ~16 ~223 ~67 ~16 dirt
fill ~218 ~68 ~16 ~223 ~68 ~16 grass_block
fill ~208 ~60 ~17 ~210 ~61 ~17 stone
fill ~208 ~62 ~17 ~210 ~64 ~17 dirt
fill ~208 ~65 ~17 ~210 ~65 ~17 grass_block
fill ~211 ~60 ~17 ~213 ~62 ~17 stone
fill ~211 ~63 ~17 ~213 ~65 ~17 dirt
fill ~211 ~66 ~17 ~213 ~66 ~17 grass_block
fill ~214 ~60 ~17 ~218 ~63 ~17 stone
fill ~214 ~64 ~17 ~218 ~66 ~17 dirt
fill ~214 ~67 ~17 ~218 ~67 ~17 grass_block
fill ~219 ~60 ~17 ~223 ~64 ~17 stone
fill ~219 ~65 ~17 ~223 ~67 ~17 dirt
fill ~219 ~68 ~17 ~223 ~68 ~17 grass_block
fill ~208 ~60 ~18 ~210 ~61 ~18 stone
fill ~208 ~62 ~18 ~210 ~64 ~18 dirt
fill ~208 ~65 ~18 ~210 ~65 ~18 grass_block
fill ~211 ~60 ~18 ~213 ~62 ~18 stone
fill ~211 ~63 ~18 ~213 ~65 ~18 dirt
fill ~211 ~66 ~18 ~213 ~66 ~18 grass_block
fill ~214 ~60 ~18 ~219 ~63 ~18 stone
fill ~214 ~64 ~18 ~219 ~66 ~18 dirt
fill ~214 ~67 ~18 ~219 ~67 ~18 grass_block
fill ~220 ~60 ~18 ~223 ~64 ~18 stone
fill ~220 ~65 ~18 ~223 ~67 ~18 dirt
fill ~220 ~68 ~18 ~223 ~68 ~18 grass_block
fill ~208 ~60 ~19 ~211 ~61 ~19 stone
fill ~208 ~62 ~19 ~211 ~64 ~19 dirt
fill ~208 ~65 ~19 ~211 ~65 ~19 grass_block
fill ~212 ~60 ~19 ~213 ~62 ~19 stone
fill ~212 ~63 ~19 ~213 ~65 ~19 dirt
fill ~212 ~66 ~19 ~213 ~66 ~19 grass_block
fill ~214 ~60 ~19 ~221 ~63 ~19 stone
fill ~214 ~64 ~19 ~221 ~66 ~19 dirt
fill ~214 ~67 ~19 ~221 ~67 ~19 grass_block
fill ~222 ~60 ~19 ~223 ~64 ~19 stone
fill ~222 ~65 ~19 ~223 ~67 ~19 dirt
fill ~222 ~68 ~19 ~223 ~68 ~19 grass_block
fill ~208 ~60 ~20 ~209 ~61 ~20 stone
fill ~208 ~62 ~20 ~209 ~64 ~20 dirt
fill ~208 ~65 ~20 ~209 ~65 ~20 grass_block
fill ~210 ~60 ~20 ~213 ~62 ~20 stone
fill ~210 ~63 ~20 ~213 ~65 ~20 dirt
fill ~210 ~66 ~20 ~213 ~66 ~20 grass_block
fill ~214 ~60 ~20 ~223 ~63 ~20 stone
fill ~214 ~64 ~20 ~223 ~66 ~20 dirt
fill ~214 ~67 ~20 ~223 ~67 ~20 grass_block
fill ~208 ~60 ~21 ~208 ~61 ~21 stone
fill ~208 ~62 ~21 ~208 ~64 ~21 dirt
fill ~208 ~65 ~21 ~208 ~65 ~21 grass_block
fill ~209 ~60 ~21 ~213 ~62 ~21 stone
fill ~209 ~63 ~21 ~213 ~65 ~21 dirt
fill ~209 ~66 ~21 ~213 ~66 ~21 grass_block
fill ~214 ~60 ~21 ~223 ~63 ~21 stone
fill ~214 ~64 ~21 ~223 ~66 ~21 dirt
fill ~214 ~67 ~21 ~223 ~67 ~21 grass_block
fill ~208 ~60 ~22 ~208 ~60 ~22 stone
fill ~208 ~61 ~22 ~208 ~63 ~22 dirt
fill ~208 ~64 ~22 ~208 ~64 ~22 grass_block
fill ~209 ~60 ~22 ~209 ~61 ~22 stone
fill ~209 ~62 ~22 ~209 ~64 ~22 dirt
fill ~209 ~65 ~22 ~209 ~65 ~22 grass_block
fill ~210 ~60 ~22 ~213 ~62 ~22 stone
fill ~210 ~63 ~22 ~213 ~65 ~22 dirt
fill ~210 ~66 ~22 ~213 ~66 ~22 grass_block
fill ~214 ~60 ~22 ~223 ~63 ~22 stone
fill ~214 ~64 ~22 ~223 ~66 ~22 dirt
fill ~214 ~67 ~22 ~223 ~67 ~22 grass_block
fill ~208 ~60 ~23 ~209 ~61 ~23 stone
fill ~208 ~62 ~23 ~209 ~64 ~23 dirt
fill ~208 ~65 ~23 ~209 ~65 ~23 grass_block
fill ~210 ~60 ~23 ~214 ~62 ~23 stone
fill ~210 ~63 ~23 ~214 ~65 ~23 dirt
fill ~210 ~66 ~23 ~214 ~66 ~23 grass_block
fill ~215 ~60 ~23 ~221 ~63 ~23 stone
fill ~215 ~64 ~23 ~221 ~66 ~23 dirt
fill ~215 ~67 ~23 ~221 ~67 ~23 grass_block
fill ~222 ~60 ~23 ~223 ~62 ~23 stone
fill ~222 ~63 ~23 ~223 ~65 ~23 dirt
fill ~222 ~66 ~23 ~223 ~66 ~23 grass_block
fill ~208 ~60 ~24 ~208 ~61 ~24 stone
fill ~208 ~62 ~24 ~208 ~64 ~24 dirt
fill ~208 ~65 ~24 ~208 ~65 ~24 grass_block
fill ~209 ~60 ~24 ~223 ~62 ~24 stone
fill ~209 ~63 ~24 ~223 ~65 ~24 dirt
fill ~209 ~66 ~24 ~223 ~66 ~24 grass_block
fill ~208 ~60 ~25 ~209 ~61 ~25 stone
fill ~208 ~62 ~25 ~209 ~64 ~25 dirt
fill ~208 ~65 ~25 ~209 ~65 ~25 grass_block
fill ~210 ~60 ~25 ~223 ~62 ~25 stone
fill ~210 ~63 ~25 ~223 ~65 ~25 dirt
fill ~210 ~66 ~25 ~223 ~66 ~25 grass_block
fill ~208 ~60 ~26 ~209 ~61 ~26 stone
fill ~208 ~62 ~26 ~209 ~64 ~26 dirt
fill ~208 ~65 ~26 ~209 ~65 ~26 grass_block
fill ~210 ~60 ~26 ~217 ~62 ~26 stone
fill ~210 ~63 ~26 ~217 ~65 ~26 dirt
fill ~210 ~66 ~26 ~217 ~66 ~26 grass_block
fill ~218 ~60 ~26 ~223 ~61 ~26 stone
fill ~218 ~62 ~26 ~223 ~64 ~26 dirt
fill ~218 ~65 ~26 ~223 ~65 ~26 grass_block
fill ~208 ~60 ~27 ~211 ~61 ~27 stone
fill ~208 ~62 ~27 ~211 ~64 ~27 dirt
fill ~208 ~65 ~27 ~211 ~65 ~27 grass_block
fill ~212 ~60 ~27 ~213 ~62 ~27 stone
fill ~212 ~63 ~27 ~213 ~65 ~27 dirt
fill ~212 ~66 ~27 ~213 ~66 ~27 grass_block
fill ~214 ~60 ~27 ~223 ~61 ~27 stone
fill ~214 ~62 ~27 ~223 ~64 ~27 dirt
fill ~214 ~65 ~27 ~223 ~65 ~27 grass_block
fill ~208 ~60 ~28 ~223 ~61 ~28 stone
fill ~208 ~62 ~28 ~223 ~64 ~28 dirt
fill ~208 ~65 ~28 ~223 ~65 ~28 grass_block
fill ~208 ~60 ~29 ~223 ~61 ~29 stone
fill ~208 ~62 ~29 ~223 ~64 ~29 dirt
fill ~208 ~65 ~29 ~223 ~65 ~29 grass_block
fill ~208 ~60 ~30 ~223 ~61 ~30 stone
fill ~208 ~62 ~30 ~223 ~64 ~30 dirt
fill ~208 ~65 ~30 ~223 ~65 ~30 grass_block
fill ~208 ~60 ~31 ~223 ~61 ~31 stone
fill ~208 ~62 ~31 ~223 ~64 ~31 dirt
fill ~208 ~65 ~31 ~223 ~65 ~31 grass_block