fill ~16 ~60 ~48 ~18 ~66 ~48 stone
fill ~16 ~67 ~48 ~18 ~69 ~48 dirt
fill ~16 ~70 ~48 ~18 ~70 ~48 grass_block
fill ~19 ~60 ~48 ~22 ~65 ~48 stone
fill ~19 ~66 ~48 ~22 ~68 ~48 dirt
fill ~19 ~69 ~48 ~22 ~69 ~48 grass_block
fill ~23 ~60 ~48 ~31 ~66 ~48 stone
fill ~23 ~67 ~48 ~31 ~69 ~48 dirt
fill ~23 ~70 ~48 ~31 ~70 ~48 grass_block
fill ~16 ~60 ~49 ~16 ~67 ~49 stone
fill ~16 ~68 ~49 ~16 ~70 ~49 dirt
fill ~16 ~71 ~49 ~16 ~71 ~49 grass_block
fill ~17 ~60 ~49 ~21 ~66 ~49 stone
fill ~17 ~67 ~49 ~21 ~69 ~49 dirt
fill ~17 ~70 ~49 ~21 ~70 ~49 grass_block
fill ~22 ~60 ~49 ~25 ~65 ~49 stone
fill ~22 ~66 ~49 ~25 ~68 ~49 dirt
fill ~22 ~69 ~49 ~25 ~69 ~49 grass_block
fill ~26 ~60 ~49 ~27 ~66 ~49 stone
fill ~26 ~67 ~49 ~27 ~69 ~49 dirt
fill ~26 ~70 ~49 ~27 ~70 ~49 grass_block
fill ~28 ~60 ~49 ~31 ~65 ~49 stone
fill ~28 ~66 ~49 ~31 ~68 ~49 dirt
fill ~28 ~69 ~49 ~31 ~69 ~49 grass_block
fill ~16 ~60 ~50 ~18 ~67 ~50 stone
fill ~16 ~68 ~50 ~18 ~70 ~50 dirt
fill ~16 ~71 ~50 ~18 ~71 ~50 grass_block
fill ~19 ~60 ~50 ~21 ~66 ~50 stone
fill ~19 ~67 ~50 ~21 ~69 ~50 dirt
fill ~19 ~70 ~50 ~21 ~70 ~50 grass_block
fill ~22 ~60 ~50 ~31 ~65 ~50 stone
fill ~22 ~66 ~50 ~31 ~68 ~50 dirt
fill ~22 ~69 ~50 ~31 ~69 ~50 grass_block
fill ~16 ~60 ~51 ~16 ~68 ~51 stone
fill ~16 ~69 ~51 ~16 ~71 ~51 dirt
fill ~16 ~72 ~51 ~16 ~72 ~51 grass_block
fill ~17 ~60 ~51 ~19 ~67 ~51 stone
fill ~17 ~68 ~51 ~19 ~70 ~51 dirt
fill ~17 ~71 ~51 ~19 ~71 ~51 grass_block
fill ~20 ~60 ~51 ~23 ~66 ~51 stone
fill ~20 ~67 ~51 ~23 ~69 ~51 dirt
fill ~20 ~70 ~51 ~23 ~70 ~51 grass_block
fill ~24 ~60 ~51 ~31 ~65 ~51 stone
fill ~24 ~66 ~51 ~31 ~68 ~51 dirt
fill ~24 ~69 ~51 ~31 ~69 ~51 grass_block
fill ~16 ~60 ~52 ~16 ~68 ~52 stone
fill ~16 ~69 ~52 ~16 ~71 ~52 dirt
fill ~16 ~72 ~52 ~16 ~72 ~52 grass_block
fill ~17 ~60 ~52 ~19 ~67 ~52 stone
fill ~17 ~68 ~52 ~19 ~70 ~52 dirt
fill ~17 ~71 ~52 ~19 ~71 ~52 grass_block
fill ~20 ~60 ~52 ~28 ~66 ~52 stone
fill ~20 ~67 ~52 ~28 ~69 ~52 dirt
fill ~20 ~70 ~52 ~28 ~70 ~52 grass_block
fill ~29 ~60 ~52 ~31 ~65 ~52 stone
fill ~29 ~66 ~52 ~31 ~68 ~52 dirt
fill ~29 ~69 ~52 ~31 ~69 ~52 grass_block
fill ~16 ~60 ~53 ~17 ~68 ~53 stone
fill ~16 ~69 ~53 ~17 ~71 ~53 dirt
fill ~16 ~72 ~53 ~17 ~72 ~53 grass_block
fill ~18 ~60 ~53 ~19 ~67 ~53 stone
fill ~18 ~68 ~53 ~19 ~70 ~53 dirt
fill ~18 ~71 ~53 ~19 ~71 ~53 grass_block
fill ~20 ~60 ~53 ~20 ~66 ~53 stone
fill ~20 ~67 ~53 ~20 ~69 ~53 dirt
fill ~20 ~70 ~53 ~20 ~70 ~53 grass_block
fill ~21 ~60 ~53 ~26 ~67 ~53 stone
fill ~21 ~68 ~53 ~26 ~70 ~53 dirt
fill ~21 ~71 ~53 ~26 ~71 ~53 grass_block
fill ~27 ~60 ~53 ~31 ~66 ~53 stone
fill ~27 ~67 ~53 ~31 ~69 ~53 dirt
fill ~27 ~70 ~53 ~31 ~70 ~53 grass_block
fill ~16 ~60 ~54 ~16 ~69 ~54 stone
fill ~16 ~70 ~54 ~16 ~72 ~54 dirt
fill ~16 ~73 ~54 ~16 ~73 ~54 grass_block
fill ~17 ~60 ~54 ~18 ~68 ~54 stone
fill ~17 ~69 ~54 ~18 ~71 ~54 dirt
fill ~17 ~72 ~54 ~18 ~72 ~54 grass_block
fill ~19 ~60 ~54 ~21 ~67 ~54 stone
fill ~19 ~68 ~54 ~21 ~70 ~54 dirt
fill ~19 ~71 ~54 ~21 ~71 ~54 grass_block
fill ~22 ~60 ~54 ~23 ~68 ~54 stone
fill ~22 ~69 ~54 ~23 ~71 ~54 dirt
fill ~22 ~72 ~54 ~23 ~72 ~54 grass_block
fill ~24 ~60 ~54 ~28 ~67 ~54 stone
fill ~24 ~68 ~54 ~28 ~70 ~54 dirt
fill ~24 ~71 ~54 ~28 ~71 ~54 grass_block
fill ~29 ~60 ~54 ~31 ~66 ~54 stone
fill ~29 ~67 ~54 ~31 ~69 ~54 dirt
fill ~29 ~70 ~54 ~31 ~70 ~54 grass_block
fill ~16 ~60 ~55 ~16 ~69 ~55 stone
fill ~16 ~70 ~55 ~16 ~72 ~55 dirt
fill ~16 ~73 ~55 ~16 ~73 ~55 grass_block
fill ~17 ~60 ~55 ~18 ~68 ~55 stone
fill ~17 ~69 ~55 ~18 ~71 ~55 dirt
fill ~17 ~72 ~55 ~18 ~72 ~55 grass_block
fill ~19 ~60 ~55 ~19 ~67 ~55 stone
fill ~19 ~68 ~55 ~19 ~70 ~55 dirt
fill ~19 ~71 ~55 ~19 ~71 ~55 grass_block
fill ~20 ~60 ~55 ~24 ~68 ~55 stone
fill ~20 ~69 ~55 ~24 ~71 ~55 dirt
fill ~20 ~72 ~55 ~24 ~72 ~55 grass_block
fill ~25 ~60 ~55 ~30 ~67 ~55 stone
fill ~25 ~68 ~55 ~30 ~70 ~55 dirt
fill ~25 ~71 ~55 ~30 ~71 ~55 grass_block
fill ~31 ~60 ~55 ~31 ~66 ~55 stone
fill ~31 ~67 ~55 ~31 ~69 ~55 dirt
fill ~31 ~70 ~55 ~31 ~70 ~55 grass_block
fill ~16 ~60 ~56 ~22 ~68 ~56 stone
fill ~16 ~69 ~56 ~22 ~71 ~56 dirt
fill ~16 ~72 ~56 ~22 ~72 ~56 grass_block
fill ~23 ~60 ~56 ~24 ~69 ~56 stone
fill ~23 ~70 ~56 ~24 ~72 ~56 dirt
fill ~23 ~73 ~56 ~24 ~73 ~56 grass_block
fill ~25 ~60 ~56 ~26 ~68 ~56 stone
fill ~25 ~69 ~56 ~26 ~71 ~56 dirt
fill ~25 ~72 ~56 ~26 ~72 ~56 grass_block
fill ~27 ~60 ~56 ~31 ~67 ~56 stone
fill ~27 ~68 ~56 ~31 ~70 ~56 dirt
fill ~27 ~71 ~56 ~31 ~71 ~56 grass_block
fill ~16 ~60 ~57 ~16 ~69 ~57 stone
fill ~16 ~70 ~57 ~16 ~72 ~57 dirt
fill ~16 ~73 ~57 ~16 ~73 ~57 grass_block
fill ~17 ~60 ~57 ~20 ~68 ~57 stone
fill ~17 ~69 ~57 ~20 ~71 ~57 dirt
fill ~17 ~72 ~57 ~20 ~72 ~57 grass_block
fill ~21 ~60 ~57 ~25 ~69 ~57 stone
fill ~21 ~70 ~57 ~25 ~72 ~57 dirt
fill ~21 ~73 ~57 ~25 ~73 ~57 grass_block
fill ~26 ~60 ~57 ~28 ~68 ~57 stone
fill ~26 ~69 ~57 ~28 ~71 ~57 dirt
fill ~26 ~72 ~57 ~28 ~72 ~57 grass_block
fill ~29 ~60 ~57 ~31 ~67 ~57 stone
fill ~29 ~68 ~57 ~31 ~70 ~57 dirt
fill ~29 ~71 ~57 ~31 ~71 ~57 grass_block
fill ~16 ~60 ~58 ~17 ~69 ~58 stone
fill ~16 ~70 ~58 ~17 ~72 ~58 dirt
fill ~16 ~73 ~58 ~17 ~73 ~58 grass_block
fill ~18 ~60 ~58 ~19 ~68 ~58 stone
fill ~18 ~69 ~58 ~19 ~71 ~58 dirt
fill ~18 ~72 ~58 ~19 ~72 ~58 grass_block
fill ~20 ~60 ~58 ~21 ~69 ~58 stone
fill ~20 ~70 ~58 ~21 ~72 ~58 dirt
fill ~20 ~73 ~58 ~21 ~73 ~58 grass_block
fill ~22 ~60 ~58 ~25 ~70 ~58 stone
fill ~22 ~71 ~58 ~25 ~73 ~58 dirt
fill ~22 ~74 ~58 ~25 ~74 ~58 grass_block
fill ~26 ~60 ~58 ~27 ~69 ~58 stone
fill ~26 ~70 ~58 ~27 ~72 ~58 dirt
fill ~26 ~73 ~58 ~27 ~73 ~58 grass_block
fill ~28 ~60 ~58 ~30 ~68 ~58 stone
fill ~28 ~69 ~58 ~30 ~71 ~58 dirt
fill ~28 ~72 ~58 ~30 ~72 ~58 grass_block
fill ~31 ~60 ~58 ~31 ~67 ~58 stone
fill ~31 ~68 ~58 ~31 ~70 ~58 dirt
fill ~31 ~71 ~58 ~31 ~71 ~58 grass_block
fill ~16 ~60 ~59 ~16 ~70 ~59 stone
fill ~16 ~71 ~59 ~16 ~73 ~59 dirt
fill ~16 ~74 ~59 ~16 ~74 ~59 grass_block
fill ~17 ~60 ~59 ~20 ~69 ~59 stone
fill ~17 ~70 ~59 ~20 ~72 ~59 dirt
fill ~17 ~73 ~59 ~20 ~73 ~59 grass_block
fill ~21 ~60 ~59 ~27 ~70 ~59 stone
fill ~21 ~71 ~59 ~27 ~73 ~59 dirt
fill ~21 ~74 ~59 ~27 ~74 ~59 grass_block
fill ~28 ~60 ~59 ~29 ~69 ~59 stone
fill ~28 ~70 ~59 ~29 ~72 ~59 dirt
fill ~28 ~73 ~59 ~29 ~73 ~59 grass_block
fill ~30 ~60 ~59 ~31 ~68 ~59 stone
fill ~30 ~69 ~59 ~31 ~71 ~59 dirt
fill ~30 ~72 ~59 ~31 ~72 ~59 grass_block
fill ~16 ~60 ~60 ~17 ~70 ~60 stone
fill ~16 ~71 ~60 ~17 ~73 ~60 dirt
fill ~16 ~74 ~60 ~17 ~74 ~60 grass_block
fill ~18 ~60 ~60 ~20 ~69 ~60 stone
fill ~18 ~70 ~60 ~20 ~72 ~60 dirt
fill ~18 ~73 ~60 ~20 ~73 ~60 grass_block
fill ~21 ~60 ~60 ~28 ~70 ~60 stone
fill ~21 ~71 ~60 ~28 ~73 ~60 dirt
fill ~21 ~74 ~60 ~28 ~74 ~60 grass_block
fill ~29 ~60 ~60 ~31 ~69 ~60 stone
fill ~29 ~70 ~60 ~31 ~72 ~60 dirt
fill ~29 ~73 ~60 ~31 ~73 ~60 grass_block
fill ~16 ~60 ~61 ~17 ~70 ~61 stone
fill ~16 ~71 ~61 ~17 ~73 ~61 dirt
fill ~16 ~74 ~61 ~17 ~74 ~61 grass_block
fill ~18 ~60 ~61 ~20 ~69 ~61 stone
fill ~18 ~70 ~61 ~20 ~72 ~61 dirt
fill ~18 ~73 ~61 ~20 ~73 ~61 grass_block
fill ~21 ~60 ~61 ~30 ~70 ~61 stone
fill ~21 ~71 ~61 ~30 ~73 ~61 dirt
fill ~21 ~74 ~61 ~30 ~74 ~61 grass_block
fill ~31 ~60 ~61 ~31 ~69 ~61 stone
fill ~31 ~70 ~61 ~31 ~72 ~61 dirt
fill ~31 ~73 ~61 ~31 ~73 ~61 grass_block
fill ~16 ~60 ~62 ~19 ~70 ~62 stone
fill ~16 ~71 ~62 ~19 ~73 ~62 dirt
fill ~16 ~74 ~62 ~19 ~74 ~62 grass_block
fill ~20 ~60 ~62 ~20 ~69 ~62 stone
fill ~20 ~70 ~62 ~20 ~72 ~62 dirt
fill ~20 ~73 ~62 ~20 ~73 ~62 grass_block
fill ~21 ~60 ~62 ~31 ~70 ~62 stone
fill ~21 ~71 ~62 ~31 ~73 ~62 dirt
fill ~21 ~74 ~62 ~31 ~74 ~62 grass_block
fill ~16 ~60 ~63 ~31 ~70 ~63 stone
fill ~16 ~71 ~63 ~31 ~73 ~63 dirt
fill ~16 ~74 ~63 ~31 ~74 ~63 grass_block