fill ~368 ~60 ~112 ~375 ~64 ~112 stone
fill ~368 ~65 ~112 ~375 ~67 ~112 dirt
fill ~368 ~68 ~112 ~375 ~68 ~112 grass_block
fill ~376 ~60 ~112 ~381 ~63 ~112 stone
fill ~376 ~64 ~112 ~381 ~66 ~112 dirt
fill ~376 ~67 ~112 ~381 ~67 ~112 grass_block
fill ~382 ~60 ~112 ~383 ~62 ~112 stone
fill ~382 ~63 ~112 ~383 ~65 ~112 dirt
fill ~382 ~66 ~112 ~383 ~66 ~112 grass_block
fill ~368 ~60 ~113 ~375 ~64 ~113 stone
fill ~368 ~65 ~113 ~375 ~67 ~113 dirt
fill ~368 ~68 ~113 ~375 ~68 ~113 grass_block
fill ~376 ~60 ~113 ~381 ~63 ~113 stone
fill ~376 ~64 ~113 ~381 ~66 ~113 dirt
fill ~376 ~67 ~113 ~381 ~67 ~113 grass_block
fill ~382 ~60 ~113 ~383 ~62 ~113 stone
fill ~382 ~63 ~113 ~383 ~65 ~113 dirt
fill ~382 ~66 ~113 ~383 ~66 ~113 grass_block
fill ~368 ~60 ~114 ~375 ~64 ~114 stone
fill ~368 ~65 ~114 ~375 ~67 ~114 dirt
fill ~368 ~68 ~114 ~375 ~68 ~114 grass_block
fill ~376 ~60 ~114 ~381 ~63 ~114 stone
fill ~376 ~64 ~114 ~381 ~66 ~114 dirt
fill ~376 ~67 ~114 ~381 ~67 ~114 grass_block
fill ~382 ~60 ~114 ~383 ~62 ~114 stone
fill ~382 ~63 ~114 ~383 ~65 ~114 dirt
fill ~382 ~66 ~114 ~383 ~66 ~114 grass_block
fill ~368 ~60 ~115 ~375 ~64 ~115 stone
fill ~368 ~65 ~115 ~375 ~67 ~115 dirt
fill ~368 ~68 ~115 ~375 ~68 ~115 grass_block
fill ~376 ~60 ~115 ~381 ~63 ~115 stone
fill ~376 ~64 ~115 ~381 ~66 ~115 dirt
fill ~376 ~67 ~115 ~381 ~67 ~115 grass_block
fill ~382 ~60 ~115 ~383 ~62 ~115 stone
fill ~382 ~63 ~115 ~383 ~65 ~115 dirt
fill ~382 ~66 ~115 ~383 ~66 ~115 grass_block
fill ~368 ~60 ~116 ~375 ~64 ~116 stone
fill ~368 ~65 ~116 ~375 ~67 ~116 dirt
fill ~368 ~68 ~116 ~375 ~68 ~116 grass_block
fill ~376 ~60 ~116 ~380 ~63 ~116 stone
fill ~376 ~64 ~116 ~380 ~66 ~116 dirt
fill ~376 ~67 ~116 ~380 ~67 ~116 grass_block
fill ~381 ~60 ~116 ~383 ~62 ~116 stone
fill ~381 ~63 ~116 ~383 ~65 ~116 dirt
fill ~381 ~66 ~116 ~383 ~66 ~116 grass_block
fill ~368 ~60 ~117 ~375 ~64 ~117 stone
fill ~368 ~65 ~117 ~375 ~67 ~117 dirt
fill ~368 ~68 ~117 ~375 ~68 ~117 grass_block
fill ~376 ~60 ~117 ~380 ~63 ~117 stone
fill ~376 ~64 ~117 ~380 ~66 ~117 dirt
fill ~376 ~67 ~117 ~380 ~67 ~117 grass_block
fill ~381 ~60 ~117 ~383 ~62 ~117 stone
fill ~381 ~63 ~117 ~383 ~65 ~117 dirt
fill ~381 ~66 ~117 ~383 ~66 ~117 grass_block
fill ~368 ~60 ~118 ~368 ~63 ~118 stone
fill ~368 ~64 ~118 ~368 ~66 ~118 dirt
fill ~368 ~67 ~118 ~368 ~67 ~118 grass_block
fill ~369 ~60 ~118 ~375 ~64 ~118 stone
fill ~369 ~65 ~118 ~375 ~67 ~118 dirt
fill ~369 ~68 ~118 ~375 ~68 ~118 grass_block
fill ~376 ~60 ~118 ~380 ~63 ~118 stone
fill ~376 ~64 ~118 ~380 ~66 ~118 dirt
fill ~376 ~67 ~118 ~380 ~67 ~118 grass_block
fill ~381 ~60 ~118 ~383 ~62 ~118 stone
fill ~381 ~63 ~118 ~383 ~65 ~118 dirt
fill ~381 ~66 ~118 ~383 ~66 ~118 grass_block
fill ~368 ~60 ~119 ~368 ~63 ~119 stone
fill ~368 ~64 ~119 ~368 ~66 ~119 dirt
fill ~368 ~67 ~119 ~368 ~67 ~119 grass_block
fill ~369 ~60 ~119 ~375 ~64 ~119 stone
fill ~369 ~65 ~119 ~375 ~67 ~119 dirt
fill ~369 ~68 ~119 ~375 ~68 ~119 grass_block
fill ~376 ~60 ~119 ~380 ~63 ~119 stone
fill ~376 ~64 ~119 ~380 ~66 ~119 dirt
fill ~376 ~67 ~119 ~380 ~67 ~119 grass_block
fill ~381 ~60 ~119 ~383 ~62 ~119 stone
fill ~381 ~63 ~119 ~383 ~65 ~119 dirt
fill ~381 ~66 ~119 ~383 ~66 ~119 grass_block
fill ~368 ~60 ~120 ~368 ~63 ~120 stone
fill ~368 ~64 ~120 ~368 ~66 ~120 dirt
fill ~368 ~67 ~120 ~368 ~67 ~120 grass_block
fill ~369 ~60 ~120 ~375 ~64 ~120 stone
fill ~369 ~65 ~120 ~375 ~67 ~120 dirt
fill ~369 ~68 ~120 ~375 ~68 ~120 grass_block
fill ~376 ~60 ~120 ~380 ~63 ~120 stone
fill ~376 ~64 ~120 ~380 ~66 ~120 dirt
fill ~376 ~67 ~120 ~380 ~67 ~120 grass_block
fill ~381 ~60 ~120 ~383 ~62 ~120 stone
fill ~381 ~63 ~120 ~383 ~65 ~120 dirt
fill ~381 ~66 ~120 ~383 ~66 ~120 grass_block
fill ~368 ~60 ~121 ~369 ~63 ~121 stone
fill ~368 ~64 ~121 ~369 ~66 ~121 dirt
fill ~368 ~67 ~121 ~369 ~67 ~121 grass_block
fill ~370 ~60 ~121 ~375 ~64 ~121 stone
fill ~370 ~65 ~121 ~375 ~67 ~121 dirt
fill ~370 ~68 ~121 ~375 ~68 ~121 grass_block
fill ~376 ~60 ~121 ~380 ~63 ~121 stone
fill ~376 ~64 ~121 ~380 ~66 ~121 dirt
fill ~376 ~67 ~121 ~380 ~67 ~121 grass_block
fill ~381 ~60 ~121 ~383 ~62 ~121 stone
fill ~381 ~63 ~121 ~383 ~65 ~121 dirt
fill ~381 ~66 ~121 ~383 ~66 ~121 grass_block
fill ~368 ~60 ~122 ~369 ~63 ~122 stone
fill ~368 ~64 ~122 ~369 ~66 ~122 dirt
fill ~368 ~67 ~122 ~369 ~67 ~122 grass_block
fill ~370 ~60 ~122 ~374 ~64 ~122 stone
fill ~370 ~65 ~122 ~374 ~67 ~122 dirt
fill ~370 ~68 ~122 ~374 ~68 ~122 grass_block
fill ~375 ~60 ~122 ~380 ~63 ~122 stone
fill ~375 ~64 ~122 ~380 ~66 ~122 dirt
fill ~375 ~67 ~122 ~380 ~67 ~122 grass_block
fill ~381 ~60 ~122 ~383 ~62 ~122 stone
fill ~381 ~63 ~122 ~383 ~65 ~122 dirt
fill ~381 ~66 ~122 ~383 ~66 ~122 grass_block
fill ~368 ~60 ~123 ~371 ~63 ~123 stone
fill ~368 ~64 ~123 ~371 ~66 ~123 dirt
fill ~368 ~67 ~123 ~371 ~67 ~123 grass_block
fill ~372 ~60 ~123 ~375 ~64 ~123 stone
fill ~372 ~65 ~123 ~375 ~67 ~123 dirt
fill ~372 ~68 ~123 ~375 ~68 ~123 grass_block
fill ~376 ~60 ~123 ~380 ~63 ~123 stone
fill ~376 ~64 ~123 ~380 ~66 ~123 dirt
fill ~376 ~67 ~123 ~380 ~67 ~123 grass_block
fill ~381 ~60 ~123 ~383 ~62 ~123 stone
fill ~381 ~63 ~123 ~383 ~65 ~123 dirt
fill ~381 ~66 ~123 ~383 ~66 ~123 grass_block
fill ~368 ~60 ~124 ~372 ~63 ~124 stone
fill ~368 ~64 ~124 ~372 ~66 ~124 dirt
fill ~368 ~67 ~124 ~372 ~67 ~124 grass_block
fill ~373 ~60 ~124 ~375 ~64 ~124 stone
fill ~373 ~65 ~124 ~375 ~67 ~124 dirt
fill ~373 ~68 ~124 ~375 ~68 ~124 grass_block
fill ~376 ~60 ~124 ~380 ~63 ~124 stone
fill ~376 ~64 ~124 ~380 ~66 ~124 dirt
fill ~376 ~67 ~124 ~380 ~67 ~124 grass_block
fill ~381 ~60 ~124 ~383 ~62 ~124 stone
fill ~381 ~63 ~124 ~383 ~65 ~124 dirt
fill ~381 ~66 ~124 ~383 ~66 ~124 grass_block
fill ~368 ~60 ~125 ~381 ~63 ~125 stone
fill ~368 ~64 ~125 ~381 ~66 ~125 dirt
fill ~368 ~67 ~125 ~381 ~67 ~125 grass_block
fill ~382 ~60 ~125 ~383 ~62 ~125 stone
fill ~382 ~63 ~125 ~383 ~65 ~125 dirt
fill ~382 ~66 ~125 ~383 ~66 ~125 grass_block
fill ~368 ~60 ~126 ~368 ~62 ~126 stone
fill ~368 ~63 ~126 ~368 ~65 ~126 dirt
fill ~368 ~66 ~126 ~368 ~66 ~126 grass_block
fill ~369 ~60 ~126 ~380 ~63 ~126 stone
fill ~369 ~64 ~126 ~380 ~66 ~126 dirt
fill ~369 ~67 ~126 ~380 ~67 ~126 grass_block
fill ~381 ~60 ~126 ~383 ~62 ~126 stone
fill ~381 ~63 ~126 ~383 ~65 ~126 dirt
fill ~381 ~66 ~126 ~383 ~66 ~126 grass_block
fill ~368 ~60 ~127 ~370 ~62 ~127 stone
fill ~368 ~63 ~127 ~370 ~65 ~127 dirt
fill ~368 ~66 ~127 ~370 ~66 ~127 grass_block
fill ~371 ~60 ~127 ~380 ~63 ~127 stone
fill ~371 ~64 ~127 ~380 ~66 ~127 dirt
fill ~371 ~67 ~127 ~380 ~67 ~127 grass_block
fill ~381 ~60 ~127 ~383 ~62 ~127 stone
fill ~381 ~63 ~127 ~383 ~65 ~127 dirt
fill ~381 ~66 ~127 ~383 ~66 ~127 grass_block