fill ~448 ~60 ~0 ~451 ~64 ~0 stone
fill ~448 ~65 ~0 ~451 ~67 ~0 dirt
fill ~448 ~68 ~0 ~451 ~68 ~0 grass_block
fill ~452 ~60 ~0 ~461 ~65 ~0 stone
fill ~452 ~66 ~0 ~461 ~68 ~0 dirt
fill ~452 ~69 ~0 ~461 ~69 ~0 grass_block
fill ~462 ~60 ~0 ~463 ~64 ~0 stone
fill ~462 ~65 ~0 ~463 ~67 ~0 dirt
fill ~462 ~68 ~0 ~463 ~68 ~0 grass_block
fill ~448 ~60 ~1 ~449 ~63 ~1 stone
fill ~448 ~64 ~1 ~449 ~66 ~1 dirt
fill ~448 ~67 ~1 ~449 ~67 ~1 grass_block
fill ~450 ~60 ~1 ~451 ~64 ~1 stone
fill ~450 ~65 ~1 ~451 ~67 ~1 dirt
fill ~450 ~68 ~1 ~451 ~68 ~1 grass_block
fill ~452 ~60 ~1 ~461 ~65 ~1 stone
fill ~452 ~66 ~1 ~461 ~68 ~1 dirt
fill ~452 ~69 ~1 ~461 ~69 ~1 grass_block
fill ~462 ~60 ~1 ~463 ~64 ~1 stone
fill ~462 ~65 ~1 ~463 ~67 ~1 dirt
fill ~462 ~68 ~1 ~463 ~68 ~1 grass_block
fill ~448 ~60 ~2 ~449 ~63 ~2 stone
fill ~448 ~64 ~2 ~449 ~66 ~2 dirt
fill ~448 ~67 ~2 ~449 ~67 ~2 grass_block
fill ~450 ~60 ~2 ~451 ~64 ~2 stone
fill ~450 ~65 ~2 ~451 ~67 ~2 dirt
fill ~450 ~68 ~2 ~451 ~68 ~2 grass_block
fill ~452 ~60 ~2 ~461 ~65 ~2 stone
fill ~452 ~66 ~2 ~461 ~68 ~2 dirt
fill ~452 ~69 ~2 ~461 ~69 ~2 grass_block
fill ~462 ~60 ~2 ~463 ~64 ~2 stone
fill ~462 ~65 ~2 ~463 ~67 ~2 dirt
fill ~462 ~68 ~2 ~463 ~68 ~2 grass_block
fill ~448 ~60 ~3 ~448 ~63 ~3 stone
fill ~448 ~64 ~3 ~448 ~66 ~3 dirt
fill ~448 ~67 ~3 ~448 ~67 ~3 grass_block
fill ~449 ~60 ~3 ~451 ~64 ~3 stone
fill ~449 ~65 ~3 ~451 ~67 ~3 dirt
fill ~449 ~68 ~3 ~451 ~68 ~3 grass_block
fill ~452 ~60 ~3 ~462 ~65 ~3 stone
fill ~452 ~66 ~3 ~462 ~68 ~3 dirt
fill ~452 ~69 ~3 ~462 ~69 ~3 grass_block
fill ~463 ~60 ~3 ~463 ~64 ~3 stone
fill ~463 ~65 ~3 ~463 ~67 ~3 dirt
fill ~463 ~68 ~3 ~463 ~68 ~3 grass_block
fill ~448 ~60 ~4 ~448 ~63 ~4 stone
fill ~448 ~64 ~4 ~448 ~66 ~4 dirt
fill ~448 ~67 ~4 ~448 ~67 ~4 grass_block
fill ~449 ~60 ~4 ~451 ~64 ~4 stone
fill ~449 ~65 ~4 ~451 ~67 ~4 dirt
fill ~449 ~68 ~4 ~451 ~68 ~4 grass_block
fill ~452 ~60 ~4 ~463 ~65 ~4 stone
fill ~452 ~66 ~4 ~463 ~68 ~4 dirt
fill ~452 ~69 ~4 ~463 ~69 ~4 grass_block
fill ~448 ~60 ~5 ~451 ~64 ~5 stone
fill ~448 ~65 ~5 ~451 ~67 ~5 dirt
fill ~448 ~68 ~5 ~451 ~68 ~5 grass_block
fill ~452 ~60 ~5 ~463 ~65 ~5 stone
fill ~452 ~66 ~5 ~463 ~68 ~5 dirt
fill ~452 ~69 ~5 ~463 ~69 ~5 grass_block
fill ~448 ~60 ~6 ~453 ~64 ~6 stone
fill ~448 ~65 ~6 ~453 ~67 ~6 dirt
fill ~448 ~68 ~6 ~453 ~68 ~6 grass_block
fill ~454 ~60 ~6 ~463 ~65 ~6 stone
fill ~454 ~66 ~6 ~463 ~68 ~6 dirt
fill ~454 ~69 ~6 ~463 ~69 ~6 grass_block
fill ~448 ~60 ~7 ~456 ~64 ~7 stone
fill ~448 ~65 ~7 ~456 ~67 ~7 dirt
fill ~448 ~68 ~7 ~456 ~68 ~7 grass_block
fill ~457 ~60 ~7 ~463 ~65 ~7 stone
fill ~457 ~66 ~7 ~463 ~68 ~7 dirt
fill ~457 ~69 ~7 ~463 ~69 ~7 grass_block
fill ~448 ~60 ~8 ~462 ~64 ~8 stone
fill ~448 ~65 ~8 ~462 ~67 ~8 dirt
fill ~448 ~68 ~8 ~462 ~68 ~8 grass_block
fill ~463 ~60 ~8 ~463 ~65 ~8 stone
fill ~463 ~66 ~8 ~463 ~68 ~8 dirt
fill ~463 ~69 ~8 ~463 ~69 ~8 grass_block
fill ~448 ~60 ~9 ~460 ~64 ~9 stone
fill ~448 ~65 ~9 ~460 ~67 ~9 dirt
fill ~448 ~68 ~9 ~460 ~68 ~9 grass_block
fill ~461 ~60 ~9 ~461 ~63 ~9 stone
fill ~461 ~64 ~9 ~461 ~66 ~9 dirt
fill ~461 ~67 ~9 ~461 ~67 ~9 grass_block
fill ~462 ~60 ~9 ~463 ~64 ~9 stone
fill ~462 ~65 ~9 ~463 ~67 ~9 dirt
fill ~462 ~68 ~9 ~463 ~68 ~9 grass_block
fill ~448 ~60 ~10 ~458 ~64 ~10 stone
fill ~448 ~65 ~10 ~458 ~67 ~10 dirt
fill ~448 ~68 ~10 ~458 ~68 ~10 grass_block
fill ~459 ~60 ~10 ~460 ~63 ~10 stone
fill ~459 ~64 ~10 ~460 ~66 ~10 dirt
fill ~459 ~67 ~10 ~460 ~67 ~10 grass_block
fill ~461 ~60 ~10 ~463 ~64 ~10 stone
fill ~461 ~65 ~10 ~463 ~67 ~10 dirt
fill ~461 ~68 ~10 ~463 ~68 ~10 grass_block
fill ~448 ~60 ~11 ~456 ~64 ~11 stone
fill ~448 ~65 ~11 ~456 ~67 ~11 dirt
fill ~448 ~68 ~11 ~456 ~68 ~11 grass_block
fill ~457 ~60 ~11 ~459 ~63 ~11 stone
fill ~457 ~64 ~11 ~459 ~66 ~11 dirt
fill ~457 ~67 ~11 ~459 ~67 ~11 grass_block
fill ~460 ~60 ~11 ~463 ~64 ~11 stone
fill ~460 ~65 ~11 ~463 ~67 ~11 dirt
fill ~460 ~68 ~11 ~463 ~68 ~11 grass_block
fill ~448 ~60 ~12 ~452 ~64 ~12 stone
fill ~448 ~65 ~12 ~452 ~67 ~12 dirt
fill ~448 ~68 ~12 ~452 ~68 ~12 grass_block
fill ~453 ~60 ~12 ~459 ~63 ~12 stone
fill ~453 ~64 ~12 ~459 ~66 ~12 dirt
fill ~453 ~67 ~12 ~459 ~67 ~12 grass_block
fill ~460 ~60 ~12 ~461 ~64 ~12 stone
fill ~460 ~65 ~12 ~461 ~67 ~12 dirt
fill ~460 ~68 ~12 ~461 ~68 ~12 grass_block
fill ~462 ~60 ~12 ~463 ~65 ~12 stone
fill ~462 ~66 ~12 ~463 ~68 ~12 dirt
fill ~462 ~69 ~12 ~463 ~69 ~12 grass_block
fill ~448 ~60 ~13 ~451 ~64 ~13 stone
fill ~448 ~65 ~13 ~451 ~67 ~13 dirt
fill ~448 ~68 ~13 ~451 ~68 ~13 grass_block
fill ~452 ~60 ~13 ~459 ~63 ~13 stone
fill ~452 ~64 ~13 ~459 ~66 ~13 dirt
fill ~452 ~67 ~13 ~459 ~67 ~13 grass_block
fill ~460 ~60 ~13 ~462 ~64 ~13 stone
fill ~460 ~65 ~13 ~462 ~67 ~13 dirt
fill ~460 ~68 ~13 ~462 ~68 ~13 grass_block
fill ~463 ~60 ~13 ~463 ~65 ~13 stone
fill ~463 ~66 ~13 ~463 ~68 ~13 dirt
fill ~463 ~69 ~13 ~463 ~69 ~13 grass_block
fill ~448 ~60 ~14 ~451 ~64 ~14 stone
fill ~448 ~65 ~14 ~451 ~67 ~14 dirt
fill ~448 ~68 ~14 ~451 ~68 ~14 grass_block
fill ~452 ~60 ~14 ~460 ~63 ~14 stone
fill ~452 ~64 ~14 ~460 ~66 ~14 dirt
fill ~452 ~67 ~14 ~460 ~67 ~14 grass_block
fill ~461 ~60 ~14 ~462 ~64 ~14 stone
fill ~461 ~65 ~14 ~462 ~67 ~14 dirt
fill ~461 ~68 ~14 ~462 ~68 ~14 grass_block
fill ~463 ~60 ~14 ~463 ~65 ~14 stone
fill ~463 ~66 ~14 ~463 ~68 ~14 dirt
fill ~463 ~69 ~14 ~463 ~69 ~14 grass_block
fill ~448 ~60 ~15 ~450 ~64 ~15 stone
fill ~448 ~65 ~15 ~450 ~67 ~15 dirt
fill ~448 ~68 ~15 ~450 ~68 ~15 grass_block
fill ~451 ~60 ~15 ~458 ~63 ~15 stone
fill ~451 ~64 ~15 ~458 ~66 ~15 dirt
fill ~451 ~67 ~15 ~458 ~67 ~15 grass_block
fill ~459 ~60 ~15 ~462 ~64 ~15 stone
fill ~459 ~65 ~15 ~462 ~67 ~15 dirt
fill ~459 ~68 ~15 ~462 ~68 ~15 grass_block
fill ~463 ~60 ~15 ~463 ~65 ~15 stone
fill ~463 ~66 ~15 ~463 ~68 ~15 dirt
fill ~463 ~69 ~15 ~463 ~69 ~15 grass_block