fill ~432 ~60 ~32 ~432 ~63 ~32 stone
fill ~432 ~64 ~32 ~432 ~66 ~32 dirt
fill ~432 ~67 ~32 ~432 ~67 ~32 grass_block
fill ~433 ~60 ~32 ~438 ~62 ~32 stone
fill ~433 ~63 ~32 ~438 ~65 ~32 dirt
fill ~433 ~66 ~32 ~438 ~66 ~32 grass_block
fill ~439 ~60 ~32 ~447 ~61 ~32 stone
fill ~439 ~62 ~32 ~447 ~64 ~32 dirt
fill ~439 ~65 ~32 ~447 ~65 ~32 grass_block
fill ~432 ~60 ~33 ~433 ~63 ~33 stone
fill ~432 ~64 ~33 ~433 ~66 ~33 dirt
fill ~432 ~67 ~33 ~433 ~67 ~33 grass_block
fill ~434 ~60 ~33 ~438 ~62 ~33 stone
fill ~434 ~63 ~33 ~438 ~65 ~33 dirt
fill ~434 ~66 ~33 ~438 ~66 ~33 grass_block
fill ~439 ~60 ~33 ~447 ~61 ~33 stone
fill ~439 ~62 ~33 ~447 ~64 ~33 dirt
fill ~439 ~65 ~33 ~447 ~65 ~33 grass_block
fill ~432 ~60 ~34 ~433 ~63 ~34 stone
fill ~432 ~64 ~34 ~433 ~66 ~34 dirt
fill ~432 ~67 ~34 ~433 ~67 ~34 grass_block
fill ~434 ~60 ~34 ~438 ~62 ~34 stone
fill ~434 ~63 ~34 ~438 ~65 ~34 dirt
fill ~434 ~66 ~34 ~438 ~66 ~34 grass_block
fill ~439 ~60 ~34 ~447 ~61 ~34 stone
fill ~439 ~62 ~34 ~447 ~64 ~34 dirt
fill ~439 ~65 ~34 ~447 ~65 ~34 grass_block
fill ~432 ~60 ~35 ~434 ~63 ~35 stone
fill ~432 ~64 ~35 ~434 ~66 ~35 dirt
fill ~432 ~67 ~35 ~434 ~67 ~35 grass_block
fill ~435 ~60 ~35 ~438 ~62 ~35 stone
fill ~435 ~63 ~35 ~438 ~65 ~35 dirt
fill ~435 ~66 ~35 ~438 ~66 ~35 grass_block
fill ~439 ~60 ~35 ~441 ~61 ~35 stone
fill ~439 ~62 ~35 ~441 ~64 ~35 dirt
fill ~439 ~65 ~35 ~441 ~65 ~35 grass_block
fill ~442 ~60 ~35 ~446 ~62 ~35 stone
fill ~442 ~63 ~35 ~446 ~65 ~35 dirt
fill ~442 ~66 ~35 ~446 ~66 ~35 grass_block
fill ~447 ~60 ~35 ~447 ~61 ~35 stone
fill ~447 ~62 ~35 ~447 ~64 ~35 dirt
fill ~447 ~65 ~35 ~447 ~65 ~35 grass_block
fill ~432 ~60 ~36 ~434 ~63 ~36 stone
fill ~432 ~64 ~36 ~434 ~66 ~36 dirt
fill ~432 ~67 ~36 ~434 ~67 ~36 grass_block
fill ~435 ~60 ~36 ~437 ~62 ~36 stone
fill ~435 ~63 ~36 ~437 ~65 ~36 dirt
fill ~435 ~66 ~36 ~437 ~66 ~36 grass_block
fill ~438 ~60 ~36 ~441 ~61 ~36 stone
fill ~438 ~62 ~36 ~441 ~64 ~36 dirt
fill ~438 ~65 ~36 ~441 ~65 ~36 grass_block
fill ~442 ~60 ~36 ~443 ~62 ~36 stone
fill ~442 ~63 ~36 ~443 ~65 ~36 dirt
fill ~442 ~66 ~36 ~443 ~66 ~36 grass_block
fill ~444 ~60 ~36 ~446 ~63 ~36 stone
fill ~444 ~64 ~36 ~446 ~66 ~36 dirt
fill ~444 ~67 ~36 ~446 ~67 ~36 grass_block
fill ~447 ~60 ~36 ~447 ~62 ~36 stone
fill ~447 ~63 ~36 ~447 ~65 ~36 dirt
fill ~447 ~66 ~36 ~447 ~66 ~36 grass_block
fill ~432 ~60 ~37 ~434 ~63 ~37 stone
fill ~432 ~64 ~37 ~434 ~66 ~37 dirt
fill ~432 ~67 ~37 ~434 ~67 ~37 grass_block
fill ~435 ~60 ~37 ~438 ~62 ~37 stone
fill ~435 ~63 ~37 ~438 ~65 ~37 dirt
fill ~435 ~66 ~37 ~438 ~66 ~37 grass_block
fill ~439 ~60 ~37 ~441 ~61 ~37 stone
fill ~439 ~62 ~37 ~441 ~64 ~37 dirt
fill ~439 ~65 ~37 ~441 ~65 ~37 grass_block
fill ~442 ~60 ~37 ~443 ~62 ~37 stone
fill ~442 ~63 ~37 ~443 ~65 ~37 dirt
fill ~442 ~66 ~37 ~443 ~66 ~37 grass_block
fill ~444 ~60 ~37 ~447 ~63 ~37 stone
fill ~444 ~64 ~37 ~447 ~66 ~37 dirt
fill ~444 ~67 ~37 ~447 ~67 ~37 grass_block
fill ~432 ~60 ~38 ~434 ~63 ~38 stone
fill ~432 ~64 ~38 ~434 ~66 ~38 dirt
fill ~432 ~67 ~38 ~434 ~67 ~38 grass_block
fill ~435 ~60 ~38 ~438 ~62 ~38 stone
fill ~435 ~63 ~38 ~438 ~65 ~38 dirt
fill ~435 ~66 ~38 ~438 ~66 ~38 grass_block
fill ~439 ~60 ~38 ~441 ~61 ~38 stone
fill ~439 ~62 ~38 ~441 ~64 ~38 dirt
fill ~439 ~65 ~38 ~441 ~65 ~38 grass_block
fill ~442 ~60 ~38 ~442 ~62 ~38 stone
fill ~442 ~63 ~38 ~442 ~65 ~38 dirt
fill ~442 ~66 ~38 ~442 ~66 ~38 grass_block
fill ~443 ~60 ~38 ~444 ~63 ~38 stone
fill ~443 ~64 ~38 ~444 ~66 ~38 dirt
fill ~443 ~67 ~38 ~444 ~67 ~38 grass_block
fill ~445 ~60 ~38 ~447 ~64 ~38 stone
fill ~445 ~65 ~38 ~447 ~67 ~38 dirt
fill ~445 ~68 ~38 ~447 ~68 ~38 grass_block
fill ~432 ~60 ~39 ~434 ~63 ~39 stone
fill ~432 ~64 ~39 ~434 ~66 ~39 dirt
fill ~432 ~67 ~39 ~434 ~67 ~39 grass_block
fill ~435 ~60 ~39 ~438 ~62 ~39 stone
fill ~435 ~63 ~39 ~438 ~65 ~39 dirt
fill ~435 ~66 ~39 ~438 ~66 ~39 grass_block
fill ~439 ~60 ~39 ~440 ~61 ~39 stone
fill ~439 ~62 ~39 ~440 ~64 ~39 dirt
fill ~439 ~65 ~39 ~440 ~65 ~39 grass_block
fill ~441 ~60 ~39 ~443 ~62 ~39 stone
fill ~441 ~63 ~39 ~443 ~65 ~39 dirt
fill ~441 ~66 ~39 ~443 ~66 ~39 grass_block
fill ~444 ~60 ~39 ~444 ~63 ~39 stone
fill ~444 ~64 ~39 ~444 ~66 ~39 dirt
fill ~444 ~67 ~39 ~444 ~67 ~39 grass_block
fill ~445 ~60 ~39 ~446 ~64 ~39 stone
fill ~445 ~65 ~39 ~446 ~67 ~39 dirt
fill ~445 ~68 ~39 ~446 ~68 ~39 grass_block
fill ~447 ~60 ~39 ~447 ~65 ~39 stone
fill ~447 ~66 ~39 ~447 ~68 ~39 dirt
fill ~447 ~69 ~39 ~447 ~69 ~39 grass_block
fill ~432 ~60 ~40 ~434 ~63 ~40 stone
fill ~432 ~64 ~40 ~434 ~66 ~40 dirt
fill ~432 ~67 ~40 ~434 ~67 ~40 grass_block
fill ~435 ~60 ~40 ~438 ~62 ~40 stone
fill ~435 ~63 ~40 ~438 ~65 ~40 dirt
fill ~435 ~66 ~40 ~438 ~66 ~40 grass_block
fill ~439 ~60 ~40 ~441 ~61 ~40 stone
fill ~439 ~62 ~40 ~441 ~64 ~40 dirt
fill ~439 ~65 ~40 ~441 ~65 ~40 grass_block
fill ~442 ~60 ~40 ~442 ~62 ~40 stone
fill ~442 ~63 ~40 ~442 ~65 ~40 dirt
fill ~442 ~66 ~40 ~442 ~66 ~40 grass_block
fill ~443 ~60 ~40 ~444 ~63 ~40 stone
fill ~443 ~64 ~40 ~444 ~66 ~40 dirt
fill ~443 ~67 ~40 ~444 ~67 ~40 grass_block
fill ~445 ~60 ~40 ~446 ~64 ~40 stone
fill ~445 ~65 ~40 ~446 ~67 ~40 dirt
fill ~445 ~68 ~40 ~446 ~68 ~40 grass_block
fill ~447 ~60 ~40 ~447 ~65 ~40 stone
fill ~447 ~66 ~40 ~447 ~68 ~40 dirt
fill ~447 ~69 ~40 ~447 ~69 ~40 grass_block
fill ~432 ~60 ~41 ~432 ~63 ~41 stone
fill ~432 ~64 ~41 ~432 ~66 ~41 dirt
fill ~432 ~67 ~41 ~432 ~67 ~41 grass_block
fill ~433 ~60 ~41 ~441 ~62 ~41 stone
fill ~433 ~63 ~41 ~441 ~65 ~41 dirt
fill ~433 ~66 ~41 ~441 ~66 ~41 grass_block
fill ~442 ~60 ~41 ~443 ~63 ~41 stone
fill ~442 ~64 ~41 ~443 ~66 ~41 dirt
fill ~442 ~67 ~41 ~443 ~67 ~41 grass_block
fill ~444 ~60 ~41 ~445 ~64 ~41 stone
fill ~444 ~65 ~41 ~445 ~67 ~41 dirt
fill ~444 ~68 ~41 ~445 ~68 ~41 grass_block
fill ~446 ~60 ~41 ~447 ~65 ~41 stone
fill ~446 ~66 ~41 ~447 ~68 ~41 dirt
fill ~446 ~69 ~41 ~447 ~69 ~41 grass_block
fill ~432 ~60 ~42 ~440 ~62 ~42 stone
fill ~432 ~63 ~42 ~440 ~65 ~42 dirt
fill ~432 ~66 ~42 ~440 ~66 ~42 grass_block
fill ~441 ~60 ~42 ~442 ~63 ~42 stone
fill ~441 ~64 ~42 ~442 ~66 ~42 dirt
fill ~441 ~67 ~42 ~442 ~67 ~42 grass_block
fill ~443 ~60 ~42 ~444 ~64 ~42 stone
fill ~443 ~65 ~42 ~444 ~67 ~42 dirt
fill ~443 ~68 ~42 ~444 ~68 ~42 grass_block
fill ~445 ~60 ~42 ~447 ~65 ~42 stone
fill ~445 ~66 ~42 ~447 ~68 ~42 dirt
fill ~445 ~69 ~42 ~447 ~69 ~42 grass_block
fill ~432 ~60 ~43 ~434 ~63 ~43 stone
fill ~432 ~64 ~43 ~434 ~66 ~43 dirt
fill ~432 ~67 ~43 ~434 ~67 ~43 grass_block
fill ~435 ~60 ~43 ~440 ~62 ~43 stone
fill ~435 ~63 ~43 ~440 ~65 ~43 dirt
fill ~435 ~66 ~43 ~440 ~66 ~43 grass_block
fill ~441 ~60 ~43 ~442 ~63 ~43 stone
fill ~441 ~64 ~43 ~442 ~66 ~43 dirt
fill ~441 ~67 ~43 ~442 ~67 ~43 grass_block
fill ~443 ~60 ~43 ~444 ~64 ~43 stone
fill ~443 ~65 ~43 ~444 ~67 ~43 dirt
fill ~443 ~68 ~43 ~444 ~68 ~43 grass_block
fill ~445 ~60 ~43 ~447 ~65 ~43 stone
fill ~445 ~66 ~43 ~447 ~68 ~43 dirt
fill ~445 ~69 ~43 ~447 ~69 ~43 grass_block
fill ~432 ~60 ~44 ~434 ~63 ~44 stone
fill ~432 ~64 ~44 ~434 ~66 ~44 dirt
fill ~432 ~67 ~44 ~434 ~67 ~44 grass_block
fill ~435 ~60 ~44 ~440 ~62 ~44 stone
fill ~435 ~63 ~44 ~440 ~65 ~44 dirt
fill ~435 ~66 ~44 ~440 ~66 ~44 grass_block
fill ~441 ~60 ~44 ~442 ~63 ~44 stone
fill ~441 ~64 ~44 ~442 ~66 ~44 dirt
fill ~441 ~67 ~44 ~442 ~67 ~44 grass_block
fill ~443 ~60 ~44 ~444 ~64 ~44 stone
fill ~443 ~65 ~44 ~444 ~67 ~44 dirt
fill ~443 ~68 ~44 ~444 ~68 ~44 grass_block
fill ~445 ~60 ~44 ~447 ~65 ~44 stone
fill ~445 ~66 ~44 ~447 ~68 ~44 dirt
fill ~445 ~69 ~44 ~447 ~69 ~44 grass_block
fill ~432 ~60 ~45 ~435 ~63 ~45 stone
fill ~432 ~64 ~45 ~435 ~66 ~45 dirt
fill ~432 ~67 ~45 ~435 ~67 ~45 grass_block
fill ~436 ~60 ~45 ~439 ~62 ~45 stone
fill ~436 ~63 ~45 ~439 ~65 ~45 dirt
fill ~436 ~66 ~45 ~439 ~66 ~45 grass_block
fill ~440 ~60 ~45 ~441 ~63 ~45 stone
fill ~440 ~64 ~45 ~441 ~66 ~45 dirt
fill ~440 ~67 ~45 ~441 ~67 ~45 grass_block
fill ~442 ~60 ~45 ~444 ~64 ~45 stone
fill ~442 ~65 ~45 ~444 ~67 ~45 dirt
fill ~442 ~68 ~45 ~444 ~68 ~45 grass_block
fill ~445 ~60 ~45 ~447 ~65 ~45 stone
fill ~445 ~66 ~45 ~447 ~68 ~45 dirt
fill ~445 ~69 ~45 ~447 ~69 ~45 grass_block
fill ~432 ~60 ~46 ~434 ~63 ~46 stone
fill ~432 ~64 ~46 ~434 ~66 ~46 dirt
fill ~432 ~67 ~46 ~434 ~67 ~46 grass_block
fill ~435 ~60 ~46 ~438 ~62 ~46 stone
fill ~435 ~63 ~46 ~438 ~65 ~46 dirt
fill ~435 ~66 ~46 ~438 ~66 ~46 grass_block
fill ~439 ~60 ~46 ~440 ~63 ~46 stone
fill ~439 ~64 ~46 ~440 ~66 ~46 dirt
fill ~439 ~67 ~46 ~440 ~67 ~46 grass_block
fill ~441 ~60 ~46 ~442 ~64 ~46 stone
fill ~441 ~65 ~46 ~442 ~67 ~46 dirt
fill ~441 ~68 ~46 ~442 ~68 ~46 grass_block
fill ~443 ~60 ~46 ~447 ~65 ~46 stone
fill ~443 ~66 ~46 ~447 ~68 ~46 dirt
fill ~443 ~69 ~46 ~447 ~69 ~46 grass_block
fill ~432 ~60 ~47 ~434 ~63 ~47 stone
fill ~432 ~64 ~47 ~434 ~66 ~47 dirt
fill ~432 ~67 ~47 ~434 ~67 ~47 grass_block
fill ~435 ~60 ~47 ~437 ~62 ~47 stone
fill ~435 ~63 ~47 ~437 ~65 ~47 dirt
fill ~435 ~66 ~47 ~437 ~66 ~47 grass_block
fill ~438 ~60 ~47 ~439 ~63 ~47 stone
fill ~438 ~64 ~47 ~439 ~66 ~47 dirt
fill ~438 ~67 ~47 ~439 ~67 ~47 grass_block
fill ~440 ~60 ~47 ~441 ~64 ~47 stone
fill ~440 ~65 ~47 ~441 ~67 ~47 dirt
fill ~440 ~68 ~47 ~441 ~68 ~47 grass_block
fill ~442 ~60 ~47 ~447 ~65 ~47 stone
fill ~442 ~66 ~47 ~447 ~68 ~47 dirt
fill ~442 ~69 ~47 ~447 ~69 ~47 grass_block