fill ~448 ~60 ~32 ~452 ~61 ~32 stone
fill ~448 ~62 ~32 ~452 ~64 ~32 dirt
fill ~448 ~65 ~32 ~452 ~65 ~32 grass_block
fill ~453 ~60 ~32 ~454 ~62 ~32 stone
fill ~453 ~63 ~32 ~454 ~65 ~32 dirt
fill ~453 ~66 ~32 ~454 ~66 ~32 grass_block
fill ~455 ~60 ~32 ~456 ~61 ~32 stone
fill ~455 ~62 ~32 ~456 ~64 ~32 dirt
fill ~455 ~65 ~32 ~456 ~65 ~32 grass_block
fill ~457 ~60 ~32 ~463 ~62 ~32 stone
fill ~457 ~63 ~32 ~463 ~65 ~32 dirt
fill ~457 ~66 ~32 ~463 ~66 ~32 grass_block
fill ~448 ~60 ~33 ~457 ~61 ~33 stone
fill ~448 ~62 ~33 ~457 ~64 ~33 dirt
fill ~448 ~65 ~33 ~457 ~65 ~33 grass_block
fill ~458 ~60 ~33 ~463 ~62 ~33 stone
fill ~458 ~63 ~33 ~463 ~65 ~33 dirt
fill ~458 ~66 ~33 ~463 ~66 ~33 grass_block
fill ~448 ~60 ~34 ~459 ~61 ~34 stone
fill ~448 ~62 ~34 ~459 ~64 ~34 dirt
fill ~448 ~65 ~34 ~459 ~65 ~34 grass_block
fill ~460 ~60 ~34 ~463 ~62 ~34 stone
fill ~460 ~63 ~34 ~463 ~65 ~34 dirt
fill ~460 ~66 ~34 ~463 ~66 ~34 grass_block
fill ~448 ~60 ~35 ~462 ~61 ~35 stone
fill ~448 ~62 ~35 ~462 ~64 ~35 dirt
fill ~448 ~65 ~35 ~462 ~65 ~35 grass_block
fill ~463 ~60 ~35 ~463 ~62 ~35 stone
fill ~463 ~63 ~35 ~463 ~65 ~35 dirt
fill ~463 ~66 ~35 ~463 ~66 ~35 grass_block
fill ~448 ~60 ~36 ~450 ~62 ~36 stone
fill ~448 ~63 ~36 ~450 ~65 ~36 dirt
fill ~448 ~66 ~36 ~450 ~66 ~36 grass_block
fill ~451 ~60 ~36 ~463 ~61 ~36 stone
fill ~451 ~62 ~36 ~463 ~64 ~36 dirt
fill ~451 ~65 ~36 ~463 ~65 ~36 grass_block
fill ~448 ~60 ~37 ~449 ~63 ~37 stone
fill ~448 ~64 ~37 ~449 ~66 ~37 dirt
fill ~448 ~67 ~37 ~449 ~67 ~37 grass_block
fill ~450 ~60 ~37 ~455 ~62 ~37 stone
fill ~450 ~63 ~37 ~455 ~65 ~37 dirt
fill ~450 ~66 ~37 ~455 ~66 ~37 grass_block
fill ~456 ~60 ~37 ~463 ~61 ~37 stone
fill ~456 ~62 ~37 ~463 ~64 ~37 dirt
fill ~456 ~65 ~37 ~463 ~65 ~37 grass_block
fill ~448 ~60 ~38 ~448 ~64 ~38 stone
fill ~448 ~65 ~38 ~448 ~67 ~38 dirt
fill ~448 ~68 ~38 ~448 ~68 ~38 grass_block
fill ~449 ~60 ~38 ~451 ~63 ~38 stone
fill ~449 ~64 ~38 ~451 ~66 ~38 dirt
fill ~449 ~67 ~38 ~451 ~67 ~38 grass_block
fill ~452 ~60 ~38 ~458 ~62 ~38 stone
fill ~452 ~63 ~38 ~458 ~65 ~38 dirt
fill ~452 ~66 ~38 ~458 ~66 ~38 grass_block
fill ~459 ~60 ~38 ~463 ~61 ~38 stone
fill ~459 ~62 ~38 ~463 ~64 ~38 dirt
fill ~459 ~65 ~38 ~463 ~65 ~38 grass_block
fill ~448 ~60 ~39 ~450 ~64 ~39 stone
fill ~448 ~65 ~39 ~450 ~67 ~39 dirt
fill ~448 ~68 ~39 ~450 ~68 ~39 grass_block
fill ~451 ~60 ~39 ~455 ~63 ~39 stone
fill ~451 ~64 ~39 ~455 ~66 ~39 dirt
fill ~451 ~67 ~39 ~455 ~67 ~39 grass_block
fill ~456 ~60 ~39 ~460 ~62 ~39 stone
fill ~456 ~63 ~39 ~460 ~65 ~39 dirt
fill ~456 ~66 ~39 ~460 ~66 ~39 grass_block
fill ~461 ~60 ~39 ~463 ~61 ~39 stone
fill ~461 ~62 ~39 ~463 ~64 ~39 dirt
fill ~461 ~65 ~39 ~463 ~65 ~39 grass_block
fill ~448 ~60 ~40 ~451 ~64 ~40 stone
fill ~448 ~65 ~40 ~451 ~67 ~40 dirt
fill ~448 ~68 ~40 ~451 ~68 ~40 grass_block
fill ~452 ~60 ~40 ~456 ~63 ~40 stone
fill ~452 ~64 ~40 ~456 ~66 ~40 dirt
fill ~452 ~67 ~40 ~456 ~67 ~40 grass_block
fill ~457 ~60 ~40 ~460 ~62 ~40 stone
fill ~457 ~63 ~40 ~460 ~65 ~40 dirt
fill ~457 ~66 ~40 ~460 ~66 ~40 grass_block
fill ~461 ~60 ~40 ~463 ~61 ~40 stone
fill ~461 ~62 ~40 ~463 ~64 ~40 dirt
fill ~461 ~65 ~40 ~463 ~65 ~40 grass_block
fill ~448 ~60 ~41 ~448 ~65 ~41 stone
fill ~448 ~66 ~41 ~448 ~68 ~41 dirt
fill ~448 ~69 ~41 ~448 ~69 ~41 grass_block
fill ~449 ~60 ~41 ~451 ~64 ~41 stone
fill ~449 ~65 ~41 ~451 ~67 ~41 dirt
fill ~449 ~68 ~41 ~451 ~68 ~41 grass_block
fill ~452 ~60 ~41 ~457 ~63 ~41 stone
fill ~452 ~64 ~41 ~457 ~66 ~41 dirt
fill ~452 ~67 ~41 ~457 ~67 ~41 grass_block
fill ~458 ~60 ~41 ~461 ~62 ~41 stone
fill ~458 ~63 ~41 ~461 ~65 ~41 dirt
fill ~458 ~66 ~41 ~461 ~66 ~41 grass_block
fill ~462 ~60 ~41 ~463 ~61 ~41 stone
fill ~462 ~62 ~41 ~463 ~64 ~41 dirt
fill ~462 ~65 ~41 ~463 ~65 ~41 grass_block
fill ~448 ~60 ~42 ~449 ~65 ~42 stone
fill ~448 ~66 ~42 ~449 ~68 ~42 dirt
fill ~448 ~69 ~42 ~449 ~69 ~42 grass_block
fill ~450 ~60 ~42 ~452 ~64 ~42 stone
fill ~450 ~65 ~42 ~452 ~67 ~42 dirt
fill ~450 ~68 ~42 ~452 ~68 ~42 grass_block
fill ~453 ~60 ~42 ~457 ~63 ~42 stone
fill ~453 ~64 ~42 ~457 ~66 ~42 dirt
fill ~453 ~67 ~42 ~457 ~67 ~42 grass_block
fill ~458 ~60 ~42 ~461 ~62 ~42 stone
fill ~458 ~63 ~42 ~461 ~65 ~42 dirt
fill ~458 ~66 ~42 ~461 ~66 ~42 grass_block
fill ~462 ~60 ~42 ~463 ~61 ~42 stone
fill ~462 ~62 ~42 ~463 ~64 ~42 dirt
fill ~462 ~65 ~42 ~463 ~65 ~42 grass_block
fill ~448 ~60 ~43 ~449 ~65 ~43 stone
fill ~448 ~66 ~43 ~449 ~68 ~43 dirt
fill ~448 ~69 ~43 ~449 ~69 ~43 grass_block
fill ~450 ~60 ~43 ~452 ~64 ~43 stone
fill ~450 ~65 ~43 ~452 ~67 ~43 dirt
fill ~450 ~68 ~43 ~452 ~68 ~43 grass_block
fill ~453 ~60 ~43 ~457 ~63 ~43 stone
fill ~453 ~64 ~43 ~457 ~66 ~43 dirt
fill ~453 ~67 ~43 ~457 ~67 ~43 grass_block
fill ~458 ~60 ~43 ~461 ~62 ~43 stone
fill ~458 ~63 ~43 ~461 ~65 ~43 dirt
fill ~458 ~66 ~43 ~461 ~66 ~43 grass_block
fill ~462 ~60 ~43 ~463 ~61 ~43 stone
fill ~462 ~62 ~43 ~463 ~64 ~43 dirt
fill ~462 ~65 ~43 ~463 ~65 ~43 grass_block
fill ~448 ~60 ~44 ~449 ~65 ~44 stone
fill ~448 ~66 ~44 ~449 ~68 ~44 dirt
fill ~448 ~69 ~44 ~449 ~69 ~44 grass_block
fill ~450 ~60 ~44 ~452 ~64 ~44 stone
fill ~450 ~65 ~44 ~452 ~67 ~44 dirt
fill ~450 ~68 ~44 ~452 ~68 ~44 grass_block
fill ~453 ~60 ~44 ~457 ~63 ~44 stone
fill ~453 ~64 ~44 ~457 ~66 ~44 dirt
fill ~453 ~67 ~44 ~457 ~67 ~44 grass_block
fill ~458 ~60 ~44 ~461 ~62 ~44 stone
fill ~458 ~63 ~44 ~461 ~65 ~44 dirt
fill ~458 ~66 ~44 ~461 ~66 ~44 grass_block
fill ~462 ~60 ~44 ~463 ~61 ~44 stone
fill ~462 ~62 ~44 ~463 ~64 ~44 dirt
fill ~462 ~65 ~44 ~463 ~65 ~44 grass_block
fill ~448 ~60 ~45 ~449 ~65 ~45 stone
fill ~448 ~66 ~45 ~449 ~68 ~45 dirt
fill ~448 ~69 ~45 ~449 ~69 ~45 grass_block
fill ~450 ~60 ~45 ~452 ~64 ~45 stone
fill ~450 ~65 ~45 ~452 ~67 ~45 dirt
fill ~450 ~68 ~45 ~452 ~68 ~45 grass_block
fill ~453 ~60 ~45 ~457 ~63 ~45 stone
fill ~453 ~64 ~45 ~457 ~66 ~45 dirt
fill ~453 ~67 ~45 ~457 ~67 ~45 grass_block
fill ~458 ~60 ~45 ~460 ~62 ~45 stone
fill ~458 ~63 ~45 ~460 ~65 ~45 dirt
fill ~458 ~66 ~45 ~460 ~66 ~45 grass_block
fill ~461 ~60 ~45 ~463 ~61 ~45 stone
fill ~461 ~62 ~45 ~463 ~64 ~45 dirt
fill ~461 ~65 ~45 ~463 ~65 ~45 grass_block
fill ~448 ~60 ~46 ~449 ~65 ~46 stone
fill ~448 ~66 ~46 ~449 ~68 ~46 dirt
fill ~448 ~69 ~46 ~449 ~69 ~46 grass_block
fill ~450 ~60 ~46 ~453 ~64 ~46 stone
fill ~450 ~65 ~46 ~453 ~67 ~46 dirt
fill ~450 ~68 ~46 ~453 ~68 ~46 grass_block
fill ~454 ~60 ~46 ~456 ~63 ~46 stone
fill ~454 ~64 ~46 ~456 ~66 ~46 dirt
fill ~454 ~67 ~46 ~456 ~67 ~46 grass_block
fill ~457 ~60 ~46 ~460 ~62 ~46 stone
fill ~457 ~63 ~46 ~460 ~65 ~46 dirt
fill ~457 ~66 ~46 ~460 ~66 ~46 grass_block
fill ~461 ~60 ~46 ~463 ~61 ~46 stone
fill ~461 ~62 ~46 ~463 ~64 ~46 dirt
fill ~461 ~65 ~46 ~463 ~65 ~46 grass_block
fill ~448 ~60 ~47 ~449 ~65 ~47 stone
fill ~448 ~66 ~47 ~449 ~68 ~47 dirt
fill ~448 ~69 ~47 ~449 ~69 ~47 grass_block
fill ~450 ~60 ~47 ~453 ~64 ~47 stone
fill ~450 ~65 ~47 ~453 ~67 ~47 dirt
fill ~450 ~68 ~47 ~453 ~68 ~47 grass_block
fill ~454 ~60 ~47 ~456 ~63 ~47 stone
fill ~454 ~64 ~47 ~456 ~66 ~47 dirt
fill ~454 ~67 ~47 ~456 ~67 ~47 grass_block
fill ~457 ~60 ~47 ~460 ~62 ~47 stone
fill ~457 ~63 ~47 ~460 ~65 ~47 dirt
fill ~457 ~66 ~47 ~460 ~66 ~47 grass_block
fill ~461 ~60 ~47 ~463 ~61 ~47 stone
fill ~461 ~62 ~47 ~463 ~64 ~47 dirt
fill ~461 ~65 ~47 ~463 ~65 ~47 grass_block