fill ~256 ~60 ~48 ~271 ~61 ~48 stone
fill ~256 ~62 ~48 ~271 ~64 ~48 dirt
fill ~256 ~65 ~48 ~271 ~65 ~48 grass_block
fill ~256 ~60 ~49 ~256 ~62 ~49 stone
fill ~256 ~63 ~49 ~256 ~65 ~49 dirt
fill ~256 ~66 ~49 ~256 ~66 ~49 grass_block
fill ~257 ~60 ~49 ~271 ~61 ~49 stone
fill ~257 ~62 ~49 ~271 ~64 ~49 dirt
fill ~257 ~65 ~49 ~271 ~65 ~49 grass_block
fill ~256 ~60 ~50 ~258 ~62 ~50 stone
fill ~256 ~63 ~50 ~258 ~65 ~50 dirt
fill ~256 ~66 ~50 ~258 ~66 ~50 grass_block
fill ~259 ~60 ~50 ~271 ~61 ~50 stone
fill ~259 ~62 ~50 ~271 ~64 ~50 dirt
fill ~259 ~65 ~50 ~271 ~65 ~50 grass_block
fill ~256 ~60 ~51 ~262 ~62 ~51 stone
fill ~256 ~63 ~51 ~262 ~65 ~51 dirt
fill ~256 ~66 ~51 ~262 ~66 ~51 grass_block
fill ~263 ~60 ~51 ~271 ~61 ~51 stone
fill ~263 ~62 ~51 ~271 ~64 ~51 dirt
fill ~263 ~65 ~51 ~271 ~65 ~51 grass_block
fill ~256 ~60 ~52 ~263 ~62 ~52 stone
fill ~256 ~63 ~52 ~263 ~65 ~52 dirt
fill ~256 ~66 ~52 ~263 ~66 ~52 grass_block
fill ~264 ~60 ~52 ~271 ~61 ~52 stone
fill ~264 ~62 ~52 ~271 ~64 ~52 dirt
fill ~264 ~65 ~52 ~271 ~65 ~52 grass_block
fill ~256 ~60 ~53 ~266 ~62 ~53 stone
fill ~256 ~63 ~53 ~266 ~65 ~53 dirt
fill ~256 ~66 ~53 ~266 ~66 ~53 grass_block
fill ~267 ~60 ~53 ~271 ~61 ~53 stone
fill ~267 ~62 ~53 ~271 ~64 ~53 dirt
fill ~267 ~65 ~53 ~271 ~65 ~53 grass_block
fill ~256 ~60 ~54 ~268 ~62 ~54 stone
fill ~256 ~63 ~54 ~268 ~65 ~54 dirt
fill ~256 ~66 ~54 ~268 ~66 ~54 grass_block
fill ~269 ~60 ~54 ~271 ~61 ~54 stone
fill ~269 ~62 ~54 ~271 ~64 ~54 dirt
fill ~269 ~65 ~54 ~271 ~65 ~54 grass_block
fill ~256 ~60 ~55 ~270 ~62 ~55 stone
fill ~256 ~63 ~55 ~270 ~65 ~55 dirt
fill ~256 ~66 ~55 ~270 ~66 ~55 grass_block
fill ~271 ~60 ~55 ~271 ~61 ~55 stone
fill ~271 ~62 ~55 ~271 ~64 ~55 dirt
fill ~271 ~65 ~55 ~271 ~65 ~55 grass_block
fill ~256 ~60 ~56 ~256 ~63 ~56 stone
fill ~256 ~64 ~56 ~256 ~66 ~56 dirt
fill ~256 ~67 ~56 ~256 ~67 ~56 grass_block
fill ~257 ~60 ~56 ~271 ~62 ~56 stone
fill ~257 ~63 ~56 ~271 ~65 ~56 dirt
fill ~257 ~66 ~56 ~271 ~66 ~56 grass_block
fill ~256 ~60 ~57 ~256 ~62 ~57 stone
fill ~256 ~63 ~57 ~256 ~65 ~57 dirt
fill ~256 ~66 ~57 ~256 ~66 ~57 grass_block
fill ~257 ~60 ~57 ~257 ~63 ~57 stone
fill ~257 ~64 ~57 ~257 ~66 ~57 dirt
fill ~257 ~67 ~57 ~257 ~67 ~57 grass_block
fill ~258 ~60 ~57 ~271 ~62 ~57 stone
fill ~258 ~63 ~57 ~271 ~65 ~57 dirt
fill ~258 ~66 ~57 ~271 ~66 ~57 grass_block
fill ~256 ~60 ~58 ~271 ~62 ~58 stone
fill ~256 ~63 ~58 ~271 ~65 ~58 dirt
fill ~256 ~66 ~58 ~271 ~66 ~58 grass_block
fill ~256 ~60 ~59 ~256 ~63 ~59 stone
fill ~256 ~64 ~59 ~256 ~66 ~59 dirt
fill ~256 ~67 ~59 ~256 ~67 ~59 grass_block
fill ~257 ~60 ~59 ~271 ~62 ~59 stone
fill ~257 ~63 ~59 ~271 ~65 ~59 dirt
fill ~257 ~66 ~59 ~271 ~66 ~59 grass_block
fill ~256 ~60 ~60 ~271 ~62 ~60 stone
fill ~256 ~63 ~60 ~271 ~65 ~60 dirt
fill ~256 ~66 ~60 ~271 ~66 ~60 grass_block
fill ~256 ~60 ~61 ~271 ~62 ~61 stone
fill ~256 ~63 ~61 ~271 ~65 ~61 dirt
fill ~256 ~66 ~61 ~271 ~66 ~61 grass_block
fill ~256 ~60 ~62 ~256 ~63 ~62 stone
fill ~256 ~64 ~62 ~256 ~66 ~62 dirt
fill ~256 ~67 ~62 ~256 ~67 ~62 grass_block
fill ~257 ~60 ~62 ~271 ~62 ~62 stone
fill ~257 ~63 ~62 ~271 ~65 ~62 dirt
fill ~257 ~66 ~62 ~271 ~66 ~62 grass_block
fill ~256 ~60 ~63 ~257 ~63 ~63 stone
fill ~256 ~64 ~63 ~257 ~66 ~63 dirt
fill ~256 ~67 ~63 ~257 ~67 ~63 grass_block
fill ~258 ~60 ~63 ~271 ~62 ~63 stone
fill ~258 ~63 ~63 ~271 ~65 ~63 dirt
fill ~258 ~66 ~63 ~271 ~66 ~63 grass_block