fill ~400 ~60 ~80 ~406 ~63 ~80 stone
fill ~400 ~64 ~80 ~406 ~66 ~80 dirt
fill ~400 ~67 ~80 ~406 ~67 ~80 grass_block
fill ~407 ~60 ~80 ~408 ~62 ~80 stone
fill ~407 ~63 ~80 ~408 ~65 ~80 dirt
fill ~407 ~66 ~80 ~408 ~66 ~80 grass_block
fill ~409 ~60 ~80 ~410 ~61 ~80 stone
fill ~409 ~62 ~80 ~410 ~64 ~80 dirt
fill ~409 ~65 ~80 ~410 ~65 ~80 grass_block
fill ~411 ~60 ~80 ~412 ~62 ~80 stone
fill ~411 ~63 ~80 ~412 ~65 ~80 dirt
fill ~411 ~66 ~80 ~412 ~66 ~80 grass_block
fill ~413 ~60 ~80 ~415 ~63 ~80 stone
fill ~413 ~64 ~80 ~415 ~66 ~80 dirt
fill ~413 ~67 ~80 ~415 ~67 ~80 grass_block
fill ~400 ~60 ~81 ~406 ~63 ~81 stone
fill ~400 ~64 ~81 ~406 ~66 ~81 dirt
fill ~400 ~67 ~81 ~406 ~67 ~81 grass_block
fill ~407 ~60 ~81 ~409 ~62 ~81 stone
fill ~407 ~63 ~81 ~409 ~65 ~81 dirt
fill ~407 ~66 ~81 ~409 ~66 ~81 grass_block
fill ~410 ~60 ~81 ~411 ~61 ~81 stone
fill ~410 ~62 ~81 ~411 ~64 ~81 dirt
fill ~410 ~65 ~81 ~411 ~65 ~81 grass_block
fill ~412 ~60 ~81 ~413 ~62 ~81 stone
fill ~412 ~63 ~81 ~413 ~65 ~81 dirt
fill ~412 ~66 ~81 ~413 ~66 ~81 grass_block
fill ~414 ~60 ~81 ~415 ~63 ~81 stone
fill ~414 ~64 ~81 ~415 ~66 ~81 dirt
fill ~414 ~67 ~81 ~415 ~67 ~81 grass_block
fill ~400 ~60 ~82 ~406 ~63 ~82 stone
fill ~400 ~64 ~82 ~406 ~66 ~82 dirt
fill ~400 ~67 ~82 ~406 ~67 ~82 grass_block
fill ~407 ~60 ~82 ~410 ~62 ~82 stone
fill ~407 ~63 ~82 ~410 ~65 ~82 dirt
fill ~407 ~66 ~82 ~410 ~66 ~82 grass_block
fill ~411 ~60 ~82 ~412 ~61 ~82 stone
fill ~411 ~62 ~82 ~412 ~64 ~82 dirt
fill ~411 ~65 ~82 ~412 ~65 ~82 grass_block
fill ~413 ~60 ~82 ~414 ~62 ~82 stone
fill ~413 ~63 ~82 ~414 ~65 ~82 dirt
fill ~413 ~66 ~82 ~414 ~66 ~82 grass_block
fill ~415 ~60 ~82 ~415 ~63 ~82 stone
fill ~415 ~64 ~82 ~415 ~66 ~82 dirt
fill ~415 ~67 ~82 ~415 ~67 ~82 grass_block
fill ~400 ~60 ~83 ~401 ~62 ~83 stone
fill ~400 ~63 ~83 ~401 ~65 ~83 dirt
fill ~400 ~66 ~83 ~401 ~66 ~83 grass_block
fill ~402 ~60 ~83 ~402 ~63 ~83 stone
fill ~402 ~64 ~83 ~402 ~66 ~83 dirt
fill ~402 ~67 ~83 ~402 ~67 ~83 grass_block
fill ~403 ~60 ~83 ~410 ~62 ~83 stone
fill ~403 ~63 ~83 ~410 ~65 ~83 dirt
fill ~403 ~66 ~83 ~410 ~66 ~83 grass_block
fill ~411 ~60 ~83 ~413 ~61 ~83 stone
fill ~411 ~62 ~83 ~413 ~64 ~83 dirt
fill ~411 ~65 ~83 ~413 ~65 ~83 grass_block
fill ~414 ~60 ~83 ~415 ~62 ~83 stone
fill ~414 ~63 ~83 ~415 ~65 ~83 dirt
fill ~414 ~66 ~83 ~415 ~66 ~83 grass_block
fill ~400 ~60 ~84 ~411 ~62 ~84 stone
fill ~400 ~63 ~84 ~411 ~65 ~84 dirt
fill ~400 ~66 ~84 ~411 ~66 ~84 grass_block
fill ~412 ~60 ~84 ~414 ~61 ~84 stone
fill ~412 ~62 ~84 ~414 ~64 ~84 dirt
fill ~412 ~65 ~84 ~414 ~65 ~84 grass_block
fill ~415 ~60 ~84 ~415 ~62 ~84 stone
fill ~415 ~63 ~84 ~415 ~65 ~84 dirt
fill ~415 ~66 ~84 ~415 ~66 ~84 grass_block
fill ~400 ~60 ~85 ~412 ~62 ~85 stone
fill ~400 ~63 ~85 ~412 ~65 ~85 dirt
fill ~400 ~66 ~85 ~412 ~66 ~85 grass_block
fill ~413 ~60 ~85 ~415 ~61 ~85 stone
fill ~413 ~62 ~85 ~415 ~64 ~85 dirt
fill ~413 ~65 ~85 ~415 ~65 ~85 grass_block
fill ~400 ~60 ~86 ~403 ~61 ~86 stone
fill ~400 ~62 ~86 ~403 ~64 ~86 dirt
fill ~400 ~65 ~86 ~403 ~65 ~86 grass_block
fill ~404 ~60 ~86 ~404 ~62 ~86 stone
fill ~404 ~63 ~86 ~404 ~65 ~86 dirt
fill ~404 ~66 ~86 ~404 ~66 ~86 grass_block
fill ~405 ~60 ~86 ~405 ~61 ~86 stone
fill ~405 ~62 ~86 ~405 ~64 ~86 dirt
fill ~405 ~65 ~86 ~405 ~65 ~86 grass_block
fill ~406 ~60 ~86 ~413 ~62 ~86 stone
fill ~406 ~63 ~86 ~413 ~65 ~86 dirt
fill ~406 ~66 ~86 ~413 ~66 ~86 grass_block
fill ~414 ~60 ~86 ~415 ~61 ~86 stone
fill ~414 ~62 ~86 ~415 ~64 ~86 dirt
fill ~414 ~65 ~86 ~415 ~65 ~86 grass_block
fill ~400 ~60 ~87 ~411 ~61 ~87 stone
fill ~400 ~62 ~87 ~411 ~64 ~87 dirt
fill ~400 ~65 ~87 ~411 ~65 ~87 grass_block
fill ~412 ~60 ~87 ~414 ~62 ~87 stone
fill ~412 ~63 ~87 ~414 ~65 ~87 dirt
fill ~412 ~66 ~87 ~414 ~66 ~87 grass_block
fill ~415 ~60 ~87 ~415 ~61 ~87 stone
fill ~415 ~62 ~87 ~415 ~64 ~87 dirt
fill ~415 ~65 ~87 ~415 ~65 ~87 grass_block
fill ~400 ~60 ~88 ~405 ~62 ~88 stone
fill ~400 ~63 ~88 ~405 ~65 ~88 dirt
fill ~400 ~66 ~88 ~405 ~66 ~88 grass_block
fill ~406 ~60 ~88 ~415 ~61 ~88 stone
fill ~406 ~62 ~88 ~415 ~64 ~88 dirt
fill ~406 ~65 ~88 ~415 ~65 ~88 grass_block
fill ~400 ~60 ~89 ~408 ~62 ~89 stone
fill ~400 ~63 ~89 ~408 ~65 ~89 dirt
fill ~400 ~66 ~89 ~408 ~66 ~89 grass_block
fill ~409 ~60 ~89 ~415 ~61 ~89 stone
fill ~409 ~62 ~89 ~415 ~64 ~89 dirt
fill ~409 ~65 ~89 ~415 ~65 ~89 grass_block
fill ~400 ~60 ~90 ~406 ~63 ~90 stone
fill ~400 ~64 ~90 ~406 ~66 ~90 dirt
fill ~400 ~67 ~90 ~406 ~67 ~90 grass_block
fill ~407 ~60 ~90 ~411 ~62 ~90 stone
fill ~407 ~63 ~90 ~411 ~65 ~90 dirt
fill ~407 ~66 ~90 ~411 ~66 ~90 grass_block
fill ~412 ~60 ~90 ~415 ~61 ~90 stone
fill ~412 ~62 ~90 ~415 ~64 ~90 dirt
fill ~412 ~65 ~90 ~415 ~65 ~90 grass_block
fill ~400 ~60 ~91 ~402 ~64 ~91 stone
fill ~400 ~65 ~91 ~402 ~67 ~91 dirt
fill ~400 ~68 ~91 ~402 ~68 ~91 grass_block
fill ~403 ~60 ~91 ~412 ~63 ~91 stone
fill ~403 ~64 ~91 ~412 ~66 ~91 dirt
fill ~403 ~67 ~91 ~412 ~67 ~91 grass_block
fill ~413 ~60 ~91 ~414 ~62 ~91 stone
fill ~413 ~63 ~91 ~414 ~65 ~91 dirt
fill ~413 ~66 ~91 ~414 ~66 ~91 grass_block
fill ~415 ~60 ~91 ~415 ~61 ~91 stone
fill ~415 ~62 ~91 ~415 ~64 ~91 dirt
fill ~415 ~65 ~91 ~415 ~65 ~91 grass_block
fill ~400 ~60 ~92 ~403 ~65 ~92 stone
fill ~400 ~66 ~92 ~403 ~68 ~92 dirt
fill ~400 ~69 ~92 ~403 ~69 ~92 grass_block
fill ~404 ~60 ~92 ~411 ~64 ~92 stone
fill ~404 ~65 ~92 ~411 ~67 ~92 dirt
fill ~404 ~68 ~92 ~411 ~68 ~92 grass_block
fill ~412 ~60 ~92 ~413 ~63 ~92 stone
fill ~412 ~64 ~92 ~413 ~66 ~92 dirt
fill ~412 ~67 ~92 ~413 ~67 ~92 grass_block
fill ~414 ~60 ~92 ~415 ~62 ~92 stone
fill ~414 ~63 ~92 ~415 ~65 ~92 dirt
fill ~414 ~66 ~92 ~415 ~66 ~92 grass_block
fill ~400 ~60 ~93 ~409 ~65 ~93 stone
fill ~400 ~66 ~93 ~409 ~68 ~93 dirt
fill ~400 ~69 ~93 ~409 ~69 ~93 grass_block
fill ~410 ~60 ~93 ~412 ~64 ~93 stone
fill ~410 ~65 ~93 ~412 ~67 ~93 dirt
fill ~410 ~68 ~93 ~412 ~68 ~93 grass_block
fill ~413 ~60 ~93 ~415 ~63 ~93 stone
fill ~413 ~64 ~93 ~415 ~66 ~93 dirt
fill ~413 ~67 ~93 ~415 ~67 ~93 grass_block
fill ~400 ~60 ~94 ~410 ~65 ~94 stone
fill ~400 ~66 ~94 ~410 ~68 ~94 dirt
fill ~400 ~69 ~94 ~410 ~69 ~94 grass_block
fill ~411 ~60 ~94 ~414 ~64 ~94 stone
fill ~411 ~65 ~94 ~414 ~67 ~94 dirt
fill ~411 ~68 ~94 ~414 ~68 ~94 grass_block
fill ~415 ~60 ~94 ~415 ~63 ~94 stone
fill ~415 ~64 ~94 ~415 ~66 ~94 dirt
fill ~415 ~67 ~94 ~415 ~67 ~94 grass_block
fill ~400 ~60 ~95 ~401 ~64 ~95 stone
fill ~400 ~65 ~95 ~401 ~67 ~95 dirt
fill ~400 ~68 ~95 ~401 ~68 ~95 grass_block
fill ~402 ~60 ~95 ~411 ~65 ~95 stone
fill ~402 ~66 ~95 ~411 ~68 ~95 dirt
fill ~402 ~69 ~95 ~411 ~69 ~95 grass_block
fill ~412 ~60 ~95 ~415 ~64 ~95 stone
fill ~412 ~65 ~95 ~415 ~67 ~95 dirt
fill ~412 ~68 ~95 ~415 ~68 ~95 grass_block