fill ~352 ~60 ~48 ~359 ~65 ~48 stone
fill ~352 ~66 ~48 ~359 ~68 ~48 dirt
fill ~352 ~69 ~48 ~359 ~69 ~48 grass_block
fill ~360 ~60 ~48 ~367 ~66 ~48 stone
fill ~360 ~67 ~48 ~367 ~69 ~48 dirt
fill ~360 ~70 ~48 ~367 ~70 ~48 grass_block
fill ~352 ~60 ~49 ~360 ~65 ~49 stone
fill ~352 ~66 ~49 ~360 ~68 ~49 dirt
fill ~352 ~69 ~49 ~360 ~69 ~49 grass_block
fill ~361 ~60 ~49 ~367 ~66 ~49 stone
fill ~361 ~67 ~49 ~367 ~69 ~49 dirt
fill ~361 ~70 ~49 ~367 ~70 ~49 grass_block
fill ~352 ~60 ~50 ~355 ~65 ~50 stone
fill ~352 ~66 ~50 ~355 ~68 ~50 dirt
fill ~352 ~69 ~50 ~355 ~69 ~50 grass_block
fill ~356 ~60 ~50 ~356 ~64 ~50 stone
fill ~356 ~65 ~50 ~356 ~67 ~50 dirt
fill ~356 ~68 ~50 ~356 ~68 ~50 grass_block
fill ~357 ~60 ~50 ~362 ~65 ~50 stone
fill ~357 ~66 ~50 ~362 ~68 ~50 dirt
fill ~357 ~69 ~50 ~362 ~69 ~50 grass_block
fill ~363 ~60 ~50 ~364 ~66 ~50 stone
fill ~363 ~67 ~50 ~364 ~69 ~50 dirt
fill ~363 ~70 ~50 ~364 ~70 ~50 grass_block
fill ~365 ~60 ~50 ~367 ~65 ~50 stone
fill ~365 ~66 ~50 ~367 ~68 ~50 dirt
fill ~365 ~69 ~50 ~367 ~69 ~50 grass_block
fill ~352 ~60 ~51 ~355 ~65 ~51 stone
fill ~352 ~66 ~51 ~355 ~68 ~51 dirt
fill ~352 ~69 ~51 ~355 ~69 ~51 grass_block
fill ~356 ~60 ~51 ~358 ~64 ~51 stone
fill ~356 ~65 ~51 ~358 ~67 ~51 dirt
fill ~356 ~68 ~51 ~358 ~68 ~51 grass_block
fill ~359 ~60 ~51 ~367 ~65 ~51 stone
fill ~359 ~66 ~51 ~367 ~68 ~51 dirt
fill ~359 ~69 ~51 ~367 ~69 ~51 grass_block
fill ~352 ~60 ~52 ~355 ~65 ~52 stone
fill ~352 ~66 ~52 ~355 ~68 ~52 dirt
fill ~352 ~69 ~52 ~355 ~69 ~52 grass_block
fill ~356 ~60 ~52 ~360 ~64 ~52 stone
fill ~356 ~65 ~52 ~360 ~67 ~52 dirt
fill ~356 ~68 ~52 ~360 ~68 ~52 grass_block
fill ~361 ~60 ~52 ~366 ~65 ~52 stone
fill ~361 ~66 ~52 ~366 ~68 ~52 dirt
fill ~361 ~69 ~52 ~366 ~69 ~52 grass_block
fill ~367 ~60 ~52 ~367 ~64 ~52 stone
fill ~367 ~65 ~52 ~367 ~67 ~52 dirt
fill ~367 ~68 ~52 ~367 ~68 ~52 grass_block
fill ~352 ~60 ~53 ~355 ~65 ~53 stone
fill ~352 ~66 ~53 ~355 ~68 ~53 dirt
fill ~352 ~69 ~53 ~355 ~69 ~53 grass_block
fill ~356 ~60 ~53 ~361 ~64 ~53 stone
fill ~356 ~65 ~53 ~361 ~67 ~53 dirt
fill ~356 ~68 ~53 ~361 ~68 ~53 grass_block
fill ~362 ~60 ~53 ~366 ~65 ~53 stone
fill ~362 ~66 ~53 ~366 ~68 ~53 dirt
fill ~362 ~69 ~53 ~366 ~69 ~53 grass_block
fill ~367 ~60 ~53 ~367 ~64 ~53 stone
fill ~367 ~65 ~53 ~367 ~67 ~53 dirt
fill ~367 ~68 ~53 ~367 ~68 ~53 grass_block
fill ~352 ~60 ~54 ~352 ~66 ~54 stone
fill ~352 ~67 ~54 ~352 ~69 ~54 dirt
fill ~352 ~70 ~54 ~352 ~70 ~54 grass_block
fill ~353 ~60 ~54 ~356 ~65 ~54 stone
fill ~353 ~66 ~54 ~356 ~68 ~54 dirt
fill ~353 ~69 ~54 ~356 ~69 ~54 grass_block
fill ~357 ~60 ~54 ~363 ~64 ~54 stone
fill ~357 ~65 ~54 ~363 ~67 ~54 dirt
fill ~357 ~68 ~54 ~363 ~68 ~54 grass_block
fill ~364 ~60 ~54 ~365 ~65 ~54 stone
fill ~364 ~66 ~54 ~365 ~68 ~54 dirt
fill ~364 ~69 ~54 ~365 ~69 ~54 grass_block
fill ~366 ~60 ~54 ~367 ~64 ~54 stone
fill ~366 ~65 ~54 ~367 ~67 ~54 dirt
fill ~366 ~68 ~54 ~367 ~68 ~54 grass_block
fill ~352 ~60 ~55 ~353 ~66 ~55 stone
fill ~352 ~67 ~55 ~353 ~69 ~55 dirt
fill ~352 ~70 ~55 ~353 ~70 ~55 grass_block
fill ~354 ~60 ~55 ~356 ~65 ~55 stone
fill ~354 ~66 ~55 ~356 ~68 ~55 dirt
fill ~354 ~69 ~55 ~356 ~69 ~55 grass_block
fill ~357 ~60 ~55 ~367 ~64 ~55 stone
fill ~357 ~65 ~55 ~367 ~67 ~55 dirt
fill ~357 ~68 ~55 ~367 ~68 ~55 grass_block
fill ~352 ~60 ~56 ~353 ~66 ~56 stone
fill ~352 ~67 ~56 ~353 ~69 ~56 dirt
fill ~352 ~70 ~56 ~353 ~70 ~56 grass_block
fill ~354 ~60 ~56 ~357 ~65 ~56 stone
fill ~354 ~66 ~56 ~357 ~68 ~56 dirt
fill ~354 ~69 ~56 ~357 ~69 ~56 grass_block
fill ~358 ~60 ~56 ~360 ~64 ~56 stone
fill ~358 ~65 ~56 ~360 ~67 ~56 dirt
fill ~358 ~68 ~56 ~360 ~68 ~56 grass_block
fill ~361 ~60 ~56 ~363 ~63 ~56 stone
fill ~361 ~64 ~56 ~363 ~66 ~56 dirt
fill ~361 ~67 ~56 ~363 ~67 ~56 grass_block
fill ~364 ~60 ~56 ~367 ~64 ~56 stone
fill ~364 ~65 ~56 ~367 ~67 ~56 dirt
fill ~364 ~68 ~56 ~367 ~68 ~56 grass_block
fill ~352 ~60 ~57 ~354 ~66 ~57 stone
fill ~352 ~67 ~57 ~354 ~69 ~57 dirt
fill ~352 ~70 ~57 ~354 ~70 ~57 grass_block
fill ~355 ~60 ~57 ~357 ~65 ~57 stone
fill ~355 ~66 ~57 ~357 ~68 ~57 dirt
fill ~355 ~69 ~57 ~357 ~69 ~57 grass_block
fill ~358 ~60 ~57 ~361 ~64 ~57 stone
fill ~358 ~65 ~57 ~361 ~67 ~57 dirt
fill ~358 ~68 ~57 ~361 ~68 ~57 grass_block
fill ~362 ~60 ~57 ~366 ~63 ~57 stone
fill ~362 ~64 ~57 ~366 ~66 ~57 dirt
fill ~362 ~67 ~57 ~366 ~67 ~57 grass_block
fill ~367 ~60 ~57 ~367 ~64 ~57 stone
fill ~367 ~65 ~57 ~367 ~67 ~57 dirt
fill ~367 ~68 ~57 ~367 ~68 ~57 grass_block
fill ~352 ~60 ~58 ~355 ~66 ~58 stone
fill ~352 ~67 ~58 ~355 ~69 ~58 dirt
fill ~352 ~70 ~58 ~355 ~70 ~58 grass_block
fill ~356 ~60 ~58 ~358 ~65 ~58 stone
fill ~356 ~66 ~58 ~358 ~68 ~58 dirt
fill ~356 ~69 ~58 ~358 ~69 ~58 grass_block
fill ~359 ~60 ~58 ~362 ~64 ~58 stone
fill ~359 ~65 ~58 ~362 ~67 ~58 dirt
fill ~359 ~68 ~58 ~362 ~68 ~58 grass_block
fill ~363 ~60 ~58 ~367 ~63 ~58 stone
fill ~363 ~64 ~58 ~367 ~66 ~58 dirt
fill ~363 ~67 ~58 ~367 ~67 ~58 grass_block
fill ~352 ~60 ~59 ~356 ~66 ~59 stone
fill ~352 ~67 ~59 ~356 ~69 ~59 dirt
fill ~352 ~70 ~59 ~356 ~70 ~59 grass_block
fill ~357 ~60 ~59 ~359 ~65 ~59 stone
fill ~357 ~66 ~59 ~359 ~68 ~59 dirt
fill ~357 ~69 ~59 ~359 ~69 ~59 grass_block
fill ~360 ~60 ~59 ~362 ~64 ~59 stone
fill ~360 ~65 ~59 ~362 ~67 ~59 dirt
fill ~360 ~68 ~59 ~362 ~68 ~59 grass_block
fill ~363 ~60 ~59 ~367 ~63 ~59 stone
fill ~363 ~64 ~59 ~367 ~66 ~59 dirt
fill ~363 ~67 ~59 ~367 ~67 ~59 grass_block
fill ~352 ~60 ~60 ~352 ~65 ~60 stone
fill ~352 ~66 ~60 ~352 ~68 ~60 dirt
fill ~352 ~69 ~60 ~352 ~69 ~60 grass_block
fill ~353 ~60 ~60 ~356 ~66 ~60 stone
fill ~353 ~67 ~60 ~356 ~69 ~60 dirt
fill ~353 ~70 ~60 ~356 ~70 ~60 grass_block
fill ~357 ~60 ~60 ~360 ~65 ~60 stone
fill ~357 ~66 ~60 ~360 ~68 ~60 dirt
fill ~357 ~69 ~60 ~360 ~69 ~60 grass_block
fill ~361 ~60 ~60 ~364 ~64 ~60 stone
fill ~361 ~65 ~60 ~364 ~67 ~60 dirt
fill ~361 ~68 ~60 ~364 ~68 ~60 grass_block
fill ~365 ~60 ~60 ~367 ~63 ~60 stone
fill ~365 ~64 ~60 ~367 ~66 ~60 dirt
fill ~365 ~67 ~60 ~367 ~67 ~60 grass_block
fill ~352 ~60 ~61 ~353 ~65 ~61 stone
fill ~352 ~66 ~61 ~353 ~68 ~61 dirt
fill ~352 ~69 ~61 ~353 ~69 ~61 grass_block
fill ~354 ~60 ~61 ~357 ~66 ~61 stone
fill ~354 ~67 ~61 ~357 ~69 ~61 dirt
fill ~354 ~70 ~61 ~357 ~70 ~61 grass_block
fill ~358 ~60 ~61 ~360 ~65 ~61 stone
fill ~358 ~66 ~61 ~360 ~68 ~61 dirt
fill ~358 ~69 ~61 ~360 ~69 ~61 grass_block
fill ~361 ~60 ~61 ~364 ~64 ~61 stone
fill ~361 ~65 ~61 ~364 ~67 ~61 dirt
fill ~361 ~68 ~61 ~364 ~68 ~61 grass_block
fill ~365 ~60 ~61 ~367 ~63 ~61 stone
fill ~365 ~64 ~61 ~367 ~66 ~61 dirt
fill ~365 ~67 ~61 ~367 ~67 ~61 grass_block
fill ~352 ~60 ~62 ~354 ~65 ~62 stone
fill ~352 ~66 ~62 ~354 ~68 ~62 dirt
fill ~352 ~69 ~62 ~354 ~69 ~62 grass_block
fill ~355 ~60 ~62 ~357 ~66 ~62 stone
fill ~355 ~67 ~62 ~357 ~69 ~62 dirt
fill ~355 ~70 ~62 ~357 ~70 ~62 grass_block
fill ~358 ~60 ~62 ~361 ~65 ~62 stone
fill ~358 ~66 ~62 ~361 ~68 ~62 dirt
fill ~358 ~69 ~62 ~361 ~69 ~62 grass_block
fill ~362 ~60 ~62 ~365 ~64 ~62 stone
fill ~362 ~65 ~62 ~365 ~67 ~62 dirt
fill ~362 ~68 ~62 ~365 ~68 ~62 grass_block
fill ~366 ~60 ~62 ~367 ~63 ~62 stone
fill ~366 ~64 ~62 ~367 ~66 ~62 dirt
fill ~366 ~67 ~62 ~367 ~67 ~62 grass_block
fill ~352 ~60 ~63 ~355 ~65 ~63 stone
fill ~352 ~66 ~63 ~355 ~68 ~63 dirt
fill ~352 ~69 ~63 ~355 ~69 ~63 grass_block
fill ~356 ~60 ~63 ~358 ~66 ~63 stone
fill ~356 ~67 ~63 ~358 ~69 ~63 dirt
fill ~356 ~70 ~63 ~358 ~70 ~63 grass_block
fill ~359 ~60 ~63 ~361 ~65 ~63 stone
fill ~359 ~66 ~63 ~361 ~68 ~63 dirt
fill ~359 ~69 ~63 ~361 ~69 ~63 grass_block
fill ~362 ~60 ~63 ~365 ~64 ~63 stone
fill ~362 ~65 ~63 ~365 ~67 ~63 dirt
fill ~362 ~68 ~63 ~365 ~68 ~63 grass_block
fill ~366 ~60 ~63 ~367 ~63 ~63 stone
fill ~366 ~64 ~63 ~367 ~66 ~63 dirt
fill ~366 ~67 ~63 ~367 ~67 ~63 grass_block