fill ~320 ~60 ~128 ~324 ~64 ~128 stone
fill ~320 ~65 ~128 ~324 ~67 ~128 dirt
fill ~320 ~68 ~128 ~324 ~68 ~128 grass_block
fill ~325 ~60 ~128 ~327 ~63 ~128 stone
fill ~325 ~64 ~128 ~327 ~66 ~128 dirt
fill ~325 ~67 ~128 ~327 ~67 ~128 grass_block
fill ~328 ~60 ~128 ~333 ~62 ~128 stone
fill ~328 ~63 ~128 ~333 ~65 ~128 dirt
fill ~328 ~66 ~128 ~333 ~66 ~128 grass_block
fill ~334 ~60 ~128 ~335 ~63 ~128 stone
fill ~334 ~64 ~128 ~335 ~66 ~128 dirt
fill ~334 ~67 ~128 ~335 ~67 ~128 grass_block
fill ~320 ~60 ~129 ~324 ~64 ~129 stone
fill ~320 ~65 ~129 ~324 ~67 ~129 dirt
fill ~320 ~68 ~129 ~324 ~68 ~129 grass_block
fill ~325 ~60 ~129 ~327 ~63 ~129 stone
fill ~325 ~64 ~129 ~327 ~66 ~129 dirt
fill ~325 ~67 ~129 ~327 ~67 ~129 grass_block
fill ~328 ~60 ~129 ~332 ~62 ~129 stone
fill ~328 ~63 ~129 ~332 ~65 ~129 dirt
fill ~328 ~66 ~129 ~332 ~66 ~129 grass_block
fill ~333 ~60 ~129 ~335 ~63 ~129 stone
fill ~333 ~64 ~129 ~335 ~66 ~129 dirt
fill ~333 ~67 ~129 ~335 ~67 ~129 grass_block
fill ~320 ~60 ~130 ~324 ~64 ~130 stone
fill ~320 ~65 ~130 ~324 ~67 ~130 dirt
fill ~320 ~68 ~130 ~324 ~68 ~130 grass_block
fill ~325 ~60 ~130 ~326 ~63 ~130 stone
fill ~325 ~64 ~130 ~326 ~66 ~130 dirt
fill ~325 ~67 ~130 ~326 ~67 ~130 grass_block
fill ~327 ~60 ~130 ~328 ~62 ~130 stone
fill ~327 ~63 ~130 ~328 ~65 ~130 dirt
fill ~327 ~66 ~130 ~328 ~66 ~130 grass_block
fill ~329 ~60 ~130 ~330 ~63 ~130 stone
fill ~329 ~64 ~130 ~330 ~66 ~130 dirt
fill ~329 ~67 ~130 ~330 ~67 ~130 grass_block
fill ~331 ~60 ~130 ~332 ~62 ~130 stone
fill ~331 ~63 ~130 ~332 ~65 ~130 dirt
fill ~331 ~66 ~130 ~332 ~66 ~130 grass_block
fill ~333 ~60 ~130 ~335 ~63 ~130 stone
fill ~333 ~64 ~130 ~335 ~66 ~130 dirt
fill ~333 ~67 ~130 ~335 ~67 ~130 grass_block
fill ~320 ~60 ~131 ~324 ~64 ~131 stone
fill ~320 ~65 ~131 ~324 ~67 ~131 dirt
fill ~320 ~68 ~131 ~324 ~68 ~131 grass_block
fill ~325 ~60 ~131 ~326 ~63 ~131 stone
fill ~325 ~64 ~131 ~326 ~66 ~131 dirt
fill ~325 ~67 ~131 ~326 ~67 ~131 grass_block
fill ~327 ~60 ~131 ~327 ~62 ~131 stone
fill ~327 ~63 ~131 ~327 ~65 ~131 dirt
fill ~327 ~66 ~131 ~327 ~66 ~131 grass_block
fill ~328 ~60 ~131 ~330 ~63 ~131 stone
fill ~328 ~64 ~131 ~330 ~66 ~131 dirt
fill ~328 ~67 ~131 ~330 ~67 ~131 grass_block
fill ~331 ~60 ~131 ~331 ~62 ~131 stone
fill ~331 ~63 ~131 ~331 ~65 ~131 dirt
fill ~331 ~66 ~131 ~331 ~66 ~131 grass_block
fill ~332 ~60 ~131 ~335 ~63 ~131 stone
fill ~332 ~64 ~131 ~335 ~66 ~131 dirt
fill ~332 ~67 ~131 ~335 ~67 ~131 grass_block
fill ~320 ~60 ~132 ~324 ~64 ~132 stone
fill ~320 ~65 ~132 ~324 ~67 ~132 dirt
fill ~320 ~68 ~132 ~324 ~68 ~132 grass_block
fill ~325 ~60 ~132 ~335 ~63 ~132 stone
fill ~325 ~64 ~132 ~335 ~66 ~132 dirt
fill ~325 ~67 ~132 ~335 ~67 ~132 grass_block
fill ~320 ~60 ~133 ~324 ~64 ~133 stone
fill ~320 ~65 ~133 ~324 ~67 ~133 dirt
fill ~320 ~68 ~133 ~324 ~68 ~133 grass_block
fill ~325 ~60 ~133 ~335 ~63 ~133 stone
fill ~325 ~64 ~133 ~335 ~66 ~133 dirt
fill ~325 ~67 ~133 ~335 ~67 ~133 grass_block
fill ~320 ~60 ~134 ~327 ~64 ~134 stone
fill ~320 ~65 ~134 ~327 ~67 ~134 dirt
fill ~320 ~68 ~134 ~327 ~68 ~134 grass_block
fill ~328 ~60 ~134 ~335 ~63 ~134 stone
fill ~328 ~64 ~134 ~335 ~66 ~134 dirt
fill ~328 ~67 ~134 ~335 ~67 ~134 grass_block
fill ~320 ~60 ~135 ~328 ~64 ~135 stone
fill ~320 ~65 ~135 ~328 ~67 ~135 dirt
fill ~320 ~68 ~135 ~328 ~68 ~135 grass_block
fill ~329 ~60 ~135 ~335 ~63 ~135 stone
fill ~329 ~64 ~135 ~335 ~66 ~135 dirt
fill ~329 ~67 ~135 ~335 ~67 ~135 grass_block
fill ~320 ~60 ~136 ~329 ~64 ~136 stone
fill ~320 ~65 ~136 ~329 ~67 ~136 dirt
fill ~320 ~68 ~136 ~329 ~68 ~136 grass_block
fill ~330 ~60 ~136 ~335 ~63 ~136 stone
fill ~330 ~64 ~136 ~335 ~66 ~136 dirt
fill ~330 ~67 ~136 ~335 ~67 ~136 grass_block
fill ~320 ~60 ~137 ~330 ~64 ~137 stone
fill ~320 ~65 ~137 ~330 ~67 ~137 dirt
fill ~320 ~68 ~137 ~330 ~68 ~137 grass_block
fill ~331 ~60 ~137 ~335 ~63 ~137 stone
fill ~331 ~64 ~137 ~335 ~66 ~137 dirt
fill ~331 ~67 ~137 ~335 ~67 ~137 grass_block
fill ~320 ~60 ~138 ~329 ~64 ~138 stone
fill ~320 ~65 ~138 ~329 ~67 ~138 dirt
fill ~320 ~68 ~138 ~329 ~68 ~138 grass_block
fill ~330 ~60 ~138 ~335 ~63 ~138 stone
fill ~330 ~64 ~138 ~335 ~66 ~138 dirt
fill ~330 ~67 ~138 ~335 ~67 ~138 grass_block
fill ~320 ~60 ~139 ~330 ~64 ~139 stone
fill ~320 ~65 ~139 ~330 ~67 ~139 dirt
fill ~320 ~68 ~139 ~330 ~68 ~139 grass_block
fill ~331 ~60 ~139 ~335 ~63 ~139 stone
fill ~331 ~64 ~139 ~335 ~66 ~139 dirt
fill ~331 ~67 ~139 ~335 ~67 ~139 grass_block
fill ~320 ~60 ~140 ~330 ~64 ~140 stone
fill ~320 ~65 ~140 ~330 ~67 ~140 dirt
fill ~320 ~68 ~140 ~330 ~68 ~140 grass_block
fill ~331 ~60 ~140 ~335 ~63 ~140 stone
fill ~331 ~64 ~140 ~335 ~66 ~140 dirt
fill ~331 ~67 ~140 ~335 ~67 ~140 grass_block
fill ~320 ~60 ~141 ~325 ~64 ~141 stone
fill ~320 ~65 ~141 ~325 ~67 ~141 dirt
fill ~320 ~68 ~141 ~325 ~68 ~141 grass_block
fill ~326 ~60 ~141 ~335 ~63 ~141 stone
fill ~326 ~64 ~141 ~335 ~66 ~141 dirt
fill ~326 ~67 ~141 ~335 ~67 ~141 grass_block
fill ~320 ~60 ~142 ~335 ~63 ~142 stone
fill ~320 ~64 ~142 ~335 ~66 ~142 dirt
fill ~320 ~67 ~142 ~335 ~67 ~142 grass_block
fill ~320 ~60 ~143 ~335 ~63 ~143 stone
fill ~320 ~64 ~143 ~335 ~66 ~143 dirt
fill ~320 ~67 ~143 ~335 ~67 ~143 grass_block