fill ~128 ~60 ~80 ~138 ~64 ~80 stone
fill ~128 ~65 ~80 ~138 ~67 ~80 dirt
fill ~128 ~68 ~80 ~138 ~68 ~80 grass_block
fill ~139 ~60 ~80 ~141 ~63 ~80 stone
fill ~139 ~64 ~80 ~141 ~66 ~80 dirt
fill ~139 ~67 ~80 ~141 ~67 ~80 grass_block
fill ~142 ~60 ~80 ~143 ~64 ~80 stone
fill ~142 ~65 ~80 ~143 ~67 ~80 dirt
fill ~142 ~68 ~80 ~143 ~68 ~80 grass_block
fill ~128 ~60 ~81 ~137 ~64 ~81 stone
fill ~128 ~65 ~81 ~137 ~67 ~81 dirt
fill ~128 ~68 ~81 ~137 ~68 ~81 grass_block
fill ~138 ~60 ~81 ~141 ~63 ~81 stone
fill ~138 ~64 ~81 ~141 ~66 ~81 dirt
fill ~138 ~67 ~81 ~141 ~67 ~81 grass_block
fill ~142 ~60 ~81 ~143 ~64 ~81 stone
fill ~142 ~65 ~81 ~143 ~67 ~81 dirt
fill ~142 ~68 ~81 ~143 ~68 ~81 grass_block
fill ~128 ~60 ~82 ~128 ~63 ~82 stone
fill ~128 ~64 ~82 ~128 ~66 ~82 dirt
fill ~128 ~67 ~82 ~128 ~67 ~82 grass_block
fill ~129 ~60 ~82 ~136 ~64 ~82 stone
fill ~129 ~65 ~82 ~136 ~67 ~82 dirt
fill ~129 ~68 ~82 ~136 ~68 ~82 grass_block
fill ~137 ~60 ~82 ~141 ~63 ~82 stone
fill ~137 ~64 ~82 ~141 ~66 ~82 dirt
fill ~137 ~67 ~82 ~141 ~67 ~82 grass_block
fill ~142 ~60 ~82 ~143 ~64 ~82 stone
fill ~142 ~65 ~82 ~143 ~67 ~82 dirt
fill ~142 ~68 ~82 ~143 ~68 ~82 grass_block
fill ~128 ~60 ~83 ~131 ~63 ~83 stone
fill ~128 ~64 ~83 ~131 ~66 ~83 dirt
fill ~128 ~67 ~83 ~131 ~67 ~83 grass_block
fill ~132 ~60 ~83 ~135 ~64 ~83 stone
fill ~132 ~65 ~83 ~135 ~67 ~83 dirt
fill ~132 ~68 ~83 ~135 ~68 ~83 grass_block
fill ~136 ~60 ~83 ~141 ~63 ~83 stone
fill ~136 ~64 ~83 ~141 ~66 ~83 dirt
fill ~136 ~67 ~83 ~141 ~67 ~83 grass_block
fill ~142 ~60 ~83 ~143 ~64 ~83 stone
fill ~142 ~65 ~83 ~143 ~67 ~83 dirt
fill ~142 ~68 ~83 ~143 ~68 ~83 grass_block
fill ~128 ~60 ~84 ~141 ~63 ~84 stone
fill ~128 ~64 ~84 ~141 ~66 ~84 dirt
fill ~128 ~67 ~84 ~141 ~67 ~84 grass_block
fill ~142 ~60 ~84 ~143 ~64 ~84 stone
fill ~142 ~65 ~84 ~143 ~67 ~84 dirt
fill ~142 ~68 ~84 ~143 ~68 ~84 grass_block
fill ~128 ~60 ~85 ~141 ~63 ~85 stone
fill ~128 ~64 ~85 ~141 ~66 ~85 dirt
fill ~128 ~67 ~85 ~141 ~67 ~85 grass_block
fill ~142 ~60 ~85 ~143 ~64 ~85 stone
fill ~142 ~65 ~85 ~143 ~67 ~85 dirt
fill ~142 ~68 ~85 ~143 ~68 ~85 grass_block
fill ~128 ~60 ~86 ~128 ~62 ~86 stone
fill ~128 ~63 ~86 ~128 ~65 ~86 dirt
fill ~128 ~66 ~86 ~128 ~66 ~86 grass_block
fill ~129 ~60 ~86 ~140 ~63 ~86 stone
fill ~129 ~64 ~86 ~140 ~66 ~86 dirt
fill ~129 ~67 ~86 ~140 ~67 ~86 grass_block
fill ~141 ~60 ~86 ~143 ~64 ~86 stone
fill ~141 ~65 ~86 ~143 ~67 ~86 dirt
fill ~141 ~68 ~86 ~143 ~68 ~86 grass_block
fill ~128 ~60 ~87 ~132 ~62 ~87 stone
fill ~128 ~63 ~87 ~132 ~65 ~87 dirt
fill ~128 ~66 ~87 ~132 ~66 ~87 grass_block
fill ~133 ~60 ~87 ~140 ~63 ~87 stone
fill ~133 ~64 ~87 ~140 ~66 ~87 dirt
fill ~133 ~67 ~87 ~140 ~67 ~87 grass_block
fill ~141 ~60 ~87 ~143 ~64 ~87 stone
fill ~141 ~65 ~87 ~143 ~67 ~87 dirt
fill ~141 ~68 ~87 ~143 ~68 ~87 grass_block
fill ~128 ~60 ~88 ~132 ~62 ~88 stone
fill ~128 ~63 ~88 ~132 ~65 ~88 dirt
fill ~128 ~66 ~88 ~132 ~66 ~88 grass_block
fill ~133 ~60 ~88 ~135 ~63 ~88 stone
fill ~133 ~64 ~88 ~135 ~66 ~88 dirt
fill ~133 ~67 ~88 ~135 ~67 ~88 grass_block
fill ~136 ~60 ~88 ~137 ~62 ~88 stone
fill ~136 ~63 ~88 ~137 ~65 ~88 dirt
fill ~136 ~66 ~88 ~137 ~66 ~88 grass_block
fill ~138 ~60 ~88 ~139 ~63 ~88 stone
fill ~138 ~64 ~88 ~139 ~66 ~88 dirt
fill ~138 ~67 ~88 ~139 ~67 ~88 grass_block
fill ~140 ~60 ~88 ~143 ~64 ~88 stone
fill ~140 ~65 ~88 ~143 ~67 ~88 dirt
fill ~140 ~68 ~88 ~143 ~68 ~88 grass_block
fill ~128 ~60 ~89 ~133 ~62 ~89 stone
fill ~128 ~63 ~89 ~133 ~65 ~89 dirt
fill ~128 ~66 ~89 ~133 ~66 ~89 grass_block
fill ~134 ~60 ~89 ~135 ~63 ~89 stone
fill ~134 ~64 ~89 ~135 ~66 ~89 dirt
fill ~134 ~67 ~89 ~135 ~67 ~89 grass_block
fill ~136 ~60 ~89 ~136 ~62 ~89 stone
fill ~136 ~63 ~89 ~136 ~65 ~89 dirt
fill ~136 ~66 ~89 ~136 ~66 ~89 grass_block
fill ~137 ~60 ~89 ~141 ~63 ~89 stone
fill ~137 ~64 ~89 ~141 ~66 ~89 dirt
fill ~137 ~67 ~89 ~141 ~67 ~89 grass_block
fill ~142 ~60 ~89 ~143 ~64 ~89 stone
fill ~142 ~65 ~89 ~143 ~67 ~89 dirt
fill ~142 ~68 ~89 ~143 ~68 ~89 grass_block
fill ~128 ~60 ~90 ~137 ~62 ~90 stone
fill ~128 ~63 ~90 ~137 ~65 ~90 dirt
fill ~128 ~66 ~90 ~137 ~66 ~90 grass_block
fill ~138 ~60 ~90 ~141 ~63 ~90 stone
fill ~138 ~64 ~90 ~141 ~66 ~90 dirt
fill ~138 ~67 ~90 ~141 ~67 ~90 grass_block
fill ~142 ~60 ~90 ~143 ~64 ~90 stone
fill ~142 ~65 ~90 ~143 ~67 ~90 dirt
fill ~142 ~68 ~90 ~143 ~68 ~90 grass_block
fill ~128 ~60 ~91 ~137 ~62 ~91 stone
fill ~128 ~63 ~91 ~137 ~65 ~91 dirt
fill ~128 ~66 ~91 ~137 ~66 ~91 grass_block
fill ~138 ~60 ~91 ~143 ~63 ~91 stone
fill ~138 ~64 ~91 ~143 ~66 ~91 dirt
fill ~138 ~67 ~91 ~143 ~67 ~91 grass_block
fill ~128 ~60 ~92 ~140 ~62 ~92 stone
fill ~128 ~63 ~92 ~140 ~65 ~92 dirt
fill ~128 ~66 ~92 ~140 ~66 ~92 grass_block
fill ~141 ~60 ~92 ~143 ~63 ~92 stone
fill ~141 ~64 ~92 ~143 ~66 ~92 dirt
fill ~141 ~67 ~92 ~143 ~67 ~92 grass_block
fill ~128 ~60 ~93 ~142 ~62 ~93 stone
fill ~128 ~63 ~93 ~142 ~65 ~93 dirt
fill ~128 ~66 ~93 ~142 ~66 ~93 grass_block
fill ~143 ~60 ~93 ~143 ~63 ~93 stone
fill ~143 ~64 ~93 ~143 ~66 ~93 dirt
fill ~143 ~67 ~93 ~143 ~67 ~93 grass_block
fill ~128 ~60 ~94 ~143 ~62 ~94 stone
fill ~128 ~63 ~94 ~143 ~65 ~94 dirt
fill ~128 ~66 ~94 ~143 ~66 ~94 grass_block
fill ~128 ~60 ~95 ~128 ~63 ~95 stone
fill ~128 ~64 ~95 ~128 ~66 ~95 dirt
fill ~128 ~67 ~95 ~128 ~67 ~95 grass_block
fill ~129 ~60 ~95 ~143 ~62 ~95 stone
fill ~129 ~63 ~95 ~143 ~65 ~95 dirt
fill ~129 ~66 ~95 ~143 ~66 ~95 grass_block