fill ~256 ~60 ~128 ~259 ~64 ~128 stone
fill ~256 ~65 ~128 ~259 ~67 ~128 dirt
fill ~256 ~68 ~128 ~259 ~68 ~128 grass_block
fill ~260 ~60 ~128 ~262 ~63 ~128 stone
fill ~260 ~64 ~128 ~262 ~66 ~128 dirt
fill ~260 ~67 ~128 ~262 ~67 ~128 grass_block
fill ~263 ~60 ~128 ~271 ~62 ~128 stone
fill ~263 ~63 ~128 ~271 ~65 ~128 dirt
fill ~263 ~66 ~128 ~271 ~66 ~128 grass_block
fill ~256 ~60 ~129 ~257 ~65 ~129 stone
fill ~256 ~66 ~129 ~257 ~68 ~129 dirt
fill ~256 ~69 ~129 ~257 ~69 ~129 grass_block
fill ~258 ~60 ~129 ~260 ~64 ~129 stone
fill ~258 ~65 ~129 ~260 ~67 ~129 dirt
fill ~258 ~68 ~129 ~260 ~68 ~129 grass_block
fill ~261 ~60 ~129 ~263 ~63 ~129 stone
fill ~261 ~64 ~129 ~263 ~66 ~129 dirt
fill ~261 ~67 ~129 ~263 ~67 ~129 grass_block
fill ~264 ~60 ~129 ~271 ~62 ~129 stone
fill ~264 ~63 ~129 ~271 ~65 ~129 dirt
fill ~264 ~66 ~129 ~271 ~66 ~129 grass_block
fill ~256 ~60 ~130 ~258 ~65 ~130 stone
fill ~256 ~66 ~130 ~258 ~68 ~130 dirt
fill ~256 ~69 ~130 ~258 ~69 ~130 grass_block
fill ~259 ~60 ~130 ~261 ~64 ~130 stone
fill ~259 ~65 ~130 ~261 ~67 ~130 dirt
fill ~259 ~68 ~130 ~261 ~68 ~130 grass_block
fill ~262 ~60 ~130 ~264 ~63 ~130 stone
fill ~262 ~64 ~130 ~264 ~66 ~130 dirt
fill ~262 ~67 ~130 ~264 ~67 ~130 grass_block
fill ~265 ~60 ~130 ~271 ~62 ~130 stone
fill ~265 ~63 ~130 ~271 ~65 ~130 dirt
fill ~265 ~66 ~130 ~271 ~66 ~130 grass_block
fill ~256 ~60 ~131 ~259 ~65 ~131 stone
fill ~256 ~66 ~131 ~259 ~68 ~131 dirt
fill ~256 ~69 ~131 ~259 ~69 ~131 grass_block
fill ~260 ~60 ~131 ~263 ~64 ~131 stone
fill ~260 ~65 ~131 ~263 ~67 ~131 dirt
fill ~260 ~68 ~131 ~263 ~68 ~131 grass_block
fill ~264 ~60 ~131 ~266 ~63 ~131 stone
fill ~264 ~64 ~131 ~266 ~66 ~131 dirt
fill ~264 ~67 ~131 ~266 ~67 ~131 grass_block
fill ~267 ~60 ~131 ~269 ~62 ~131 stone
fill ~267 ~63 ~131 ~269 ~65 ~131 dirt
fill ~267 ~66 ~131 ~269 ~66 ~131 grass_block
fill ~270 ~60 ~131 ~270 ~61 ~131 stone
fill ~270 ~62 ~131 ~270 ~64 ~131 dirt
fill ~270 ~65 ~131 ~270 ~65 ~131 grass_block
fill ~271 ~60 ~131 ~271 ~62 ~131 stone
fill ~271 ~63 ~131 ~271 ~65 ~131 dirt
fill ~271 ~66 ~131 ~271 ~66 ~131 grass_block
fill ~256 ~60 ~132 ~259 ~64 ~132 stone
fill ~256 ~65 ~132 ~259 ~67 ~132 dirt
fill ~256 ~68 ~132 ~259 ~68 ~132 grass_block
fill ~260 ~60 ~132 ~260 ~65 ~132 stone
fill ~260 ~66 ~132 ~260 ~68 ~132 dirt
fill ~260 ~69 ~132 ~260 ~69 ~132 grass_block
fill ~261 ~60 ~132 ~263 ~64 ~132 stone
fill ~261 ~65 ~132 ~263 ~67 ~132 dirt
fill ~261 ~68 ~132 ~263 ~68 ~132 grass_block
fill ~264 ~60 ~132 ~266 ~63 ~132 stone
fill ~264 ~64 ~132 ~266 ~66 ~132 dirt
fill ~264 ~67 ~132 ~266 ~67 ~132 grass_block
fill ~267 ~60 ~132 ~269 ~62 ~132 stone
fill ~267 ~63 ~132 ~269 ~65 ~132 dirt
fill ~267 ~66 ~132 ~269 ~66 ~132 grass_block
fill ~270 ~60 ~132 ~270 ~61 ~132 stone
fill ~270 ~62 ~132 ~270 ~64 ~132 dirt
fill ~270 ~65 ~132 ~270 ~65 ~132 grass_block
fill ~271 ~60 ~132 ~271 ~62 ~132 stone
fill ~271 ~63 ~132 ~271 ~65 ~132 dirt
fill ~271 ~66 ~132 ~271 ~66 ~132 grass_block
fill ~256 ~60 ~133 ~264 ~64 ~133 stone
fill ~256 ~65 ~133 ~264 ~67 ~133 dirt
fill ~256 ~68 ~133 ~264 ~68 ~133 grass_block
fill ~265 ~60 ~133 ~268 ~63 ~133 stone
fill ~265 ~64 ~133 ~268 ~66 ~133 dirt
fill ~265 ~67 ~133 ~268 ~67 ~133 grass_block
fill ~269 ~60 ~133 ~270 ~62 ~133 stone
fill ~269 ~63 ~133 ~270 ~65 ~133 dirt
fill ~269 ~66 ~133 ~270 ~66 ~133 grass_block
fill ~271 ~60 ~133 ~271 ~61 ~133 stone
fill ~271 ~62 ~133 ~271 ~64 ~133 dirt
fill ~271 ~65 ~133 ~271 ~65 ~133 grass_block
fill ~256 ~60 ~134 ~265 ~64 ~134 stone
fill ~256 ~65 ~134 ~265 ~67 ~134 dirt
fill ~256 ~68 ~134 ~265 ~68 ~134 grass_block
fill ~266 ~60 ~134 ~269 ~63 ~134 stone
fill ~266 ~64 ~134 ~269 ~66 ~134 dirt
fill ~266 ~67 ~134 ~269 ~67 ~134 grass_block
fill ~270 ~60 ~134 ~271 ~62 ~134 stone
fill ~270 ~63 ~134 ~271 ~65 ~134 dirt
fill ~270 ~66 ~134 ~271 ~66 ~134 grass_block
fill ~256 ~60 ~135 ~267 ~64 ~135 stone
fill ~256 ~65 ~135 ~267 ~67 ~135 dirt
fill ~256 ~68 ~135 ~267 ~68 ~135 grass_block
fill ~268 ~60 ~135 ~270 ~63 ~135 stone
fill ~268 ~64 ~135 ~270 ~66 ~135 dirt
fill ~268 ~67 ~135 ~270 ~67 ~135 grass_block
fill ~271 ~60 ~135 ~271 ~62 ~135 stone
fill ~271 ~63 ~135 ~271 ~65 ~135 dirt
fill ~271 ~66 ~135 ~271 ~66 ~135 grass_block
fill ~256 ~60 ~136 ~256 ~63 ~136 stone
fill ~256 ~64 ~136 ~256 ~66 ~136 dirt
fill ~256 ~67 ~136 ~256 ~67 ~136 grass_block
fill ~257 ~60 ~136 ~268 ~64 ~136 stone
fill ~257 ~65 ~136 ~268 ~67 ~136 dirt
fill ~257 ~68 ~136 ~268 ~68 ~136 grass_block
fill ~269 ~60 ~136 ~271 ~63 ~136 stone
fill ~269 ~64 ~136 ~271 ~66 ~136 dirt
fill ~269 ~67 ~136 ~271 ~67 ~136 grass_block
fill ~256 ~60 ~137 ~258 ~63 ~137 stone
fill ~256 ~64 ~137 ~258 ~66 ~137 dirt
fill ~256 ~67 ~137 ~258 ~67 ~137 grass_block
fill ~259 ~60 ~137 ~269 ~64 ~137 stone
fill ~259 ~65 ~137 ~269 ~67 ~137 dirt
fill ~259 ~68 ~137 ~269 ~68 ~137 grass_block
fill ~270 ~60 ~137 ~271 ~63 ~137 stone
fill ~270 ~64 ~137 ~271 ~66 ~137 dirt
fill ~270 ~67 ~137 ~271 ~67 ~137 grass_block
fill ~256 ~60 ~138 ~260 ~63 ~138 stone
fill ~256 ~64 ~138 ~260 ~66 ~138 dirt
fill ~256 ~67 ~138 ~260 ~67 ~138 grass_block
fill ~261 ~60 ~138 ~269 ~64 ~138 stone
fill ~261 ~65 ~138 ~269 ~67 ~138 dirt
fill ~261 ~68 ~138 ~269 ~68 ~138 grass_block
fill ~270 ~60 ~138 ~271 ~63 ~138 stone
fill ~270 ~64 ~138 ~271 ~66 ~138 dirt
fill ~270 ~67 ~138 ~271 ~67 ~138 grass_block
fill ~256 ~60 ~139 ~262 ~63 ~139 stone
fill ~256 ~64 ~139 ~262 ~66 ~139 dirt
fill ~256 ~67 ~139 ~262 ~67 ~139 grass_block
fill ~263 ~60 ~139 ~270 ~64 ~139 stone
fill ~263 ~65 ~139 ~270 ~67 ~139 dirt
fill ~263 ~68 ~139 ~270 ~68 ~139 grass_block
fill ~271 ~60 ~139 ~271 ~63 ~139 stone
fill ~271 ~64 ~139 ~271 ~66 ~139 dirt
fill ~271 ~67 ~139 ~271 ~67 ~139 grass_block
fill ~256 ~60 ~140 ~256 ~62 ~140 stone
fill ~256 ~63 ~140 ~256 ~65 ~140 dirt
fill ~256 ~66 ~140 ~256 ~66 ~140 grass_block
fill ~257 ~60 ~140 ~267 ~63 ~140 stone
fill ~257 ~64 ~140 ~267 ~66 ~140 dirt
fill ~257 ~67 ~140 ~267 ~67 ~140 grass_block
fill ~268 ~60 ~140 ~271 ~64 ~140 stone
fill ~268 ~65 ~140 ~271 ~67 ~140 dirt
fill ~268 ~68 ~140 ~271 ~68 ~140 grass_block
fill ~256 ~60 ~141 ~256 ~62 ~141 stone
fill ~256 ~63 ~141 ~256 ~65 ~141 dirt
fill ~256 ~66 ~141 ~256 ~66 ~141 grass_block
fill ~257 ~60 ~141 ~271 ~63 ~141 stone
fill ~257 ~64 ~141 ~271 ~66 ~141 dirt
fill ~257 ~67 ~141 ~271 ~67 ~141 grass_block
fill ~256 ~60 ~142 ~256 ~62 ~142 stone
fill ~256 ~63 ~142 ~256 ~65 ~142 dirt
fill ~256 ~66 ~142 ~256 ~66 ~142 grass_block
fill ~257 ~60 ~142 ~271 ~63 ~142 stone
fill ~257 ~64 ~142 ~271 ~66 ~142 dirt
fill ~257 ~67 ~142 ~271 ~67 ~142 grass_block
fill ~256 ~60 ~143 ~258 ~62 ~143 stone
fill ~256 ~63 ~143 ~258 ~65 ~143 dirt
fill ~256 ~66 ~143 ~258 ~66 ~143 grass_block
fill ~259 ~60 ~143 ~271 ~63 ~143 stone
fill ~259 ~64 ~143 ~271 ~66 ~143 dirt
fill ~259 ~67 ~143 ~271 ~67 ~143 grass_block