fill ~400 ~60 ~16 ~403 ~63 ~16 stone
fill ~400 ~64 ~16 ~403 ~66 ~16 dirt
fill ~400 ~67 ~16 ~403 ~67 ~16 grass_block
fill ~404 ~60 ~16 ~414 ~62 ~16 stone
fill ~404 ~63 ~16 ~414 ~65 ~16 dirt
fill ~404 ~66 ~16 ~414 ~66 ~16 grass_block
fill ~415 ~60 ~16 ~415 ~63 ~16 stone
fill ~415 ~64 ~16 ~415 ~66 ~16 dirt
fill ~415 ~67 ~16 ~415 ~67 ~16 grass_block
fill ~400 ~60 ~17 ~402 ~62 ~17 stone
fill ~400 ~63 ~17 ~402 ~65 ~17 dirt
fill ~400 ~66 ~17 ~402 ~66 ~17 grass_block
fill ~403 ~60 ~17 ~403 ~63 ~17 stone
fill ~403 ~64 ~17 ~403 ~66 ~17 dirt
fill ~403 ~67 ~17 ~403 ~67 ~17 grass_block
fill ~404 ~60 ~17 ~415 ~62 ~17 stone
fill ~404 ~63 ~17 ~415 ~65 ~17 dirt
fill ~404 ~66 ~17 ~415 ~66 ~17 grass_block
fill ~400 ~60 ~18 ~407 ~62 ~18 stone
fill ~400 ~63 ~18 ~407 ~65 ~18 dirt
fill ~400 ~66 ~18 ~407 ~66 ~18 grass_block
fill ~408 ~60 ~18 ~408 ~61 ~18 stone
fill ~408 ~62 ~18 ~408 ~64 ~18 dirt
fill ~408 ~65 ~18 ~408 ~65 ~18 grass_block
fill ~409 ~60 ~18 ~415 ~62 ~18 stone
fill ~409 ~63 ~18 ~415 ~65 ~18 dirt
fill ~409 ~66 ~18 ~415 ~66 ~18 grass_block
fill ~400 ~60 ~19 ~408 ~62 ~19 stone
fill ~400 ~63 ~19 ~408 ~65 ~19 dirt
fill ~400 ~66 ~19 ~408 ~66 ~19 grass_block
fill ~409 ~60 ~19 ~409 ~61 ~19 stone
fill ~409 ~62 ~19 ~409 ~64 ~19 dirt
fill ~409 ~65 ~19 ~409 ~65 ~19 grass_block
fill ~410 ~60 ~19 ~415 ~62 ~19 stone
fill ~410 ~63 ~19 ~415 ~65 ~19 dirt
fill ~410 ~66 ~19 ~415 ~66 ~19 grass_block
fill ~400 ~60 ~20 ~404 ~61 ~20 stone
fill ~400 ~62 ~20 ~404 ~64 ~20 dirt
fill ~400 ~65 ~20 ~404 ~65 ~20 grass_block
fill ~405 ~60 ~20 ~409 ~62 ~20 stone
fill ~405 ~63 ~20 ~409 ~65 ~20 dirt
fill ~405 ~66 ~20 ~409 ~66 ~20 grass_block
fill ~410 ~60 ~20 ~413 ~61 ~20 stone
fill ~410 ~62 ~20 ~413 ~64 ~20 dirt
fill ~410 ~65 ~20 ~413 ~65 ~20 grass_block
fill ~414 ~60 ~20 ~415 ~62 ~20 stone
fill ~414 ~63 ~20 ~415 ~65 ~20 dirt
fill ~414 ~66 ~20 ~415 ~66 ~20 grass_block
fill ~400 ~60 ~21 ~404 ~62 ~21 stone
fill ~400 ~63 ~21 ~404 ~65 ~21 dirt
fill ~400 ~66 ~21 ~404 ~66 ~21 grass_block
fill ~405 ~60 ~21 ~406 ~61 ~21 stone
fill ~405 ~62 ~21 ~406 ~64 ~21 dirt
fill ~405 ~65 ~21 ~406 ~65 ~21 grass_block
fill ~407 ~60 ~21 ~409 ~62 ~21 stone
fill ~407 ~63 ~21 ~409 ~65 ~21 dirt
fill ~407 ~66 ~21 ~409 ~66 ~21 grass_block
fill ~410 ~60 ~21 ~415 ~61 ~21 stone
fill ~410 ~62 ~21 ~415 ~64 ~21 dirt
fill ~410 ~65 ~21 ~415 ~65 ~21 grass_block
fill ~400 ~60 ~22 ~401 ~63 ~22 stone
fill ~400 ~64 ~22 ~401 ~66 ~22 dirt
fill ~400 ~67 ~22 ~401 ~67 ~22 grass_block
fill ~402 ~60 ~22 ~404 ~62 ~22 stone
fill ~402 ~63 ~22 ~404 ~65 ~22 dirt
fill ~402 ~66 ~22 ~404 ~66 ~22 grass_block
fill ~405 ~60 ~22 ~407 ~61 ~22 stone
fill ~405 ~62 ~22 ~407 ~64 ~22 dirt
fill ~405 ~65 ~22 ~407 ~65 ~22 grass_block
fill ~408 ~60 ~22 ~409 ~62 ~22 stone
fill ~408 ~63 ~22 ~409 ~65 ~22 dirt
fill ~408 ~66 ~22 ~409 ~66 ~22 grass_block
fill ~410 ~60 ~22 ~415 ~61 ~22 stone
fill ~410 ~62 ~22 ~415 ~64 ~22 dirt
fill ~410 ~65 ~22 ~415 ~65 ~22 grass_block
fill ~400 ~60 ~23 ~400 ~63 ~23 stone
fill ~400 ~64 ~23 ~400 ~66 ~23 dirt
fill ~400 ~67 ~23 ~400 ~67 ~23 grass_block
fill ~401 ~60 ~23 ~405 ~62 ~23 stone
fill ~401 ~63 ~23 ~405 ~65 ~23 dirt
fill ~401 ~66 ~23 ~405 ~66 ~23 grass_block
fill ~406 ~60 ~23 ~407 ~61 ~23 stone
fill ~406 ~62 ~23 ~407 ~64 ~23 dirt
fill ~406 ~65 ~23 ~407 ~65 ~23 grass_block
fill ~408 ~60 ~23 ~409 ~62 ~23 stone
fill ~408 ~63 ~23 ~409 ~65 ~23 dirt
fill ~408 ~66 ~23 ~409 ~66 ~23 grass_block
fill ~410 ~60 ~23 ~415 ~61 ~23 stone
fill ~410 ~62 ~23 ~415 ~64 ~23 dirt
fill ~410 ~65 ~23 ~415 ~65 ~23 grass_block
fill ~400 ~60 ~24 ~403 ~62 ~24 stone
fill ~400 ~63 ~24 ~403 ~65 ~24 dirt
fill ~400 ~66 ~24 ~403 ~66 ~24 grass_block
fill ~404 ~60 ~24 ~413 ~61 ~24 stone
fill ~404 ~62 ~24 ~413 ~64 ~24 dirt
fill ~404 ~65 ~24 ~413 ~65 ~24 grass_block
fill ~414 ~60 ~24 ~414 ~62 ~24 stone
fill ~414 ~63 ~24 ~414 ~65 ~24 dirt
fill ~414 ~66 ~24 ~414 ~66 ~24 grass_block
fill ~415 ~60 ~24 ~415 ~61 ~24 stone
fill ~415 ~62 ~24 ~415 ~64 ~24 dirt
fill ~415 ~65 ~24 ~415 ~65 ~24 grass_block
fill ~400 ~60 ~25 ~403 ~62 ~25 stone
fill ~400 ~63 ~25 ~403 ~65 ~25 dirt
fill ~400 ~66 ~25 ~403 ~66 ~25 grass_block
fill ~404 ~60 ~25 ~404 ~61 ~25 stone
fill ~404 ~62 ~25 ~404 ~64 ~25 dirt
fill ~404 ~65 ~25 ~404 ~65 ~25 grass_block
fill ~405 ~60 ~25 ~405 ~62 ~25 stone
fill ~405 ~63 ~25 ~405 ~65 ~25 dirt
fill ~405 ~66 ~25 ~405 ~66 ~25 grass_block
fill ~406 ~60 ~25 ~412 ~61 ~25 stone
fill ~406 ~62 ~25 ~412 ~64 ~25 dirt
fill ~406 ~65 ~25 ~412 ~65 ~25 grass_block
fill ~413 ~60 ~25 ~415 ~62 ~25 stone
fill ~413 ~63 ~25 ~415 ~65 ~25 dirt
fill ~413 ~66 ~25 ~415 ~66 ~25 grass_block
fill ~400 ~60 ~26 ~400 ~63 ~26 stone
fill ~400 ~64 ~26 ~400 ~66 ~26 dirt
fill ~400 ~67 ~26 ~400 ~67 ~26 grass_block
fill ~401 ~60 ~26 ~403 ~62 ~26 stone
fill ~401 ~63 ~26 ~403 ~65 ~26 dirt
fill ~401 ~66 ~26 ~403 ~66 ~26 grass_block
fill ~404 ~60 ~26 ~404 ~61 ~26 stone
fill ~404 ~62 ~26 ~404 ~64 ~26 dirt
fill ~404 ~65 ~26 ~404 ~65 ~26 grass_block
fill ~405 ~60 ~26 ~407 ~62 ~26 stone
fill ~405 ~63 ~26 ~407 ~65 ~26 dirt
fill ~405 ~66 ~26 ~407 ~66 ~26 grass_block
fill ~408 ~60 ~26 ~412 ~61 ~26 stone
fill ~408 ~62 ~26 ~412 ~64 ~26 dirt
fill ~408 ~65 ~26 ~412 ~65 ~26 grass_block
fill ~413 ~60 ~26 ~413 ~62 ~26 stone
fill ~413 ~63 ~26 ~413 ~65 ~26 dirt
fill ~413 ~66 ~26 ~413 ~66 ~26 grass_block
fill ~414 ~60 ~26 ~415 ~63 ~26 stone
fill ~414 ~64 ~26 ~415 ~66 ~26 dirt
fill ~414 ~67 ~26 ~415 ~67 ~26 grass_block
fill ~400 ~60 ~27 ~400 ~63 ~27 stone
fill ~400 ~64 ~27 ~400 ~66 ~27 dirt
fill ~400 ~67 ~27 ~400 ~67 ~27 grass_block
fill ~401 ~60 ~27 ~413 ~62 ~27 stone
fill ~401 ~63 ~27 ~413 ~65 ~27 dirt
fill ~401 ~66 ~27 ~413 ~66 ~27 grass_block
fill ~414 ~60 ~27 ~415 ~63 ~27 stone
fill ~414 ~64 ~27 ~415 ~66 ~27 dirt
fill ~414 ~67 ~27 ~415 ~67 ~27 grass_block
fill ~400 ~60 ~28 ~401 ~63 ~28 stone
fill ~400 ~64 ~28 ~401 ~66 ~28 dirt
fill ~400 ~67 ~28 ~401 ~67 ~28 grass_block
fill ~402 ~60 ~28 ~407 ~62 ~28 stone
fill ~402 ~63 ~28 ~407 ~65 ~28 dirt
fill ~402 ~66 ~28 ~407 ~66 ~28 grass_block
fill ~408 ~60 ~28 ~415 ~63 ~28 stone
fill ~408 ~64 ~28 ~415 ~66 ~28 dirt
fill ~408 ~67 ~28 ~415 ~67 ~28 grass_block
fill ~400 ~60 ~29 ~401 ~63 ~29 stone
fill ~400 ~64 ~29 ~401 ~66 ~29 dirt
fill ~400 ~67 ~29 ~401 ~67 ~29 grass_block
fill ~402 ~60 ~29 ~407 ~62 ~29 stone
fill ~402 ~63 ~29 ~407 ~65 ~29 dirt
fill ~402 ~66 ~29 ~407 ~66 ~29 grass_block
fill ~408 ~60 ~29 ~408 ~63 ~29 stone
fill ~408 ~64 ~29 ~408 ~66 ~29 dirt
fill ~408 ~67 ~29 ~408 ~67 ~29 grass_block
fill ~409 ~60 ~29 ~413 ~64 ~29 stone
fill ~409 ~65 ~29 ~413 ~67 ~29 dirt
fill ~409 ~68 ~29 ~413 ~68 ~29 grass_block
fill ~414 ~60 ~29 ~415 ~63 ~29 stone
fill ~414 ~64 ~29 ~415 ~66 ~29 dirt
fill ~414 ~67 ~29 ~415 ~67 ~29 grass_block
fill ~400 ~60 ~30 ~402 ~62 ~30 stone
fill ~400 ~63 ~30 ~402 ~65 ~30 dirt
fill ~400 ~66 ~30 ~402 ~66 ~30 grass_block
fill ~403 ~60 ~30 ~403 ~63 ~30 stone
fill ~403 ~64 ~30 ~403 ~66 ~30 dirt
fill ~403 ~67 ~30 ~403 ~67 ~30 grass_block
fill ~404 ~60 ~30 ~407 ~62 ~30 stone
fill ~404 ~63 ~30 ~407 ~65 ~30 dirt
fill ~404 ~66 ~30 ~407 ~66 ~30 grass_block
fill ~408 ~60 ~30 ~409 ~63 ~30 stone
fill ~408 ~64 ~30 ~409 ~66 ~30 dirt
fill ~408 ~67 ~30 ~409 ~67 ~30 grass_block
fill ~410 ~60 ~30 ~413 ~64 ~30 stone
fill ~410 ~65 ~30 ~413 ~67 ~30 dirt
fill ~410 ~68 ~30 ~413 ~68 ~30 grass_block
fill ~414 ~60 ~30 ~415 ~63 ~30 stone
fill ~414 ~64 ~30 ~415 ~66 ~30 dirt
fill ~414 ~67 ~30 ~415 ~67 ~30 grass_block
fill ~400 ~60 ~31 ~401 ~62 ~31 stone
fill ~400 ~63 ~31 ~401 ~65 ~31 dirt
fill ~400 ~66 ~31 ~401 ~66 ~31 grass_block
fill ~402 ~60 ~31 ~403 ~63 ~31 stone
fill ~402 ~64 ~31 ~403 ~66 ~31 dirt
fill ~402 ~67 ~31 ~403 ~67 ~31 grass_block
fill ~404 ~60 ~31 ~404 ~64 ~31 stone
fill ~404 ~65 ~31 ~404 ~67 ~31 dirt
fill ~404 ~68 ~31 ~404 ~68 ~31 grass_block
fill ~405 ~60 ~31 ~409 ~63 ~31 stone
fill ~405 ~64 ~31 ~409 ~66 ~31 dirt
fill ~405 ~67 ~31 ~409 ~67 ~31 grass_block
fill ~410 ~60 ~31 ~412 ~64 ~31 stone
fill ~410 ~65 ~31 ~412 ~67 ~31 dirt
fill ~410 ~68 ~31 ~412 ~68 ~31 grass_block
fill ~413 ~60 ~31 ~415 ~63 ~31 stone
fill ~413 ~64 ~31 ~415 ~66 ~31 dirt
fill ~413 ~67 ~31 ~415 ~67 ~31 grass_block