fill ~240 ~60 ~128 ~243 ~64 ~128 stone
fill ~240 ~65 ~128 ~243 ~67 ~128 dirt
fill ~240 ~68 ~128 ~243 ~68 ~128 grass_block
fill ~244 ~60 ~128 ~255 ~65 ~128 stone
fill ~244 ~66 ~128 ~255 ~68 ~128 dirt
fill ~244 ~69 ~128 ~255 ~69 ~128 grass_block
fill ~240 ~60 ~129 ~244 ~64 ~129 stone
fill ~240 ~65 ~129 ~244 ~67 ~129 dirt
fill ~240 ~68 ~129 ~244 ~68 ~129 grass_block
fill ~245 ~60 ~129 ~255 ~65 ~129 stone
fill ~245 ~66 ~129 ~255 ~68 ~129 dirt
fill ~245 ~69 ~129 ~255 ~69 ~129 grass_block
fill ~240 ~60 ~130 ~240 ~63 ~130 stone
fill ~240 ~64 ~130 ~240 ~66 ~130 dirt
fill ~240 ~67 ~130 ~240 ~67 ~130 grass_block
fill ~241 ~60 ~130 ~245 ~64 ~130 stone
fill ~241 ~65 ~130 ~245 ~67 ~130 dirt
fill ~241 ~68 ~130 ~245 ~68 ~130 grass_block
fill ~246 ~60 ~130 ~246 ~65 ~130 stone
fill ~246 ~66 ~130 ~246 ~68 ~130 dirt
fill ~246 ~69 ~130 ~246 ~69 ~130 grass_block
fill ~247 ~60 ~130 ~252 ~64 ~130 stone
fill ~247 ~65 ~130 ~252 ~67 ~130 dirt
fill ~247 ~68 ~130 ~252 ~68 ~130 grass_block
fill ~253 ~60 ~130 ~255 ~65 ~130 stone
fill ~253 ~66 ~130 ~255 ~68 ~130 dirt
fill ~253 ~69 ~130 ~255 ~69 ~130 grass_block
fill ~240 ~60 ~131 ~241 ~63 ~131 stone
fill ~240 ~64 ~131 ~241 ~66 ~131 dirt
fill ~240 ~67 ~131 ~241 ~67 ~131 grass_block
fill ~242 ~60 ~131 ~255 ~64 ~131 stone
fill ~242 ~65 ~131 ~255 ~67 ~131 dirt
fill ~242 ~68 ~131 ~255 ~68 ~131 grass_block
fill ~240 ~60 ~132 ~242 ~63 ~132 stone
fill ~240 ~64 ~132 ~242 ~66 ~132 dirt
fill ~240 ~67 ~132 ~242 ~67 ~132 grass_block
fill ~243 ~60 ~132 ~255 ~64 ~132 stone
fill ~243 ~65 ~132 ~255 ~67 ~132 dirt
fill ~243 ~68 ~132 ~255 ~68 ~132 grass_block
fill ~240 ~60 ~133 ~243 ~63 ~133 stone
fill ~240 ~64 ~133 ~243 ~66 ~133 dirt
fill ~240 ~67 ~133 ~243 ~67 ~133 grass_block
fill ~244 ~60 ~133 ~249 ~64 ~133 stone
fill ~244 ~65 ~133 ~249 ~67 ~133 dirt
fill ~244 ~68 ~133 ~249 ~68 ~133 grass_block
fill ~250 ~60 ~133 ~251 ~63 ~133 stone
fill ~250 ~64 ~133 ~251 ~66 ~133 dirt
fill ~250 ~67 ~133 ~251 ~67 ~133 grass_block
fill ~252 ~60 ~133 ~255 ~64 ~133 stone
fill ~252 ~65 ~133 ~255 ~67 ~133 dirt
fill ~252 ~68 ~133 ~255 ~68 ~133 grass_block
fill ~240 ~60 ~134 ~244 ~63 ~134 stone
fill ~240 ~64 ~134 ~244 ~66 ~134 dirt
fill ~240 ~67 ~134 ~244 ~67 ~134 grass_block
fill ~245 ~60 ~134 ~249 ~64 ~134 stone
fill ~245 ~65 ~134 ~249 ~67 ~134 dirt
fill ~245 ~68 ~134 ~249 ~68 ~134 grass_block
fill ~250 ~60 ~134 ~253 ~63 ~134 stone
fill ~250 ~64 ~134 ~253 ~66 ~134 dirt
fill ~250 ~67 ~134 ~253 ~67 ~134 grass_block
fill ~254 ~60 ~134 ~255 ~64 ~134 stone
fill ~254 ~65 ~134 ~255 ~67 ~134 dirt
fill ~254 ~68 ~134 ~255 ~68 ~134 grass_block
fill ~240 ~60 ~135 ~245 ~63 ~135 stone
fill ~240 ~64 ~135 ~245 ~66 ~135 dirt
fill ~240 ~67 ~135 ~245 ~67 ~135 grass_block
fill ~246 ~60 ~135 ~250 ~64 ~135 stone
fill ~246 ~65 ~135 ~250 ~67 ~135 dirt
fill ~246 ~68 ~135 ~250 ~68 ~135 grass_block
fill ~251 ~60 ~135 ~255 ~63 ~135 stone
fill ~251 ~64 ~135 ~255 ~66 ~135 dirt
fill ~251 ~67 ~135 ~255 ~67 ~135 grass_block
fill ~240 ~60 ~136 ~240 ~63 ~136 stone
fill ~240 ~64 ~136 ~240 ~66 ~136 dirt
fill ~240 ~67 ~136 ~240 ~67 ~136 grass_block
fill ~241 ~60 ~136 ~241 ~62 ~136 stone
fill ~241 ~63 ~136 ~241 ~65 ~136 dirt
fill ~241 ~66 ~136 ~241 ~66 ~136 grass_block
fill ~242 ~60 ~136 ~247 ~63 ~136 stone
fill ~242 ~64 ~136 ~247 ~66 ~136 dirt
fill ~242 ~67 ~136 ~247 ~67 ~136 grass_block
fill ~248 ~60 ~136 ~248 ~64 ~136 stone
fill ~248 ~65 ~136 ~248 ~67 ~136 dirt
fill ~248 ~68 ~136 ~248 ~68 ~136 grass_block
fill ~249 ~60 ~136 ~249 ~63 ~136 stone
fill ~249 ~64 ~136 ~249 ~66 ~136 dirt
fill ~249 ~67 ~136 ~249 ~67 ~136 grass_block
fill ~250 ~60 ~136 ~250 ~64 ~136 stone
fill ~250 ~65 ~136 ~250 ~67 ~136 dirt
fill ~250 ~68 ~136 ~250 ~68 ~136 grass_block
fill ~251 ~60 ~136 ~255 ~63 ~136 stone
fill ~251 ~64 ~136 ~255 ~66 ~136 dirt
fill ~251 ~67 ~136 ~255 ~67 ~136 grass_block
fill ~240 ~60 ~137 ~240 ~63 ~137 stone
fill ~240 ~64 ~137 ~240 ~66 ~137 dirt
fill ~240 ~67 ~137 ~240 ~67 ~137 grass_block
fill ~241 ~60 ~137 ~241 ~62 ~137 stone
fill ~241 ~63 ~137 ~241 ~65 ~137 dirt
fill ~241 ~66 ~137 ~241 ~66 ~137 grass_block
fill ~242 ~60 ~137 ~255 ~63 ~137 stone
fill ~242 ~64 ~137 ~255 ~66 ~137 dirt
fill ~242 ~67 ~137 ~255 ~67 ~137 grass_block
fill ~240 ~60 ~138 ~242 ~62 ~138 stone
fill ~240 ~63 ~138 ~242 ~65 ~138 dirt
fill ~240 ~66 ~138 ~242 ~66 ~138 grass_block
fill ~243 ~60 ~138 ~253 ~63 ~138 stone
fill ~243 ~64 ~138 ~253 ~66 ~138 dirt
fill ~243 ~67 ~138 ~253 ~67 ~138 grass_block
fill ~254 ~60 ~138 ~254 ~62 ~138 stone
fill ~254 ~63 ~138 ~254 ~65 ~138 dirt
fill ~254 ~66 ~138 ~254 ~66 ~138 grass_block
fill ~255 ~60 ~138 ~255 ~63 ~138 stone
fill ~255 ~64 ~138 ~255 ~66 ~138 dirt
fill ~255 ~67 ~138 ~255 ~67 ~138 grass_block
fill ~240 ~60 ~139 ~243 ~62 ~139 stone
fill ~240 ~63 ~139 ~243 ~65 ~139 dirt
fill ~240 ~66 ~139 ~243 ~66 ~139 grass_block
fill ~244 ~60 ~139 ~253 ~63 ~139 stone
fill ~244 ~64 ~139 ~253 ~66 ~139 dirt
fill ~244 ~67 ~139 ~253 ~67 ~139 grass_block
fill ~254 ~60 ~139 ~255 ~62 ~139 stone
fill ~254 ~63 ~139 ~255 ~65 ~139 dirt
fill ~254 ~66 ~139 ~255 ~66 ~139 grass_block
fill ~240 ~60 ~140 ~245 ~62 ~140 stone
fill ~240 ~63 ~140 ~245 ~65 ~140 dirt
fill ~240 ~66 ~140 ~245 ~66 ~140 grass_block
fill ~246 ~60 ~140 ~253 ~63 ~140 stone
fill ~246 ~64 ~140 ~253 ~66 ~140 dirt
fill ~246 ~67 ~140 ~253 ~67 ~140 grass_block
fill ~254 ~60 ~140 ~255 ~62 ~140 stone
fill ~254 ~63 ~140 ~255 ~65 ~140 dirt
fill ~254 ~66 ~140 ~255 ~66 ~140 grass_block
fill ~240 ~60 ~141 ~246 ~62 ~141 stone
fill ~240 ~63 ~141 ~246 ~65 ~141 dirt
fill ~240 ~66 ~141 ~246 ~66 ~141 grass_block
fill ~247 ~60 ~141 ~252 ~63 ~141 stone
fill ~247 ~64 ~141 ~252 ~66 ~141 dirt
fill ~247 ~67 ~141 ~252 ~67 ~141 grass_block
fill ~253 ~60 ~141 ~255 ~62 ~141 stone
fill ~253 ~63 ~141 ~255 ~65 ~141 dirt
fill ~253 ~66 ~141 ~255 ~66 ~141 grass_block
fill ~240 ~60 ~142 ~248 ~62 ~142 stone
fill ~240 ~63 ~142 ~248 ~65 ~142 dirt
fill ~240 ~66 ~142 ~248 ~66 ~142 grass_block
fill ~249 ~60 ~142 ~253 ~63 ~142 stone
fill ~249 ~64 ~142 ~253 ~66 ~142 dirt
fill ~249 ~67 ~142 ~253 ~67 ~142 grass_block
fill ~254 ~60 ~142 ~255 ~62 ~142 stone
fill ~254 ~63 ~142 ~255 ~65 ~142 dirt
fill ~254 ~66 ~142 ~255 ~66 ~142 grass_block
fill ~240 ~60 ~143 ~251 ~62 ~143 stone
fill ~240 ~63 ~143 ~251 ~65 ~143 dirt
fill ~240 ~66 ~143 ~251 ~66 ~143 grass_block
fill ~252 ~60 ~143 ~253 ~63 ~143 stone
fill ~252 ~64 ~143 ~253 ~66 ~143 dirt
fill ~252 ~67 ~143 ~253 ~67 ~143 grass_block
fill ~254 ~60 ~143 ~255 ~62 ~143 stone
fill ~254 ~63 ~143 ~255 ~65 ~143 dirt
fill ~254 ~66 ~143 ~255 ~66 ~143 grass_block