fill ~384 ~60 ~128 ~384 ~62 ~128 stone
fill ~384 ~63 ~128 ~384 ~65 ~128 dirt
fill ~384 ~66 ~128 ~384 ~66 ~128 grass_block
fill ~385 ~60 ~128 ~388 ~61 ~128 stone
fill ~385 ~62 ~128 ~388 ~64 ~128 dirt
fill ~385 ~65 ~128 ~388 ~65 ~128 grass_block
fill ~389 ~60 ~128 ~390 ~62 ~128 stone
fill ~389 ~63 ~128 ~390 ~65 ~128 dirt
fill ~389 ~66 ~128 ~390 ~66 ~128 grass_block
fill ~391 ~60 ~128 ~398 ~63 ~128 stone
fill ~391 ~64 ~128 ~398 ~66 ~128 dirt
fill ~391 ~67 ~128 ~398 ~67 ~128 grass_block
fill ~399 ~60 ~128 ~399 ~64 ~128 stone
fill ~399 ~65 ~128 ~399 ~67 ~128 dirt
fill ~399 ~68 ~128 ~399 ~68 ~128 grass_block
fill ~384 ~60 ~129 ~385 ~62 ~129 stone
fill ~384 ~63 ~129 ~385 ~65 ~129 dirt
fill ~384 ~66 ~129 ~385 ~66 ~129 grass_block
fill ~386 ~60 ~129 ~389 ~61 ~129 stone
fill ~386 ~62 ~129 ~389 ~64 ~129 dirt
fill ~386 ~65 ~129 ~389 ~65 ~129 grass_block
fill ~390 ~60 ~129 ~391 ~62 ~129 stone
fill ~390 ~63 ~129 ~391 ~65 ~129 dirt
fill ~390 ~66 ~129 ~391 ~66 ~129 grass_block
fill ~392 ~60 ~129 ~398 ~63 ~129 stone
fill ~392 ~64 ~129 ~398 ~66 ~129 dirt
fill ~392 ~67 ~129 ~398 ~67 ~129 grass_block
fill ~399 ~60 ~129 ~399 ~64 ~129 stone
fill ~399 ~65 ~129 ~399 ~67 ~129 dirt
fill ~399 ~68 ~129 ~399 ~68 ~129 grass_block
fill ~384 ~60 ~130 ~385 ~62 ~130 stone
fill ~384 ~63 ~130 ~385 ~65 ~130 dirt
fill ~384 ~66 ~130 ~385 ~66 ~130 grass_block
fill ~386 ~60 ~130 ~389 ~61 ~130 stone
fill ~386 ~62 ~130 ~389 ~64 ~130 dirt
fill ~386 ~65 ~130 ~389 ~65 ~130 grass_block
fill ~390 ~60 ~130 ~392 ~62 ~130 stone
fill ~390 ~63 ~130 ~392 ~65 ~130 dirt
fill ~390 ~66 ~130 ~392 ~66 ~130 grass_block
fill ~393 ~60 ~130 ~399 ~63 ~130 stone
fill ~393 ~64 ~130 ~399 ~66 ~130 dirt
fill ~393 ~67 ~130 ~399 ~67 ~130 grass_block
fill ~384 ~60 ~131 ~385 ~62 ~131 stone
fill ~384 ~63 ~131 ~385 ~65 ~131 dirt
fill ~384 ~66 ~131 ~385 ~66 ~131 grass_block
fill ~386 ~60 ~131 ~389 ~61 ~131 stone
fill ~386 ~62 ~131 ~389 ~64 ~131 dirt
fill ~386 ~65 ~131 ~389 ~65 ~131 grass_block
fill ~390 ~60 ~131 ~392 ~62 ~131 stone
fill ~390 ~63 ~131 ~392 ~65 ~131 dirt
fill ~390 ~66 ~131 ~392 ~66 ~131 grass_block
fill ~393 ~60 ~131 ~399 ~63 ~131 stone
fill ~393 ~64 ~131 ~399 ~66 ~131 dirt
fill ~393 ~67 ~131 ~399 ~67 ~131 grass_block
fill ~384 ~60 ~132 ~385 ~62 ~132 stone
fill ~384 ~63 ~132 ~385 ~65 ~132 dirt
fill ~384 ~66 ~132 ~385 ~66 ~132 grass_block
fill ~386 ~60 ~132 ~390 ~61 ~132 stone
fill ~386 ~62 ~132 ~390 ~64 ~132 dirt
fill ~386 ~65 ~132 ~390 ~65 ~132 grass_block
fill ~391 ~60 ~132 ~393 ~62 ~132 stone
fill ~391 ~63 ~132 ~393 ~65 ~132 dirt
fill ~391 ~66 ~132 ~393 ~66 ~132 grass_block
fill ~394 ~60 ~132 ~399 ~63 ~132 stone
fill ~394 ~64 ~132 ~399 ~66 ~132 dirt
fill ~394 ~67 ~132 ~399 ~67 ~132 grass_block
fill ~384 ~60 ~133 ~385 ~62 ~133 stone
fill ~384 ~63 ~133 ~385 ~65 ~133 dirt
fill ~384 ~66 ~133 ~385 ~66 ~133 grass_block
fill ~386 ~60 ~133 ~390 ~61 ~133 stone
fill ~386 ~62 ~133 ~390 ~64 ~133 dirt
fill ~386 ~65 ~133 ~390 ~65 ~133 grass_block
fill ~391 ~60 ~133 ~394 ~62 ~133 stone
fill ~391 ~63 ~133 ~394 ~65 ~133 dirt
fill ~391 ~66 ~133 ~394 ~66 ~133 grass_block
fill ~395 ~60 ~133 ~399 ~63 ~133 stone
fill ~395 ~64 ~133 ~399 ~66 ~133 dirt
fill ~395 ~67 ~133 ~399 ~67 ~133 grass_block
fill ~384 ~60 ~134 ~386 ~62 ~134 stone
fill ~384 ~63 ~134 ~386 ~65 ~134 dirt
fill ~384 ~66 ~134 ~386 ~66 ~134 grass_block
fill ~387 ~60 ~134 ~391 ~61 ~134 stone
fill ~387 ~62 ~134 ~391 ~64 ~134 dirt
fill ~387 ~65 ~134 ~391 ~65 ~134 grass_block
fill ~392 ~60 ~134 ~399 ~62 ~134 stone
fill ~392 ~63 ~134 ~399 ~65 ~134 dirt
fill ~392 ~66 ~134 ~399 ~66 ~134 grass_block
fill ~384 ~60 ~135 ~384 ~61 ~135 stone
fill ~384 ~62 ~135 ~384 ~64 ~135 dirt
fill ~384 ~65 ~135 ~384 ~65 ~135 grass_block
fill ~385 ~60 ~135 ~386 ~62 ~135 stone
fill ~385 ~63 ~135 ~386 ~65 ~135 dirt
fill ~385 ~66 ~135 ~386 ~66 ~135 grass_block
fill ~387 ~60 ~135 ~393 ~61 ~135 stone
fill ~387 ~62 ~135 ~393 ~64 ~135 dirt
fill ~387 ~65 ~135 ~393 ~65 ~135 grass_block
fill ~394 ~60 ~135 ~399 ~62 ~135 stone
fill ~394 ~63 ~135 ~399 ~65 ~135 dirt
fill ~394 ~66 ~135 ~399 ~66 ~135 grass_block
fill ~384 ~60 ~136 ~394 ~61 ~136 stone
fill ~384 ~62 ~136 ~394 ~64 ~136 dirt
fill ~384 ~65 ~136 ~394 ~65 ~136 grass_block
fill ~395 ~60 ~136 ~399 ~62 ~136 stone
fill ~395 ~63 ~136 ~399 ~65 ~136 dirt
fill ~395 ~66 ~136 ~399 ~66 ~136 grass_block
fill ~384 ~60 ~137 ~387 ~60 ~137 stone
fill ~384 ~61 ~137 ~387 ~63 ~137 dirt
fill ~384 ~64 ~137 ~387 ~64 ~137 grass_block
fill ~388 ~60 ~137 ~399 ~61 ~137 stone
fill ~388 ~62 ~137 ~399 ~64 ~137 dirt
fill ~388 ~65 ~137 ~399 ~65 ~137 grass_block
fill ~384 ~60 ~138 ~392 ~60 ~138 stone
fill ~384 ~61 ~138 ~392 ~63 ~138 dirt
fill ~384 ~64 ~138 ~392 ~64 ~138 grass_block
fill ~393 ~60 ~138 ~399 ~61 ~138 stone
fill ~393 ~62 ~138 ~399 ~64 ~138 dirt
fill ~393 ~65 ~138 ~399 ~65 ~138 grass_block
fill ~384 ~60 ~139 ~399 ~60 ~139 stone
fill ~384 ~61 ~139 ~399 ~63 ~139 dirt
fill ~384 ~64 ~139 ~399 ~64 ~139 grass_block
fill ~384 ~60 ~140 ~399 ~60 ~140 stone
fill ~384 ~61 ~140 ~399 ~63 ~140 dirt
fill ~384 ~64 ~140 ~399 ~64 ~140 grass_block
fill ~384 ~60 ~141 ~399 ~60 ~141 stone
fill ~384 ~61 ~141 ~399 ~63 ~141 dirt
fill ~384 ~64 ~141 ~399 ~64 ~141 grass_block
fill ~384 ~60 ~142 ~399 ~60 ~142 stone
fill ~384 ~61 ~142 ~399 ~63 ~142 dirt
fill ~384 ~64 ~142 ~399 ~64 ~142 grass_block
fill ~384 ~60 ~143 ~399 ~60 ~143 stone
fill ~384 ~61 ~143 ~399 ~63 ~143 dirt
fill ~384 ~64 ~143 ~399 ~64 ~143 grass_block