fill ~80 ~60 ~112 ~86 ~67 ~112 stone
fill ~80 ~68 ~112 ~86 ~70 ~112 dirt
fill ~80 ~71 ~112 ~86 ~71 ~112 grass_block
fill ~87 ~60 ~112 ~92 ~66 ~112 stone
fill ~87 ~67 ~112 ~92 ~69 ~112 dirt
fill ~87 ~70 ~112 ~92 ~70 ~112 grass_block
fill ~93 ~60 ~112 ~95 ~67 ~112 stone
fill ~93 ~68 ~112 ~95 ~70 ~112 dirt
fill ~93 ~71 ~112 ~95 ~71 ~112 grass_block
fill ~80 ~60 ~113 ~82 ~67 ~113 stone
fill ~80 ~68 ~113 ~82 ~70 ~113 dirt
fill ~80 ~71 ~113 ~82 ~71 ~113 grass_block
fill ~83 ~60 ~113 ~83 ~66 ~113 stone
fill ~83 ~67 ~113 ~83 ~69 ~113 dirt
fill ~83 ~70 ~113 ~83 ~70 ~113 grass_block
fill ~84 ~60 ~113 ~86 ~67 ~113 stone
fill ~84 ~68 ~113 ~86 ~70 ~113 dirt
fill ~84 ~71 ~113 ~86 ~71 ~113 grass_block
fill ~87 ~60 ~113 ~88 ~66 ~113 stone
fill ~87 ~67 ~113 ~88 ~69 ~113 dirt
fill ~87 ~70 ~113 ~88 ~70 ~113 grass_block
fill ~89 ~60 ~113 ~91 ~65 ~113 stone
fill ~89 ~66 ~113 ~91 ~68 ~113 dirt
fill ~89 ~69 ~113 ~91 ~69 ~113 grass_block
fill ~92 ~60 ~113 ~92 ~66 ~113 stone
fill ~92 ~67 ~113 ~92 ~69 ~113 dirt
fill ~92 ~70 ~113 ~92 ~70 ~113 grass_block
fill ~93 ~60 ~113 ~95 ~67 ~113 stone
fill ~93 ~68 ~113 ~95 ~70 ~113 dirt
fill ~93 ~71 ~113 ~95 ~71 ~113 grass_block
fill ~80 ~60 ~114 ~83 ~67 ~114 stone
fill ~80 ~68 ~114 ~83 ~70 ~114 dirt
fill ~80 ~71 ~114 ~83 ~71 ~114 grass_block
fill ~84 ~60 ~114 ~88 ~66 ~114 stone
fill ~84 ~67 ~114 ~88 ~69 ~114 dirt
fill ~84 ~70 ~114 ~88 ~70 ~114 grass_block
fill ~89 ~60 ~114 ~91 ~65 ~114 stone
fill ~89 ~66 ~114 ~91 ~68 ~114 dirt
fill ~89 ~69 ~114 ~91 ~69 ~114 grass_block
fill ~92 ~60 ~114 ~93 ~66 ~114 stone
fill ~92 ~67 ~114 ~93 ~69 ~114 dirt
fill ~92 ~70 ~114 ~93 ~70 ~114 grass_block
fill ~94 ~60 ~114 ~95 ~67 ~114 stone
fill ~94 ~68 ~114 ~95 ~70 ~114 dirt
fill ~94 ~71 ~114 ~95 ~71 ~114 grass_block
fill ~80 ~60 ~115 ~83 ~67 ~115 stone
fill ~80 ~68 ~115 ~83 ~70 ~115 dirt
fill ~80 ~71 ~115 ~83 ~71 ~115 grass_block
fill ~84 ~60 ~115 ~86 ~66 ~115 stone
fill ~84 ~67 ~115 ~86 ~69 ~115 dirt
fill ~84 ~70 ~115 ~86 ~70 ~115 grass_block
fill ~87 ~60 ~115 ~91 ~65 ~115 stone
fill ~87 ~66 ~115 ~91 ~68 ~115 dirt
fill ~87 ~69 ~115 ~91 ~69 ~115 grass_block
fill ~92 ~60 ~115 ~93 ~66 ~115 stone
fill ~92 ~67 ~115 ~93 ~69 ~115 dirt
fill ~92 ~70 ~115 ~93 ~70 ~115 grass_block
fill ~94 ~60 ~115 ~95 ~67 ~115 stone
fill ~94 ~68 ~115 ~95 ~70 ~115 dirt
fill ~94 ~71 ~115 ~95 ~71 ~115 grass_block
fill ~80 ~60 ~116 ~80 ~66 ~116 stone
fill ~80 ~67 ~116 ~80 ~69 ~116 dirt
fill ~80 ~70 ~116 ~80 ~70 ~116 grass_block
fill ~81 ~60 ~116 ~84 ~67 ~116 stone
fill ~81 ~68 ~116 ~84 ~70 ~116 dirt
fill ~81 ~71 ~116 ~84 ~71 ~116 grass_block
fill ~85 ~60 ~116 ~85 ~66 ~116 stone
fill ~85 ~67 ~116 ~85 ~69 ~116 dirt
fill ~85 ~70 ~116 ~85 ~70 ~116 grass_block
fill ~86 ~60 ~116 ~92 ~65 ~116 stone
fill ~86 ~66 ~116 ~92 ~68 ~116 dirt
fill ~86 ~69 ~116 ~92 ~69 ~116 grass_block
fill ~93 ~60 ~116 ~94 ~66 ~116 stone
fill ~93 ~67 ~116 ~94 ~69 ~116 dirt
fill ~93 ~70 ~116 ~94 ~70 ~116 grass_block
fill ~95 ~60 ~116 ~95 ~67 ~116 stone
fill ~95 ~68 ~116 ~95 ~70 ~116 dirt
fill ~95 ~71 ~116 ~95 ~71 ~116 grass_block
fill ~80 ~60 ~117 ~81 ~66 ~117 stone
fill ~80 ~67 ~117 ~81 ~69 ~117 dirt
fill ~80 ~70 ~117 ~81 ~70 ~117 grass_block
fill ~82 ~60 ~117 ~84 ~67 ~117 stone
fill ~82 ~68 ~117 ~84 ~70 ~117 dirt
fill ~82 ~71 ~117 ~84 ~71 ~117 grass_block
fill ~85 ~60 ~117 ~86 ~66 ~117 stone
fill ~85 ~67 ~117 ~86 ~69 ~117 dirt
fill ~85 ~70 ~117 ~86 ~70 ~117 grass_block
fill ~87 ~60 ~117 ~92 ~65 ~117 stone
fill ~87 ~66 ~117 ~92 ~68 ~117 dirt
fill ~87 ~69 ~117 ~92 ~69 ~117 grass_block
fill ~93 ~60 ~117 ~95 ~66 ~117 stone
fill ~93 ~67 ~117 ~95 ~69 ~117 dirt
fill ~93 ~70 ~117 ~95 ~70 ~117 grass_block
fill ~80 ~60 ~118 ~80 ~65 ~118 stone
fill ~80 ~66 ~118 ~80 ~68 ~118 dirt
fill ~80 ~69 ~118 ~80 ~69 ~118 grass_block
fill ~81 ~60 ~118 ~82 ~66 ~118 stone
fill ~81 ~67 ~118 ~82 ~69 ~118 dirt
fill ~81 ~70 ~118 ~82 ~70 ~118 grass_block
fill ~83 ~60 ~118 ~85 ~67 ~118 stone
fill ~83 ~68 ~118 ~85 ~70 ~118 dirt
fill ~83 ~71 ~118 ~85 ~71 ~118 grass_block
fill ~86 ~60 ~118 ~87 ~66 ~118 stone
fill ~86 ~67 ~118 ~87 ~69 ~118 dirt
fill ~86 ~70 ~118 ~87 ~70 ~118 grass_block
fill ~88 ~60 ~118 ~90 ~65 ~118 stone
fill ~88 ~66 ~118 ~90 ~68 ~118 dirt
fill ~88 ~69 ~118 ~90 ~69 ~118 grass_block
fill ~91 ~60 ~118 ~91 ~64 ~118 stone
fill ~91 ~65 ~118 ~91 ~67 ~118 dirt
fill ~91 ~68 ~118 ~91 ~68 ~118 grass_block
fill ~92 ~60 ~118 ~93 ~65 ~118 stone
fill ~92 ~66 ~118 ~93 ~68 ~118 dirt
fill ~92 ~69 ~118 ~93 ~69 ~118 grass_block
fill ~94 ~60 ~118 ~95 ~66 ~118 stone
fill ~94 ~67 ~118 ~95 ~69 ~118 dirt
fill ~94 ~70 ~118 ~95 ~70 ~118 grass_block
fill ~80 ~60 ~119 ~81 ~65 ~119 stone
fill ~80 ~66 ~119 ~81 ~68 ~119 dirt
fill ~80 ~69 ~119 ~81 ~69 ~119 grass_block
fill ~82 ~60 ~119 ~83 ~66 ~119 stone
fill ~82 ~67 ~119 ~83 ~69 ~119 dirt
fill ~82 ~70 ~119 ~83 ~70 ~119 grass_block
fill ~84 ~60 ~119 ~85 ~67 ~119 stone
fill ~84 ~68 ~119 ~85 ~70 ~119 dirt
fill ~84 ~71 ~119 ~85 ~71 ~119 grass_block
fill ~86 ~60 ~119 ~87 ~66 ~119 stone
fill ~86 ~67 ~119 ~87 ~69 ~119 dirt
fill ~86 ~70 ~119 ~87 ~70 ~119 grass_block
fill ~88 ~60 ~119 ~90 ~65 ~119 stone
fill ~88 ~66 ~119 ~90 ~68 ~119 dirt
fill ~88 ~69 ~119 ~90 ~69 ~119 grass_block
fill ~91 ~60 ~119 ~92 ~64 ~119 stone
fill ~91 ~65 ~119 ~92 ~67 ~119 dirt
fill ~91 ~68 ~119 ~92 ~68 ~119 grass_block
fill ~93 ~60 ~119 ~94 ~65 ~119 stone
fill ~93 ~66 ~119 ~94 ~68 ~119 dirt
fill ~93 ~69 ~119 ~94 ~69 ~119 grass_block
fill ~95 ~60 ~119 ~95 ~66 ~119 stone
fill ~95 ~67 ~119 ~95 ~69 ~119 dirt
fill ~95 ~70 ~119 ~95 ~70 ~119 grass_block
fill ~80 ~60 ~120 ~81 ~65 ~120 stone
fill ~80 ~66 ~120 ~81 ~68 ~120 dirt
fill ~80 ~69 ~120 ~81 ~69 ~120 grass_block
fill ~82 ~60 ~120 ~87 ~66 ~120 stone
fill ~82 ~67 ~120 ~87 ~69 ~120 dirt
fill ~82 ~70 ~120 ~87 ~70 ~120 grass_block
fill ~88 ~60 ~120 ~90 ~65 ~120 stone
fill ~88 ~66 ~120 ~90 ~68 ~120 dirt
fill ~88 ~69 ~120 ~90 ~69 ~120 grass_block
fill ~91 ~60 ~120 ~93 ~64 ~120 stone
fill ~91 ~65 ~120 ~93 ~67 ~120 dirt
fill ~91 ~68 ~120 ~93 ~68 ~120 grass_block
fill ~94 ~60 ~120 ~95 ~65 ~120 stone
fill ~94 ~66 ~120 ~95 ~68 ~120 dirt
fill ~94 ~69 ~120 ~95 ~69 ~120 grass_block
fill ~80 ~60 ~121 ~83 ~65 ~121 stone
fill ~80 ~66 ~121 ~83 ~68 ~121 dirt
fill ~80 ~69 ~121 ~83 ~69 ~121 grass_block
fill ~84 ~60 ~121 ~87 ~66 ~121 stone
fill ~84 ~67 ~121 ~87 ~69 ~121 dirt
fill ~84 ~70 ~121 ~87 ~70 ~121 grass_block
fill ~88 ~60 ~121 ~91 ~65 ~121 stone
fill ~88 ~66 ~121 ~91 ~68 ~121 dirt
fill ~88 ~69 ~121 ~91 ~69 ~121 grass_block
fill ~92 ~60 ~121 ~94 ~64 ~121 stone
fill ~92 ~65 ~121 ~94 ~67 ~121 dirt
fill ~92 ~68 ~121 ~94 ~68 ~121 grass_block
fill ~95 ~60 ~121 ~95 ~65 ~121 stone
fill ~95 ~66 ~121 ~95 ~68 ~121 dirt
fill ~95 ~69 ~121 ~95 ~69 ~121 grass_block
fill ~80 ~60 ~122 ~80 ~64 ~122 stone
fill ~80 ~65 ~122 ~80 ~67 ~122 dirt
fill ~80 ~68 ~122 ~80 ~68 ~122 grass_block
fill ~81 ~60 ~122 ~86 ~65 ~122 stone
fill ~81 ~66 ~122 ~86 ~68 ~122 dirt
fill ~81 ~69 ~122 ~86 ~69 ~122 grass_block
fill ~87 ~60 ~122 ~88 ~66 ~122 stone
fill ~87 ~67 ~122 ~88 ~69 ~122 dirt
fill ~87 ~70 ~122 ~88 ~70 ~122 grass_block
fill ~89 ~60 ~122 ~91 ~65 ~122 stone
fill ~89 ~66 ~122 ~91 ~68 ~122 dirt
fill ~89 ~69 ~122 ~91 ~69 ~122 grass_block
fill ~92 ~60 ~122 ~95 ~64 ~122 stone
fill ~92 ~65 ~122 ~95 ~67 ~122 dirt
fill ~92 ~68 ~122 ~95 ~68 ~122 grass_block
fill ~80 ~60 ~123 ~83 ~64 ~123 stone
fill ~80 ~65 ~123 ~83 ~67 ~123 dirt
fill ~80 ~68 ~123 ~83 ~68 ~123 grass_block
fill ~84 ~60 ~123 ~87 ~65 ~123 stone
fill ~84 ~66 ~123 ~87 ~68 ~123 dirt
fill ~84 ~69 ~123 ~87 ~69 ~123 grass_block
fill ~88 ~60 ~123 ~89 ~66 ~123 stone
fill ~88 ~67 ~123 ~89 ~69 ~123 dirt
fill ~88 ~70 ~123 ~89 ~70 ~123 grass_block
fill ~90 ~60 ~123 ~91 ~65 ~123 stone
fill ~90 ~66 ~123 ~91 ~68 ~123 dirt
fill ~90 ~69 ~123 ~91 ~69 ~123 grass_block
fill ~92 ~60 ~123 ~95 ~64 ~123 stone
fill ~92 ~65 ~123 ~95 ~67 ~123 dirt
fill ~92 ~68 ~123 ~95 ~68 ~123 grass_block
fill ~80 ~60 ~124 ~85 ~64 ~124 stone
fill ~80 ~65 ~124 ~85 ~67 ~124 dirt
fill ~80 ~68 ~124 ~85 ~68 ~124 grass_block
fill ~86 ~60 ~124 ~92 ~65 ~124 stone
fill ~86 ~66 ~124 ~92 ~68 ~124 dirt
fill ~86 ~69 ~124 ~92 ~69 ~124 grass_block
fill ~93 ~60 ~124 ~95 ~64 ~124 stone
fill ~93 ~65 ~124 ~95 ~67 ~124 dirt
fill ~93 ~68 ~124 ~95 ~68 ~124 grass_block
fill ~80 ~60 ~125 ~81 ~63 ~125 stone
fill ~80 ~64 ~125 ~81 ~66 ~125 dirt
fill ~80 ~67 ~125 ~81 ~67 ~125 grass_block
fill ~82 ~60 ~125 ~86 ~64 ~125 stone
fill ~82 ~65 ~125 ~86 ~67 ~125 dirt
fill ~82 ~68 ~125 ~86 ~68 ~125 grass_block
fill ~87 ~60 ~125 ~92 ~65 ~125 stone
fill ~87 ~66 ~125 ~92 ~68 ~125 dirt
fill ~87 ~69 ~125 ~92 ~69 ~125 grass_block
fill ~93 ~60 ~125 ~95 ~64 ~125 stone
fill ~93 ~65 ~125 ~95 ~67 ~125 dirt
fill ~93 ~68 ~125 ~95 ~68 ~125 grass_block
fill ~80 ~60 ~126 ~85 ~63 ~126 stone
fill ~80 ~64 ~126 ~85 ~66 ~126 dirt
fill ~80 ~67 ~126 ~85 ~67 ~126 grass_block
fill ~86 ~60 ~126 ~88 ~64 ~126 stone
fill ~86 ~65 ~126 ~88 ~67 ~126 dirt
fill ~86 ~68 ~126 ~88 ~68 ~126 grass_block
fill ~89 ~60 ~126 ~93 ~65 ~126 stone
fill ~89 ~66 ~126 ~93 ~68 ~126 dirt
fill ~89 ~69 ~126 ~93 ~69 ~126 grass_block
fill ~94 ~60 ~126 ~95 ~64 ~126 stone
fill ~94 ~65 ~126 ~95 ~67 ~126 dirt
fill ~94 ~68 ~126 ~95 ~68 ~126 grass_block
fill ~80 ~60 ~127 ~86 ~63 ~127 stone
fill ~80 ~64 ~127 ~86 ~66 ~127 dirt
fill ~80 ~67 ~127 ~86 ~67 ~127 grass_block
fill ~87 ~60 ~127 ~92 ~64 ~127 stone
fill ~87 ~65 ~127 ~92 ~67 ~127 dirt
fill ~87 ~68 ~127 ~92 ~68 ~127 grass_block
fill ~93 ~60 ~127 ~94 ~65 ~127 stone
fill ~93 ~66 ~127 ~94 ~68 ~127 dirt
fill ~93 ~69 ~127 ~94 ~69 ~127 grass_block
fill ~95 ~60 ~127 ~95 ~64 ~127 stone
fill ~95 ~65 ~127 ~95 ~67 ~127 dirt
fill ~95 ~68 ~127 ~95 ~68 ~127 grass_block