fill ~0 ~60 ~48 ~8 ~69 ~48 stone
fill ~0 ~70 ~48 ~8 ~72 ~48 dirt
fill ~0 ~73 ~48 ~8 ~73 ~48 grass_block
fill ~9 ~60 ~48 ~11 ~68 ~48 stone
fill ~9 ~69 ~48 ~11 ~71 ~48 dirt
fill ~9 ~72 ~48 ~11 ~72 ~48 grass_block
fill ~12 ~60 ~48 ~14 ~67 ~48 stone
fill ~12 ~68 ~48 ~14 ~70 ~48 dirt
fill ~12 ~71 ~48 ~14 ~71 ~48 grass_block
fill ~15 ~60 ~48 ~15 ~66 ~48 stone
fill ~15 ~67 ~48 ~15 ~69 ~48 dirt
fill ~15 ~70 ~48 ~15 ~70 ~48 grass_block
fill ~0 ~60 ~49 ~3 ~69 ~49 stone
fill ~0 ~70 ~49 ~3 ~72 ~49 dirt
fill ~0 ~73 ~49 ~3 ~73 ~49 grass_block
fill ~4 ~60 ~49 ~6 ~70 ~49 stone
fill ~4 ~71 ~49 ~6 ~73 ~49 dirt
fill ~4 ~74 ~49 ~6 ~74 ~49 grass_block
fill ~7 ~60 ~49 ~10 ~69 ~49 stone
fill ~7 ~70 ~49 ~10 ~72 ~49 dirt
fill ~7 ~73 ~49 ~10 ~73 ~49 grass_block
fill ~11 ~60 ~49 ~13 ~68 ~49 stone
fill ~11 ~69 ~49 ~13 ~71 ~49 dirt
fill ~11 ~72 ~49 ~13 ~72 ~49 grass_block
fill ~14 ~60 ~49 ~15 ~67 ~49 stone
fill ~14 ~68 ~49 ~15 ~70 ~49 dirt
fill ~14 ~71 ~49 ~15 ~71 ~49 grass_block
fill ~0 ~60 ~50 ~0 ~68 ~50 stone
fill ~0 ~69 ~50 ~0 ~71 ~50 dirt
fill ~0 ~72 ~50 ~0 ~72 ~50 grass_block
fill ~1 ~60 ~50 ~4 ~69 ~50 stone
fill ~1 ~70 ~50 ~4 ~72 ~50 dirt
fill ~1 ~73 ~50 ~4 ~73 ~50 grass_block
fill ~5 ~60 ~50 ~8 ~70 ~50 stone
fill ~5 ~71 ~50 ~8 ~73 ~50 dirt
fill ~5 ~74 ~50 ~8 ~74 ~50 grass_block
fill ~9 ~60 ~50 ~12 ~69 ~50 stone
fill ~9 ~70 ~50 ~12 ~72 ~50 dirt
fill ~9 ~73 ~50 ~12 ~73 ~50 grass_block
fill ~13 ~60 ~50 ~15 ~68 ~50 stone
fill ~13 ~69 ~50 ~15 ~71 ~50 dirt
fill ~13 ~72 ~50 ~15 ~72 ~50 grass_block
fill ~0 ~60 ~51 ~1 ~68 ~51 stone
fill ~0 ~69 ~51 ~1 ~71 ~51 dirt
fill ~0 ~72 ~51 ~1 ~72 ~51 grass_block
fill ~2 ~60 ~51 ~4 ~69 ~51 stone
fill ~2 ~70 ~51 ~4 ~72 ~51 dirt
fill ~2 ~73 ~51 ~4 ~73 ~51 grass_block
fill ~5 ~60 ~51 ~8 ~70 ~51 stone
fill ~5 ~71 ~51 ~8 ~73 ~51 dirt
fill ~5 ~74 ~51 ~8 ~74 ~51 grass_block
fill ~9 ~60 ~51 ~9 ~69 ~51 stone
fill ~9 ~70 ~51 ~9 ~72 ~51 dirt
fill ~9 ~73 ~51 ~9 ~73 ~51 grass_block
fill ~10 ~60 ~51 ~10 ~70 ~51 stone
fill ~10 ~71 ~51 ~10 ~73 ~51 dirt
fill ~10 ~74 ~51 ~10 ~74 ~51 grass_block
fill ~11 ~60 ~51 ~13 ~69 ~51 stone
fill ~11 ~70 ~51 ~13 ~72 ~51 dirt
fill ~11 ~73 ~51 ~13 ~73 ~51 grass_block
fill ~14 ~60 ~51 ~15 ~68 ~51 stone
fill ~14 ~69 ~51 ~15 ~71 ~51 dirt
fill ~14 ~72 ~51 ~15 ~72 ~51 grass_block
fill ~0 ~60 ~52 ~2 ~68 ~52 stone
fill ~0 ~69 ~52 ~2 ~71 ~52 dirt
fill ~0 ~72 ~52 ~2 ~72 ~52 grass_block
fill ~3 ~60 ~52 ~5 ~69 ~52 stone
fill ~3 ~70 ~52 ~5 ~72 ~52 dirt
fill ~3 ~73 ~52 ~5 ~73 ~52 grass_block
fill ~6 ~60 ~52 ~11 ~70 ~52 stone
fill ~6 ~71 ~52 ~11 ~73 ~52 dirt
fill ~6 ~74 ~52 ~11 ~74 ~52 grass_block
fill ~12 ~60 ~52 ~14 ~69 ~52 stone
fill ~12 ~70 ~52 ~14 ~72 ~52 dirt
fill ~12 ~73 ~52 ~14 ~73 ~52 grass_block
fill ~15 ~60 ~52 ~15 ~68 ~52 stone
fill ~15 ~69 ~52 ~15 ~71 ~52 dirt
fill ~15 ~72 ~52 ~15 ~72 ~52 grass_block
fill ~0 ~60 ~53 ~1 ~67 ~53 stone
fill ~0 ~68 ~53 ~1 ~70 ~53 dirt
fill ~0 ~71 ~53 ~1 ~71 ~53 grass_block
fill ~2 ~60 ~53 ~2 ~68 ~53 stone
fill ~2 ~69 ~53 ~2 ~71 ~53 dirt
fill ~2 ~72 ~53 ~2 ~72 ~53 grass_block
fill ~3 ~60 ~53 ~6 ~69 ~53 stone
fill ~3 ~70 ~53 ~6 ~72 ~53 dirt
fill ~3 ~73 ~53 ~6 ~73 ~53 grass_block
fill ~7 ~60 ~53 ~12 ~70 ~53 stone
fill ~7 ~71 ~53 ~12 ~73 ~53 dirt
fill ~7 ~74 ~53 ~12 ~74 ~53 grass_block
fill ~13 ~60 ~53 ~15 ~69 ~53 stone
fill ~13 ~70 ~53 ~15 ~72 ~53 dirt
fill ~13 ~73 ~53 ~15 ~73 ~53 grass_block
fill ~0 ~60 ~54 ~1 ~67 ~54 stone
fill ~0 ~68 ~54 ~1 ~70 ~54 dirt
fill ~0 ~71 ~54 ~1 ~71 ~54 grass_block
fill ~2 ~60 ~54 ~4 ~68 ~54 stone
fill ~2 ~69 ~54 ~4 ~71 ~54 dirt
fill ~2 ~72 ~54 ~4 ~72 ~54 grass_block
fill ~5 ~60 ~54 ~7 ~69 ~54 stone
fill ~5 ~70 ~54 ~7 ~72 ~54 dirt
fill ~5 ~73 ~54 ~7 ~73 ~54 grass_block
fill ~8 ~60 ~54 ~12 ~70 ~54 stone
fill ~8 ~71 ~54 ~12 ~73 ~54 dirt
fill ~8 ~74 ~54 ~12 ~74 ~54 grass_block
fill ~13 ~60 ~54 ~15 ~69 ~54 stone
fill ~13 ~70 ~54 ~15 ~72 ~54 dirt
fill ~13 ~73 ~54 ~15 ~73 ~54 grass_block
fill ~0 ~60 ~55 ~0 ~66 ~55 stone
fill ~0 ~67 ~55 ~0 ~69 ~55 dirt
fill ~0 ~70 ~55 ~0 ~70 ~55 grass_block
fill ~1 ~60 ~55 ~2 ~67 ~55 stone
fill ~1 ~68 ~55 ~2 ~70 ~55 dirt
fill ~1 ~71 ~55 ~2 ~71 ~55 grass_block
fill ~3 ~60 ~55 ~5 ~68 ~55 stone
fill ~3 ~69 ~55 ~5 ~71 ~55 dirt
fill ~3 ~72 ~55 ~5 ~72 ~55 grass_block
fill ~6 ~60 ~55 ~7 ~69 ~55 stone
fill ~6 ~70 ~55 ~7 ~72 ~55 dirt
fill ~6 ~73 ~55 ~7 ~73 ~55 grass_block
fill ~8 ~60 ~55 ~13 ~70 ~55 stone
fill ~8 ~71 ~55 ~13 ~73 ~55 dirt
fill ~8 ~74 ~55 ~13 ~74 ~55 grass_block
fill ~14 ~60 ~55 ~15 ~69 ~55 stone
fill ~14 ~70 ~55 ~15 ~72 ~55 dirt
fill ~14 ~73 ~55 ~15 ~73 ~55 grass_block
fill ~0 ~60 ~56 ~1 ~66 ~56 stone
fill ~0 ~67 ~56 ~1 ~69 ~56 dirt
fill ~0 ~70 ~56 ~1 ~70 ~56 grass_block
fill ~2 ~60 ~56 ~4 ~67 ~56 stone
fill ~2 ~68 ~56 ~4 ~70 ~56 dirt
fill ~2 ~71 ~56 ~4 ~71 ~56 grass_block
fill ~5 ~60 ~56 ~5 ~68 ~56 stone
fill ~5 ~69 ~56 ~5 ~71 ~56 dirt
fill ~5 ~72 ~56 ~5 ~72 ~56 grass_block
fill ~6 ~60 ~56 ~11 ~69 ~56 stone
fill ~6 ~70 ~56 ~11 ~72 ~56 dirt
fill ~6 ~73 ~56 ~11 ~73 ~56 grass_block
fill ~12 ~60 ~56 ~13 ~70 ~56 stone
fill ~12 ~71 ~56 ~13 ~73 ~56 dirt
fill ~12 ~74 ~56 ~13 ~74 ~56 grass_block
fill ~14 ~60 ~56 ~15 ~69 ~56 stone
fill ~14 ~70 ~56 ~15 ~72 ~56 dirt
fill ~14 ~73 ~56 ~15 ~73 ~56 grass_block
fill ~0 ~60 ~57 ~2 ~66 ~57 stone
fill ~0 ~67 ~57 ~2 ~69 ~57 dirt
fill ~0 ~70 ~57 ~2 ~70 ~57 grass_block
fill ~3 ~60 ~57 ~5 ~67 ~57 stone
fill ~3 ~68 ~57 ~5 ~70 ~57 dirt
fill ~3 ~71 ~57 ~5 ~71 ~57 grass_block
fill ~6 ~60 ~57 ~7 ~68 ~57 stone
fill ~6 ~69 ~57 ~7 ~71 ~57 dirt
fill ~6 ~72 ~57 ~7 ~72 ~57 grass_block
fill ~8 ~60 ~57 ~12 ~69 ~57 stone
fill ~8 ~70 ~57 ~12 ~72 ~57 dirt
fill ~8 ~73 ~57 ~12 ~73 ~57 grass_block
fill ~13 ~60 ~57 ~14 ~70 ~57 stone
fill ~13 ~71 ~57 ~14 ~73 ~57 dirt
fill ~13 ~74 ~57 ~14 ~74 ~57 grass_block
fill ~15 ~60 ~57 ~15 ~69 ~57 stone
fill ~15 ~70 ~57 ~15 ~72 ~57 dirt
fill ~15 ~73 ~57 ~15 ~73 ~57 grass_block
fill ~0 ~60 ~58 ~3 ~66 ~58 stone
fill ~0 ~67 ~58 ~3 ~69 ~58 dirt
fill ~0 ~70 ~58 ~3 ~70 ~58 grass_block
fill ~4 ~60 ~58 ~6 ~67 ~58 stone
fill ~4 ~68 ~58 ~6 ~70 ~58 dirt
fill ~4 ~71 ~58 ~6 ~71 ~58 grass_block
fill ~7 ~60 ~58 ~10 ~68 ~58 stone
fill ~7 ~69 ~58 ~10 ~71 ~58 dirt
fill ~7 ~72 ~58 ~10 ~72 ~58 grass_block
fill ~11 ~60 ~58 ~13 ~69 ~58 stone
fill ~11 ~70 ~58 ~13 ~72 ~58 dirt
fill ~11 ~73 ~58 ~13 ~73 ~58 grass_block
fill ~14 ~60 ~58 ~15 ~70 ~58 stone
fill ~14 ~71 ~58 ~15 ~73 ~58 dirt
fill ~14 ~74 ~58 ~15 ~74 ~58 grass_block
fill ~0 ~60 ~59 ~1 ~65 ~59 stone
fill ~0 ~66 ~59 ~1 ~68 ~59 dirt
fill ~0 ~69 ~59 ~1 ~69 ~59 grass_block
fill ~2 ~60 ~59 ~4 ~66 ~59 stone
fill ~2 ~67 ~59 ~4 ~69 ~59 dirt
fill ~2 ~70 ~59 ~4 ~70 ~59 grass_block
fill ~5 ~60 ~59 ~6 ~67 ~59 stone
fill ~5 ~68 ~59 ~6 ~70 ~59 dirt
fill ~5 ~71 ~59 ~6 ~71 ~59 grass_block
fill ~7 ~60 ~59 ~11 ~68 ~59 stone
fill ~7 ~69 ~59 ~11 ~71 ~59 dirt
fill ~7 ~72 ~59 ~11 ~72 ~59 grass_block
fill ~12 ~60 ~59 ~12 ~69 ~59 stone
fill ~12 ~70 ~59 ~12 ~72 ~59 dirt
fill ~12 ~73 ~59 ~12 ~73 ~59 grass_block
fill ~13 ~60 ~59 ~15 ~70 ~59 stone
fill ~13 ~71 ~59 ~15 ~73 ~59 dirt
fill ~13 ~74 ~59 ~15 ~74 ~59 grass_block
fill ~0 ~60 ~60 ~2 ~65 ~60 stone
fill ~0 ~66 ~60 ~2 ~68 ~60 dirt
fill ~0 ~69 ~60 ~2 ~69 ~60 grass_block
fill ~3 ~60 ~60 ~5 ~66 ~60 stone
fill ~3 ~67 ~60 ~5 ~69 ~60 dirt
fill ~3 ~70 ~60 ~5 ~70 ~60 grass_block
fill ~6 ~60 ~60 ~7 ~67 ~60 stone
fill ~6 ~68 ~60 ~7 ~70 ~60 dirt
fill ~6 ~71 ~60 ~7 ~71 ~60 grass_block
fill ~8 ~60 ~60 ~11 ~68 ~60 stone
fill ~8 ~69 ~60 ~11 ~71 ~60 dirt
fill ~8 ~72 ~60 ~11 ~72 ~60 grass_block
fill ~12 ~60 ~60 ~13 ~69 ~60 stone
fill ~12 ~70 ~60 ~13 ~72 ~60 dirt
fill ~12 ~73 ~60 ~13 ~73 ~60 grass_block
fill ~14 ~60 ~60 ~15 ~70 ~60 stone
fill ~14 ~71 ~60 ~15 ~73 ~60 dirt
fill ~14 ~74 ~60 ~15 ~74 ~60 grass_block
fill ~0 ~60 ~61 ~3 ~65 ~61 stone
fill ~0 ~66 ~61 ~3 ~68 ~61 dirt
fill ~0 ~69 ~61 ~3 ~69 ~61 grass_block
fill ~4 ~60 ~61 ~5 ~66 ~61 stone
fill ~4 ~67 ~61 ~5 ~69 ~61 dirt
fill ~4 ~70 ~61 ~5 ~70 ~61 grass_block
fill ~6 ~60 ~61 ~10 ~67 ~61 stone
fill ~6 ~68 ~61 ~10 ~70 ~61 dirt
fill ~6 ~71 ~61 ~10 ~71 ~61 grass_block
fill ~11 ~60 ~61 ~12 ~68 ~61 stone
fill ~11 ~69 ~61 ~12 ~71 ~61 dirt
fill ~11 ~72 ~61 ~12 ~72 ~61 grass_block
fill ~13 ~60 ~61 ~14 ~69 ~61 stone
fill ~13 ~70 ~61 ~14 ~72 ~61 dirt
fill ~13 ~73 ~61 ~14 ~73 ~61 grass_block
fill ~15 ~60 ~61 ~15 ~70 ~61 stone
fill ~15 ~71 ~61 ~15 ~73 ~61 dirt
fill ~15 ~74 ~61 ~15 ~74 ~61 grass_block
fill ~0 ~60 ~62 ~2 ~65 ~62 stone
fill ~0 ~66 ~62 ~2 ~68 ~62 dirt
fill ~0 ~69 ~62 ~2 ~69 ~62 grass_block
fill ~3 ~60 ~62 ~4 ~66 ~62 stone
fill ~3 ~67 ~62 ~4 ~69 ~62 dirt
fill ~3 ~70 ~62 ~4 ~70 ~62 grass_block
fill ~5 ~60 ~62 ~10 ~67 ~62 stone
fill ~5 ~68 ~62 ~10 ~70 ~62 dirt
fill ~5 ~71 ~62 ~10 ~71 ~62 grass_block
fill ~11 ~60 ~62 ~13 ~68 ~62 stone
fill ~11 ~69 ~62 ~13 ~71 ~62 dirt
fill ~11 ~72 ~62 ~13 ~72 ~62 grass_block
fill ~14 ~60 ~62 ~14 ~69 ~62 stone
fill ~14 ~70 ~62 ~14 ~72 ~62 dirt
fill ~14 ~73 ~62 ~14 ~73 ~62 grass_block
fill ~15 ~60 ~62 ~15 ~70 ~62 stone
fill ~15 ~71 ~62 ~15 ~73 ~62 dirt
fill ~15 ~74 ~62 ~15 ~74 ~62 grass_block
fill ~0 ~60 ~63 ~1 ~65 ~63 stone
fill ~0 ~66 ~63 ~1 ~68 ~63 dirt
fill ~0 ~69 ~63 ~1 ~69 ~63 grass_block
fill ~2 ~60 ~63 ~3 ~66 ~63 stone
fill ~2 ~67 ~63 ~3 ~69 ~63 dirt
fill ~2 ~70 ~63 ~3 ~70 ~63 grass_block
fill ~4 ~60 ~63 ~7 ~67 ~63 stone
fill ~4 ~68 ~63 ~7 ~70 ~63 dirt
fill ~4 ~71 ~63 ~7 ~71 ~63 grass_block
fill ~8 ~60 ~63 ~8 ~66 ~63 stone
fill ~8 ~67 ~63 ~8 ~69 ~63 dirt
fill ~8 ~70 ~63 ~8 ~70 ~63 grass_block
fill ~9 ~60 ~63 ~12 ~67 ~63 stone
fill ~9 ~68 ~63 ~12 ~70 ~63 dirt
fill ~9 ~71 ~63 ~12 ~71 ~63 grass_block
fill ~13 ~60 ~63 ~14 ~68 ~63 stone
fill ~13 ~69 ~63 ~14 ~71 ~63 dirt
fill ~13 ~72 ~63 ~14 ~72 ~63 grass_block
fill ~15 ~60 ~63 ~15 ~69 ~63 stone
fill ~15 ~70 ~63 ~15 ~72 ~63 dirt
fill ~15 ~73 ~63 ~15 ~73 ~63 grass_block