fill ~96 ~60 ~16 ~105 ~69 ~16 stone
fill ~96 ~70 ~16 ~105 ~72 ~16 dirt
fill ~96 ~73 ~16 ~105 ~73 ~16 grass_block
fill ~106 ~60 ~16 ~108 ~68 ~16 stone
fill ~106 ~69 ~16 ~108 ~71 ~16 dirt
fill ~106 ~72 ~16 ~108 ~72 ~16 grass_block
fill ~109 ~60 ~16 ~111 ~67 ~16 stone
fill ~109 ~68 ~16 ~111 ~70 ~16 dirt
fill ~109 ~71 ~16 ~111 ~71 ~16 grass_block
fill ~96 ~60 ~17 ~106 ~69 ~17 stone
fill ~96 ~70 ~17 ~106 ~72 ~17 dirt
fill ~96 ~73 ~17 ~106 ~73 ~17 grass_block
fill ~107 ~60 ~17 ~109 ~68 ~17 stone
fill ~107 ~69 ~17 ~109 ~71 ~17 dirt
fill ~107 ~72 ~17 ~109 ~72 ~17 grass_block
fill ~110 ~60 ~17 ~111 ~67 ~17 stone
fill ~110 ~68 ~17 ~111 ~70 ~17 dirt
fill ~110 ~71 ~17 ~111 ~71 ~17 grass_block
fill ~96 ~60 ~18 ~107 ~69 ~18 stone
fill ~96 ~70 ~18 ~107 ~72 ~18 dirt
fill ~96 ~73 ~18 ~107 ~73 ~18 grass_block
fill ~108 ~60 ~18 ~110 ~68 ~18 stone
fill ~108 ~69 ~18 ~110 ~71 ~18 dirt
fill ~108 ~72 ~18 ~110 ~72 ~18 grass_block
fill ~111 ~60 ~18 ~111 ~67 ~18 stone
fill ~111 ~68 ~18 ~111 ~70 ~18 dirt
fill ~111 ~71 ~18 ~111 ~71 ~18 grass_block
fill ~96 ~60 ~19 ~107 ~69 ~19 stone
fill ~96 ~70 ~19 ~107 ~72 ~19 dirt
fill ~96 ~73 ~19 ~107 ~73 ~19 grass_block
fill ~108 ~60 ~19 ~111 ~68 ~19 stone
fill ~108 ~69 ~19 ~111 ~71 ~19 dirt
fill ~108 ~72 ~19 ~111 ~72 ~19 grass_block
fill ~96 ~60 ~20 ~108 ~69 ~20 stone
fill ~96 ~70 ~20 ~108 ~72 ~20 dirt
fill ~96 ~73 ~20 ~108 ~73 ~20 grass_block
fill ~109 ~60 ~20 ~111 ~68 ~20 stone
fill ~109 ~69 ~20 ~111 ~71 ~20 dirt
fill ~109 ~72 ~20 ~111 ~72 ~20 grass_block
fill ~96 ~60 ~21 ~97 ~68 ~21 stone
fill ~96 ~69 ~21 ~97 ~71 ~21 dirt
fill ~96 ~72 ~21 ~97 ~72 ~21 grass_block
fill ~98 ~60 ~21 ~108 ~69 ~21 stone
fill ~98 ~70 ~21 ~108 ~72 ~21 dirt
fill ~98 ~73 ~21 ~108 ~73 ~21 grass_block
fill ~109 ~60 ~21 ~111 ~68 ~21 stone
fill ~109 ~69 ~21 ~111 ~71 ~21 dirt
fill ~109 ~72 ~21 ~111 ~72 ~21 grass_block
fill ~96 ~60 ~22 ~98 ~68 ~22 stone
fill ~96 ~69 ~22 ~98 ~71 ~22 dirt
fill ~96 ~72 ~22 ~98 ~72 ~22 grass_block
fill ~99 ~60 ~22 ~109 ~69 ~22 stone
fill ~99 ~70 ~22 ~109 ~72 ~22 dirt
fill ~99 ~73 ~22 ~109 ~73 ~22 grass_block
fill ~110 ~60 ~22 ~111 ~68 ~22 stone
fill ~110 ~69 ~22 ~111 ~71 ~22 dirt
fill ~110 ~72 ~22 ~111 ~72 ~22 grass_block
fill ~96 ~60 ~23 ~99 ~68 ~23 stone
fill ~96 ~69 ~23 ~99 ~71 ~23 dirt
fill ~96 ~72 ~23 ~99 ~72 ~23 grass_block
fill ~100 ~60 ~23 ~109 ~69 ~23 stone
fill ~100 ~70 ~23 ~109 ~72 ~23 dirt
fill ~100 ~73 ~23 ~109 ~73 ~23 grass_block
fill ~110 ~60 ~23 ~111 ~68 ~23 stone
fill ~110 ~69 ~23 ~111 ~71 ~23 dirt
fill ~110 ~72 ~23 ~111 ~72 ~23 grass_block
fill ~96 ~60 ~24 ~97 ~67 ~24 stone
fill ~96 ~68 ~24 ~97 ~70 ~24 dirt
fill ~96 ~71 ~24 ~97 ~71 ~24 grass_block
fill ~98 ~60 ~24 ~100 ~68 ~24 stone
fill ~98 ~69 ~24 ~100 ~71 ~24 dirt
fill ~98 ~72 ~24 ~100 ~72 ~24 grass_block
fill ~101 ~60 ~24 ~109 ~69 ~24 stone
fill ~101 ~70 ~24 ~109 ~72 ~24 dirt
fill ~101 ~73 ~24 ~109 ~73 ~24 grass_block
fill ~110 ~60 ~24 ~111 ~68 ~24 stone
fill ~110 ~69 ~24 ~111 ~71 ~24 dirt
fill ~110 ~72 ~24 ~111 ~72 ~24 grass_block
fill ~96 ~60 ~25 ~98 ~67 ~25 stone
fill ~96 ~68 ~25 ~98 ~70 ~25 dirt
fill ~96 ~71 ~25 ~98 ~71 ~25 grass_block
fill ~99 ~60 ~25 ~103 ~68 ~25 stone
fill ~99 ~69 ~25 ~103 ~71 ~25 dirt
fill ~99 ~72 ~25 ~103 ~72 ~25 grass_block
fill ~104 ~60 ~25 ~108 ~69 ~25 stone
fill ~104 ~70 ~25 ~108 ~72 ~25 dirt
fill ~104 ~73 ~25 ~108 ~73 ~25 grass_block
fill ~109 ~60 ~25 ~111 ~68 ~25 stone
fill ~109 ~69 ~25 ~111 ~71 ~25 dirt
fill ~109 ~72 ~25 ~111 ~72 ~25 grass_block
fill ~96 ~60 ~26 ~97 ~66 ~26 stone
fill ~96 ~67 ~26 ~97 ~69 ~26 dirt
fill ~96 ~70 ~26 ~97 ~70 ~26 grass_block
fill ~98 ~60 ~26 ~102 ~67 ~26 stone
fill ~98 ~68 ~26 ~102 ~70 ~26 dirt
fill ~98 ~71 ~26 ~102 ~71 ~26 grass_block
fill ~103 ~60 ~26 ~103 ~68 ~26 stone
fill ~103 ~69 ~26 ~103 ~71 ~26 dirt
fill ~103 ~72 ~26 ~103 ~72 ~26 grass_block
fill ~104 ~60 ~26 ~106 ~69 ~26 stone
fill ~104 ~70 ~26 ~106 ~72 ~26 dirt
fill ~104 ~73 ~26 ~106 ~73 ~26 grass_block
fill ~107 ~60 ~26 ~111 ~68 ~26 stone
fill ~107 ~69 ~26 ~111 ~71 ~26 dirt
fill ~107 ~72 ~26 ~111 ~72 ~26 grass_block
fill ~96 ~60 ~27 ~99 ~66 ~27 stone
fill ~96 ~67 ~27 ~99 ~69 ~27 dirt
fill ~96 ~70 ~27 ~99 ~70 ~27 grass_block
fill ~100 ~60 ~27 ~102 ~67 ~27 stone
fill ~100 ~68 ~27 ~102 ~70 ~27 dirt
fill ~100 ~71 ~27 ~102 ~71 ~27 grass_block
fill ~103 ~60 ~27 ~105 ~68 ~27 stone
fill ~103 ~69 ~27 ~105 ~71 ~27 dirt
fill ~103 ~72 ~27 ~105 ~72 ~27 grass_block
fill ~106 ~60 ~27 ~107 ~69 ~27 stone
fill ~106 ~70 ~27 ~107 ~72 ~27 dirt
fill ~106 ~73 ~27 ~107 ~73 ~27 grass_block
fill ~108 ~60 ~27 ~111 ~68 ~27 stone
fill ~108 ~69 ~27 ~111 ~71 ~27 dirt
fill ~108 ~72 ~27 ~111 ~72 ~27 grass_block
fill ~96 ~60 ~28 ~100 ~66 ~28 stone
fill ~96 ~67 ~28 ~100 ~69 ~28 dirt
fill ~96 ~70 ~28 ~100 ~70 ~28 grass_block
fill ~101 ~60 ~28 ~103 ~67 ~28 stone
fill ~101 ~68 ~28 ~103 ~70 ~28 dirt
fill ~101 ~71 ~28 ~103 ~71 ~28 grass_block
fill ~104 ~60 ~28 ~106 ~68 ~28 stone
fill ~104 ~69 ~28 ~106 ~71 ~28 dirt
fill ~104 ~72 ~28 ~106 ~72 ~28 grass_block
fill ~107 ~60 ~28 ~107 ~69 ~28 stone
fill ~107 ~70 ~28 ~107 ~72 ~28 dirt
fill ~107 ~73 ~28 ~107 ~73 ~28 grass_block
fill ~108 ~60 ~28 ~110 ~68 ~28 stone
fill ~108 ~69 ~28 ~110 ~71 ~28 dirt
fill ~108 ~72 ~28 ~110 ~72 ~28 grass_block
fill ~111 ~60 ~28 ~111 ~67 ~28 stone
fill ~111 ~68 ~28 ~111 ~70 ~28 dirt
fill ~111 ~71 ~28 ~111 ~71 ~28 grass_block
fill ~96 ~60 ~29 ~96 ~67 ~29 stone
fill ~96 ~68 ~29 ~96 ~70 ~29 dirt
fill ~96 ~71 ~29 ~96 ~71 ~29 grass_block
fill ~97 ~60 ~29 ~97 ~66 ~29 stone
fill ~97 ~67 ~29 ~97 ~69 ~29 dirt
fill ~97 ~70 ~29 ~97 ~70 ~29 grass_block
fill ~98 ~60 ~29 ~98 ~65 ~29 stone
fill ~98 ~66 ~29 ~98 ~68 ~29 dirt
fill ~98 ~69 ~29 ~98 ~69 ~29 grass_block
fill ~99 ~60 ~29 ~101 ~66 ~29 stone
fill ~99 ~67 ~29 ~101 ~69 ~29 dirt
fill ~99 ~70 ~29 ~101 ~70 ~29 grass_block
fill ~102 ~60 ~29 ~103 ~67 ~29 stone
fill ~102 ~68 ~29 ~103 ~70 ~29 dirt
fill ~102 ~71 ~29 ~103 ~71 ~29 grass_block
fill ~104 ~60 ~29 ~110 ~68 ~29 stone
fill ~104 ~69 ~29 ~110 ~71 ~29 dirt
fill ~104 ~72 ~29 ~110 ~72 ~29 grass_block
fill ~111 ~60 ~29 ~111 ~67 ~29 stone
fill ~111 ~68 ~29 ~111 ~70 ~29 dirt
fill ~111 ~71 ~29 ~111 ~71 ~29 grass_block
fill ~96 ~60 ~30 ~96 ~67 ~30 stone
fill ~96 ~68 ~30 ~96 ~70 ~30 dirt
fill ~96 ~71 ~30 ~96 ~71 ~30 grass_block
fill ~97 ~60 ~30 ~97 ~66 ~30 stone
fill ~97 ~67 ~30 ~97 ~69 ~30 dirt
fill ~97 ~70 ~30 ~97 ~70 ~30 grass_block
fill ~98 ~60 ~30 ~100 ~65 ~30 stone
fill ~98 ~66 ~30 ~100 ~68 ~30 dirt
fill ~98 ~69 ~30 ~100 ~69 ~30 grass_block
fill ~101 ~60 ~30 ~102 ~66 ~30 stone
fill ~101 ~67 ~30 ~102 ~69 ~30 dirt
fill ~101 ~70 ~30 ~102 ~70 ~30 grass_block
fill ~103 ~60 ~30 ~104 ~67 ~30 stone
fill ~103 ~68 ~30 ~104 ~70 ~30 dirt
fill ~103 ~71 ~30 ~104 ~71 ~30 grass_block
fill ~105 ~60 ~30 ~110 ~68 ~30 stone
fill ~105 ~69 ~30 ~110 ~71 ~30 dirt
fill ~105 ~72 ~30 ~110 ~72 ~30 grass_block
fill ~111 ~60 ~30 ~111 ~67 ~30 stone
fill ~111 ~68 ~30 ~111 ~70 ~30 dirt
fill ~111 ~71 ~30 ~111 ~71 ~30 grass_block
fill ~96 ~60 ~31 ~96 ~67 ~31 stone
fill ~96 ~68 ~31 ~96 ~70 ~31 dirt
fill ~96 ~71 ~31 ~96 ~71 ~31 grass_block
fill ~97 ~60 ~31 ~98 ~66 ~31 stone
fill ~97 ~67 ~31 ~98 ~69 ~31 dirt
fill ~97 ~70 ~31 ~98 ~70 ~31 grass_block
fill ~99 ~60 ~31 ~101 ~65 ~31 stone
fill ~99 ~66 ~31 ~101 ~68 ~31 dirt
fill ~99 ~69 ~31 ~101 ~69 ~31 grass_block
fill ~102 ~60 ~31 ~103 ~66 ~31 stone
fill ~102 ~67 ~31 ~103 ~69 ~31 dirt
fill ~102 ~70 ~31 ~103 ~70 ~31 grass_block
fill ~104 ~60 ~31 ~106 ~67 ~31 stone
fill ~104 ~68 ~31 ~106 ~70 ~31 dirt
fill ~104 ~71 ~31 ~106 ~71 ~31 grass_block
fill ~107 ~60 ~31 ~110 ~68 ~31 stone
fill ~107 ~69 ~31 ~110 ~71 ~31 dirt
fill ~107 ~72 ~31 ~110 ~72 ~31 grass_block
fill ~111 ~60 ~31 ~111 ~67 ~31 stone
fill ~111 ~68 ~31 ~111 ~70 ~31 dirt
fill ~111 ~71 ~31 ~111 ~71 ~31 grass_block