fill ~224 ~60 ~80 ~239 ~66 ~80 stone
fill ~224 ~67 ~80 ~239 ~69 ~80 dirt
fill ~224 ~70 ~80 ~239 ~70 ~80 grass_block
fill ~224 ~60 ~81 ~225 ~67 ~81 stone
fill ~224 ~68 ~81 ~225 ~70 ~81 dirt
fill ~224 ~71 ~81 ~225 ~71 ~81 grass_block
fill ~226 ~60 ~81 ~239 ~66 ~81 stone
fill ~226 ~67 ~81 ~239 ~69 ~81 dirt
fill ~226 ~70 ~81 ~239 ~70 ~81 grass_block
fill ~224 ~60 ~82 ~226 ~67 ~82 stone
fill ~224 ~68 ~82 ~226 ~70 ~82 dirt
fill ~224 ~71 ~82 ~226 ~71 ~82 grass_block
fill ~227 ~60 ~82 ~239 ~66 ~82 stone
fill ~227 ~67 ~82 ~239 ~69 ~82 dirt
fill ~227 ~70 ~82 ~239 ~70 ~82 grass_block
fill ~224 ~60 ~83 ~227 ~67 ~83 stone
fill ~224 ~68 ~83 ~227 ~70 ~83 dirt
fill ~224 ~71 ~83 ~227 ~71 ~83 grass_block
fill ~228 ~60 ~83 ~233 ~66 ~83 stone
fill ~228 ~67 ~83 ~233 ~69 ~83 dirt
fill ~228 ~70 ~83 ~233 ~70 ~83 grass_block
fill ~234 ~60 ~83 ~236 ~65 ~83 stone
fill ~234 ~66 ~83 ~236 ~68 ~83 dirt
fill ~234 ~69 ~83 ~236 ~69 ~83 grass_block
fill ~237 ~60 ~83 ~239 ~66 ~83 stone
fill ~237 ~67 ~83 ~239 ~69 ~83 dirt
fill ~237 ~70 ~83 ~239 ~70 ~83 grass_block
fill ~224 ~60 ~84 ~228 ~67 ~84 stone
fill ~224 ~68 ~84 ~228 ~70 ~84 dirt
fill ~224 ~71 ~84 ~228 ~71 ~84 grass_block
fill ~229 ~60 ~84 ~233 ~66 ~84 stone
fill ~229 ~67 ~84 ~233 ~69 ~84 dirt
fill ~229 ~70 ~84 ~233 ~70 ~84 grass_block
fill ~234 ~60 ~84 ~238 ~65 ~84 stone
fill ~234 ~66 ~84 ~238 ~68 ~84 dirt
fill ~234 ~69 ~84 ~238 ~69 ~84 grass_block
fill ~239 ~60 ~84 ~239 ~66 ~84 stone
fill ~239 ~67 ~84 ~239 ~69 ~84 dirt
fill ~239 ~70 ~84 ~239 ~70 ~84 grass_block
fill ~224 ~60 ~85 ~229 ~67 ~85 stone
fill ~224 ~68 ~85 ~229 ~70 ~85 dirt
fill ~224 ~71 ~85 ~229 ~71 ~85 grass_block
fill ~230 ~60 ~85 ~233 ~66 ~85 stone
fill ~230 ~67 ~85 ~233 ~69 ~85 dirt
fill ~230 ~70 ~85 ~233 ~70 ~85 grass_block
fill ~234 ~60 ~85 ~235 ~65 ~85 stone
fill ~234 ~66 ~85 ~235 ~68 ~85 dirt
fill ~234 ~69 ~85 ~235 ~69 ~85 grass_block
fill ~236 ~60 ~85 ~237 ~64 ~85 stone
fill ~236 ~65 ~85 ~237 ~67 ~85 dirt
fill ~236 ~68 ~85 ~237 ~68 ~85 grass_block
fill ~238 ~60 ~85 ~239 ~65 ~85 stone
fill ~238 ~66 ~85 ~239 ~68 ~85 dirt
fill ~238 ~69 ~85 ~239 ~69 ~85 grass_block
fill ~224 ~60 ~86 ~229 ~67 ~86 stone
fill ~224 ~68 ~86 ~229 ~70 ~86 dirt
fill ~224 ~71 ~86 ~229 ~71 ~86 grass_block
fill ~230 ~60 ~86 ~233 ~66 ~86 stone
fill ~230 ~67 ~86 ~233 ~69 ~86 dirt
fill ~230 ~70 ~86 ~233 ~70 ~86 grass_block
fill ~234 ~60 ~86 ~235 ~65 ~86 stone
fill ~234 ~66 ~86 ~235 ~68 ~86 dirt
fill ~234 ~69 ~86 ~235 ~69 ~86 grass_block
fill ~236 ~60 ~86 ~238 ~64 ~86 stone
fill ~236 ~65 ~86 ~238 ~67 ~86 dirt
fill ~236 ~68 ~86 ~238 ~68 ~86 grass_block
fill ~239 ~60 ~86 ~239 ~65 ~86 stone
fill ~239 ~66 ~86 ~239 ~68 ~86 dirt
fill ~239 ~69 ~86 ~239 ~69 ~86 grass_block
fill ~224 ~60 ~87 ~224 ~66 ~87 stone
fill ~224 ~67 ~87 ~224 ~69 ~87 dirt
fill ~224 ~70 ~87 ~224 ~70 ~87 grass_block
fill ~225 ~60 ~87 ~228 ~67 ~87 stone
fill ~225 ~68 ~87 ~228 ~70 ~87 dirt
fill ~225 ~71 ~87 ~228 ~71 ~87 grass_block
fill ~229 ~60 ~87 ~230 ~66 ~87 stone
fill ~229 ~67 ~87 ~230 ~69 ~87 dirt
fill ~229 ~70 ~87 ~230 ~70 ~87 grass_block
fill ~231 ~60 ~87 ~231 ~67 ~87 stone
fill ~231 ~68 ~87 ~231 ~70 ~87 dirt
fill ~231 ~71 ~87 ~231 ~71 ~87 grass_block
fill ~232 ~60 ~87 ~234 ~66 ~87 stone
fill ~232 ~67 ~87 ~234 ~69 ~87 dirt
fill ~232 ~70 ~87 ~234 ~70 ~87 grass_block
fill ~235 ~60 ~87 ~236 ~65 ~87 stone
fill ~235 ~66 ~87 ~236 ~68 ~87 dirt
fill ~235 ~69 ~87 ~236 ~69 ~87 grass_block
fill ~237 ~60 ~87 ~239 ~64 ~87 stone
fill ~237 ~65 ~87 ~239 ~67 ~87 dirt
fill ~237 ~68 ~87 ~239 ~68 ~87 grass_block
fill ~224 ~60 ~88 ~228 ~66 ~88 stone
fill ~224 ~67 ~88 ~228 ~69 ~88 dirt
fill ~224 ~70 ~88 ~228 ~70 ~88 grass_block
fill ~229 ~60 ~88 ~231 ~67 ~88 stone
fill ~229 ~68 ~88 ~231 ~70 ~88 dirt
fill ~229 ~71 ~88 ~231 ~71 ~88 grass_block
fill ~232 ~60 ~88 ~234 ~66 ~88 stone
fill ~232 ~67 ~88 ~234 ~69 ~88 dirt
fill ~232 ~70 ~88 ~234 ~70 ~88 grass_block
fill ~235 ~60 ~88 ~237 ~65 ~88 stone
fill ~235 ~66 ~88 ~237 ~68 ~88 dirt
fill ~235 ~69 ~88 ~237 ~69 ~88 grass_block
fill ~238 ~60 ~88 ~239 ~64 ~88 stone
fill ~238 ~65 ~88 ~239 ~67 ~88 dirt
fill ~238 ~68 ~88 ~239 ~68 ~88 grass_block
fill ~224 ~60 ~89 ~235 ~66 ~89 stone
fill ~224 ~67 ~89 ~235 ~69 ~89 dirt
fill ~224 ~70 ~89 ~235 ~70 ~89 grass_block
fill ~236 ~60 ~89 ~238 ~65 ~89 stone
fill ~236 ~66 ~89 ~238 ~68 ~89 dirt
fill ~236 ~69 ~89 ~238 ~69 ~89 grass_block
fill ~239 ~60 ~89 ~239 ~64 ~89 stone
fill ~239 ~65 ~89 ~239 ~67 ~89 dirt
fill ~239 ~68 ~89 ~239 ~68 ~89 grass_block
fill ~224 ~60 ~90 ~226 ~65 ~90 stone
fill ~224 ~66 ~90 ~226 ~68 ~90 dirt
fill ~224 ~69 ~90 ~226 ~69 ~90 grass_block
fill ~227 ~60 ~90 ~230 ~66 ~90 stone
fill ~227 ~67 ~90 ~230 ~69 ~90 dirt
fill ~227 ~70 ~90 ~230 ~70 ~90 grass_block
fill ~231 ~60 ~90 ~231 ~67 ~90 stone
fill ~231 ~68 ~90 ~231 ~70 ~90 dirt
fill ~231 ~71 ~90 ~231 ~71 ~90 grass_block
fill ~232 ~60 ~90 ~236 ~66 ~90 stone
fill ~232 ~67 ~90 ~236 ~69 ~90 dirt
fill ~232 ~70 ~90 ~236 ~70 ~90 grass_block
fill ~237 ~60 ~90 ~238 ~65 ~90 stone
fill ~237 ~66 ~90 ~238 ~68 ~90 dirt
fill ~237 ~69 ~90 ~238 ~69 ~90 grass_block
fill ~239 ~60 ~90 ~239 ~64 ~90 stone
fill ~239 ~65 ~90 ~239 ~67 ~90 dirt
fill ~239 ~68 ~90 ~239 ~68 ~90 grass_block
fill ~224 ~60 ~91 ~225 ~65 ~91 stone
fill ~224 ~66 ~91 ~225 ~68 ~91 dirt
fill ~224 ~69 ~91 ~225 ~69 ~91 grass_block
fill ~226 ~60 ~91 ~236 ~66 ~91 stone
fill ~226 ~67 ~91 ~236 ~69 ~91 dirt
fill ~226 ~70 ~91 ~236 ~70 ~91 grass_block
fill ~237 ~60 ~91 ~239 ~65 ~91 stone
fill ~237 ~66 ~91 ~239 ~68 ~91 dirt
fill ~237 ~69 ~91 ~239 ~69 ~91 grass_block
fill ~224 ~60 ~92 ~224 ~65 ~92 stone
fill ~224 ~66 ~92 ~224 ~68 ~92 dirt
fill ~224 ~69 ~92 ~224 ~69 ~92 grass_block
fill ~225 ~60 ~92 ~236 ~66 ~92 stone
fill ~225 ~67 ~92 ~236 ~69 ~92 dirt
fill ~225 ~70 ~92 ~236 ~70 ~92 grass_block
fill ~237 ~60 ~92 ~239 ~65 ~92 stone
fill ~237 ~66 ~92 ~239 ~68 ~92 dirt
fill ~237 ~69 ~92 ~239 ~69 ~92 grass_block
fill ~224 ~60 ~93 ~224 ~65 ~93 stone
fill ~224 ~66 ~93 ~224 ~68 ~93 dirt
fill ~224 ~69 ~93 ~224 ~69 ~93 grass_block
fill ~225 ~60 ~93 ~237 ~66 ~93 stone
fill ~225 ~67 ~93 ~237 ~69 ~93 dirt
fill ~225 ~70 ~93 ~237 ~70 ~93 grass_block
fill ~238 ~60 ~93 ~239 ~65 ~93 stone
fill ~238 ~66 ~93 ~239 ~68 ~93 dirt
fill ~238 ~69 ~93 ~239 ~69 ~93 grass_block
fill ~224 ~60 ~94 ~226 ~65 ~94 stone
fill ~224 ~66 ~94 ~226 ~68 ~94 dirt
fill ~224 ~69 ~94 ~226 ~69 ~94 grass_block
fill ~227 ~60 ~94 ~237 ~66 ~94 stone
fill ~227 ~67 ~94 ~237 ~69 ~94 dirt
fill ~227 ~70 ~94 ~237 ~70 ~94 grass_block
fill ~238 ~60 ~94 ~239 ~65 ~94 stone
fill ~238 ~66 ~94 ~239 ~68 ~94 dirt
fill ~238 ~69 ~94 ~239 ~69 ~94 grass_block
fill ~224 ~60 ~95 ~227 ~65 ~95 stone
fill ~224 ~66 ~95 ~227 ~68 ~95 dirt
fill ~224 ~69 ~95 ~227 ~69 ~95 grass_block
fill ~228 ~60 ~95 ~228 ~66 ~95 stone
fill ~228 ~67 ~95 ~228 ~69 ~95 dirt
fill ~228 ~70 ~95 ~228 ~70 ~95 grass_block
fill ~229 ~60 ~95 ~229 ~65 ~95 stone
fill ~229 ~66 ~95 ~229 ~68 ~95 dirt
fill ~229 ~69 ~95 ~229 ~69 ~95 grass_block
fill ~230 ~60 ~95 ~230 ~66 ~95 stone
fill ~230 ~67 ~95 ~230 ~69 ~95 dirt
fill ~230 ~70 ~95 ~230 ~70 ~95 grass_block
fill ~231 ~60 ~95 ~235 ~65 ~95 stone
fill ~231 ~66 ~95 ~235 ~68 ~95 dirt
fill ~231 ~69 ~95 ~235 ~69 ~95 grass_block
fill ~236 ~60 ~95 ~238 ~66 ~95 stone
fill ~236 ~67 ~95 ~238 ~69 ~95 dirt
fill ~236 ~70 ~95 ~238 ~70 ~95 grass_block
fill ~239 ~60 ~95 ~239 ~65 ~95 stone
fill ~239 ~66 ~95 ~239 ~68 ~95 dirt
fill ~239 ~69 ~95 ~239 ~69 ~95 grass_block