fill ~400 ~60 ~32 ~400 ~62 ~32 stone
fill ~400 ~63 ~32 ~400 ~65 ~32 dirt
fill ~400 ~66 ~32 ~400 ~66 ~32 grass_block
fill ~401 ~60 ~32 ~403 ~63 ~32 stone
fill ~401 ~64 ~32 ~403 ~66 ~32 dirt
fill ~401 ~67 ~32 ~403 ~67 ~32 grass_block
fill ~404 ~60 ~32 ~412 ~64 ~32 stone
fill ~404 ~65 ~32 ~412 ~67 ~32 dirt
fill ~404 ~68 ~32 ~412 ~68 ~32 grass_block
fill ~413 ~60 ~32 ~415 ~63 ~32 stone
fill ~413 ~64 ~32 ~415 ~66 ~32 dirt
fill ~413 ~67 ~32 ~415 ~67 ~32 grass_block
fill ~400 ~60 ~33 ~401 ~63 ~33 stone
fill ~400 ~64 ~33 ~401 ~66 ~33 dirt
fill ~400 ~67 ~33 ~401 ~67 ~33 grass_block
fill ~402 ~60 ~33 ~412 ~64 ~33 stone
fill ~402 ~65 ~33 ~412 ~67 ~33 dirt
fill ~402 ~68 ~33 ~412 ~68 ~33 grass_block
fill ~413 ~60 ~33 ~415 ~63 ~33 stone
fill ~413 ~64 ~33 ~415 ~66 ~33 dirt
fill ~413 ~67 ~33 ~415 ~67 ~33 grass_block
fill ~400 ~60 ~34 ~400 ~63 ~34 stone
fill ~400 ~64 ~34 ~400 ~66 ~34 dirt
fill ~400 ~67 ~34 ~400 ~67 ~34 grass_block
fill ~401 ~60 ~34 ~401 ~64 ~34 stone
fill ~401 ~65 ~34 ~401 ~67 ~34 dirt
fill ~401 ~68 ~34 ~401 ~68 ~34 grass_block
fill ~402 ~60 ~34 ~407 ~65 ~34 stone
fill ~402 ~66 ~34 ~407 ~68 ~34 dirt
fill ~402 ~69 ~34 ~407 ~69 ~34 grass_block
fill ~408 ~60 ~34 ~413 ~64 ~34 stone
fill ~408 ~65 ~34 ~413 ~67 ~34 dirt
fill ~408 ~68 ~34 ~413 ~68 ~34 grass_block
fill ~414 ~60 ~34 ~415 ~63 ~34 stone
fill ~414 ~64 ~34 ~415 ~66 ~34 dirt
fill ~414 ~67 ~34 ~415 ~67 ~34 grass_block
fill ~400 ~60 ~35 ~400 ~63 ~35 stone
fill ~400 ~64 ~35 ~400 ~66 ~35 dirt
fill ~400 ~67 ~35 ~400 ~67 ~35 grass_block
fill ~401 ~60 ~35 ~401 ~64 ~35 stone
fill ~401 ~65 ~35 ~401 ~67 ~35 dirt
fill ~401 ~68 ~35 ~401 ~68 ~35 grass_block
fill ~402 ~60 ~35 ~407 ~65 ~35 stone
fill ~402 ~66 ~35 ~407 ~68 ~35 dirt
fill ~402 ~69 ~35 ~407 ~69 ~35 grass_block
fill ~408 ~60 ~35 ~413 ~64 ~35 stone
fill ~408 ~65 ~35 ~413 ~67 ~35 dirt
fill ~408 ~68 ~35 ~413 ~68 ~35 grass_block
fill ~414 ~60 ~35 ~415 ~63 ~35 stone
fill ~414 ~64 ~35 ~415 ~66 ~35 dirt
fill ~414 ~67 ~35 ~415 ~67 ~35 grass_block
fill ~400 ~60 ~36 ~400 ~63 ~36 stone
fill ~400 ~64 ~36 ~400 ~66 ~36 dirt
fill ~400 ~67 ~36 ~400 ~67 ~36 grass_block
fill ~401 ~60 ~36 ~402 ~64 ~36 stone
fill ~401 ~65 ~36 ~402 ~67 ~36 dirt
fill ~401 ~68 ~36 ~402 ~68 ~36 grass_block
fill ~403 ~60 ~36 ~406 ~65 ~36 stone
fill ~403 ~66 ~36 ~406 ~68 ~36 dirt
fill ~403 ~69 ~36 ~406 ~69 ~36 grass_block
fill ~407 ~60 ~36 ~412 ~64 ~36 stone
fill ~407 ~65 ~36 ~412 ~67 ~36 dirt
fill ~407 ~68 ~36 ~412 ~68 ~36 grass_block
fill ~413 ~60 ~36 ~415 ~63 ~36 stone
fill ~413 ~64 ~36 ~415 ~66 ~36 dirt
fill ~413 ~67 ~36 ~415 ~67 ~36 grass_block
fill ~400 ~60 ~37 ~401 ~64 ~37 stone
fill ~400 ~65 ~37 ~401 ~67 ~37 dirt
fill ~400 ~68 ~37 ~401 ~68 ~37 grass_block
fill ~402 ~60 ~37 ~405 ~65 ~37 stone
fill ~402 ~66 ~37 ~405 ~68 ~37 dirt
fill ~402 ~69 ~37 ~405 ~69 ~37 grass_block
fill ~406 ~60 ~37 ~409 ~64 ~37 stone
fill ~406 ~65 ~37 ~409 ~67 ~37 dirt
fill ~406 ~68 ~37 ~409 ~68 ~37 grass_block
fill ~410 ~60 ~37 ~414 ~63 ~37 stone
fill ~410 ~64 ~37 ~414 ~66 ~37 dirt
fill ~410 ~67 ~37 ~414 ~67 ~37 grass_block
fill ~415 ~60 ~37 ~415 ~62 ~37 stone
fill ~415 ~63 ~37 ~415 ~65 ~37 dirt
fill ~415 ~66 ~37 ~415 ~66 ~37 grass_block
fill ~400 ~60 ~38 ~400 ~64 ~38 stone
fill ~400 ~65 ~38 ~400 ~67 ~38 dirt
fill ~400 ~68 ~38 ~400 ~68 ~38 grass_block
fill ~401 ~60 ~38 ~404 ~65 ~38 stone
fill ~401 ~66 ~38 ~404 ~68 ~38 dirt
fill ~401 ~69 ~38 ~404 ~69 ~38 grass_block
fill ~405 ~60 ~38 ~407 ~64 ~38 stone
fill ~405 ~65 ~38 ~407 ~67 ~38 dirt
fill ~405 ~68 ~38 ~407 ~68 ~38 grass_block
fill ~408 ~60 ~38 ~412 ~63 ~38 stone
fill ~408 ~64 ~38 ~412 ~66 ~38 dirt
fill ~408 ~67 ~38 ~412 ~67 ~38 grass_block
fill ~413 ~60 ~38 ~415 ~62 ~38 stone
fill ~413 ~63 ~38 ~415 ~65 ~38 dirt
fill ~413 ~66 ~38 ~415 ~66 ~38 grass_block
fill ~400 ~60 ~39 ~400 ~64 ~39 stone
fill ~400 ~65 ~39 ~400 ~67 ~39 dirt
fill ~400 ~68 ~39 ~400 ~68 ~39 grass_block
fill ~401 ~60 ~39 ~404 ~65 ~39 stone
fill ~401 ~66 ~39 ~404 ~68 ~39 dirt
fill ~401 ~69 ~39 ~404 ~69 ~39 grass_block
fill ~405 ~60 ~39 ~406 ~64 ~39 stone
fill ~405 ~65 ~39 ~406 ~67 ~39 dirt
fill ~405 ~68 ~39 ~406 ~68 ~39 grass_block
fill ~407 ~60 ~39 ~412 ~63 ~39 stone
fill ~407 ~64 ~39 ~412 ~66 ~39 dirt
fill ~407 ~67 ~39 ~412 ~67 ~39 grass_block
fill ~413 ~60 ~39 ~415 ~62 ~39 stone
fill ~413 ~63 ~39 ~415 ~65 ~39 dirt
fill ~413 ~66 ~39 ~415 ~66 ~39 grass_block
fill ~400 ~60 ~40 ~401 ~64 ~40 stone
fill ~400 ~65 ~40 ~401 ~67 ~40 dirt
fill ~400 ~68 ~40 ~401 ~68 ~40 grass_block
fill ~402 ~60 ~40 ~405 ~65 ~40 stone
fill ~402 ~66 ~40 ~405 ~68 ~40 dirt
fill ~402 ~69 ~40 ~405 ~69 ~40 grass_block
fill ~406 ~60 ~40 ~410 ~64 ~40 stone
fill ~406 ~65 ~40 ~410 ~67 ~40 dirt
fill ~406 ~68 ~40 ~410 ~68 ~40 grass_block
fill ~411 ~60 ~40 ~413 ~63 ~40 stone
fill ~411 ~64 ~40 ~413 ~66 ~40 dirt
fill ~411 ~67 ~40 ~413 ~67 ~40 grass_block
fill ~414 ~60 ~40 ~415 ~62 ~40 stone
fill ~414 ~63 ~40 ~415 ~65 ~40 dirt
fill ~414 ~66 ~40 ~415 ~66 ~40 grass_block
fill ~400 ~60 ~41 ~405 ~65 ~41 stone
fill ~400 ~66 ~41 ~405 ~68 ~41 dirt
fill ~400 ~69 ~41 ~405 ~69 ~41 grass_block
fill ~406 ~60 ~41 ~406 ~64 ~41 stone
fill ~406 ~65 ~41 ~406 ~67 ~41 dirt
fill ~406 ~68 ~41 ~406 ~68 ~41 grass_block
fill ~407 ~60 ~41 ~408 ~65 ~41 stone
fill ~407 ~66 ~41 ~408 ~68 ~41 dirt
fill ~407 ~69 ~41 ~408 ~69 ~41 grass_block
fill ~409 ~60 ~41 ~411 ~64 ~41 stone
fill ~409 ~65 ~41 ~411 ~67 ~41 dirt
fill ~409 ~68 ~41 ~411 ~68 ~41 grass_block
fill ~412 ~60 ~41 ~414 ~63 ~41 stone
fill ~412 ~64 ~41 ~414 ~66 ~41 dirt
fill ~412 ~67 ~41 ~414 ~67 ~41 grass_block
fill ~415 ~60 ~41 ~415 ~62 ~41 stone
fill ~415 ~63 ~41 ~415 ~65 ~41 dirt
fill ~415 ~66 ~41 ~415 ~66 ~41 grass_block
fill ~400 ~60 ~42 ~409 ~65 ~42 stone
fill ~400 ~66 ~42 ~409 ~68 ~42 dirt
fill ~400 ~69 ~42 ~409 ~69 ~42 grass_block
fill ~410 ~60 ~42 ~412 ~64 ~42 stone
fill ~410 ~65 ~42 ~412 ~67 ~42 dirt
fill ~410 ~68 ~42 ~412 ~68 ~42 grass_block
fill ~413 ~60 ~42 ~415 ~63 ~42 stone
fill ~413 ~64 ~42 ~415 ~66 ~42 dirt
fill ~413 ~67 ~42 ~415 ~67 ~42 grass_block
fill ~400 ~60 ~43 ~410 ~65 ~43 stone
fill ~400 ~66 ~43 ~410 ~68 ~43 dirt
fill ~400 ~69 ~43 ~410 ~69 ~43 grass_block
fill ~411 ~60 ~43 ~412 ~64 ~43 stone
fill ~411 ~65 ~43 ~412 ~67 ~43 dirt
fill ~411 ~68 ~43 ~412 ~68 ~43 grass_block
fill ~413 ~60 ~43 ~414 ~63 ~43 stone
fill ~413 ~64 ~43 ~414 ~66 ~43 dirt
fill ~413 ~67 ~43 ~414 ~67 ~43 grass_block
fill ~415 ~60 ~43 ~415 ~62 ~43 stone
fill ~415 ~63 ~43 ~415 ~65 ~43 dirt
fill ~415 ~66 ~43 ~415 ~66 ~43 grass_block
fill ~400 ~60 ~44 ~400 ~66 ~44 stone
fill ~400 ~67 ~44 ~400 ~69 ~44 dirt
fill ~400 ~70 ~44 ~400 ~70 ~44 grass_block
fill ~401 ~60 ~44 ~411 ~65 ~44 stone
fill ~401 ~66 ~44 ~411 ~68 ~44 dirt
fill ~401 ~69 ~44 ~411 ~69 ~44 grass_block
fill ~412 ~60 ~44 ~412 ~64 ~44 stone
fill ~412 ~65 ~44 ~412 ~67 ~44 dirt
fill ~412 ~68 ~44 ~412 ~68 ~44 grass_block
fill ~413 ~60 ~44 ~415 ~63 ~44 stone
fill ~413 ~64 ~44 ~415 ~66 ~44 dirt
fill ~413 ~67 ~44 ~415 ~67 ~44 grass_block
fill ~400 ~60 ~45 ~400 ~66 ~45 stone
fill ~400 ~67 ~45 ~400 ~69 ~45 dirt
fill ~400 ~70 ~45 ~400 ~70 ~45 grass_block
fill ~401 ~60 ~45 ~409 ~65 ~45 stone
fill ~401 ~66 ~45 ~409 ~68 ~45 dirt
fill ~401 ~69 ~45 ~409 ~69 ~45 grass_block
fill ~410 ~60 ~45 ~413 ~64 ~45 stone
fill ~410 ~65 ~45 ~413 ~67 ~45 dirt
fill ~410 ~68 ~45 ~413 ~68 ~45 grass_block
fill ~414 ~60 ~45 ~415 ~63 ~45 stone
fill ~414 ~64 ~45 ~415 ~66 ~45 dirt
fill ~414 ~67 ~45 ~415 ~67 ~45 grass_block
fill ~400 ~60 ~46 ~400 ~66 ~46 stone
fill ~400 ~67 ~46 ~400 ~69 ~46 dirt
fill ~400 ~70 ~46 ~400 ~70 ~46 grass_block
fill ~401 ~60 ~46 ~408 ~65 ~46 stone
fill ~401 ~66 ~46 ~408 ~68 ~46 dirt
fill ~401 ~69 ~46 ~408 ~69 ~46 grass_block
fill ~409 ~60 ~46 ~412 ~64 ~46 stone
fill ~409 ~65 ~46 ~412 ~67 ~46 dirt
fill ~409 ~68 ~46 ~412 ~68 ~46 grass_block
fill ~413 ~60 ~46 ~415 ~63 ~46 stone
fill ~413 ~64 ~46 ~415 ~66 ~46 dirt
fill ~413 ~67 ~46 ~415 ~67 ~46 grass_block
fill ~400 ~60 ~47 ~400 ~66 ~47 stone
fill ~400 ~67 ~47 ~400 ~69 ~47 dirt
fill ~400 ~70 ~47 ~400 ~70 ~47 grass_block
fill ~401 ~60 ~47 ~403 ~65 ~47 stone
fill ~401 ~66 ~47 ~403 ~68 ~47 dirt
fill ~401 ~69 ~47 ~403 ~69 ~47 grass_block
fill ~404 ~60 ~47 ~406 ~64 ~47 stone
fill ~404 ~65 ~47 ~406 ~67 ~47 dirt
fill ~404 ~68 ~47 ~406 ~68 ~47 grass_block
fill ~407 ~60 ~47 ~409 ~65 ~47 stone
fill ~407 ~66 ~47 ~409 ~68 ~47 dirt
fill ~407 ~69 ~47 ~409 ~69 ~47 grass_block
fill ~410 ~60 ~47 ~411 ~64 ~47 stone
fill ~410 ~65 ~47 ~411 ~67 ~47 dirt
fill ~410 ~68 ~47 ~411 ~68 ~47 grass_block
fill ~412 ~60 ~47 ~415 ~63 ~47 stone
fill ~412 ~64 ~47 ~415 ~66 ~47 dirt
fill ~412 ~67 ~47 ~415 ~67 ~47 grass_block