fill ~448 ~60 ~112 ~463 ~61 ~112 stone
fill ~448 ~62 ~112 ~463 ~64 ~112 dirt
fill ~448 ~65 ~112 ~463 ~65 ~112 grass_block
fill ~448 ~60 ~113 ~448 ~62 ~113 stone
fill ~448 ~63 ~113 ~448 ~65 ~113 dirt
fill ~448 ~66 ~113 ~448 ~66 ~113 grass_block
fill ~449 ~60 ~113 ~463 ~61 ~113 stone
fill ~449 ~62 ~113 ~463 ~64 ~113 dirt
fill ~449 ~65 ~113 ~463 ~65 ~113 grass_block
fill ~448 ~60 ~114 ~449 ~62 ~114 stone
fill ~448 ~63 ~114 ~449 ~65 ~114 dirt
fill ~448 ~66 ~114 ~449 ~66 ~114 grass_block
fill ~450 ~60 ~114 ~452 ~61 ~114 stone
fill ~450 ~62 ~114 ~452 ~64 ~114 dirt
fill ~450 ~65 ~114 ~452 ~65 ~114 grass_block
fill ~453 ~60 ~114 ~453 ~62 ~114 stone
fill ~453 ~63 ~114 ~453 ~65 ~114 dirt
fill ~453 ~66 ~114 ~453 ~66 ~114 grass_block
fill ~454 ~60 ~114 ~463 ~61 ~114 stone
fill ~454 ~62 ~114 ~463 ~64 ~114 dirt
fill ~454 ~65 ~114 ~463 ~65 ~114 grass_block
fill ~448 ~60 ~115 ~448 ~62 ~115 stone
fill ~448 ~63 ~115 ~448 ~65 ~115 dirt
fill ~448 ~66 ~115 ~448 ~66 ~115 grass_block
fill ~449 ~60 ~115 ~452 ~61 ~115 stone
fill ~449 ~62 ~115 ~452 ~64 ~115 dirt
fill ~449 ~65 ~115 ~452 ~65 ~115 grass_block
fill ~453 ~60 ~115 ~458 ~62 ~115 stone
fill ~453 ~63 ~115 ~458 ~65 ~115 dirt
fill ~453 ~66 ~115 ~458 ~66 ~115 grass_block
fill ~459 ~60 ~115 ~463 ~61 ~115 stone
fill ~459 ~62 ~115 ~463 ~64 ~115 dirt
fill ~459 ~65 ~115 ~463 ~65 ~115 grass_block
fill ~448 ~60 ~116 ~448 ~62 ~116 stone
fill ~448 ~63 ~116 ~448 ~65 ~116 dirt
fill ~448 ~66 ~116 ~448 ~66 ~116 grass_block
fill ~449 ~60 ~116 ~451 ~61 ~116 stone
fill ~449 ~62 ~116 ~451 ~64 ~116 dirt
fill ~449 ~65 ~116 ~451 ~65 ~116 grass_block
fill ~452 ~60 ~116 ~454 ~62 ~116 stone
fill ~452 ~63 ~116 ~454 ~65 ~116 dirt
fill ~452 ~66 ~116 ~454 ~66 ~116 grass_block
fill ~455 ~60 ~116 ~457 ~63 ~116 stone
fill ~455 ~64 ~116 ~457 ~66 ~116 dirt
fill ~455 ~67 ~116 ~457 ~67 ~116 grass_block
fill ~458 ~60 ~116 ~461 ~62 ~116 stone
fill ~458 ~63 ~116 ~461 ~65 ~116 dirt
fill ~458 ~66 ~116 ~461 ~66 ~116 grass_block
fill ~462 ~60 ~116 ~463 ~61 ~116 stone
fill ~462 ~62 ~116 ~463 ~64 ~116 dirt
fill ~462 ~65 ~116 ~463 ~65 ~116 grass_block
fill ~448 ~60 ~117 ~452 ~61 ~117 stone
fill ~448 ~62 ~117 ~452 ~64 ~117 dirt
fill ~448 ~65 ~117 ~452 ~65 ~117 grass_block
fill ~453 ~60 ~117 ~454 ~62 ~117 stone
fill ~453 ~63 ~117 ~454 ~65 ~117 dirt
fill ~453 ~66 ~117 ~454 ~66 ~117 grass_block
fill ~455 ~60 ~117 ~458 ~63 ~117 stone
fill ~455 ~64 ~117 ~458 ~66 ~117 dirt
fill ~455 ~67 ~117 ~458 ~67 ~117 grass_block
fill ~459 ~60 ~117 ~462 ~62 ~117 stone
fill ~459 ~63 ~117 ~462 ~65 ~117 dirt
fill ~459 ~66 ~117 ~462 ~66 ~117 grass_block
fill ~463 ~60 ~117 ~463 ~61 ~117 stone
fill ~463 ~62 ~117 ~463 ~64 ~117 dirt
fill ~463 ~65 ~117 ~463 ~65 ~117 grass_block
fill ~448 ~60 ~118 ~454 ~62 ~118 stone
fill ~448 ~63 ~118 ~454 ~65 ~118 dirt
fill ~448 ~66 ~118 ~454 ~66 ~118 grass_block
fill ~455 ~60 ~118 ~459 ~63 ~118 stone
fill ~455 ~64 ~118 ~459 ~66 ~118 dirt
fill ~455 ~67 ~118 ~459 ~67 ~118 grass_block
fill ~460 ~60 ~118 ~463 ~62 ~118 stone
fill ~460 ~63 ~118 ~463 ~65 ~118 dirt
fill ~460 ~66 ~118 ~463 ~66 ~118 grass_block
fill ~448 ~60 ~119 ~448 ~62 ~119 stone
fill ~448 ~63 ~119 ~448 ~65 ~119 dirt
fill ~448 ~66 ~119 ~448 ~66 ~119 grass_block
fill ~449 ~60 ~119 ~451 ~63 ~119 stone
fill ~449 ~64 ~119 ~451 ~66 ~119 dirt
fill ~449 ~67 ~119 ~451 ~67 ~119 grass_block
fill ~452 ~60 ~119 ~454 ~62 ~119 stone
fill ~452 ~63 ~119 ~454 ~65 ~119 dirt
fill ~452 ~66 ~119 ~454 ~66 ~119 grass_block
fill ~455 ~60 ~119 ~460 ~63 ~119 stone
fill ~455 ~64 ~119 ~460 ~66 ~119 dirt
fill ~455 ~67 ~119 ~460 ~67 ~119 grass_block
fill ~461 ~60 ~119 ~463 ~62 ~119 stone
fill ~461 ~63 ~119 ~463 ~65 ~119 dirt
fill ~461 ~66 ~119 ~463 ~66 ~119 grass_block
fill ~448 ~60 ~120 ~456 ~63 ~120 stone
fill ~448 ~64 ~120 ~456 ~66 ~120 dirt
fill ~448 ~67 ~120 ~456 ~67 ~120 grass_block
fill ~457 ~60 ~120 ~458 ~64 ~120 stone
fill ~457 ~65 ~120 ~458 ~67 ~120 dirt
fill ~457 ~68 ~120 ~458 ~68 ~120 grass_block
fill ~459 ~60 ~120 ~462 ~63 ~120 stone
fill ~459 ~64 ~120 ~462 ~66 ~120 dirt
fill ~459 ~67 ~120 ~462 ~67 ~120 grass_block
fill ~463 ~60 ~120 ~463 ~62 ~120 stone
fill ~463 ~63 ~120 ~463 ~65 ~120 dirt
fill ~463 ~66 ~120 ~463 ~66 ~120 grass_block
fill ~448 ~60 ~121 ~448 ~63 ~121 stone
fill ~448 ~64 ~121 ~448 ~66 ~121 dirt
fill ~448 ~67 ~121 ~448 ~67 ~121 grass_block
fill ~449 ~60 ~121 ~453 ~64 ~121 stone
fill ~449 ~65 ~121 ~453 ~67 ~121 dirt
fill ~449 ~68 ~121 ~453 ~68 ~121 grass_block
fill ~454 ~60 ~121 ~454 ~63 ~121 stone
fill ~454 ~64 ~121 ~454 ~66 ~121 dirt
fill ~454 ~67 ~121 ~454 ~67 ~121 grass_block
fill ~455 ~60 ~121 ~459 ~64 ~121 stone
fill ~455 ~65 ~121 ~459 ~67 ~121 dirt
fill ~455 ~68 ~121 ~459 ~68 ~121 grass_block
fill ~460 ~60 ~121 ~463 ~63 ~121 stone
fill ~460 ~64 ~121 ~463 ~66 ~121 dirt
fill ~460 ~67 ~121 ~463 ~67 ~121 grass_block
fill ~448 ~60 ~122 ~462 ~64 ~122 stone
fill ~448 ~65 ~122 ~462 ~67 ~122 dirt
fill ~448 ~68 ~122 ~462 ~68 ~122 grass_block
fill ~463 ~60 ~122 ~463 ~63 ~122 stone
fill ~463 ~64 ~122 ~463 ~66 ~122 dirt
fill ~463 ~67 ~122 ~463 ~67 ~122 grass_block
fill ~448 ~60 ~123 ~463 ~64 ~123 stone
fill ~448 ~65 ~123 ~463 ~67 ~123 dirt
fill ~448 ~68 ~123 ~463 ~68 ~123 grass_block
fill ~448 ~60 ~124 ~448 ~63 ~124 stone
fill ~448 ~64 ~124 ~448 ~66 ~124 dirt
fill ~448 ~67 ~124 ~448 ~67 ~124 grass_block
fill ~449 ~60 ~124 ~463 ~64 ~124 stone
fill ~449 ~65 ~124 ~463 ~67 ~124 dirt
fill ~449 ~68 ~124 ~463 ~68 ~124 grass_block
fill ~448 ~60 ~125 ~451 ~63 ~125 stone
fill ~448 ~64 ~125 ~451 ~66 ~125 dirt
fill ~448 ~67 ~125 ~451 ~67 ~125 grass_block
fill ~452 ~60 ~125 ~458 ~64 ~125 stone
fill ~452 ~65 ~125 ~458 ~67 ~125 dirt
fill ~452 ~68 ~125 ~458 ~68 ~125 grass_block
fill ~459 ~60 ~125 ~460 ~63 ~125 stone
fill ~459 ~64 ~125 ~460 ~66 ~125 dirt
fill ~459 ~67 ~125 ~460 ~67 ~125 grass_block
fill ~461 ~60 ~125 ~463 ~64 ~125 stone
fill ~461 ~65 ~125 ~463 ~67 ~125 dirt
fill ~461 ~68 ~125 ~463 ~68 ~125 grass_block
fill ~448 ~60 ~126 ~461 ~63 ~126 stone
fill ~448 ~64 ~126 ~461 ~66 ~126 dirt
fill ~448 ~67 ~126 ~461 ~67 ~126 grass_block
fill ~462 ~60 ~126 ~463 ~64 ~126 stone
fill ~462 ~65 ~126 ~463 ~67 ~126 dirt
fill ~462 ~68 ~126 ~463 ~68 ~126 grass_block
fill ~448 ~60 ~127 ~461 ~63 ~127 stone
fill ~448 ~64 ~127 ~461 ~66 ~127 dirt
fill ~448 ~67 ~127 ~461 ~67 ~127 grass_block
fill ~462 ~60 ~127 ~463 ~64 ~127 stone
fill ~462 ~65 ~127 ~463 ~67 ~127 dirt
fill ~462 ~68 ~127 ~463 ~68 ~127 grass_block