fill ~32 ~60 ~16 ~37 ~68 ~16 stone
fill ~32 ~69 ~16 ~37 ~71 ~16 dirt
fill ~32 ~72 ~16 ~37 ~72 ~16 grass_block
fill ~38 ~60 ~16 ~39 ~67 ~16 stone
fill ~38 ~68 ~16 ~39 ~70 ~16 dirt
fill ~38 ~71 ~16 ~39 ~71 ~16 grass_block
fill ~40 ~60 ~16 ~43 ~66 ~16 stone
fill ~40 ~67 ~16 ~43 ~69 ~16 dirt
fill ~40 ~70 ~16 ~43 ~70 ~16 grass_block
fill ~44 ~60 ~16 ~46 ~65 ~16 stone
fill ~44 ~66 ~16 ~46 ~68 ~16 dirt
fill ~44 ~69 ~16 ~46 ~69 ~16 grass_block
fill ~47 ~60 ~16 ~47 ~64 ~16 stone
fill ~47 ~65 ~16 ~47 ~67 ~16 dirt
fill ~47 ~68 ~16 ~47 ~68 ~16 grass_block
fill ~32 ~60 ~17 ~40 ~68 ~17 stone
fill ~32 ~69 ~17 ~40 ~71 ~17 dirt
fill ~32 ~72 ~17 ~40 ~72 ~17 grass_block
fill ~41 ~60 ~17 ~42 ~67 ~17 stone
fill ~41 ~68 ~17 ~42 ~70 ~17 dirt
fill ~41 ~71 ~17 ~42 ~71 ~17 grass_block
fill ~43 ~60 ~17 ~44 ~66 ~17 stone
fill ~43 ~67 ~17 ~44 ~69 ~17 dirt
fill ~43 ~70 ~17 ~44 ~70 ~17 grass_block
fill ~45 ~60 ~17 ~47 ~65 ~17 stone
fill ~45 ~66 ~17 ~47 ~68 ~17 dirt
fill ~45 ~69 ~17 ~47 ~69 ~17 grass_block
fill ~32 ~60 ~18 ~42 ~68 ~18 stone
fill ~32 ~69 ~18 ~42 ~71 ~18 dirt
fill ~32 ~72 ~18 ~42 ~72 ~18 grass_block
fill ~43 ~60 ~18 ~44 ~67 ~18 stone
fill ~43 ~68 ~18 ~44 ~70 ~18 dirt
fill ~43 ~71 ~18 ~44 ~71 ~18 grass_block
fill ~45 ~60 ~18 ~46 ~66 ~18 stone
fill ~45 ~67 ~18 ~46 ~69 ~18 dirt
fill ~45 ~70 ~18 ~46 ~70 ~18 grass_block
fill ~47 ~60 ~18 ~47 ~65 ~18 stone
fill ~47 ~66 ~18 ~47 ~68 ~18 dirt
fill ~47 ~69 ~18 ~47 ~69 ~18 grass_block
fill ~32 ~60 ~19 ~34 ~67 ~19 stone
fill ~32 ~68 ~19 ~34 ~70 ~19 dirt
fill ~32 ~71 ~19 ~34 ~71 ~19 grass_block
fill ~35 ~60 ~19 ~44 ~68 ~19 stone
fill ~35 ~69 ~19 ~44 ~71 ~19 dirt
fill ~35 ~72 ~19 ~44 ~72 ~19 grass_block
fill ~45 ~60 ~19 ~45 ~67 ~19 stone
fill ~45 ~68 ~19 ~45 ~70 ~19 dirt
fill ~45 ~71 ~19 ~45 ~71 ~19 grass_block
fill ~46 ~60 ~19 ~47 ~66 ~19 stone
fill ~46 ~67 ~19 ~47 ~69 ~19 dirt
fill ~46 ~70 ~19 ~47 ~70 ~19 grass_block
fill ~32 ~60 ~20 ~35 ~67 ~20 stone
fill ~32 ~68 ~20 ~35 ~70 ~20 dirt
fill ~32 ~71 ~20 ~35 ~71 ~20 grass_block
fill ~36 ~60 ~20 ~44 ~68 ~20 stone
fill ~36 ~69 ~20 ~44 ~71 ~20 dirt
fill ~36 ~72 ~20 ~44 ~72 ~20 grass_block
fill ~45 ~60 ~20 ~46 ~67 ~20 stone
fill ~45 ~68 ~20 ~46 ~70 ~20 dirt
fill ~45 ~71 ~20 ~46 ~71 ~20 grass_block
fill ~47 ~60 ~20 ~47 ~66 ~20 stone
fill ~47 ~67 ~20 ~47 ~69 ~20 dirt
fill ~47 ~70 ~20 ~47 ~70 ~20 grass_block
fill ~32 ~60 ~21 ~32 ~67 ~21 stone
fill ~32 ~68 ~21 ~32 ~70 ~21 dirt
fill ~32 ~71 ~21 ~32 ~71 ~21 grass_block
fill ~33 ~60 ~21 ~35 ~66 ~21 stone
fill ~33 ~67 ~21 ~35 ~69 ~21 dirt
fill ~33 ~70 ~21 ~35 ~70 ~21 grass_block
fill ~36 ~60 ~21 ~39 ~67 ~21 stone
fill ~36 ~68 ~21 ~39 ~70 ~21 dirt
fill ~36 ~71 ~21 ~39 ~71 ~21 grass_block
fill ~40 ~60 ~21 ~46 ~68 ~21 stone
fill ~40 ~69 ~21 ~46 ~71 ~21 dirt
fill ~40 ~72 ~21 ~46 ~72 ~21 grass_block
fill ~47 ~60 ~21 ~47 ~67 ~21 stone
fill ~47 ~68 ~21 ~47 ~70 ~21 dirt
fill ~47 ~71 ~21 ~47 ~71 ~21 grass_block
fill ~32 ~60 ~22 ~38 ~66 ~22 stone
fill ~32 ~67 ~22 ~38 ~69 ~22 dirt
fill ~32 ~70 ~22 ~38 ~70 ~22 grass_block
fill ~39 ~60 ~22 ~41 ~67 ~22 stone
fill ~39 ~68 ~22 ~41 ~70 ~22 dirt
fill ~39 ~71 ~22 ~41 ~71 ~22 grass_block
fill ~42 ~60 ~22 ~47 ~68 ~22 stone
fill ~42 ~69 ~22 ~47 ~71 ~22 dirt
fill ~42 ~72 ~22 ~47 ~72 ~22 grass_block
fill ~32 ~60 ~23 ~35 ~66 ~23 stone
fill ~32 ~67 ~23 ~35 ~69 ~23 dirt
fill ~32 ~70 ~23 ~35 ~70 ~23 grass_block
fill ~36 ~60 ~23 ~36 ~65 ~23 stone
fill ~36 ~66 ~23 ~36 ~68 ~23 dirt
fill ~36 ~69 ~23 ~36 ~69 ~23 grass_block
fill ~37 ~60 ~23 ~39 ~66 ~23 stone
fill ~37 ~67 ~23 ~39 ~69 ~23 dirt
fill ~37 ~70 ~23 ~39 ~70 ~23 grass_block
fill ~40 ~60 ~23 ~45 ~67 ~23 stone
fill ~40 ~68 ~23 ~45 ~70 ~23 dirt
fill ~40 ~71 ~23 ~45 ~71 ~23 grass_block
fill ~46 ~60 ~23 ~47 ~68 ~23 stone
fill ~46 ~69 ~23 ~47 ~71 ~23 dirt
fill ~46 ~72 ~23 ~47 ~72 ~23 grass_block
fill ~32 ~60 ~24 ~34 ~66 ~24 stone
fill ~32 ~67 ~24 ~34 ~69 ~24 dirt
fill ~32 ~70 ~24 ~34 ~70 ~24 grass_block
fill ~35 ~60 ~24 ~38 ~65 ~24 stone
fill ~35 ~66 ~24 ~38 ~68 ~24 dirt
fill ~35 ~69 ~24 ~38 ~69 ~24 grass_block
fill ~39 ~60 ~24 ~40 ~66 ~24 stone
fill ~39 ~67 ~24 ~40 ~69 ~24 dirt
fill ~39 ~70 ~24 ~40 ~70 ~24 grass_block
fill ~41 ~60 ~24 ~41 ~67 ~24 stone
fill ~41 ~68 ~24 ~41 ~70 ~24 dirt
fill ~41 ~71 ~24 ~41 ~71 ~24 grass_block
fill ~42 ~60 ~24 ~44 ~66 ~24 stone
fill ~42 ~67 ~24 ~44 ~69 ~24 dirt
fill ~42 ~70 ~24 ~44 ~70 ~24 grass_block
fill ~45 ~60 ~24 ~47 ~67 ~24 stone
fill ~45 ~68 ~24 ~47 ~70 ~24 dirt
fill ~45 ~71 ~24 ~47 ~71 ~24 grass_block
fill ~32 ~60 ~25 ~32 ~65 ~25 stone
fill ~32 ~66 ~25 ~32 ~68 ~25 dirt
fill ~32 ~69 ~25 ~32 ~69 ~25 grass_block
fill ~33 ~60 ~25 ~34 ~66 ~25 stone
fill ~33 ~67 ~25 ~34 ~69 ~25 dirt
fill ~33 ~70 ~25 ~34 ~70 ~25 grass_block
fill ~35 ~60 ~25 ~39 ~65 ~25 stone
fill ~35 ~66 ~25 ~39 ~68 ~25 dirt
fill ~35 ~69 ~25 ~39 ~69 ~25 grass_block
fill ~40 ~60 ~25 ~45 ~66 ~25 stone
fill ~40 ~67 ~25 ~45 ~69 ~25 dirt
fill ~40 ~70 ~25 ~45 ~70 ~25 grass_block
fill ~46 ~60 ~25 ~47 ~67 ~25 stone
fill ~46 ~68 ~25 ~47 ~70 ~25 dirt
fill ~46 ~71 ~25 ~47 ~71 ~25 grass_block
fill ~32 ~60 ~26 ~32 ~65 ~26 stone
fill ~32 ~66 ~26 ~32 ~68 ~26 dirt
fill ~32 ~69 ~26 ~32 ~69 ~26 grass_block
fill ~33 ~60 ~26 ~34 ~66 ~26 stone
fill ~33 ~67 ~26 ~34 ~69 ~26 dirt
fill ~33 ~70 ~26 ~34 ~70 ~26 grass_block
fill ~35 ~60 ~26 ~39 ~65 ~26 stone
fill ~35 ~66 ~26 ~39 ~68 ~26 dirt
fill ~35 ~69 ~26 ~39 ~69 ~26 grass_block
fill ~40 ~60 ~26 ~42 ~66 ~26 stone
fill ~40 ~67 ~26 ~42 ~69 ~26 dirt
fill ~40 ~70 ~26 ~42 ~70 ~26 grass_block
fill ~43 ~60 ~26 ~43 ~65 ~26 stone
fill ~43 ~66 ~26 ~43 ~68 ~26 dirt
fill ~43 ~69 ~26 ~43 ~69 ~26 grass_block
fill ~44 ~60 ~26 ~46 ~66 ~26 stone
fill ~44 ~67 ~26 ~46 ~69 ~26 dirt
fill ~44 ~70 ~26 ~46 ~70 ~26 grass_block
fill ~47 ~60 ~26 ~47 ~67 ~26 stone
fill ~47 ~68 ~26 ~47 ~70 ~26 dirt
fill ~47 ~71 ~26 ~47 ~71 ~26 grass_block
fill ~32 ~60 ~27 ~44 ~65 ~27 stone
fill ~32 ~66 ~27 ~44 ~68 ~27 dirt
fill ~32 ~69 ~27 ~44 ~69 ~27 grass_block
fill ~45 ~60 ~27 ~46 ~66 ~27 stone
fill ~45 ~67 ~27 ~46 ~69 ~27 dirt
fill ~45 ~70 ~27 ~46 ~70 ~27 grass_block
fill ~47 ~60 ~27 ~47 ~67 ~27 stone
fill ~47 ~68 ~27 ~47 ~70 ~27 dirt
fill ~47 ~71 ~27 ~47 ~71 ~27 grass_block
fill ~32 ~60 ~28 ~44 ~65 ~28 stone
fill ~32 ~66 ~28 ~44 ~68 ~28 dirt
fill ~32 ~69 ~28 ~44 ~69 ~28 grass_block
fill ~45 ~60 ~28 ~47 ~66 ~28 stone
fill ~45 ~67 ~28 ~47 ~69 ~28 dirt
fill ~45 ~70 ~28 ~47 ~70 ~28 grass_block
fill ~32 ~60 ~29 ~34 ~64 ~29 stone
fill ~32 ~65 ~29 ~34 ~67 ~29 dirt
fill ~32 ~68 ~29 ~34 ~68 ~29 grass_block
fill ~35 ~60 ~29 ~37 ~65 ~29 stone
fill ~35 ~66 ~29 ~37 ~68 ~29 dirt
fill ~35 ~69 ~29 ~37 ~69 ~29 grass_block
fill ~38 ~60 ~29 ~39 ~64 ~29 stone
fill ~38 ~65 ~29 ~39 ~67 ~29 dirt
fill ~38 ~68 ~29 ~39 ~68 ~29 grass_block
fill ~40 ~60 ~29 ~40 ~65 ~29 stone
fill ~40 ~66 ~29 ~40 ~68 ~29 dirt
fill ~40 ~69 ~29 ~40 ~69 ~29 grass_block
fill ~41 ~60 ~29 ~42 ~64 ~29 stone
fill ~41 ~65 ~29 ~42 ~67 ~29 dirt
fill ~41 ~68 ~29 ~42 ~68 ~29 grass_block
fill ~43 ~60 ~29 ~45 ~65 ~29 stone
fill ~43 ~66 ~29 ~45 ~68 ~29 dirt
fill ~43 ~69 ~29 ~45 ~69 ~29 grass_block
fill ~46 ~60 ~29 ~47 ~66 ~29 stone
fill ~46 ~67 ~29 ~47 ~69 ~29 dirt
fill ~46 ~70 ~29 ~47 ~70 ~29 grass_block
fill ~32 ~60 ~30 ~41 ~64 ~30 stone
fill ~32 ~65 ~30 ~41 ~67 ~30 dirt
fill ~32 ~68 ~30 ~41 ~68 ~30 grass_block
fill ~42 ~60 ~30 ~47 ~65 ~30 stone
fill ~42 ~66 ~30 ~47 ~68 ~30 dirt
fill ~42 ~69 ~30 ~47 ~69 ~30 grass_block
fill ~32 ~60 ~31 ~41 ~64 ~31 stone
fill ~32 ~65 ~31 ~41 ~67 ~31 dirt
fill ~32 ~68 ~31 ~41 ~68 ~31 grass_block
fill ~42 ~60 ~31 ~44 ~65 ~31 stone
fill ~42 ~66 ~31 ~44 ~68 ~31 dirt
fill ~42 ~69 ~31 ~44 ~69 ~31 grass_block
fill ~45 ~60 ~31 ~45 ~64 ~31 stone
fill ~45 ~65 ~31 ~45 ~67 ~31 dirt
fill ~45 ~68 ~31 ~45 ~68 ~31 grass_block
fill ~46 ~60 ~31 ~47 ~65 ~31 stone
fill ~46 ~66 ~31 ~47 ~68 ~31 dirt
fill ~46 ~69 ~31 ~47 ~69 ~31 grass_block