fill ~128 ~60 ~48 ~131 ~65 ~48 stone
fill ~128 ~66 ~48 ~131 ~68 ~48 dirt
fill ~128 ~69 ~48 ~131 ~69 ~48 grass_block
fill ~132 ~60 ~48 ~143 ~66 ~48 stone
fill ~132 ~67 ~48 ~143 ~69 ~48 dirt
fill ~132 ~70 ~48 ~143 ~70 ~48 grass_block
fill ~128 ~60 ~49 ~132 ~65 ~49 stone
fill ~128 ~66 ~49 ~132 ~68 ~49 dirt
fill ~128 ~69 ~49 ~132 ~69 ~49 grass_block
fill ~133 ~60 ~49 ~135 ~66 ~49 stone
fill ~133 ~67 ~49 ~135 ~69 ~49 dirt
fill ~133 ~70 ~49 ~135 ~70 ~49 grass_block
fill ~136 ~60 ~49 ~136 ~65 ~49 stone
fill ~136 ~66 ~49 ~136 ~68 ~49 dirt
fill ~136 ~69 ~49 ~136 ~69 ~49 grass_block
fill ~137 ~60 ~49 ~143 ~66 ~49 stone
fill ~137 ~67 ~49 ~143 ~69 ~49 dirt
fill ~137 ~70 ~49 ~143 ~70 ~49 grass_block
fill ~128 ~60 ~50 ~128 ~66 ~50 stone
fill ~128 ~67 ~50 ~128 ~69 ~50 dirt
fill ~128 ~70 ~50 ~128 ~70 ~50 grass_block
fill ~129 ~60 ~50 ~134 ~65 ~50 stone
fill ~129 ~66 ~50 ~134 ~68 ~50 dirt
fill ~129 ~69 ~50 ~134 ~69 ~50 grass_block
fill ~135 ~60 ~50 ~135 ~66 ~50 stone
fill ~135 ~67 ~50 ~135 ~69 ~50 dirt
fill ~135 ~70 ~50 ~135 ~70 ~50 grass_block
fill ~136 ~60 ~50 ~143 ~65 ~50 stone
fill ~136 ~66 ~50 ~143 ~68 ~50 dirt
fill ~136 ~69 ~50 ~143 ~69 ~50 grass_block
fill ~128 ~60 ~51 ~128 ~66 ~51 stone
fill ~128 ~67 ~51 ~128 ~69 ~51 dirt
fill ~128 ~70 ~51 ~128 ~70 ~51 grass_block
fill ~129 ~60 ~51 ~143 ~65 ~51 stone
fill ~129 ~66 ~51 ~143 ~68 ~51 dirt
fill ~129 ~69 ~51 ~143 ~69 ~51 grass_block
fill ~128 ~60 ~52 ~128 ~66 ~52 stone
fill ~128 ~67 ~52 ~128 ~69 ~52 dirt
fill ~128 ~70 ~52 ~128 ~70 ~52 grass_block
fill ~129 ~60 ~52 ~132 ~65 ~52 stone
fill ~129 ~66 ~52 ~132 ~68 ~52 dirt
fill ~129 ~69 ~52 ~132 ~69 ~52 grass_block
fill ~133 ~60 ~52 ~133 ~64 ~52 stone
fill ~133 ~65 ~52 ~133 ~67 ~52 dirt
fill ~133 ~68 ~52 ~133 ~68 ~52 grass_block
fill ~134 ~60 ~52 ~143 ~65 ~52 stone
fill ~134 ~66 ~52 ~143 ~68 ~52 dirt
fill ~134 ~69 ~52 ~143 ~69 ~52 grass_block
fill ~128 ~60 ~53 ~129 ~66 ~53 stone
fill ~128 ~67 ~53 ~129 ~69 ~53 dirt
fill ~128 ~70 ~53 ~129 ~70 ~53 grass_block
fill ~130 ~60 ~53 ~138 ~65 ~53 stone
fill ~130 ~66 ~53 ~138 ~68 ~53 dirt
fill ~130 ~69 ~53 ~138 ~69 ~53 grass_block
fill ~139 ~60 ~53 ~141 ~64 ~53 stone
fill ~139 ~65 ~53 ~141 ~67 ~53 dirt
fill ~139 ~68 ~53 ~141 ~68 ~53 grass_block
fill ~142 ~60 ~53 ~143 ~65 ~53 stone
fill ~142 ~66 ~53 ~143 ~68 ~53 dirt
fill ~142 ~69 ~53 ~143 ~69 ~53 grass_block
fill ~128 ~60 ~54 ~130 ~66 ~54 stone
fill ~128 ~67 ~54 ~130 ~69 ~54 dirt
fill ~128 ~70 ~54 ~130 ~70 ~54 grass_block
fill ~131 ~60 ~54 ~133 ~65 ~54 stone
fill ~131 ~66 ~54 ~133 ~68 ~54 dirt
fill ~131 ~69 ~54 ~133 ~69 ~54 grass_block
fill ~134 ~60 ~54 ~136 ~64 ~54 stone
fill ~134 ~65 ~54 ~136 ~67 ~54 dirt
fill ~134 ~68 ~54 ~136 ~68 ~54 grass_block
fill ~137 ~60 ~54 ~138 ~65 ~54 stone
fill ~137 ~66 ~54 ~138 ~68 ~54 dirt
fill ~137 ~69 ~54 ~138 ~69 ~54 grass_block
fill ~139 ~60 ~54 ~140 ~64 ~54 stone
fill ~139 ~65 ~54 ~140 ~67 ~54 dirt
fill ~139 ~68 ~54 ~140 ~68 ~54 grass_block
fill ~141 ~60 ~54 ~143 ~65 ~54 stone
fill ~141 ~66 ~54 ~143 ~68 ~54 dirt
fill ~141 ~69 ~54 ~143 ~69 ~54 grass_block
fill ~128 ~60 ~55 ~131 ~66 ~55 stone
fill ~128 ~67 ~55 ~131 ~69 ~55 dirt
fill ~128 ~70 ~55 ~131 ~70 ~55 grass_block
fill ~132 ~60 ~55 ~134 ~65 ~55 stone
fill ~132 ~66 ~55 ~134 ~68 ~55 dirt
fill ~132 ~69 ~55 ~134 ~69 ~55 grass_block
fill ~135 ~60 ~55 ~140 ~64 ~55 stone
fill ~135 ~65 ~55 ~140 ~67 ~55 dirt
fill ~135 ~68 ~55 ~140 ~68 ~55 grass_block
fill ~141 ~60 ~55 ~143 ~65 ~55 stone
fill ~141 ~66 ~55 ~143 ~68 ~55 dirt
fill ~141 ~69 ~55 ~143 ~69 ~55 grass_block
fill ~128 ~60 ~56 ~133 ~66 ~56 stone
fill ~128 ~67 ~56 ~133 ~69 ~56 dirt
fill ~128 ~70 ~56 ~133 ~70 ~56 grass_block
fill ~134 ~60 ~56 ~135 ~65 ~56 stone
fill ~134 ~66 ~56 ~135 ~68 ~56 dirt
fill ~134 ~69 ~56 ~135 ~69 ~56 grass_block
fill ~136 ~60 ~56 ~140 ~64 ~56 stone
fill ~136 ~65 ~56 ~140 ~67 ~56 dirt
fill ~136 ~68 ~56 ~140 ~68 ~56 grass_block
fill ~141 ~60 ~56 ~143 ~65 ~56 stone
fill ~141 ~66 ~56 ~143 ~68 ~56 dirt
fill ~141 ~69 ~56 ~143 ~69 ~56 grass_block
fill ~128 ~60 ~57 ~134 ~66 ~57 stone
fill ~128 ~67 ~57 ~134 ~69 ~57 dirt
fill ~128 ~70 ~57 ~134 ~70 ~57 grass_block
fill ~135 ~60 ~57 ~136 ~65 ~57 stone
fill ~135 ~66 ~57 ~136 ~68 ~57 dirt
fill ~135 ~69 ~57 ~136 ~69 ~57 grass_block
fill ~137 ~60 ~57 ~141 ~64 ~57 stone
fill ~137 ~65 ~57 ~141 ~67 ~57 dirt
fill ~137 ~68 ~57 ~141 ~68 ~57 grass_block
fill ~142 ~60 ~57 ~143 ~65 ~57 stone
fill ~142 ~66 ~57 ~143 ~68 ~57 dirt
fill ~142 ~69 ~57 ~143 ~69 ~57 grass_block
fill ~128 ~60 ~58 ~130 ~66 ~58 stone
fill ~128 ~67 ~58 ~130 ~69 ~58 dirt
fill ~128 ~70 ~58 ~130 ~70 ~58 grass_block
fill ~131 ~60 ~58 ~131 ~65 ~58 stone
fill ~131 ~66 ~58 ~131 ~68 ~58 dirt
fill ~131 ~69 ~58 ~131 ~69 ~58 grass_block
fill ~132 ~60 ~58 ~135 ~66 ~58 stone
fill ~132 ~67 ~58 ~135 ~69 ~58 dirt
fill ~132 ~70 ~58 ~135 ~70 ~58 grass_block
fill ~136 ~60 ~58 ~137 ~65 ~58 stone
fill ~136 ~66 ~58 ~137 ~68 ~58 dirt
fill ~136 ~69 ~58 ~137 ~69 ~58 grass_block
fill ~138 ~60 ~58 ~143 ~64 ~58 stone
fill ~138 ~65 ~58 ~143 ~67 ~58 dirt
fill ~138 ~68 ~58 ~143 ~68 ~58 grass_block
fill ~128 ~60 ~59 ~132 ~65 ~59 stone
fill ~128 ~66 ~59 ~132 ~68 ~59 dirt
fill ~128 ~69 ~59 ~132 ~69 ~59 grass_block
fill ~133 ~60 ~59 ~135 ~66 ~59 stone
fill ~133 ~67 ~59 ~135 ~69 ~59 dirt
fill ~133 ~70 ~59 ~135 ~70 ~59 grass_block
fill ~136 ~60 ~59 ~138 ~65 ~59 stone
fill ~136 ~66 ~59 ~138 ~68 ~59 dirt
fill ~136 ~69 ~59 ~138 ~69 ~59 grass_block
fill ~139 ~60 ~59 ~143 ~64 ~59 stone
fill ~139 ~65 ~59 ~143 ~67 ~59 dirt
fill ~139 ~68 ~59 ~143 ~68 ~59 grass_block
fill ~128 ~60 ~60 ~133 ~65 ~60 stone
fill ~128 ~66 ~60 ~133 ~68 ~60 dirt
fill ~128 ~69 ~60 ~133 ~69 ~60 grass_block
fill ~134 ~60 ~60 ~136 ~66 ~60 stone
fill ~134 ~67 ~60 ~136 ~69 ~60 dirt
fill ~134 ~70 ~60 ~136 ~70 ~60 grass_block
fill ~137 ~60 ~60 ~138 ~65 ~60 stone
fill ~137 ~66 ~60 ~138 ~68 ~60 dirt
fill ~137 ~69 ~60 ~138 ~69 ~60 grass_block
fill ~139 ~60 ~60 ~143 ~64 ~60 stone
fill ~139 ~65 ~60 ~143 ~67 ~60 dirt
fill ~139 ~68 ~60 ~143 ~68 ~60 grass_block
fill ~128 ~60 ~61 ~134 ~65 ~61 stone
fill ~128 ~66 ~61 ~134 ~68 ~61 dirt
fill ~128 ~69 ~61 ~134 ~69 ~61 grass_block
fill ~135 ~60 ~61 ~137 ~66 ~61 stone
fill ~135 ~67 ~61 ~137 ~69 ~61 dirt
fill ~135 ~70 ~61 ~137 ~70 ~61 grass_block
fill ~138 ~60 ~61 ~139 ~65 ~61 stone
fill ~138 ~66 ~61 ~139 ~68 ~61 dirt
fill ~138 ~69 ~61 ~139 ~69 ~61 grass_block
fill ~140 ~60 ~61 ~143 ~64 ~61 stone
fill ~140 ~65 ~61 ~143 ~67 ~61 dirt
fill ~140 ~68 ~61 ~143 ~68 ~61 grass_block
fill ~128 ~60 ~62 ~128 ~65 ~62 stone
fill ~128 ~66 ~62 ~128 ~68 ~62 dirt
fill ~128 ~69 ~62 ~128 ~69 ~62 grass_block
fill ~129 ~60 ~62 ~130 ~64 ~62 stone
fill ~129 ~65 ~62 ~130 ~67 ~62 dirt
fill ~129 ~68 ~62 ~130 ~68 ~62 grass_block
fill ~131 ~60 ~62 ~134 ~65 ~62 stone
fill ~131 ~66 ~62 ~134 ~68 ~62 dirt
fill ~131 ~69 ~62 ~134 ~69 ~62 grass_block
fill ~135 ~60 ~62 ~137 ~66 ~62 stone
fill ~135 ~67 ~62 ~137 ~69 ~62 dirt
fill ~135 ~70 ~62 ~137 ~70 ~62 grass_block
fill ~138 ~60 ~62 ~140 ~65 ~62 stone
fill ~138 ~66 ~62 ~140 ~68 ~62 dirt
fill ~138 ~69 ~62 ~140 ~69 ~62 grass_block
fill ~141 ~60 ~62 ~143 ~64 ~62 stone
fill ~141 ~65 ~62 ~143 ~67 ~62 dirt
fill ~141 ~68 ~62 ~143 ~68 ~62 grass_block
fill ~128 ~60 ~63 ~128 ~65 ~63 stone
fill ~128 ~66 ~63 ~128 ~68 ~63 dirt
fill ~128 ~69 ~63 ~128 ~69 ~63 grass_block
fill ~129 ~60 ~63 ~130 ~64 ~63 stone
fill ~129 ~65 ~63 ~130 ~67 ~63 dirt
fill ~129 ~68 ~63 ~130 ~68 ~63 grass_block
fill ~131 ~60 ~63 ~134 ~65 ~63 stone
fill ~131 ~66 ~63 ~134 ~68 ~63 dirt
fill ~131 ~69 ~63 ~134 ~69 ~63 grass_block
fill ~135 ~60 ~63 ~138 ~66 ~63 stone
fill ~135 ~67 ~63 ~138 ~69 ~63 dirt
fill ~135 ~70 ~63 ~138 ~70 ~63 grass_block
fill ~139 ~60 ~63 ~141 ~65 ~63 stone
fill ~139 ~66 ~63 ~141 ~68 ~63 dirt
fill ~139 ~69 ~63 ~141 ~69 ~63 grass_block
fill ~142 ~60 ~63 ~143 ~64 ~63 stone
fill ~142 ~65 ~63 ~143 ~67 ~63 dirt
fill ~142 ~68 ~63 ~143 ~68 ~63 grass_block