fill ~320 ~60 ~96 ~324 ~61 ~96 stone
fill ~320 ~62 ~96 ~324 ~64 ~96 dirt
fill ~320 ~65 ~96 ~324 ~65 ~96 grass_block
fill ~325 ~60 ~96 ~326 ~60 ~96 stone
fill ~325 ~61 ~96 ~326 ~63 ~96 dirt
fill ~325 ~64 ~96 ~326 ~64 ~96 grass_block
fill ~327 ~60 ~96 ~327 ~61 ~96 stone
fill ~327 ~62 ~96 ~327 ~64 ~96 dirt
fill ~327 ~65 ~96 ~327 ~65 ~96 grass_block
fill ~328 ~60 ~96 ~335 ~60 ~96 stone
fill ~328 ~61 ~96 ~335 ~63 ~96 dirt
fill ~328 ~64 ~96 ~335 ~64 ~96 grass_block
fill ~320 ~60 ~97 ~324 ~61 ~97 stone
fill ~320 ~62 ~97 ~324 ~64 ~97 dirt
fill ~320 ~65 ~97 ~324 ~65 ~97 grass_block
fill ~325 ~60 ~97 ~335 ~60 ~97 stone
fill ~325 ~61 ~97 ~335 ~63 ~97 dirt
fill ~325 ~64 ~97 ~335 ~64 ~97 grass_block
fill ~320 ~60 ~98 ~327 ~61 ~98 stone
fill ~320 ~62 ~98 ~327 ~64 ~98 dirt
fill ~320 ~65 ~98 ~327 ~65 ~98 grass_block
fill ~328 ~60 ~98 ~335 ~60 ~98 stone
fill ~328 ~61 ~98 ~335 ~63 ~98 dirt
fill ~328 ~64 ~98 ~335 ~64 ~98 grass_block
fill ~320 ~60 ~99 ~327 ~61 ~99 stone
fill ~320 ~62 ~99 ~327 ~64 ~99 dirt
fill ~320 ~65 ~99 ~327 ~65 ~99 grass_block
fill ~328 ~60 ~99 ~335 ~60 ~99 stone
fill ~328 ~61 ~99 ~335 ~63 ~99 dirt
fill ~328 ~64 ~99 ~335 ~64 ~99 grass_block
fill ~320 ~60 ~100 ~322 ~62 ~100 stone
fill ~320 ~63 ~100 ~322 ~65 ~100 dirt
fill ~320 ~66 ~100 ~322 ~66 ~100 grass_block
fill ~323 ~60 ~100 ~327 ~61 ~100 stone
fill ~323 ~62 ~100 ~327 ~64 ~100 dirt
fill ~323 ~65 ~100 ~327 ~65 ~100 grass_block
fill ~328 ~60 ~100 ~335 ~60 ~100 stone
fill ~328 ~61 ~100 ~335 ~63 ~100 dirt
fill ~328 ~64 ~100 ~335 ~64 ~100 grass_block
fill ~320 ~60 ~101 ~323 ~62 ~101 stone
fill ~320 ~63 ~101 ~323 ~65 ~101 dirt
fill ~320 ~66 ~101 ~323 ~66 ~101 grass_block
fill ~324 ~60 ~101 ~327 ~61 ~101 stone
fill ~324 ~62 ~101 ~327 ~64 ~101 dirt
fill ~324 ~65 ~101 ~327 ~65 ~101 grass_block
fill ~328 ~60 ~101 ~335 ~60 ~101 stone
fill ~328 ~61 ~101 ~335 ~63 ~101 dirt
fill ~328 ~64 ~101 ~335 ~64 ~101 grass_block
fill ~320 ~60 ~102 ~323 ~62 ~102 stone
fill ~320 ~63 ~102 ~323 ~65 ~102 dirt
fill ~320 ~66 ~102 ~323 ~66 ~102 grass_block
fill ~324 ~60 ~102 ~328 ~61 ~102 stone
fill ~324 ~62 ~102 ~328 ~64 ~102 dirt
fill ~324 ~65 ~102 ~328 ~65 ~102 grass_block
fill ~329 ~60 ~102 ~335 ~60 ~102 stone
fill ~329 ~61 ~102 ~335 ~63 ~102 dirt
fill ~329 ~64 ~102 ~335 ~64 ~102 grass_block
fill ~320 ~60 ~103 ~324 ~62 ~103 stone
fill ~320 ~63 ~103 ~324 ~65 ~103 dirt
fill ~320 ~66 ~103 ~324 ~66 ~103 grass_block
fill ~325 ~60 ~103 ~329 ~61 ~103 stone
fill ~325 ~62 ~103 ~329 ~64 ~103 dirt
fill ~325 ~65 ~103 ~329 ~65 ~103 grass_block
fill ~330 ~60 ~103 ~332 ~60 ~103 stone
fill ~330 ~61 ~103 ~332 ~63 ~103 dirt
fill ~330 ~64 ~103 ~332 ~64 ~103 grass_block
fill ~333 ~60 ~103 ~333 ~61 ~103 stone
fill ~333 ~62 ~103 ~333 ~64 ~103 dirt
fill ~333 ~65 ~103 ~333 ~65 ~103 grass_block
fill ~334 ~60 ~103 ~335 ~60 ~103 stone
fill ~334 ~61 ~103 ~335 ~63 ~103 dirt
fill ~334 ~64 ~103 ~335 ~64 ~103 grass_block
fill ~320 ~60 ~104 ~324 ~62 ~104 stone
fill ~320 ~63 ~104 ~324 ~65 ~104 dirt
fill ~320 ~66 ~104 ~324 ~66 ~104 grass_block
fill ~325 ~60 ~104 ~330 ~61 ~104 stone
fill ~325 ~62 ~104 ~330 ~64 ~104 dirt
fill ~325 ~65 ~104 ~330 ~65 ~104 grass_block
fill ~331 ~60 ~104 ~335 ~60 ~104 stone
fill ~331 ~61 ~104 ~335 ~63 ~104 dirt
fill ~331 ~64 ~104 ~335 ~64 ~104 grass_block
fill ~320 ~60 ~105 ~327 ~62 ~105 stone
fill ~320 ~63 ~105 ~327 ~65 ~105 dirt
fill ~320 ~66 ~105 ~327 ~66 ~105 grass_block
fill ~328 ~60 ~105 ~331 ~61 ~105 stone
fill ~328 ~62 ~105 ~331 ~64 ~105 dirt
fill ~328 ~65 ~105 ~331 ~65 ~105 grass_block
fill ~332 ~60 ~105 ~335 ~60 ~105 stone
fill ~332 ~61 ~105 ~335 ~63 ~105 dirt
fill ~332 ~64 ~105 ~335 ~64 ~105 grass_block
fill ~320 ~60 ~106 ~328 ~62 ~106 stone
fill ~320 ~63 ~106 ~328 ~65 ~106 dirt
fill ~320 ~66 ~106 ~328 ~66 ~106 grass_block
fill ~329 ~60 ~106 ~331 ~61 ~106 stone
fill ~329 ~62 ~106 ~331 ~64 ~106 dirt
fill ~329 ~65 ~106 ~331 ~65 ~106 grass_block
fill ~332 ~60 ~106 ~335 ~60 ~106 stone
fill ~332 ~61 ~106 ~335 ~63 ~106 dirt
fill ~332 ~64 ~106 ~335 ~64 ~106 grass_block
fill ~320 ~60 ~107 ~328 ~62 ~107 stone
fill ~320 ~63 ~107 ~328 ~65 ~107 dirt
fill ~320 ~66 ~107 ~328 ~66 ~107 grass_block
fill ~329 ~60 ~107 ~333 ~61 ~107 stone
fill ~329 ~62 ~107 ~333 ~64 ~107 dirt
fill ~329 ~65 ~107 ~333 ~65 ~107 grass_block
fill ~334 ~60 ~107 ~335 ~60 ~107 stone
fill ~334 ~61 ~107 ~335 ~63 ~107 dirt
fill ~334 ~64 ~107 ~335 ~64 ~107 grass_block
fill ~320 ~60 ~108 ~331 ~62 ~108 stone
fill ~320 ~63 ~108 ~331 ~65 ~108 dirt
fill ~320 ~66 ~108 ~331 ~66 ~108 grass_block
fill ~332 ~60 ~108 ~333 ~61 ~108 stone
fill ~332 ~62 ~108 ~333 ~64 ~108 dirt
fill ~332 ~65 ~108 ~333 ~65 ~108 grass_block
fill ~334 ~60 ~108 ~335 ~60 ~108 stone
fill ~334 ~61 ~108 ~335 ~63 ~108 dirt
fill ~334 ~64 ~108 ~335 ~64 ~108 grass_block
fill ~320 ~60 ~109 ~332 ~62 ~109 stone
fill ~320 ~63 ~109 ~332 ~65 ~109 dirt
fill ~320 ~66 ~109 ~332 ~66 ~109 grass_block
fill ~333 ~60 ~109 ~334 ~61 ~109 stone
fill ~333 ~62 ~109 ~334 ~64 ~109 dirt
fill ~333 ~65 ~109 ~334 ~65 ~109 grass_block
fill ~335 ~60 ~109 ~335 ~60 ~109 stone
fill ~335 ~61 ~109 ~335 ~63 ~109 dirt
fill ~335 ~64 ~109 ~335 ~64 ~109 grass_block
fill ~320 ~60 ~110 ~333 ~62 ~110 stone
fill ~320 ~63 ~110 ~333 ~65 ~110 dirt
fill ~320 ~66 ~110 ~333 ~66 ~110 grass_block
fill ~334 ~60 ~110 ~335 ~61 ~110 stone
fill ~334 ~62 ~110 ~335 ~64 ~110 dirt
fill ~334 ~65 ~110 ~335 ~65 ~110 grass_block
fill ~320 ~60 ~111 ~333 ~62 ~111 stone
fill ~320 ~63 ~111 ~333 ~65 ~111 dirt
fill ~320 ~66 ~111 ~333 ~66 ~111 grass_block
fill ~334 ~60 ~111 ~335 ~61 ~111 stone
fill ~334 ~62 ~111 ~335 ~64 ~111 dirt
fill ~334 ~65 ~111 ~335 ~65 ~111 grass_block