fill ~272 ~60 ~64 ~272 ~62 ~64 stone
fill ~272 ~63 ~64 ~272 ~65 ~64 dirt
fill ~272 ~66 ~64 ~272 ~66 ~64 grass_block
fill ~273 ~60 ~64 ~285 ~61 ~64 stone
fill ~273 ~62 ~64 ~285 ~64 ~64 dirt
fill ~273 ~65 ~64 ~285 ~65 ~64 grass_block
fill ~286 ~60 ~64 ~286 ~60 ~64 stone
fill ~286 ~61 ~64 ~286 ~63 ~64 dirt
fill ~286 ~64 ~64 ~286 ~64 ~64 grass_block
fill ~287 ~60 ~64 ~287 ~61 ~64 stone
fill ~287 ~62 ~64 ~287 ~64 ~64 dirt
fill ~287 ~65 ~64 ~287 ~65 ~64 grass_block
fill ~272 ~60 ~65 ~274 ~62 ~65 stone
fill ~272 ~63 ~65 ~274 ~65 ~65 dirt
fill ~272 ~66 ~65 ~274 ~66 ~65 grass_block
fill ~275 ~60 ~65 ~275 ~61 ~65 stone
fill ~275 ~62 ~65 ~275 ~64 ~65 dirt
fill ~275 ~65 ~65 ~275 ~65 ~65 grass_block
fill ~276 ~60 ~65 ~276 ~62 ~65 stone
fill ~276 ~63 ~65 ~276 ~65 ~65 dirt
fill ~276 ~66 ~65 ~276 ~66 ~65 grass_block
fill ~277 ~60 ~65 ~287 ~61 ~65 stone
fill ~277 ~62 ~65 ~287 ~64 ~65 dirt
fill ~277 ~65 ~65 ~287 ~65 ~65 grass_block
fill ~272 ~60 ~66 ~273 ~62 ~66 stone
fill ~272 ~63 ~66 ~273 ~65 ~66 dirt
fill ~272 ~66 ~66 ~273 ~66 ~66 grass_block
fill ~274 ~60 ~66 ~287 ~61 ~66 stone
fill ~274 ~62 ~66 ~287 ~64 ~66 dirt
fill ~274 ~65 ~66 ~287 ~65 ~66 grass_block
fill ~272 ~60 ~67 ~273 ~62 ~67 stone
fill ~272 ~63 ~67 ~273 ~65 ~67 dirt
fill ~272 ~66 ~67 ~273 ~66 ~67 grass_block
fill ~274 ~60 ~67 ~287 ~61 ~67 stone
fill ~274 ~62 ~67 ~287 ~64 ~67 dirt
fill ~274 ~65 ~67 ~287 ~65 ~67 grass_block
fill ~272 ~60 ~68 ~287 ~61 ~68 stone
fill ~272 ~62 ~68 ~287 ~64 ~68 dirt
fill ~272 ~65 ~68 ~287 ~65 ~68 grass_block
fill ~272 ~60 ~69 ~278 ~62 ~69 stone
fill ~272 ~63 ~69 ~278 ~65 ~69 dirt
fill ~272 ~66 ~69 ~278 ~66 ~69 grass_block
fill ~279 ~60 ~69 ~287 ~61 ~69 stone
fill ~279 ~62 ~69 ~287 ~64 ~69 dirt
fill ~279 ~65 ~69 ~287 ~65 ~69 grass_block
fill ~272 ~60 ~70 ~279 ~62 ~70 stone
fill ~272 ~63 ~70 ~279 ~65 ~70 dirt
fill ~272 ~66 ~70 ~279 ~66 ~70 grass_block
fill ~280 ~60 ~70 ~287 ~61 ~70 stone
fill ~280 ~62 ~70 ~287 ~64 ~70 dirt
fill ~280 ~65 ~70 ~287 ~65 ~70 grass_block
fill ~272 ~60 ~71 ~277 ~62 ~71 stone
fill ~272 ~63 ~71 ~277 ~65 ~71 dirt
fill ~272 ~66 ~71 ~277 ~66 ~71 grass_block
fill ~278 ~60 ~71 ~287 ~61 ~71 stone
fill ~278 ~62 ~71 ~287 ~64 ~71 dirt
fill ~278 ~65 ~71 ~287 ~65 ~71 grass_block
fill ~272 ~60 ~72 ~279 ~62 ~72 stone
fill ~272 ~63 ~72 ~279 ~65 ~72 dirt
fill ~272 ~66 ~72 ~279 ~66 ~72 grass_block
fill ~280 ~60 ~72 ~283 ~61 ~72 stone
fill ~280 ~62 ~72 ~283 ~64 ~72 dirt
fill ~280 ~65 ~72 ~283 ~65 ~72 grass_block
fill ~284 ~60 ~72 ~285 ~62 ~72 stone
fill ~284 ~63 ~72 ~285 ~65 ~72 dirt
fill ~284 ~66 ~72 ~285 ~66 ~72 grass_block
fill ~286 ~60 ~72 ~287 ~61 ~72 stone
fill ~286 ~62 ~72 ~287 ~64 ~72 dirt
fill ~286 ~65 ~72 ~287 ~65 ~72 grass_block
fill ~272 ~60 ~73 ~278 ~62 ~73 stone
fill ~272 ~63 ~73 ~278 ~65 ~73 dirt
fill ~272 ~66 ~73 ~278 ~66 ~73 grass_block
fill ~279 ~60 ~73 ~282 ~61 ~73 stone
fill ~279 ~62 ~73 ~282 ~64 ~73 dirt
fill ~279 ~65 ~73 ~282 ~65 ~73 grass_block
fill ~283 ~60 ~73 ~286 ~62 ~73 stone
fill ~283 ~63 ~73 ~286 ~65 ~73 dirt
fill ~283 ~66 ~73 ~286 ~66 ~73 grass_block
fill ~287 ~60 ~73 ~287 ~61 ~73 stone
fill ~287 ~62 ~73 ~287 ~64 ~73 dirt
fill ~287 ~65 ~73 ~287 ~65 ~73 grass_block
fill ~272 ~60 ~74 ~278 ~62 ~74 stone
fill ~272 ~63 ~74 ~278 ~65 ~74 dirt
fill ~272 ~66 ~74 ~278 ~66 ~74 grass_block
fill ~279 ~60 ~74 ~281 ~61 ~74 stone
fill ~279 ~62 ~74 ~281 ~64 ~74 dirt
fill ~279 ~65 ~74 ~281 ~65 ~74 grass_block
fill ~282 ~60 ~74 ~286 ~62 ~74 stone
fill ~282 ~63 ~74 ~286 ~65 ~74 dirt
fill ~282 ~66 ~74 ~286 ~66 ~74 grass_block
fill ~287 ~60 ~74 ~287 ~61 ~74 stone
fill ~287 ~62 ~74 ~287 ~64 ~74 dirt
fill ~287 ~65 ~74 ~287 ~65 ~74 grass_block
fill ~272 ~60 ~75 ~278 ~62 ~75 stone
fill ~272 ~63 ~75 ~278 ~65 ~75 dirt
fill ~272 ~66 ~75 ~278 ~66 ~75 grass_block
fill ~279 ~60 ~75 ~280 ~61 ~75 stone
fill ~279 ~62 ~75 ~280 ~64 ~75 dirt
fill ~279 ~65 ~75 ~280 ~65 ~75 grass_block
fill ~281 ~60 ~75 ~287 ~62 ~75 stone
fill ~281 ~63 ~75 ~287 ~65 ~75 dirt
fill ~281 ~66 ~75 ~287 ~66 ~75 grass_block
fill ~272 ~60 ~76 ~278 ~62 ~76 stone
fill ~272 ~63 ~76 ~278 ~65 ~76 dirt
fill ~272 ~66 ~76 ~278 ~66 ~76 grass_block
fill ~279 ~60 ~76 ~279 ~61 ~76 stone
fill ~279 ~62 ~76 ~279 ~64 ~76 dirt
fill ~279 ~65 ~76 ~279 ~65 ~76 grass_block
fill ~280 ~60 ~76 ~287 ~62 ~76 stone
fill ~280 ~63 ~76 ~287 ~65 ~76 dirt
fill ~280 ~66 ~76 ~287 ~66 ~76 grass_block
fill ~272 ~60 ~77 ~287 ~62 ~77 stone
fill ~272 ~63 ~77 ~287 ~65 ~77 dirt
fill ~272 ~66 ~77 ~287 ~66 ~77 grass_block
fill ~272 ~60 ~78 ~274 ~62 ~78 stone
fill ~272 ~63 ~78 ~274 ~65 ~78 dirt
fill ~272 ~66 ~78 ~274 ~66 ~78 grass_block
fill ~275 ~60 ~78 ~276 ~63 ~78 stone
fill ~275 ~64 ~78 ~276 ~66 ~78 dirt
fill ~275 ~67 ~78 ~276 ~67 ~78 grass_block
fill ~277 ~60 ~78 ~287 ~62 ~78 stone
fill ~277 ~63 ~78 ~287 ~65 ~78 dirt
fill ~277 ~66 ~78 ~287 ~66 ~78 grass_block
fill ~272 ~60 ~79 ~275 ~63 ~79 stone
fill ~272 ~64 ~79 ~275 ~66 ~79 dirt
fill ~272 ~67 ~79 ~275 ~67 ~79 grass_block
fill ~276 ~60 ~79 ~276 ~62 ~79 stone
fill ~276 ~63 ~79 ~276 ~65 ~79 dirt
fill ~276 ~66 ~79 ~276 ~66 ~79 grass_block
fill ~277 ~60 ~79 ~277 ~63 ~79 stone
fill ~277 ~64 ~79 ~277 ~66 ~79 dirt
fill ~277 ~67 ~79 ~277 ~67 ~79 grass_block
fill ~278 ~60 ~79 ~287 ~62 ~79 stone
fill ~278 ~63 ~79 ~287 ~65 ~79 dirt
fill ~278 ~66 ~79 ~287 ~66 ~79 grass_block