fill ~80 ~60 ~0 ~83 ~65 ~0 stone
fill ~80 ~66 ~0 ~83 ~68 ~0 dirt
fill ~80 ~69 ~0 ~83 ~69 ~0 grass_block
fill ~84 ~60 ~0 ~88 ~64 ~0 stone
fill ~84 ~65 ~0 ~88 ~67 ~0 dirt
fill ~84 ~68 ~0 ~88 ~68 ~0 grass_block
fill ~89 ~60 ~0 ~90 ~63 ~0 stone
fill ~89 ~64 ~0 ~90 ~66 ~0 dirt
fill ~89 ~67 ~0 ~90 ~67 ~0 grass_block
fill ~91 ~60 ~0 ~93 ~64 ~0 stone
fill ~91 ~65 ~0 ~93 ~67 ~0 dirt
fill ~91 ~68 ~0 ~93 ~68 ~0 grass_block
fill ~94 ~60 ~0 ~95 ~65 ~0 stone
fill ~94 ~66 ~0 ~95 ~68 ~0 dirt
fill ~94 ~69 ~0 ~95 ~69 ~0 grass_block
fill ~80 ~60 ~1 ~87 ~65 ~1 stone
fill ~80 ~66 ~1 ~87 ~68 ~1 dirt
fill ~80 ~69 ~1 ~87 ~69 ~1 grass_block
fill ~88 ~60 ~1 ~93 ~64 ~1 stone
fill ~88 ~65 ~1 ~93 ~67 ~1 dirt
fill ~88 ~68 ~1 ~93 ~68 ~1 grass_block
fill ~94 ~60 ~1 ~95 ~65 ~1 stone
fill ~94 ~66 ~1 ~95 ~68 ~1 dirt
fill ~94 ~69 ~1 ~95 ~69 ~1 grass_block
fill ~80 ~60 ~2 ~84 ~66 ~2 stone
fill ~80 ~67 ~2 ~84 ~69 ~2 dirt
fill ~80 ~70 ~2 ~84 ~70 ~2 grass_block
fill ~85 ~60 ~2 ~87 ~65 ~2 stone
fill ~85 ~66 ~2 ~87 ~68 ~2 dirt
fill ~85 ~69 ~2 ~87 ~69 ~2 grass_block
fill ~88 ~60 ~2 ~92 ~64 ~2 stone
fill ~88 ~65 ~2 ~92 ~67 ~2 dirt
fill ~88 ~68 ~2 ~92 ~68 ~2 grass_block
fill ~93 ~60 ~2 ~95 ~65 ~2 stone
fill ~93 ~66 ~2 ~95 ~68 ~2 dirt
fill ~93 ~69 ~2 ~95 ~69 ~2 grass_block
fill ~80 ~60 ~3 ~81 ~67 ~3 stone
fill ~80 ~68 ~3 ~81 ~70 ~3 dirt
fill ~80 ~71 ~3 ~81 ~71 ~3 grass_block
fill ~82 ~60 ~3 ~84 ~66 ~3 stone
fill ~82 ~67 ~3 ~84 ~69 ~3 dirt
fill ~82 ~70 ~3 ~84 ~70 ~3 grass_block
fill ~85 ~60 ~3 ~86 ~65 ~3 stone
fill ~85 ~66 ~3 ~86 ~68 ~3 dirt
fill ~85 ~69 ~3 ~86 ~69 ~3 grass_block
fill ~87 ~60 ~3 ~91 ~64 ~3 stone
fill ~87 ~65 ~3 ~91 ~67 ~3 dirt
fill ~87 ~68 ~3 ~91 ~68 ~3 grass_block
fill ~92 ~60 ~3 ~94 ~65 ~3 stone
fill ~92 ~66 ~3 ~94 ~68 ~3 dirt
fill ~92 ~69 ~3 ~94 ~69 ~3 grass_block
fill ~95 ~60 ~3 ~95 ~66 ~3 stone
fill ~95 ~67 ~3 ~95 ~69 ~3 dirt
fill ~95 ~70 ~3 ~95 ~70 ~3 grass_block
fill ~80 ~60 ~4 ~80 ~68 ~4 stone
fill ~80 ~69 ~4 ~80 ~71 ~4 dirt
fill ~80 ~72 ~4 ~80 ~72 ~4 grass_block
fill ~81 ~60 ~4 ~82 ~67 ~4 stone
fill ~81 ~68 ~4 ~82 ~70 ~4 dirt
fill ~81 ~71 ~4 ~82 ~71 ~4 grass_block
fill ~83 ~60 ~4 ~84 ~66 ~4 stone
fill ~83 ~67 ~4 ~84 ~69 ~4 dirt
fill ~83 ~70 ~4 ~84 ~70 ~4 grass_block
fill ~85 ~60 ~4 ~87 ~65 ~4 stone
fill ~85 ~66 ~4 ~87 ~68 ~4 dirt
fill ~85 ~69 ~4 ~87 ~69 ~4 grass_block
fill ~88 ~60 ~4 ~88 ~64 ~4 stone
fill ~88 ~65 ~4 ~88 ~67 ~4 dirt
fill ~88 ~68 ~4 ~88 ~68 ~4 grass_block
fill ~89 ~60 ~4 ~94 ~65 ~4 stone
fill ~89 ~66 ~4 ~94 ~68 ~4 dirt
fill ~89 ~69 ~4 ~94 ~69 ~4 grass_block
fill ~95 ~60 ~4 ~95 ~66 ~4 stone
fill ~95 ~67 ~4 ~95 ~69 ~4 dirt
fill ~95 ~70 ~4 ~95 ~70 ~4 grass_block
fill ~80 ~60 ~5 ~81 ~68 ~5 stone
fill ~80 ~69 ~5 ~81 ~71 ~5 dirt
fill ~80 ~72 ~5 ~81 ~72 ~5 grass_block
fill ~82 ~60 ~5 ~83 ~67 ~5 stone
fill ~82 ~68 ~5 ~83 ~70 ~5 dirt
fill ~82 ~71 ~5 ~83 ~71 ~5 grass_block
fill ~84 ~60 ~5 ~85 ~66 ~5 stone
fill ~84 ~67 ~5 ~85 ~69 ~5 dirt
fill ~84 ~70 ~5 ~85 ~70 ~5 grass_block
fill ~86 ~60 ~5 ~92 ~65 ~5 stone
fill ~86 ~66 ~5 ~92 ~68 ~5 dirt
fill ~86 ~69 ~5 ~92 ~69 ~5 grass_block
fill ~93 ~60 ~5 ~95 ~66 ~5 stone
fill ~93 ~67 ~5 ~95 ~69 ~5 dirt
fill ~93 ~70 ~5 ~95 ~70 ~5 grass_block
fill ~80 ~60 ~6 ~82 ~68 ~6 stone
fill ~80 ~69 ~6 ~82 ~71 ~6 dirt
fill ~80 ~72 ~6 ~82 ~72 ~6 grass_block
fill ~83 ~60 ~6 ~83 ~67 ~6 stone
fill ~83 ~68 ~6 ~83 ~70 ~6 dirt
fill ~83 ~71 ~6 ~83 ~71 ~6 grass_block
fill ~84 ~60 ~6 ~85 ~66 ~6 stone
fill ~84 ~67 ~6 ~85 ~69 ~6 dirt
fill ~84 ~70 ~6 ~85 ~70 ~6 grass_block
fill ~86 ~60 ~6 ~90 ~65 ~6 stone
fill ~86 ~66 ~6 ~90 ~68 ~6 dirt
fill ~86 ~69 ~6 ~90 ~69 ~6 grass_block
fill ~91 ~60 ~6 ~94 ~66 ~6 stone
fill ~91 ~67 ~6 ~94 ~69 ~6 dirt
fill ~91 ~70 ~6 ~94 ~70 ~6 grass_block
fill ~95 ~60 ~6 ~95 ~67 ~6 stone
fill ~95 ~68 ~6 ~95 ~70 ~6 dirt
fill ~95 ~71 ~6 ~95 ~71 ~6 grass_block
fill ~80 ~60 ~7 ~80 ~69 ~7 stone
fill ~80 ~70 ~7 ~80 ~72 ~7 dirt
fill ~80 ~73 ~7 ~80 ~73 ~7 grass_block
fill ~81 ~60 ~7 ~82 ~68 ~7 stone
fill ~81 ~69 ~7 ~82 ~71 ~7 dirt
fill ~81 ~72 ~7 ~82 ~72 ~7 grass_block
fill ~83 ~60 ~7 ~84 ~67 ~7 stone
fill ~83 ~68 ~7 ~84 ~70 ~7 dirt
fill ~83 ~71 ~7 ~84 ~71 ~7 grass_block
fill ~85 ~60 ~7 ~86 ~66 ~7 stone
fill ~85 ~67 ~7 ~86 ~69 ~7 dirt
fill ~85 ~70 ~7 ~86 ~70 ~7 grass_block
fill ~87 ~60 ~7 ~88 ~65 ~7 stone
fill ~87 ~66 ~7 ~88 ~68 ~7 dirt
fill ~87 ~69 ~7 ~88 ~69 ~7 grass_block
fill ~89 ~60 ~7 ~92 ~66 ~7 stone
fill ~89 ~67 ~7 ~92 ~69 ~7 dirt
fill ~89 ~70 ~7 ~92 ~70 ~7 grass_block
fill ~93 ~60 ~7 ~95 ~67 ~7 stone
fill ~93 ~68 ~7 ~95 ~70 ~7 dirt
fill ~93 ~71 ~7 ~95 ~71 ~7 grass_block
fill ~80 ~60 ~8 ~81 ~69 ~8 stone
fill ~80 ~70 ~8 ~81 ~72 ~8 dirt
fill ~80 ~73 ~8 ~81 ~73 ~8 grass_block
fill ~82 ~60 ~8 ~82 ~68 ~8 stone
fill ~82 ~69 ~8 ~82 ~71 ~8 dirt
fill ~82 ~72 ~8 ~82 ~72 ~8 grass_block
fill ~83 ~60 ~8 ~84 ~67 ~8 stone
fill ~83 ~68 ~8 ~84 ~70 ~8 dirt
fill ~83 ~71 ~8 ~84 ~71 ~8 grass_block
fill ~85 ~60 ~8 ~86 ~66 ~8 stone
fill ~85 ~67 ~8 ~86 ~69 ~8 dirt
fill ~85 ~70 ~8 ~86 ~70 ~8 grass_block
fill ~87 ~60 ~8 ~87 ~65 ~8 stone
fill ~87 ~66 ~8 ~87 ~68 ~8 dirt
fill ~87 ~69 ~8 ~87 ~69 ~8 grass_block
fill ~88 ~60 ~8 ~91 ~66 ~8 stone
fill ~88 ~67 ~8 ~91 ~69 ~8 dirt
fill ~88 ~70 ~8 ~91 ~70 ~8 grass_block
fill ~92 ~60 ~8 ~93 ~67 ~8 stone
fill ~92 ~68 ~8 ~93 ~70 ~8 dirt
fill ~92 ~71 ~8 ~93 ~71 ~8 grass_block
fill ~94 ~60 ~8 ~95 ~68 ~8 stone
fill ~94 ~69 ~8 ~95 ~71 ~8 dirt
fill ~94 ~72 ~8 ~95 ~72 ~8 grass_block
fill ~80 ~60 ~9 ~82 ~69 ~9 stone
fill ~80 ~70 ~9 ~82 ~72 ~9 dirt
fill ~80 ~73 ~9 ~82 ~73 ~9 grass_block
fill ~83 ~60 ~9 ~83 ~68 ~9 stone
fill ~83 ~69 ~9 ~83 ~71 ~9 dirt
fill ~83 ~72 ~9 ~83 ~72 ~9 grass_block
fill ~84 ~60 ~9 ~85 ~67 ~9 stone
fill ~84 ~68 ~9 ~85 ~70 ~9 dirt
fill ~84 ~71 ~9 ~85 ~71 ~9 grass_block
fill ~86 ~60 ~9 ~89 ~66 ~9 stone
fill ~86 ~67 ~9 ~89 ~69 ~9 dirt
fill ~86 ~70 ~9 ~89 ~70 ~9 grass_block
fill ~90 ~60 ~9 ~92 ~67 ~9 stone
fill ~90 ~68 ~9 ~92 ~70 ~9 dirt
fill ~90 ~71 ~9 ~92 ~71 ~9 grass_block
fill ~93 ~60 ~9 ~95 ~68 ~9 stone
fill ~93 ~69 ~9 ~95 ~71 ~9 dirt
fill ~93 ~72 ~9 ~95 ~72 ~9 grass_block
fill ~80 ~60 ~10 ~82 ~69 ~10 stone
fill ~80 ~70 ~10 ~82 ~72 ~10 dirt
fill ~80 ~73 ~10 ~82 ~73 ~10 grass_block
fill ~83 ~60 ~10 ~84 ~68 ~10 stone
fill ~83 ~69 ~10 ~84 ~71 ~10 dirt
fill ~83 ~72 ~10 ~84 ~72 ~10 grass_block
fill ~85 ~60 ~10 ~86 ~67 ~10 stone
fill ~85 ~68 ~10 ~86 ~70 ~10 dirt
fill ~85 ~71 ~10 ~86 ~71 ~10 grass_block
fill ~87 ~60 ~10 ~88 ~66 ~10 stone
fill ~87 ~67 ~10 ~88 ~69 ~10 dirt
fill ~87 ~70 ~10 ~88 ~70 ~10 grass_block
fill ~89 ~60 ~10 ~89 ~67 ~10 stone
fill ~89 ~68 ~10 ~89 ~70 ~10 dirt
fill ~89 ~71 ~10 ~89 ~71 ~10 grass_block
fill ~90 ~60 ~10 ~92 ~68 ~10 stone
fill ~90 ~69 ~10 ~92 ~71 ~10 dirt
fill ~90 ~72 ~10 ~92 ~72 ~10 grass_block
fill ~93 ~60 ~10 ~95 ~69 ~10 stone
fill ~93 ~70 ~10 ~95 ~72 ~10 dirt
fill ~93 ~73 ~10 ~95 ~73 ~10 grass_block
fill ~80 ~60 ~11 ~83 ~69 ~11 stone
fill ~80 ~70 ~11 ~83 ~72 ~11 dirt
fill ~80 ~73 ~11 ~83 ~73 ~11 grass_block
fill ~84 ~60 ~11 ~85 ~68 ~11 stone
fill ~84 ~69 ~11 ~85 ~71 ~11 dirt
fill ~84 ~72 ~11 ~85 ~72 ~11 grass_block
fill ~86 ~60 ~11 ~87 ~67 ~11 stone
fill ~86 ~68 ~11 ~87 ~70 ~11 dirt
fill ~86 ~71 ~11 ~87 ~71 ~11 grass_block
fill ~88 ~60 ~11 ~88 ~66 ~11 stone
fill ~88 ~67 ~11 ~88 ~69 ~11 dirt
fill ~88 ~70 ~11 ~88 ~70 ~11 grass_block
fill ~89 ~60 ~11 ~89 ~67 ~11 stone
fill ~89 ~68 ~11 ~89 ~70 ~11 dirt
fill ~89 ~71 ~11 ~89 ~71 ~11 grass_block
fill ~90 ~60 ~11 ~91 ~68 ~11 stone
fill ~90 ~69 ~11 ~91 ~71 ~11 dirt
fill ~90 ~72 ~11 ~91 ~72 ~11 grass_block
fill ~92 ~60 ~11 ~95 ~69 ~11 stone
fill ~92 ~70 ~11 ~95 ~72 ~11 dirt
fill ~92 ~73 ~11 ~95 ~73 ~11 grass_block
fill ~80 ~60 ~12 ~83 ~69 ~12 stone
fill ~80 ~70 ~12 ~83 ~72 ~12 dirt
fill ~80 ~73 ~12 ~83 ~73 ~12 grass_block
fill ~84 ~60 ~12 ~86 ~68 ~12 stone
fill ~84 ~69 ~12 ~86 ~71 ~12 dirt
fill ~84 ~72 ~12 ~86 ~72 ~12 grass_block
fill ~87 ~60 ~12 ~89 ~67 ~12 stone
fill ~87 ~68 ~12 ~89 ~70 ~12 dirt
fill ~87 ~71 ~12 ~89 ~71 ~12 grass_block
fill ~90 ~60 ~12 ~91 ~68 ~12 stone
fill ~90 ~69 ~12 ~91 ~71 ~12 dirt
fill ~90 ~72 ~12 ~91 ~72 ~12 grass_block
fill ~92 ~60 ~12 ~95 ~69 ~12 stone
fill ~92 ~70 ~12 ~95 ~72 ~12 dirt
fill ~92 ~73 ~12 ~95 ~73 ~12 grass_block
fill ~80 ~60 ~13 ~84 ~69 ~13 stone
fill ~80 ~70 ~13 ~84 ~72 ~13 dirt
fill ~80 ~73 ~13 ~84 ~73 ~13 grass_block
fill ~85 ~60 ~13 ~87 ~68 ~13 stone
fill ~85 ~69 ~13 ~87 ~71 ~13 dirt
fill ~85 ~72 ~13 ~87 ~72 ~13 grass_block
fill ~88 ~60 ~13 ~89 ~67 ~13 stone
fill ~88 ~68 ~13 ~89 ~70 ~13 dirt
fill ~88 ~71 ~13 ~89 ~71 ~13 grass_block
fill ~90 ~60 ~13 ~92 ~68 ~13 stone
fill ~90 ~69 ~13 ~92 ~71 ~13 dirt
fill ~90 ~72 ~13 ~92 ~72 ~13 grass_block
fill ~93 ~60 ~13 ~95 ~69 ~13 stone
fill ~93 ~70 ~13 ~95 ~72 ~13 dirt
fill ~93 ~73 ~13 ~95 ~73 ~13 grass_block
fill ~80 ~60 ~14 ~85 ~69 ~14 stone
fill ~80 ~70 ~14 ~85 ~72 ~14 dirt
fill ~80 ~73 ~14 ~85 ~73 ~14 grass_block
fill ~86 ~60 ~14 ~88 ~68 ~14 stone
fill ~86 ~69 ~14 ~88 ~71 ~14 dirt
fill ~86 ~72 ~14 ~88 ~72 ~14 grass_block
fill ~89 ~60 ~14 ~89 ~67 ~14 stone
fill ~89 ~68 ~14 ~89 ~70 ~14 dirt
fill ~89 ~71 ~14 ~89 ~71 ~14 grass_block
fill ~90 ~60 ~14 ~92 ~68 ~14 stone
fill ~90 ~69 ~14 ~92 ~71 ~14 dirt
fill ~90 ~72 ~14 ~92 ~72 ~14 grass_block
fill ~93 ~60 ~14 ~95 ~69 ~14 stone
fill ~93 ~70 ~14 ~95 ~72 ~14 dirt
fill ~93 ~73 ~14 ~95 ~73 ~14 grass_block
fill ~80 ~60 ~15 ~81 ~68 ~15 stone
fill ~80 ~69 ~15 ~81 ~71 ~15 dirt
fill ~80 ~72 ~15 ~81 ~72 ~15 grass_block
fill ~82 ~60 ~15 ~86 ~69 ~15 stone
fill ~82 ~70 ~15 ~86 ~72 ~15 dirt
fill ~82 ~73 ~15 ~86 ~73 ~15 grass_block
fill ~87 ~60 ~15 ~92 ~68 ~15 stone
fill ~87 ~69 ~15 ~92 ~71 ~15 dirt
fill ~87 ~72 ~15 ~92 ~72 ~15 grass_block
fill ~93 ~60 ~15 ~95 ~69 ~15 stone
fill ~93 ~70 ~15 ~95 ~72 ~15 dirt
fill ~93 ~73 ~15 ~95 ~73 ~15 grass_block