fill ~352 ~60 ~32 ~354 ~63 ~32 stone
fill ~352 ~64 ~32 ~354 ~66 ~32 dirt
fill ~352 ~67 ~32 ~354 ~67 ~32 grass_block
fill ~355 ~60 ~32 ~356 ~64 ~32 stone
fill ~355 ~65 ~32 ~356 ~67 ~32 dirt
fill ~355 ~68 ~32 ~356 ~68 ~32 grass_block
fill ~357 ~60 ~32 ~359 ~65 ~32 stone
fill ~357 ~66 ~32 ~359 ~68 ~32 dirt
fill ~357 ~69 ~32 ~359 ~69 ~32 grass_block
fill ~360 ~60 ~32 ~366 ~66 ~32 stone
fill ~360 ~67 ~32 ~366 ~69 ~32 dirt
fill ~360 ~70 ~32 ~366 ~70 ~32 grass_block
fill ~367 ~60 ~32 ~367 ~65 ~32 stone
fill ~367 ~66 ~32 ~367 ~68 ~32 dirt
fill ~367 ~69 ~32 ~367 ~69 ~32 grass_block
fill ~352 ~60 ~33 ~354 ~63 ~33 stone
fill ~352 ~64 ~33 ~354 ~66 ~33 dirt
fill ~352 ~67 ~33 ~354 ~67 ~33 grass_block
fill ~355 ~60 ~33 ~359 ~64 ~33 stone
fill ~355 ~65 ~33 ~359 ~67 ~33 dirt
fill ~355 ~68 ~33 ~359 ~68 ~33 grass_block
fill ~360 ~60 ~33 ~361 ~65 ~33 stone
fill ~360 ~66 ~33 ~361 ~68 ~33 dirt
fill ~360 ~69 ~33 ~361 ~69 ~33 grass_block
fill ~362 ~60 ~33 ~366 ~66 ~33 stone
fill ~362 ~67 ~33 ~366 ~69 ~33 dirt
fill ~362 ~70 ~33 ~366 ~70 ~33 grass_block
fill ~367 ~60 ~33 ~367 ~65 ~33 stone
fill ~367 ~66 ~33 ~367 ~68 ~33 dirt
fill ~367 ~69 ~33 ~367 ~69 ~33 grass_block
fill ~352 ~60 ~34 ~354 ~63 ~34 stone
fill ~352 ~64 ~34 ~354 ~66 ~34 dirt
fill ~352 ~67 ~34 ~354 ~67 ~34 grass_block
fill ~355 ~60 ~34 ~358 ~64 ~34 stone
fill ~355 ~65 ~34 ~358 ~67 ~34 dirt
fill ~355 ~68 ~34 ~358 ~68 ~34 grass_block
fill ~359 ~60 ~34 ~367 ~65 ~34 stone
fill ~359 ~66 ~34 ~367 ~68 ~34 dirt
fill ~359 ~69 ~34 ~367 ~69 ~34 grass_block
fill ~352 ~60 ~35 ~356 ~64 ~35 stone
fill ~352 ~65 ~35 ~356 ~67 ~35 dirt
fill ~352 ~68 ~35 ~356 ~68 ~35 grass_block
fill ~357 ~60 ~35 ~367 ~65 ~35 stone
fill ~357 ~66 ~35 ~367 ~68 ~35 dirt
fill ~357 ~69 ~35 ~367 ~69 ~35 grass_block
fill ~352 ~60 ~36 ~355 ~64 ~36 stone
fill ~352 ~65 ~36 ~355 ~67 ~36 dirt
fill ~352 ~68 ~36 ~355 ~68 ~36 grass_block
fill ~356 ~60 ~36 ~357 ~65 ~36 stone
fill ~356 ~66 ~36 ~357 ~68 ~36 dirt
fill ~356 ~69 ~36 ~357 ~69 ~36 grass_block
fill ~358 ~60 ~36 ~362 ~66 ~36 stone
fill ~358 ~67 ~36 ~362 ~69 ~36 dirt
fill ~358 ~70 ~36 ~362 ~70 ~36 grass_block
fill ~363 ~60 ~36 ~367 ~65 ~36 stone
fill ~363 ~66 ~36 ~367 ~68 ~36 dirt
fill ~363 ~69 ~36 ~367 ~69 ~36 grass_block
fill ~352 ~60 ~37 ~357 ~65 ~37 stone
fill ~352 ~66 ~37 ~357 ~68 ~37 dirt
fill ~352 ~69 ~37 ~357 ~69 ~37 grass_block
fill ~358 ~60 ~37 ~363 ~66 ~37 stone
fill ~358 ~67 ~37 ~363 ~69 ~37 dirt
fill ~358 ~70 ~37 ~363 ~70 ~37 grass_block
fill ~364 ~60 ~37 ~367 ~65 ~37 stone
fill ~364 ~66 ~37 ~367 ~68 ~37 dirt
fill ~364 ~69 ~37 ~367 ~69 ~37 grass_block
fill ~352 ~60 ~38 ~355 ~65 ~38 stone
fill ~352 ~66 ~38 ~355 ~68 ~38 dirt
fill ~352 ~69 ~38 ~355 ~69 ~38 grass_block
fill ~356 ~60 ~38 ~363 ~66 ~38 stone
fill ~356 ~67 ~38 ~363 ~69 ~38 dirt
fill ~356 ~70 ~38 ~363 ~70 ~38 grass_block
fill ~364 ~60 ~38 ~367 ~65 ~38 stone
fill ~364 ~66 ~38 ~367 ~68 ~38 dirt
fill ~364 ~69 ~38 ~367 ~69 ~38 grass_block
fill ~352 ~60 ~39 ~353 ~65 ~39 stone
fill ~352 ~66 ~39 ~353 ~68 ~39 dirt
fill ~352 ~69 ~39 ~353 ~69 ~39 grass_block
fill ~354 ~60 ~39 ~357 ~66 ~39 stone
fill ~354 ~67 ~39 ~357 ~69 ~39 dirt
fill ~354 ~70 ~39 ~357 ~70 ~39 grass_block
fill ~358 ~60 ~39 ~358 ~67 ~39 stone
fill ~358 ~68 ~39 ~358 ~70 ~39 dirt
fill ~358 ~71 ~39 ~358 ~71 ~39 grass_block
fill ~359 ~60 ~39 ~364 ~66 ~39 stone
fill ~359 ~67 ~39 ~364 ~69 ~39 dirt
fill ~359 ~70 ~39 ~364 ~70 ~39 grass_block
fill ~365 ~60 ~39 ~367 ~65 ~39 stone
fill ~365 ~66 ~39 ~367 ~68 ~39 dirt
fill ~365 ~69 ~39 ~367 ~69 ~39 grass_block
fill ~352 ~60 ~40 ~354 ~65 ~40 stone
fill ~352 ~66 ~40 ~354 ~68 ~40 dirt
fill ~352 ~69 ~40 ~354 ~69 ~40 grass_block
fill ~355 ~60 ~40 ~357 ~66 ~40 stone
fill ~355 ~67 ~40 ~357 ~69 ~40 dirt
fill ~355 ~70 ~40 ~357 ~70 ~40 grass_block
fill ~358 ~60 ~40 ~360 ~67 ~40 stone
fill ~358 ~68 ~40 ~360 ~70 ~40 dirt
fill ~358 ~71 ~40 ~360 ~71 ~40 grass_block
fill ~361 ~60 ~40 ~364 ~66 ~40 stone
fill ~361 ~67 ~40 ~364 ~69 ~40 dirt
fill ~361 ~70 ~40 ~364 ~70 ~40 grass_block
fill ~365 ~60 ~40 ~367 ~65 ~40 stone
fill ~365 ~66 ~40 ~367 ~68 ~40 dirt
fill ~365 ~69 ~40 ~367 ~69 ~40 grass_block
fill ~352 ~60 ~41 ~354 ~65 ~41 stone
fill ~352 ~66 ~41 ~354 ~68 ~41 dirt
fill ~352 ~69 ~41 ~354 ~69 ~41 grass_block
fill ~355 ~60 ~41 ~357 ~66 ~41 stone
fill ~355 ~67 ~41 ~357 ~69 ~41 dirt
fill ~355 ~70 ~41 ~357 ~70 ~41 grass_block
fill ~358 ~60 ~41 ~360 ~67 ~41 stone
fill ~358 ~68 ~41 ~360 ~70 ~41 dirt
fill ~358 ~71 ~41 ~360 ~71 ~41 grass_block
fill ~361 ~60 ~41 ~365 ~66 ~41 stone
fill ~361 ~67 ~41 ~365 ~69 ~41 dirt
fill ~361 ~70 ~41 ~365 ~70 ~41 grass_block
fill ~366 ~60 ~41 ~367 ~65 ~41 stone
fill ~366 ~66 ~41 ~367 ~68 ~41 dirt
fill ~366 ~69 ~41 ~367 ~69 ~41 grass_block
fill ~352 ~60 ~42 ~354 ~65 ~42 stone
fill ~352 ~66 ~42 ~354 ~68 ~42 dirt
fill ~352 ~69 ~42 ~354 ~69 ~42 grass_block
fill ~355 ~60 ~42 ~358 ~66 ~42 stone
fill ~355 ~67 ~42 ~358 ~69 ~42 dirt
fill ~355 ~70 ~42 ~358 ~70 ~42 grass_block
fill ~359 ~60 ~42 ~359 ~67 ~42 stone
fill ~359 ~68 ~42 ~359 ~70 ~42 dirt
fill ~359 ~71 ~42 ~359 ~71 ~42 grass_block
fill ~360 ~60 ~42 ~360 ~66 ~42 stone
fill ~360 ~67 ~42 ~360 ~69 ~42 dirt
fill ~360 ~70 ~42 ~360 ~70 ~42 grass_block
fill ~361 ~60 ~42 ~361 ~67 ~42 stone
fill ~361 ~68 ~42 ~361 ~70 ~42 dirt
fill ~361 ~71 ~42 ~361 ~71 ~42 grass_block
fill ~362 ~60 ~42 ~365 ~66 ~42 stone
fill ~362 ~67 ~42 ~365 ~69 ~42 dirt
fill ~362 ~70 ~42 ~365 ~70 ~42 grass_block
fill ~366 ~60 ~42 ~367 ~65 ~42 stone
fill ~366 ~66 ~42 ~367 ~68 ~42 dirt
fill ~366 ~69 ~42 ~367 ~69 ~42 grass_block
fill ~352 ~60 ~43 ~354 ~65 ~43 stone
fill ~352 ~66 ~43 ~354 ~68 ~43 dirt
fill ~352 ~69 ~43 ~354 ~69 ~43 grass_block
fill ~355 ~60 ~43 ~360 ~66 ~43 stone
fill ~355 ~67 ~43 ~360 ~69 ~43 dirt
fill ~355 ~70 ~43 ~360 ~70 ~43 grass_block
fill ~361 ~60 ~43 ~361 ~67 ~43 stone
fill ~361 ~68 ~43 ~361 ~70 ~43 dirt
fill ~361 ~71 ~43 ~361 ~71 ~43 grass_block
fill ~362 ~60 ~43 ~366 ~66 ~43 stone
fill ~362 ~67 ~43 ~366 ~69 ~43 dirt
fill ~362 ~70 ~43 ~366 ~70 ~43 grass_block
fill ~367 ~60 ~43 ~367 ~65 ~43 stone
fill ~367 ~66 ~43 ~367 ~68 ~43 dirt
fill ~367 ~69 ~43 ~367 ~69 ~43 grass_block
fill ~352 ~60 ~44 ~354 ~65 ~44 stone
fill ~352 ~66 ~44 ~354 ~68 ~44 dirt
fill ~352 ~69 ~44 ~354 ~69 ~44 grass_block
fill ~355 ~60 ~44 ~367 ~66 ~44 stone
fill ~355 ~67 ~44 ~367 ~69 ~44 dirt
fill ~355 ~70 ~44 ~367 ~70 ~44 grass_block
fill ~352 ~60 ~45 ~356 ~65 ~45 stone
fill ~352 ~66 ~45 ~356 ~68 ~45 dirt
fill ~352 ~69 ~45 ~356 ~69 ~45 grass_block
fill ~357 ~60 ~45 ~367 ~66 ~45 stone
fill ~357 ~67 ~45 ~367 ~69 ~45 dirt
fill ~357 ~70 ~45 ~367 ~70 ~45 grass_block
fill ~352 ~60 ~46 ~357 ~65 ~46 stone
fill ~352 ~66 ~46 ~357 ~68 ~46 dirt
fill ~352 ~69 ~46 ~357 ~69 ~46 grass_block
fill ~358 ~60 ~46 ~367 ~66 ~46 stone
fill ~358 ~67 ~46 ~367 ~69 ~46 dirt
fill ~358 ~70 ~46 ~367 ~70 ~46 grass_block
fill ~352 ~60 ~47 ~358 ~65 ~47 stone
fill ~352 ~66 ~47 ~358 ~68 ~47 dirt
fill ~352 ~69 ~47 ~358 ~69 ~47 grass_block
fill ~359 ~60 ~47 ~367 ~66 ~47 stone
fill ~359 ~67 ~47 ~367 ~69 ~47 dirt
fill ~359 ~70 ~47 ~367 ~70 ~47 grass_block