fill ~336 ~60 ~128 ~341 ~63 ~128 stone
fill ~336 ~64 ~128 ~341 ~66 ~128 dirt
fill ~336 ~67 ~128 ~341 ~67 ~128 grass_block
fill ~342 ~60 ~128 ~345 ~62 ~128 stone
fill ~342 ~63 ~128 ~345 ~65 ~128 dirt
fill ~342 ~66 ~128 ~345 ~66 ~128 grass_block
fill ~346 ~60 ~128 ~351 ~61 ~128 stone
fill ~346 ~62 ~128 ~351 ~64 ~128 dirt
fill ~346 ~65 ~128 ~351 ~65 ~128 grass_block
fill ~336 ~60 ~129 ~341 ~63 ~129 stone
fill ~336 ~64 ~129 ~341 ~66 ~129 dirt
fill ~336 ~67 ~129 ~341 ~67 ~129 grass_block
fill ~342 ~60 ~129 ~345 ~62 ~129 stone
fill ~342 ~63 ~129 ~345 ~65 ~129 dirt
fill ~342 ~66 ~129 ~345 ~66 ~129 grass_block
fill ~346 ~60 ~129 ~351 ~61 ~129 stone
fill ~346 ~62 ~129 ~351 ~64 ~129 dirt
fill ~346 ~65 ~129 ~351 ~65 ~129 grass_block
fill ~336 ~60 ~130 ~342 ~63 ~130 stone
fill ~336 ~64 ~130 ~342 ~66 ~130 dirt
fill ~336 ~67 ~130 ~342 ~67 ~130 grass_block
fill ~343 ~60 ~130 ~346 ~62 ~130 stone
fill ~343 ~63 ~130 ~346 ~65 ~130 dirt
fill ~343 ~66 ~130 ~346 ~66 ~130 grass_block
fill ~347 ~60 ~130 ~351 ~61 ~130 stone
fill ~347 ~62 ~130 ~351 ~64 ~130 dirt
fill ~347 ~65 ~130 ~351 ~65 ~130 grass_block
fill ~336 ~60 ~131 ~343 ~63 ~131 stone
fill ~336 ~64 ~131 ~343 ~66 ~131 dirt
fill ~336 ~67 ~131 ~343 ~67 ~131 grass_block
fill ~344 ~60 ~131 ~348 ~62 ~131 stone
fill ~344 ~63 ~131 ~348 ~65 ~131 dirt
fill ~344 ~66 ~131 ~348 ~66 ~131 grass_block
fill ~349 ~60 ~131 ~351 ~61 ~131 stone
fill ~349 ~62 ~131 ~351 ~64 ~131 dirt
fill ~349 ~65 ~131 ~351 ~65 ~131 grass_block
fill ~336 ~60 ~132 ~344 ~63 ~132 stone
fill ~336 ~64 ~132 ~344 ~66 ~132 dirt
fill ~336 ~67 ~132 ~344 ~67 ~132 grass_block
fill ~345 ~60 ~132 ~349 ~62 ~132 stone
fill ~345 ~63 ~132 ~349 ~65 ~132 dirt
fill ~345 ~66 ~132 ~349 ~66 ~132 grass_block
fill ~350 ~60 ~132 ~351 ~61 ~132 stone
fill ~350 ~62 ~132 ~351 ~64 ~132 dirt
fill ~350 ~65 ~132 ~351 ~65 ~132 grass_block
fill ~336 ~60 ~133 ~345 ~63 ~133 stone
fill ~336 ~64 ~133 ~345 ~66 ~133 dirt
fill ~336 ~67 ~133 ~345 ~67 ~133 grass_block
fill ~346 ~60 ~133 ~350 ~62 ~133 stone
fill ~346 ~63 ~133 ~350 ~65 ~133 dirt
fill ~346 ~66 ~133 ~350 ~66 ~133 grass_block
fill ~351 ~60 ~133 ~351 ~61 ~133 stone
fill ~351 ~62 ~133 ~351 ~64 ~133 dirt
fill ~351 ~65 ~133 ~351 ~65 ~133 grass_block
fill ~336 ~60 ~134 ~347 ~63 ~134 stone
fill ~336 ~64 ~134 ~347 ~66 ~134 dirt
fill ~336 ~67 ~134 ~347 ~67 ~134 grass_block
fill ~348 ~60 ~134 ~351 ~62 ~134 stone
fill ~348 ~63 ~134 ~351 ~65 ~134 dirt
fill ~348 ~66 ~134 ~351 ~66 ~134 grass_block
fill ~336 ~60 ~135 ~348 ~63 ~135 stone
fill ~336 ~64 ~135 ~348 ~66 ~135 dirt
fill ~336 ~67 ~135 ~348 ~67 ~135 grass_block
fill ~349 ~60 ~135 ~351 ~62 ~135 stone
fill ~349 ~63 ~135 ~351 ~65 ~135 dirt
fill ~349 ~66 ~135 ~351 ~66 ~135 grass_block
fill ~336 ~60 ~136 ~351 ~63 ~136 stone
fill ~336 ~64 ~136 ~351 ~66 ~136 dirt
fill ~336 ~67 ~136 ~351 ~67 ~136 grass_block
fill ~336 ~60 ~137 ~347 ~63 ~137 stone
fill ~336 ~64 ~137 ~347 ~66 ~137 dirt
fill ~336 ~67 ~137 ~347 ~67 ~137 grass_block
fill ~348 ~60 ~137 ~348 ~62 ~137 stone
fill ~348 ~63 ~137 ~348 ~65 ~137 dirt
fill ~348 ~66 ~137 ~348 ~66 ~137 grass_block
fill ~349 ~60 ~137 ~350 ~63 ~137 stone
fill ~349 ~64 ~137 ~350 ~66 ~137 dirt
fill ~349 ~67 ~137 ~350 ~67 ~137 grass_block
fill ~351 ~60 ~137 ~351 ~62 ~137 stone
fill ~351 ~63 ~137 ~351 ~65 ~137 dirt
fill ~351 ~66 ~137 ~351 ~66 ~137 grass_block
fill ~336 ~60 ~138 ~348 ~63 ~138 stone
fill ~336 ~64 ~138 ~348 ~66 ~138 dirt
fill ~336 ~67 ~138 ~348 ~67 ~138 grass_block
fill ~349 ~60 ~138 ~350 ~62 ~138 stone
fill ~349 ~63 ~138 ~350 ~65 ~138 dirt
fill ~349 ~66 ~138 ~350 ~66 ~138 grass_block
fill ~351 ~60 ~138 ~351 ~63 ~138 stone
fill ~351 ~64 ~138 ~351 ~66 ~138 dirt
fill ~351 ~67 ~138 ~351 ~67 ~138 grass_block
fill ~336 ~60 ~139 ~340 ~63 ~139 stone
fill ~336 ~64 ~139 ~340 ~66 ~139 dirt
fill ~336 ~67 ~139 ~340 ~67 ~139 grass_block
fill ~341 ~60 ~139 ~341 ~62 ~139 stone
fill ~341 ~63 ~139 ~341 ~65 ~139 dirt
fill ~341 ~66 ~139 ~341 ~66 ~139 grass_block
fill ~342 ~60 ~139 ~349 ~63 ~139 stone
fill ~342 ~64 ~139 ~349 ~66 ~139 dirt
fill ~342 ~67 ~139 ~349 ~67 ~139 grass_block
fill ~350 ~60 ~139 ~350 ~62 ~139 stone
fill ~350 ~63 ~139 ~350 ~65 ~139 dirt
fill ~350 ~66 ~139 ~350 ~66 ~139 grass_block
fill ~351 ~60 ~139 ~351 ~63 ~139 stone
fill ~351 ~64 ~139 ~351 ~66 ~139 dirt
fill ~351 ~67 ~139 ~351 ~67 ~139 grass_block
fill ~336 ~60 ~140 ~351 ~63 ~140 stone
fill ~336 ~64 ~140 ~351 ~66 ~140 dirt
fill ~336 ~67 ~140 ~351 ~67 ~140 grass_block
fill ~336 ~60 ~141 ~347 ~63 ~141 stone
fill ~336 ~64 ~141 ~347 ~66 ~141 dirt
fill ~336 ~67 ~141 ~347 ~67 ~141 grass_block
fill ~348 ~60 ~141 ~348 ~62 ~141 stone
fill ~348 ~63 ~141 ~348 ~65 ~141 dirt
fill ~348 ~66 ~141 ~348 ~66 ~141 grass_block
fill ~349 ~60 ~141 ~350 ~63 ~141 stone
fill ~349 ~64 ~141 ~350 ~66 ~141 dirt
fill ~349 ~67 ~141 ~350 ~67 ~141 grass_block
fill ~351 ~60 ~141 ~351 ~62 ~141 stone
fill ~351 ~63 ~141 ~351 ~65 ~141 dirt
fill ~351 ~66 ~141 ~351 ~66 ~141 grass_block
fill ~336 ~60 ~142 ~350 ~63 ~142 stone
fill ~336 ~64 ~142 ~350 ~66 ~142 dirt
fill ~336 ~67 ~142 ~350 ~67 ~142 grass_block
fill ~351 ~60 ~142 ~351 ~62 ~142 stone
fill ~351 ~63 ~142 ~351 ~65 ~142 dirt
fill ~351 ~66 ~142 ~351 ~66 ~142 grass_block
fill ~336 ~60 ~143 ~350 ~63 ~143 stone
fill ~336 ~64 ~143 ~350 ~66 ~143 dirt
fill ~336 ~67 ~143 ~350 ~67 ~143 grass_block
fill ~351 ~60 ~143 ~351 ~62 ~143 stone
fill ~351 ~63 ~143 ~351 ~65 ~143 dirt
fill ~351 ~66 ~143 ~351 ~66 ~143 grass_block