fill ~48 ~60 ~128 ~63 ~64 ~128 stone
fill ~48 ~65 ~128 ~63 ~67 ~128 dirt
fill ~48 ~68 ~128 ~63 ~68 ~128 grass_block
fill ~48 ~60 ~129 ~59 ~64 ~129 stone
fill ~48 ~65 ~129 ~59 ~67 ~129 dirt
fill ~48 ~68 ~129 ~59 ~68 ~129 grass_block
fill ~60 ~60 ~129 ~62 ~63 ~129 stone
fill ~60 ~64 ~129 ~62 ~66 ~129 dirt
fill ~60 ~67 ~129 ~62 ~67 ~129 grass_block
fill ~63 ~60 ~129 ~63 ~64 ~129 stone
fill ~63 ~65 ~129 ~63 ~67 ~129 dirt
fill ~63 ~68 ~129 ~63 ~68 ~129 grass_block
fill ~48 ~60 ~130 ~56 ~64 ~130 stone
fill ~48 ~65 ~130 ~56 ~67 ~130 dirt
fill ~48 ~68 ~130 ~56 ~68 ~130 grass_block
fill ~57 ~60 ~130 ~63 ~63 ~130 stone
fill ~57 ~64 ~130 ~63 ~66 ~130 dirt
fill ~57 ~67 ~130 ~63 ~67 ~130 grass_block
fill ~48 ~60 ~131 ~58 ~64 ~131 stone
fill ~48 ~65 ~131 ~58 ~67 ~131 dirt
fill ~48 ~68 ~131 ~58 ~68 ~131 grass_block
fill ~59 ~60 ~131 ~63 ~63 ~131 stone
fill ~59 ~64 ~131 ~63 ~66 ~131 dirt
fill ~59 ~67 ~131 ~63 ~67 ~131 grass_block
fill ~48 ~60 ~132 ~51 ~64 ~132 stone
fill ~48 ~65 ~132 ~51 ~67 ~132 dirt
fill ~48 ~68 ~132 ~51 ~68 ~132 grass_block
fill ~52 ~60 ~132 ~58 ~65 ~132 stone
fill ~52 ~66 ~132 ~58 ~68 ~132 dirt
fill ~52 ~69 ~132 ~58 ~69 ~132 grass_block
fill ~59 ~60 ~132 ~63 ~64 ~132 stone
fill ~59 ~65 ~132 ~63 ~67 ~132 dirt
fill ~59 ~68 ~132 ~63 ~68 ~132 grass_block
fill ~48 ~60 ~133 ~52 ~65 ~133 stone
fill ~48 ~66 ~133 ~52 ~68 ~133 dirt
fill ~48 ~69 ~133 ~52 ~69 ~133 grass_block
fill ~53 ~60 ~133 ~55 ~66 ~133 stone
fill ~53 ~67 ~133 ~55 ~69 ~133 dirt
fill ~53 ~70 ~133 ~55 ~70 ~133 grass_block
fill ~56 ~60 ~133 ~58 ~65 ~133 stone
fill ~56 ~66 ~133 ~58 ~68 ~133 dirt
fill ~56 ~69 ~133 ~58 ~69 ~133 grass_block
fill ~59 ~60 ~133 ~63 ~64 ~133 stone
fill ~59 ~65 ~133 ~63 ~67 ~133 dirt
fill ~59 ~68 ~133 ~63 ~68 ~133 grass_block
fill ~48 ~60 ~134 ~54 ~66 ~134 stone
fill ~48 ~67 ~134 ~54 ~69 ~134 dirt
fill ~48 ~70 ~134 ~54 ~70 ~134 grass_block
fill ~55 ~60 ~134 ~57 ~65 ~134 stone
fill ~55 ~66 ~134 ~57 ~68 ~134 dirt
fill ~55 ~69 ~134 ~57 ~69 ~134 grass_block
fill ~58 ~60 ~134 ~61 ~64 ~134 stone
fill ~58 ~65 ~134 ~61 ~67 ~134 dirt
fill ~58 ~68 ~134 ~61 ~68 ~134 grass_block
fill ~62 ~60 ~134 ~63 ~65 ~134 stone
fill ~62 ~66 ~134 ~63 ~68 ~134 dirt
fill ~62 ~69 ~134 ~63 ~69 ~134 grass_block
fill ~48 ~60 ~135 ~48 ~67 ~135 stone
fill ~48 ~68 ~135 ~48 ~70 ~135 dirt
fill ~48 ~71 ~135 ~48 ~71 ~135 grass_block
fill ~49 ~60 ~135 ~52 ~66 ~135 stone
fill ~49 ~67 ~135 ~52 ~69 ~135 dirt
fill ~49 ~70 ~135 ~52 ~70 ~135 grass_block
fill ~53 ~60 ~135 ~56 ~65 ~135 stone
fill ~53 ~66 ~135 ~56 ~68 ~135 dirt
fill ~53 ~69 ~135 ~56 ~69 ~135 grass_block
fill ~57 ~60 ~135 ~60 ~64 ~135 stone
fill ~57 ~65 ~135 ~60 ~67 ~135 dirt
fill ~57 ~68 ~135 ~60 ~68 ~135 grass_block
fill ~61 ~60 ~135 ~62 ~65 ~135 stone
fill ~61 ~66 ~135 ~62 ~68 ~135 dirt
fill ~61 ~69 ~135 ~62 ~69 ~135 grass_block
fill ~63 ~60 ~135 ~63 ~66 ~135 stone
fill ~63 ~67 ~135 ~63 ~69 ~135 dirt
fill ~63 ~70 ~135 ~63 ~70 ~135 grass_block
fill ~48 ~60 ~136 ~49 ~67 ~136 stone
fill ~48 ~68 ~136 ~49 ~70 ~136 dirt
fill ~48 ~71 ~136 ~49 ~71 ~136 grass_block
fill ~50 ~60 ~136 ~51 ~66 ~136 stone
fill ~50 ~67 ~136 ~51 ~69 ~136 dirt
fill ~50 ~70 ~136 ~51 ~70 ~136 grass_block
fill ~52 ~60 ~136 ~54 ~65 ~136 stone
fill ~52 ~66 ~136 ~54 ~68 ~136 dirt
fill ~52 ~69 ~136 ~54 ~69 ~136 grass_block
fill ~55 ~60 ~136 ~59 ~64 ~136 stone
fill ~55 ~65 ~136 ~59 ~67 ~136 dirt
fill ~55 ~68 ~136 ~59 ~68 ~136 grass_block
fill ~60 ~60 ~136 ~61 ~65 ~136 stone
fill ~60 ~66 ~136 ~61 ~68 ~136 dirt
fill ~60 ~69 ~136 ~61 ~69 ~136 grass_block
fill ~62 ~60 ~136 ~63 ~66 ~136 stone
fill ~62 ~67 ~136 ~63 ~69 ~136 dirt
fill ~62 ~70 ~136 ~63 ~70 ~136 grass_block
fill ~48 ~60 ~137 ~50 ~66 ~137 stone
fill ~48 ~67 ~137 ~50 ~69 ~137 dirt
fill ~48 ~70 ~137 ~50 ~70 ~137 grass_block
fill ~51 ~60 ~137 ~54 ~65 ~137 stone
fill ~51 ~66 ~137 ~54 ~68 ~137 dirt
fill ~51 ~69 ~137 ~54 ~69 ~137 grass_block
fill ~55 ~60 ~137 ~57 ~64 ~137 stone
fill ~55 ~65 ~137 ~57 ~67 ~137 dirt
fill ~55 ~68 ~137 ~57 ~68 ~137 grass_block
fill ~58 ~60 ~137 ~61 ~65 ~137 stone
fill ~58 ~66 ~137 ~61 ~68 ~137 dirt
fill ~58 ~69 ~137 ~61 ~69 ~137 grass_block
fill ~62 ~60 ~137 ~62 ~66 ~137 stone
fill ~62 ~67 ~137 ~62 ~69 ~137 dirt
fill ~62 ~70 ~137 ~62 ~70 ~137 grass_block
fill ~63 ~60 ~137 ~63 ~67 ~137 stone
fill ~63 ~68 ~137 ~63 ~70 ~137 dirt
fill ~63 ~71 ~137 ~63 ~71 ~137 grass_block
fill ~48 ~60 ~138 ~48 ~66 ~138 stone
fill ~48 ~67 ~138 ~48 ~69 ~138 dirt
fill ~48 ~70 ~138 ~48 ~70 ~138 grass_block
fill ~49 ~60 ~138 ~53 ~65 ~138 stone
fill ~49 ~66 ~138 ~53 ~68 ~138 dirt
fill ~49 ~69 ~138 ~53 ~69 ~138 grass_block
fill ~54 ~60 ~138 ~55 ~64 ~138 stone
fill ~54 ~65 ~138 ~55 ~67 ~138 dirt
fill ~54 ~68 ~138 ~55 ~68 ~138 grass_block
fill ~56 ~60 ~138 ~58 ~65 ~138 stone
fill ~56 ~66 ~138 ~58 ~68 ~138 dirt
fill ~56 ~69 ~138 ~58 ~69 ~138 grass_block
fill ~59 ~60 ~138 ~59 ~66 ~138 stone
fill ~59 ~67 ~138 ~59 ~69 ~138 dirt
fill ~59 ~70 ~138 ~59 ~70 ~138 grass_block
fill ~60 ~60 ~138 ~61 ~65 ~138 stone
fill ~60 ~66 ~138 ~61 ~68 ~138 dirt
fill ~60 ~69 ~138 ~61 ~69 ~138 grass_block
fill ~62 ~60 ~138 ~63 ~66 ~138 stone
fill ~62 ~67 ~138 ~63 ~69 ~138 dirt
fill ~62 ~70 ~138 ~63 ~70 ~138 grass_block
fill ~48 ~60 ~139 ~56 ~65 ~139 stone
fill ~48 ~66 ~139 ~56 ~68 ~139 dirt
fill ~48 ~69 ~139 ~56 ~69 ~139 grass_block
fill ~57 ~60 ~139 ~58 ~66 ~139 stone
fill ~57 ~67 ~139 ~58 ~69 ~139 dirt
fill ~57 ~70 ~139 ~58 ~70 ~139 grass_block
fill ~59 ~60 ~139 ~59 ~67 ~139 stone
fill ~59 ~68 ~139 ~59 ~70 ~139 dirt
fill ~59 ~71 ~139 ~59 ~71 ~139 grass_block
fill ~60 ~60 ~139 ~63 ~66 ~139 stone
fill ~60 ~67 ~139 ~63 ~69 ~139 dirt
fill ~60 ~70 ~139 ~63 ~70 ~139 grass_block
fill ~48 ~60 ~140 ~51 ~66 ~140 stone
fill ~48 ~67 ~140 ~51 ~69 ~140 dirt
fill ~48 ~70 ~140 ~51 ~70 ~140 grass_block
fill ~52 ~60 ~140 ~55 ~65 ~140 stone
fill ~52 ~66 ~140 ~55 ~68 ~140 dirt
fill ~52 ~69 ~140 ~55 ~69 ~140 grass_block
fill ~56 ~60 ~140 ~57 ~66 ~140 stone
fill ~56 ~67 ~140 ~57 ~69 ~140 dirt
fill ~56 ~70 ~140 ~57 ~70 ~140 grass_block
fill ~58 ~60 ~140 ~60 ~67 ~140 stone
fill ~58 ~68 ~140 ~60 ~70 ~140 dirt
fill ~58 ~71 ~140 ~60 ~71 ~140 grass_block
fill ~61 ~60 ~140 ~63 ~66 ~140 stone
fill ~61 ~67 ~140 ~63 ~69 ~140 dirt
fill ~61 ~70 ~140 ~63 ~70 ~140 grass_block
fill ~48 ~60 ~141 ~49 ~67 ~141 stone
fill ~48 ~68 ~141 ~49 ~70 ~141 dirt
fill ~48 ~71 ~141 ~49 ~71 ~141 grass_block
fill ~50 ~60 ~141 ~51 ~66 ~141 stone
fill ~50 ~67 ~141 ~51 ~69 ~141 dirt
fill ~50 ~70 ~141 ~51 ~70 ~141 grass_block
fill ~52 ~60 ~141 ~54 ~65 ~141 stone
fill ~52 ~66 ~141 ~54 ~68 ~141 dirt
fill ~52 ~69 ~141 ~54 ~69 ~141 grass_block
fill ~55 ~60 ~141 ~56 ~66 ~141 stone
fill ~55 ~67 ~141 ~56 ~69 ~141 dirt
fill ~55 ~70 ~141 ~56 ~70 ~141 grass_block
fill ~57 ~60 ~141 ~60 ~67 ~141 stone
fill ~57 ~68 ~141 ~60 ~70 ~141 dirt
fill ~57 ~71 ~141 ~60 ~71 ~141 grass_block
fill ~61 ~60 ~141 ~63 ~66 ~141 stone
fill ~61 ~67 ~141 ~63 ~69 ~141 dirt
fill ~61 ~70 ~141 ~63 ~70 ~141 grass_block
fill ~48 ~60 ~142 ~49 ~67 ~142 stone
fill ~48 ~68 ~142 ~49 ~70 ~142 dirt
fill ~48 ~71 ~142 ~49 ~71 ~142 grass_block
fill ~50 ~60 ~142 ~51 ~66 ~142 stone
fill ~50 ~67 ~142 ~51 ~69 ~142 dirt
fill ~50 ~70 ~142 ~51 ~70 ~142 grass_block
fill ~52 ~60 ~142 ~53 ~65 ~142 stone
fill ~52 ~66 ~142 ~53 ~68 ~142 dirt
fill ~52 ~69 ~142 ~53 ~69 ~142 grass_block
fill ~54 ~60 ~142 ~55 ~66 ~142 stone
fill ~54 ~67 ~142 ~55 ~69 ~142 dirt
fill ~54 ~70 ~142 ~55 ~70 ~142 grass_block
fill ~56 ~60 ~142 ~60 ~67 ~142 stone
fill ~56 ~68 ~142 ~60 ~70 ~142 dirt
fill ~56 ~71 ~142 ~60 ~71 ~142 grass_block
fill ~61 ~60 ~142 ~62 ~66 ~142 stone
fill ~61 ~67 ~142 ~62 ~69 ~142 dirt
fill ~61 ~70 ~142 ~62 ~70 ~142 grass_block
fill ~63 ~60 ~142 ~63 ~65 ~142 stone
fill ~63 ~66 ~142 ~63 ~68 ~142 dirt
fill ~63 ~69 ~142 ~63 ~69 ~142 grass_block
fill ~48 ~60 ~143 ~49 ~67 ~143 stone
fill ~48 ~68 ~143 ~49 ~70 ~143 dirt
fill ~48 ~71 ~143 ~49 ~71 ~143 grass_block
fill ~50 ~60 ~143 ~53 ~66 ~143 stone
fill ~50 ~67 ~143 ~53 ~69 ~143 dirt
fill ~50 ~70 ~143 ~53 ~70 ~143 grass_block
fill ~54 ~60 ~143 ~60 ~67 ~143 stone
fill ~54 ~68 ~143 ~60 ~70 ~143 dirt
fill ~54 ~71 ~143 ~60 ~71 ~143 grass_block
fill ~61 ~60 ~143 ~62 ~66 ~143 stone
fill ~61 ~67 ~143 ~62 ~69 ~143 dirt
fill ~61 ~70 ~143 ~62 ~70 ~143 grass_block
fill ~63 ~60 ~143 ~63 ~65 ~143 stone
fill ~63 ~66 ~143 ~63 ~68 ~143 dirt
fill ~63 ~69 ~143 ~63 ~69 ~143 grass_block