fill ~96 ~60 ~0 ~96 ~65 ~0 stone
fill ~96 ~66 ~0 ~96 ~68 ~0 dirt
fill ~96 ~69 ~0 ~96 ~69 ~0 grass_block
fill ~97 ~60 ~0 ~97 ~66 ~0 stone
fill ~97 ~67 ~0 ~97 ~69 ~0 dirt
fill ~97 ~70 ~0 ~97 ~70 ~0 grass_block
fill ~98 ~60 ~0 ~108 ~65 ~0 stone
fill ~98 ~66 ~0 ~108 ~68 ~0 dirt
fill ~98 ~69 ~0 ~108 ~69 ~0 grass_block
fill ~109 ~60 ~0 ~111 ~64 ~0 stone
fill ~109 ~65 ~0 ~111 ~67 ~0 dirt
fill ~109 ~68 ~0 ~111 ~68 ~0 grass_block
fill ~96 ~60 ~1 ~96 ~65 ~1 stone
fill ~96 ~66 ~1 ~96 ~68 ~1 dirt
fill ~96 ~69 ~1 ~96 ~69 ~1 grass_block
fill ~97 ~60 ~1 ~100 ~66 ~1 stone
fill ~97 ~67 ~1 ~100 ~69 ~1 dirt
fill ~97 ~70 ~1 ~100 ~70 ~1 grass_block
fill ~101 ~60 ~1 ~103 ~65 ~1 stone
fill ~101 ~66 ~1 ~103 ~68 ~1 dirt
fill ~101 ~69 ~1 ~103 ~69 ~1 grass_block
fill ~104 ~60 ~1 ~106 ~66 ~1 stone
fill ~104 ~67 ~1 ~106 ~69 ~1 dirt
fill ~104 ~70 ~1 ~106 ~70 ~1 grass_block
fill ~107 ~60 ~1 ~111 ~65 ~1 stone
fill ~107 ~66 ~1 ~111 ~68 ~1 dirt
fill ~107 ~69 ~1 ~111 ~69 ~1 grass_block
fill ~96 ~60 ~2 ~97 ~66 ~2 stone
fill ~96 ~67 ~2 ~97 ~69 ~2 dirt
fill ~96 ~70 ~2 ~97 ~70 ~2 grass_block
fill ~98 ~60 ~2 ~99 ~67 ~2 stone
fill ~98 ~68 ~2 ~99 ~70 ~2 dirt
fill ~98 ~71 ~2 ~99 ~71 ~2 grass_block
fill ~100 ~60 ~2 ~109 ~66 ~2 stone
fill ~100 ~67 ~2 ~109 ~69 ~2 dirt
fill ~100 ~70 ~2 ~109 ~70 ~2 grass_block
fill ~110 ~60 ~2 ~111 ~65 ~2 stone
fill ~110 ~66 ~2 ~111 ~68 ~2 dirt
fill ~110 ~69 ~2 ~111 ~69 ~2 grass_block
fill ~96 ~60 ~3 ~97 ~66 ~3 stone
fill ~96 ~67 ~3 ~97 ~69 ~3 dirt
fill ~96 ~70 ~3 ~97 ~70 ~3 grass_block
fill ~98 ~60 ~3 ~103 ~67 ~3 stone
fill ~98 ~68 ~3 ~103 ~70 ~3 dirt
fill ~98 ~71 ~3 ~103 ~71 ~3 grass_block
fill ~104 ~60 ~3 ~109 ~66 ~3 stone
fill ~104 ~67 ~3 ~109 ~69 ~3 dirt
fill ~104 ~70 ~3 ~109 ~70 ~3 grass_block
fill ~110 ~60 ~3 ~111 ~65 ~3 stone
fill ~110 ~66 ~3 ~111 ~68 ~3 dirt
fill ~110 ~69 ~3 ~111 ~69 ~3 grass_block
fill ~96 ~60 ~4 ~96 ~66 ~4 stone
fill ~96 ~67 ~4 ~96 ~69 ~4 dirt
fill ~96 ~70 ~4 ~96 ~70 ~4 grass_block
fill ~97 ~60 ~4 ~103 ~67 ~4 stone
fill ~97 ~68 ~4 ~103 ~70 ~4 dirt
fill ~97 ~71 ~4 ~103 ~71 ~4 grass_block
fill ~104 ~60 ~4 ~108 ~66 ~4 stone
fill ~104 ~67 ~4 ~108 ~69 ~4 dirt
fill ~104 ~70 ~4 ~108 ~70 ~4 grass_block
fill ~109 ~60 ~4 ~111 ~65 ~4 stone
fill ~109 ~66 ~4 ~111 ~68 ~4 dirt
fill ~109 ~69 ~4 ~111 ~69 ~4 grass_block
fill ~96 ~60 ~5 ~97 ~67 ~5 stone
fill ~96 ~68 ~5 ~97 ~70 ~5 dirt
fill ~96 ~71 ~5 ~97 ~71 ~5 grass_block
fill ~98 ~60 ~5 ~98 ~68 ~5 stone
fill ~98 ~69 ~5 ~98 ~71 ~5 dirt
fill ~98 ~72 ~5 ~98 ~72 ~5 grass_block
fill ~99 ~60 ~5 ~102 ~67 ~5 stone
fill ~99 ~68 ~5 ~102 ~70 ~5 dirt
fill ~99 ~71 ~5 ~102 ~71 ~5 grass_block
fill ~103 ~60 ~5 ~106 ~66 ~5 stone
fill ~103 ~67 ~5 ~106 ~69 ~5 dirt
fill ~103 ~70 ~5 ~106 ~70 ~5 grass_block
fill ~107 ~60 ~5 ~111 ~65 ~5 stone
fill ~107 ~66 ~5 ~111 ~68 ~5 dirt
fill ~107 ~69 ~5 ~111 ~69 ~5 grass_block
fill ~96 ~60 ~6 ~99 ~68 ~6 stone
fill ~96 ~69 ~6 ~99 ~71 ~6 dirt
fill ~96 ~72 ~6 ~99 ~72 ~6 grass_block
fill ~100 ~60 ~6 ~102 ~67 ~6 stone
fill ~100 ~68 ~6 ~102 ~70 ~6 dirt
fill ~100 ~71 ~6 ~102 ~71 ~6 grass_block
fill ~103 ~60 ~6 ~105 ~66 ~6 stone
fill ~103 ~67 ~6 ~105 ~69 ~6 dirt
fill ~103 ~70 ~6 ~105 ~70 ~6 grass_block
fill ~106 ~60 ~6 ~108 ~65 ~6 stone
fill ~106 ~66 ~6 ~108 ~68 ~6 dirt
fill ~106 ~69 ~6 ~108 ~69 ~6 grass_block
fill ~109 ~60 ~6 ~111 ~64 ~6 stone
fill ~109 ~65 ~6 ~111 ~67 ~6 dirt
fill ~109 ~68 ~6 ~111 ~68 ~6 grass_block
fill ~96 ~60 ~7 ~99 ~68 ~7 stone
fill ~96 ~69 ~7 ~99 ~71 ~7 dirt
fill ~96 ~72 ~7 ~99 ~72 ~7 grass_block
fill ~100 ~60 ~7 ~101 ~67 ~7 stone
fill ~100 ~68 ~7 ~101 ~70 ~7 dirt
fill ~100 ~71 ~7 ~101 ~71 ~7 grass_block
fill ~102 ~60 ~7 ~104 ~66 ~7 stone
fill ~102 ~67 ~7 ~104 ~69 ~7 dirt
fill ~102 ~70 ~7 ~104 ~70 ~7 grass_block
fill ~105 ~60 ~7 ~109 ~65 ~7 stone
fill ~105 ~66 ~7 ~109 ~68 ~7 dirt
fill ~105 ~69 ~7 ~109 ~69 ~7 grass_block
fill ~110 ~60 ~7 ~111 ~64 ~7 stone
fill ~110 ~65 ~7 ~111 ~67 ~7 dirt
fill ~110 ~68 ~7 ~111 ~68 ~7 grass_block
fill ~96 ~60 ~8 ~99 ~68 ~8 stone
fill ~96 ~69 ~8 ~99 ~71 ~8 dirt
fill ~96 ~72 ~8 ~99 ~72 ~8 grass_block
fill ~100 ~60 ~8 ~101 ~67 ~8 stone
fill ~100 ~68 ~8 ~101 ~70 ~8 dirt
fill ~100 ~71 ~8 ~101 ~71 ~8 grass_block
fill ~102 ~60 ~8 ~103 ~66 ~8 stone
fill ~102 ~67 ~8 ~103 ~69 ~8 dirt
fill ~102 ~70 ~8 ~103 ~70 ~8 grass_block
fill ~104 ~60 ~8 ~111 ~65 ~8 stone
fill ~104 ~66 ~8 ~111 ~68 ~8 dirt
fill ~104 ~69 ~8 ~111 ~69 ~8 grass_block
fill ~96 ~60 ~9 ~100 ~68 ~9 stone
fill ~96 ~69 ~9 ~100 ~71 ~9 dirt
fill ~96 ~72 ~9 ~100 ~72 ~9 grass_block
fill ~101 ~60 ~9 ~101 ~67 ~9 stone
fill ~101 ~68 ~9 ~101 ~70 ~9 dirt
fill ~101 ~71 ~9 ~101 ~71 ~9 grass_block
fill ~102 ~60 ~9 ~103 ~66 ~9 stone
fill ~102 ~67 ~9 ~103 ~69 ~9 dirt
fill ~102 ~70 ~9 ~103 ~70 ~9 grass_block
fill ~104 ~60 ~9 ~105 ~65 ~9 stone
fill ~104 ~66 ~9 ~105 ~68 ~9 dirt
fill ~104 ~69 ~9 ~105 ~69 ~9 grass_block
fill ~106 ~60 ~9 ~107 ~66 ~9 stone
fill ~106 ~67 ~9 ~107 ~69 ~9 dirt
fill ~106 ~70 ~9 ~107 ~70 ~9 grass_block
fill ~108 ~60 ~9 ~111 ~65 ~9 stone
fill ~108 ~66 ~9 ~111 ~68 ~9 dirt
fill ~108 ~69 ~9 ~111 ~69 ~9 grass_block
fill ~96 ~60 ~10 ~97 ~69 ~10 stone
fill ~96 ~70 ~10 ~97 ~72 ~10 dirt
fill ~96 ~73 ~10 ~97 ~73 ~10 grass_block
fill ~98 ~60 ~10 ~100 ~68 ~10 stone
fill ~98 ~69 ~10 ~100 ~71 ~10 dirt
fill ~98 ~72 ~10 ~100 ~72 ~10 grass_block
fill ~101 ~60 ~10 ~101 ~67 ~10 stone
fill ~101 ~68 ~10 ~101 ~70 ~10 dirt
fill ~101 ~71 ~10 ~101 ~71 ~10 grass_block
fill ~102 ~60 ~10 ~104 ~66 ~10 stone
fill ~102 ~67 ~10 ~104 ~69 ~10 dirt
fill ~102 ~70 ~10 ~104 ~70 ~10 grass_block
fill ~105 ~60 ~10 ~106 ~67 ~10 stone
fill ~105 ~68 ~10 ~106 ~70 ~10 dirt
fill ~105 ~71 ~10 ~106 ~71 ~10 grass_block
fill ~107 ~60 ~10 ~110 ~66 ~10 stone
fill ~107 ~67 ~10 ~110 ~69 ~10 dirt
fill ~107 ~70 ~10 ~110 ~70 ~10 grass_block
fill ~111 ~60 ~10 ~111 ~65 ~10 stone
fill ~111 ~66 ~10 ~111 ~68 ~10 dirt
fill ~111 ~69 ~10 ~111 ~69 ~10 grass_block
fill ~96 ~60 ~11 ~98 ~69 ~11 stone
fill ~96 ~70 ~11 ~98 ~72 ~11 dirt
fill ~96 ~73 ~11 ~98 ~73 ~11 grass_block
fill ~99 ~60 ~11 ~100 ~68 ~11 stone
fill ~99 ~69 ~11 ~100 ~71 ~11 dirt
fill ~99 ~72 ~11 ~100 ~72 ~11 grass_block
fill ~101 ~60 ~11 ~107 ~67 ~11 stone
fill ~101 ~68 ~11 ~107 ~70 ~11 dirt
fill ~101 ~71 ~11 ~107 ~71 ~11 grass_block
fill ~108 ~60 ~11 ~111 ~66 ~11 stone
fill ~108 ~67 ~11 ~111 ~69 ~11 dirt
fill ~108 ~70 ~11 ~111 ~70 ~11 grass_block
fill ~96 ~60 ~12 ~98 ~69 ~12 stone
fill ~96 ~70 ~12 ~98 ~72 ~12 dirt
fill ~96 ~73 ~12 ~98 ~73 ~12 grass_block
fill ~99 ~60 ~12 ~102 ~68 ~12 stone
fill ~99 ~69 ~12 ~102 ~71 ~12 dirt
fill ~99 ~72 ~12 ~102 ~72 ~12 grass_block
fill ~103 ~60 ~12 ~108 ~67 ~12 stone
fill ~103 ~68 ~12 ~108 ~70 ~12 dirt
fill ~103 ~71 ~12 ~108 ~71 ~12 grass_block
fill ~109 ~60 ~12 ~111 ~66 ~12 stone
fill ~109 ~67 ~12 ~111 ~69 ~12 dirt
fill ~109 ~70 ~12 ~111 ~70 ~12 grass_block
fill ~96 ~60 ~13 ~99 ~69 ~13 stone
fill ~96 ~70 ~13 ~99 ~72 ~13 dirt
fill ~96 ~73 ~13 ~99 ~73 ~13 grass_block
fill ~100 ~60 ~13 ~106 ~68 ~13 stone
fill ~100 ~69 ~13 ~106 ~71 ~13 dirt
fill ~100 ~72 ~13 ~106 ~72 ~13 grass_block
fill ~107 ~60 ~13 ~109 ~67 ~13 stone
fill ~107 ~68 ~13 ~109 ~70 ~13 dirt
fill ~107 ~71 ~13 ~109 ~71 ~13 grass_block
fill ~110 ~60 ~13 ~111 ~66 ~13 stone
fill ~110 ~67 ~13 ~111 ~69 ~13 dirt
fill ~110 ~70 ~13 ~111 ~70 ~13 grass_block
fill ~96 ~60 ~14 ~101 ~69 ~14 stone
fill ~96 ~70 ~14 ~101 ~72 ~14 dirt
fill ~96 ~73 ~14 ~101 ~73 ~14 grass_block
fill ~102 ~60 ~14 ~106 ~68 ~14 stone
fill ~102 ~69 ~14 ~106 ~71 ~14 dirt
fill ~102 ~72 ~14 ~106 ~72 ~14 grass_block
fill ~107 ~60 ~14 ~110 ~67 ~14 stone
fill ~107 ~68 ~14 ~110 ~70 ~14 dirt
fill ~107 ~71 ~14 ~110 ~71 ~14 grass_block
fill ~111 ~60 ~14 ~111 ~66 ~14 stone
fill ~111 ~67 ~14 ~111 ~69 ~14 dirt
fill ~111 ~70 ~14 ~111 ~70 ~14 grass_block
fill ~96 ~60 ~15 ~103 ~69 ~15 stone
fill ~96 ~70 ~15 ~103 ~72 ~15 dirt
fill ~96 ~73 ~15 ~103 ~73 ~15 grass_block
fill ~104 ~60 ~15 ~108 ~68 ~15 stone
fill ~104 ~69 ~15 ~108 ~71 ~15 dirt
fill ~104 ~72 ~15 ~108 ~72 ~15 grass_block
fill ~109 ~60 ~15 ~111 ~67 ~15 stone
fill ~109 ~68 ~15 ~111 ~70 ~15 dirt
fill ~109 ~71 ~15 ~111 ~71 ~15 grass_block