fill ~304 ~60 ~80 ~304 ~61 ~80 stone
fill ~304 ~62 ~80 ~304 ~64 ~80 dirt
fill ~304 ~65 ~80 ~304 ~65 ~80 grass_block
fill ~305 ~60 ~80 ~306 ~60 ~80 stone
fill ~305 ~61 ~80 ~306 ~63 ~80 dirt
fill ~305 ~64 ~80 ~306 ~64 ~80 grass_block
fill ~307 ~60 ~80 ~311 ~61 ~80 stone
fill ~307 ~62 ~80 ~311 ~64 ~80 dirt
fill ~307 ~65 ~80 ~311 ~65 ~80 grass_block
fill ~312 ~60 ~80 ~312 ~60 ~80 stone
fill ~312 ~61 ~80 ~312 ~63 ~80 dirt
fill ~312 ~64 ~80 ~312 ~64 ~80 grass_block
fill ~313 ~60 ~80 ~319 ~61 ~80 stone
fill ~313 ~62 ~80 ~319 ~64 ~80 dirt
fill ~313 ~65 ~80 ~319 ~65 ~80 grass_block
fill ~304 ~60 ~81 ~306 ~61 ~81 stone
fill ~304 ~62 ~81 ~306 ~64 ~81 dirt
fill ~304 ~65 ~81 ~306 ~65 ~81 grass_block
fill ~307 ~60 ~81 ~309 ~60 ~81 stone
fill ~307 ~61 ~81 ~309 ~63 ~81 dirt
fill ~307 ~64 ~81 ~309 ~64 ~81 grass_block
fill ~310 ~60 ~81 ~319 ~61 ~81 stone
fill ~310 ~62 ~81 ~319 ~64 ~81 dirt
fill ~310 ~65 ~81 ~319 ~65 ~81 grass_block
fill ~304 ~60 ~82 ~304 ~60 ~82 stone
fill ~304 ~61 ~82 ~304 ~63 ~82 dirt
fill ~304 ~64 ~82 ~304 ~64 ~82 grass_block
fill ~305 ~60 ~82 ~308 ~61 ~82 stone
fill ~305 ~62 ~82 ~308 ~64 ~82 dirt
fill ~305 ~65 ~82 ~308 ~65 ~82 grass_block
fill ~309 ~60 ~82 ~309 ~60 ~82 stone
fill ~309 ~61 ~82 ~309 ~63 ~82 dirt
fill ~309 ~64 ~82 ~309 ~64 ~82 grass_block
fill ~310 ~60 ~82 ~310 ~61 ~82 stone
fill ~310 ~62 ~82 ~310 ~64 ~82 dirt
fill ~310 ~65 ~82 ~310 ~65 ~82 grass_block
fill ~311 ~60 ~82 ~312 ~60 ~82 stone
fill ~311 ~61 ~82 ~312 ~63 ~82 dirt
fill ~311 ~64 ~82 ~312 ~64 ~82 grass_block
fill ~313 ~60 ~82 ~319 ~61 ~82 stone
fill ~313 ~62 ~82 ~319 ~64 ~82 dirt
fill ~313 ~65 ~82 ~319 ~65 ~82 grass_block
fill ~304 ~60 ~83 ~305 ~60 ~83 stone
fill ~304 ~61 ~83 ~305 ~63 ~83 dirt
fill ~304 ~64 ~83 ~305 ~64 ~83 grass_block
fill ~306 ~60 ~83 ~306 ~61 ~83 stone
fill ~306 ~62 ~83 ~306 ~64 ~83 dirt
fill ~306 ~65 ~83 ~306 ~65 ~83 grass_block
fill ~307 ~60 ~83 ~308 ~60 ~83 stone
fill ~307 ~61 ~83 ~308 ~63 ~83 dirt
fill ~307 ~64 ~83 ~308 ~64 ~83 grass_block
fill ~309 ~60 ~83 ~309 ~61 ~83 stone
fill ~309 ~62 ~83 ~309 ~64 ~83 dirt
fill ~309 ~65 ~83 ~309 ~65 ~83 grass_block
fill ~310 ~60 ~83 ~313 ~60 ~83 stone
fill ~310 ~61 ~83 ~313 ~63 ~83 dirt
fill ~310 ~64 ~83 ~313 ~64 ~83 grass_block
fill ~314 ~60 ~83 ~316 ~61 ~83 stone
fill ~314 ~62 ~83 ~316 ~64 ~83 dirt
fill ~314 ~65 ~83 ~316 ~65 ~83 grass_block
fill ~317 ~60 ~83 ~317 ~60 ~83 stone
fill ~317 ~61 ~83 ~317 ~63 ~83 dirt
fill ~317 ~64 ~83 ~317 ~64 ~83 grass_block
fill ~318 ~60 ~83 ~319 ~61 ~83 stone
fill ~318 ~62 ~83 ~319 ~64 ~83 dirt
fill ~318 ~65 ~83 ~319 ~65 ~83 grass_block
fill ~304 ~60 ~84 ~307 ~61 ~84 stone
fill ~304 ~62 ~84 ~307 ~64 ~84 dirt
fill ~304 ~65 ~84 ~307 ~65 ~84 grass_block
fill ~308 ~60 ~84 ~314 ~60 ~84 stone
fill ~308 ~61 ~84 ~314 ~63 ~84 dirt
fill ~308 ~64 ~84 ~314 ~64 ~84 grass_block
fill ~315 ~60 ~84 ~315 ~61 ~84 stone
fill ~315 ~62 ~84 ~315 ~64 ~84 dirt
fill ~315 ~65 ~84 ~315 ~65 ~84 grass_block
fill ~316 ~60 ~84 ~316 ~60 ~84 stone
fill ~316 ~61 ~84 ~316 ~63 ~84 dirt
fill ~316 ~64 ~84 ~316 ~64 ~84 grass_block
fill ~317 ~60 ~84 ~319 ~61 ~84 stone
fill ~317 ~62 ~84 ~319 ~64 ~84 dirt
fill ~317 ~65 ~84 ~319 ~65 ~84 grass_block
fill ~304 ~60 ~85 ~311 ~61 ~85 stone
fill ~304 ~62 ~85 ~311 ~64 ~85 dirt
fill ~304 ~65 ~85 ~311 ~65 ~85 grass_block
fill ~312 ~60 ~85 ~317 ~60 ~85 stone
fill ~312 ~61 ~85 ~317 ~63 ~85 dirt
fill ~312 ~64 ~85 ~317 ~64 ~85 grass_block
fill ~318 ~60 ~85 ~319 ~61 ~85 stone
fill ~318 ~62 ~85 ~319 ~64 ~85 dirt
fill ~318 ~65 ~85 ~319 ~65 ~85 grass_block
fill ~304 ~60 ~86 ~312 ~61 ~86 stone
fill ~304 ~62 ~86 ~312 ~64 ~86 dirt
fill ~304 ~65 ~86 ~312 ~65 ~86 grass_block
fill ~313 ~60 ~86 ~317 ~60 ~86 stone
fill ~313 ~61 ~86 ~317 ~63 ~86 dirt
fill ~313 ~64 ~86 ~317 ~64 ~86 grass_block
fill ~318 ~60 ~86 ~318 ~61 ~86 stone
fill ~318 ~62 ~86 ~318 ~64 ~86 dirt
fill ~318 ~65 ~86 ~318 ~65 ~86 grass_block
fill ~319 ~60 ~86 ~319 ~60 ~86 stone
fill ~319 ~61 ~86 ~319 ~63 ~86 dirt
fill ~319 ~64 ~86 ~319 ~64 ~86 grass_block
fill ~304 ~60 ~87 ~315 ~61 ~87 stone
fill ~304 ~62 ~87 ~315 ~64 ~87 dirt
fill ~304 ~65 ~87 ~315 ~65 ~87 grass_block
fill ~316 ~60 ~87 ~318 ~60 ~87 stone
fill ~316 ~61 ~87 ~318 ~63 ~87 dirt
fill ~316 ~64 ~87 ~318 ~64 ~87 grass_block
fill ~319 ~60 ~87 ~319 ~61 ~87 stone
fill ~319 ~62 ~87 ~319 ~64 ~87 dirt
fill ~319 ~65 ~87 ~319 ~65 ~87 grass_block
fill ~304 ~60 ~88 ~316 ~61 ~88 stone
fill ~304 ~62 ~88 ~316 ~64 ~88 dirt
fill ~304 ~65 ~88 ~316 ~65 ~88 grass_block
fill ~317 ~60 ~88 ~319 ~60 ~88 stone
fill ~317 ~61 ~88 ~319 ~63 ~88 dirt
fill ~317 ~64 ~88 ~319 ~64 ~88 grass_block
fill ~304 ~60 ~89 ~319 ~61 ~89 stone
fill ~304 ~62 ~89 ~319 ~64 ~89 dirt
fill ~304 ~65 ~89 ~319 ~65 ~89 grass_block
fill ~304 ~60 ~90 ~319 ~61 ~90 stone
fill ~304 ~62 ~90 ~319 ~64 ~90 dirt
fill ~304 ~65 ~90 ~319 ~65 ~90 grass_block
fill ~304 ~60 ~91 ~304 ~62 ~91 stone
fill ~304 ~63 ~91 ~304 ~65 ~91 dirt
fill ~304 ~66 ~91 ~304 ~66 ~91 grass_block
fill ~305 ~60 ~91 ~319 ~61 ~91 stone
fill ~305 ~62 ~91 ~319 ~64 ~91 dirt
fill ~305 ~65 ~91 ~319 ~65 ~91 grass_block
fill ~304 ~60 ~92 ~319 ~61 ~92 stone
fill ~304 ~62 ~92 ~319 ~64 ~92 dirt
fill ~304 ~65 ~92 ~319 ~65 ~92 grass_block
fill ~304 ~60 ~93 ~319 ~61 ~93 stone
fill ~304 ~62 ~93 ~319 ~64 ~93 dirt
fill ~304 ~65 ~93 ~319 ~65 ~93 grass_block
fill ~304 ~60 ~94 ~319 ~61 ~94 stone
fill ~304 ~62 ~94 ~319 ~64 ~94 dirt
fill ~304 ~65 ~94 ~319 ~65 ~94 grass_block
fill ~304 ~60 ~95 ~304 ~62 ~95 stone
fill ~304 ~63 ~95 ~304 ~65 ~95 dirt
fill ~304 ~66 ~95 ~304 ~66 ~95 grass_block
fill ~305 ~60 ~95 ~319 ~61 ~95 stone
fill ~305 ~62 ~95 ~319 ~64 ~95 dirt
fill ~305 ~65 ~95 ~319 ~65 ~95 grass_block