fill ~272 ~60 ~96 ~277 ~65 ~96 stone
fill ~272 ~66 ~96 ~277 ~68 ~96 dirt
fill ~272 ~69 ~96 ~277 ~69 ~96 grass_block
fill ~278 ~60 ~96 ~285 ~64 ~96 stone
fill ~278 ~65 ~96 ~285 ~67 ~96 dirt
fill ~278 ~68 ~96 ~285 ~68 ~96 grass_block
fill ~286 ~60 ~96 ~287 ~63 ~96 stone
fill ~286 ~64 ~96 ~287 ~66 ~96 dirt
fill ~286 ~67 ~96 ~287 ~67 ~96 grass_block
fill ~272 ~60 ~97 ~277 ~65 ~97 stone
fill ~272 ~66 ~97 ~277 ~68 ~97 dirt
fill ~272 ~69 ~97 ~277 ~69 ~97 grass_block
fill ~278 ~60 ~97 ~287 ~64 ~97 stone
fill ~278 ~65 ~97 ~287 ~67 ~97 dirt
fill ~278 ~68 ~97 ~287 ~68 ~97 grass_block
fill ~272 ~60 ~98 ~278 ~65 ~98 stone
fill ~272 ~66 ~98 ~278 ~68 ~98 dirt
fill ~272 ~69 ~98 ~278 ~69 ~98 grass_block
fill ~279 ~60 ~98 ~285 ~64 ~98 stone
fill ~279 ~65 ~98 ~285 ~67 ~98 dirt
fill ~279 ~68 ~98 ~285 ~68 ~98 grass_block
fill ~286 ~60 ~98 ~286 ~63 ~98 stone
fill ~286 ~64 ~98 ~286 ~66 ~98 dirt
fill ~286 ~67 ~98 ~286 ~67 ~98 grass_block
fill ~287 ~60 ~98 ~287 ~64 ~98 stone
fill ~287 ~65 ~98 ~287 ~67 ~98 dirt
fill ~287 ~68 ~98 ~287 ~68 ~98 grass_block
fill ~272 ~60 ~99 ~279 ~65 ~99 stone
fill ~272 ~66 ~99 ~279 ~68 ~99 dirt
fill ~272 ~69 ~99 ~279 ~69 ~99 grass_block
fill ~280 ~60 ~99 ~286 ~64 ~99 stone
fill ~280 ~65 ~99 ~286 ~67 ~99 dirt
fill ~280 ~68 ~99 ~286 ~68 ~99 grass_block
fill ~287 ~60 ~99 ~287 ~63 ~99 stone
fill ~287 ~64 ~99 ~287 ~66 ~99 dirt
fill ~287 ~67 ~99 ~287 ~67 ~99 grass_block
fill ~272 ~60 ~100 ~279 ~65 ~100 stone
fill ~272 ~66 ~100 ~279 ~68 ~100 dirt
fill ~272 ~69 ~100 ~279 ~69 ~100 grass_block
fill ~280 ~60 ~100 ~287 ~64 ~100 stone
fill ~280 ~65 ~100 ~287 ~67 ~100 dirt
fill ~280 ~68 ~100 ~287 ~68 ~100 grass_block
fill ~272 ~60 ~101 ~280 ~65 ~101 stone
fill ~272 ~66 ~101 ~280 ~68 ~101 dirt
fill ~272 ~69 ~101 ~280 ~69 ~101 grass_block
fill ~281 ~60 ~101 ~284 ~64 ~101 stone
fill ~281 ~65 ~101 ~284 ~67 ~101 dirt
fill ~281 ~68 ~101 ~284 ~68 ~101 grass_block
fill ~285 ~60 ~101 ~287 ~63 ~101 stone
fill ~285 ~64 ~101 ~287 ~66 ~101 dirt
fill ~285 ~67 ~101 ~287 ~67 ~101 grass_block
fill ~272 ~60 ~102 ~278 ~65 ~102 stone
fill ~272 ~66 ~102 ~278 ~68 ~102 dirt
fill ~272 ~69 ~102 ~278 ~69 ~102 grass_block
fill ~279 ~60 ~102 ~282 ~64 ~102 stone
fill ~279 ~65 ~102 ~282 ~67 ~102 dirt
fill ~279 ~68 ~102 ~282 ~68 ~102 grass_block
fill ~283 ~60 ~102 ~287 ~63 ~102 stone
fill ~283 ~64 ~102 ~287 ~66 ~102 dirt
fill ~283 ~67 ~102 ~287 ~67 ~102 grass_block
fill ~272 ~60 ~103 ~277 ~65 ~103 stone
fill ~272 ~66 ~103 ~277 ~68 ~103 dirt
fill ~272 ~69 ~103 ~277 ~69 ~103 grass_block
fill ~278 ~60 ~103 ~280 ~64 ~103 stone
fill ~278 ~65 ~103 ~280 ~67 ~103 dirt
fill ~278 ~68 ~103 ~280 ~68 ~103 grass_block
fill ~281 ~60 ~103 ~284 ~63 ~103 stone
fill ~281 ~64 ~103 ~284 ~66 ~103 dirt
fill ~281 ~67 ~103 ~284 ~67 ~103 grass_block
fill ~285 ~60 ~103 ~287 ~62 ~103 stone
fill ~285 ~63 ~103 ~287 ~65 ~103 dirt
fill ~285 ~66 ~103 ~287 ~66 ~103 grass_block
fill ~272 ~60 ~104 ~276 ~65 ~104 stone
fill ~272 ~66 ~104 ~276 ~68 ~104 dirt
fill ~272 ~69 ~104 ~276 ~69 ~104 grass_block
fill ~277 ~60 ~104 ~279 ~64 ~104 stone
fill ~277 ~65 ~104 ~279 ~67 ~104 dirt
fill ~277 ~68 ~104 ~279 ~68 ~104 grass_block
fill ~280 ~60 ~104 ~283 ~63 ~104 stone
fill ~280 ~64 ~104 ~283 ~66 ~104 dirt
fill ~280 ~67 ~104 ~283 ~67 ~104 grass_block
fill ~284 ~60 ~104 ~287 ~62 ~104 stone
fill ~284 ~63 ~104 ~287 ~65 ~104 dirt
fill ~284 ~66 ~104 ~287 ~66 ~104 grass_block
fill ~272 ~60 ~105 ~275 ~64 ~105 stone
fill ~272 ~65 ~105 ~275 ~67 ~105 dirt
fill ~272 ~68 ~105 ~275 ~68 ~105 grass_block
fill ~276 ~60 ~105 ~276 ~65 ~105 stone
fill ~276 ~66 ~105 ~276 ~68 ~105 dirt
fill ~276 ~69 ~105 ~276 ~69 ~105 grass_block
fill ~277 ~60 ~105 ~279 ~64 ~105 stone
fill ~277 ~65 ~105 ~279 ~67 ~105 dirt
fill ~277 ~68 ~105 ~279 ~68 ~105 grass_block
fill ~280 ~60 ~105 ~287 ~63 ~105 stone
fill ~280 ~64 ~105 ~287 ~66 ~105 dirt
fill ~280 ~67 ~105 ~287 ~67 ~105 grass_block
fill ~272 ~60 ~106 ~275 ~64 ~106 stone
fill ~272 ~65 ~106 ~275 ~67 ~106 dirt
fill ~272 ~68 ~106 ~275 ~68 ~106 grass_block
fill ~276 ~60 ~106 ~277 ~65 ~106 stone
fill ~276 ~66 ~106 ~277 ~68 ~106 dirt
fill ~276 ~69 ~106 ~277 ~69 ~106 grass_block
fill ~278 ~60 ~106 ~282 ~64 ~106 stone
fill ~278 ~65 ~106 ~282 ~67 ~106 dirt
fill ~278 ~68 ~106 ~282 ~68 ~106 grass_block
fill ~283 ~60 ~106 ~287 ~63 ~106 stone
fill ~283 ~64 ~106 ~287 ~66 ~106 dirt
fill ~283 ~67 ~106 ~287 ~67 ~106 grass_block
fill ~272 ~60 ~107 ~274 ~63 ~107 stone
fill ~272 ~64 ~107 ~274 ~66 ~107 dirt
fill ~272 ~67 ~107 ~274 ~67 ~107 grass_block
fill ~275 ~60 ~107 ~275 ~64 ~107 stone
fill ~275 ~65 ~107 ~275 ~67 ~107 dirt
fill ~275 ~68 ~107 ~275 ~68 ~107 grass_block
fill ~276 ~60 ~107 ~280 ~65 ~107 stone
fill ~276 ~66 ~107 ~280 ~68 ~107 dirt
fill ~276 ~69 ~107 ~280 ~69 ~107 grass_block
fill ~281 ~60 ~107 ~287 ~64 ~107 stone
fill ~281 ~65 ~107 ~287 ~67 ~107 dirt
fill ~281 ~68 ~107 ~287 ~68 ~107 grass_block
fill ~272 ~60 ~108 ~274 ~63 ~108 stone
fill ~272 ~64 ~108 ~274 ~66 ~108 dirt
fill ~272 ~67 ~108 ~274 ~67 ~108 grass_block
fill ~275 ~60 ~108 ~276 ~64 ~108 stone
fill ~275 ~65 ~108 ~276 ~67 ~108 dirt
fill ~275 ~68 ~108 ~276 ~68 ~108 grass_block
fill ~277 ~60 ~108 ~282 ~65 ~108 stone
fill ~277 ~66 ~108 ~282 ~68 ~108 dirt
fill ~277 ~69 ~108 ~282 ~69 ~108 grass_block
fill ~283 ~60 ~108 ~285 ~64 ~108 stone
fill ~283 ~65 ~108 ~285 ~67 ~108 dirt
fill ~283 ~68 ~108 ~285 ~68 ~108 grass_block
fill ~286 ~60 ~108 ~286 ~65 ~108 stone
fill ~286 ~66 ~108 ~286 ~68 ~108 dirt
fill ~286 ~69 ~108 ~286 ~69 ~108 grass_block
fill ~287 ~60 ~108 ~287 ~64 ~108 stone
fill ~287 ~65 ~108 ~287 ~67 ~108 dirt
fill ~287 ~68 ~108 ~287 ~68 ~108 grass_block
fill ~272 ~60 ~109 ~273 ~63 ~109 stone
fill ~272 ~64 ~109 ~273 ~66 ~109 dirt
fill ~272 ~67 ~109 ~273 ~67 ~109 grass_block
fill ~274 ~60 ~109 ~276 ~64 ~109 stone
fill ~274 ~65 ~109 ~276 ~67 ~109 dirt
fill ~274 ~68 ~109 ~276 ~68 ~109 grass_block
fill ~277 ~60 ~109 ~287 ~65 ~109 stone
fill ~277 ~66 ~109 ~287 ~68 ~109 dirt
fill ~277 ~69 ~109 ~287 ~69 ~109 grass_block
fill ~272 ~60 ~110 ~272 ~63 ~110 stone
fill ~272 ~64 ~110 ~272 ~66 ~110 dirt
fill ~272 ~67 ~110 ~272 ~67 ~110 grass_block
fill ~273 ~60 ~110 ~280 ~64 ~110 stone
fill ~273 ~65 ~110 ~280 ~67 ~110 dirt
fill ~273 ~68 ~110 ~280 ~68 ~110 grass_block
fill ~281 ~60 ~110 ~287 ~65 ~110 stone
fill ~281 ~66 ~110 ~287 ~68 ~110 dirt
fill ~281 ~69 ~110 ~287 ~69 ~110 grass_block
fill ~272 ~60 ~111 ~282 ~64 ~111 stone
fill ~272 ~65 ~111 ~282 ~67 ~111 dirt
fill ~272 ~68 ~111 ~282 ~68 ~111 grass_block
fill ~283 ~60 ~111 ~287 ~65 ~111 stone
fill ~283 ~66 ~111 ~287 ~68 ~111 dirt
fill ~283 ~69 ~111 ~287 ~69 ~111 grass_block