fill ~176 ~60 ~112 ~177 ~63 ~112 stone
fill ~176 ~64 ~112 ~177 ~66 ~112 dirt
fill ~176 ~67 ~112 ~177 ~67 ~112 grass_block
fill ~178 ~60 ~112 ~181 ~64 ~112 stone
fill ~178 ~65 ~112 ~181 ~67 ~112 dirt
fill ~178 ~68 ~112 ~181 ~68 ~112 grass_block
fill ~182 ~60 ~112 ~188 ~63 ~112 stone
fill ~182 ~64 ~112 ~188 ~66 ~112 dirt
fill ~182 ~67 ~112 ~188 ~67 ~112 grass_block
fill ~189 ~60 ~112 ~191 ~62 ~112 stone
fill ~189 ~63 ~112 ~191 ~65 ~112 dirt
fill ~189 ~66 ~112 ~191 ~66 ~112 grass_block
fill ~176 ~60 ~113 ~179 ~63 ~113 stone
fill ~176 ~64 ~113 ~179 ~66 ~113 dirt
fill ~176 ~67 ~113 ~179 ~67 ~113 grass_block
fill ~180 ~60 ~113 ~180 ~64 ~113 stone
fill ~180 ~65 ~113 ~180 ~67 ~113 dirt
fill ~180 ~68 ~113 ~180 ~68 ~113 grass_block
fill ~181 ~60 ~113 ~189 ~63 ~113 stone
fill ~181 ~64 ~113 ~189 ~66 ~113 dirt
fill ~181 ~67 ~113 ~189 ~67 ~113 grass_block
fill ~190 ~60 ~113 ~191 ~62 ~113 stone
fill ~190 ~63 ~113 ~191 ~65 ~113 dirt
fill ~190 ~66 ~113 ~191 ~66 ~113 grass_block
fill ~176 ~60 ~114 ~176 ~62 ~114 stone
fill ~176 ~63 ~114 ~176 ~65 ~114 dirt
fill ~176 ~66 ~114 ~176 ~66 ~114 grass_block
fill ~177 ~60 ~114 ~190 ~63 ~114 stone
fill ~177 ~64 ~114 ~190 ~66 ~114 dirt
fill ~177 ~67 ~114 ~190 ~67 ~114 grass_block
fill ~191 ~60 ~114 ~191 ~62 ~114 stone
fill ~191 ~63 ~114 ~191 ~65 ~114 dirt
fill ~191 ~66 ~114 ~191 ~66 ~114 grass_block
fill ~176 ~60 ~115 ~181 ~62 ~115 stone
fill ~176 ~63 ~115 ~181 ~65 ~115 dirt
fill ~176 ~66 ~115 ~181 ~66 ~115 grass_block
fill ~182 ~60 ~115 ~191 ~63 ~115 stone
fill ~182 ~64 ~115 ~191 ~66 ~115 dirt
fill ~182 ~67 ~115 ~191 ~67 ~115 grass_block
fill ~176 ~60 ~116 ~183 ~62 ~116 stone
fill ~176 ~63 ~116 ~183 ~65 ~116 dirt
fill ~176 ~66 ~116 ~183 ~66 ~116 grass_block
fill ~184 ~60 ~116 ~184 ~63 ~116 stone
fill ~184 ~64 ~116 ~184 ~66 ~116 dirt
fill ~184 ~67 ~116 ~184 ~67 ~116 grass_block
fill ~185 ~60 ~116 ~185 ~62 ~116 stone
fill ~185 ~63 ~116 ~185 ~65 ~116 dirt
fill ~185 ~66 ~116 ~185 ~66 ~116 grass_block
fill ~186 ~60 ~116 ~191 ~63 ~116 stone
fill ~186 ~64 ~116 ~191 ~66 ~116 dirt
fill ~186 ~67 ~116 ~191 ~67 ~116 grass_block
fill ~176 ~60 ~117 ~186 ~62 ~117 stone
fill ~176 ~63 ~117 ~186 ~65 ~117 dirt
fill ~176 ~66 ~117 ~186 ~66 ~117 grass_block
fill ~187 ~60 ~117 ~191 ~63 ~117 stone
fill ~187 ~64 ~117 ~191 ~66 ~117 dirt
fill ~187 ~67 ~117 ~191 ~67 ~117 grass_block
fill ~176 ~60 ~118 ~189 ~62 ~118 stone
fill ~176 ~63 ~118 ~189 ~65 ~118 dirt
fill ~176 ~66 ~118 ~189 ~66 ~118 grass_block
fill ~190 ~60 ~118 ~191 ~63 ~118 stone
fill ~190 ~64 ~118 ~191 ~66 ~118 dirt
fill ~190 ~67 ~118 ~191 ~67 ~118 grass_block
fill ~176 ~60 ~119 ~191 ~62 ~119 stone
fill ~176 ~63 ~119 ~191 ~65 ~119 dirt
fill ~176 ~66 ~119 ~191 ~66 ~119 grass_block
fill ~176 ~60 ~120 ~191 ~62 ~120 stone
fill ~176 ~63 ~120 ~191 ~65 ~120 dirt
fill ~176 ~66 ~120 ~191 ~66 ~120 grass_block
fill ~176 ~60 ~121 ~191 ~62 ~121 stone
fill ~176 ~63 ~121 ~191 ~65 ~121 dirt
fill ~176 ~66 ~121 ~191 ~66 ~121 grass_block
fill ~176 ~60 ~122 ~191 ~62 ~122 stone
fill ~176 ~63 ~122 ~191 ~65 ~122 dirt
fill ~176 ~66 ~122 ~191 ~66 ~122 grass_block
fill ~176 ~60 ~123 ~178 ~63 ~123 stone
fill ~176 ~64 ~123 ~178 ~66 ~123 dirt
fill ~176 ~67 ~123 ~178 ~67 ~123 grass_block
fill ~179 ~60 ~123 ~191 ~62 ~123 stone
fill ~179 ~63 ~123 ~191 ~65 ~123 dirt
fill ~179 ~66 ~123 ~191 ~66 ~123 grass_block
fill ~176 ~60 ~124 ~179 ~63 ~124 stone
fill ~176 ~64 ~124 ~179 ~66 ~124 dirt
fill ~176 ~67 ~124 ~179 ~67 ~124 grass_block
fill ~180 ~60 ~124 ~191 ~62 ~124 stone
fill ~180 ~63 ~124 ~191 ~65 ~124 dirt
fill ~180 ~66 ~124 ~191 ~66 ~124 grass_block
fill ~176 ~60 ~125 ~183 ~63 ~125 stone
fill ~176 ~64 ~125 ~183 ~66 ~125 dirt
fill ~176 ~67 ~125 ~183 ~67 ~125 grass_block
fill ~184 ~60 ~125 ~191 ~62 ~125 stone
fill ~184 ~63 ~125 ~191 ~65 ~125 dirt
fill ~184 ~66 ~125 ~191 ~66 ~125 grass_block
fill ~176 ~60 ~126 ~177 ~64 ~126 stone
fill ~176 ~65 ~126 ~177 ~67 ~126 dirt
fill ~176 ~68 ~126 ~177 ~68 ~126 grass_block
fill ~178 ~60 ~126 ~187 ~63 ~126 stone
fill ~178 ~64 ~126 ~187 ~66 ~126 dirt
fill ~178 ~67 ~126 ~187 ~67 ~126 grass_block
fill ~188 ~60 ~126 ~191 ~62 ~126 stone
fill ~188 ~63 ~126 ~191 ~65 ~126 dirt
fill ~188 ~66 ~126 ~191 ~66 ~126 grass_block
fill ~176 ~60 ~127 ~181 ~64 ~127 stone
fill ~176 ~65 ~127 ~181 ~67 ~127 dirt
fill ~176 ~68 ~127 ~181 ~68 ~127 grass_block
fill ~182 ~60 ~127 ~189 ~63 ~127 stone
fill ~182 ~64 ~127 ~189 ~66 ~127 dirt
fill ~182 ~67 ~127 ~189 ~67 ~127 grass_block
fill ~190 ~60 ~127 ~191 ~62 ~127 stone
fill ~190 ~63 ~127 ~191 ~65 ~127 dirt
fill ~190 ~66 ~127 ~191 ~66 ~127 grass_block