fill ~32 ~60 ~0 ~33 ~64 ~0 stone
fill ~32 ~65 ~0 ~33 ~67 ~0 dirt
fill ~32 ~68 ~0 ~33 ~68 ~0 grass_block
fill ~34 ~60 ~0 ~34 ~65 ~0 stone
fill ~34 ~66 ~0 ~34 ~68 ~0 dirt
fill ~34 ~69 ~0 ~34 ~69 ~0 grass_block
fill ~35 ~60 ~0 ~41 ~64 ~0 stone
fill ~35 ~65 ~0 ~41 ~67 ~0 dirt
fill ~35 ~68 ~0 ~41 ~68 ~0 grass_block
fill ~42 ~60 ~0 ~43 ~65 ~0 stone
fill ~42 ~66 ~0 ~43 ~68 ~0 dirt
fill ~42 ~69 ~0 ~43 ~69 ~0 grass_block
fill ~44 ~60 ~0 ~45 ~66 ~0 stone
fill ~44 ~67 ~0 ~45 ~69 ~0 dirt
fill ~44 ~70 ~0 ~45 ~70 ~0 grass_block
fill ~46 ~60 ~0 ~47 ~67 ~0 stone
fill ~46 ~68 ~0 ~47 ~70 ~0 dirt
fill ~46 ~71 ~0 ~47 ~71 ~0 grass_block
fill ~32 ~60 ~1 ~41 ~64 ~1 stone
fill ~32 ~65 ~1 ~41 ~67 ~1 dirt
fill ~32 ~68 ~1 ~41 ~68 ~1 grass_block
fill ~42 ~60 ~1 ~44 ~65 ~1 stone
fill ~42 ~66 ~1 ~44 ~68 ~1 dirt
fill ~42 ~69 ~1 ~44 ~69 ~1 grass_block
fill ~45 ~60 ~1 ~47 ~66 ~1 stone
fill ~45 ~67 ~1 ~47 ~69 ~1 dirt
fill ~45 ~70 ~1 ~47 ~70 ~1 grass_block
fill ~32 ~60 ~2 ~32 ~63 ~2 stone
fill ~32 ~64 ~2 ~32 ~66 ~2 dirt
fill ~32 ~67 ~2 ~32 ~67 ~2 grass_block
fill ~33 ~60 ~2 ~42 ~64 ~2 stone
fill ~33 ~65 ~2 ~42 ~67 ~2 dirt
fill ~33 ~68 ~2 ~42 ~68 ~2 grass_block
fill ~43 ~60 ~2 ~44 ~65 ~2 stone
fill ~43 ~66 ~2 ~44 ~68 ~2 dirt
fill ~43 ~69 ~2 ~44 ~69 ~2 grass_block
fill ~45 ~60 ~2 ~47 ~66 ~2 stone
fill ~45 ~67 ~2 ~47 ~69 ~2 dirt
fill ~45 ~70 ~2 ~47 ~70 ~2 grass_block
fill ~32 ~60 ~3 ~34 ~63 ~3 stone
fill ~32 ~64 ~3 ~34 ~66 ~3 dirt
fill ~32 ~67 ~3 ~34 ~67 ~3 grass_block
fill ~35 ~60 ~3 ~42 ~64 ~3 stone
fill ~35 ~65 ~3 ~42 ~67 ~3 dirt
fill ~35 ~68 ~3 ~42 ~68 ~3 grass_block
fill ~43 ~60 ~3 ~45 ~65 ~3 stone
fill ~43 ~66 ~3 ~45 ~68 ~3 dirt
fill ~43 ~69 ~3 ~45 ~69 ~3 grass_block
fill ~46 ~60 ~3 ~47 ~66 ~3 stone
fill ~46 ~67 ~3 ~47 ~69 ~3 dirt
fill ~46 ~70 ~3 ~47 ~70 ~3 grass_block
fill ~32 ~60 ~4 ~35 ~63 ~4 stone
fill ~32 ~64 ~4 ~35 ~66 ~4 dirt
fill ~32 ~67 ~4 ~35 ~67 ~4 grass_block
fill ~36 ~60 ~4 ~44 ~64 ~4 stone
fill ~36 ~65 ~4 ~44 ~67 ~4 dirt
fill ~36 ~68 ~4 ~44 ~68 ~4 grass_block
fill ~45 ~60 ~4 ~47 ~65 ~4 stone
fill ~45 ~66 ~4 ~47 ~68 ~4 dirt
fill ~45 ~69 ~4 ~47 ~69 ~4 grass_block
fill ~32 ~60 ~5 ~34 ~64 ~5 stone
fill ~32 ~65 ~5 ~34 ~67 ~5 dirt
fill ~32 ~68 ~5 ~34 ~68 ~5 grass_block
fill ~35 ~60 ~5 ~37 ~63 ~5 stone
fill ~35 ~64 ~5 ~37 ~66 ~5 dirt
fill ~35 ~67 ~5 ~37 ~67 ~5 grass_block
fill ~38 ~60 ~5 ~40 ~64 ~5 stone
fill ~38 ~65 ~5 ~40 ~67 ~5 dirt
fill ~38 ~68 ~5 ~40 ~68 ~5 grass_block
fill ~41 ~60 ~5 ~41 ~63 ~5 stone
fill ~41 ~64 ~5 ~41 ~66 ~5 dirt
fill ~41 ~67 ~5 ~41 ~67 ~5 grass_block
fill ~42 ~60 ~5 ~44 ~64 ~5 stone
fill ~42 ~65 ~5 ~44 ~67 ~5 dirt
fill ~42 ~68 ~5 ~44 ~68 ~5 grass_block
fill ~45 ~60 ~5 ~47 ~65 ~5 stone
fill ~45 ~66 ~5 ~47 ~68 ~5 dirt
fill ~45 ~69 ~5 ~47 ~69 ~5 grass_block
fill ~32 ~60 ~6 ~35 ~64 ~6 stone
fill ~32 ~65 ~6 ~35 ~67 ~6 dirt
fill ~32 ~68 ~6 ~35 ~68 ~6 grass_block
fill ~36 ~60 ~6 ~38 ~63 ~6 stone
fill ~36 ~64 ~6 ~38 ~66 ~6 dirt
fill ~36 ~67 ~6 ~38 ~67 ~6 grass_block
fill ~39 ~60 ~6 ~40 ~64 ~6 stone
fill ~39 ~65 ~6 ~40 ~67 ~6 dirt
fill ~39 ~68 ~6 ~40 ~68 ~6 grass_block
fill ~41 ~60 ~6 ~42 ~63 ~6 stone
fill ~41 ~64 ~6 ~42 ~66 ~6 dirt
fill ~41 ~67 ~6 ~42 ~67 ~6 grass_block
fill ~43 ~60 ~6 ~45 ~64 ~6 stone
fill ~43 ~65 ~6 ~45 ~67 ~6 dirt
fill ~43 ~68 ~6 ~45 ~68 ~6 grass_block
fill ~46 ~60 ~6 ~47 ~65 ~6 stone
fill ~46 ~66 ~6 ~47 ~68 ~6 dirt
fill ~46 ~69 ~6 ~47 ~69 ~6 grass_block
fill ~32 ~60 ~7 ~32 ~65 ~7 stone
fill ~32 ~66 ~7 ~32 ~68 ~7 dirt
fill ~32 ~69 ~7 ~32 ~69 ~7 grass_block
fill ~33 ~60 ~7 ~35 ~64 ~7 stone
fill ~33 ~65 ~7 ~35 ~67 ~7 dirt
fill ~33 ~68 ~7 ~35 ~68 ~7 grass_block
fill ~36 ~60 ~7 ~42 ~63 ~7 stone
fill ~36 ~64 ~7 ~42 ~66 ~7 dirt
fill ~36 ~67 ~7 ~42 ~67 ~7 grass_block
fill ~43 ~60 ~7 ~47 ~64 ~7 stone
fill ~43 ~65 ~7 ~47 ~67 ~7 dirt
fill ~43 ~68 ~7 ~47 ~68 ~7 grass_block
fill ~32 ~60 ~8 ~32 ~65 ~8 stone
fill ~32 ~66 ~8 ~32 ~68 ~8 dirt
fill ~32 ~69 ~8 ~32 ~69 ~8 grass_block
fill ~33 ~60 ~8 ~38 ~64 ~8 stone
fill ~33 ~65 ~8 ~38 ~67 ~8 dirt
fill ~33 ~68 ~8 ~38 ~68 ~8 grass_block
fill ~39 ~60 ~8 ~45 ~63 ~8 stone
fill ~39 ~64 ~8 ~45 ~66 ~8 dirt
fill ~39 ~67 ~8 ~45 ~67 ~8 grass_block
fill ~46 ~60 ~8 ~47 ~64 ~8 stone
fill ~46 ~65 ~8 ~47 ~67 ~8 dirt
fill ~46 ~68 ~8 ~47 ~68 ~8 grass_block
fill ~32 ~60 ~9 ~34 ~65 ~9 stone
fill ~32 ~66 ~9 ~34 ~68 ~9 dirt
fill ~32 ~69 ~9 ~34 ~69 ~9 grass_block
fill ~35 ~60 ~9 ~40 ~64 ~9 stone
fill ~35 ~65 ~9 ~40 ~67 ~9 dirt
fill ~35 ~68 ~9 ~40 ~68 ~9 grass_block
fill ~41 ~60 ~9 ~47 ~63 ~9 stone
fill ~41 ~64 ~9 ~47 ~66 ~9 dirt
fill ~41 ~67 ~9 ~47 ~67 ~9 grass_block
fill ~32 ~60 ~10 ~36 ~65 ~10 stone
fill ~32 ~66 ~10 ~36 ~68 ~10 dirt
fill ~32 ~69 ~10 ~36 ~69 ~10 grass_block
fill ~37 ~60 ~10 ~43 ~64 ~10 stone
fill ~37 ~65 ~10 ~43 ~67 ~10 dirt
fill ~37 ~68 ~10 ~43 ~68 ~10 grass_block
fill ~44 ~60 ~10 ~47 ~63 ~10 stone
fill ~44 ~64 ~10 ~47 ~66 ~10 dirt
fill ~44 ~67 ~10 ~47 ~67 ~10 grass_block
fill ~32 ~60 ~11 ~33 ~66 ~11 stone
fill ~32 ~67 ~11 ~33 ~69 ~11 dirt
fill ~32 ~70 ~11 ~33 ~70 ~11 grass_block
fill ~34 ~60 ~11 ~40 ~65 ~11 stone
fill ~34 ~66 ~11 ~40 ~68 ~11 dirt
fill ~34 ~69 ~11 ~40 ~69 ~11 grass_block
fill ~41 ~60 ~11 ~46 ~64 ~11 stone
fill ~41 ~65 ~11 ~46 ~67 ~11 dirt
fill ~41 ~68 ~11 ~46 ~68 ~11 grass_block
fill ~47 ~60 ~11 ~47 ~63 ~11 stone
fill ~47 ~64 ~11 ~47 ~66 ~11 dirt
fill ~47 ~67 ~11 ~47 ~67 ~11 grass_block
fill ~32 ~60 ~12 ~32 ~67 ~12 stone
fill ~32 ~68 ~12 ~32 ~70 ~12 dirt
fill ~32 ~71 ~12 ~32 ~71 ~12 grass_block
fill ~33 ~60 ~12 ~36 ~66 ~12 stone
fill ~33 ~67 ~12 ~36 ~69 ~12 dirt
fill ~33 ~70 ~12 ~36 ~70 ~12 grass_block
fill ~37 ~60 ~12 ~41 ~65 ~12 stone
fill ~37 ~66 ~12 ~41 ~68 ~12 dirt
fill ~37 ~69 ~12 ~41 ~69 ~12 grass_block
fill ~42 ~60 ~12 ~47 ~64 ~12 stone
fill ~42 ~65 ~12 ~47 ~67 ~12 dirt
fill ~42 ~68 ~12 ~47 ~68 ~12 grass_block
fill ~32 ~60 ~13 ~32 ~68 ~13 stone
fill ~32 ~69 ~13 ~32 ~71 ~13 dirt
fill ~32 ~72 ~13 ~32 ~72 ~13 grass_block
fill ~33 ~60 ~13 ~33 ~67 ~13 stone
fill ~33 ~68 ~13 ~33 ~70 ~13 dirt
fill ~33 ~71 ~13 ~33 ~71 ~13 grass_block
fill ~34 ~60 ~13 ~38 ~66 ~13 stone
fill ~34 ~67 ~13 ~38 ~69 ~13 dirt
fill ~34 ~70 ~13 ~38 ~70 ~13 grass_block
fill ~39 ~60 ~13 ~44 ~65 ~13 stone
fill ~39 ~66 ~13 ~44 ~68 ~13 dirt
fill ~39 ~69 ~13 ~44 ~69 ~13 grass_block
fill ~45 ~60 ~13 ~47 ~64 ~13 stone
fill ~45 ~65 ~13 ~47 ~67 ~13 dirt
fill ~45 ~68 ~13 ~47 ~68 ~13 grass_block
fill ~32 ~60 ~14 ~34 ~68 ~14 stone
fill ~32 ~69 ~14 ~34 ~71 ~14 dirt
fill ~32 ~72 ~14 ~34 ~72 ~14 grass_block
fill ~35 ~60 ~14 ~36 ~67 ~14 stone
fill ~35 ~68 ~14 ~36 ~70 ~14 dirt
fill ~35 ~71 ~14 ~36 ~71 ~14 grass_block
fill ~37 ~60 ~14 ~39 ~66 ~14 stone
fill ~37 ~67 ~14 ~39 ~69 ~14 dirt
fill ~37 ~70 ~14 ~39 ~70 ~14 grass_block
fill ~40 ~60 ~14 ~45 ~65 ~14 stone
fill ~40 ~66 ~14 ~45 ~68 ~14 dirt
fill ~40 ~69 ~14 ~45 ~69 ~14 grass_block
fill ~46 ~60 ~14 ~47 ~64 ~14 stone
fill ~46 ~65 ~14 ~47 ~67 ~14 dirt
fill ~46 ~68 ~14 ~47 ~68 ~14 grass_block
fill ~32 ~60 ~15 ~36 ~68 ~15 stone
fill ~32 ~69 ~15 ~36 ~71 ~15 dirt
fill ~32 ~72 ~15 ~36 ~72 ~15 grass_block
fill ~37 ~60 ~15 ~37 ~67 ~15 stone
fill ~37 ~68 ~15 ~37 ~70 ~15 dirt
fill ~37 ~71 ~15 ~37 ~71 ~15 grass_block
fill ~38 ~60 ~15 ~41 ~66 ~15 stone
fill ~38 ~67 ~15 ~41 ~69 ~15 dirt
fill ~38 ~70 ~15 ~41 ~70 ~15 grass_block
fill ~42 ~60 ~15 ~46 ~65 ~15 stone
fill ~42 ~66 ~15 ~46 ~68 ~15 dirt
fill ~42 ~69 ~15 ~46 ~69 ~15 grass_block
fill ~47 ~60 ~15 ~47 ~64 ~15 stone
fill ~47 ~65 ~15 ~47 ~67 ~15 dirt
fill ~47 ~68 ~15 ~47 ~68 ~15 grass_block