fill ~112 ~60 ~128 ~113 ~65 ~128 stone
fill ~112 ~66 ~128 ~113 ~68 ~128 dirt
fill ~112 ~69 ~128 ~113 ~69 ~128 grass_block
fill ~114 ~60 ~128 ~115 ~64 ~128 stone
fill ~114 ~65 ~128 ~115 ~67 ~128 dirt
fill ~114 ~68 ~128 ~115 ~68 ~128 grass_block
fill ~116 ~60 ~128 ~117 ~65 ~128 stone
fill ~116 ~66 ~128 ~117 ~68 ~128 dirt
fill ~116 ~69 ~128 ~117 ~69 ~128 grass_block
fill ~118 ~60 ~128 ~118 ~66 ~128 stone
fill ~118 ~67 ~128 ~118 ~69 ~128 dirt
fill ~118 ~70 ~128 ~118 ~70 ~128 grass_block
fill ~119 ~60 ~128 ~120 ~65 ~128 stone
fill ~119 ~66 ~128 ~120 ~68 ~128 dirt
fill ~119 ~69 ~128 ~120 ~69 ~128 grass_block
fill ~121 ~60 ~128 ~122 ~64 ~128 stone
fill ~121 ~65 ~128 ~122 ~67 ~128 dirt
fill ~121 ~68 ~128 ~122 ~68 ~128 grass_block
fill ~123 ~60 ~128 ~124 ~65 ~128 stone
fill ~123 ~66 ~128 ~124 ~68 ~128 dirt
fill ~123 ~69 ~128 ~124 ~69 ~128 grass_block
fill ~125 ~60 ~128 ~127 ~66 ~128 stone
fill ~125 ~67 ~128 ~127 ~69 ~128 dirt
fill ~125 ~70 ~128 ~127 ~70 ~128 grass_block
fill ~112 ~60 ~129 ~112 ~65 ~129 stone
fill ~112 ~66 ~129 ~112 ~68 ~129 dirt
fill ~112 ~69 ~129 ~112 ~69 ~129 grass_block
fill ~113 ~60 ~129 ~115 ~64 ~129 stone
fill ~113 ~65 ~129 ~115 ~67 ~129 dirt
fill ~113 ~68 ~129 ~115 ~68 ~129 grass_block
fill ~116 ~60 ~129 ~117 ~65 ~129 stone
fill ~116 ~66 ~129 ~117 ~68 ~129 dirt
fill ~116 ~69 ~129 ~117 ~69 ~129 grass_block
fill ~118 ~60 ~129 ~118 ~66 ~129 stone
fill ~118 ~67 ~129 ~118 ~69 ~129 dirt
fill ~118 ~70 ~129 ~118 ~70 ~129 grass_block
fill ~119 ~60 ~129 ~120 ~65 ~129 stone
fill ~119 ~66 ~129 ~120 ~68 ~129 dirt
fill ~119 ~69 ~129 ~120 ~69 ~129 grass_block
fill ~121 ~60 ~129 ~123 ~64 ~129 stone
fill ~121 ~65 ~129 ~123 ~67 ~129 dirt
fill ~121 ~68 ~129 ~123 ~68 ~129 grass_block
fill ~124 ~60 ~129 ~124 ~65 ~129 stone
fill ~124 ~66 ~129 ~124 ~68 ~129 dirt
fill ~124 ~69 ~129 ~124 ~69 ~129 grass_block
fill ~125 ~60 ~129 ~127 ~66 ~129 stone
fill ~125 ~67 ~129 ~127 ~69 ~129 dirt
fill ~125 ~70 ~129 ~127 ~70 ~129 grass_block
fill ~112 ~60 ~130 ~115 ~64 ~130 stone
fill ~112 ~65 ~130 ~115 ~67 ~130 dirt
fill ~112 ~68 ~130 ~115 ~68 ~130 grass_block
fill ~116 ~60 ~130 ~117 ~65 ~130 stone
fill ~116 ~66 ~130 ~117 ~68 ~130 dirt
fill ~116 ~69 ~130 ~117 ~69 ~130 grass_block
fill ~118 ~60 ~130 ~118 ~66 ~130 stone
fill ~118 ~67 ~130 ~118 ~69 ~130 dirt
fill ~118 ~70 ~130 ~118 ~70 ~130 grass_block
fill ~119 ~60 ~130 ~120 ~65 ~130 stone
fill ~119 ~66 ~130 ~120 ~68 ~130 dirt
fill ~119 ~69 ~130 ~120 ~69 ~130 grass_block
fill ~121 ~60 ~130 ~123 ~64 ~130 stone
fill ~121 ~65 ~130 ~123 ~67 ~130 dirt
fill ~121 ~68 ~130 ~123 ~68 ~130 grass_block
fill ~124 ~60 ~130 ~125 ~65 ~130 stone
fill ~124 ~66 ~130 ~125 ~68 ~130 dirt
fill ~124 ~69 ~130 ~125 ~69 ~130 grass_block
fill ~126 ~60 ~130 ~127 ~66 ~130 stone
fill ~126 ~67 ~130 ~127 ~69 ~130 dirt
fill ~126 ~70 ~130 ~127 ~70 ~130 grass_block
fill ~112 ~60 ~131 ~115 ~64 ~131 stone
fill ~112 ~65 ~131 ~115 ~67 ~131 dirt
fill ~112 ~68 ~131 ~115 ~68 ~131 grass_block
fill ~116 ~60 ~131 ~120 ~65 ~131 stone
fill ~116 ~66 ~131 ~120 ~68 ~131 dirt
fill ~116 ~69 ~131 ~120 ~69 ~131 grass_block
fill ~121 ~60 ~131 ~124 ~64 ~131 stone
fill ~121 ~65 ~131 ~124 ~67 ~131 dirt
fill ~121 ~68 ~131 ~124 ~68 ~131 grass_block
fill ~125 ~60 ~131 ~126 ~65 ~131 stone
fill ~125 ~66 ~131 ~126 ~68 ~131 dirt
fill ~125 ~69 ~131 ~126 ~69 ~131 grass_block
fill ~127 ~60 ~131 ~127 ~66 ~131 stone
fill ~127 ~67 ~131 ~127 ~69 ~131 dirt
fill ~127 ~70 ~131 ~127 ~70 ~131 grass_block
fill ~112 ~60 ~132 ~115 ~64 ~132 stone
fill ~112 ~65 ~132 ~115 ~67 ~132 dirt
fill ~112 ~68 ~132 ~115 ~68 ~132 grass_block
fill ~116 ~60 ~132 ~120 ~65 ~132 stone
fill ~116 ~66 ~132 ~120 ~68 ~132 dirt
fill ~116 ~69 ~132 ~120 ~69 ~132 grass_block
fill ~121 ~60 ~132 ~125 ~64 ~132 stone
fill ~121 ~65 ~132 ~125 ~67 ~132 dirt
fill ~121 ~68 ~132 ~125 ~68 ~132 grass_block
fill ~126 ~60 ~132 ~127 ~65 ~132 stone
fill ~126 ~66 ~132 ~127 ~68 ~132 dirt
fill ~126 ~69 ~132 ~127 ~69 ~132 grass_block
fill ~112 ~60 ~133 ~112 ~64 ~133 stone
fill ~112 ~65 ~133 ~112 ~67 ~133 dirt
fill ~112 ~68 ~133 ~112 ~68 ~133 grass_block
fill ~113 ~60 ~133 ~113 ~63 ~133 stone
fill ~113 ~64 ~133 ~113 ~66 ~133 dirt
fill ~113 ~67 ~133 ~113 ~67 ~133 grass_block
fill ~114 ~60 ~133 ~117 ~64 ~133 stone
fill ~114 ~65 ~133 ~117 ~67 ~133 dirt
fill ~114 ~68 ~133 ~117 ~68 ~133 grass_block
fill ~118 ~60 ~133 ~121 ~65 ~133 stone
fill ~118 ~66 ~133 ~121 ~68 ~133 dirt
fill ~118 ~69 ~133 ~121 ~69 ~133 grass_block
fill ~122 ~60 ~133 ~126 ~64 ~133 stone
fill ~122 ~65 ~133 ~126 ~67 ~133 dirt
fill ~122 ~68 ~133 ~126 ~68 ~133 grass_block
fill ~127 ~60 ~133 ~127 ~65 ~133 stone
fill ~127 ~66 ~133 ~127 ~68 ~133 dirt
fill ~127 ~69 ~133 ~127 ~69 ~133 grass_block
fill ~112 ~60 ~134 ~112 ~64 ~134 stone
fill ~112 ~65 ~134 ~112 ~67 ~134 dirt
fill ~112 ~68 ~134 ~112 ~68 ~134 grass_block
fill ~113 ~60 ~134 ~114 ~63 ~134 stone
fill ~113 ~64 ~134 ~114 ~66 ~134 dirt
fill ~113 ~67 ~134 ~114 ~67 ~134 grass_block
fill ~115 ~60 ~134 ~117 ~64 ~134 stone
fill ~115 ~65 ~134 ~117 ~67 ~134 dirt
fill ~115 ~68 ~134 ~117 ~68 ~134 grass_block
fill ~118 ~60 ~134 ~120 ~65 ~134 stone
fill ~118 ~66 ~134 ~120 ~68 ~134 dirt
fill ~118 ~69 ~134 ~120 ~69 ~134 grass_block
fill ~121 ~60 ~134 ~126 ~64 ~134 stone
fill ~121 ~65 ~134 ~126 ~67 ~134 dirt
fill ~121 ~68 ~134 ~126 ~68 ~134 grass_block
fill ~127 ~60 ~134 ~127 ~65 ~134 stone
fill ~127 ~66 ~134 ~127 ~68 ~134 dirt
fill ~127 ~69 ~134 ~127 ~69 ~134 grass_block
fill ~112 ~60 ~135 ~113 ~64 ~135 stone
fill ~112 ~65 ~135 ~113 ~67 ~135 dirt
fill ~112 ~68 ~135 ~113 ~68 ~135 grass_block
fill ~114 ~60 ~135 ~115 ~63 ~135 stone
fill ~114 ~64 ~135 ~115 ~66 ~135 dirt
fill ~114 ~67 ~135 ~115 ~67 ~135 grass_block
fill ~116 ~60 ~135 ~118 ~64 ~135 stone
fill ~116 ~65 ~135 ~118 ~67 ~135 dirt
fill ~116 ~68 ~135 ~118 ~68 ~135 grass_block
fill ~119 ~60 ~135 ~121 ~65 ~135 stone
fill ~119 ~66 ~135 ~121 ~68 ~135 dirt
fill ~119 ~69 ~135 ~121 ~69 ~135 grass_block
fill ~122 ~60 ~135 ~127 ~64 ~135 stone
fill ~122 ~65 ~135 ~127 ~67 ~135 dirt
fill ~122 ~68 ~135 ~127 ~68 ~135 grass_block
fill ~112 ~60 ~136 ~113 ~64 ~136 stone
fill ~112 ~65 ~136 ~113 ~67 ~136 dirt
fill ~112 ~68 ~136 ~113 ~68 ~136 grass_block
fill ~114 ~60 ~136 ~115 ~63 ~136 stone
fill ~114 ~64 ~136 ~115 ~66 ~136 dirt
fill ~114 ~67 ~136 ~115 ~67 ~136 grass_block
fill ~116 ~60 ~136 ~118 ~64 ~136 stone
fill ~116 ~65 ~136 ~118 ~67 ~136 dirt
fill ~116 ~68 ~136 ~118 ~68 ~136 grass_block
fill ~119 ~60 ~136 ~122 ~65 ~136 stone
fill ~119 ~66 ~136 ~122 ~68 ~136 dirt
fill ~119 ~69 ~136 ~122 ~69 ~136 grass_block
fill ~123 ~60 ~136 ~127 ~64 ~136 stone
fill ~123 ~65 ~136 ~127 ~67 ~136 dirt
fill ~123 ~68 ~136 ~127 ~68 ~136 grass_block
fill ~112 ~60 ~137 ~113 ~64 ~137 stone
fill ~112 ~65 ~137 ~113 ~67 ~137 dirt
fill ~112 ~68 ~137 ~113 ~68 ~137 grass_block
fill ~114 ~60 ~137 ~116 ~63 ~137 stone
fill ~114 ~64 ~137 ~116 ~66 ~137 dirt
fill ~114 ~67 ~137 ~116 ~67 ~137 grass_block
fill ~117 ~60 ~137 ~119 ~64 ~137 stone
fill ~117 ~65 ~137 ~119 ~67 ~137 dirt
fill ~117 ~68 ~137 ~119 ~68 ~137 grass_block
fill ~120 ~60 ~137 ~122 ~65 ~137 stone
fill ~120 ~66 ~137 ~122 ~68 ~137 dirt
fill ~120 ~69 ~137 ~122 ~69 ~137 grass_block
fill ~123 ~60 ~137 ~125 ~64 ~137 stone
fill ~123 ~65 ~137 ~125 ~67 ~137 dirt
fill ~123 ~68 ~137 ~125 ~68 ~137 grass_block
fill ~126 ~60 ~137 ~126 ~63 ~137 stone
fill ~126 ~64 ~137 ~126 ~66 ~137 dirt
fill ~126 ~67 ~137 ~126 ~67 ~137 grass_block
fill ~127 ~60 ~137 ~127 ~64 ~137 stone
fill ~127 ~65 ~137 ~127 ~67 ~137 dirt
fill ~127 ~68 ~137 ~127 ~68 ~137 grass_block
fill ~112 ~60 ~138 ~114 ~64 ~138 stone
fill ~112 ~65 ~138 ~114 ~67 ~138 dirt
fill ~112 ~68 ~138 ~114 ~68 ~138 grass_block
fill ~115 ~60 ~138 ~116 ~63 ~138 stone
fill ~115 ~64 ~138 ~116 ~66 ~138 dirt
fill ~115 ~67 ~138 ~116 ~67 ~138 grass_block
fill ~117 ~60 ~138 ~119 ~64 ~138 stone
fill ~117 ~65 ~138 ~119 ~67 ~138 dirt
fill ~117 ~68 ~138 ~119 ~68 ~138 grass_block
fill ~120 ~60 ~138 ~122 ~65 ~138 stone
fill ~120 ~66 ~138 ~122 ~68 ~138 dirt
fill ~120 ~69 ~138 ~122 ~69 ~138 grass_block
fill ~123 ~60 ~138 ~125 ~64 ~138 stone
fill ~123 ~65 ~138 ~125 ~67 ~138 dirt
fill ~123 ~68 ~138 ~125 ~68 ~138 grass_block
fill ~126 ~60 ~138 ~126 ~63 ~138 stone
fill ~126 ~64 ~138 ~126 ~66 ~138 dirt
fill ~126 ~67 ~138 ~126 ~67 ~138 grass_block
fill ~127 ~60 ~138 ~127 ~64 ~138 stone
fill ~127 ~65 ~138 ~127 ~67 ~138 dirt
fill ~127 ~68 ~138 ~127 ~68 ~138 grass_block
fill ~112 ~60 ~139 ~112 ~64 ~139 stone
fill ~112 ~65 ~139 ~112 ~67 ~139 dirt
fill ~112 ~68 ~139 ~112 ~68 ~139 grass_block
fill ~113 ~60 ~139 ~116 ~63 ~139 stone
fill ~113 ~64 ~139 ~116 ~66 ~139 dirt
fill ~113 ~67 ~139 ~116 ~67 ~139 grass_block
fill ~117 ~60 ~139 ~120 ~64 ~139 stone
fill ~117 ~65 ~139 ~120 ~67 ~139 dirt
fill ~117 ~68 ~139 ~120 ~68 ~139 grass_block
fill ~121 ~60 ~139 ~122 ~65 ~139 stone
fill ~121 ~66 ~139 ~122 ~68 ~139 dirt
fill ~121 ~69 ~139 ~122 ~69 ~139 grass_block
fill ~123 ~60 ~139 ~126 ~64 ~139 stone
fill ~123 ~65 ~139 ~126 ~67 ~139 dirt
fill ~123 ~68 ~139 ~126 ~68 ~139 grass_block
fill ~127 ~60 ~139 ~127 ~63 ~139 stone
fill ~127 ~64 ~139 ~127 ~66 ~139 dirt
fill ~127 ~67 ~139 ~127 ~67 ~139 grass_block
fill ~112 ~60 ~140 ~117 ~63 ~140 stone
fill ~112 ~64 ~140 ~117 ~66 ~140 dirt
fill ~112 ~67 ~140 ~117 ~67 ~140 grass_block
fill ~118 ~60 ~140 ~126 ~64 ~140 stone
fill ~118 ~65 ~140 ~126 ~67 ~140 dirt
fill ~118 ~68 ~140 ~126 ~68 ~140 grass_block
fill ~127 ~60 ~140 ~127 ~63 ~140 stone
fill ~127 ~64 ~140 ~127 ~66 ~140 dirt
fill ~127 ~67 ~140 ~127 ~67 ~140 grass_block
fill ~112 ~60 ~141 ~117 ~63 ~141 stone
fill ~112 ~64 ~141 ~117 ~66 ~141 dirt
fill ~112 ~67 ~141 ~117 ~67 ~141 grass_block
fill ~118 ~60 ~141 ~126 ~64 ~141 stone
fill ~118 ~65 ~141 ~126 ~67 ~141 dirt
fill ~118 ~68 ~141 ~126 ~68 ~141 grass_block
fill ~127 ~60 ~141 ~127 ~63 ~141 stone
fill ~127 ~64 ~141 ~127 ~66 ~141 dirt
fill ~127 ~67 ~141 ~127 ~67 ~141 grass_block
fill ~112 ~60 ~142 ~120 ~63 ~142 stone
fill ~112 ~64 ~142 ~120 ~66 ~142 dirt
fill ~112 ~67 ~142 ~120 ~67 ~142 grass_block
fill ~121 ~60 ~142 ~126 ~64 ~142 stone
fill ~121 ~65 ~142 ~126 ~67 ~142 dirt
fill ~121 ~68 ~142 ~126 ~68 ~142 grass_block
fill ~127 ~60 ~142 ~127 ~63 ~142 stone
fill ~127 ~64 ~142 ~127 ~66 ~142 dirt
fill ~127 ~67 ~142 ~127 ~67 ~142 grass_block
fill ~112 ~60 ~143 ~122 ~63 ~143 stone
fill ~112 ~64 ~143 ~122 ~66 ~143 dirt
fill ~112 ~67 ~143 ~122 ~67 ~143 grass_block
fill ~123 ~60 ~143 ~126 ~64 ~143 stone
fill ~123 ~65 ~143 ~126 ~67 ~143 dirt
fill ~123 ~68 ~143 ~126 ~68 ~143 grass_block
fill ~127 ~60 ~143 ~127 ~63 ~143 stone
fill ~127 ~64 ~143 ~127 ~66 ~143 dirt
fill ~127 ~67 ~143 ~127 ~67 ~143 grass_block