fill ~192 ~60 ~32 ~194 ~64 ~32 stone
fill ~192 ~65 ~32 ~194 ~67 ~32 dirt
fill ~192 ~68 ~32 ~194 ~68 ~32 grass_block
fill ~195 ~60 ~32 ~197 ~63 ~32 stone
fill ~195 ~64 ~32 ~197 ~66 ~32 dirt
fill ~195 ~67 ~32 ~197 ~67 ~32 grass_block
fill ~198 ~60 ~32 ~198 ~64 ~32 stone
fill ~198 ~65 ~32 ~198 ~67 ~32 dirt
fill ~198 ~68 ~32 ~198 ~68 ~32 grass_block
fill ~199 ~60 ~32 ~202 ~63 ~32 stone
fill ~199 ~64 ~32 ~202 ~66 ~32 dirt
fill ~199 ~67 ~32 ~202 ~67 ~32 grass_block
fill ~203 ~60 ~32 ~205 ~62 ~32 stone
fill ~203 ~63 ~32 ~205 ~65 ~32 dirt
fill ~203 ~66 ~32 ~205 ~66 ~32 grass_block
fill ~206 ~60 ~32 ~207 ~61 ~32 stone
fill ~206 ~62 ~32 ~207 ~64 ~32 dirt
fill ~206 ~65 ~32 ~207 ~65 ~32 grass_block
fill ~192 ~60 ~33 ~200 ~64 ~33 stone
fill ~192 ~65 ~33 ~200 ~67 ~33 dirt
fill ~192 ~68 ~33 ~200 ~68 ~33 grass_block
fill ~201 ~60 ~33 ~203 ~63 ~33 stone
fill ~201 ~64 ~33 ~203 ~66 ~33 dirt
fill ~201 ~67 ~33 ~203 ~67 ~33 grass_block
fill ~204 ~60 ~33 ~206 ~62 ~33 stone
fill ~204 ~63 ~33 ~206 ~65 ~33 dirt
fill ~204 ~66 ~33 ~206 ~66 ~33 grass_block
fill ~207 ~60 ~33 ~207 ~61 ~33 stone
fill ~207 ~62 ~33 ~207 ~64 ~33 dirt
fill ~207 ~65 ~33 ~207 ~65 ~33 grass_block
fill ~192 ~60 ~34 ~201 ~64 ~34 stone
fill ~192 ~65 ~34 ~201 ~67 ~34 dirt
fill ~192 ~68 ~34 ~201 ~68 ~34 grass_block
fill ~202 ~60 ~34 ~204 ~63 ~34 stone
fill ~202 ~64 ~34 ~204 ~66 ~34 dirt
fill ~202 ~67 ~34 ~204 ~67 ~34 grass_block
fill ~205 ~60 ~34 ~207 ~62 ~34 stone
fill ~205 ~63 ~34 ~207 ~65 ~34 dirt
fill ~205 ~66 ~34 ~207 ~66 ~34 grass_block
fill ~192 ~60 ~35 ~192 ~65 ~35 stone
fill ~192 ~66 ~35 ~192 ~68 ~35 dirt
fill ~192 ~69 ~35 ~192 ~69 ~35 grass_block
fill ~193 ~60 ~35 ~201 ~64 ~35 stone
fill ~193 ~65 ~35 ~201 ~67 ~35 dirt
fill ~193 ~68 ~35 ~201 ~68 ~35 grass_block
fill ~202 ~60 ~35 ~204 ~63 ~35 stone
fill ~202 ~64 ~35 ~204 ~66 ~35 dirt
fill ~202 ~67 ~35 ~204 ~67 ~35 grass_block
fill ~205 ~60 ~35 ~207 ~62 ~35 stone
fill ~205 ~63 ~35 ~207 ~65 ~35 dirt
fill ~205 ~66 ~35 ~207 ~66 ~35 grass_block
fill ~192 ~60 ~36 ~193 ~65 ~36 stone
fill ~192 ~66 ~36 ~193 ~68 ~36 dirt
fill ~192 ~69 ~36 ~193 ~69 ~36 grass_block
fill ~194 ~60 ~36 ~202 ~64 ~36 stone
fill ~194 ~65 ~36 ~202 ~67 ~36 dirt
fill ~194 ~68 ~36 ~202 ~68 ~36 grass_block
fill ~203 ~60 ~36 ~205 ~63 ~36 stone
fill ~203 ~64 ~36 ~205 ~66 ~36 dirt
fill ~203 ~67 ~36 ~205 ~67 ~36 grass_block
fill ~206 ~60 ~36 ~207 ~62 ~36 stone
fill ~206 ~63 ~36 ~207 ~65 ~36 dirt
fill ~206 ~66 ~36 ~207 ~66 ~36 grass_block
fill ~192 ~60 ~37 ~197 ~65 ~37 stone
fill ~192 ~66 ~37 ~197 ~68 ~37 dirt
fill ~192 ~69 ~37 ~197 ~69 ~37 grass_block
fill ~198 ~60 ~37 ~203 ~64 ~37 stone
fill ~198 ~65 ~37 ~203 ~67 ~37 dirt
fill ~198 ~68 ~37 ~203 ~68 ~37 grass_block
fill ~204 ~60 ~37 ~206 ~63 ~37 stone
fill ~204 ~64 ~37 ~206 ~66 ~37 dirt
fill ~204 ~67 ~37 ~206 ~67 ~37 grass_block
fill ~207 ~60 ~37 ~207 ~62 ~37 stone
fill ~207 ~63 ~37 ~207 ~65 ~37 dirt
fill ~207 ~66 ~37 ~207 ~66 ~37 grass_block
fill ~192 ~60 ~38 ~197 ~65 ~38 stone
fill ~192 ~66 ~38 ~197 ~68 ~38 dirt
fill ~192 ~69 ~38 ~197 ~69 ~38 grass_block
fill ~198 ~60 ~38 ~203 ~64 ~38 stone
fill ~198 ~65 ~38 ~203 ~67 ~38 dirt
fill ~198 ~68 ~38 ~203 ~68 ~38 grass_block
fill ~204 ~60 ~38 ~207 ~63 ~38 stone
fill ~204 ~64 ~38 ~207 ~66 ~38 dirt
fill ~204 ~67 ~38 ~207 ~67 ~38 grass_block
fill ~192 ~60 ~39 ~197 ~65 ~39 stone
fill ~192 ~66 ~39 ~197 ~68 ~39 dirt
fill ~192 ~69 ~39 ~197 ~69 ~39 grass_block
fill ~198 ~60 ~39 ~205 ~64 ~39 stone
fill ~198 ~65 ~39 ~205 ~67 ~39 dirt
fill ~198 ~68 ~39 ~205 ~68 ~39 grass_block
fill ~206 ~60 ~39 ~207 ~63 ~39 stone
fill ~206 ~64 ~39 ~207 ~66 ~39 dirt
fill ~206 ~67 ~39 ~207 ~67 ~39 grass_block
fill ~192 ~60 ~40 ~199 ~65 ~40 stone
fill ~192 ~66 ~40 ~199 ~68 ~40 dirt
fill ~192 ~69 ~40 ~199 ~69 ~40 grass_block
fill ~200 ~60 ~40 ~207 ~64 ~40 stone
fill ~200 ~65 ~40 ~207 ~67 ~40 dirt
fill ~200 ~68 ~40 ~207 ~68 ~40 grass_block
fill ~192 ~60 ~41 ~198 ~65 ~41 stone
fill ~192 ~66 ~41 ~198 ~68 ~41 dirt
fill ~192 ~69 ~41 ~198 ~69 ~41 grass_block
fill ~199 ~60 ~41 ~207 ~64 ~41 stone
fill ~199 ~65 ~41 ~207 ~67 ~41 dirt
fill ~199 ~68 ~41 ~207 ~68 ~41 grass_block
fill ~192 ~60 ~42 ~193 ~64 ~42 stone
fill ~192 ~65 ~42 ~193 ~67 ~42 dirt
fill ~192 ~68 ~42 ~193 ~68 ~42 grass_block
fill ~194 ~60 ~42 ~200 ~65 ~42 stone
fill ~194 ~66 ~42 ~200 ~68 ~42 dirt
fill ~194 ~69 ~42 ~200 ~69 ~42 grass_block
fill ~201 ~60 ~42 ~207 ~64 ~42 stone
fill ~201 ~65 ~42 ~207 ~67 ~42 dirt
fill ~201 ~68 ~42 ~207 ~68 ~42 grass_block
fill ~192 ~60 ~43 ~195 ~64 ~43 stone
fill ~192 ~65 ~43 ~195 ~67 ~43 dirt
fill ~192 ~68 ~43 ~195 ~68 ~43 grass_block
fill ~196 ~60 ~43 ~200 ~65 ~43 stone
fill ~196 ~66 ~43 ~200 ~68 ~43 dirt
fill ~196 ~69 ~43 ~200 ~69 ~43 grass_block
fill ~201 ~60 ~43 ~207 ~64 ~43 stone
fill ~201 ~65 ~43 ~207 ~67 ~43 dirt
fill ~201 ~68 ~43 ~207 ~68 ~43 grass_block
fill ~192 ~60 ~44 ~198 ~64 ~44 stone
fill ~192 ~65 ~44 ~198 ~67 ~44 dirt
fill ~192 ~68 ~44 ~198 ~68 ~44 grass_block
fill ~199 ~60 ~44 ~199 ~65 ~44 stone
fill ~199 ~66 ~44 ~199 ~68 ~44 dirt
fill ~199 ~69 ~44 ~199 ~69 ~44 grass_block
fill ~200 ~60 ~44 ~207 ~64 ~44 stone
fill ~200 ~65 ~44 ~207 ~67 ~44 dirt
fill ~200 ~68 ~44 ~207 ~68 ~44 grass_block
fill ~192 ~60 ~45 ~193 ~63 ~45 stone
fill ~192 ~64 ~45 ~193 ~66 ~45 dirt
fill ~192 ~67 ~45 ~193 ~67 ~45 grass_block
fill ~194 ~60 ~45 ~199 ~64 ~45 stone
fill ~194 ~65 ~45 ~199 ~67 ~45 dirt
fill ~194 ~68 ~45 ~199 ~68 ~45 grass_block
fill ~200 ~60 ~45 ~203 ~65 ~45 stone
fill ~200 ~66 ~45 ~203 ~68 ~45 dirt
fill ~200 ~69 ~45 ~203 ~69 ~45 grass_block
fill ~204 ~60 ~45 ~207 ~64 ~45 stone
fill ~204 ~65 ~45 ~207 ~67 ~45 dirt
fill ~204 ~68 ~45 ~207 ~68 ~45 grass_block
fill ~192 ~60 ~46 ~195 ~63 ~46 stone
fill ~192 ~64 ~46 ~195 ~66 ~46 dirt
fill ~192 ~67 ~46 ~195 ~67 ~46 grass_block
fill ~196 ~60 ~46 ~202 ~64 ~46 stone
fill ~196 ~65 ~46 ~202 ~67 ~46 dirt
fill ~196 ~68 ~46 ~202 ~68 ~46 grass_block
fill ~203 ~60 ~46 ~204 ~65 ~46 stone
fill ~203 ~66 ~46 ~204 ~68 ~46 dirt
fill ~203 ~69 ~46 ~204 ~69 ~46 grass_block
fill ~205 ~60 ~46 ~207 ~64 ~46 stone
fill ~205 ~65 ~46 ~207 ~67 ~46 dirt
fill ~205 ~68 ~46 ~207 ~68 ~46 grass_block
fill ~192 ~60 ~47 ~192 ~64 ~47 stone
fill ~192 ~65 ~47 ~192 ~67 ~47 dirt
fill ~192 ~68 ~47 ~192 ~68 ~47 grass_block
fill ~193 ~60 ~47 ~197 ~63 ~47 stone
fill ~193 ~64 ~47 ~197 ~66 ~47 dirt
fill ~193 ~67 ~47 ~197 ~67 ~47 grass_block
fill ~198 ~60 ~47 ~203 ~64 ~47 stone
fill ~198 ~65 ~47 ~203 ~67 ~47 dirt
fill ~198 ~68 ~47 ~203 ~68 ~47 grass_block
fill ~204 ~60 ~47 ~204 ~65 ~47 stone
fill ~204 ~66 ~47 ~204 ~68 ~47 dirt
fill ~204 ~69 ~47 ~204 ~69 ~47 grass_block
fill ~205 ~60 ~47 ~207 ~64 ~47 stone
fill ~205 ~65 ~47 ~207 ~67 ~47 dirt
fill ~205 ~68 ~47 ~207 ~68 ~47 grass_block