fill ~432 ~60 ~48 ~433 ~63 ~48 stone
fill ~432 ~64 ~48 ~433 ~66 ~48 dirt
fill ~432 ~67 ~48 ~433 ~67 ~48 grass_block
fill ~434 ~60 ~48 ~437 ~62 ~48 stone
fill ~434 ~63 ~48 ~437 ~65 ~48 dirt
fill ~434 ~66 ~48 ~437 ~66 ~48 grass_block
fill ~438 ~60 ~48 ~439 ~63 ~48 stone
fill ~438 ~64 ~48 ~439 ~66 ~48 dirt
fill ~438 ~67 ~48 ~439 ~67 ~48 grass_block
fill ~440 ~60 ~48 ~441 ~64 ~48 stone
fill ~440 ~65 ~48 ~441 ~67 ~48 dirt
fill ~440 ~68 ~48 ~441 ~68 ~48 grass_block
fill ~442 ~60 ~48 ~447 ~65 ~48 stone
fill ~442 ~66 ~48 ~447 ~68 ~48 dirt
fill ~442 ~69 ~48 ~447 ~69 ~48 grass_block
fill ~432 ~60 ~49 ~437 ~62 ~49 stone
fill ~432 ~63 ~49 ~437 ~65 ~49 dirt
fill ~432 ~66 ~49 ~437 ~66 ~49 grass_block
fill ~438 ~60 ~49 ~439 ~63 ~49 stone
fill ~438 ~64 ~49 ~439 ~66 ~49 dirt
fill ~438 ~67 ~49 ~439 ~67 ~49 grass_block
fill ~440 ~60 ~49 ~441 ~64 ~49 stone
fill ~440 ~65 ~49 ~441 ~67 ~49 dirt
fill ~440 ~68 ~49 ~441 ~68 ~49 grass_block
fill ~442 ~60 ~49 ~447 ~65 ~49 stone
fill ~442 ~66 ~49 ~447 ~68 ~49 dirt
fill ~442 ~69 ~49 ~447 ~69 ~49 grass_block
fill ~432 ~60 ~50 ~433 ~62 ~50 stone
fill ~432 ~63 ~50 ~433 ~65 ~50 dirt
fill ~432 ~66 ~50 ~433 ~66 ~50 grass_block
fill ~434 ~60 ~50 ~436 ~63 ~50 stone
fill ~434 ~64 ~50 ~436 ~66 ~50 dirt
fill ~434 ~67 ~50 ~436 ~67 ~50 grass_block
fill ~437 ~60 ~50 ~437 ~62 ~50 stone
fill ~437 ~63 ~50 ~437 ~65 ~50 dirt
fill ~437 ~66 ~50 ~437 ~66 ~50 grass_block
fill ~438 ~60 ~50 ~439 ~63 ~50 stone
fill ~438 ~64 ~50 ~439 ~66 ~50 dirt
fill ~438 ~67 ~50 ~439 ~67 ~50 grass_block
fill ~440 ~60 ~50 ~441 ~64 ~50 stone
fill ~440 ~65 ~50 ~441 ~67 ~50 dirt
fill ~440 ~68 ~50 ~441 ~68 ~50 grass_block
fill ~442 ~60 ~50 ~446 ~65 ~50 stone
fill ~442 ~66 ~50 ~446 ~68 ~50 dirt
fill ~442 ~69 ~50 ~446 ~69 ~50 grass_block
fill ~447 ~60 ~50 ~447 ~64 ~50 stone
fill ~447 ~65 ~50 ~447 ~67 ~50 dirt
fill ~447 ~68 ~50 ~447 ~68 ~50 grass_block
fill ~432 ~60 ~51 ~432 ~62 ~51 stone
fill ~432 ~63 ~51 ~432 ~65 ~51 dirt
fill ~432 ~66 ~51 ~432 ~66 ~51 grass_block
fill ~433 ~60 ~51 ~439 ~63 ~51 stone
fill ~433 ~64 ~51 ~439 ~66 ~51 dirt
fill ~433 ~67 ~51 ~439 ~67 ~51 grass_block
fill ~440 ~60 ~51 ~441 ~64 ~51 stone
fill ~440 ~65 ~51 ~441 ~67 ~51 dirt
fill ~440 ~68 ~51 ~441 ~68 ~51 grass_block
fill ~442 ~60 ~51 ~445 ~65 ~51 stone
fill ~442 ~66 ~51 ~445 ~68 ~51 dirt
fill ~442 ~69 ~51 ~445 ~69 ~51 grass_block
fill ~446 ~60 ~51 ~447 ~64 ~51 stone
fill ~446 ~65 ~51 ~447 ~67 ~51 dirt
fill ~446 ~68 ~51 ~447 ~68 ~51 grass_block
fill ~432 ~60 ~52 ~432 ~62 ~52 stone
fill ~432 ~63 ~52 ~432 ~65 ~52 dirt
fill ~432 ~66 ~52 ~432 ~66 ~52 grass_block
fill ~433 ~60 ~52 ~439 ~63 ~52 stone
fill ~433 ~64 ~52 ~439 ~66 ~52 dirt
fill ~433 ~67 ~52 ~439 ~67 ~52 grass_block
fill ~440 ~60 ~52 ~441 ~64 ~52 stone
fill ~440 ~65 ~52 ~441 ~67 ~52 dirt
fill ~440 ~68 ~52 ~441 ~68 ~52 grass_block
fill ~442 ~60 ~52 ~442 ~65 ~52 stone
fill ~442 ~66 ~52 ~442 ~68 ~52 dirt
fill ~442 ~69 ~52 ~442 ~69 ~52 grass_block
fill ~443 ~60 ~52 ~443 ~66 ~52 stone
fill ~443 ~67 ~52 ~443 ~69 ~52 dirt
fill ~443 ~70 ~52 ~443 ~70 ~52 grass_block
fill ~444 ~60 ~52 ~446 ~65 ~52 stone
fill ~444 ~66 ~52 ~446 ~68 ~52 dirt
fill ~444 ~69 ~52 ~446 ~69 ~52 grass_block
fill ~447 ~60 ~52 ~447 ~64 ~52 stone
fill ~447 ~65 ~52 ~447 ~67 ~52 dirt
fill ~447 ~68 ~52 ~447 ~68 ~52 grass_block
fill ~432 ~60 ~53 ~434 ~63 ~53 stone
fill ~432 ~64 ~53 ~434 ~66 ~53 dirt
fill ~432 ~67 ~53 ~434 ~67 ~53 grass_block
fill ~435 ~60 ~53 ~436 ~64 ~53 stone
fill ~435 ~65 ~53 ~436 ~67 ~53 dirt
fill ~435 ~68 ~53 ~436 ~68 ~53 grass_block
fill ~437 ~60 ~53 ~439 ~63 ~53 stone
fill ~437 ~64 ~53 ~439 ~66 ~53 dirt
fill ~437 ~67 ~53 ~439 ~67 ~53 grass_block
fill ~440 ~60 ~53 ~441 ~64 ~53 stone
fill ~440 ~65 ~53 ~441 ~67 ~53 dirt
fill ~440 ~68 ~53 ~441 ~68 ~53 grass_block
fill ~442 ~60 ~53 ~442 ~65 ~53 stone
fill ~442 ~66 ~53 ~442 ~68 ~53 dirt
fill ~442 ~69 ~53 ~442 ~69 ~53 grass_block
fill ~443 ~60 ~53 ~444 ~66 ~53 stone
fill ~443 ~67 ~53 ~444 ~69 ~53 dirt
fill ~443 ~70 ~53 ~444 ~70 ~53 grass_block
fill ~445 ~60 ~53 ~446 ~65 ~53 stone
fill ~445 ~66 ~53 ~446 ~68 ~53 dirt
fill ~445 ~69 ~53 ~446 ~69 ~53 grass_block
fill ~447 ~60 ~53 ~447 ~64 ~53 stone
fill ~447 ~65 ~53 ~447 ~67 ~53 dirt
fill ~447 ~68 ~53 ~447 ~68 ~53 grass_block
fill ~432 ~60 ~54 ~435 ~63 ~54 stone
fill ~432 ~64 ~54 ~435 ~66 ~54 dirt
fill ~432 ~67 ~54 ~435 ~67 ~54 grass_block
fill ~436 ~60 ~54 ~438 ~64 ~54 stone
fill ~436 ~65 ~54 ~438 ~67 ~54 dirt
fill ~436 ~68 ~54 ~438 ~68 ~54 grass_block
fill ~439 ~60 ~54 ~439 ~63 ~54 stone
fill ~439 ~64 ~54 ~439 ~66 ~54 dirt
fill ~439 ~67 ~54 ~439 ~67 ~54 grass_block
fill ~440 ~60 ~54 ~441 ~64 ~54 stone
fill ~440 ~65 ~54 ~441 ~67 ~54 dirt
fill ~440 ~68 ~54 ~441 ~68 ~54 grass_block
fill ~442 ~60 ~54 ~443 ~65 ~54 stone
fill ~442 ~66 ~54 ~443 ~68 ~54 dirt
fill ~442 ~69 ~54 ~443 ~69 ~54 grass_block
fill ~444 ~60 ~54 ~444 ~66 ~54 stone
fill ~444 ~67 ~54 ~444 ~69 ~54 dirt
fill ~444 ~70 ~54 ~444 ~70 ~54 grass_block
fill ~445 ~60 ~54 ~447 ~65 ~54 stone
fill ~445 ~66 ~54 ~447 ~68 ~54 dirt
fill ~445 ~69 ~54 ~447 ~69 ~54 grass_block
fill ~432 ~60 ~55 ~434 ~63 ~55 stone
fill ~432 ~64 ~55 ~434 ~66 ~55 dirt
fill ~432 ~67 ~55 ~434 ~67 ~55 grass_block
fill ~435 ~60 ~55 ~436 ~64 ~55 stone
fill ~435 ~65 ~55 ~436 ~67 ~55 dirt
fill ~435 ~68 ~55 ~436 ~68 ~55 grass_block
fill ~437 ~60 ~55 ~437 ~65 ~55 stone
fill ~437 ~66 ~55 ~437 ~68 ~55 dirt
fill ~437 ~69 ~55 ~437 ~69 ~55 grass_block
fill ~438 ~60 ~55 ~441 ~64 ~55 stone
fill ~438 ~65 ~55 ~441 ~67 ~55 dirt
fill ~438 ~68 ~55 ~441 ~68 ~55 grass_block
fill ~442 ~60 ~55 ~442 ~65 ~55 stone
fill ~442 ~66 ~55 ~442 ~68 ~55 dirt
fill ~442 ~69 ~55 ~442 ~69 ~55 grass_block
fill ~443 ~60 ~55 ~445 ~66 ~55 stone
fill ~443 ~67 ~55 ~445 ~69 ~55 dirt
fill ~443 ~70 ~55 ~445 ~70 ~55 grass_block
fill ~446 ~60 ~55 ~447 ~65 ~55 stone
fill ~446 ~66 ~55 ~447 ~68 ~55 dirt
fill ~446 ~69 ~55 ~447 ~69 ~55 grass_block
fill ~432 ~60 ~56 ~434 ~63 ~56 stone
fill ~432 ~64 ~56 ~434 ~66 ~56 dirt
fill ~432 ~67 ~56 ~434 ~67 ~56 grass_block
fill ~435 ~60 ~56 ~435 ~64 ~56 stone
fill ~435 ~65 ~56 ~435 ~67 ~56 dirt
fill ~435 ~68 ~56 ~435 ~68 ~56 grass_block
fill ~436 ~60 ~56 ~439 ~65 ~56 stone
fill ~436 ~66 ~56 ~439 ~68 ~56 dirt
fill ~436 ~69 ~56 ~439 ~69 ~56 grass_block
fill ~440 ~60 ~56 ~441 ~64 ~56 stone
fill ~440 ~65 ~56 ~441 ~67 ~56 dirt
fill ~440 ~68 ~56 ~441 ~68 ~56 grass_block
fill ~442 ~60 ~56 ~443 ~65 ~56 stone
fill ~442 ~66 ~56 ~443 ~68 ~56 dirt
fill ~442 ~69 ~56 ~443 ~69 ~56 grass_block
fill ~444 ~60 ~56 ~446 ~66 ~56 stone
fill ~444 ~67 ~56 ~446 ~69 ~56 dirt
fill ~444 ~70 ~56 ~446 ~70 ~56 grass_block
fill ~447 ~60 ~56 ~447 ~65 ~56 stone
fill ~447 ~66 ~56 ~447 ~68 ~56 dirt
fill ~447 ~69 ~56 ~447 ~69 ~56 grass_block
fill ~432 ~60 ~57 ~434 ~63 ~57 stone
fill ~432 ~64 ~57 ~434 ~66 ~57 dirt
fill ~432 ~67 ~57 ~434 ~67 ~57 grass_block
fill ~435 ~60 ~57 ~435 ~64 ~57 stone
fill ~435 ~65 ~57 ~435 ~67 ~57 dirt
fill ~435 ~68 ~57 ~435 ~68 ~57 grass_block
fill ~436 ~60 ~57 ~439 ~65 ~57 stone
fill ~436 ~66 ~57 ~439 ~68 ~57 dirt
fill ~436 ~69 ~57 ~439 ~69 ~57 grass_block
fill ~440 ~60 ~57 ~441 ~64 ~57 stone
fill ~440 ~65 ~57 ~441 ~67 ~57 dirt
fill ~440 ~68 ~57 ~441 ~68 ~57 grass_block
fill ~442 ~60 ~57 ~443 ~65 ~57 stone
fill ~442 ~66 ~57 ~443 ~68 ~57 dirt
fill ~442 ~69 ~57 ~443 ~69 ~57 grass_block
fill ~444 ~60 ~57 ~447 ~66 ~57 stone
fill ~444 ~67 ~57 ~447 ~69 ~57 dirt
fill ~444 ~70 ~57 ~447 ~70 ~57 grass_block
fill ~432 ~60 ~58 ~432 ~64 ~58 stone
fill ~432 ~65 ~58 ~432 ~67 ~58 dirt
fill ~432 ~68 ~58 ~432 ~68 ~58 grass_block
fill ~433 ~60 ~58 ~433 ~63 ~58 stone
fill ~433 ~64 ~58 ~433 ~66 ~58 dirt
fill ~433 ~67 ~58 ~433 ~67 ~58 grass_block
fill ~434 ~60 ~58 ~435 ~64 ~58 stone
fill ~434 ~65 ~58 ~435 ~67 ~58 dirt
fill ~434 ~68 ~58 ~435 ~68 ~58 grass_block
fill ~436 ~60 ~58 ~437 ~65 ~58 stone
fill ~436 ~66 ~58 ~437 ~68 ~58 dirt
fill ~436 ~69 ~58 ~437 ~69 ~58 grass_block
fill ~438 ~60 ~58 ~438 ~66 ~58 stone
fill ~438 ~67 ~58 ~438 ~69 ~58 dirt
fill ~438 ~70 ~58 ~438 ~70 ~58 grass_block
fill ~439 ~60 ~58 ~443 ~65 ~58 stone
fill ~439 ~66 ~58 ~443 ~68 ~58 dirt
fill ~439 ~69 ~58 ~443 ~69 ~58 grass_block
fill ~444 ~60 ~58 ~447 ~66 ~58 stone
fill ~444 ~67 ~58 ~447 ~69 ~58 dirt
fill ~444 ~70 ~58 ~447 ~70 ~58 grass_block
fill ~432 ~60 ~59 ~435 ~64 ~59 stone
fill ~432 ~65 ~59 ~435 ~67 ~59 dirt
fill ~432 ~68 ~59 ~435 ~68 ~59 grass_block
fill ~436 ~60 ~59 ~437 ~65 ~59 stone
fill ~436 ~66 ~59 ~437 ~68 ~59 dirt
fill ~436 ~69 ~59 ~437 ~69 ~59 grass_block
fill ~438 ~60 ~59 ~439 ~66 ~59 stone
fill ~438 ~67 ~59 ~439 ~69 ~59 dirt
fill ~438 ~70 ~59 ~439 ~70 ~59 grass_block
fill ~440 ~60 ~59 ~443 ~65 ~59 stone
fill ~440 ~66 ~59 ~443 ~68 ~59 dirt
fill ~440 ~69 ~59 ~443 ~69 ~59 grass_block
fill ~444 ~60 ~59 ~447 ~66 ~59 stone
fill ~444 ~67 ~59 ~447 ~69 ~59 dirt
fill ~444 ~70 ~59 ~447 ~70 ~59 grass_block
fill ~432 ~60 ~60 ~436 ~64 ~60 stone
fill ~432 ~65 ~60 ~436 ~67 ~60 dirt
fill ~432 ~68 ~60 ~436 ~68 ~60 grass_block
fill ~437 ~60 ~60 ~437 ~65 ~60 stone
fill ~437 ~66 ~60 ~437 ~68 ~60 dirt
fill ~437 ~69 ~60 ~437 ~69 ~60 grass_block
fill ~438 ~60 ~60 ~440 ~66 ~60 stone
fill ~438 ~67 ~60 ~440 ~69 ~60 dirt
fill ~438 ~70 ~60 ~440 ~70 ~60 grass_block
fill ~441 ~60 ~60 ~442 ~65 ~60 stone
fill ~441 ~66 ~60 ~442 ~68 ~60 dirt
fill ~441 ~69 ~60 ~442 ~69 ~60 grass_block
fill ~443 ~60 ~60 ~447 ~66 ~60 stone
fill ~443 ~67 ~60 ~447 ~69 ~60 dirt
fill ~443 ~70 ~60 ~447 ~70 ~60 grass_block
fill ~432 ~60 ~61 ~432 ~64 ~61 stone
fill ~432 ~65 ~61 ~432 ~67 ~61 dirt
fill ~432 ~68 ~61 ~432 ~68 ~61 grass_block
fill ~433 ~60 ~61 ~434 ~65 ~61 stone
fill ~433 ~66 ~61 ~434 ~68 ~61 dirt
fill ~433 ~69 ~61 ~434 ~69 ~61 grass_block
fill ~435 ~60 ~61 ~436 ~64 ~61 stone
fill ~435 ~65 ~61 ~436 ~67 ~61 dirt
fill ~435 ~68 ~61 ~436 ~68 ~61 grass_block
fill ~437 ~60 ~61 ~438 ~65 ~61 stone
fill ~437 ~66 ~61 ~438 ~68 ~61 dirt
fill ~437 ~69 ~61 ~438 ~69 ~61 grass_block
fill ~439 ~60 ~61 ~445 ~66 ~61 stone
fill ~439 ~67 ~61 ~445 ~69 ~61 dirt
fill ~439 ~70 ~61 ~445 ~70 ~61 grass_block
fill ~446 ~60 ~61 ~447 ~65 ~61 stone
fill ~446 ~66 ~61 ~447 ~68 ~61 dirt
fill ~446 ~69 ~61 ~447 ~69 ~61 grass_block
fill ~432 ~60 ~62 ~438 ~65 ~62 stone
fill ~432 ~66 ~62 ~438 ~68 ~62 dirt
fill ~432 ~69 ~62 ~438 ~69 ~62 grass_block
fill ~439 ~60 ~62 ~445 ~66 ~62 stone
fill ~439 ~67 ~62 ~445 ~69 ~62 dirt
fill ~439 ~70 ~62 ~445 ~70 ~62 grass_block
fill ~446 ~60 ~62 ~447 ~65 ~62 stone
fill ~446 ~66 ~62 ~447 ~68 ~62 dirt
fill ~446 ~69 ~62 ~447 ~69 ~62 grass_block
fill ~432 ~60 ~63 ~439 ~65 ~63 stone
fill ~432 ~66 ~63 ~439 ~68 ~63 dirt
fill ~432 ~69 ~63 ~439 ~69 ~63 grass_block
fill ~440 ~60 ~63 ~445 ~66 ~63 stone
fill ~440 ~67 ~63 ~445 ~69 ~63 dirt
fill ~440 ~70 ~63 ~445 ~70 ~63 grass_block
fill ~446 ~60 ~63 ~447 ~65 ~63 stone
fill ~446 ~66 ~63 ~447 ~68 ~63 dirt
fill ~446 ~69 ~63 ~447 ~69 ~63 grass_block