fill ~400 ~60 ~48 ~401 ~65 ~48 stone
fill ~400 ~66 ~48 ~401 ~68 ~48 dirt
fill ~400 ~69 ~48 ~401 ~69 ~48 grass_block
fill ~402 ~60 ~48 ~406 ~64 ~48 stone
fill ~402 ~65 ~48 ~406 ~67 ~48 dirt
fill ~402 ~68 ~48 ~406 ~68 ~48 grass_block
fill ~407 ~60 ~48 ~410 ~65 ~48 stone
fill ~407 ~66 ~48 ~410 ~68 ~48 dirt
fill ~407 ~69 ~48 ~410 ~69 ~48 grass_block
fill ~411 ~60 ~48 ~414 ~64 ~48 stone
fill ~411 ~65 ~48 ~414 ~67 ~48 dirt
fill ~411 ~68 ~48 ~414 ~68 ~48 grass_block
fill ~415 ~60 ~48 ~415 ~63 ~48 stone
fill ~415 ~64 ~48 ~415 ~66 ~48 dirt
fill ~415 ~67 ~48 ~415 ~67 ~48 grass_block
fill ~400 ~60 ~49 ~405 ~64 ~49 stone
fill ~400 ~65 ~49 ~405 ~67 ~49 dirt
fill ~400 ~68 ~49 ~405 ~68 ~49 grass_block
fill ~406 ~60 ~49 ~413 ~65 ~49 stone
fill ~406 ~66 ~49 ~413 ~68 ~49 dirt
fill ~406 ~69 ~49 ~413 ~69 ~49 grass_block
fill ~414 ~60 ~49 ~415 ~64 ~49 stone
fill ~414 ~65 ~49 ~415 ~67 ~49 dirt
fill ~414 ~68 ~49 ~415 ~68 ~49 grass_block
fill ~400 ~60 ~50 ~405 ~64 ~50 stone
fill ~400 ~65 ~50 ~405 ~67 ~50 dirt
fill ~400 ~68 ~50 ~405 ~68 ~50 grass_block
fill ~406 ~60 ~50 ~408 ~65 ~50 stone
fill ~406 ~66 ~50 ~408 ~68 ~50 dirt
fill ~406 ~69 ~50 ~408 ~69 ~50 grass_block
fill ~409 ~60 ~50 ~412 ~66 ~50 stone
fill ~409 ~67 ~50 ~412 ~69 ~50 dirt
fill ~409 ~70 ~50 ~412 ~70 ~50 grass_block
fill ~413 ~60 ~50 ~415 ~65 ~50 stone
fill ~413 ~66 ~50 ~415 ~68 ~50 dirt
fill ~413 ~69 ~50 ~415 ~69 ~50 grass_block
fill ~400 ~60 ~51 ~402 ~64 ~51 stone
fill ~400 ~65 ~51 ~402 ~67 ~51 dirt
fill ~400 ~68 ~51 ~402 ~68 ~51 grass_block
fill ~403 ~60 ~51 ~403 ~63 ~51 stone
fill ~403 ~64 ~51 ~403 ~66 ~51 dirt
fill ~403 ~67 ~51 ~403 ~67 ~51 grass_block
fill ~404 ~60 ~51 ~405 ~64 ~51 stone
fill ~404 ~65 ~51 ~405 ~67 ~51 dirt
fill ~404 ~68 ~51 ~405 ~68 ~51 grass_block
fill ~406 ~60 ~51 ~409 ~65 ~51 stone
fill ~406 ~66 ~51 ~409 ~68 ~51 dirt
fill ~406 ~69 ~51 ~409 ~69 ~51 grass_block
fill ~410 ~60 ~51 ~414 ~66 ~51 stone
fill ~410 ~67 ~51 ~414 ~69 ~51 dirt
fill ~410 ~70 ~51 ~414 ~70 ~51 grass_block
fill ~415 ~60 ~51 ~415 ~65 ~51 stone
fill ~415 ~66 ~51 ~415 ~68 ~51 dirt
fill ~415 ~69 ~51 ~415 ~69 ~51 grass_block
fill ~400 ~60 ~52 ~400 ~65 ~52 stone
fill ~400 ~66 ~52 ~400 ~68 ~52 dirt
fill ~400 ~69 ~52 ~400 ~69 ~52 grass_block
fill ~401 ~60 ~52 ~402 ~64 ~52 stone
fill ~401 ~65 ~52 ~402 ~67 ~52 dirt
fill ~401 ~68 ~52 ~402 ~68 ~52 grass_block
fill ~403 ~60 ~52 ~404 ~63 ~52 stone
fill ~403 ~64 ~52 ~404 ~66 ~52 dirt
fill ~403 ~67 ~52 ~404 ~67 ~52 grass_block
fill ~405 ~60 ~52 ~407 ~64 ~52 stone
fill ~405 ~65 ~52 ~407 ~67 ~52 dirt
fill ~405 ~68 ~52 ~407 ~68 ~52 grass_block
fill ~408 ~60 ~52 ~410 ~65 ~52 stone
fill ~408 ~66 ~52 ~410 ~68 ~52 dirt
fill ~408 ~69 ~52 ~410 ~69 ~52 grass_block
fill ~411 ~60 ~52 ~415 ~66 ~52 stone
fill ~411 ~67 ~52 ~415 ~69 ~52 dirt
fill ~411 ~70 ~52 ~415 ~70 ~52 grass_block
fill ~400 ~60 ~53 ~400 ~65 ~53 stone
fill ~400 ~66 ~53 ~400 ~68 ~53 dirt
fill ~400 ~69 ~53 ~400 ~69 ~53 grass_block
fill ~401 ~60 ~53 ~402 ~64 ~53 stone
fill ~401 ~65 ~53 ~402 ~67 ~53 dirt
fill ~401 ~68 ~53 ~402 ~68 ~53 grass_block
fill ~403 ~60 ~53 ~405 ~63 ~53 stone
fill ~403 ~64 ~53 ~405 ~66 ~53 dirt
fill ~403 ~67 ~53 ~405 ~67 ~53 grass_block
fill ~406 ~60 ~53 ~409 ~64 ~53 stone
fill ~406 ~65 ~53 ~409 ~67 ~53 dirt
fill ~406 ~68 ~53 ~409 ~68 ~53 grass_block
fill ~410 ~60 ~53 ~411 ~65 ~53 stone
fill ~410 ~66 ~53 ~411 ~68 ~53 dirt
fill ~410 ~69 ~53 ~411 ~69 ~53 grass_block
fill ~412 ~60 ~53 ~415 ~66 ~53 stone
fill ~412 ~67 ~53 ~415 ~69 ~53 dirt
fill ~412 ~70 ~53 ~415 ~70 ~53 grass_block
fill ~400 ~60 ~54 ~401 ~65 ~54 stone
fill ~400 ~66 ~54 ~401 ~68 ~54 dirt
fill ~400 ~69 ~54 ~401 ~69 ~54 grass_block
fill ~402 ~60 ~54 ~403 ~64 ~54 stone
fill ~402 ~65 ~54 ~403 ~67 ~54 dirt
fill ~402 ~68 ~54 ~403 ~68 ~54 grass_block
fill ~404 ~60 ~54 ~406 ~63 ~54 stone
fill ~404 ~64 ~54 ~406 ~66 ~54 dirt
fill ~404 ~67 ~54 ~406 ~67 ~54 grass_block
fill ~407 ~60 ~54 ~410 ~64 ~54 stone
fill ~407 ~65 ~54 ~410 ~67 ~54 dirt
fill ~407 ~68 ~54 ~410 ~68 ~54 grass_block
fill ~411 ~60 ~54 ~412 ~65 ~54 stone
fill ~411 ~66 ~54 ~412 ~68 ~54 dirt
fill ~411 ~69 ~54 ~412 ~69 ~54 grass_block
fill ~413 ~60 ~54 ~415 ~66 ~54 stone
fill ~413 ~67 ~54 ~415 ~69 ~54 dirt
fill ~413 ~70 ~54 ~415 ~70 ~54 grass_block
fill ~400 ~60 ~55 ~401 ~65 ~55 stone
fill ~400 ~66 ~55 ~401 ~68 ~55 dirt
fill ~400 ~69 ~55 ~401 ~69 ~55 grass_block
fill ~402 ~60 ~55 ~403 ~64 ~55 stone
fill ~402 ~65 ~55 ~403 ~67 ~55 dirt
fill ~402 ~68 ~55 ~403 ~68 ~55 grass_block
fill ~404 ~60 ~55 ~408 ~63 ~55 stone
fill ~404 ~64 ~55 ~408 ~66 ~55 dirt
fill ~404 ~67 ~55 ~408 ~67 ~55 grass_block
fill ~409 ~60 ~55 ~410 ~64 ~55 stone
fill ~409 ~65 ~55 ~410 ~67 ~55 dirt
fill ~409 ~68 ~55 ~410 ~68 ~55 grass_block
fill ~411 ~60 ~55 ~412 ~65 ~55 stone
fill ~411 ~66 ~55 ~412 ~68 ~55 dirt
fill ~411 ~69 ~55 ~412 ~69 ~55 grass_block
fill ~413 ~60 ~55 ~415 ~66 ~55 stone
fill ~413 ~67 ~55 ~415 ~69 ~55 dirt
fill ~413 ~70 ~55 ~415 ~70 ~55 grass_block
fill ~400 ~60 ~56 ~401 ~65 ~56 stone
fill ~400 ~66 ~56 ~401 ~68 ~56 dirt
fill ~400 ~69 ~56 ~401 ~69 ~56 grass_block
fill ~402 ~60 ~56 ~403 ~64 ~56 stone
fill ~402 ~65 ~56 ~403 ~67 ~56 dirt
fill ~402 ~68 ~56 ~403 ~68 ~56 grass_block
fill ~404 ~60 ~56 ~408 ~63 ~56 stone
fill ~404 ~64 ~56 ~408 ~66 ~56 dirt
fill ~404 ~67 ~56 ~408 ~67 ~56 grass_block
fill ~409 ~60 ~56 ~410 ~64 ~56 stone
fill ~409 ~65 ~56 ~410 ~67 ~56 dirt
fill ~409 ~68 ~56 ~410 ~68 ~56 grass_block
fill ~411 ~60 ~56 ~413 ~65 ~56 stone
fill ~411 ~66 ~56 ~413 ~68 ~56 dirt
fill ~411 ~69 ~56 ~413 ~69 ~56 grass_block
fill ~414 ~60 ~56 ~415 ~66 ~56 stone
fill ~414 ~67 ~56 ~415 ~69 ~56 dirt
fill ~414 ~70 ~56 ~415 ~70 ~56 grass_block
fill ~400 ~60 ~57 ~404 ~64 ~57 stone
fill ~400 ~65 ~57 ~404 ~67 ~57 dirt
fill ~400 ~68 ~57 ~404 ~68 ~57 grass_block
fill ~405 ~60 ~57 ~408 ~63 ~57 stone
fill ~405 ~64 ~57 ~408 ~66 ~57 dirt
fill ~405 ~67 ~57 ~408 ~67 ~57 grass_block
fill ~409 ~60 ~57 ~410 ~64 ~57 stone
fill ~409 ~65 ~57 ~410 ~67 ~57 dirt
fill ~409 ~68 ~57 ~410 ~68 ~57 grass_block
fill ~411 ~60 ~57 ~413 ~65 ~57 stone
fill ~411 ~66 ~57 ~413 ~68 ~57 dirt
fill ~411 ~69 ~57 ~413 ~69 ~57 grass_block
fill ~414 ~60 ~57 ~415 ~66 ~57 stone
fill ~414 ~67 ~57 ~415 ~69 ~57 dirt
fill ~414 ~70 ~57 ~415 ~70 ~57 grass_block
fill ~400 ~60 ~58 ~403 ~64 ~58 stone
fill ~400 ~65 ~58 ~403 ~67 ~58 dirt
fill ~400 ~68 ~58 ~403 ~68 ~58 grass_block
fill ~404 ~60 ~58 ~408 ~63 ~58 stone
fill ~404 ~64 ~58 ~408 ~66 ~58 dirt
fill ~404 ~67 ~58 ~408 ~67 ~58 grass_block
fill ~409 ~60 ~58 ~410 ~64 ~58 stone
fill ~409 ~65 ~58 ~410 ~67 ~58 dirt
fill ~409 ~68 ~58 ~410 ~68 ~58 grass_block
fill ~411 ~60 ~58 ~414 ~65 ~58 stone
fill ~411 ~66 ~58 ~414 ~68 ~58 dirt
fill ~411 ~69 ~58 ~414 ~69 ~58 grass_block
fill ~415 ~60 ~58 ~415 ~66 ~58 stone
fill ~415 ~67 ~58 ~415 ~69 ~58 dirt
fill ~415 ~70 ~58 ~415 ~70 ~58 grass_block
fill ~400 ~60 ~59 ~400 ~63 ~59 stone
fill ~400 ~64 ~59 ~400 ~66 ~59 dirt
fill ~400 ~67 ~59 ~400 ~67 ~59 grass_block
fill ~401 ~60 ~59 ~403 ~64 ~59 stone
fill ~401 ~65 ~59 ~403 ~67 ~59 dirt
fill ~401 ~68 ~59 ~403 ~68 ~59 grass_block
fill ~404 ~60 ~59 ~408 ~63 ~59 stone
fill ~404 ~64 ~59 ~408 ~66 ~59 dirt
fill ~404 ~67 ~59 ~408 ~67 ~59 grass_block
fill ~409 ~60 ~59 ~411 ~64 ~59 stone
fill ~409 ~65 ~59 ~411 ~67 ~59 dirt
fill ~409 ~68 ~59 ~411 ~68 ~59 grass_block
fill ~412 ~60 ~59 ~415 ~65 ~59 stone
fill ~412 ~66 ~59 ~415 ~68 ~59 dirt
fill ~412 ~69 ~59 ~415 ~69 ~59 grass_block
fill ~400 ~60 ~60 ~409 ~63 ~60 stone
fill ~400 ~64 ~60 ~409 ~66 ~60 dirt
fill ~400 ~67 ~60 ~409 ~67 ~60 grass_block
fill ~410 ~60 ~60 ~412 ~64 ~60 stone
fill ~410 ~65 ~60 ~412 ~67 ~60 dirt
fill ~410 ~68 ~60 ~412 ~68 ~60 grass_block
fill ~413 ~60 ~60 ~415 ~65 ~60 stone
fill ~413 ~66 ~60 ~415 ~68 ~60 dirt
fill ~413 ~69 ~60 ~415 ~69 ~60 grass_block
fill ~400 ~60 ~61 ~405 ~63 ~61 stone
fill ~400 ~64 ~61 ~405 ~66 ~61 dirt
fill ~400 ~67 ~61 ~405 ~67 ~61 grass_block
fill ~406 ~60 ~61 ~407 ~62 ~61 stone
fill ~406 ~63 ~61 ~407 ~65 ~61 dirt
fill ~406 ~66 ~61 ~407 ~66 ~61 grass_block
fill ~408 ~60 ~61 ~409 ~63 ~61 stone
fill ~408 ~64 ~61 ~409 ~66 ~61 dirt
fill ~408 ~67 ~61 ~409 ~67 ~61 grass_block
fill ~410 ~60 ~61 ~411 ~64 ~61 stone
fill ~410 ~65 ~61 ~411 ~67 ~61 dirt
fill ~410 ~68 ~61 ~411 ~68 ~61 grass_block
fill ~412 ~60 ~61 ~415 ~65 ~61 stone
fill ~412 ~66 ~61 ~415 ~68 ~61 dirt
fill ~412 ~69 ~61 ~415 ~69 ~61 grass_block
fill ~400 ~60 ~62 ~405 ~63 ~62 stone
fill ~400 ~64 ~62 ~405 ~66 ~62 dirt
fill ~400 ~67 ~62 ~405 ~67 ~62 grass_block
fill ~406 ~60 ~62 ~407 ~62 ~62 stone
fill ~406 ~63 ~62 ~407 ~65 ~62 dirt
fill ~406 ~66 ~62 ~407 ~66 ~62 grass_block
fill ~408 ~60 ~62 ~409 ~63 ~62 stone
fill ~408 ~64 ~62 ~409 ~66 ~62 dirt
fill ~408 ~67 ~62 ~409 ~67 ~62 grass_block
fill ~410 ~60 ~62 ~411 ~64 ~62 stone
fill ~410 ~65 ~62 ~411 ~67 ~62 dirt
fill ~410 ~68 ~62 ~411 ~68 ~62 grass_block
fill ~412 ~60 ~62 ~415 ~65 ~62 stone
fill ~412 ~66 ~62 ~415 ~68 ~62 dirt
fill ~412 ~69 ~62 ~415 ~69 ~62 grass_block
fill ~400 ~60 ~63 ~402 ~63 ~63 stone
fill ~400 ~64 ~63 ~402 ~66 ~63 dirt
fill ~400 ~67 ~63 ~402 ~67 ~63 grass_block
fill ~403 ~60 ~63 ~407 ~62 ~63 stone
fill ~403 ~63 ~63 ~407 ~65 ~63 dirt
fill ~403 ~66 ~63 ~407 ~66 ~63 grass_block
fill ~408 ~60 ~63 ~409 ~63 ~63 stone
fill ~408 ~64 ~63 ~409 ~66 ~63 dirt
fill ~408 ~67 ~63 ~409 ~67 ~63 grass_block
fill ~410 ~60 ~63 ~412 ~64 ~63 stone
fill ~410 ~65 ~63 ~412 ~67 ~63 dirt
fill ~410 ~68 ~63 ~412 ~68 ~63 grass_block
fill ~413 ~60 ~63 ~415 ~65 ~63 stone
fill ~413 ~66 ~63 ~415 ~68 ~63 dirt
fill ~413 ~69 ~63 ~415 ~69 ~63 grass_block