fill ~0 ~60 ~64 ~1 ~65 ~64 stone
fill ~0 ~66 ~64 ~1 ~68 ~64 dirt
fill ~0 ~69 ~64 ~1 ~69 ~64 grass_block
fill ~2 ~60 ~64 ~10 ~66 ~64 stone
fill ~2 ~67 ~64 ~10 ~69 ~64 dirt
fill ~2 ~70 ~64 ~10 ~70 ~64 grass_block
fill ~11 ~60 ~64 ~12 ~67 ~64 stone
fill ~11 ~68 ~64 ~12 ~70 ~64 dirt
fill ~11 ~71 ~64 ~12 ~71 ~64 grass_block
fill ~13 ~60 ~64 ~15 ~68 ~64 stone
fill ~13 ~69 ~64 ~15 ~71 ~64 dirt
fill ~13 ~72 ~64 ~15 ~72 ~64 grass_block
fill ~0 ~60 ~65 ~2 ~65 ~65 stone
fill ~0 ~66 ~65 ~2 ~68 ~65 dirt
fill ~0 ~69 ~65 ~2 ~69 ~65 grass_block
fill ~3 ~60 ~65 ~10 ~66 ~65 stone
fill ~3 ~67 ~65 ~10 ~69 ~65 dirt
fill ~3 ~70 ~65 ~10 ~70 ~65 grass_block
fill ~11 ~60 ~65 ~13 ~67 ~65 stone
fill ~11 ~68 ~65 ~13 ~70 ~65 dirt
fill ~11 ~71 ~65 ~13 ~71 ~65 grass_block
fill ~14 ~60 ~65 ~15 ~68 ~65 stone
fill ~14 ~69 ~65 ~15 ~71 ~65 dirt
fill ~14 ~72 ~65 ~15 ~72 ~65 grass_block
fill ~0 ~60 ~66 ~3 ~65 ~66 stone
fill ~0 ~66 ~66 ~3 ~68 ~66 dirt
fill ~0 ~69 ~66 ~3 ~69 ~66 grass_block
fill ~4 ~60 ~66 ~6 ~66 ~66 stone
fill ~4 ~67 ~66 ~6 ~69 ~66 dirt
fill ~4 ~70 ~66 ~6 ~70 ~66 grass_block
fill ~7 ~60 ~66 ~7 ~65 ~66 stone
fill ~7 ~66 ~66 ~7 ~68 ~66 dirt
fill ~7 ~69 ~66 ~7 ~69 ~66 grass_block
fill ~8 ~60 ~66 ~10 ~66 ~66 stone
fill ~8 ~67 ~66 ~10 ~69 ~66 dirt
fill ~8 ~70 ~66 ~10 ~70 ~66 grass_block
fill ~11 ~60 ~66 ~14 ~67 ~66 stone
fill ~11 ~68 ~66 ~14 ~70 ~66 dirt
fill ~11 ~71 ~66 ~14 ~71 ~66 grass_block
fill ~15 ~60 ~66 ~15 ~68 ~66 stone
fill ~15 ~69 ~66 ~15 ~71 ~66 dirt
fill ~15 ~72 ~66 ~15 ~72 ~66 grass_block
fill ~0 ~60 ~67 ~0 ~64 ~67 stone
fill ~0 ~65 ~67 ~0 ~67 ~67 dirt
fill ~0 ~68 ~67 ~0 ~68 ~67 grass_block
fill ~1 ~60 ~67 ~7 ~65 ~67 stone
fill ~1 ~66 ~67 ~7 ~68 ~67 dirt
fill ~1 ~69 ~67 ~7 ~69 ~67 grass_block
fill ~8 ~60 ~67 ~11 ~66 ~67 stone
fill ~8 ~67 ~67 ~11 ~69 ~67 dirt
fill ~8 ~70 ~67 ~11 ~70 ~67 grass_block
fill ~12 ~60 ~67 ~14 ~67 ~67 stone
fill ~12 ~68 ~67 ~14 ~70 ~67 dirt
fill ~12 ~71 ~67 ~14 ~71 ~67 grass_block
fill ~15 ~60 ~67 ~15 ~68 ~67 stone
fill ~15 ~69 ~67 ~15 ~71 ~67 dirt
fill ~15 ~72 ~67 ~15 ~72 ~67 grass_block
fill ~0 ~60 ~68 ~0 ~64 ~68 stone
fill ~0 ~65 ~68 ~0 ~67 ~68 dirt
fill ~0 ~68 ~68 ~0 ~68 ~68 grass_block
fill ~1 ~60 ~68 ~8 ~65 ~68 stone
fill ~1 ~66 ~68 ~8 ~68 ~68 dirt
fill ~1 ~69 ~68 ~8 ~69 ~68 grass_block
fill ~9 ~60 ~68 ~12 ~66 ~68 stone
fill ~9 ~67 ~68 ~12 ~69 ~68 dirt
fill ~9 ~70 ~68 ~12 ~70 ~68 grass_block
fill ~13 ~60 ~68 ~14 ~67 ~68 stone
fill ~13 ~68 ~68 ~14 ~70 ~68 dirt
fill ~13 ~71 ~68 ~14 ~71 ~68 grass_block
fill ~15 ~60 ~68 ~15 ~68 ~68 stone
fill ~15 ~69 ~68 ~15 ~71 ~68 dirt
fill ~15 ~72 ~68 ~15 ~72 ~68 grass_block
fill ~0 ~60 ~69 ~1 ~64 ~69 stone
fill ~0 ~65 ~69 ~1 ~67 ~69 dirt
fill ~0 ~68 ~69 ~1 ~68 ~69 grass_block
fill ~2 ~60 ~69 ~10 ~65 ~69 stone
fill ~2 ~66 ~69 ~10 ~68 ~69 dirt
fill ~2 ~69 ~69 ~10 ~69 ~69 grass_block
fill ~11 ~60 ~69 ~13 ~66 ~69 stone
fill ~11 ~67 ~69 ~13 ~69 ~69 dirt
fill ~11 ~70 ~69 ~13 ~70 ~69 grass_block
fill ~14 ~60 ~69 ~14 ~67 ~69 stone
fill ~14 ~68 ~69 ~14 ~70 ~69 dirt
fill ~14 ~71 ~69 ~14 ~71 ~69 grass_block
fill ~15 ~60 ~69 ~15 ~68 ~69 stone
fill ~15 ~69 ~69 ~15 ~71 ~69 dirt
fill ~15 ~72 ~69 ~15 ~72 ~69 grass_block
fill ~0 ~60 ~70 ~1 ~64 ~70 stone
fill ~0 ~65 ~70 ~1 ~67 ~70 dirt
fill ~0 ~68 ~70 ~1 ~68 ~70 grass_block
fill ~2 ~60 ~70 ~11 ~65 ~70 stone
fill ~2 ~66 ~70 ~11 ~68 ~70 dirt
fill ~2 ~69 ~70 ~11 ~69 ~70 grass_block
fill ~12 ~60 ~70 ~13 ~66 ~70 stone
fill ~12 ~67 ~70 ~13 ~69 ~70 dirt
fill ~12 ~70 ~70 ~13 ~70 ~70 grass_block
fill ~14 ~60 ~70 ~15 ~67 ~70 stone
fill ~14 ~68 ~70 ~15 ~70 ~70 dirt
fill ~14 ~71 ~70 ~15 ~71 ~70 grass_block
fill ~0 ~60 ~71 ~2 ~64 ~71 stone
fill ~0 ~65 ~71 ~2 ~67 ~71 dirt
fill ~0 ~68 ~71 ~2 ~68 ~71 grass_block
fill ~3 ~60 ~71 ~5 ~65 ~71 stone
fill ~3 ~66 ~71 ~5 ~68 ~71 dirt
fill ~3 ~69 ~71 ~5 ~69 ~71 grass_block
fill ~6 ~60 ~71 ~7 ~64 ~71 stone
fill ~6 ~65 ~71 ~7 ~67 ~71 dirt
fill ~6 ~68 ~71 ~7 ~68 ~71 grass_block
fill ~8 ~60 ~71 ~11 ~65 ~71 stone
fill ~8 ~66 ~71 ~11 ~68 ~71 dirt
fill ~8 ~69 ~71 ~11 ~69 ~71 grass_block
fill ~12 ~60 ~71 ~14 ~66 ~71 stone
fill ~12 ~67 ~71 ~14 ~69 ~71 dirt
fill ~12 ~70 ~71 ~14 ~70 ~71 grass_block
fill ~15 ~60 ~71 ~15 ~67 ~71 stone
fill ~15 ~68 ~71 ~15 ~70 ~71 dirt
fill ~15 ~71 ~71 ~15 ~71 ~71 grass_block
fill ~0 ~60 ~72 ~2 ~64 ~72 stone
fill ~0 ~65 ~72 ~2 ~67 ~72 dirt
fill ~0 ~68 ~72 ~2 ~68 ~72 grass_block
fill ~3 ~60 ~72 ~4 ~65 ~72 stone
fill ~3 ~66 ~72 ~4 ~68 ~72 dirt
fill ~3 ~69 ~72 ~4 ~69 ~72 grass_block
fill ~5 ~60 ~72 ~7 ~64 ~72 stone
fill ~5 ~65 ~72 ~7 ~67 ~72 dirt
fill ~5 ~68 ~72 ~7 ~68 ~72 grass_block
fill ~8 ~60 ~72 ~10 ~65 ~72 stone
fill ~8 ~66 ~72 ~10 ~68 ~72 dirt
fill ~8 ~69 ~72 ~10 ~69 ~72 grass_block
fill ~11 ~60 ~72 ~15 ~66 ~72 stone
fill ~11 ~67 ~72 ~15 ~69 ~72 dirt
fill ~11 ~70 ~72 ~15 ~70 ~72 grass_block
fill ~0 ~60 ~73 ~7 ~64 ~73 stone
fill ~0 ~65 ~73 ~7 ~67 ~73 dirt
fill ~0 ~68 ~73 ~7 ~68 ~73 grass_block
fill ~8 ~60 ~73 ~10 ~65 ~73 stone
fill ~8 ~66 ~73 ~10 ~68 ~73 dirt
fill ~8 ~69 ~73 ~10 ~69 ~73 grass_block
fill ~11 ~60 ~73 ~15 ~66 ~73 stone
fill ~11 ~67 ~73 ~15 ~69 ~73 dirt
fill ~11 ~70 ~73 ~15 ~70 ~73 grass_block
fill ~0 ~60 ~74 ~7 ~64 ~74 stone
fill ~0 ~65 ~74 ~7 ~67 ~74 dirt
fill ~0 ~68 ~74 ~7 ~68 ~74 grass_block
fill ~8 ~60 ~74 ~14 ~65 ~74 stone
fill ~8 ~66 ~74 ~14 ~68 ~74 dirt
fill ~8 ~69 ~74 ~14 ~69 ~74 grass_block
fill ~15 ~60 ~74 ~15 ~66 ~74 stone
fill ~15 ~67 ~74 ~15 ~69 ~74 dirt
fill ~15 ~70 ~74 ~15 ~70 ~74 grass_block
fill ~0 ~60 ~75 ~7 ~64 ~75 stone
fill ~0 ~65 ~75 ~7 ~67 ~75 dirt
fill ~0 ~68 ~75 ~7 ~68 ~75 grass_block
fill ~8 ~60 ~75 ~15 ~65 ~75 stone
fill ~8 ~66 ~75 ~15 ~68 ~75 dirt
fill ~8 ~69 ~75 ~15 ~69 ~75 grass_block
fill ~0 ~60 ~76 ~8 ~64 ~76 stone
fill ~0 ~65 ~76 ~8 ~67 ~76 dirt
fill ~0 ~68 ~76 ~8 ~68 ~76 grass_block
fill ~9 ~60 ~76 ~11 ~65 ~76 stone
fill ~9 ~66 ~76 ~11 ~68 ~76 dirt
fill ~9 ~69 ~76 ~11 ~69 ~76 grass_block
fill ~12 ~60 ~76 ~12 ~64 ~76 stone
fill ~12 ~65 ~76 ~12 ~67 ~76 dirt
fill ~12 ~68 ~76 ~12 ~68 ~76 grass_block
fill ~13 ~60 ~76 ~15 ~65 ~76 stone
fill ~13 ~66 ~76 ~15 ~68 ~76 dirt
fill ~13 ~69 ~76 ~15 ~69 ~76 grass_block
fill ~0 ~60 ~77 ~13 ~64 ~77 stone
fill ~0 ~65 ~77 ~13 ~67 ~77 dirt
fill ~0 ~68 ~77 ~13 ~68 ~77 grass_block
fill ~14 ~60 ~77 ~15 ~65 ~77 stone
fill ~14 ~66 ~77 ~15 ~68 ~77 dirt
fill ~14 ~69 ~77 ~15 ~69 ~77 grass_block
fill ~0 ~60 ~78 ~13 ~64 ~78 stone
fill ~0 ~65 ~78 ~13 ~67 ~78 dirt
fill ~0 ~68 ~78 ~13 ~68 ~78 grass_block
fill ~14 ~60 ~78 ~15 ~65 ~78 stone
fill ~14 ~66 ~78 ~15 ~68 ~78 dirt
fill ~14 ~69 ~78 ~15 ~69 ~78 grass_block
fill ~0 ~60 ~79 ~14 ~64 ~79 stone
fill ~0 ~65 ~79 ~14 ~67 ~79 dirt
fill ~0 ~68 ~79 ~14 ~68 ~79 grass_block
fill ~15 ~60 ~79 ~15 ~65 ~79 stone
fill ~15 ~66 ~79 ~15 ~68 ~79 dirt
fill ~15 ~69 ~79 ~15 ~69 ~79 grass_block