fill ~272 ~60 ~128 ~274 ~62 ~128 stone
fill ~272 ~63 ~128 ~274 ~65 ~128 dirt
fill ~272 ~66 ~128 ~274 ~66 ~128 grass_block
fill ~275 ~60 ~128 ~277 ~63 ~128 stone
fill ~275 ~64 ~128 ~277 ~66 ~128 dirt
fill ~275 ~67 ~128 ~277 ~67 ~128 grass_block
fill ~278 ~60 ~128 ~282 ~64 ~128 stone
fill ~278 ~65 ~128 ~282 ~67 ~128 dirt
fill ~278 ~68 ~128 ~282 ~68 ~128 grass_block
fill ~283 ~60 ~128 ~287 ~65 ~128 stone
fill ~283 ~66 ~128 ~287 ~68 ~128 dirt
fill ~283 ~69 ~128 ~287 ~69 ~128 grass_block
fill ~272 ~60 ~129 ~274 ~62 ~129 stone
fill ~272 ~63 ~129 ~274 ~65 ~129 dirt
fill ~272 ~66 ~129 ~274 ~66 ~129 grass_block
fill ~275 ~60 ~129 ~280 ~63 ~129 stone
fill ~275 ~64 ~129 ~280 ~66 ~129 dirt
fill ~275 ~67 ~129 ~280 ~67 ~129 grass_block
fill ~281 ~60 ~129 ~284 ~64 ~129 stone
fill ~281 ~65 ~129 ~284 ~67 ~129 dirt
fill ~281 ~68 ~129 ~284 ~68 ~129 grass_block
fill ~285 ~60 ~129 ~287 ~65 ~129 stone
fill ~285 ~66 ~129 ~287 ~68 ~129 dirt
fill ~285 ~69 ~129 ~287 ~69 ~129 grass_block
fill ~272 ~60 ~130 ~274 ~62 ~130 stone
fill ~272 ~63 ~130 ~274 ~65 ~130 dirt
fill ~272 ~66 ~130 ~274 ~66 ~130 grass_block
fill ~275 ~60 ~130 ~281 ~63 ~130 stone
fill ~275 ~64 ~130 ~281 ~66 ~130 dirt
fill ~275 ~67 ~130 ~281 ~67 ~130 grass_block
fill ~282 ~60 ~130 ~285 ~64 ~130 stone
fill ~282 ~65 ~130 ~285 ~67 ~130 dirt
fill ~282 ~68 ~130 ~285 ~68 ~130 grass_block
fill ~286 ~60 ~130 ~287 ~65 ~130 stone
fill ~286 ~66 ~130 ~287 ~68 ~130 dirt
fill ~286 ~69 ~130 ~287 ~69 ~130 grass_block
fill ~272 ~60 ~131 ~274 ~62 ~131 stone
fill ~272 ~63 ~131 ~274 ~65 ~131 dirt
fill ~272 ~66 ~131 ~274 ~66 ~131 grass_block
fill ~275 ~60 ~131 ~282 ~63 ~131 stone
fill ~275 ~64 ~131 ~282 ~66 ~131 dirt
fill ~275 ~67 ~131 ~282 ~67 ~131 grass_block
fill ~283 ~60 ~131 ~285 ~64 ~131 stone
fill ~283 ~65 ~131 ~285 ~67 ~131 dirt
fill ~283 ~68 ~131 ~285 ~68 ~131 grass_block
fill ~286 ~60 ~131 ~287 ~65 ~131 stone
fill ~286 ~66 ~131 ~287 ~68 ~131 dirt
fill ~286 ~69 ~131 ~287 ~69 ~131 grass_block
fill ~272 ~60 ~132 ~275 ~62 ~132 stone
fill ~272 ~63 ~132 ~275 ~65 ~132 dirt
fill ~272 ~66 ~132 ~275 ~66 ~132 grass_block
fill ~276 ~60 ~132 ~282 ~63 ~132 stone
fill ~276 ~64 ~132 ~282 ~66 ~132 dirt
fill ~276 ~67 ~132 ~282 ~67 ~132 grass_block
fill ~283 ~60 ~132 ~286 ~64 ~132 stone
fill ~283 ~65 ~132 ~286 ~67 ~132 dirt
fill ~283 ~68 ~132 ~286 ~68 ~132 grass_block
fill ~287 ~60 ~132 ~287 ~65 ~132 stone
fill ~287 ~66 ~132 ~287 ~68 ~132 dirt
fill ~287 ~69 ~132 ~287 ~69 ~132 grass_block
fill ~272 ~60 ~133 ~276 ~62 ~133 stone
fill ~272 ~63 ~133 ~276 ~65 ~133 dirt
fill ~272 ~66 ~133 ~276 ~66 ~133 grass_block
fill ~277 ~60 ~133 ~278 ~63 ~133 stone
fill ~277 ~64 ~133 ~278 ~66 ~133 dirt
fill ~277 ~67 ~133 ~278 ~67 ~133 grass_block
fill ~279 ~60 ~133 ~280 ~62 ~133 stone
fill ~279 ~63 ~133 ~280 ~65 ~133 dirt
fill ~279 ~66 ~133 ~280 ~66 ~133 grass_block
fill ~281 ~60 ~133 ~282 ~63 ~133 stone
fill ~281 ~64 ~133 ~282 ~66 ~133 dirt
fill ~281 ~67 ~133 ~282 ~67 ~133 grass_block
fill ~283 ~60 ~133 ~286 ~64 ~133 stone
fill ~283 ~65 ~133 ~286 ~67 ~133 dirt
fill ~283 ~68 ~133 ~286 ~68 ~133 grass_block
fill ~287 ~60 ~133 ~287 ~65 ~133 stone
fill ~287 ~66 ~133 ~287 ~68 ~133 dirt
fill ~287 ~69 ~133 ~287 ~69 ~133 grass_block
fill ~272 ~60 ~134 ~273 ~61 ~134 stone
fill ~272 ~62 ~134 ~273 ~64 ~134 dirt
fill ~272 ~65 ~134 ~273 ~65 ~134 grass_block
fill ~274 ~60 ~134 ~276 ~62 ~134 stone
fill ~274 ~63 ~134 ~276 ~65 ~134 dirt
fill ~274 ~66 ~134 ~276 ~66 ~134 grass_block
fill ~277 ~60 ~134 ~277 ~63 ~134 stone
fill ~277 ~64 ~134 ~277 ~66 ~134 dirt
fill ~277 ~67 ~134 ~277 ~67 ~134 grass_block
fill ~278 ~60 ~134 ~280 ~62 ~134 stone
fill ~278 ~63 ~134 ~280 ~65 ~134 dirt
fill ~278 ~66 ~134 ~280 ~66 ~134 grass_block
fill ~281 ~60 ~134 ~283 ~63 ~134 stone
fill ~281 ~64 ~134 ~283 ~66 ~134 dirt
fill ~281 ~67 ~134 ~283 ~67 ~134 grass_block
fill ~284 ~60 ~134 ~287 ~64 ~134 stone
fill ~284 ~65 ~134 ~287 ~67 ~134 dirt
fill ~284 ~68 ~134 ~287 ~68 ~134 grass_block
fill ~272 ~60 ~135 ~272 ~62 ~135 stone
fill ~272 ~63 ~135 ~272 ~65 ~135 dirt
fill ~272 ~66 ~135 ~272 ~66 ~135 grass_block
fill ~273 ~60 ~135 ~274 ~61 ~135 stone
fill ~273 ~62 ~135 ~274 ~64 ~135 dirt
fill ~273 ~65 ~135 ~274 ~65 ~135 grass_block
fill ~275 ~60 ~135 ~281 ~62 ~135 stone
fill ~275 ~63 ~135 ~281 ~65 ~135 dirt
fill ~275 ~66 ~135 ~281 ~66 ~135 grass_block
fill ~282 ~60 ~135 ~284 ~63 ~135 stone
fill ~282 ~64 ~135 ~284 ~66 ~135 dirt
fill ~282 ~67 ~135 ~284 ~67 ~135 grass_block
fill ~285 ~60 ~135 ~287 ~64 ~135 stone
fill ~285 ~65 ~135 ~287 ~67 ~135 dirt
fill ~285 ~68 ~135 ~287 ~68 ~135 grass_block
fill ~272 ~60 ~136 ~273 ~62 ~136 stone
fill ~272 ~63 ~136 ~273 ~65 ~136 dirt
fill ~272 ~66 ~136 ~273 ~66 ~136 grass_block
fill ~274 ~60 ~136 ~275 ~61 ~136 stone
fill ~274 ~62 ~136 ~275 ~64 ~136 dirt
fill ~274 ~65 ~136 ~275 ~65 ~136 grass_block
fill ~276 ~60 ~136 ~281 ~62 ~136 stone
fill ~276 ~63 ~136 ~281 ~65 ~136 dirt
fill ~276 ~66 ~136 ~281 ~66 ~136 grass_block
fill ~282 ~60 ~136 ~284 ~63 ~136 stone
fill ~282 ~64 ~136 ~284 ~66 ~136 dirt
fill ~282 ~67 ~136 ~284 ~67 ~136 grass_block
fill ~285 ~60 ~136 ~287 ~64 ~136 stone
fill ~285 ~65 ~136 ~287 ~67 ~136 dirt
fill ~285 ~68 ~136 ~287 ~68 ~136 grass_block
fill ~272 ~60 ~137 ~274 ~62 ~137 stone
fill ~272 ~63 ~137 ~274 ~65 ~137 dirt
fill ~272 ~66 ~137 ~274 ~66 ~137 grass_block
fill ~275 ~60 ~137 ~276 ~61 ~137 stone
fill ~275 ~62 ~137 ~276 ~64 ~137 dirt
fill ~275 ~65 ~137 ~276 ~65 ~137 grass_block
fill ~277 ~60 ~137 ~282 ~62 ~137 stone
fill ~277 ~63 ~137 ~282 ~65 ~137 dirt
fill ~277 ~66 ~137 ~282 ~66 ~137 grass_block
fill ~283 ~60 ~137 ~285 ~63 ~137 stone
fill ~283 ~64 ~137 ~285 ~66 ~137 dirt
fill ~283 ~67 ~137 ~285 ~67 ~137 grass_block
fill ~286 ~60 ~137 ~287 ~64 ~137 stone
fill ~286 ~65 ~137 ~287 ~67 ~137 dirt
fill ~286 ~68 ~137 ~287 ~68 ~137 grass_block
fill ~272 ~60 ~138 ~272 ~63 ~138 stone
fill ~272 ~64 ~138 ~272 ~66 ~138 dirt
fill ~272 ~67 ~138 ~272 ~67 ~138 grass_block
fill ~273 ~60 ~138 ~275 ~62 ~138 stone
fill ~273 ~63 ~138 ~275 ~65 ~138 dirt
fill ~273 ~66 ~138 ~275 ~66 ~138 grass_block
fill ~276 ~60 ~138 ~277 ~61 ~138 stone
fill ~276 ~62 ~138 ~277 ~64 ~138 dirt
fill ~276 ~65 ~138 ~277 ~65 ~138 grass_block
fill ~278 ~60 ~138 ~282 ~62 ~138 stone
fill ~278 ~63 ~138 ~282 ~65 ~138 dirt
fill ~278 ~66 ~138 ~282 ~66 ~138 grass_block
fill ~283 ~60 ~138 ~286 ~63 ~138 stone
fill ~283 ~64 ~138 ~286 ~66 ~138 dirt
fill ~283 ~67 ~138 ~286 ~67 ~138 grass_block
fill ~287 ~60 ~138 ~287 ~64 ~138 stone
fill ~287 ~65 ~138 ~287 ~67 ~138 dirt
fill ~287 ~68 ~138 ~287 ~68 ~138 grass_block
fill ~272 ~60 ~139 ~273 ~63 ~139 stone
fill ~272 ~64 ~139 ~273 ~66 ~139 dirt
fill ~272 ~67 ~139 ~273 ~67 ~139 grass_block
fill ~274 ~60 ~139 ~276 ~62 ~139 stone
fill ~274 ~63 ~139 ~276 ~65 ~139 dirt
fill ~274 ~66 ~139 ~276 ~66 ~139 grass_block
fill ~277 ~60 ~139 ~279 ~61 ~139 stone
fill ~277 ~62 ~139 ~279 ~64 ~139 dirt
fill ~277 ~65 ~139 ~279 ~65 ~139 grass_block
fill ~280 ~60 ~139 ~283 ~62 ~139 stone
fill ~280 ~63 ~139 ~283 ~65 ~139 dirt
fill ~280 ~66 ~139 ~283 ~66 ~139 grass_block
fill ~284 ~60 ~139 ~286 ~63 ~139 stone
fill ~284 ~64 ~139 ~286 ~66 ~139 dirt
fill ~284 ~67 ~139 ~286 ~67 ~139 grass_block
fill ~287 ~60 ~139 ~287 ~64 ~139 stone
fill ~287 ~65 ~139 ~287 ~67 ~139 dirt
fill ~287 ~68 ~139 ~287 ~68 ~139 grass_block
fill ~272 ~60 ~140 ~274 ~63 ~140 stone
fill ~272 ~64 ~140 ~274 ~66 ~140 dirt
fill ~272 ~67 ~140 ~274 ~67 ~140 grass_block
fill ~275 ~60 ~140 ~277 ~62 ~140 stone
fill ~275 ~63 ~140 ~277 ~65 ~140 dirt
fill ~275 ~66 ~140 ~277 ~66 ~140 grass_block
fill ~278 ~60 ~140 ~280 ~61 ~140 stone
fill ~278 ~62 ~140 ~280 ~64 ~140 dirt
fill ~278 ~65 ~140 ~280 ~65 ~140 grass_block
fill ~281 ~60 ~140 ~284 ~62 ~140 stone
fill ~281 ~63 ~140 ~284 ~65 ~140 dirt
fill ~281 ~66 ~140 ~284 ~66 ~140 grass_block
fill ~285 ~60 ~140 ~287 ~63 ~140 stone
fill ~285 ~64 ~140 ~287 ~66 ~140 dirt
fill ~285 ~67 ~140 ~287 ~67 ~140 grass_block
fill ~272 ~60 ~141 ~275 ~63 ~141 stone
fill ~272 ~64 ~141 ~275 ~66 ~141 dirt
fill ~272 ~67 ~141 ~275 ~67 ~141 grass_block
fill ~276 ~60 ~141 ~277 ~62 ~141 stone
fill ~276 ~63 ~141 ~277 ~65 ~141 dirt
fill ~276 ~66 ~141 ~277 ~66 ~141 grass_block
fill ~278 ~60 ~141 ~280 ~61 ~141 stone
fill ~278 ~62 ~141 ~280 ~64 ~141 dirt
fill ~278 ~65 ~141 ~280 ~65 ~141 grass_block
fill ~281 ~60 ~141 ~285 ~62 ~141 stone
fill ~281 ~63 ~141 ~285 ~65 ~141 dirt
fill ~281 ~66 ~141 ~285 ~66 ~141 grass_block
fill ~286 ~60 ~141 ~287 ~63 ~141 stone
fill ~286 ~64 ~141 ~287 ~66 ~141 dirt
fill ~286 ~67 ~141 ~287 ~67 ~141 grass_block
fill ~272 ~60 ~142 ~275 ~63 ~142 stone
fill ~272 ~64 ~142 ~275 ~66 ~142 dirt
fill ~272 ~67 ~142 ~275 ~67 ~142 grass_block
fill ~276 ~60 ~142 ~278 ~62 ~142 stone
fill ~276 ~63 ~142 ~278 ~65 ~142 dirt
fill ~276 ~66 ~142 ~278 ~66 ~142 grass_block
fill ~279 ~60 ~142 ~281 ~61 ~142 stone
fill ~279 ~62 ~142 ~281 ~64 ~142 dirt
fill ~279 ~65 ~142 ~281 ~65 ~142 grass_block
fill ~282 ~60 ~142 ~285 ~62 ~142 stone
fill ~282 ~63 ~142 ~285 ~65 ~142 dirt
fill ~282 ~66 ~142 ~285 ~66 ~142 grass_block
fill ~286 ~60 ~142 ~287 ~63 ~142 stone
fill ~286 ~64 ~142 ~287 ~66 ~142 dirt
fill ~286 ~67 ~142 ~287 ~67 ~142 grass_block
fill ~272 ~60 ~143 ~276 ~63 ~143 stone
fill ~272 ~64 ~143 ~276 ~66 ~143 dirt
fill ~272 ~67 ~143 ~276 ~67 ~143 grass_block
fill ~277 ~60 ~143 ~279 ~62 ~143 stone
fill ~277 ~63 ~143 ~279 ~65 ~143 dirt
fill ~277 ~66 ~143 ~279 ~66 ~143 grass_block
fill ~280 ~60 ~143 ~282 ~61 ~143 stone
fill ~280 ~62 ~143 ~282 ~64 ~143 dirt
fill ~280 ~65 ~143 ~282 ~65 ~143 grass_block
fill ~283 ~60 ~143 ~287 ~62 ~143 stone
fill ~283 ~63 ~143 ~287 ~65 ~143 dirt
fill ~283 ~66 ~143 ~287 ~66 ~143 grass_block