fill ~176 ~60 ~0 ~177 ~62 ~0 stone
fill ~176 ~63 ~0 ~177 ~65 ~0 dirt
fill ~176 ~66 ~0 ~177 ~66 ~0 grass_block
fill ~178 ~60 ~0 ~178 ~63 ~0 stone
fill ~178 ~64 ~0 ~178 ~66 ~0 dirt
fill ~178 ~67 ~0 ~178 ~67 ~0 grass_block
fill ~179 ~60 ~0 ~180 ~62 ~0 stone
fill ~179 ~63 ~0 ~180 ~65 ~0 dirt
fill ~179 ~66 ~0 ~180 ~66 ~0 grass_block
fill ~181 ~60 ~0 ~181 ~63 ~0 stone
fill ~181 ~64 ~0 ~181 ~66 ~0 dirt
fill ~181 ~67 ~0 ~181 ~67 ~0 grass_block
fill ~182 ~60 ~0 ~188 ~64 ~0 stone
fill ~182 ~65 ~0 ~188 ~67 ~0 dirt
fill ~182 ~68 ~0 ~188 ~68 ~0 grass_block
fill ~189 ~60 ~0 ~191 ~63 ~0 stone
fill ~189 ~64 ~0 ~191 ~66 ~0 dirt
fill ~189 ~67 ~0 ~191 ~67 ~0 grass_block
fill ~176 ~60 ~1 ~179 ~62 ~1 stone
fill ~176 ~63 ~1 ~179 ~65 ~1 dirt
fill ~176 ~66 ~1 ~179 ~66 ~1 grass_block
fill ~180 ~60 ~1 ~180 ~61 ~1 stone
fill ~180 ~62 ~1 ~180 ~64 ~1 dirt
fill ~180 ~65 ~1 ~180 ~65 ~1 grass_block
fill ~181 ~60 ~1 ~181 ~62 ~1 stone
fill ~181 ~63 ~1 ~181 ~65 ~1 dirt
fill ~181 ~66 ~1 ~181 ~66 ~1 grass_block
fill ~182 ~60 ~1 ~182 ~63 ~1 stone
fill ~182 ~64 ~1 ~182 ~66 ~1 dirt
fill ~182 ~67 ~1 ~182 ~67 ~1 grass_block
fill ~183 ~60 ~1 ~188 ~64 ~1 stone
fill ~183 ~65 ~1 ~188 ~67 ~1 dirt
fill ~183 ~68 ~1 ~188 ~68 ~1 grass_block
fill ~189 ~60 ~1 ~191 ~63 ~1 stone
fill ~189 ~64 ~1 ~191 ~66 ~1 dirt
fill ~189 ~67 ~1 ~191 ~67 ~1 grass_block
fill ~176 ~60 ~2 ~178 ~62 ~2 stone
fill ~176 ~63 ~2 ~178 ~65 ~2 dirt
fill ~176 ~66 ~2 ~178 ~66 ~2 grass_block
fill ~179 ~60 ~2 ~179 ~61 ~2 stone
fill ~179 ~62 ~2 ~179 ~64 ~2 dirt
fill ~179 ~65 ~2 ~179 ~65 ~2 grass_block
fill ~180 ~60 ~2 ~180 ~60 ~2 stone
fill ~180 ~61 ~2 ~180 ~63 ~2 dirt
fill ~180 ~64 ~2 ~180 ~64 ~2 grass_block
fill ~181 ~60 ~2 ~181 ~62 ~2 stone
fill ~181 ~63 ~2 ~181 ~65 ~2 dirt
fill ~181 ~66 ~2 ~181 ~66 ~2 grass_block
fill ~182 ~60 ~2 ~183 ~63 ~2 stone
fill ~182 ~64 ~2 ~183 ~66 ~2 dirt
fill ~182 ~67 ~2 ~183 ~67 ~2 grass_block
fill ~184 ~60 ~2 ~188 ~64 ~2 stone
fill ~184 ~65 ~2 ~188 ~67 ~2 dirt
fill ~184 ~68 ~2 ~188 ~68 ~2 grass_block
fill ~189 ~60 ~2 ~191 ~63 ~2 stone
fill ~189 ~64 ~2 ~191 ~66 ~2 dirt
fill ~189 ~67 ~2 ~191 ~67 ~2 grass_block
fill ~176 ~60 ~3 ~176 ~61 ~3 stone
fill ~176 ~62 ~3 ~176 ~64 ~3 dirt
fill ~176 ~65 ~3 ~176 ~65 ~3 grass_block
fill ~177 ~60 ~3 ~178 ~62 ~3 stone
fill ~177 ~63 ~3 ~178 ~65 ~3 dirt
fill ~177 ~66 ~3 ~178 ~66 ~3 grass_block
fill ~179 ~60 ~3 ~181 ~61 ~3 stone
fill ~179 ~62 ~3 ~181 ~64 ~3 dirt
fill ~179 ~65 ~3 ~181 ~65 ~3 grass_block
fill ~182 ~60 ~3 ~182 ~62 ~3 stone
fill ~182 ~63 ~3 ~182 ~65 ~3 dirt
fill ~182 ~66 ~3 ~182 ~66 ~3 grass_block
fill ~183 ~60 ~3 ~183 ~63 ~3 stone
fill ~183 ~64 ~3 ~183 ~66 ~3 dirt
fill ~183 ~67 ~3 ~183 ~67 ~3 grass_block
fill ~184 ~60 ~3 ~188 ~64 ~3 stone
fill ~184 ~65 ~3 ~188 ~67 ~3 dirt
fill ~184 ~68 ~3 ~188 ~68 ~3 grass_block
fill ~189 ~60 ~3 ~191 ~63 ~3 stone
fill ~189 ~64 ~3 ~191 ~66 ~3 dirt
fill ~189 ~67 ~3 ~191 ~67 ~3 grass_block
fill ~176 ~60 ~4 ~177 ~62 ~4 stone
fill ~176 ~63 ~4 ~177 ~65 ~4 dirt
fill ~176 ~66 ~4 ~177 ~66 ~4 grass_block
fill ~178 ~60 ~4 ~180 ~61 ~4 stone
fill ~178 ~62 ~4 ~180 ~64 ~4 dirt
fill ~178 ~65 ~4 ~180 ~65 ~4 grass_block
fill ~181 ~60 ~4 ~181 ~62 ~4 stone
fill ~181 ~63 ~4 ~181 ~65 ~4 dirt
fill ~181 ~66 ~4 ~181 ~66 ~4 grass_block
fill ~182 ~60 ~4 ~185 ~63 ~4 stone
fill ~182 ~64 ~4 ~185 ~66 ~4 dirt
fill ~182 ~67 ~4 ~185 ~67 ~4 grass_block
fill ~186 ~60 ~4 ~188 ~64 ~4 stone
fill ~186 ~65 ~4 ~188 ~67 ~4 dirt
fill ~186 ~68 ~4 ~188 ~68 ~4 grass_block
fill ~189 ~60 ~4 ~191 ~63 ~4 stone
fill ~189 ~64 ~4 ~191 ~66 ~4 dirt
fill ~189 ~67 ~4 ~191 ~67 ~4 grass_block
fill ~176 ~60 ~5 ~176 ~61 ~5 stone
fill ~176 ~62 ~5 ~176 ~64 ~5 dirt
fill ~176 ~65 ~5 ~176 ~65 ~5 grass_block
fill ~177 ~60 ~5 ~177 ~62 ~5 stone
fill ~177 ~63 ~5 ~177 ~65 ~5 dirt
fill ~177 ~66 ~5 ~177 ~66 ~5 grass_block
fill ~178 ~60 ~5 ~180 ~61 ~5 stone
fill ~178 ~62 ~5 ~180 ~64 ~5 dirt
fill ~178 ~65 ~5 ~180 ~65 ~5 grass_block
fill ~181 ~60 ~5 ~182 ~62 ~5 stone
fill ~181 ~63 ~5 ~182 ~65 ~5 dirt
fill ~181 ~66 ~5 ~182 ~66 ~5 grass_block
fill ~183 ~60 ~5 ~191 ~63 ~5 stone
fill ~183 ~64 ~5 ~191 ~66 ~5 dirt
fill ~183 ~67 ~5 ~191 ~67 ~5 grass_block
fill ~176 ~60 ~6 ~177 ~62 ~6 stone
fill ~176 ~63 ~6 ~177 ~65 ~6 dirt
fill ~176 ~66 ~6 ~177 ~66 ~6 grass_block
fill ~178 ~60 ~6 ~180 ~61 ~6 stone
fill ~178 ~62 ~6 ~180 ~64 ~6 dirt
fill ~178 ~65 ~6 ~180 ~65 ~6 grass_block
fill ~181 ~60 ~6 ~182 ~62 ~6 stone
fill ~181 ~63 ~6 ~182 ~65 ~6 dirt
fill ~181 ~66 ~6 ~182 ~66 ~6 grass_block
fill ~183 ~60 ~6 ~191 ~63 ~6 stone
fill ~183 ~64 ~6 ~191 ~66 ~6 dirt
fill ~183 ~67 ~6 ~191 ~67 ~6 grass_block
fill ~176 ~60 ~7 ~180 ~61 ~7 stone
fill ~176 ~62 ~7 ~180 ~64 ~7 dirt
fill ~176 ~65 ~7 ~180 ~65 ~7 grass_block
fill ~181 ~60 ~7 ~185 ~62 ~7 stone
fill ~181 ~63 ~7 ~185 ~65 ~7 dirt
fill ~181 ~66 ~7 ~185 ~66 ~7 grass_block
fill ~186 ~60 ~7 ~186 ~63 ~7 stone
fill ~186 ~64 ~7 ~186 ~66 ~7 dirt
fill ~186 ~67 ~7 ~186 ~67 ~7 grass_block
fill ~187 ~60 ~7 ~188 ~62 ~7 stone
fill ~187 ~63 ~7 ~188 ~65 ~7 dirt
fill ~187 ~66 ~7 ~188 ~66 ~7 grass_block
fill ~189 ~60 ~7 ~191 ~63 ~7 stone
fill ~189 ~64 ~7 ~191 ~66 ~7 dirt
fill ~189 ~67 ~7 ~191 ~67 ~7 grass_block
fill ~176 ~60 ~8 ~179 ~61 ~8 stone
fill ~176 ~62 ~8 ~179 ~64 ~8 dirt
fill ~176 ~65 ~8 ~179 ~65 ~8 grass_block
fill ~180 ~60 ~8 ~191 ~62 ~8 stone
fill ~180 ~63 ~8 ~191 ~65 ~8 dirt
fill ~180 ~66 ~8 ~191 ~66 ~8 grass_block
fill ~176 ~60 ~9 ~180 ~61 ~9 stone
fill ~176 ~62 ~9 ~180 ~64 ~9 dirt
fill ~176 ~65 ~9 ~180 ~65 ~9 grass_block
fill ~181 ~60 ~9 ~191 ~62 ~9 stone
fill ~181 ~63 ~9 ~191 ~65 ~9 dirt
fill ~181 ~66 ~9 ~191 ~66 ~9 grass_block
fill ~176 ~60 ~10 ~184 ~61 ~10 stone
fill ~176 ~62 ~10 ~184 ~64 ~10 dirt
fill ~176 ~65 ~10 ~184 ~65 ~10 grass_block
fill ~185 ~60 ~10 ~186 ~62 ~10 stone
fill ~185 ~63 ~10 ~186 ~65 ~10 dirt
fill ~185 ~66 ~10 ~186 ~66 ~10 grass_block
fill ~187 ~60 ~10 ~191 ~61 ~10 stone
fill ~187 ~62 ~10 ~191 ~64 ~10 dirt
fill ~187 ~65 ~10 ~191 ~65 ~10 grass_block
fill ~176 ~60 ~11 ~191 ~61 ~11 stone
fill ~176 ~62 ~11 ~191 ~64 ~11 dirt
fill ~176 ~65 ~11 ~191 ~65 ~11 grass_block
fill ~176 ~60 ~12 ~177 ~61 ~12 stone
fill ~176 ~62 ~12 ~177 ~64 ~12 dirt
fill ~176 ~65 ~12 ~177 ~65 ~12 grass_block
fill ~178 ~60 ~12 ~179 ~62 ~12 stone
fill ~178 ~63 ~12 ~179 ~65 ~12 dirt
fill ~178 ~66 ~12 ~179 ~66 ~12 grass_block
fill ~180 ~60 ~12 ~191 ~61 ~12 stone
fill ~180 ~62 ~12 ~191 ~64 ~12 dirt
fill ~180 ~65 ~12 ~191 ~65 ~12 grass_block
fill ~176 ~60 ~13 ~176 ~61 ~13 stone
fill ~176 ~62 ~13 ~176 ~64 ~13 dirt
fill ~176 ~65 ~13 ~176 ~65 ~13 grass_block
fill ~177 ~60 ~13 ~181 ~62 ~13 stone
fill ~177 ~63 ~13 ~181 ~65 ~13 dirt
fill ~177 ~66 ~13 ~181 ~66 ~13 grass_block
fill ~182 ~60 ~13 ~191 ~61 ~13 stone
fill ~182 ~62 ~13 ~191 ~64 ~13 dirt
fill ~182 ~65 ~13 ~191 ~65 ~13 grass_block
fill ~176 ~60 ~14 ~185 ~62 ~14 stone
fill ~176 ~63 ~14 ~185 ~65 ~14 dirt
fill ~176 ~66 ~14 ~185 ~66 ~14 grass_block
fill ~186 ~60 ~14 ~191 ~61 ~14 stone
fill ~186 ~62 ~14 ~191 ~64 ~14 dirt
fill ~186 ~65 ~14 ~191 ~65 ~14 grass_block
fill ~176 ~60 ~15 ~185 ~62 ~15 stone
fill ~176 ~63 ~15 ~185 ~65 ~15 dirt
fill ~176 ~66 ~15 ~185 ~66 ~15 grass_block
fill ~186 ~60 ~15 ~191 ~61 ~15 stone
fill ~186 ~62 ~15 ~191 ~64 ~15 dirt
fill ~186 ~65 ~15 ~191 ~65 ~15 grass_block