fill ~112 ~60 ~48 ~112 ~64 ~48 stone
fill ~112 ~65 ~48 ~112 ~67 ~48 dirt
fill ~112 ~68 ~48 ~112 ~68 ~48 grass_block
fill ~113 ~60 ~48 ~114 ~65 ~48 stone
fill ~113 ~66 ~48 ~114 ~68 ~48 dirt
fill ~113 ~69 ~48 ~114 ~69 ~48 grass_block
fill ~115 ~60 ~48 ~116 ~66 ~48 stone
fill ~115 ~67 ~48 ~116 ~69 ~48 dirt
fill ~115 ~70 ~48 ~116 ~70 ~48 grass_block
fill ~117 ~60 ~48 ~119 ~67 ~48 stone
fill ~117 ~68 ~48 ~119 ~70 ~48 dirt
fill ~117 ~71 ~48 ~119 ~71 ~48 grass_block
fill ~120 ~60 ~48 ~121 ~66 ~48 stone
fill ~120 ~67 ~48 ~121 ~69 ~48 dirt
fill ~120 ~70 ~48 ~121 ~70 ~48 grass_block
fill ~122 ~60 ~48 ~123 ~65 ~48 stone
fill ~122 ~66 ~48 ~123 ~68 ~48 dirt
fill ~122 ~69 ~48 ~123 ~69 ~48 grass_block
fill ~124 ~60 ~48 ~127 ~66 ~48 stone
fill ~124 ~67 ~48 ~127 ~69 ~48 dirt
fill ~124 ~70 ~48 ~127 ~70 ~48 grass_block
fill ~112 ~60 ~49 ~112 ~64 ~49 stone
fill ~112 ~65 ~49 ~112 ~67 ~49 dirt
fill ~112 ~68 ~49 ~112 ~68 ~49 grass_block
fill ~113 ~60 ~49 ~114 ~65 ~49 stone
fill ~113 ~66 ~49 ~114 ~68 ~49 dirt
fill ~113 ~69 ~49 ~114 ~69 ~49 grass_block
fill ~115 ~60 ~49 ~116 ~66 ~49 stone
fill ~115 ~67 ~49 ~116 ~69 ~49 dirt
fill ~115 ~70 ~49 ~116 ~70 ~49 grass_block
fill ~117 ~60 ~49 ~118 ~67 ~49 stone
fill ~117 ~68 ~49 ~118 ~70 ~49 dirt
fill ~117 ~71 ~49 ~118 ~71 ~49 grass_block
fill ~119 ~60 ~49 ~121 ~66 ~49 stone
fill ~119 ~67 ~49 ~121 ~69 ~49 dirt
fill ~119 ~70 ~49 ~121 ~70 ~49 grass_block
fill ~122 ~60 ~49 ~124 ~65 ~49 stone
fill ~122 ~66 ~49 ~124 ~68 ~49 dirt
fill ~122 ~69 ~49 ~124 ~69 ~49 grass_block
fill ~125 ~60 ~49 ~127 ~66 ~49 stone
fill ~125 ~67 ~49 ~127 ~69 ~49 dirt
fill ~125 ~70 ~49 ~127 ~70 ~49 grass_block
fill ~112 ~60 ~50 ~113 ~64 ~50 stone
fill ~112 ~65 ~50 ~113 ~67 ~50 dirt
fill ~112 ~68 ~50 ~113 ~68 ~50 grass_block
fill ~114 ~60 ~50 ~114 ~65 ~50 stone
fill ~114 ~66 ~50 ~114 ~68 ~50 dirt
fill ~114 ~69 ~50 ~114 ~69 ~50 grass_block
fill ~115 ~60 ~50 ~120 ~66 ~50 stone
fill ~115 ~67 ~50 ~120 ~69 ~50 dirt
fill ~115 ~70 ~50 ~120 ~70 ~50 grass_block
fill ~121 ~60 ~50 ~125 ~65 ~50 stone
fill ~121 ~66 ~50 ~125 ~68 ~50 dirt
fill ~121 ~69 ~50 ~125 ~69 ~50 grass_block
fill ~126 ~60 ~50 ~127 ~66 ~50 stone
fill ~126 ~67 ~50 ~127 ~69 ~50 dirt
fill ~126 ~70 ~50 ~127 ~70 ~50 grass_block
fill ~112 ~60 ~51 ~112 ~64 ~51 stone
fill ~112 ~65 ~51 ~112 ~67 ~51 dirt
fill ~112 ~68 ~51 ~112 ~68 ~51 grass_block
fill ~113 ~60 ~51 ~114 ~65 ~51 stone
fill ~113 ~66 ~51 ~114 ~68 ~51 dirt
fill ~113 ~69 ~51 ~114 ~69 ~51 grass_block
fill ~115 ~60 ~51 ~119 ~66 ~51 stone
fill ~115 ~67 ~51 ~119 ~69 ~51 dirt
fill ~115 ~70 ~51 ~119 ~70 ~51 grass_block
fill ~120 ~60 ~51 ~125 ~65 ~51 stone
fill ~120 ~66 ~51 ~125 ~68 ~51 dirt
fill ~120 ~69 ~51 ~125 ~69 ~51 grass_block
fill ~126 ~60 ~51 ~127 ~66 ~51 stone
fill ~126 ~67 ~51 ~127 ~69 ~51 dirt
fill ~126 ~70 ~51 ~127 ~70 ~51 grass_block
fill ~112 ~60 ~52 ~112 ~64 ~52 stone
fill ~112 ~65 ~52 ~112 ~67 ~52 dirt
fill ~112 ~68 ~52 ~112 ~68 ~52 grass_block
fill ~113 ~60 ~52 ~115 ~65 ~52 stone
fill ~113 ~66 ~52 ~115 ~68 ~52 dirt
fill ~113 ~69 ~52 ~115 ~69 ~52 grass_block
fill ~116 ~60 ~52 ~119 ~66 ~52 stone
fill ~116 ~67 ~52 ~119 ~69 ~52 dirt
fill ~116 ~70 ~52 ~119 ~70 ~52 grass_block
fill ~120 ~60 ~52 ~122 ~65 ~52 stone
fill ~120 ~66 ~52 ~122 ~68 ~52 dirt
fill ~120 ~69 ~52 ~122 ~69 ~52 grass_block
fill ~123 ~60 ~52 ~123 ~64 ~52 stone
fill ~123 ~65 ~52 ~123 ~67 ~52 dirt
fill ~123 ~68 ~52 ~123 ~68 ~52 grass_block
fill ~124 ~60 ~52 ~126 ~65 ~52 stone
fill ~124 ~66 ~52 ~126 ~68 ~52 dirt
fill ~124 ~69 ~52 ~126 ~69 ~52 grass_block
fill ~127 ~60 ~52 ~127 ~66 ~52 stone
fill ~127 ~67 ~52 ~127 ~69 ~52 dirt
fill ~127 ~70 ~52 ~127 ~70 ~52 grass_block
fill ~112 ~60 ~53 ~113 ~64 ~53 stone
fill ~112 ~65 ~53 ~113 ~67 ~53 dirt
fill ~112 ~68 ~53 ~113 ~68 ~53 grass_block
fill ~114 ~60 ~53 ~116 ~65 ~53 stone
fill ~114 ~66 ~53 ~116 ~68 ~53 dirt
fill ~114 ~69 ~53 ~116 ~69 ~53 grass_block
fill ~117 ~60 ~53 ~117 ~66 ~53 stone
fill ~117 ~67 ~53 ~117 ~69 ~53 dirt
fill ~117 ~70 ~53 ~117 ~70 ~53 grass_block
fill ~118 ~60 ~53 ~121 ~65 ~53 stone
fill ~118 ~66 ~53 ~121 ~68 ~53 dirt
fill ~118 ~69 ~53 ~121 ~69 ~53 grass_block
fill ~122 ~60 ~53 ~123 ~64 ~53 stone
fill ~122 ~65 ~53 ~123 ~67 ~53 dirt
fill ~122 ~68 ~53 ~123 ~68 ~53 grass_block
fill ~124 ~60 ~53 ~126 ~65 ~53 stone
fill ~124 ~66 ~53 ~126 ~68 ~53 dirt
fill ~124 ~69 ~53 ~126 ~69 ~53 grass_block
fill ~127 ~60 ~53 ~127 ~66 ~53 stone
fill ~127 ~67 ~53 ~127 ~69 ~53 dirt
fill ~127 ~70 ~53 ~127 ~70 ~53 grass_block
fill ~112 ~60 ~54 ~113 ~64 ~54 stone
fill ~112 ~65 ~54 ~113 ~67 ~54 dirt
fill ~112 ~68 ~54 ~113 ~68 ~54 grass_block
fill ~114 ~60 ~54 ~120 ~65 ~54 stone
fill ~114 ~66 ~54 ~120 ~68 ~54 dirt
fill ~114 ~69 ~54 ~120 ~69 ~54 grass_block
fill ~121 ~60 ~54 ~124 ~64 ~54 stone
fill ~121 ~65 ~54 ~124 ~67 ~54 dirt
fill ~121 ~68 ~54 ~124 ~68 ~54 grass_block
fill ~125 ~60 ~54 ~126 ~65 ~54 stone
fill ~125 ~66 ~54 ~126 ~68 ~54 dirt
fill ~125 ~69 ~54 ~126 ~69 ~54 grass_block
fill ~127 ~60 ~54 ~127 ~66 ~54 stone
fill ~127 ~67 ~54 ~127 ~69 ~54 dirt
fill ~127 ~70 ~54 ~127 ~70 ~54 grass_block
fill ~112 ~60 ~55 ~114 ~64 ~55 stone
fill ~112 ~65 ~55 ~114 ~67 ~55 dirt
fill ~112 ~68 ~55 ~114 ~68 ~55 grass_block
fill ~115 ~60 ~55 ~119 ~65 ~55 stone
fill ~115 ~66 ~55 ~119 ~68 ~55 dirt
fill ~115 ~69 ~55 ~119 ~69 ~55 grass_block
fill ~120 ~60 ~55 ~124 ~64 ~55 stone
fill ~120 ~65 ~55 ~124 ~67 ~55 dirt
fill ~120 ~68 ~55 ~124 ~68 ~55 grass_block
fill ~125 ~60 ~55 ~126 ~65 ~55 stone
fill ~125 ~66 ~55 ~126 ~68 ~55 dirt
fill ~125 ~69 ~55 ~126 ~69 ~55 grass_block
fill ~127 ~60 ~55 ~127 ~66 ~55 stone
fill ~127 ~67 ~55 ~127 ~69 ~55 dirt
fill ~127 ~70 ~55 ~127 ~70 ~55 grass_block
fill ~112 ~60 ~56 ~112 ~63 ~56 stone
fill ~112 ~64 ~56 ~112 ~66 ~56 dirt
fill ~112 ~67 ~56 ~112 ~67 ~56 grass_block
fill ~113 ~60 ~56 ~114 ~64 ~56 stone
fill ~113 ~65 ~56 ~114 ~67 ~56 dirt
fill ~113 ~68 ~56 ~114 ~68 ~56 grass_block
fill ~115 ~60 ~56 ~118 ~65 ~56 stone
fill ~115 ~66 ~56 ~118 ~68 ~56 dirt
fill ~115 ~69 ~56 ~118 ~69 ~56 grass_block
fill ~119 ~60 ~56 ~124 ~64 ~56 stone
fill ~119 ~65 ~56 ~124 ~67 ~56 dirt
fill ~119 ~68 ~56 ~124 ~68 ~56 grass_block
fill ~125 ~60 ~56 ~126 ~65 ~56 stone
fill ~125 ~66 ~56 ~126 ~68 ~56 dirt
fill ~125 ~69 ~56 ~126 ~69 ~56 grass_block
fill ~127 ~60 ~56 ~127 ~66 ~56 stone
fill ~127 ~67 ~56 ~127 ~69 ~56 dirt
fill ~127 ~70 ~56 ~127 ~70 ~56 grass_block
fill ~112 ~60 ~57 ~112 ~63 ~57 stone
fill ~112 ~64 ~57 ~112 ~66 ~57 dirt
fill ~112 ~67 ~57 ~112 ~67 ~57 grass_block
fill ~113 ~60 ~57 ~116 ~64 ~57 stone
fill ~113 ~65 ~57 ~116 ~67 ~57 dirt
fill ~113 ~68 ~57 ~116 ~68 ~57 grass_block
fill ~117 ~60 ~57 ~117 ~65 ~57 stone
fill ~117 ~66 ~57 ~117 ~68 ~57 dirt
fill ~117 ~69 ~57 ~117 ~69 ~57 grass_block
fill ~118 ~60 ~57 ~124 ~64 ~57 stone
fill ~118 ~65 ~57 ~124 ~67 ~57 dirt
fill ~118 ~68 ~57 ~124 ~68 ~57 grass_block
fill ~125 ~60 ~57 ~126 ~65 ~57 stone
fill ~125 ~66 ~57 ~126 ~68 ~57 dirt
fill ~125 ~69 ~57 ~126 ~69 ~57 grass_block
fill ~127 ~60 ~57 ~127 ~66 ~57 stone
fill ~127 ~67 ~57 ~127 ~69 ~57 dirt
fill ~127 ~70 ~57 ~127 ~70 ~57 grass_block
fill ~112 ~60 ~58 ~112 ~63 ~58 stone
fill ~112 ~64 ~58 ~112 ~66 ~58 dirt
fill ~112 ~67 ~58 ~112 ~67 ~58 grass_block
fill ~113 ~60 ~58 ~120 ~64 ~58 stone
fill ~113 ~65 ~58 ~120 ~67 ~58 dirt
fill ~113 ~68 ~58 ~120 ~68 ~58 grass_block
fill ~121 ~60 ~58 ~122 ~63 ~58 stone
fill ~121 ~64 ~58 ~122 ~66 ~58 dirt
fill ~121 ~67 ~58 ~122 ~67 ~58 grass_block
fill ~123 ~60 ~58 ~124 ~64 ~58 stone
fill ~123 ~65 ~58 ~124 ~67 ~58 dirt
fill ~123 ~68 ~58 ~124 ~68 ~58 grass_block
fill ~125 ~60 ~58 ~127 ~65 ~58 stone
fill ~125 ~66 ~58 ~127 ~68 ~58 dirt
fill ~125 ~69 ~58 ~127 ~69 ~58 grass_block
fill ~112 ~60 ~59 ~113 ~63 ~59 stone
fill ~112 ~64 ~59 ~113 ~66 ~59 dirt
fill ~112 ~67 ~59 ~113 ~67 ~59 grass_block
fill ~114 ~60 ~59 ~120 ~64 ~59 stone
fill ~114 ~65 ~59 ~120 ~67 ~59 dirt
fill ~114 ~68 ~59 ~120 ~68 ~59 grass_block
fill ~121 ~60 ~59 ~122 ~63 ~59 stone
fill ~121 ~64 ~59 ~122 ~66 ~59 dirt
fill ~121 ~67 ~59 ~122 ~67 ~59 grass_block
fill ~123 ~60 ~59 ~124 ~64 ~59 stone
fill ~123 ~65 ~59 ~124 ~67 ~59 dirt
fill ~123 ~68 ~59 ~124 ~68 ~59 grass_block
fill ~125 ~60 ~59 ~127 ~65 ~59 stone
fill ~125 ~66 ~59 ~127 ~68 ~59 dirt
fill ~125 ~69 ~59 ~127 ~69 ~59 grass_block
fill ~112 ~60 ~60 ~113 ~63 ~60 stone
fill ~112 ~64 ~60 ~113 ~66 ~60 dirt
fill ~112 ~67 ~60 ~113 ~67 ~60 grass_block
fill ~114 ~60 ~60 ~118 ~64 ~60 stone
fill ~114 ~65 ~60 ~118 ~67 ~60 dirt
fill ~114 ~68 ~60 ~118 ~68 ~60 grass_block
fill ~119 ~60 ~60 ~121 ~63 ~60 stone
fill ~119 ~64 ~60 ~121 ~66 ~60 dirt
fill ~119 ~67 ~60 ~121 ~67 ~60 grass_block
fill ~122 ~60 ~60 ~123 ~64 ~60 stone
fill ~122 ~65 ~60 ~123 ~67 ~60 dirt
fill ~122 ~68 ~60 ~123 ~68 ~60 grass_block
fill ~124 ~60 ~60 ~127 ~65 ~60 stone
fill ~124 ~66 ~60 ~127 ~68 ~60 dirt
fill ~124 ~69 ~60 ~127 ~69 ~60 grass_block
fill ~112 ~60 ~61 ~121 ~63 ~61 stone
fill ~112 ~64 ~61 ~121 ~66 ~61 dirt
fill ~112 ~67 ~61 ~121 ~67 ~61 grass_block
fill ~122 ~60 ~61 ~122 ~64 ~61 stone
fill ~122 ~65 ~61 ~122 ~67 ~61 dirt
fill ~122 ~68 ~61 ~122 ~68 ~61 grass_block
fill ~123 ~60 ~61 ~127 ~65 ~61 stone
fill ~123 ~66 ~61 ~127 ~68 ~61 dirt
fill ~123 ~69 ~61 ~127 ~69 ~61 grass_block
fill ~112 ~60 ~62 ~119 ~63 ~62 stone
fill ~112 ~64 ~62 ~119 ~66 ~62 dirt
fill ~112 ~67 ~62 ~119 ~67 ~62 grass_block
fill ~120 ~60 ~62 ~122 ~64 ~62 stone
fill ~120 ~65 ~62 ~122 ~67 ~62 dirt
fill ~120 ~68 ~62 ~122 ~68 ~62 grass_block
fill ~123 ~60 ~62 ~127 ~65 ~62 stone
fill ~123 ~66 ~62 ~127 ~68 ~62 dirt
fill ~123 ~69 ~62 ~127 ~69 ~62 grass_block
fill ~112 ~60 ~63 ~118 ~63 ~63 stone
fill ~112 ~64 ~63 ~118 ~66 ~63 dirt
fill ~112 ~67 ~63 ~118 ~67 ~63 grass_block
fill ~119 ~60 ~63 ~122 ~64 ~63 stone
fill ~119 ~65 ~63 ~122 ~67 ~63 dirt
fill ~119 ~68 ~63 ~122 ~68 ~63 grass_block
fill ~123 ~60 ~63 ~127 ~65 ~63 stone
fill ~123 ~66 ~63 ~127 ~68 ~63 dirt
fill ~123 ~69 ~63 ~127 ~69 ~63 grass_block