fill ~208 ~60 ~112 ~208 ~63 ~112 stone
fill ~208 ~64 ~112 ~208 ~66 ~112 dirt
fill ~208 ~67 ~112 ~208 ~67 ~112 grass_block
fill ~209 ~60 ~112 ~211 ~64 ~112 stone
fill ~209 ~65 ~112 ~211 ~67 ~112 dirt
fill ~209 ~68 ~112 ~211 ~68 ~112 grass_block
fill ~212 ~60 ~112 ~217 ~65 ~112 stone
fill ~212 ~66 ~112 ~217 ~68 ~112 dirt
fill ~212 ~69 ~112 ~217 ~69 ~112 grass_block
fill ~218 ~60 ~112 ~223 ~66 ~112 stone
fill ~218 ~67 ~112 ~223 ~69 ~112 dirt
fill ~218 ~70 ~112 ~223 ~70 ~112 grass_block
fill ~208 ~60 ~113 ~208 ~63 ~113 stone
fill ~208 ~64 ~113 ~208 ~66 ~113 dirt
fill ~208 ~67 ~113 ~208 ~67 ~113 grass_block
fill ~209 ~60 ~113 ~215 ~64 ~113 stone
fill ~209 ~65 ~113 ~215 ~67 ~113 dirt
fill ~209 ~68 ~113 ~215 ~68 ~113 grass_block
fill ~216 ~60 ~113 ~223 ~65 ~113 stone
fill ~216 ~66 ~113 ~223 ~68 ~113 dirt
fill ~216 ~69 ~113 ~223 ~69 ~113 grass_block
fill ~208 ~60 ~114 ~209 ~63 ~114 stone
fill ~208 ~64 ~114 ~209 ~66 ~114 dirt
fill ~208 ~67 ~114 ~209 ~67 ~114 grass_block
fill ~210 ~60 ~114 ~216 ~64 ~114 stone
fill ~210 ~65 ~114 ~216 ~67 ~114 dirt
fill ~210 ~68 ~114 ~216 ~68 ~114 grass_block
fill ~217 ~60 ~114 ~223 ~65 ~114 stone
fill ~217 ~66 ~114 ~223 ~68 ~114 dirt
fill ~217 ~69 ~114 ~223 ~69 ~114 grass_block
fill ~208 ~60 ~115 ~214 ~63 ~115 stone
fill ~208 ~64 ~115 ~214 ~66 ~115 dirt
fill ~208 ~67 ~115 ~214 ~67 ~115 grass_block
fill ~215 ~60 ~115 ~217 ~64 ~115 stone
fill ~215 ~65 ~115 ~217 ~67 ~115 dirt
fill ~215 ~68 ~115 ~217 ~68 ~115 grass_block
fill ~218 ~60 ~115 ~223 ~65 ~115 stone
fill ~218 ~66 ~115 ~223 ~68 ~115 dirt
fill ~218 ~69 ~115 ~223 ~69 ~115 grass_block
fill ~208 ~60 ~116 ~208 ~63 ~116 stone
fill ~208 ~64 ~116 ~208 ~66 ~116 dirt
fill ~208 ~67 ~116 ~208 ~67 ~116 grass_block
fill ~209 ~60 ~116 ~209 ~62 ~116 stone
fill ~209 ~63 ~116 ~209 ~65 ~116 dirt
fill ~209 ~66 ~116 ~209 ~66 ~116 grass_block
fill ~210 ~60 ~116 ~213 ~63 ~116 stone
fill ~210 ~64 ~116 ~213 ~66 ~116 dirt
fill ~210 ~67 ~116 ~213 ~67 ~116 grass_block
fill ~214 ~60 ~116 ~217 ~64 ~116 stone
fill ~214 ~65 ~116 ~217 ~67 ~116 dirt
fill ~214 ~68 ~116 ~217 ~68 ~116 grass_block
fill ~218 ~60 ~116 ~221 ~65 ~116 stone
fill ~218 ~66 ~116 ~221 ~68 ~116 dirt
fill ~218 ~69 ~116 ~221 ~69 ~116 grass_block
fill ~222 ~60 ~116 ~223 ~64 ~116 stone
fill ~222 ~65 ~116 ~223 ~67 ~116 dirt
fill ~222 ~68 ~116 ~223 ~68 ~116 grass_block
fill ~208 ~60 ~117 ~208 ~62 ~117 stone
fill ~208 ~63 ~117 ~208 ~65 ~117 dirt
fill ~208 ~66 ~117 ~208 ~66 ~117 grass_block
fill ~209 ~60 ~117 ~213 ~63 ~117 stone
fill ~209 ~64 ~117 ~213 ~66 ~117 dirt
fill ~209 ~67 ~117 ~213 ~67 ~117 grass_block
fill ~214 ~60 ~117 ~223 ~64 ~117 stone
fill ~214 ~65 ~117 ~223 ~67 ~117 dirt
fill ~214 ~68 ~117 ~223 ~68 ~117 grass_block
fill ~208 ~60 ~118 ~208 ~62 ~118 stone
fill ~208 ~63 ~118 ~208 ~65 ~118 dirt
fill ~208 ~66 ~118 ~208 ~66 ~118 grass_block
fill ~209 ~60 ~118 ~214 ~63 ~118 stone
fill ~209 ~64 ~118 ~214 ~66 ~118 dirt
fill ~209 ~67 ~118 ~214 ~67 ~118 grass_block
fill ~215 ~60 ~118 ~223 ~64 ~118 stone
fill ~215 ~65 ~118 ~223 ~67 ~118 dirt
fill ~215 ~68 ~118 ~223 ~68 ~118 grass_block
fill ~208 ~60 ~119 ~208 ~62 ~119 stone
fill ~208 ~63 ~119 ~208 ~65 ~119 dirt
fill ~208 ~66 ~119 ~208 ~66 ~119 grass_block
fill ~209 ~60 ~119 ~210 ~63 ~119 stone
fill ~209 ~64 ~119 ~210 ~66 ~119 dirt
fill ~209 ~67 ~119 ~210 ~67 ~119 grass_block
fill ~211 ~60 ~119 ~223 ~64 ~119 stone
fill ~211 ~65 ~119 ~223 ~67 ~119 dirt
fill ~211 ~68 ~119 ~223 ~68 ~119 grass_block
fill ~208 ~60 ~120 ~208 ~62 ~120 stone
fill ~208 ~63 ~120 ~208 ~65 ~120 dirt
fill ~208 ~66 ~120 ~208 ~66 ~120 grass_block
fill ~209 ~60 ~120 ~210 ~63 ~120 stone
fill ~209 ~64 ~120 ~210 ~66 ~120 dirt
fill ~209 ~67 ~120 ~210 ~67 ~120 grass_block
fill ~211 ~60 ~120 ~222 ~64 ~120 stone
fill ~211 ~65 ~120 ~222 ~67 ~120 dirt
fill ~211 ~68 ~120 ~222 ~68 ~120 grass_block
fill ~223 ~60 ~120 ~223 ~63 ~120 stone
fill ~223 ~64 ~120 ~223 ~66 ~120 dirt
fill ~223 ~67 ~120 ~223 ~67 ~120 grass_block
fill ~208 ~60 ~121 ~209 ~62 ~121 stone
fill ~208 ~63 ~121 ~209 ~65 ~121 dirt
fill ~208 ~66 ~121 ~209 ~66 ~121 grass_block
fill ~210 ~60 ~121 ~211 ~63 ~121 stone
fill ~210 ~64 ~121 ~211 ~66 ~121 dirt
fill ~210 ~67 ~121 ~211 ~67 ~121 grass_block
fill ~212 ~60 ~121 ~221 ~64 ~121 stone
fill ~212 ~65 ~121 ~221 ~67 ~121 dirt
fill ~212 ~68 ~121 ~221 ~68 ~121 grass_block
fill ~222 ~60 ~121 ~223 ~63 ~121 stone
fill ~222 ~64 ~121 ~223 ~66 ~121 dirt
fill ~222 ~67 ~121 ~223 ~67 ~121 grass_block
fill ~208 ~60 ~122 ~209 ~62 ~122 stone
fill ~208 ~63 ~122 ~209 ~65 ~122 dirt
fill ~208 ~66 ~122 ~209 ~66 ~122 grass_block
fill ~210 ~60 ~122 ~211 ~63 ~122 stone
fill ~210 ~64 ~122 ~211 ~66 ~122 dirt
fill ~210 ~67 ~122 ~211 ~67 ~122 grass_block
fill ~212 ~60 ~122 ~220 ~64 ~122 stone
fill ~212 ~65 ~122 ~220 ~67 ~122 dirt
fill ~212 ~68 ~122 ~220 ~68 ~122 grass_block
fill ~221 ~60 ~122 ~223 ~63 ~122 stone
fill ~221 ~64 ~122 ~223 ~66 ~122 dirt
fill ~221 ~67 ~122 ~223 ~67 ~122 grass_block
fill ~208 ~60 ~123 ~209 ~62 ~123 stone
fill ~208 ~63 ~123 ~209 ~65 ~123 dirt
fill ~208 ~66 ~123 ~209 ~66 ~123 grass_block
fill ~210 ~60 ~123 ~211 ~63 ~123 stone
fill ~210 ~64 ~123 ~211 ~66 ~123 dirt
fill ~210 ~67 ~123 ~211 ~67 ~123 grass_block
fill ~212 ~60 ~123 ~219 ~64 ~123 stone
fill ~212 ~65 ~123 ~219 ~67 ~123 dirt
fill ~212 ~68 ~123 ~219 ~68 ~123 grass_block
fill ~220 ~60 ~123 ~223 ~63 ~123 stone
fill ~220 ~64 ~123 ~223 ~66 ~123 dirt
fill ~220 ~67 ~123 ~223 ~67 ~123 grass_block
fill ~208 ~60 ~124 ~209 ~62 ~124 stone
fill ~208 ~63 ~124 ~209 ~65 ~124 dirt
fill ~208 ~66 ~124 ~209 ~66 ~124 grass_block
fill ~210 ~60 ~124 ~212 ~63 ~124 stone
fill ~210 ~64 ~124 ~212 ~66 ~124 dirt
fill ~210 ~67 ~124 ~212 ~67 ~124 grass_block
fill ~213 ~60 ~124 ~218 ~64 ~124 stone
fill ~213 ~65 ~124 ~218 ~67 ~124 dirt
fill ~213 ~68 ~124 ~218 ~68 ~124 grass_block
fill ~219 ~60 ~124 ~223 ~63 ~124 stone
fill ~219 ~64 ~124 ~223 ~66 ~124 dirt
fill ~219 ~67 ~124 ~223 ~67 ~124 grass_block
fill ~208 ~60 ~125 ~209 ~62 ~125 stone
fill ~208 ~63 ~125 ~209 ~65 ~125 dirt
fill ~208 ~66 ~125 ~209 ~66 ~125 grass_block
fill ~210 ~60 ~125 ~214 ~63 ~125 stone
fill ~210 ~64 ~125 ~214 ~66 ~125 dirt
fill ~210 ~67 ~125 ~214 ~67 ~125 grass_block
fill ~215 ~60 ~125 ~218 ~64 ~125 stone
fill ~215 ~65 ~125 ~218 ~67 ~125 dirt
fill ~215 ~68 ~125 ~218 ~68 ~125 grass_block
fill ~219 ~60 ~125 ~223 ~63 ~125 stone
fill ~219 ~64 ~125 ~223 ~66 ~125 dirt
fill ~219 ~67 ~125 ~223 ~67 ~125 grass_block
fill ~208 ~60 ~126 ~209 ~62 ~126 stone
fill ~208 ~63 ~126 ~209 ~65 ~126 dirt
fill ~208 ~66 ~126 ~209 ~66 ~126 grass_block
fill ~210 ~60 ~126 ~215 ~63 ~126 stone
fill ~210 ~64 ~126 ~215 ~66 ~126 dirt
fill ~210 ~67 ~126 ~215 ~67 ~126 grass_block
fill ~216 ~60 ~126 ~217 ~64 ~126 stone
fill ~216 ~65 ~126 ~217 ~67 ~126 dirt
fill ~216 ~68 ~126 ~217 ~68 ~126 grass_block
fill ~218 ~60 ~126 ~223 ~63 ~126 stone
fill ~218 ~64 ~126 ~223 ~66 ~126 dirt
fill ~218 ~67 ~126 ~223 ~67 ~126 grass_block
fill ~208 ~60 ~127 ~210 ~62 ~127 stone
fill ~208 ~63 ~127 ~210 ~65 ~127 dirt
fill ~208 ~66 ~127 ~210 ~66 ~127 grass_block
fill ~211 ~60 ~127 ~223 ~63 ~127 stone
fill ~211 ~64 ~127 ~223 ~66 ~127 dirt
fill ~211 ~67 ~127 ~223 ~67 ~127 grass_block