fill ~304 ~60 ~32 ~305 ~65 ~32 stone
fill ~304 ~66 ~32 ~305 ~68 ~32 dirt
fill ~304 ~69 ~32 ~305 ~69 ~32 grass_block
fill ~306 ~60 ~32 ~312 ~64 ~32 stone
fill ~306 ~65 ~32 ~312 ~67 ~32 dirt
fill ~306 ~68 ~32 ~312 ~68 ~32 grass_block
fill ~313 ~60 ~32 ~316 ~63 ~32 stone
fill ~313 ~64 ~32 ~316 ~66 ~32 dirt
fill ~313 ~67 ~32 ~316 ~67 ~32 grass_block
fill ~317 ~60 ~32 ~319 ~62 ~32 stone
fill ~317 ~63 ~32 ~319 ~65 ~32 dirt
fill ~317 ~66 ~32 ~319 ~66 ~32 grass_block
fill ~304 ~60 ~33 ~306 ~65 ~33 stone
fill ~304 ~66 ~33 ~306 ~68 ~33 dirt
fill ~304 ~69 ~33 ~306 ~69 ~33 grass_block
fill ~307 ~60 ~33 ~311 ~64 ~33 stone
fill ~307 ~65 ~33 ~311 ~67 ~33 dirt
fill ~307 ~68 ~33 ~311 ~68 ~33 grass_block
fill ~312 ~60 ~33 ~317 ~63 ~33 stone
fill ~312 ~64 ~33 ~317 ~66 ~33 dirt
fill ~312 ~67 ~33 ~317 ~67 ~33 grass_block
fill ~318 ~60 ~33 ~319 ~62 ~33 stone
fill ~318 ~63 ~33 ~319 ~65 ~33 dirt
fill ~318 ~66 ~33 ~319 ~66 ~33 grass_block
fill ~304 ~60 ~34 ~306 ~65 ~34 stone
fill ~304 ~66 ~34 ~306 ~68 ~34 dirt
fill ~304 ~69 ~34 ~306 ~69 ~34 grass_block
fill ~307 ~60 ~34 ~311 ~64 ~34 stone
fill ~307 ~65 ~34 ~311 ~67 ~34 dirt
fill ~307 ~68 ~34 ~311 ~68 ~34 grass_block
fill ~312 ~60 ~34 ~316 ~63 ~34 stone
fill ~312 ~64 ~34 ~316 ~66 ~34 dirt
fill ~312 ~67 ~34 ~316 ~67 ~34 grass_block
fill ~317 ~60 ~34 ~319 ~62 ~34 stone
fill ~317 ~63 ~34 ~319 ~65 ~34 dirt
fill ~317 ~66 ~34 ~319 ~66 ~34 grass_block
fill ~304 ~60 ~35 ~306 ~65 ~35 stone
fill ~304 ~66 ~35 ~306 ~68 ~35 dirt
fill ~304 ~69 ~35 ~306 ~69 ~35 grass_block
fill ~307 ~60 ~35 ~310 ~64 ~35 stone
fill ~307 ~65 ~35 ~310 ~67 ~35 dirt
fill ~307 ~68 ~35 ~310 ~68 ~35 grass_block
fill ~311 ~60 ~35 ~311 ~63 ~35 stone
fill ~311 ~64 ~35 ~311 ~66 ~35 dirt
fill ~311 ~67 ~35 ~311 ~67 ~35 grass_block
fill ~312 ~60 ~35 ~312 ~64 ~35 stone
fill ~312 ~65 ~35 ~312 ~67 ~35 dirt
fill ~312 ~68 ~35 ~312 ~68 ~35 grass_block
fill ~313 ~60 ~35 ~316 ~63 ~35 stone
fill ~313 ~64 ~35 ~316 ~66 ~35 dirt
fill ~313 ~67 ~35 ~316 ~67 ~35 grass_block
fill ~317 ~60 ~35 ~319 ~62 ~35 stone
fill ~317 ~63 ~35 ~319 ~65 ~35 dirt
fill ~317 ~66 ~35 ~319 ~66 ~35 grass_block
fill ~304 ~60 ~36 ~306 ~65 ~36 stone
fill ~304 ~66 ~36 ~306 ~68 ~36 dirt
fill ~304 ~69 ~36 ~306 ~69 ~36 grass_block
fill ~307 ~60 ~36 ~311 ~64 ~36 stone
fill ~307 ~65 ~36 ~311 ~67 ~36 dirt
fill ~307 ~68 ~36 ~311 ~68 ~36 grass_block
fill ~312 ~60 ~36 ~316 ~63 ~36 stone
fill ~312 ~64 ~36 ~316 ~66 ~36 dirt
fill ~312 ~67 ~36 ~316 ~67 ~36 grass_block
fill ~317 ~60 ~36 ~319 ~62 ~36 stone
fill ~317 ~63 ~36 ~319 ~65 ~36 dirt
fill ~317 ~66 ~36 ~319 ~66 ~36 grass_block
fill ~304 ~60 ~37 ~305 ~65 ~37 stone
fill ~304 ~66 ~37 ~305 ~68 ~37 dirt
fill ~304 ~69 ~37 ~305 ~69 ~37 grass_block
fill ~306 ~60 ~37 ~311 ~64 ~37 stone
fill ~306 ~65 ~37 ~311 ~67 ~37 dirt
fill ~306 ~68 ~37 ~311 ~68 ~37 grass_block
fill ~312 ~60 ~37 ~316 ~63 ~37 stone
fill ~312 ~64 ~37 ~316 ~66 ~37 dirt
fill ~312 ~67 ~37 ~316 ~67 ~37 grass_block
fill ~317 ~60 ~37 ~319 ~62 ~37 stone
fill ~317 ~63 ~37 ~319 ~65 ~37 dirt
fill ~317 ~66 ~37 ~319 ~66 ~37 grass_block
fill ~304 ~60 ~38 ~304 ~65 ~38 stone
fill ~304 ~66 ~38 ~304 ~68 ~38 dirt
fill ~304 ~69 ~38 ~304 ~69 ~38 grass_block
fill ~305 ~60 ~38 ~311 ~64 ~38 stone
fill ~305 ~65 ~38 ~311 ~67 ~38 dirt
fill ~305 ~68 ~38 ~311 ~68 ~38 grass_block
fill ~312 ~60 ~38 ~316 ~63 ~38 stone
fill ~312 ~64 ~38 ~316 ~66 ~38 dirt
fill ~312 ~67 ~38 ~316 ~67 ~38 grass_block
fill ~317 ~60 ~38 ~319 ~62 ~38 stone
fill ~317 ~63 ~38 ~319 ~65 ~38 dirt
fill ~317 ~66 ~38 ~319 ~66 ~38 grass_block
fill ~304 ~60 ~39 ~312 ~64 ~39 stone
fill ~304 ~65 ~39 ~312 ~67 ~39 dirt
fill ~304 ~68 ~39 ~312 ~68 ~39 grass_block
fill ~313 ~60 ~39 ~316 ~63 ~39 stone
fill ~313 ~64 ~39 ~316 ~66 ~39 dirt
fill ~313 ~67 ~39 ~316 ~67 ~39 grass_block
fill ~317 ~60 ~39 ~319 ~62 ~39 stone
fill ~317 ~63 ~39 ~319 ~65 ~39 dirt
fill ~317 ~66 ~39 ~319 ~66 ~39 grass_block
fill ~304 ~60 ~40 ~311 ~64 ~40 stone
fill ~304 ~65 ~40 ~311 ~67 ~40 dirt
fill ~304 ~68 ~40 ~311 ~68 ~40 grass_block
fill ~312 ~60 ~40 ~316 ~63 ~40 stone
fill ~312 ~64 ~40 ~316 ~66 ~40 dirt
fill ~312 ~67 ~40 ~316 ~67 ~40 grass_block
fill ~317 ~60 ~40 ~319 ~62 ~40 stone
fill ~317 ~63 ~40 ~319 ~65 ~40 dirt
fill ~317 ~66 ~40 ~319 ~66 ~40 grass_block
fill ~304 ~60 ~41 ~309 ~64 ~41 stone
fill ~304 ~65 ~41 ~309 ~67 ~41 dirt
fill ~304 ~68 ~41 ~309 ~68 ~41 grass_block
fill ~310 ~60 ~41 ~316 ~63 ~41 stone
fill ~310 ~64 ~41 ~316 ~66 ~41 dirt
fill ~310 ~67 ~41 ~316 ~67 ~41 grass_block
fill ~317 ~60 ~41 ~319 ~62 ~41 stone
fill ~317 ~63 ~41 ~319 ~65 ~41 dirt
fill ~317 ~66 ~41 ~319 ~66 ~41 grass_block
fill ~304 ~60 ~42 ~308 ~64 ~42 stone
fill ~304 ~65 ~42 ~308 ~67 ~42 dirt
fill ~304 ~68 ~42 ~308 ~68 ~42 grass_block
fill ~309 ~60 ~42 ~316 ~63 ~42 stone
fill ~309 ~64 ~42 ~316 ~66 ~42 dirt
fill ~309 ~67 ~42 ~316 ~67 ~42 grass_block
fill ~317 ~60 ~42 ~319 ~62 ~42 stone
fill ~317 ~63 ~42 ~319 ~65 ~42 dirt
fill ~317 ~66 ~42 ~319 ~66 ~42 grass_block
fill ~304 ~60 ~43 ~308 ~64 ~43 stone
fill ~304 ~65 ~43 ~308 ~67 ~43 dirt
fill ~304 ~68 ~43 ~308 ~68 ~43 grass_block
fill ~309 ~60 ~43 ~316 ~63 ~43 stone
fill ~309 ~64 ~43 ~316 ~66 ~43 dirt
fill ~309 ~67 ~43 ~316 ~67 ~43 grass_block
fill ~317 ~60 ~43 ~319 ~62 ~43 stone
fill ~317 ~63 ~43 ~319 ~65 ~43 dirt
fill ~317 ~66 ~43 ~319 ~66 ~43 grass_block
fill ~304 ~60 ~44 ~306 ~64 ~44 stone
fill ~304 ~65 ~44 ~306 ~67 ~44 dirt
fill ~304 ~68 ~44 ~306 ~68 ~44 grass_block
fill ~307 ~60 ~44 ~315 ~63 ~44 stone
fill ~307 ~64 ~44 ~315 ~66 ~44 dirt
fill ~307 ~67 ~44 ~315 ~67 ~44 grass_block
fill ~316 ~60 ~44 ~319 ~62 ~44 stone
fill ~316 ~63 ~44 ~319 ~65 ~44 dirt
fill ~316 ~66 ~44 ~319 ~66 ~44 grass_block
fill ~304 ~60 ~45 ~305 ~64 ~45 stone
fill ~304 ~65 ~45 ~305 ~67 ~45 dirt
fill ~304 ~68 ~45 ~305 ~68 ~45 grass_block
fill ~306 ~60 ~45 ~314 ~63 ~45 stone
fill ~306 ~64 ~45 ~314 ~66 ~45 dirt
fill ~306 ~67 ~45 ~314 ~67 ~45 grass_block
fill ~315 ~60 ~45 ~319 ~62 ~45 stone
fill ~315 ~63 ~45 ~319 ~65 ~45 dirt
fill ~315 ~66 ~45 ~319 ~66 ~45 grass_block
fill ~304 ~60 ~46 ~313 ~63 ~46 stone
fill ~304 ~64 ~46 ~313 ~66 ~46 dirt
fill ~304 ~67 ~46 ~313 ~67 ~46 grass_block
fill ~314 ~60 ~46 ~319 ~62 ~46 stone
fill ~314 ~63 ~46 ~319 ~65 ~46 dirt
fill ~314 ~66 ~46 ~319 ~66 ~46 grass_block
fill ~304 ~60 ~47 ~304 ~64 ~47 stone
fill ~304 ~65 ~47 ~304 ~67 ~47 dirt
fill ~304 ~68 ~47 ~304 ~68 ~47 grass_block
fill ~305 ~60 ~47 ~313 ~63 ~47 stone
fill ~305 ~64 ~47 ~313 ~66 ~47 dirt
fill ~305 ~67 ~47 ~313 ~67 ~47 grass_block
fill ~314 ~60 ~47 ~319 ~62 ~47 stone
fill ~314 ~63 ~47 ~319 ~65 ~47 dirt
fill ~314 ~66 ~47 ~319 ~66 ~47 grass_block