fill ~272 ~60 ~0 ~274 ~64 ~0 stone
fill ~272 ~65 ~0 ~274 ~67 ~0 dirt
fill ~272 ~68 ~0 ~274 ~68 ~0 grass_block
fill ~275 ~60 ~0 ~279 ~65 ~0 stone
fill ~275 ~66 ~0 ~279 ~68 ~0 dirt
fill ~275 ~69 ~0 ~279 ~69 ~0 grass_block
fill ~280 ~60 ~0 ~283 ~66 ~0 stone
fill ~280 ~67 ~0 ~283 ~69 ~0 dirt
fill ~280 ~70 ~0 ~283 ~70 ~0 grass_block
fill ~284 ~60 ~0 ~287 ~65 ~0 stone
fill ~284 ~66 ~0 ~287 ~68 ~0 dirt
fill ~284 ~69 ~0 ~287 ~69 ~0 grass_block
fill ~272 ~60 ~1 ~274 ~64 ~1 stone
fill ~272 ~65 ~1 ~274 ~67 ~1 dirt
fill ~272 ~68 ~1 ~274 ~68 ~1 grass_block
fill ~275 ~60 ~1 ~287 ~65 ~1 stone
fill ~275 ~66 ~1 ~287 ~68 ~1 dirt
fill ~275 ~69 ~1 ~287 ~69 ~1 grass_block
fill ~272 ~60 ~2 ~287 ~65 ~2 stone
fill ~272 ~66 ~2 ~287 ~68 ~2 dirt
fill ~272 ~69 ~2 ~287 ~69 ~2 grass_block
fill ~272 ~60 ~3 ~287 ~65 ~3 stone
fill ~272 ~66 ~3 ~287 ~68 ~3 dirt
fill ~272 ~69 ~3 ~287 ~69 ~3 grass_block
fill ~272 ~60 ~4 ~286 ~65 ~4 stone
fill ~272 ~66 ~4 ~286 ~68 ~4 dirt
fill ~272 ~69 ~4 ~286 ~69 ~4 grass_block
fill ~287 ~60 ~4 ~287 ~64 ~4 stone
fill ~287 ~65 ~4 ~287 ~67 ~4 dirt
fill ~287 ~68 ~4 ~287 ~68 ~4 grass_block
fill ~272 ~60 ~5 ~285 ~65 ~5 stone
fill ~272 ~66 ~5 ~285 ~68 ~5 dirt
fill ~272 ~69 ~5 ~285 ~69 ~5 grass_block
fill ~286 ~60 ~5 ~287 ~64 ~5 stone
fill ~286 ~65 ~5 ~287 ~67 ~5 dirt
fill ~286 ~68 ~5 ~287 ~68 ~5 grass_block
fill ~272 ~60 ~6 ~283 ~65 ~6 stone
fill ~272 ~66 ~6 ~283 ~68 ~6 dirt
fill ~272 ~69 ~6 ~283 ~69 ~6 grass_block
fill ~284 ~60 ~6 ~287 ~64 ~6 stone
fill ~284 ~65 ~6 ~287 ~67 ~6 dirt
fill ~284 ~68 ~6 ~287 ~68 ~6 grass_block
fill ~272 ~60 ~7 ~282 ~65 ~7 stone
fill ~272 ~66 ~7 ~282 ~68 ~7 dirt
fill ~272 ~69 ~7 ~282 ~69 ~7 grass_block
fill ~283 ~60 ~7 ~287 ~64 ~7 stone
fill ~283 ~65 ~7 ~287 ~67 ~7 dirt
fill ~283 ~68 ~7 ~287 ~68 ~7 grass_block
fill ~272 ~60 ~8 ~272 ~64 ~8 stone
fill ~272 ~65 ~8 ~272 ~67 ~8 dirt
fill ~272 ~68 ~8 ~272 ~68 ~8 grass_block
fill ~273 ~60 ~8 ~281 ~65 ~8 stone
fill ~273 ~66 ~8 ~281 ~68 ~8 dirt
fill ~273 ~69 ~8 ~281 ~69 ~8 grass_block
fill ~282 ~60 ~8 ~287 ~64 ~8 stone
fill ~282 ~65 ~8 ~287 ~67 ~8 dirt
fill ~282 ~68 ~8 ~287 ~68 ~8 grass_block
fill ~272 ~60 ~9 ~273 ~64 ~9 stone
fill ~272 ~65 ~9 ~273 ~67 ~9 dirt
fill ~272 ~68 ~9 ~273 ~68 ~9 grass_block
fill ~274 ~60 ~9 ~281 ~65 ~9 stone
fill ~274 ~66 ~9 ~281 ~68 ~9 dirt
fill ~274 ~69 ~9 ~281 ~69 ~9 grass_block
fill ~282 ~60 ~9 ~287 ~64 ~9 stone
fill ~282 ~65 ~9 ~287 ~67 ~9 dirt
fill ~282 ~68 ~9 ~287 ~68 ~9 grass_block
fill ~272 ~60 ~10 ~275 ~64 ~10 stone
fill ~272 ~65 ~10 ~275 ~67 ~10 dirt
fill ~272 ~68 ~10 ~275 ~68 ~10 grass_block
fill ~276 ~60 ~10 ~281 ~65 ~10 stone
fill ~276 ~66 ~10 ~281 ~68 ~10 dirt
fill ~276 ~69 ~10 ~281 ~69 ~10 grass_block
fill ~282 ~60 ~10 ~287 ~64 ~10 stone
fill ~282 ~65 ~10 ~287 ~67 ~10 dirt
fill ~282 ~68 ~10 ~287 ~68 ~10 grass_block
fill ~272 ~60 ~11 ~273 ~63 ~11 stone
fill ~272 ~64 ~11 ~273 ~66 ~11 dirt
fill ~272 ~67 ~11 ~273 ~67 ~11 grass_block
fill ~274 ~60 ~11 ~276 ~64 ~11 stone
fill ~274 ~65 ~11 ~276 ~67 ~11 dirt
fill ~274 ~68 ~11 ~276 ~68 ~11 grass_block
fill ~277 ~60 ~11 ~280 ~65 ~11 stone
fill ~277 ~66 ~11 ~280 ~68 ~11 dirt
fill ~277 ~69 ~11 ~280 ~69 ~11 grass_block
fill ~281 ~60 ~11 ~287 ~64 ~11 stone
fill ~281 ~65 ~11 ~287 ~67 ~11 dirt
fill ~281 ~68 ~11 ~287 ~68 ~11 grass_block
fill ~272 ~60 ~12 ~273 ~63 ~12 stone
fill ~272 ~64 ~12 ~273 ~66 ~12 dirt
fill ~272 ~67 ~12 ~273 ~67 ~12 grass_block
fill ~274 ~60 ~12 ~287 ~64 ~12 stone
fill ~274 ~65 ~12 ~287 ~67 ~12 dirt
fill ~274 ~68 ~12 ~287 ~68 ~12 grass_block
fill ~272 ~60 ~13 ~274 ~63 ~13 stone
fill ~272 ~64 ~13 ~274 ~66 ~13 dirt
fill ~272 ~67 ~13 ~274 ~67 ~13 grass_block
fill ~275 ~60 ~13 ~285 ~64 ~13 stone
fill ~275 ~65 ~13 ~285 ~67 ~13 dirt
fill ~275 ~68 ~13 ~285 ~68 ~13 grass_block
fill ~286 ~60 ~13 ~287 ~63 ~13 stone
fill ~286 ~64 ~13 ~287 ~66 ~13 dirt
fill ~286 ~67 ~13 ~287 ~67 ~13 grass_block
fill ~272 ~60 ~14 ~273 ~63 ~14 stone
fill ~272 ~64 ~14 ~273 ~66 ~14 dirt
fill ~272 ~67 ~14 ~273 ~67 ~14 grass_block
fill ~274 ~60 ~14 ~285 ~64 ~14 stone
fill ~274 ~65 ~14 ~285 ~67 ~14 dirt
fill ~274 ~68 ~14 ~285 ~68 ~14 grass_block
fill ~286 ~60 ~14 ~287 ~63 ~14 stone
fill ~286 ~64 ~14 ~287 ~66 ~14 dirt
fill ~286 ~67 ~14 ~287 ~67 ~14 grass_block
fill ~272 ~60 ~15 ~274 ~63 ~15 stone
fill ~272 ~64 ~15 ~274 ~66 ~15 dirt
fill ~272 ~67 ~15 ~274 ~67 ~15 grass_block
fill ~275 ~60 ~15 ~284 ~64 ~15 stone
fill ~275 ~65 ~15 ~284 ~67 ~15 dirt
fill ~275 ~68 ~15 ~284 ~68 ~15 grass_block
fill ~285 ~60 ~15 ~287 ~63 ~15 stone
fill ~285 ~64 ~15 ~287 ~66 ~15 dirt
fill ~285 ~67 ~15 ~287 ~67 ~15 grass_block