fill ~448 ~60 ~96 ~448 ~63 ~96 stone
fill ~448 ~64 ~96 ~448 ~66 ~96 dirt
fill ~448 ~67 ~96 ~448 ~67 ~96 grass_block
fill ~449 ~60 ~96 ~455 ~62 ~96 stone
fill ~449 ~63 ~96 ~455 ~65 ~96 dirt
fill ~449 ~66 ~96 ~455 ~66 ~96 grass_block
fill ~456 ~60 ~96 ~459 ~63 ~96 stone
fill ~456 ~64 ~96 ~459 ~66 ~96 dirt
fill ~456 ~67 ~96 ~459 ~67 ~96 grass_block
fill ~460 ~60 ~96 ~463 ~64 ~96 stone
fill ~460 ~65 ~96 ~463 ~67 ~96 dirt
fill ~460 ~68 ~96 ~463 ~68 ~96 grass_block
fill ~448 ~60 ~97 ~448 ~63 ~97 stone
fill ~448 ~64 ~97 ~448 ~66 ~97 dirt
fill ~448 ~67 ~97 ~448 ~67 ~97 grass_block
fill ~449 ~60 ~97 ~456 ~62 ~97 stone
fill ~449 ~63 ~97 ~456 ~65 ~97 dirt
fill ~449 ~66 ~97 ~456 ~66 ~97 grass_block
fill ~457 ~60 ~97 ~459 ~63 ~97 stone
fill ~457 ~64 ~97 ~459 ~66 ~97 dirt
fill ~457 ~67 ~97 ~459 ~67 ~97 grass_block
fill ~460 ~60 ~97 ~463 ~64 ~97 stone
fill ~460 ~65 ~97 ~463 ~67 ~97 dirt
fill ~460 ~68 ~97 ~463 ~68 ~97 grass_block
fill ~448 ~60 ~98 ~448 ~63 ~98 stone
fill ~448 ~64 ~98 ~448 ~66 ~98 dirt
fill ~448 ~67 ~98 ~448 ~67 ~98 grass_block
fill ~449 ~60 ~98 ~456 ~62 ~98 stone
fill ~449 ~63 ~98 ~456 ~65 ~98 dirt
fill ~449 ~66 ~98 ~456 ~66 ~98 grass_block
fill ~457 ~60 ~98 ~460 ~63 ~98 stone
fill ~457 ~64 ~98 ~460 ~66 ~98 dirt
fill ~457 ~67 ~98 ~460 ~67 ~98 grass_block
fill ~461 ~60 ~98 ~463 ~64 ~98 stone
fill ~461 ~65 ~98 ~463 ~67 ~98 dirt
fill ~461 ~68 ~98 ~463 ~68 ~98 grass_block
fill ~448 ~60 ~99 ~456 ~62 ~99 stone
fill ~448 ~63 ~99 ~456 ~65 ~99 dirt
fill ~448 ~66 ~99 ~456 ~66 ~99 grass_block
fill ~457 ~60 ~99 ~460 ~63 ~99 stone
fill ~457 ~64 ~99 ~460 ~66 ~99 dirt
fill ~457 ~67 ~99 ~460 ~67 ~99 grass_block
fill ~461 ~60 ~99 ~463 ~64 ~99 stone
fill ~461 ~65 ~99 ~463 ~67 ~99 dirt
fill ~461 ~68 ~99 ~463 ~68 ~99 grass_block
fill ~448 ~60 ~100 ~457 ~62 ~100 stone
fill ~448 ~63 ~100 ~457 ~65 ~100 dirt
fill ~448 ~66 ~100 ~457 ~66 ~100 grass_block
fill ~458 ~60 ~100 ~461 ~63 ~100 stone
fill ~458 ~64 ~100 ~461 ~66 ~100 dirt
fill ~458 ~67 ~100 ~461 ~67 ~100 grass_block
fill ~462 ~60 ~100 ~463 ~64 ~100 stone
fill ~462 ~65 ~100 ~463 ~67 ~100 dirt
fill ~462 ~68 ~100 ~463 ~68 ~100 grass_block
fill ~448 ~60 ~101 ~452 ~62 ~101 stone
fill ~448 ~63 ~101 ~452 ~65 ~101 dirt
fill ~448 ~66 ~101 ~452 ~66 ~101 grass_block
fill ~453 ~60 ~101 ~453 ~61 ~101 stone
fill ~453 ~62 ~101 ~453 ~64 ~101 dirt
fill ~453 ~65 ~101 ~453 ~65 ~101 grass_block
fill ~454 ~60 ~101 ~458 ~62 ~101 stone
fill ~454 ~63 ~101 ~458 ~65 ~101 dirt
fill ~454 ~66 ~101 ~458 ~66 ~101 grass_block
fill ~459 ~60 ~101 ~463 ~63 ~101 stone
fill ~459 ~64 ~101 ~463 ~66 ~101 dirt
fill ~459 ~67 ~101 ~463 ~67 ~101 grass_block
fill ~448 ~60 ~102 ~452 ~62 ~102 stone
fill ~448 ~63 ~102 ~452 ~65 ~102 dirt
fill ~448 ~66 ~102 ~452 ~66 ~102 grass_block
fill ~453 ~60 ~102 ~454 ~61 ~102 stone
fill ~453 ~62 ~102 ~454 ~64 ~102 dirt
fill ~453 ~65 ~102 ~454 ~65 ~102 grass_block
fill ~455 ~60 ~102 ~458 ~62 ~102 stone
fill ~455 ~63 ~102 ~458 ~65 ~102 dirt
fill ~455 ~66 ~102 ~458 ~66 ~102 grass_block
fill ~459 ~60 ~102 ~463 ~63 ~102 stone
fill ~459 ~64 ~102 ~463 ~66 ~102 dirt
fill ~459 ~67 ~102 ~463 ~67 ~102 grass_block
fill ~448 ~60 ~103 ~448 ~61 ~103 stone
fill ~448 ~62 ~103 ~448 ~64 ~103 dirt
fill ~448 ~65 ~103 ~448 ~65 ~103 grass_block
fill ~449 ~60 ~103 ~453 ~62 ~103 stone
fill ~449 ~63 ~103 ~453 ~65 ~103 dirt
fill ~449 ~66 ~103 ~453 ~66 ~103 grass_block
fill ~454 ~60 ~103 ~454 ~61 ~103 stone
fill ~454 ~62 ~103 ~454 ~64 ~103 dirt
fill ~454 ~65 ~103 ~454 ~65 ~103 grass_block
fill ~455 ~60 ~103 ~460 ~62 ~103 stone
fill ~455 ~63 ~103 ~460 ~65 ~103 dirt
fill ~455 ~66 ~103 ~460 ~66 ~103 grass_block
fill ~461 ~60 ~103 ~463 ~63 ~103 stone
fill ~461 ~64 ~103 ~463 ~66 ~103 dirt
fill ~461 ~67 ~103 ~463 ~67 ~103 grass_block
fill ~448 ~60 ~104 ~450 ~61 ~104 stone
fill ~448 ~62 ~104 ~450 ~64 ~104 dirt
fill ~448 ~65 ~104 ~450 ~65 ~104 grass_block
fill ~451 ~60 ~104 ~453 ~62 ~104 stone
fill ~451 ~63 ~104 ~453 ~65 ~104 dirt
fill ~451 ~66 ~104 ~453 ~66 ~104 grass_block
fill ~454 ~60 ~104 ~455 ~61 ~104 stone
fill ~454 ~62 ~104 ~455 ~64 ~104 dirt
fill ~454 ~65 ~104 ~455 ~65 ~104 grass_block
fill ~456 ~60 ~104 ~462 ~62 ~104 stone
fill ~456 ~63 ~104 ~462 ~65 ~104 dirt
fill ~456 ~66 ~104 ~462 ~66 ~104 grass_block
fill ~463 ~60 ~104 ~463 ~63 ~104 stone
fill ~463 ~64 ~104 ~463 ~66 ~104 dirt
fill ~463 ~67 ~104 ~463 ~67 ~104 grass_block
fill ~448 ~60 ~105 ~452 ~61 ~105 stone
fill ~448 ~62 ~105 ~452 ~64 ~105 dirt
fill ~448 ~65 ~105 ~452 ~65 ~105 grass_block
fill ~453 ~60 ~105 ~453 ~62 ~105 stone
fill ~453 ~63 ~105 ~453 ~65 ~105 dirt
fill ~453 ~66 ~105 ~453 ~66 ~105 grass_block
fill ~454 ~60 ~105 ~456 ~61 ~105 stone
fill ~454 ~62 ~105 ~456 ~64 ~105 dirt
fill ~454 ~65 ~105 ~456 ~65 ~105 grass_block
fill ~457 ~60 ~105 ~463 ~62 ~105 stone
fill ~457 ~63 ~105 ~463 ~65 ~105 dirt
fill ~457 ~66 ~105 ~463 ~66 ~105 grass_block
fill ~448 ~60 ~106 ~457 ~61 ~106 stone
fill ~448 ~62 ~106 ~457 ~64 ~106 dirt
fill ~448 ~65 ~106 ~457 ~65 ~106 grass_block
fill ~458 ~60 ~106 ~463 ~62 ~106 stone
fill ~458 ~63 ~106 ~463 ~65 ~106 dirt
fill ~458 ~66 ~106 ~463 ~66 ~106 grass_block
fill ~448 ~60 ~107 ~458 ~61 ~107 stone
fill ~448 ~62 ~107 ~458 ~64 ~107 dirt
fill ~448 ~65 ~107 ~458 ~65 ~107 grass_block
fill ~459 ~60 ~107 ~463 ~62 ~107 stone
fill ~459 ~63 ~107 ~463 ~65 ~107 dirt
fill ~459 ~66 ~107 ~463 ~66 ~107 grass_block
fill ~448 ~60 ~108 ~459 ~61 ~108 stone
fill ~448 ~62 ~108 ~459 ~64 ~108 dirt
fill ~448 ~65 ~108 ~459 ~65 ~108 grass_block
fill ~460 ~60 ~108 ~463 ~62 ~108 stone
fill ~460 ~63 ~108 ~463 ~65 ~108 dirt
fill ~460 ~66 ~108 ~463 ~66 ~108 grass_block
fill ~448 ~60 ~109 ~448 ~62 ~109 stone
fill ~448 ~63 ~109 ~448 ~65 ~109 dirt
fill ~448 ~66 ~109 ~448 ~66 ~109 grass_block
fill ~449 ~60 ~109 ~461 ~61 ~109 stone
fill ~449 ~62 ~109 ~461 ~64 ~109 dirt
fill ~449 ~65 ~109 ~461 ~65 ~109 grass_block
fill ~462 ~60 ~109 ~463 ~62 ~109 stone
fill ~462 ~63 ~109 ~463 ~65 ~109 dirt
fill ~462 ~66 ~109 ~463 ~66 ~109 grass_block
fill ~448 ~60 ~110 ~449 ~62 ~110 stone
fill ~448 ~63 ~110 ~449 ~65 ~110 dirt
fill ~448 ~66 ~110 ~449 ~66 ~110 grass_block
fill ~450 ~60 ~110 ~463 ~61 ~110 stone
fill ~450 ~62 ~110 ~463 ~64 ~110 dirt
fill ~450 ~65 ~110 ~463 ~65 ~110 grass_block
fill ~448 ~60 ~111 ~448 ~62 ~111 stone
fill ~448 ~63 ~111 ~448 ~65 ~111 dirt
fill ~448 ~66 ~111 ~448 ~66 ~111 grass_block
fill ~449 ~60 ~111 ~463 ~61 ~111 stone
fill ~449 ~62 ~111 ~463 ~64 ~111 dirt
fill ~449 ~65 ~111 ~463 ~65 ~111 grass_block