fill ~112 ~60 ~112 ~119 ~68 ~112 stone
fill ~112 ~69 ~112 ~119 ~71 ~112 dirt
fill ~112 ~72 ~112 ~119 ~72 ~112 grass_block
fill ~120 ~60 ~112 ~121 ~67 ~112 stone
fill ~120 ~68 ~112 ~121 ~70 ~112 dirt
fill ~120 ~71 ~112 ~121 ~71 ~112 grass_block
fill ~122 ~60 ~112 ~123 ~66 ~112 stone
fill ~122 ~67 ~112 ~123 ~69 ~112 dirt
fill ~122 ~70 ~112 ~123 ~70 ~112 grass_block
fill ~124 ~60 ~112 ~125 ~65 ~112 stone
fill ~124 ~66 ~112 ~125 ~68 ~112 dirt
fill ~124 ~69 ~112 ~125 ~69 ~112 grass_block
fill ~126 ~60 ~112 ~127 ~64 ~112 stone
fill ~126 ~65 ~112 ~127 ~67 ~112 dirt
fill ~126 ~68 ~112 ~127 ~68 ~112 grass_block
fill ~112 ~60 ~113 ~113 ~67 ~113 stone
fill ~112 ~68 ~113 ~113 ~70 ~113 dirt
fill ~112 ~71 ~113 ~113 ~71 ~113 grass_block
fill ~114 ~60 ~113 ~119 ~68 ~113 stone
fill ~114 ~69 ~113 ~119 ~71 ~113 dirt
fill ~114 ~72 ~113 ~119 ~72 ~113 grass_block
fill ~120 ~60 ~113 ~121 ~67 ~113 stone
fill ~120 ~68 ~113 ~121 ~70 ~113 dirt
fill ~120 ~71 ~113 ~121 ~71 ~113 grass_block
fill ~122 ~60 ~113 ~123 ~66 ~113 stone
fill ~122 ~67 ~113 ~123 ~69 ~113 dirt
fill ~122 ~70 ~113 ~123 ~70 ~113 grass_block
fill ~124 ~60 ~113 ~126 ~65 ~113 stone
fill ~124 ~66 ~113 ~126 ~68 ~113 dirt
fill ~124 ~69 ~113 ~126 ~69 ~113 grass_block
fill ~127 ~60 ~113 ~127 ~64 ~113 stone
fill ~127 ~65 ~113 ~127 ~67 ~113 dirt
fill ~127 ~68 ~113 ~127 ~68 ~113 grass_block
fill ~112 ~60 ~114 ~114 ~67 ~114 stone
fill ~112 ~68 ~114 ~114 ~70 ~114 dirt
fill ~112 ~71 ~114 ~114 ~71 ~114 grass_block
fill ~115 ~60 ~114 ~120 ~68 ~114 stone
fill ~115 ~69 ~114 ~120 ~71 ~114 dirt
fill ~115 ~72 ~114 ~120 ~72 ~114 grass_block
fill ~121 ~60 ~114 ~122 ~67 ~114 stone
fill ~121 ~68 ~114 ~122 ~70 ~114 dirt
fill ~121 ~71 ~114 ~122 ~71 ~114 grass_block
fill ~123 ~60 ~114 ~124 ~66 ~114 stone
fill ~123 ~67 ~114 ~124 ~69 ~114 dirt
fill ~123 ~70 ~114 ~124 ~70 ~114 grass_block
fill ~125 ~60 ~114 ~127 ~65 ~114 stone
fill ~125 ~66 ~114 ~127 ~68 ~114 dirt
fill ~125 ~69 ~114 ~127 ~69 ~114 grass_block
fill ~112 ~60 ~115 ~118 ~67 ~115 stone
fill ~112 ~68 ~115 ~118 ~70 ~115 dirt
fill ~112 ~71 ~115 ~118 ~71 ~115 grass_block
fill ~119 ~60 ~115 ~121 ~68 ~115 stone
fill ~119 ~69 ~115 ~121 ~71 ~115 dirt
fill ~119 ~72 ~115 ~121 ~72 ~115 grass_block
fill ~122 ~60 ~115 ~123 ~67 ~115 stone
fill ~122 ~68 ~115 ~123 ~70 ~115 dirt
fill ~122 ~71 ~115 ~123 ~71 ~115 grass_block
fill ~124 ~60 ~115 ~126 ~66 ~115 stone
fill ~124 ~67 ~115 ~126 ~69 ~115 dirt
fill ~124 ~70 ~115 ~126 ~70 ~115 grass_block
fill ~127 ~60 ~115 ~127 ~65 ~115 stone
fill ~127 ~66 ~115 ~127 ~68 ~115 dirt
fill ~127 ~69 ~115 ~127 ~69 ~115 grass_block
fill ~112 ~60 ~116 ~113 ~66 ~116 stone
fill ~112 ~67 ~116 ~113 ~69 ~116 dirt
fill ~112 ~70 ~116 ~113 ~70 ~116 grass_block
fill ~114 ~60 ~116 ~120 ~67 ~116 stone
fill ~114 ~68 ~116 ~120 ~70 ~116 dirt
fill ~114 ~71 ~116 ~120 ~71 ~116 grass_block
fill ~121 ~60 ~116 ~121 ~68 ~116 stone
fill ~121 ~69 ~116 ~121 ~71 ~116 dirt
fill ~121 ~72 ~116 ~121 ~72 ~116 grass_block
fill ~122 ~60 ~116 ~126 ~67 ~116 stone
fill ~122 ~68 ~116 ~126 ~70 ~116 dirt
fill ~122 ~71 ~116 ~126 ~71 ~116 grass_block
fill ~127 ~60 ~116 ~127 ~66 ~116 stone
fill ~127 ~67 ~116 ~127 ~69 ~116 dirt
fill ~127 ~70 ~116 ~127 ~70 ~116 grass_block
fill ~112 ~60 ~117 ~112 ~65 ~117 stone
fill ~112 ~66 ~117 ~112 ~68 ~117 dirt
fill ~112 ~69 ~117 ~112 ~69 ~117 grass_block
fill ~113 ~60 ~117 ~114 ~66 ~117 stone
fill ~113 ~67 ~117 ~114 ~69 ~117 dirt
fill ~113 ~70 ~117 ~114 ~70 ~117 grass_block
fill ~115 ~60 ~117 ~127 ~67 ~117 stone
fill ~115 ~68 ~117 ~127 ~70 ~117 dirt
fill ~115 ~71 ~117 ~127 ~71 ~117 grass_block
fill ~112 ~60 ~118 ~112 ~66 ~118 stone
fill ~112 ~67 ~118 ~112 ~69 ~118 dirt
fill ~112 ~70 ~118 ~112 ~70 ~118 grass_block
fill ~113 ~60 ~118 ~113 ~65 ~118 stone
fill ~113 ~66 ~118 ~113 ~68 ~118 dirt
fill ~113 ~69 ~118 ~113 ~69 ~118 grass_block
fill ~114 ~60 ~118 ~117 ~66 ~118 stone
fill ~114 ~67 ~118 ~117 ~69 ~118 dirt
fill ~114 ~70 ~118 ~117 ~70 ~118 grass_block
fill ~118 ~60 ~118 ~127 ~67 ~118 stone
fill ~118 ~68 ~118 ~127 ~70 ~118 dirt
fill ~118 ~71 ~118 ~127 ~71 ~118 grass_block
fill ~112 ~60 ~119 ~112 ~66 ~119 stone
fill ~112 ~67 ~119 ~112 ~69 ~119 dirt
fill ~112 ~70 ~119 ~112 ~70 ~119 grass_block
fill ~113 ~60 ~119 ~115 ~65 ~119 stone
fill ~113 ~66 ~119 ~115 ~68 ~119 dirt
fill ~113 ~69 ~119 ~115 ~69 ~119 grass_block
fill ~116 ~60 ~119 ~118 ~66 ~119 stone
fill ~116 ~67 ~119 ~118 ~69 ~119 dirt
fill ~116 ~70 ~119 ~118 ~70 ~119 grass_block
fill ~119 ~60 ~119 ~127 ~67 ~119 stone
fill ~119 ~68 ~119 ~127 ~70 ~119 dirt
fill ~119 ~71 ~119 ~127 ~71 ~119 grass_block
fill ~112 ~60 ~120 ~113 ~66 ~120 stone
fill ~112 ~67 ~120 ~113 ~69 ~120 dirt
fill ~112 ~70 ~120 ~113 ~70 ~120 grass_block
fill ~114 ~60 ~120 ~117 ~65 ~120 stone
fill ~114 ~66 ~120 ~117 ~68 ~120 dirt
fill ~114 ~69 ~120 ~117 ~69 ~120 grass_block
fill ~118 ~60 ~120 ~119 ~66 ~120 stone
fill ~118 ~67 ~120 ~119 ~69 ~120 dirt
fill ~118 ~70 ~120 ~119 ~70 ~120 grass_block
fill ~120 ~60 ~120 ~127 ~67 ~120 stone
fill ~120 ~68 ~120 ~127 ~70 ~120 dirt
fill ~120 ~71 ~120 ~127 ~71 ~120 grass_block
fill ~112 ~60 ~121 ~114 ~66 ~121 stone
fill ~112 ~67 ~121 ~114 ~69 ~121 dirt
fill ~112 ~70 ~121 ~114 ~70 ~121 grass_block
fill ~115 ~60 ~121 ~117 ~65 ~121 stone
fill ~115 ~66 ~121 ~117 ~68 ~121 dirt
fill ~115 ~69 ~121 ~117 ~69 ~121 grass_block
fill ~118 ~60 ~121 ~120 ~66 ~121 stone
fill ~118 ~67 ~121 ~120 ~69 ~121 dirt
fill ~118 ~70 ~121 ~120 ~70 ~121 grass_block
fill ~121 ~60 ~121 ~127 ~67 ~121 stone
fill ~121 ~68 ~121 ~127 ~70 ~121 dirt
fill ~121 ~71 ~121 ~127 ~71 ~121 grass_block
fill ~112 ~60 ~122 ~114 ~66 ~122 stone
fill ~112 ~67 ~122 ~114 ~69 ~122 dirt
fill ~112 ~70 ~122 ~114 ~70 ~122 grass_block
fill ~115 ~60 ~122 ~118 ~65 ~122 stone
fill ~115 ~66 ~122 ~118 ~68 ~122 dirt
fill ~115 ~69 ~122 ~118 ~69 ~122 grass_block
fill ~119 ~60 ~122 ~123 ~66 ~122 stone
fill ~119 ~67 ~122 ~123 ~69 ~122 dirt
fill ~119 ~70 ~122 ~123 ~70 ~122 grass_block
fill ~124 ~60 ~122 ~127 ~67 ~122 stone
fill ~124 ~68 ~122 ~127 ~70 ~122 dirt
fill ~124 ~71 ~122 ~127 ~71 ~122 grass_block
fill ~112 ~60 ~123 ~114 ~66 ~123 stone
fill ~112 ~67 ~123 ~114 ~69 ~123 dirt
fill ~112 ~70 ~123 ~114 ~70 ~123 grass_block
fill ~115 ~60 ~123 ~118 ~65 ~123 stone
fill ~115 ~66 ~123 ~118 ~68 ~123 dirt
fill ~115 ~69 ~123 ~118 ~69 ~123 grass_block
fill ~119 ~60 ~123 ~126 ~66 ~123 stone
fill ~119 ~67 ~123 ~126 ~69 ~123 dirt
fill ~119 ~70 ~123 ~126 ~70 ~123 grass_block
fill ~127 ~60 ~123 ~127 ~67 ~123 stone
fill ~127 ~68 ~123 ~127 ~70 ~123 dirt
fill ~127 ~71 ~123 ~127 ~71 ~123 grass_block
fill ~112 ~60 ~124 ~115 ~66 ~124 stone
fill ~112 ~67 ~124 ~115 ~69 ~124 dirt
fill ~112 ~70 ~124 ~115 ~70 ~124 grass_block
fill ~116 ~60 ~124 ~122 ~65 ~124 stone
fill ~116 ~66 ~124 ~122 ~68 ~124 dirt
fill ~116 ~69 ~124 ~122 ~69 ~124 grass_block
fill ~123 ~60 ~124 ~126 ~66 ~124 stone
fill ~123 ~67 ~124 ~126 ~69 ~124 dirt
fill ~123 ~70 ~124 ~126 ~70 ~124 grass_block
fill ~127 ~60 ~124 ~127 ~67 ~124 stone
fill ~127 ~68 ~124 ~127 ~70 ~124 dirt
fill ~127 ~71 ~124 ~127 ~71 ~124 grass_block
fill ~112 ~60 ~125 ~115 ~66 ~125 stone
fill ~112 ~67 ~125 ~115 ~69 ~125 dirt
fill ~112 ~70 ~125 ~115 ~70 ~125 grass_block
fill ~116 ~60 ~125 ~117 ~65 ~125 stone
fill ~116 ~66 ~125 ~117 ~68 ~125 dirt
fill ~116 ~69 ~125 ~117 ~69 ~125 grass_block
fill ~118 ~60 ~125 ~119 ~64 ~125 stone
fill ~118 ~65 ~125 ~119 ~67 ~125 dirt
fill ~118 ~68 ~125 ~119 ~68 ~125 grass_block
fill ~120 ~60 ~125 ~121 ~65 ~125 stone
fill ~120 ~66 ~125 ~121 ~68 ~125 dirt
fill ~120 ~69 ~125 ~121 ~69 ~125 grass_block
fill ~122 ~60 ~125 ~123 ~66 ~125 stone
fill ~122 ~67 ~125 ~123 ~69 ~125 dirt
fill ~122 ~70 ~125 ~123 ~70 ~125 grass_block
fill ~124 ~60 ~125 ~124 ~65 ~125 stone
fill ~124 ~66 ~125 ~124 ~68 ~125 dirt
fill ~124 ~69 ~125 ~124 ~69 ~125 grass_block
fill ~125 ~60 ~125 ~126 ~66 ~125 stone
fill ~125 ~67 ~125 ~126 ~69 ~125 dirt
fill ~125 ~70 ~125 ~126 ~70 ~125 grass_block
fill ~127 ~60 ~125 ~127 ~67 ~125 stone
fill ~127 ~68 ~125 ~127 ~70 ~125 dirt
fill ~127 ~71 ~125 ~127 ~71 ~125 grass_block
fill ~112 ~60 ~126 ~116 ~66 ~126 stone
fill ~112 ~67 ~126 ~116 ~69 ~126 dirt
fill ~112 ~70 ~126 ~116 ~70 ~126 grass_block
fill ~117 ~60 ~126 ~118 ~65 ~126 stone
fill ~117 ~66 ~126 ~118 ~68 ~126 dirt
fill ~117 ~69 ~126 ~118 ~69 ~126 grass_block
fill ~119 ~60 ~126 ~120 ~64 ~126 stone
fill ~119 ~65 ~126 ~120 ~67 ~126 dirt
fill ~119 ~68 ~126 ~120 ~68 ~126 grass_block
fill ~121 ~60 ~126 ~124 ~65 ~126 stone
fill ~121 ~66 ~126 ~124 ~68 ~126 dirt
fill ~121 ~69 ~126 ~124 ~69 ~126 grass_block
fill ~125 ~60 ~126 ~125 ~66 ~126 stone
fill ~125 ~67 ~126 ~125 ~69 ~126 dirt
fill ~125 ~70 ~126 ~125 ~70 ~126 grass_block
fill ~126 ~60 ~126 ~127 ~67 ~126 stone
fill ~126 ~68 ~126 ~127 ~70 ~126 dirt
fill ~126 ~71 ~126 ~127 ~71 ~126 grass_block
fill ~112 ~60 ~127 ~112 ~66 ~127 stone
fill ~112 ~67 ~127 ~112 ~69 ~127 dirt
fill ~112 ~70 ~127 ~112 ~70 ~127 grass_block
fill ~113 ~60 ~127 ~116 ~65 ~127 stone
fill ~113 ~66 ~127 ~116 ~68 ~127 dirt
fill ~113 ~69 ~127 ~116 ~69 ~127 grass_block
fill ~117 ~60 ~127 ~117 ~66 ~127 stone
fill ~117 ~67 ~127 ~117 ~69 ~127 dirt
fill ~117 ~70 ~127 ~117 ~70 ~127 grass_block
fill ~118 ~60 ~127 ~119 ~65 ~127 stone
fill ~118 ~66 ~127 ~119 ~68 ~127 dirt
fill ~118 ~69 ~127 ~119 ~69 ~127 grass_block
fill ~120 ~60 ~127 ~122 ~64 ~127 stone
fill ~120 ~65 ~127 ~122 ~67 ~127 dirt
fill ~120 ~68 ~127 ~122 ~68 ~127 grass_block
fill ~123 ~60 ~127 ~123 ~65 ~127 stone
fill ~123 ~66 ~127 ~123 ~68 ~127 dirt
fill ~123 ~69 ~127 ~123 ~69 ~127 grass_block
fill ~124 ~60 ~127 ~126 ~66 ~127 stone
fill ~124 ~67 ~127 ~126 ~69 ~127 dirt
fill ~124 ~70 ~127 ~126 ~70 ~127 grass_block
fill ~127 ~60 ~127 ~127 ~67 ~127 stone
fill ~127 ~68 ~127 ~127 ~70 ~127 dirt
fill ~127 ~71 ~127 ~127 ~71 ~127 grass_block