fill ~96 ~60 ~32 ~96 ~67 ~32 stone
fill ~96 ~68 ~32 ~96 ~70 ~32 dirt
fill ~96 ~71 ~32 ~96 ~71 ~32 grass_block
fill ~97 ~60 ~32 ~98 ~66 ~32 stone
fill ~97 ~67 ~32 ~98 ~69 ~32 dirt
fill ~97 ~70 ~32 ~98 ~70 ~32 grass_block
fill ~99 ~60 ~32 ~102 ~65 ~32 stone
fill ~99 ~66 ~32 ~102 ~68 ~32 dirt
fill ~99 ~69 ~32 ~102 ~69 ~32 grass_block
fill ~103 ~60 ~32 ~105 ~66 ~32 stone
fill ~103 ~67 ~32 ~105 ~69 ~32 dirt
fill ~103 ~70 ~32 ~105 ~70 ~32 grass_block
fill ~106 ~60 ~32 ~111 ~67 ~32 stone
fill ~106 ~68 ~32 ~111 ~70 ~32 dirt
fill ~106 ~71 ~32 ~111 ~71 ~32 grass_block
fill ~96 ~60 ~33 ~96 ~67 ~33 stone
fill ~96 ~68 ~33 ~96 ~70 ~33 dirt
fill ~96 ~71 ~33 ~96 ~71 ~33 grass_block
fill ~97 ~60 ~33 ~98 ~66 ~33 stone
fill ~97 ~67 ~33 ~98 ~69 ~33 dirt
fill ~97 ~70 ~33 ~98 ~70 ~33 grass_block
fill ~99 ~60 ~33 ~103 ~65 ~33 stone
fill ~99 ~66 ~33 ~103 ~68 ~33 dirt
fill ~99 ~69 ~33 ~103 ~69 ~33 grass_block
fill ~104 ~60 ~33 ~105 ~66 ~33 stone
fill ~104 ~67 ~33 ~105 ~69 ~33 dirt
fill ~104 ~70 ~33 ~105 ~70 ~33 grass_block
fill ~106 ~60 ~33 ~106 ~67 ~33 stone
fill ~106 ~68 ~33 ~106 ~70 ~33 dirt
fill ~106 ~71 ~33 ~106 ~71 ~33 grass_block
fill ~107 ~60 ~33 ~111 ~66 ~33 stone
fill ~107 ~67 ~33 ~111 ~69 ~33 dirt
fill ~107 ~70 ~33 ~111 ~70 ~33 grass_block
fill ~96 ~60 ~34 ~96 ~67 ~34 stone
fill ~96 ~68 ~34 ~96 ~70 ~34 dirt
fill ~96 ~71 ~34 ~96 ~71 ~34 grass_block
fill ~97 ~60 ~34 ~98 ~66 ~34 stone
fill ~97 ~67 ~34 ~98 ~69 ~34 dirt
fill ~97 ~70 ~34 ~98 ~70 ~34 grass_block
fill ~99 ~60 ~34 ~103 ~65 ~34 stone
fill ~99 ~66 ~34 ~103 ~68 ~34 dirt
fill ~99 ~69 ~34 ~103 ~69 ~34 grass_block
fill ~104 ~60 ~34 ~111 ~66 ~34 stone
fill ~104 ~67 ~34 ~111 ~69 ~34 dirt
fill ~104 ~70 ~34 ~111 ~70 ~34 grass_block
fill ~96 ~60 ~35 ~98 ~66 ~35 stone
fill ~96 ~67 ~35 ~98 ~69 ~35 dirt
fill ~96 ~70 ~35 ~98 ~70 ~35 grass_block
fill ~99 ~60 ~35 ~104 ~65 ~35 stone
fill ~99 ~66 ~35 ~104 ~68 ~35 dirt
fill ~99 ~69 ~35 ~104 ~69 ~35 grass_block
fill ~105 ~60 ~35 ~108 ~66 ~35 stone
fill ~105 ~67 ~35 ~108 ~69 ~35 dirt
fill ~105 ~70 ~35 ~108 ~70 ~35 grass_block
fill ~109 ~60 ~35 ~110 ~65 ~35 stone
fill ~109 ~66 ~35 ~110 ~68 ~35 dirt
fill ~109 ~69 ~35 ~110 ~69 ~35 grass_block
fill ~111 ~60 ~35 ~111 ~66 ~35 stone
fill ~111 ~67 ~35 ~111 ~69 ~35 dirt
fill ~111 ~70 ~35 ~111 ~70 ~35 grass_block
fill ~96 ~60 ~36 ~98 ~66 ~36 stone
fill ~96 ~67 ~36 ~98 ~69 ~36 dirt
fill ~96 ~70 ~36 ~98 ~70 ~36 grass_block
fill ~99 ~60 ~36 ~111 ~65 ~36 stone
fill ~99 ~66 ~36 ~111 ~68 ~36 dirt
fill ~99 ~69 ~36 ~111 ~69 ~36 grass_block
fill ~96 ~60 ~37 ~96 ~67 ~37 stone
fill ~96 ~68 ~37 ~96 ~70 ~37 dirt
fill ~96 ~71 ~37 ~96 ~71 ~37 grass_block
fill ~97 ~60 ~37 ~99 ~66 ~37 stone
fill ~97 ~67 ~37 ~99 ~69 ~37 dirt
fill ~97 ~70 ~37 ~99 ~70 ~37 grass_block
fill ~100 ~60 ~37 ~111 ~65 ~37 stone
fill ~100 ~66 ~37 ~111 ~68 ~37 dirt
fill ~100 ~69 ~37 ~111 ~69 ~37 grass_block
fill ~96 ~60 ~38 ~97 ~67 ~38 stone
fill ~96 ~68 ~38 ~97 ~70 ~38 dirt
fill ~96 ~71 ~38 ~97 ~71 ~38 grass_block
fill ~98 ~60 ~38 ~99 ~66 ~38 stone
fill ~98 ~67 ~38 ~99 ~69 ~38 dirt
fill ~98 ~70 ~38 ~99 ~70 ~38 grass_block
fill ~100 ~60 ~38 ~101 ~65 ~38 stone
fill ~100 ~66 ~38 ~101 ~68 ~38 dirt
fill ~100 ~69 ~38 ~101 ~69 ~38 grass_block
fill ~102 ~60 ~38 ~103 ~64 ~38 stone
fill ~102 ~65 ~38 ~103 ~67 ~38 dirt
fill ~102 ~68 ~38 ~103 ~68 ~38 grass_block
fill ~104 ~60 ~38 ~107 ~65 ~38 stone
fill ~104 ~66 ~38 ~107 ~68 ~38 dirt
fill ~104 ~69 ~38 ~107 ~69 ~38 grass_block
fill ~108 ~60 ~38 ~109 ~64 ~38 stone
fill ~108 ~65 ~38 ~109 ~67 ~38 dirt
fill ~108 ~68 ~38 ~109 ~68 ~38 grass_block
fill ~110 ~60 ~38 ~111 ~65 ~38 stone
fill ~110 ~66 ~38 ~111 ~68 ~38 dirt
fill ~110 ~69 ~38 ~111 ~69 ~38 grass_block
fill ~96 ~60 ~39 ~97 ~67 ~39 stone
fill ~96 ~68 ~39 ~97 ~70 ~39 dirt
fill ~96 ~71 ~39 ~97 ~71 ~39 grass_block
fill ~98 ~60 ~39 ~100 ~66 ~39 stone
fill ~98 ~67 ~39 ~100 ~69 ~39 dirt
fill ~98 ~70 ~39 ~100 ~70 ~39 grass_block
fill ~101 ~60 ~39 ~102 ~65 ~39 stone
fill ~101 ~66 ~39 ~102 ~68 ~39 dirt
fill ~101 ~69 ~39 ~102 ~69 ~39 grass_block
fill ~103 ~60 ~39 ~109 ~64 ~39 stone
fill ~103 ~65 ~39 ~109 ~67 ~39 dirt
fill ~103 ~68 ~39 ~109 ~68 ~39 grass_block
fill ~110 ~60 ~39 ~111 ~65 ~39 stone
fill ~110 ~66 ~39 ~111 ~68 ~39 dirt
fill ~110 ~69 ~39 ~111 ~69 ~39 grass_block
fill ~96 ~60 ~40 ~97 ~67 ~40 stone
fill ~96 ~68 ~40 ~97 ~70 ~40 dirt
fill ~96 ~71 ~40 ~97 ~71 ~40 grass_block
fill ~98 ~60 ~40 ~100 ~66 ~40 stone
fill ~98 ~67 ~40 ~100 ~69 ~40 dirt
fill ~98 ~70 ~40 ~100 ~70 ~40 grass_block
fill ~101 ~60 ~40 ~102 ~65 ~40 stone
fill ~101 ~66 ~40 ~102 ~68 ~40 dirt
fill ~101 ~69 ~40 ~102 ~69 ~40 grass_block
fill ~103 ~60 ~40 ~109 ~64 ~40 stone
fill ~103 ~65 ~40 ~109 ~67 ~40 dirt
fill ~103 ~68 ~40 ~109 ~68 ~40 grass_block
fill ~110 ~60 ~40 ~110 ~65 ~40 stone
fill ~110 ~66 ~40 ~110 ~68 ~40 dirt
fill ~110 ~69 ~40 ~110 ~69 ~40 grass_block
fill ~111 ~60 ~40 ~111 ~66 ~40 stone
fill ~111 ~67 ~40 ~111 ~69 ~40 dirt
fill ~111 ~70 ~40 ~111 ~70 ~40 grass_block
fill ~96 ~60 ~41 ~100 ~66 ~41 stone
fill ~96 ~67 ~41 ~100 ~69 ~41 dirt
fill ~96 ~70 ~41 ~100 ~70 ~41 grass_block
fill ~101 ~60 ~41 ~103 ~65 ~41 stone
fill ~101 ~66 ~41 ~103 ~68 ~41 dirt
fill ~101 ~69 ~41 ~103 ~69 ~41 grass_block
fill ~104 ~60 ~41 ~108 ~64 ~41 stone
fill ~104 ~65 ~41 ~108 ~67 ~41 dirt
fill ~104 ~68 ~41 ~108 ~68 ~41 grass_block
fill ~109 ~60 ~41 ~110 ~65 ~41 stone
fill ~109 ~66 ~41 ~110 ~68 ~41 dirt
fill ~109 ~69 ~41 ~110 ~69 ~41 grass_block
fill ~111 ~60 ~41 ~111 ~66 ~41 stone
fill ~111 ~67 ~41 ~111 ~69 ~41 dirt
fill ~111 ~70 ~41 ~111 ~70 ~41 grass_block
fill ~96 ~60 ~42 ~101 ~66 ~42 stone
fill ~96 ~67 ~42 ~101 ~69 ~42 dirt
fill ~96 ~70 ~42 ~101 ~70 ~42 grass_block
fill ~102 ~60 ~42 ~104 ~65 ~42 stone
fill ~102 ~66 ~42 ~104 ~68 ~42 dirt
fill ~102 ~69 ~42 ~104 ~69 ~42 grass_block
fill ~105 ~60 ~42 ~109 ~64 ~42 stone
fill ~105 ~65 ~42 ~109 ~67 ~42 dirt
fill ~105 ~68 ~42 ~109 ~68 ~42 grass_block
fill ~110 ~60 ~42 ~111 ~65 ~42 stone
fill ~110 ~66 ~42 ~111 ~68 ~42 dirt
fill ~110 ~69 ~42 ~111 ~69 ~42 grass_block
fill ~96 ~60 ~43 ~97 ~65 ~43 stone
fill ~96 ~66 ~43 ~97 ~68 ~43 dirt
fill ~96 ~69 ~43 ~97 ~69 ~43 grass_block
fill ~98 ~60 ~43 ~98 ~66 ~43 stone
fill ~98 ~67 ~43 ~98 ~69 ~43 dirt
fill ~98 ~70 ~43 ~98 ~70 ~43 grass_block
fill ~99 ~60 ~43 ~100 ~65 ~43 stone
fill ~99 ~66 ~43 ~100 ~68 ~43 dirt
fill ~99 ~69 ~43 ~100 ~69 ~43 grass_block
fill ~101 ~60 ~43 ~101 ~66 ~43 stone
fill ~101 ~67 ~43 ~101 ~69 ~43 dirt
fill ~101 ~70 ~43 ~101 ~70 ~43 grass_block
fill ~102 ~60 ~43 ~104 ~65 ~43 stone
fill ~102 ~66 ~43 ~104 ~68 ~43 dirt
fill ~102 ~69 ~43 ~104 ~69 ~43 grass_block
fill ~105 ~60 ~43 ~109 ~64 ~43 stone
fill ~105 ~65 ~43 ~109 ~67 ~43 dirt
fill ~105 ~68 ~43 ~109 ~68 ~43 grass_block
fill ~110 ~60 ~43 ~111 ~65 ~43 stone
fill ~110 ~66 ~43 ~111 ~68 ~43 dirt
fill ~110 ~69 ~43 ~111 ~69 ~43 grass_block
fill ~96 ~60 ~44 ~104 ~65 ~44 stone
fill ~96 ~66 ~44 ~104 ~68 ~44 dirt
fill ~96 ~69 ~44 ~104 ~69 ~44 grass_block
fill ~105 ~60 ~44 ~111 ~64 ~44 stone
fill ~105 ~65 ~44 ~111 ~67 ~44 dirt
fill ~105 ~68 ~44 ~111 ~68 ~44 grass_block
fill ~96 ~60 ~45 ~97 ~65 ~45 stone
fill ~96 ~66 ~45 ~97 ~68 ~45 dirt
fill ~96 ~69 ~45 ~97 ~69 ~45 grass_block
fill ~98 ~60 ~45 ~100 ~64 ~45 stone
fill ~98 ~65 ~45 ~100 ~67 ~45 dirt
fill ~98 ~68 ~45 ~100 ~68 ~45 grass_block
fill ~101 ~60 ~45 ~105 ~65 ~45 stone
fill ~101 ~66 ~45 ~105 ~68 ~45 dirt
fill ~101 ~69 ~45 ~105 ~69 ~45 grass_block
fill ~106 ~60 ~45 ~111 ~64 ~45 stone
fill ~106 ~65 ~45 ~111 ~67 ~45 dirt
fill ~106 ~68 ~45 ~111 ~68 ~45 grass_block
fill ~96 ~60 ~46 ~100 ~64 ~46 stone
fill ~96 ~65 ~46 ~100 ~67 ~46 dirt
fill ~96 ~68 ~46 ~100 ~68 ~46 grass_block
fill ~101 ~60 ~46 ~105 ~65 ~46 stone
fill ~101 ~66 ~46 ~105 ~68 ~46 dirt
fill ~101 ~69 ~46 ~105 ~69 ~46 grass_block
fill ~106 ~60 ~46 ~108 ~64 ~46 stone
fill ~106 ~65 ~46 ~108 ~67 ~46 dirt
fill ~106 ~68 ~46 ~108 ~68 ~46 grass_block
fill ~109 ~60 ~46 ~110 ~63 ~46 stone
fill ~109 ~64 ~46 ~110 ~66 ~46 dirt
fill ~109 ~67 ~46 ~110 ~67 ~46 grass_block
fill ~111 ~60 ~46 ~111 ~64 ~46 stone
fill ~111 ~65 ~46 ~111 ~67 ~46 dirt
fill ~111 ~68 ~46 ~111 ~68 ~46 grass_block
fill ~96 ~60 ~47 ~101 ~64 ~47 stone
fill ~96 ~65 ~47 ~101 ~67 ~47 dirt
fill ~96 ~68 ~47 ~101 ~68 ~47 grass_block
fill ~102 ~60 ~47 ~105 ~65 ~47 stone
fill ~102 ~66 ~47 ~105 ~68 ~47 dirt
fill ~102 ~69 ~47 ~105 ~69 ~47 grass_block
fill ~106 ~60 ~47 ~108 ~64 ~47 stone
fill ~106 ~65 ~47 ~108 ~67 ~47 dirt
fill ~106 ~68 ~47 ~108 ~68 ~47 grass_block
fill ~109 ~60 ~47 ~110 ~63 ~47 stone
fill ~109 ~64 ~47 ~110 ~66 ~47 dirt
fill ~109 ~67 ~47 ~110 ~67 ~47 grass_block
fill ~111 ~60 ~47 ~111 ~64 ~47 stone
fill ~111 ~65 ~47 ~111 ~67 ~47 dirt
fill ~111 ~68 ~47 ~111 ~68 ~47 grass_block