fill ~464 ~60 ~0 ~465 ~64 ~0 stone
fill ~464 ~65 ~0 ~465 ~67 ~0 dirt
fill ~464 ~68 ~0 ~465 ~68 ~0 grass_block
fill ~466 ~60 ~0 ~469 ~63 ~0 stone
fill ~466 ~64 ~0 ~469 ~66 ~0 dirt
fill ~466 ~67 ~0 ~469 ~67 ~0 grass_block
fill ~464 ~60 ~1 ~466 ~64 ~1 stone
fill ~464 ~65 ~1 ~466 ~67 ~1 dirt
fill ~464 ~68 ~1 ~466 ~68 ~1 grass_block
fill ~467 ~60 ~1 ~469 ~63 ~1 stone
fill ~467 ~64 ~1 ~469 ~66 ~1 dirt
fill ~467 ~67 ~1 ~469 ~67 ~1 grass_block
fill ~464 ~60 ~2 ~469 ~64 ~2 stone
fill ~464 ~65 ~2 ~469 ~67 ~2 dirt
fill ~464 ~68 ~2 ~469 ~68 ~2 grass_block
fill ~464 ~60 ~3 ~469 ~64 ~3 stone
fill ~464 ~65 ~3 ~469 ~67 ~3 dirt
fill ~464 ~68 ~3 ~469 ~68 ~3 grass_block
fill ~464 ~60 ~4 ~465 ~65 ~4 stone
fill ~464 ~66 ~4 ~465 ~68 ~4 dirt
fill ~464 ~69 ~4 ~465 ~69 ~4 grass_block
fill ~466 ~60 ~4 ~469 ~64 ~4 stone
fill ~466 ~65 ~4 ~469 ~67 ~4 dirt
fill ~466 ~68 ~4 ~469 ~68 ~4 grass_block
fill ~464 ~60 ~5 ~466 ~65 ~5 stone
fill ~464 ~66 ~5 ~466 ~68 ~5 dirt
fill ~464 ~69 ~5 ~466 ~69 ~5 grass_block
fill ~467 ~60 ~5 ~469 ~64 ~5 stone
fill ~467 ~65 ~5 ~469 ~67 ~5 dirt
fill ~467 ~68 ~5 ~469 ~68 ~5 grass_block
fill ~464 ~60 ~6 ~469 ~65 ~6 stone
fill ~464 ~66 ~6 ~469 ~68 ~6 dirt
fill ~464 ~69 ~6 ~469 ~69 ~6 grass_block
fill ~464 ~60 ~7 ~468 ~65 ~7 stone
fill ~464 ~66 ~7 ~468 ~68 ~7 dirt
fill ~464 ~69 ~7 ~468 ~69 ~7 grass_block
fill ~469 ~60 ~7 ~469 ~64 ~7 stone
fill ~469 ~65 ~7 ~469 ~67 ~7 dirt
fill ~469 ~68 ~7 ~469 ~68 ~7 grass_block
fill ~464 ~60 ~8 ~469 ~65 ~8 stone
fill ~464 ~66 ~8 ~469 ~68 ~8 dirt
fill ~464 ~69 ~8 ~469 ~69 ~8 grass_block
fill ~464 ~60 ~9 ~469 ~65 ~9 stone
fill ~464 ~66 ~9 ~469 ~68 ~9 dirt
fill ~464 ~69 ~9 ~469 ~69 ~9 grass_block
fill ~464 ~60 ~10 ~464 ~64 ~10 stone
fill ~464 ~65 ~10 ~464 ~67 ~10 dirt
fill ~464 ~68 ~10 ~464 ~68 ~10 grass_block
fill ~465 ~60 ~10 ~469 ~65 ~10 stone
fill ~465 ~66 ~10 ~469 ~68 ~10 dirt
fill ~465 ~69 ~10 ~469 ~69 ~10 grass_block
fill ~464 ~60 ~11 ~464 ~64 ~11 stone
fill ~464 ~65 ~11 ~464 ~67 ~11 dirt
fill ~464 ~68 ~11 ~464 ~68 ~11 grass_block
fill ~465 ~60 ~11 ~468 ~65 ~11 stone
fill ~465 ~66 ~11 ~468 ~68 ~11 dirt
fill ~465 ~69 ~11 ~468 ~69 ~11 grass_block
fill ~469 ~60 ~11 ~469 ~64 ~11 stone
fill ~469 ~65 ~11 ~469 ~67 ~11 dirt
fill ~469 ~68 ~11 ~469 ~68 ~11 grass_block
fill ~464 ~60 ~12 ~469 ~65 ~12 stone
fill ~464 ~66 ~12 ~469 ~68 ~12 dirt
fill ~464 ~69 ~12 ~469 ~69 ~12 grass_block
fill ~464 ~60 ~13 ~469 ~65 ~13 stone
fill ~464 ~66 ~13 ~469 ~68 ~13 dirt
fill ~464 ~69 ~13 ~469 ~69 ~13 grass_block
fill ~464 ~60 ~14 ~469 ~65 ~14 stone
fill ~464 ~66 ~14 ~469 ~68 ~14 dirt
fill ~464 ~69 ~14 ~469 ~69 ~14 grass_block
fill ~464 ~60 ~15 ~467 ~65 ~15 stone
fill ~464 ~66 ~15 ~467 ~68 ~15 dirt
fill ~464 ~69 ~15 ~467 ~69 ~15 grass_block
fill ~468 ~60 ~15 ~468 ~66 ~15 stone
fill ~468 ~67 ~15 ~468 ~69 ~15 dirt
fill ~468 ~70 ~15 ~468 ~70 ~15 grass_block
fill ~469 ~60 ~15 ~469 ~65 ~15 stone
fill ~469 ~66 ~15 ~469 ~68 ~15 dirt
fill ~469 ~69 ~15 ~469 ~69 ~15 grass_block