fill ~192 ~60 ~96 ~193 ~63 ~96 stone
fill ~192 ~64 ~96 ~193 ~66 ~96 dirt
fill ~192 ~67 ~96 ~193 ~67 ~96 grass_block
fill ~194 ~60 ~96 ~198 ~64 ~96 stone
fill ~194 ~65 ~96 ~198 ~67 ~96 dirt
fill ~194 ~68 ~96 ~198 ~68 ~96 grass_block
fill ~199 ~60 ~96 ~200 ~65 ~96 stone
fill ~199 ~66 ~96 ~200 ~68 ~96 dirt
fill ~199 ~69 ~96 ~200 ~69 ~96 grass_block
fill ~201 ~60 ~96 ~207 ~66 ~96 stone
fill ~201 ~67 ~96 ~207 ~69 ~96 dirt
fill ~201 ~70 ~96 ~207 ~70 ~96 grass_block
fill ~192 ~60 ~97 ~192 ~63 ~97 stone
fill ~192 ~64 ~97 ~192 ~66 ~97 dirt
fill ~192 ~67 ~97 ~192 ~67 ~97 grass_block
fill ~193 ~60 ~97 ~198 ~64 ~97 stone
fill ~193 ~65 ~97 ~198 ~67 ~97 dirt
fill ~193 ~68 ~97 ~198 ~68 ~97 grass_block
fill ~199 ~60 ~97 ~200 ~65 ~97 stone
fill ~199 ~66 ~97 ~200 ~68 ~97 dirt
fill ~199 ~69 ~97 ~200 ~69 ~97 grass_block
fill ~201 ~60 ~97 ~207 ~66 ~97 stone
fill ~201 ~67 ~97 ~207 ~69 ~97 dirt
fill ~201 ~70 ~97 ~207 ~70 ~97 grass_block
fill ~192 ~60 ~98 ~194 ~64 ~98 stone
fill ~192 ~65 ~98 ~194 ~67 ~98 dirt
fill ~192 ~68 ~98 ~194 ~68 ~98 grass_block
fill ~195 ~60 ~98 ~200 ~65 ~98 stone
fill ~195 ~66 ~98 ~200 ~68 ~98 dirt
fill ~195 ~69 ~98 ~200 ~69 ~98 grass_block
fill ~201 ~60 ~98 ~207 ~66 ~98 stone
fill ~201 ~67 ~98 ~207 ~69 ~98 dirt
fill ~201 ~70 ~98 ~207 ~70 ~98 grass_block
fill ~192 ~60 ~99 ~194 ~64 ~99 stone
fill ~192 ~65 ~99 ~194 ~67 ~99 dirt
fill ~192 ~68 ~99 ~194 ~68 ~99 grass_block
fill ~195 ~60 ~99 ~201 ~65 ~99 stone
fill ~195 ~66 ~99 ~201 ~68 ~99 dirt
fill ~195 ~69 ~99 ~201 ~69 ~99 grass_block
fill ~202 ~60 ~99 ~207 ~66 ~99 stone
fill ~202 ~67 ~99 ~207 ~69 ~99 dirt
fill ~202 ~70 ~99 ~207 ~70 ~99 grass_block
fill ~192 ~60 ~100 ~194 ~64 ~100 stone
fill ~192 ~65 ~100 ~194 ~67 ~100 dirt
fill ~192 ~68 ~100 ~194 ~68 ~100 grass_block
fill ~195 ~60 ~100 ~203 ~65 ~100 stone
fill ~195 ~66 ~100 ~203 ~68 ~100 dirt
fill ~195 ~69 ~100 ~203 ~69 ~100 grass_block
fill ~204 ~60 ~100 ~207 ~66 ~100 stone
fill ~204 ~67 ~100 ~207 ~69 ~100 dirt
fill ~204 ~70 ~100 ~207 ~70 ~100 grass_block
fill ~192 ~60 ~101 ~192 ~63 ~101 stone
fill ~192 ~64 ~101 ~192 ~66 ~101 dirt
fill ~192 ~67 ~101 ~192 ~67 ~101 grass_block
fill ~193 ~60 ~101 ~194 ~64 ~101 stone
fill ~193 ~65 ~101 ~194 ~67 ~101 dirt
fill ~193 ~68 ~101 ~194 ~68 ~101 grass_block
fill ~195 ~60 ~101 ~206 ~65 ~101 stone
fill ~195 ~66 ~101 ~206 ~68 ~101 dirt
fill ~195 ~69 ~101 ~206 ~69 ~101 grass_block
fill ~207 ~60 ~101 ~207 ~66 ~101 stone
fill ~207 ~67 ~101 ~207 ~69 ~101 dirt
fill ~207 ~70 ~101 ~207 ~70 ~101 grass_block
fill ~192 ~60 ~102 ~192 ~63 ~102 stone
fill ~192 ~64 ~102 ~192 ~66 ~102 dirt
fill ~192 ~67 ~102 ~192 ~67 ~102 grass_block
fill ~193 ~60 ~102 ~195 ~64 ~102 stone
fill ~193 ~65 ~102 ~195 ~67 ~102 dirt
fill ~193 ~68 ~102 ~195 ~68 ~102 grass_block
fill ~196 ~60 ~102 ~207 ~65 ~102 stone
fill ~196 ~66 ~102 ~207 ~68 ~102 dirt
fill ~196 ~69 ~102 ~207 ~69 ~102 grass_block
fill ~192 ~60 ~103 ~193 ~63 ~103 stone
fill ~192 ~64 ~103 ~193 ~66 ~103 dirt
fill ~192 ~67 ~103 ~193 ~67 ~103 grass_block
fill ~194 ~60 ~103 ~196 ~64 ~103 stone
fill ~194 ~65 ~103 ~196 ~67 ~103 dirt
fill ~194 ~68 ~103 ~196 ~68 ~103 grass_block
fill ~197 ~60 ~103 ~201 ~65 ~103 stone
fill ~197 ~66 ~103 ~201 ~68 ~103 dirt
fill ~197 ~69 ~103 ~201 ~69 ~103 grass_block
fill ~202 ~60 ~103 ~202 ~64 ~103 stone
fill ~202 ~65 ~103 ~202 ~67 ~103 dirt
fill ~202 ~68 ~103 ~202 ~68 ~103 grass_block
fill ~203 ~60 ~103 ~207 ~65 ~103 stone
fill ~203 ~66 ~103 ~207 ~68 ~103 dirt
fill ~203 ~69 ~103 ~207 ~69 ~103 grass_block
fill ~192 ~60 ~104 ~194 ~63 ~104 stone
fill ~192 ~64 ~104 ~194 ~66 ~104 dirt
fill ~192 ~67 ~104 ~194 ~67 ~104 grass_block
fill ~195 ~60 ~104 ~196 ~64 ~104 stone
fill ~195 ~65 ~104 ~196 ~67 ~104 dirt
fill ~195 ~68 ~104 ~196 ~68 ~104 grass_block
fill ~197 ~60 ~104 ~199 ~65 ~104 stone
fill ~197 ~66 ~104 ~199 ~68 ~104 dirt
fill ~197 ~69 ~104 ~199 ~69 ~104 grass_block
fill ~200 ~60 ~104 ~207 ~64 ~104 stone
fill ~200 ~65 ~104 ~207 ~67 ~104 dirt
fill ~200 ~68 ~104 ~207 ~68 ~104 grass_block
fill ~192 ~60 ~105 ~192 ~62 ~105 stone
fill ~192 ~63 ~105 ~192 ~65 ~105 dirt
fill ~192 ~66 ~105 ~192 ~66 ~105 grass_block
fill ~193 ~60 ~105 ~193 ~63 ~105 stone
fill ~193 ~64 ~105 ~193 ~66 ~105 dirt
fill ~193 ~67 ~105 ~193 ~67 ~105 grass_block
fill ~194 ~60 ~105 ~196 ~64 ~105 stone
fill ~194 ~65 ~105 ~196 ~67 ~105 dirt
fill ~194 ~68 ~105 ~196 ~68 ~105 grass_block
fill ~197 ~60 ~105 ~199 ~65 ~105 stone
fill ~197 ~66 ~105 ~199 ~68 ~105 dirt
fill ~197 ~69 ~105 ~199 ~69 ~105 grass_block
fill ~200 ~60 ~105 ~207 ~64 ~105 stone
fill ~200 ~65 ~105 ~207 ~67 ~105 dirt
fill ~200 ~68 ~105 ~207 ~68 ~105 grass_block
fill ~192 ~60 ~106 ~194 ~63 ~106 stone
fill ~192 ~64 ~106 ~194 ~66 ~106 dirt
fill ~192 ~67 ~106 ~194 ~67 ~106 grass_block
fill ~195 ~60 ~106 ~207 ~64 ~106 stone
fill ~195 ~65 ~106 ~207 ~67 ~106 dirt
fill ~195 ~68 ~106 ~207 ~68 ~106 grass_block
fill ~192 ~60 ~107 ~195 ~63 ~107 stone
fill ~192 ~64 ~107 ~195 ~66 ~107 dirt
fill ~192 ~67 ~107 ~195 ~67 ~107 grass_block
fill ~196 ~60 ~107 ~202 ~64 ~107 stone
fill ~196 ~65 ~107 ~202 ~67 ~107 dirt
fill ~196 ~68 ~107 ~202 ~68 ~107 grass_block
fill ~203 ~60 ~107 ~207 ~63 ~107 stone
fill ~203 ~64 ~107 ~207 ~66 ~107 dirt
fill ~203 ~67 ~107 ~207 ~67 ~107 grass_block
fill ~192 ~60 ~108 ~193 ~62 ~108 stone
fill ~192 ~63 ~108 ~193 ~65 ~108 dirt
fill ~192 ~66 ~108 ~193 ~66 ~108 grass_block
fill ~194 ~60 ~108 ~194 ~63 ~108 stone
fill ~194 ~64 ~108 ~194 ~66 ~108 dirt
fill ~194 ~67 ~108 ~194 ~67 ~108 grass_block
fill ~195 ~60 ~108 ~202 ~64 ~108 stone
fill ~195 ~65 ~108 ~202 ~67 ~108 dirt
fill ~195 ~68 ~108 ~202 ~68 ~108 grass_block
fill ~203 ~60 ~108 ~207 ~63 ~108 stone
fill ~203 ~64 ~108 ~207 ~66 ~108 dirt
fill ~203 ~67 ~108 ~207 ~67 ~108 grass_block
fill ~192 ~60 ~109 ~193 ~62 ~109 stone
fill ~192 ~63 ~109 ~193 ~65 ~109 dirt
fill ~192 ~66 ~109 ~193 ~66 ~109 grass_block
fill ~194 ~60 ~109 ~195 ~63 ~109 stone
fill ~194 ~64 ~109 ~195 ~66 ~109 dirt
fill ~194 ~67 ~109 ~195 ~67 ~109 grass_block
fill ~196 ~60 ~109 ~202 ~64 ~109 stone
fill ~196 ~65 ~109 ~202 ~67 ~109 dirt
fill ~196 ~68 ~109 ~202 ~68 ~109 grass_block
fill ~203 ~60 ~109 ~207 ~63 ~109 stone
fill ~203 ~64 ~109 ~207 ~66 ~109 dirt
fill ~203 ~67 ~109 ~207 ~67 ~109 grass_block
fill ~192 ~60 ~110 ~193 ~62 ~110 stone
fill ~192 ~63 ~110 ~193 ~65 ~110 dirt
fill ~192 ~66 ~110 ~193 ~66 ~110 grass_block
fill ~194 ~60 ~110 ~196 ~63 ~110 stone
fill ~194 ~64 ~110 ~196 ~66 ~110 dirt
fill ~194 ~67 ~110 ~196 ~67 ~110 grass_block
fill ~197 ~60 ~110 ~202 ~64 ~110 stone
fill ~197 ~65 ~110 ~202 ~67 ~110 dirt
fill ~197 ~68 ~110 ~202 ~68 ~110 grass_block
fill ~203 ~60 ~110 ~207 ~63 ~110 stone
fill ~203 ~64 ~110 ~207 ~66 ~110 dirt
fill ~203 ~67 ~110 ~207 ~67 ~110 grass_block
fill ~192 ~60 ~111 ~193 ~62 ~111 stone
fill ~192 ~63 ~111 ~193 ~65 ~111 dirt
fill ~192 ~66 ~111 ~193 ~66 ~111 grass_block
fill ~194 ~60 ~111 ~196 ~63 ~111 stone
fill ~194 ~64 ~111 ~196 ~66 ~111 dirt
fill ~194 ~67 ~111 ~196 ~67 ~111 grass_block
fill ~197 ~60 ~111 ~202 ~64 ~111 stone
fill ~197 ~65 ~111 ~202 ~67 ~111 dirt
fill ~197 ~68 ~111 ~202 ~68 ~111 grass_block
fill ~203 ~60 ~111 ~207 ~63 ~111 stone
fill ~203 ~64 ~111 ~207 ~66 ~111 dirt
fill ~203 ~67 ~111 ~207 ~67 ~111 grass_block