fill ~80 ~60 ~16 ~85 ~68 ~16 stone
fill ~80 ~69 ~16 ~85 ~71 ~16 dirt
fill ~80 ~72 ~16 ~85 ~72 ~16 grass_block
fill ~86 ~60 ~16 ~88 ~69 ~16 stone
fill ~86 ~70 ~16 ~88 ~72 ~16 dirt
fill ~86 ~73 ~16 ~88 ~73 ~16 grass_block
fill ~89 ~60 ~16 ~92 ~68 ~16 stone
fill ~89 ~69 ~16 ~92 ~71 ~16 dirt
fill ~89 ~72 ~16 ~92 ~72 ~16 grass_block
fill ~93 ~60 ~16 ~95 ~69 ~16 stone
fill ~93 ~70 ~16 ~95 ~72 ~16 dirt
fill ~93 ~73 ~16 ~95 ~73 ~16 grass_block
fill ~80 ~60 ~17 ~83 ~67 ~17 stone
fill ~80 ~68 ~17 ~83 ~70 ~17 dirt
fill ~80 ~71 ~17 ~83 ~71 ~17 grass_block
fill ~84 ~60 ~17 ~85 ~68 ~17 stone
fill ~84 ~69 ~17 ~85 ~71 ~17 dirt
fill ~84 ~72 ~17 ~85 ~72 ~17 grass_block
fill ~86 ~60 ~17 ~89 ~69 ~17 stone
fill ~86 ~70 ~17 ~89 ~72 ~17 dirt
fill ~86 ~73 ~17 ~89 ~73 ~17 grass_block
fill ~90 ~60 ~17 ~90 ~68 ~17 stone
fill ~90 ~69 ~17 ~90 ~71 ~17 dirt
fill ~90 ~72 ~17 ~90 ~72 ~17 grass_block
fill ~91 ~60 ~17 ~91 ~69 ~17 stone
fill ~91 ~70 ~17 ~91 ~72 ~17 dirt
fill ~91 ~73 ~17 ~91 ~73 ~17 grass_block
fill ~92 ~60 ~17 ~93 ~68 ~17 stone
fill ~92 ~69 ~17 ~93 ~71 ~17 dirt
fill ~92 ~72 ~17 ~93 ~72 ~17 grass_block
fill ~94 ~60 ~17 ~95 ~69 ~17 stone
fill ~94 ~70 ~17 ~95 ~72 ~17 dirt
fill ~94 ~73 ~17 ~95 ~73 ~17 grass_block
fill ~80 ~60 ~18 ~81 ~66 ~18 stone
fill ~80 ~67 ~18 ~81 ~69 ~18 dirt
fill ~80 ~70 ~18 ~81 ~70 ~18 grass_block
fill ~82 ~60 ~18 ~83 ~67 ~18 stone
fill ~82 ~68 ~18 ~83 ~70 ~18 dirt
fill ~82 ~71 ~18 ~83 ~71 ~18 grass_block
fill ~84 ~60 ~18 ~85 ~68 ~18 stone
fill ~84 ~69 ~18 ~85 ~71 ~18 dirt
fill ~84 ~72 ~18 ~85 ~72 ~18 grass_block
fill ~86 ~60 ~18 ~90 ~69 ~18 stone
fill ~86 ~70 ~18 ~90 ~72 ~18 dirt
fill ~86 ~73 ~18 ~90 ~73 ~18 grass_block
fill ~91 ~60 ~18 ~93 ~68 ~18 stone
fill ~91 ~69 ~18 ~93 ~71 ~18 dirt
fill ~91 ~72 ~18 ~93 ~72 ~18 grass_block
fill ~94 ~60 ~18 ~95 ~69 ~18 stone
fill ~94 ~70 ~18 ~95 ~72 ~18 dirt
fill ~94 ~73 ~18 ~95 ~73 ~18 grass_block
fill ~80 ~60 ~19 ~82 ~66 ~19 stone
fill ~80 ~67 ~19 ~82 ~69 ~19 dirt
fill ~80 ~70 ~19 ~82 ~70 ~19 grass_block
fill ~83 ~60 ~19 ~83 ~67 ~19 stone
fill ~83 ~68 ~19 ~83 ~70 ~19 dirt
fill ~83 ~71 ~19 ~83 ~71 ~19 grass_block
fill ~84 ~60 ~19 ~85 ~68 ~19 stone
fill ~84 ~69 ~19 ~85 ~71 ~19 dirt
fill ~84 ~72 ~19 ~85 ~72 ~19 grass_block
fill ~86 ~60 ~19 ~89 ~69 ~19 stone
fill ~86 ~70 ~19 ~89 ~72 ~19 dirt
fill ~86 ~73 ~19 ~89 ~73 ~19 grass_block
fill ~90 ~60 ~19 ~93 ~68 ~19 stone
fill ~90 ~69 ~19 ~93 ~71 ~19 dirt
fill ~90 ~72 ~19 ~93 ~72 ~19 grass_block
fill ~94 ~60 ~19 ~95 ~69 ~19 stone
fill ~94 ~70 ~19 ~95 ~72 ~19 dirt
fill ~94 ~73 ~19 ~95 ~73 ~19 grass_block
fill ~80 ~60 ~20 ~81 ~66 ~20 stone
fill ~80 ~67 ~20 ~81 ~69 ~20 dirt
fill ~80 ~70 ~20 ~81 ~70 ~20 grass_block
fill ~82 ~60 ~20 ~83 ~67 ~20 stone
fill ~82 ~68 ~20 ~83 ~70 ~20 dirt
fill ~82 ~71 ~20 ~83 ~71 ~20 grass_block
fill ~84 ~60 ~20 ~86 ~68 ~20 stone
fill ~84 ~69 ~20 ~86 ~71 ~20 dirt
fill ~84 ~72 ~20 ~86 ~72 ~20 grass_block
fill ~87 ~60 ~20 ~89 ~69 ~20 stone
fill ~87 ~70 ~20 ~89 ~72 ~20 dirt
fill ~87 ~73 ~20 ~89 ~73 ~20 grass_block
fill ~90 ~60 ~20 ~95 ~68 ~20 stone
fill ~90 ~69 ~20 ~95 ~71 ~20 dirt
fill ~90 ~72 ~20 ~95 ~72 ~20 grass_block
fill ~80 ~60 ~21 ~81 ~66 ~21 stone
fill ~80 ~67 ~21 ~81 ~69 ~21 dirt
fill ~80 ~70 ~21 ~81 ~70 ~21 grass_block
fill ~82 ~60 ~21 ~83 ~67 ~21 stone
fill ~82 ~68 ~21 ~83 ~70 ~21 dirt
fill ~82 ~71 ~21 ~83 ~71 ~21 grass_block
fill ~84 ~60 ~21 ~87 ~68 ~21 stone
fill ~84 ~69 ~21 ~87 ~71 ~21 dirt
fill ~84 ~72 ~21 ~87 ~72 ~21 grass_block
fill ~88 ~60 ~21 ~88 ~69 ~21 stone
fill ~88 ~70 ~21 ~88 ~72 ~21 dirt
fill ~88 ~73 ~21 ~88 ~73 ~21 grass_block
fill ~89 ~60 ~21 ~91 ~68 ~21 stone
fill ~89 ~69 ~21 ~91 ~71 ~21 dirt
fill ~89 ~72 ~21 ~91 ~72 ~21 grass_block
fill ~92 ~60 ~21 ~92 ~67 ~21 stone
fill ~92 ~68 ~21 ~92 ~70 ~21 dirt
fill ~92 ~71 ~21 ~92 ~71 ~21 grass_block
fill ~93 ~60 ~21 ~95 ~68 ~21 stone
fill ~93 ~69 ~21 ~95 ~71 ~21 dirt
fill ~93 ~72 ~21 ~95 ~72 ~21 grass_block
fill ~80 ~60 ~22 ~82 ~66 ~22 stone
fill ~80 ~67 ~22 ~82 ~69 ~22 dirt
fill ~80 ~70 ~22 ~82 ~70 ~22 grass_block
fill ~83 ~60 ~22 ~84 ~67 ~22 stone
fill ~83 ~68 ~22 ~84 ~70 ~22 dirt
fill ~83 ~71 ~22 ~84 ~71 ~22 grass_block
fill ~85 ~60 ~22 ~91 ~68 ~22 stone
fill ~85 ~69 ~22 ~91 ~71 ~22 dirt
fill ~85 ~72 ~22 ~91 ~72 ~22 grass_block
fill ~92 ~60 ~22 ~93 ~67 ~22 stone
fill ~92 ~68 ~22 ~93 ~70 ~22 dirt
fill ~92 ~71 ~22 ~93 ~71 ~22 grass_block
fill ~94 ~60 ~22 ~95 ~68 ~22 stone
fill ~94 ~69 ~22 ~95 ~71 ~22 dirt
fill ~94 ~72 ~22 ~95 ~72 ~22 grass_block
fill ~80 ~60 ~23 ~80 ~65 ~23 stone
fill ~80 ~66 ~23 ~80 ~68 ~23 dirt
fill ~80 ~69 ~23 ~80 ~69 ~23 grass_block
fill ~81 ~60 ~23 ~83 ~66 ~23 stone
fill ~81 ~67 ~23 ~83 ~69 ~23 dirt
fill ~81 ~70 ~23 ~83 ~70 ~23 grass_block
fill ~84 ~60 ~23 ~86 ~67 ~23 stone
fill ~84 ~68 ~23 ~86 ~70 ~23 dirt
fill ~84 ~71 ~23 ~86 ~71 ~23 grass_block
fill ~87 ~60 ~23 ~91 ~68 ~23 stone
fill ~87 ~69 ~23 ~91 ~71 ~23 dirt
fill ~87 ~72 ~23 ~91 ~72 ~23 grass_block
fill ~92 ~60 ~23 ~95 ~67 ~23 stone
fill ~92 ~68 ~23 ~95 ~70 ~23 dirt
fill ~92 ~71 ~23 ~95 ~71 ~23 grass_block
fill ~80 ~60 ~24 ~82 ~65 ~24 stone
fill ~80 ~66 ~24 ~82 ~68 ~24 dirt
fill ~80 ~69 ~24 ~82 ~69 ~24 grass_block
fill ~83 ~60 ~24 ~86 ~66 ~24 stone
fill ~83 ~67 ~24 ~86 ~69 ~24 dirt
fill ~83 ~70 ~24 ~86 ~70 ~24 grass_block
fill ~87 ~60 ~24 ~89 ~67 ~24 stone
fill ~87 ~68 ~24 ~89 ~70 ~24 dirt
fill ~87 ~71 ~24 ~89 ~71 ~24 grass_block
fill ~90 ~60 ~24 ~91 ~68 ~24 stone
fill ~90 ~69 ~24 ~91 ~71 ~24 dirt
fill ~90 ~72 ~24 ~91 ~72 ~24 grass_block
fill ~92 ~60 ~24 ~95 ~67 ~24 stone
fill ~92 ~68 ~24 ~95 ~70 ~24 dirt
fill ~92 ~71 ~24 ~95 ~71 ~24 grass_block
fill ~80 ~60 ~25 ~85 ~65 ~25 stone
fill ~80 ~66 ~25 ~85 ~68 ~25 dirt
fill ~80 ~69 ~25 ~85 ~69 ~25 grass_block
fill ~86 ~60 ~25 ~87 ~66 ~25 stone
fill ~86 ~67 ~25 ~87 ~69 ~25 dirt
fill ~86 ~70 ~25 ~87 ~70 ~25 grass_block
fill ~88 ~60 ~25 ~89 ~67 ~25 stone
fill ~88 ~68 ~25 ~89 ~70 ~25 dirt
fill ~88 ~71 ~25 ~89 ~71 ~25 grass_block
fill ~90 ~60 ~25 ~92 ~68 ~25 stone
fill ~90 ~69 ~25 ~92 ~71 ~25 dirt
fill ~90 ~72 ~25 ~92 ~72 ~25 grass_block
fill ~93 ~60 ~25 ~94 ~67 ~25 stone
fill ~93 ~68 ~25 ~94 ~70 ~25 dirt
fill ~93 ~71 ~25 ~94 ~71 ~25 grass_block
fill ~95 ~60 ~25 ~95 ~66 ~25 stone
fill ~95 ~67 ~25 ~95 ~69 ~25 dirt
fill ~95 ~70 ~25 ~95 ~70 ~25 grass_block
fill ~80 ~60 ~26 ~80 ~64 ~26 stone
fill ~80 ~65 ~26 ~80 ~67 ~26 dirt
fill ~80 ~68 ~26 ~80 ~68 ~26 grass_block
fill ~81 ~60 ~26 ~86 ~65 ~26 stone
fill ~81 ~66 ~26 ~86 ~68 ~26 dirt
fill ~81 ~69 ~26 ~86 ~69 ~26 grass_block
fill ~87 ~60 ~26 ~88 ~66 ~26 stone
fill ~87 ~67 ~26 ~88 ~69 ~26 dirt
fill ~87 ~70 ~26 ~88 ~70 ~26 grass_block
fill ~89 ~60 ~26 ~89 ~67 ~26 stone
fill ~89 ~68 ~26 ~89 ~70 ~26 dirt
fill ~89 ~71 ~26 ~89 ~71 ~26 grass_block
fill ~90 ~60 ~26 ~92 ~68 ~26 stone
fill ~90 ~69 ~26 ~92 ~71 ~26 dirt
fill ~90 ~72 ~26 ~92 ~72 ~26 grass_block
fill ~93 ~60 ~26 ~95 ~67 ~26 stone
fill ~93 ~68 ~26 ~95 ~70 ~26 dirt
fill ~93 ~71 ~26 ~95 ~71 ~26 grass_block
fill ~80 ~60 ~27 ~82 ~64 ~27 stone
fill ~80 ~65 ~27 ~82 ~67 ~27 dirt
fill ~80 ~68 ~27 ~82 ~68 ~27 grass_block
fill ~83 ~60 ~27 ~86 ~65 ~27 stone
fill ~83 ~66 ~27 ~86 ~68 ~27 dirt
fill ~83 ~69 ~27 ~86 ~69 ~27 grass_block
fill ~87 ~60 ~27 ~88 ~66 ~27 stone
fill ~87 ~67 ~27 ~88 ~69 ~27 dirt
fill ~87 ~70 ~27 ~88 ~70 ~27 grass_block
fill ~89 ~60 ~27 ~90 ~67 ~27 stone
fill ~89 ~68 ~27 ~90 ~70 ~27 dirt
fill ~89 ~71 ~27 ~90 ~71 ~27 grass_block
fill ~91 ~60 ~27 ~92 ~68 ~27 stone
fill ~91 ~69 ~27 ~92 ~71 ~27 dirt
fill ~91 ~72 ~27 ~92 ~72 ~27 grass_block
fill ~93 ~60 ~27 ~95 ~67 ~27 stone
fill ~93 ~68 ~27 ~95 ~70 ~27 dirt
fill ~93 ~71 ~27 ~95 ~71 ~27 grass_block
fill ~80 ~60 ~28 ~83 ~64 ~28 stone
fill ~80 ~65 ~28 ~83 ~67 ~28 dirt
fill ~80 ~68 ~28 ~83 ~68 ~28 grass_block
fill ~84 ~60 ~28 ~86 ~65 ~28 stone
fill ~84 ~66 ~28 ~86 ~68 ~28 dirt
fill ~84 ~69 ~28 ~86 ~69 ~28 grass_block
fill ~87 ~60 ~28 ~89 ~66 ~28 stone
fill ~87 ~67 ~28 ~89 ~69 ~28 dirt
fill ~87 ~70 ~28 ~89 ~70 ~28 grass_block
fill ~90 ~60 ~28 ~90 ~67 ~28 stone
fill ~90 ~68 ~28 ~90 ~70 ~28 dirt
fill ~90 ~71 ~28 ~90 ~71 ~28 grass_block
fill ~91 ~60 ~28 ~93 ~68 ~28 stone
fill ~91 ~69 ~28 ~93 ~71 ~28 dirt
fill ~91 ~72 ~28 ~93 ~72 ~28 grass_block
fill ~94 ~60 ~28 ~95 ~67 ~28 stone
fill ~94 ~68 ~28 ~95 ~70 ~28 dirt
fill ~94 ~71 ~28 ~95 ~71 ~28 grass_block
fill ~80 ~60 ~29 ~83 ~64 ~29 stone
fill ~80 ~65 ~29 ~83 ~67 ~29 dirt
fill ~80 ~68 ~29 ~83 ~68 ~29 grass_block
fill ~84 ~60 ~29 ~86 ~65 ~29 stone
fill ~84 ~66 ~29 ~86 ~68 ~29 dirt
fill ~84 ~69 ~29 ~86 ~69 ~29 grass_block
fill ~87 ~60 ~29 ~89 ~66 ~29 stone
fill ~87 ~67 ~29 ~89 ~69 ~29 dirt
fill ~87 ~70 ~29 ~89 ~70 ~29 grass_block
fill ~90 ~60 ~29 ~90 ~67 ~29 stone
fill ~90 ~68 ~29 ~90 ~70 ~29 dirt
fill ~90 ~71 ~29 ~90 ~71 ~29 grass_block
fill ~91 ~60 ~29 ~93 ~68 ~29 stone
fill ~91 ~69 ~29 ~93 ~71 ~29 dirt
fill ~91 ~72 ~29 ~93 ~72 ~29 grass_block
fill ~94 ~60 ~29 ~95 ~67 ~29 stone
fill ~94 ~68 ~29 ~95 ~70 ~29 dirt
fill ~94 ~71 ~29 ~95 ~71 ~29 grass_block
fill ~80 ~60 ~30 ~84 ~64 ~30 stone
fill ~80 ~65 ~30 ~84 ~67 ~30 dirt
fill ~80 ~68 ~30 ~84 ~68 ~30 grass_block
fill ~85 ~60 ~30 ~87 ~65 ~30 stone
fill ~85 ~66 ~30 ~87 ~68 ~30 dirt
fill ~85 ~69 ~30 ~87 ~69 ~30 grass_block
fill ~88 ~60 ~30 ~89 ~66 ~30 stone
fill ~88 ~67 ~30 ~89 ~69 ~30 dirt
fill ~88 ~70 ~30 ~89 ~70 ~30 grass_block
fill ~90 ~60 ~30 ~91 ~67 ~30 stone
fill ~90 ~68 ~30 ~91 ~70 ~30 dirt
fill ~90 ~71 ~30 ~91 ~71 ~30 grass_block
fill ~92 ~60 ~30 ~93 ~68 ~30 stone
fill ~92 ~69 ~30 ~93 ~71 ~30 dirt
fill ~92 ~72 ~30 ~93 ~72 ~30 grass_block
fill ~94 ~60 ~30 ~95 ~67 ~30 stone
fill ~94 ~68 ~30 ~95 ~70 ~30 dirt
fill ~94 ~71 ~30 ~95 ~71 ~30 grass_block
fill ~80 ~60 ~31 ~80 ~64 ~31 stone
fill ~80 ~65 ~31 ~80 ~67 ~31 dirt
fill ~80 ~68 ~31 ~80 ~68 ~31 grass_block
fill ~81 ~60 ~31 ~82 ~63 ~31 stone
fill ~81 ~64 ~31 ~82 ~66 ~31 dirt
fill ~81 ~67 ~31 ~82 ~67 ~31 grass_block
fill ~83 ~60 ~31 ~84 ~64 ~31 stone
fill ~83 ~65 ~31 ~84 ~67 ~31 dirt
fill ~83 ~68 ~31 ~84 ~68 ~31 grass_block
fill ~85 ~60 ~31 ~87 ~65 ~31 stone
fill ~85 ~66 ~31 ~87 ~68 ~31 dirt
fill ~85 ~69 ~31 ~87 ~69 ~31 grass_block
fill ~88 ~60 ~31 ~89 ~66 ~31 stone
fill ~88 ~67 ~31 ~89 ~69 ~31 dirt
fill ~88 ~70 ~31 ~89 ~70 ~31 grass_block
fill ~90 ~60 ~31 ~92 ~67 ~31 stone
fill ~90 ~68 ~31 ~92 ~70 ~31 dirt
fill ~90 ~71 ~31 ~92 ~71 ~31 grass_block
fill ~93 ~60 ~31 ~93 ~68 ~31 stone
fill ~93 ~69 ~31 ~93 ~71 ~31 dirt
fill ~93 ~72 ~31 ~93 ~72 ~31 grass_block
fill ~94 ~60 ~31 ~95 ~67 ~31 stone
fill ~94 ~68 ~31 ~95 ~70 ~31 dirt
fill ~94 ~71 ~31 ~95 ~71 ~31 grass_block