fill ~192 ~60 ~16 ~207 ~61 ~16 stone
fill ~192 ~62 ~16 ~207 ~64 ~16 dirt
fill ~192 ~65 ~16 ~207 ~65 ~16 grass_block
fill ~192 ~60 ~17 ~207 ~61 ~17 stone
fill ~192 ~62 ~17 ~207 ~64 ~17 dirt
fill ~192 ~65 ~17 ~207 ~65 ~17 grass_block
fill ~192 ~60 ~18 ~207 ~61 ~18 stone
fill ~192 ~62 ~18 ~207 ~64 ~18 dirt
fill ~192 ~65 ~18 ~207 ~65 ~18 grass_block
fill ~192 ~60 ~19 ~207 ~61 ~19 stone
fill ~192 ~62 ~19 ~207 ~64 ~19 dirt
fill ~192 ~65 ~19 ~207 ~65 ~19 grass_block
fill ~192 ~60 ~20 ~207 ~61 ~20 stone
fill ~192 ~62 ~20 ~207 ~64 ~20 dirt
fill ~192 ~65 ~20 ~207 ~65 ~20 grass_block
fill ~192 ~60 ~21 ~192 ~62 ~21 stone
fill ~192 ~63 ~21 ~192 ~65 ~21 dirt
fill ~192 ~66 ~21 ~192 ~66 ~21 grass_block
fill ~193 ~60 ~21 ~207 ~61 ~21 stone
fill ~193 ~62 ~21 ~207 ~64 ~21 dirt
fill ~193 ~65 ~21 ~207 ~65 ~21 grass_block
fill ~192 ~60 ~22 ~193 ~62 ~22 stone
fill ~192 ~63 ~22 ~193 ~65 ~22 dirt
fill ~192 ~66 ~22 ~193 ~66 ~22 grass_block
fill ~194 ~60 ~22 ~194 ~61 ~22 stone
fill ~194 ~62 ~22 ~194 ~64 ~22 dirt
fill ~194 ~65 ~22 ~194 ~65 ~22 grass_block
fill ~195 ~60 ~22 ~197 ~60 ~22 stone
fill ~195 ~61 ~22 ~197 ~63 ~22 dirt
fill ~195 ~64 ~22 ~197 ~64 ~22 grass_block
fill ~198 ~60 ~22 ~207 ~61 ~22 stone
fill ~198 ~62 ~22 ~207 ~64 ~22 dirt
fill ~198 ~65 ~22 ~207 ~65 ~22 grass_block
fill ~192 ~60 ~23 ~192 ~63 ~23 stone
fill ~192 ~64 ~23 ~192 ~66 ~23 dirt
fill ~192 ~67 ~23 ~192 ~67 ~23 grass_block
fill ~193 ~60 ~23 ~195 ~62 ~23 stone
fill ~193 ~63 ~23 ~195 ~65 ~23 dirt
fill ~193 ~66 ~23 ~195 ~66 ~23 grass_block
fill ~196 ~60 ~23 ~196 ~61 ~23 stone
fill ~196 ~62 ~23 ~196 ~64 ~23 dirt
fill ~196 ~65 ~23 ~196 ~65 ~23 grass_block
fill ~197 ~60 ~23 ~200 ~60 ~23 stone
fill ~197 ~61 ~23 ~200 ~63 ~23 dirt
fill ~197 ~64 ~23 ~200 ~64 ~23 grass_block
fill ~201 ~60 ~23 ~202 ~61 ~23 stone
fill ~201 ~62 ~23 ~202 ~64 ~23 dirt
fill ~201 ~65 ~23 ~202 ~65 ~23 grass_block
fill ~203 ~60 ~23 ~203 ~60 ~23 stone
fill ~203 ~61 ~23 ~203 ~63 ~23 dirt
fill ~203 ~64 ~23 ~203 ~64 ~23 grass_block
fill ~204 ~60 ~23 ~207 ~61 ~23 stone
fill ~204 ~62 ~23 ~207 ~64 ~23 dirt
fill ~204 ~65 ~23 ~207 ~65 ~23 grass_block
fill ~192 ~60 ~24 ~193 ~63 ~24 stone
fill ~192 ~64 ~24 ~193 ~66 ~24 dirt
fill ~192 ~67 ~24 ~193 ~67 ~24 grass_block
fill ~194 ~60 ~24 ~197 ~62 ~24 stone
fill ~194 ~63 ~24 ~197 ~65 ~24 dirt
fill ~194 ~66 ~24 ~197 ~66 ~24 grass_block
fill ~198 ~60 ~24 ~203 ~60 ~24 stone
fill ~198 ~61 ~24 ~203 ~63 ~24 dirt
fill ~198 ~64 ~24 ~203 ~64 ~24 grass_block
fill ~204 ~60 ~24 ~207 ~61 ~24 stone
fill ~204 ~62 ~24 ~207 ~64 ~24 dirt
fill ~204 ~65 ~24 ~207 ~65 ~24 grass_block
fill ~192 ~60 ~25 ~197 ~63 ~25 stone
fill ~192 ~64 ~25 ~197 ~66 ~25 dirt
fill ~192 ~67 ~25 ~197 ~67 ~25 grass_block
fill ~198 ~60 ~25 ~198 ~62 ~25 stone
fill ~198 ~63 ~25 ~198 ~65 ~25 dirt
fill ~198 ~66 ~25 ~198 ~66 ~25 grass_block
fill ~199 ~60 ~25 ~199 ~61 ~25 stone
fill ~199 ~62 ~25 ~199 ~64 ~25 dirt
fill ~199 ~65 ~25 ~199 ~65 ~25 grass_block
fill ~200 ~60 ~25 ~202 ~60 ~25 stone
fill ~200 ~61 ~25 ~202 ~63 ~25 dirt
fill ~200 ~64 ~25 ~202 ~64 ~25 grass_block
fill ~203 ~60 ~25 ~207 ~61 ~25 stone
fill ~203 ~62 ~25 ~207 ~64 ~25 dirt
fill ~203 ~65 ~25 ~207 ~65 ~25 grass_block
fill ~192 ~60 ~26 ~198 ~63 ~26 stone
fill ~192 ~64 ~26 ~198 ~66 ~26 dirt
fill ~192 ~67 ~26 ~198 ~67 ~26 grass_block
fill ~199 ~60 ~26 ~199 ~62 ~26 stone
fill ~199 ~63 ~26 ~199 ~65 ~26 dirt
fill ~199 ~66 ~26 ~199 ~66 ~26 grass_block
fill ~200 ~60 ~26 ~202 ~61 ~26 stone
fill ~200 ~62 ~26 ~202 ~64 ~26 dirt
fill ~200 ~65 ~26 ~202 ~65 ~26 grass_block
fill ~203 ~60 ~26 ~205 ~62 ~26 stone
fill ~203 ~63 ~26 ~205 ~65 ~26 dirt
fill ~203 ~66 ~26 ~205 ~66 ~26 grass_block
fill ~206 ~60 ~26 ~207 ~61 ~26 stone
fill ~206 ~62 ~26 ~207 ~64 ~26 dirt
fill ~206 ~65 ~26 ~207 ~65 ~26 grass_block
fill ~192 ~60 ~27 ~199 ~63 ~27 stone
fill ~192 ~64 ~27 ~199 ~66 ~27 dirt
fill ~192 ~67 ~27 ~199 ~67 ~27 grass_block
fill ~200 ~60 ~27 ~205 ~62 ~27 stone
fill ~200 ~63 ~27 ~205 ~65 ~27 dirt
fill ~200 ~66 ~27 ~205 ~66 ~27 grass_block
fill ~206 ~60 ~27 ~207 ~61 ~27 stone
fill ~206 ~62 ~27 ~207 ~64 ~27 dirt
fill ~206 ~65 ~27 ~207 ~65 ~27 grass_block
fill ~192 ~60 ~28 ~198 ~63 ~28 stone
fill ~192 ~64 ~28 ~198 ~66 ~28 dirt
fill ~192 ~67 ~28 ~198 ~67 ~28 grass_block
fill ~199 ~60 ~28 ~205 ~62 ~28 stone
fill ~199 ~63 ~28 ~205 ~65 ~28 dirt
fill ~199 ~66 ~28 ~205 ~66 ~28 grass_block
fill ~206 ~60 ~28 ~207 ~61 ~28 stone
fill ~206 ~62 ~28 ~207 ~64 ~28 dirt
fill ~206 ~65 ~28 ~207 ~65 ~28 grass_block
fill ~192 ~60 ~29 ~199 ~63 ~29 stone
fill ~192 ~64 ~29 ~199 ~66 ~29 dirt
fill ~192 ~67 ~29 ~199 ~67 ~29 grass_block
fill ~200 ~60 ~29 ~204 ~62 ~29 stone
fill ~200 ~63 ~29 ~204 ~65 ~29 dirt
fill ~200 ~66 ~29 ~204 ~66 ~29 grass_block
fill ~205 ~60 ~29 ~207 ~61 ~29 stone
fill ~205 ~62 ~29 ~207 ~64 ~29 dirt
fill ~205 ~65 ~29 ~207 ~65 ~29 grass_block
fill ~192 ~60 ~30 ~192 ~64 ~30 stone
fill ~192 ~65 ~30 ~192 ~67 ~30 dirt
fill ~192 ~68 ~30 ~192 ~68 ~30 grass_block
fill ~193 ~60 ~30 ~201 ~63 ~30 stone
fill ~193 ~64 ~30 ~201 ~66 ~30 dirt
fill ~193 ~67 ~30 ~201 ~67 ~30 grass_block
fill ~202 ~60 ~30 ~205 ~62 ~30 stone
fill ~202 ~63 ~30 ~205 ~65 ~30 dirt
fill ~202 ~66 ~30 ~205 ~66 ~30 grass_block
fill ~206 ~60 ~30 ~207 ~61 ~30 stone
fill ~206 ~62 ~30 ~207 ~64 ~30 dirt
fill ~206 ~65 ~30 ~207 ~65 ~30 grass_block
fill ~192 ~60 ~31 ~193 ~64 ~31 stone
fill ~192 ~65 ~31 ~193 ~67 ~31 dirt
fill ~192 ~68 ~31 ~193 ~68 ~31 grass_block
fill ~194 ~60 ~31 ~202 ~63 ~31 stone
fill ~194 ~64 ~31 ~202 ~66 ~31 dirt
fill ~194 ~67 ~31 ~202 ~67 ~31 grass_block
fill ~203 ~60 ~31 ~205 ~62 ~31 stone
fill ~203 ~63 ~31 ~205 ~65 ~31 dirt
fill ~203 ~66 ~31 ~205 ~66 ~31 grass_block
fill ~206 ~60 ~31 ~207 ~61 ~31 stone
fill ~206 ~62 ~31 ~207 ~64 ~31 dirt
fill ~206 ~65 ~31 ~207 ~65 ~31 grass_block