fill ~0 ~60 ~128 ~4 ~70 ~128 stone
fill ~0 ~71 ~128 ~4 ~73 ~128 dirt
fill ~0 ~74 ~128 ~4 ~74 ~128 grass_block
fill ~5 ~60 ~128 ~12 ~69 ~128 stone
fill ~5 ~70 ~128 ~12 ~72 ~128 dirt
fill ~5 ~73 ~128 ~12 ~73 ~128 grass_block
fill ~13 ~60 ~128 ~14 ~68 ~128 stone
fill ~13 ~69 ~128 ~14 ~71 ~128 dirt
fill ~13 ~72 ~128 ~14 ~72 ~128 grass_block
fill ~15 ~60 ~128 ~15 ~67 ~128 stone
fill ~15 ~68 ~128 ~15 ~70 ~128 dirt
fill ~15 ~71 ~128 ~15 ~71 ~128 grass_block
fill ~0 ~60 ~129 ~10 ~70 ~129 stone
fill ~0 ~71 ~129 ~10 ~73 ~129 dirt
fill ~0 ~74 ~129 ~10 ~74 ~129 grass_block
fill ~11 ~60 ~129 ~13 ~69 ~129 stone
fill ~11 ~70 ~129 ~13 ~72 ~129 dirt
fill ~11 ~73 ~129 ~13 ~73 ~129 grass_block
fill ~14 ~60 ~129 ~15 ~68 ~129 stone
fill ~14 ~69 ~129 ~15 ~71 ~129 dirt
fill ~14 ~72 ~129 ~15 ~72 ~129 grass_block
fill ~0 ~60 ~130 ~11 ~70 ~130 stone
fill ~0 ~71 ~130 ~11 ~73 ~130 dirt
fill ~0 ~74 ~130 ~11 ~74 ~130 grass_block
fill ~12 ~60 ~130 ~13 ~69 ~130 stone
fill ~12 ~70 ~130 ~13 ~72 ~130 dirt
fill ~12 ~73 ~130 ~13 ~73 ~130 grass_block
fill ~14 ~60 ~130 ~15 ~68 ~130 stone
fill ~14 ~69 ~130 ~15 ~71 ~130 dirt
fill ~14 ~72 ~130 ~15 ~72 ~130 grass_block
fill ~0 ~60 ~131 ~11 ~70 ~131 stone
fill ~0 ~71 ~131 ~11 ~73 ~131 dirt
fill ~0 ~74 ~131 ~11 ~74 ~131 grass_block
fill ~12 ~60 ~131 ~14 ~69 ~131 stone
fill ~12 ~70 ~131 ~14 ~72 ~131 dirt
fill ~12 ~73 ~131 ~14 ~73 ~131 grass_block
fill ~15 ~60 ~131 ~15 ~68 ~131 stone
fill ~15 ~69 ~131 ~15 ~71 ~131 dirt
fill ~15 ~72 ~131 ~15 ~72 ~131 grass_block
fill ~0 ~60 ~132 ~0 ~69 ~132 stone
fill ~0 ~70 ~132 ~0 ~72 ~132 dirt
fill ~0 ~73 ~132 ~0 ~73 ~132 grass_block
fill ~1 ~60 ~132 ~4 ~70 ~132 stone
fill ~1 ~71 ~132 ~4 ~73 ~132 dirt
fill ~1 ~74 ~132 ~4 ~74 ~132 grass_block
fill ~5 ~60 ~132 ~7 ~69 ~132 stone
fill ~5 ~70 ~132 ~7 ~72 ~132 dirt
fill ~5 ~73 ~132 ~7 ~73 ~132 grass_block
fill ~8 ~60 ~132 ~11 ~70 ~132 stone
fill ~8 ~71 ~132 ~11 ~73 ~132 dirt
fill ~8 ~74 ~132 ~11 ~74 ~132 grass_block
fill ~12 ~60 ~132 ~15 ~69 ~132 stone
fill ~12 ~70 ~132 ~15 ~72 ~132 dirt
fill ~12 ~73 ~132 ~15 ~73 ~132 grass_block
fill ~0 ~60 ~133 ~2 ~69 ~133 stone
fill ~0 ~70 ~133 ~2 ~72 ~133 dirt
fill ~0 ~73 ~133 ~2 ~73 ~133 grass_block
fill ~3 ~60 ~133 ~3 ~70 ~133 stone
fill ~3 ~71 ~133 ~3 ~73 ~133 dirt
fill ~3 ~74 ~133 ~3 ~74 ~133 grass_block
fill ~4 ~60 ~133 ~9 ~69 ~133 stone
fill ~4 ~70 ~133 ~9 ~72 ~133 dirt
fill ~4 ~73 ~133 ~9 ~73 ~133 grass_block
fill ~10 ~60 ~133 ~12 ~70 ~133 stone
fill ~10 ~71 ~133 ~12 ~73 ~133 dirt
fill ~10 ~74 ~133 ~12 ~74 ~133 grass_block
fill ~13 ~60 ~133 ~15 ~69 ~133 stone
fill ~13 ~70 ~133 ~15 ~72 ~133 dirt
fill ~13 ~73 ~133 ~15 ~73 ~133 grass_block
fill ~0 ~60 ~134 ~6 ~69 ~134 stone
fill ~0 ~70 ~134 ~6 ~72 ~134 dirt
fill ~0 ~73 ~134 ~6 ~73 ~134 grass_block
fill ~7 ~60 ~134 ~7 ~68 ~134 stone
fill ~7 ~69 ~134 ~7 ~71 ~134 dirt
fill ~7 ~72 ~134 ~7 ~72 ~134 grass_block
fill ~8 ~60 ~134 ~11 ~69 ~134 stone
fill ~8 ~70 ~134 ~11 ~72 ~134 dirt
fill ~8 ~73 ~134 ~11 ~73 ~134 grass_block
fill ~12 ~60 ~134 ~13 ~70 ~134 stone
fill ~12 ~71 ~134 ~13 ~73 ~134 dirt
fill ~12 ~74 ~134 ~13 ~74 ~134 grass_block
fill ~14 ~60 ~134 ~15 ~69 ~134 stone
fill ~14 ~70 ~134 ~15 ~72 ~134 dirt
fill ~14 ~73 ~134 ~15 ~73 ~134 grass_block
fill ~0 ~60 ~135 ~0 ~69 ~135 stone
fill ~0 ~70 ~135 ~0 ~72 ~135 dirt
fill ~0 ~73 ~135 ~0 ~73 ~135 grass_block
fill ~1 ~60 ~135 ~3 ~68 ~135 stone
fill ~1 ~69 ~135 ~3 ~71 ~135 dirt
fill ~1 ~72 ~135 ~3 ~72 ~135 grass_block
fill ~4 ~60 ~135 ~4 ~69 ~135 stone
fill ~4 ~70 ~135 ~4 ~72 ~135 dirt
fill ~4 ~73 ~135 ~4 ~73 ~135 grass_block
fill ~5 ~60 ~135 ~9 ~68 ~135 stone
fill ~5 ~69 ~135 ~9 ~71 ~135 dirt
fill ~5 ~72 ~135 ~9 ~72 ~135 grass_block
fill ~10 ~60 ~135 ~12 ~69 ~135 stone
fill ~10 ~70 ~135 ~12 ~72 ~135 dirt
fill ~10 ~73 ~135 ~12 ~73 ~135 grass_block
fill ~13 ~60 ~135 ~13 ~70 ~135 stone
fill ~13 ~71 ~135 ~13 ~73 ~135 dirt
fill ~13 ~74 ~135 ~13 ~74 ~135 grass_block
fill ~14 ~60 ~135 ~15 ~69 ~135 stone
fill ~14 ~70 ~135 ~15 ~72 ~135 dirt
fill ~14 ~73 ~135 ~15 ~73 ~135 grass_block
fill ~0 ~60 ~136 ~10 ~68 ~136 stone
fill ~0 ~69 ~136 ~10 ~71 ~136 dirt
fill ~0 ~72 ~136 ~10 ~72 ~136 grass_block
fill ~11 ~60 ~136 ~13 ~69 ~136 stone
fill ~11 ~70 ~136 ~13 ~72 ~136 dirt
fill ~11 ~73 ~136 ~13 ~73 ~136 grass_block
fill ~14 ~60 ~136 ~15 ~70 ~136 stone
fill ~14 ~71 ~136 ~15 ~73 ~136 dirt
fill ~14 ~74 ~136 ~15 ~74 ~136 grass_block
fill ~0 ~60 ~137 ~0 ~68 ~137 stone
fill ~0 ~69 ~137 ~0 ~71 ~137 dirt
fill ~0 ~72 ~137 ~0 ~72 ~137 grass_block
fill ~1 ~60 ~137 ~2 ~67 ~137 stone
fill ~1 ~68 ~137 ~2 ~70 ~137 dirt
fill ~1 ~71 ~137 ~2 ~71 ~137 grass_block
fill ~3 ~60 ~137 ~6 ~68 ~137 stone
fill ~3 ~69 ~137 ~6 ~71 ~137 dirt
fill ~3 ~72 ~137 ~6 ~72 ~137 grass_block
fill ~7 ~60 ~137 ~8 ~67 ~137 stone
fill ~7 ~68 ~137 ~8 ~70 ~137 dirt
fill ~7 ~71 ~137 ~8 ~71 ~137 grass_block
fill ~9 ~60 ~137 ~11 ~68 ~137 stone
fill ~9 ~69 ~137 ~11 ~71 ~137 dirt
fill ~9 ~72 ~137 ~11 ~72 ~137 grass_block
fill ~12 ~60 ~137 ~14 ~69 ~137 stone
fill ~12 ~70 ~137 ~14 ~72 ~137 dirt
fill ~12 ~73 ~137 ~14 ~73 ~137 grass_block
fill ~15 ~60 ~137 ~15 ~70 ~137 stone
fill ~15 ~71 ~137 ~15 ~73 ~137 dirt
fill ~15 ~74 ~137 ~15 ~74 ~137 grass_block
fill ~0 ~60 ~138 ~2 ~67 ~138 stone
fill ~0 ~68 ~138 ~2 ~70 ~138 dirt
fill ~0 ~71 ~138 ~2 ~71 ~138 grass_block
fill ~3 ~60 ~138 ~6 ~68 ~138 stone
fill ~3 ~69 ~138 ~6 ~71 ~138 dirt
fill ~3 ~72 ~138 ~6 ~72 ~138 grass_block
fill ~7 ~60 ~138 ~8 ~67 ~138 stone
fill ~7 ~68 ~138 ~8 ~70 ~138 dirt
fill ~7 ~71 ~138 ~8 ~71 ~138 grass_block
fill ~9 ~60 ~138 ~11 ~68 ~138 stone
fill ~9 ~69 ~138 ~11 ~71 ~138 dirt
fill ~9 ~72 ~138 ~11 ~72 ~138 grass_block
fill ~12 ~60 ~138 ~14 ~69 ~138 stone
fill ~12 ~70 ~138 ~14 ~72 ~138 dirt
fill ~12 ~73 ~138 ~14 ~73 ~138 grass_block
fill ~15 ~60 ~138 ~15 ~70 ~138 stone
fill ~15 ~71 ~138 ~15 ~73 ~138 dirt
fill ~15 ~74 ~138 ~15 ~74 ~138 grass_block
fill ~0 ~60 ~139 ~0 ~66 ~139 stone
fill ~0 ~67 ~139 ~0 ~69 ~139 dirt
fill ~0 ~70 ~139 ~0 ~70 ~139 grass_block
fill ~1 ~60 ~139 ~2 ~67 ~139 stone
fill ~1 ~68 ~139 ~2 ~70 ~139 dirt
fill ~1 ~71 ~139 ~2 ~71 ~139 grass_block
fill ~3 ~60 ~139 ~6 ~68 ~139 stone
fill ~3 ~69 ~139 ~6 ~71 ~139 dirt
fill ~3 ~72 ~139 ~6 ~72 ~139 grass_block
fill ~7 ~60 ~139 ~9 ~67 ~139 stone
fill ~7 ~68 ~139 ~9 ~70 ~139 dirt
fill ~7 ~71 ~139 ~9 ~71 ~139 grass_block
fill ~10 ~60 ~139 ~12 ~68 ~139 stone
fill ~10 ~69 ~139 ~12 ~71 ~139 dirt
fill ~10 ~72 ~139 ~12 ~72 ~139 grass_block
fill ~13 ~60 ~139 ~15 ~69 ~139 stone
fill ~13 ~70 ~139 ~15 ~72 ~139 dirt
fill ~13 ~73 ~139 ~15 ~73 ~139 grass_block
fill ~0 ~60 ~140 ~0 ~66 ~140 stone
fill ~0 ~67 ~140 ~0 ~69 ~140 dirt
fill ~0 ~70 ~140 ~0 ~70 ~140 grass_block
fill ~1 ~60 ~140 ~2 ~67 ~140 stone
fill ~1 ~68 ~140 ~2 ~70 ~140 dirt
fill ~1 ~71 ~140 ~2 ~71 ~140 grass_block
fill ~3 ~60 ~140 ~5 ~68 ~140 stone
fill ~3 ~69 ~140 ~5 ~71 ~140 dirt
fill ~3 ~72 ~140 ~5 ~72 ~140 grass_block
fill ~6 ~60 ~140 ~10 ~67 ~140 stone
fill ~6 ~68 ~140 ~10 ~70 ~140 dirt
fill ~6 ~71 ~140 ~10 ~71 ~140 grass_block
fill ~11 ~60 ~140 ~13 ~68 ~140 stone
fill ~11 ~69 ~140 ~13 ~71 ~140 dirt
fill ~11 ~72 ~140 ~13 ~72 ~140 grass_block
fill ~14 ~60 ~140 ~15 ~69 ~140 stone
fill ~14 ~70 ~140 ~15 ~72 ~140 dirt
fill ~14 ~73 ~140 ~15 ~73 ~140 grass_block
fill ~0 ~60 ~141 ~1 ~67 ~141 stone
fill ~0 ~68 ~141 ~1 ~70 ~141 dirt
fill ~0 ~71 ~141 ~1 ~71 ~141 grass_block
fill ~2 ~60 ~141 ~5 ~68 ~141 stone
fill ~2 ~69 ~141 ~5 ~71 ~141 dirt
fill ~2 ~72 ~141 ~5 ~72 ~141 grass_block
fill ~6 ~60 ~141 ~10 ~67 ~141 stone
fill ~6 ~68 ~141 ~10 ~70 ~141 dirt
fill ~6 ~71 ~141 ~10 ~71 ~141 grass_block
fill ~11 ~60 ~141 ~14 ~68 ~141 stone
fill ~11 ~69 ~141 ~14 ~71 ~141 dirt
fill ~11 ~72 ~141 ~14 ~72 ~141 grass_block
fill ~15 ~60 ~141 ~15 ~69 ~141 stone
fill ~15 ~70 ~141 ~15 ~72 ~141 dirt
fill ~15 ~73 ~141 ~15 ~73 ~141 grass_block
fill ~0 ~60 ~142 ~2 ~67 ~142 stone
fill ~0 ~68 ~142 ~2 ~70 ~142 dirt
fill ~0 ~71 ~142 ~2 ~71 ~142 grass_block
fill ~3 ~60 ~142 ~5 ~68 ~142 stone
fill ~3 ~69 ~142 ~5 ~71 ~142 dirt
fill ~3 ~72 ~142 ~5 ~72 ~142 grass_block
fill ~6 ~60 ~142 ~10 ~67 ~142 stone
fill ~6 ~68 ~142 ~10 ~70 ~142 dirt
fill ~6 ~71 ~142 ~10 ~71 ~142 grass_block
fill ~11 ~60 ~142 ~13 ~68 ~142 stone
fill ~11 ~69 ~142 ~13 ~71 ~142 dirt
fill ~11 ~72 ~142 ~13 ~72 ~142 grass_block
fill ~14 ~60 ~142 ~15 ~69 ~142 stone
fill ~14 ~70 ~142 ~15 ~72 ~142 dirt
fill ~14 ~73 ~142 ~15 ~73 ~142 grass_block
fill ~0 ~60 ~143 ~0 ~66 ~143 stone
fill ~0 ~67 ~143 ~0 ~69 ~143 dirt
fill ~0 ~70 ~143 ~0 ~70 ~143 grass_block
fill ~1 ~60 ~143 ~11 ~67 ~143 stone
fill ~1 ~68 ~143 ~11 ~70 ~143 dirt
fill ~1 ~71 ~143 ~11 ~71 ~143 grass_block
fill ~12 ~60 ~143 ~13 ~68 ~143 stone
fill ~12 ~69 ~143 ~13 ~71 ~143 dirt
fill ~12 ~72 ~143 ~13 ~72 ~143 grass_block
fill ~14 ~60 ~143 ~15 ~69 ~143 stone
fill ~14 ~70 ~143 ~15 ~72 ~143 dirt
fill ~14 ~73 ~143 ~15 ~73 ~143 grass_block