fill ~368 ~60 ~0 ~374 ~64 ~0 stone
fill ~368 ~65 ~0 ~374 ~67 ~0 dirt
fill ~368 ~68 ~0 ~374 ~68 ~0 grass_block
fill ~375 ~60 ~0 ~382 ~65 ~0 stone
fill ~375 ~66 ~0 ~382 ~68 ~0 dirt
fill ~375 ~69 ~0 ~382 ~69 ~0 grass_block
fill ~383 ~60 ~0 ~383 ~64 ~0 stone
fill ~383 ~65 ~0 ~383 ~67 ~0 dirt
fill ~383 ~68 ~0 ~383 ~68 ~0 grass_block
fill ~368 ~60 ~1 ~372 ~63 ~1 stone
fill ~368 ~64 ~1 ~372 ~66 ~1 dirt
fill ~368 ~67 ~1 ~372 ~67 ~1 grass_block
fill ~373 ~60 ~1 ~374 ~64 ~1 stone
fill ~373 ~65 ~1 ~374 ~67 ~1 dirt
fill ~373 ~68 ~1 ~374 ~68 ~1 grass_block
fill ~375 ~60 ~1 ~382 ~65 ~1 stone
fill ~375 ~66 ~1 ~382 ~68 ~1 dirt
fill ~375 ~69 ~1 ~382 ~69 ~1 grass_block
fill ~383 ~60 ~1 ~383 ~64 ~1 stone
fill ~383 ~65 ~1 ~383 ~67 ~1 dirt
fill ~383 ~68 ~1 ~383 ~68 ~1 grass_block
fill ~368 ~60 ~2 ~371 ~63 ~2 stone
fill ~368 ~64 ~2 ~371 ~66 ~2 dirt
fill ~368 ~67 ~2 ~371 ~67 ~2 grass_block
fill ~372 ~60 ~2 ~374 ~64 ~2 stone
fill ~372 ~65 ~2 ~374 ~67 ~2 dirt
fill ~372 ~68 ~2 ~374 ~68 ~2 grass_block
fill ~375 ~60 ~2 ~383 ~65 ~2 stone
fill ~375 ~66 ~2 ~383 ~68 ~2 dirt
fill ~375 ~69 ~2 ~383 ~69 ~2 grass_block
fill ~368 ~60 ~3 ~370 ~63 ~3 stone
fill ~368 ~64 ~3 ~370 ~66 ~3 dirt
fill ~368 ~67 ~3 ~370 ~67 ~3 grass_block
fill ~371 ~60 ~3 ~375 ~64 ~3 stone
fill ~371 ~65 ~3 ~375 ~67 ~3 dirt
fill ~371 ~68 ~3 ~375 ~68 ~3 grass_block
fill ~376 ~60 ~3 ~383 ~65 ~3 stone
fill ~376 ~66 ~3 ~383 ~68 ~3 dirt
fill ~376 ~69 ~3 ~383 ~69 ~3 grass_block
fill ~368 ~60 ~4 ~370 ~63 ~4 stone
fill ~368 ~64 ~4 ~370 ~66 ~4 dirt
fill ~368 ~67 ~4 ~370 ~67 ~4 grass_block
fill ~371 ~60 ~4 ~377 ~64 ~4 stone
fill ~371 ~65 ~4 ~377 ~67 ~4 dirt
fill ~371 ~68 ~4 ~377 ~68 ~4 grass_block
fill ~378 ~60 ~4 ~383 ~65 ~4 stone
fill ~378 ~66 ~4 ~383 ~68 ~4 dirt
fill ~378 ~69 ~4 ~383 ~69 ~4 grass_block
fill ~368 ~60 ~5 ~371 ~63 ~5 stone
fill ~368 ~64 ~5 ~371 ~66 ~5 dirt
fill ~368 ~67 ~5 ~371 ~67 ~5 grass_block
fill ~372 ~60 ~5 ~378 ~64 ~5 stone
fill ~372 ~65 ~5 ~378 ~67 ~5 dirt
fill ~372 ~68 ~5 ~378 ~68 ~5 grass_block
fill ~379 ~60 ~5 ~383 ~65 ~5 stone
fill ~379 ~66 ~5 ~383 ~68 ~5 dirt
fill ~379 ~69 ~5 ~383 ~69 ~5 grass_block
fill ~368 ~60 ~6 ~368 ~62 ~6 stone
fill ~368 ~63 ~6 ~368 ~65 ~6 dirt
fill ~368 ~66 ~6 ~368 ~66 ~6 grass_block
fill ~369 ~60 ~6 ~371 ~63 ~6 stone
fill ~369 ~64 ~6 ~371 ~66 ~6 dirt
fill ~369 ~67 ~6 ~371 ~67 ~6 grass_block
fill ~372 ~60 ~6 ~380 ~64 ~6 stone
fill ~372 ~65 ~6 ~380 ~67 ~6 dirt
fill ~372 ~68 ~6 ~380 ~68 ~6 grass_block
fill ~381 ~60 ~6 ~383 ~65 ~6 stone
fill ~381 ~66 ~6 ~383 ~68 ~6 dirt
fill ~381 ~69 ~6 ~383 ~69 ~6 grass_block
fill ~368 ~60 ~7 ~369 ~62 ~7 stone
fill ~368 ~63 ~7 ~369 ~65 ~7 dirt
fill ~368 ~66 ~7 ~369 ~66 ~7 grass_block
fill ~370 ~60 ~7 ~372 ~63 ~7 stone
fill ~370 ~64 ~7 ~372 ~66 ~7 dirt
fill ~370 ~67 ~7 ~372 ~67 ~7 grass_block
fill ~373 ~60 ~7 ~376 ~64 ~7 stone
fill ~373 ~65 ~7 ~376 ~67 ~7 dirt
fill ~373 ~68 ~7 ~376 ~68 ~7 grass_block
fill ~377 ~60 ~7 ~377 ~63 ~7 stone
fill ~377 ~64 ~7 ~377 ~66 ~7 dirt
fill ~377 ~67 ~7 ~377 ~67 ~7 grass_block
fill ~378 ~60 ~7 ~382 ~64 ~7 stone
fill ~378 ~65 ~7 ~382 ~67 ~7 dirt
fill ~378 ~68 ~7 ~382 ~68 ~7 grass_block
fill ~383 ~60 ~7 ~383 ~65 ~7 stone
fill ~383 ~66 ~7 ~383 ~68 ~7 dirt
fill ~383 ~69 ~7 ~383 ~69 ~7 grass_block
fill ~368 ~60 ~8 ~370 ~62 ~8 stone
fill ~368 ~63 ~8 ~370 ~65 ~8 dirt
fill ~368 ~66 ~8 ~370 ~66 ~8 grass_block
fill ~371 ~60 ~8 ~373 ~63 ~8 stone
fill ~371 ~64 ~8 ~373 ~66 ~8 dirt
fill ~371 ~67 ~8 ~373 ~67 ~8 grass_block
fill ~374 ~60 ~8 ~376 ~64 ~8 stone
fill ~374 ~65 ~8 ~376 ~67 ~8 dirt
fill ~374 ~68 ~8 ~376 ~68 ~8 grass_block
fill ~377 ~60 ~8 ~378 ~63 ~8 stone
fill ~377 ~64 ~8 ~378 ~66 ~8 dirt
fill ~377 ~67 ~8 ~378 ~67 ~8 grass_block
fill ~379 ~60 ~8 ~383 ~64 ~8 stone
fill ~379 ~65 ~8 ~383 ~67 ~8 dirt
fill ~379 ~68 ~8 ~383 ~68 ~8 grass_block
fill ~368 ~60 ~9 ~368 ~63 ~9 stone
fill ~368 ~64 ~9 ~368 ~66 ~9 dirt
fill ~368 ~67 ~9 ~368 ~67 ~9 grass_block
fill ~369 ~60 ~9 ~370 ~62 ~9 stone
fill ~369 ~63 ~9 ~370 ~65 ~9 dirt
fill ~369 ~66 ~9 ~370 ~66 ~9 grass_block
fill ~371 ~60 ~9 ~374 ~63 ~9 stone
fill ~371 ~64 ~9 ~374 ~66 ~9 dirt
fill ~371 ~67 ~9 ~374 ~67 ~9 grass_block
fill ~375 ~60 ~9 ~375 ~64 ~9 stone
fill ~375 ~65 ~9 ~375 ~67 ~9 dirt
fill ~375 ~68 ~9 ~375 ~68 ~9 grass_block
fill ~376 ~60 ~9 ~380 ~63 ~9 stone
fill ~376 ~64 ~9 ~380 ~66 ~9 dirt
fill ~376 ~67 ~9 ~380 ~67 ~9 grass_block
fill ~381 ~60 ~9 ~383 ~64 ~9 stone
fill ~381 ~65 ~9 ~383 ~67 ~9 dirt
fill ~381 ~68 ~9 ~383 ~68 ~9 grass_block
fill ~368 ~60 ~10 ~369 ~63 ~10 stone
fill ~368 ~64 ~10 ~369 ~66 ~10 dirt
fill ~368 ~67 ~10 ~369 ~67 ~10 grass_block
fill ~370 ~60 ~10 ~371 ~62 ~10 stone
fill ~370 ~63 ~10 ~371 ~65 ~10 dirt
fill ~370 ~66 ~10 ~371 ~66 ~10 grass_block
fill ~372 ~60 ~10 ~381 ~63 ~10 stone
fill ~372 ~64 ~10 ~381 ~66 ~10 dirt
fill ~372 ~67 ~10 ~381 ~67 ~10 grass_block
fill ~382 ~60 ~10 ~383 ~64 ~10 stone
fill ~382 ~65 ~10 ~383 ~67 ~10 dirt
fill ~382 ~68 ~10 ~383 ~68 ~10 grass_block
fill ~368 ~60 ~11 ~370 ~63 ~11 stone
fill ~368 ~64 ~11 ~370 ~66 ~11 dirt
fill ~368 ~67 ~11 ~370 ~67 ~11 grass_block
fill ~371 ~60 ~11 ~372 ~62 ~11 stone
fill ~371 ~63 ~11 ~372 ~65 ~11 dirt
fill ~371 ~66 ~11 ~372 ~66 ~11 grass_block
fill ~373 ~60 ~11 ~383 ~63 ~11 stone
fill ~373 ~64 ~11 ~383 ~66 ~11 dirt
fill ~373 ~67 ~11 ~383 ~67 ~11 grass_block
fill ~368 ~60 ~12 ~371 ~63 ~12 stone
fill ~368 ~64 ~12 ~371 ~66 ~12 dirt
fill ~368 ~67 ~12 ~371 ~67 ~12 grass_block
fill ~372 ~60 ~12 ~373 ~62 ~12 stone
fill ~372 ~63 ~12 ~373 ~65 ~12 dirt
fill ~372 ~66 ~12 ~373 ~66 ~12 grass_block
fill ~374 ~60 ~12 ~377 ~63 ~12 stone
fill ~374 ~64 ~12 ~377 ~66 ~12 dirt
fill ~374 ~67 ~12 ~377 ~67 ~12 grass_block
fill ~378 ~60 ~12 ~378 ~62 ~12 stone
fill ~378 ~63 ~12 ~378 ~65 ~12 dirt
fill ~378 ~66 ~12 ~378 ~66 ~12 grass_block
fill ~379 ~60 ~12 ~383 ~63 ~12 stone
fill ~379 ~64 ~12 ~383 ~66 ~12 dirt
fill ~379 ~67 ~12 ~383 ~67 ~12 grass_block
fill ~368 ~60 ~13 ~372 ~63 ~13 stone
fill ~368 ~64 ~13 ~372 ~66 ~13 dirt
fill ~368 ~67 ~13 ~372 ~67 ~13 grass_block
fill ~373 ~60 ~13 ~374 ~62 ~13 stone
fill ~373 ~63 ~13 ~374 ~65 ~13 dirt
fill ~373 ~66 ~13 ~374 ~66 ~13 grass_block
fill ~375 ~60 ~13 ~377 ~63 ~13 stone
fill ~375 ~64 ~13 ~377 ~66 ~13 dirt
fill ~375 ~67 ~13 ~377 ~67 ~13 grass_block
fill ~378 ~60 ~13 ~379 ~62 ~13 stone
fill ~378 ~63 ~13 ~379 ~65 ~13 dirt
fill ~378 ~66 ~13 ~379 ~66 ~13 grass_block
fill ~380 ~60 ~13 ~383 ~63 ~13 stone
fill ~380 ~64 ~13 ~383 ~66 ~13 dirt
fill ~380 ~67 ~13 ~383 ~67 ~13 grass_block
fill ~368 ~60 ~14 ~369 ~62 ~14 stone
fill ~368 ~63 ~14 ~369 ~65 ~14 dirt
fill ~368 ~66 ~14 ~369 ~66 ~14 grass_block
fill ~370 ~60 ~14 ~372 ~63 ~14 stone
fill ~370 ~64 ~14 ~372 ~66 ~14 dirt
fill ~370 ~67 ~14 ~372 ~67 ~14 grass_block
fill ~373 ~60 ~14 ~375 ~62 ~14 stone
fill ~373 ~63 ~14 ~375 ~65 ~14 dirt
fill ~373 ~66 ~14 ~375 ~66 ~14 grass_block
fill ~376 ~60 ~14 ~376 ~63 ~14 stone
fill ~376 ~64 ~14 ~376 ~66 ~14 dirt
fill ~376 ~67 ~14 ~376 ~67 ~14 grass_block
fill ~377 ~60 ~14 ~379 ~62 ~14 stone
fill ~377 ~63 ~14 ~379 ~65 ~14 dirt
fill ~377 ~66 ~14 ~379 ~66 ~14 grass_block
fill ~380 ~60 ~14 ~383 ~63 ~14 stone
fill ~380 ~64 ~14 ~383 ~66 ~14 dirt
fill ~380 ~67 ~14 ~383 ~67 ~14 grass_block
fill ~368 ~60 ~15 ~379 ~62 ~15 stone
fill ~368 ~63 ~15 ~379 ~65 ~15 dirt
fill ~368 ~66 ~15 ~379 ~66 ~15 grass_block
fill ~380 ~60 ~15 ~382 ~63 ~15 stone
fill ~380 ~64 ~15 ~382 ~66 ~15 dirt
fill ~380 ~67 ~15 ~382 ~67 ~15 grass_block
fill ~383 ~60 ~15 ~383 ~62 ~15 stone
fill ~383 ~63 ~15 ~383 ~65 ~15 dirt
fill ~383 ~66 ~15 ~383 ~66 ~15 grass_block