fill ~96 ~60 ~96 ~97 ~66 ~96 stone
fill ~96 ~67 ~96 ~97 ~69 ~96 dirt
fill ~96 ~70 ~96 ~97 ~70 ~96 grass_block
fill ~98 ~60 ~96 ~101 ~65 ~96 stone
fill ~98 ~66 ~96 ~101 ~68 ~96 dirt
fill ~98 ~69 ~96 ~101 ~69 ~96 grass_block
fill ~102 ~60 ~96 ~104 ~64 ~96 stone
fill ~102 ~65 ~96 ~104 ~67 ~96 dirt
fill ~102 ~68 ~96 ~104 ~68 ~96 grass_block
fill ~105 ~60 ~96 ~111 ~63 ~96 stone
fill ~105 ~64 ~96 ~111 ~66 ~96 dirt
fill ~105 ~67 ~96 ~111 ~67 ~96 grass_block
fill ~96 ~60 ~97 ~97 ~66 ~97 stone
fill ~96 ~67 ~97 ~97 ~69 ~97 dirt
fill ~96 ~70 ~97 ~97 ~70 ~97 grass_block
fill ~98 ~60 ~97 ~101 ~65 ~97 stone
fill ~98 ~66 ~97 ~101 ~68 ~97 dirt
fill ~98 ~69 ~97 ~101 ~69 ~97 grass_block
fill ~102 ~60 ~97 ~104 ~64 ~97 stone
fill ~102 ~65 ~97 ~104 ~67 ~97 dirt
fill ~102 ~68 ~97 ~104 ~68 ~97 grass_block
fill ~105 ~60 ~97 ~108 ~63 ~97 stone
fill ~105 ~64 ~97 ~108 ~66 ~97 dirt
fill ~105 ~67 ~97 ~108 ~67 ~97 grass_block
fill ~109 ~60 ~97 ~109 ~64 ~97 stone
fill ~109 ~65 ~97 ~109 ~67 ~97 dirt
fill ~109 ~68 ~97 ~109 ~68 ~97 grass_block
fill ~110 ~60 ~97 ~111 ~63 ~97 stone
fill ~110 ~64 ~97 ~111 ~66 ~97 dirt
fill ~110 ~67 ~97 ~111 ~67 ~97 grass_block
fill ~96 ~60 ~98 ~96 ~66 ~98 stone
fill ~96 ~67 ~98 ~96 ~69 ~98 dirt
fill ~96 ~70 ~98 ~96 ~70 ~98 grass_block
fill ~97 ~60 ~98 ~99 ~65 ~98 stone
fill ~97 ~66 ~98 ~99 ~68 ~98 dirt
fill ~97 ~69 ~98 ~99 ~69 ~98 grass_block
fill ~100 ~60 ~98 ~103 ~64 ~98 stone
fill ~100 ~65 ~98 ~103 ~67 ~98 dirt
fill ~100 ~68 ~98 ~103 ~68 ~98 grass_block
fill ~104 ~60 ~98 ~107 ~63 ~98 stone
fill ~104 ~64 ~98 ~107 ~66 ~98 dirt
fill ~104 ~67 ~98 ~107 ~67 ~98 grass_block
fill ~108 ~60 ~98 ~109 ~64 ~98 stone
fill ~108 ~65 ~98 ~109 ~67 ~98 dirt
fill ~108 ~68 ~98 ~109 ~68 ~98 grass_block
fill ~110 ~60 ~98 ~111 ~63 ~98 stone
fill ~110 ~64 ~98 ~111 ~66 ~98 dirt
fill ~110 ~67 ~98 ~111 ~67 ~98 grass_block
fill ~96 ~60 ~99 ~97 ~65 ~99 stone
fill ~96 ~66 ~99 ~97 ~68 ~99 dirt
fill ~96 ~69 ~99 ~97 ~69 ~99 grass_block
fill ~98 ~60 ~99 ~102 ~64 ~99 stone
fill ~98 ~65 ~99 ~102 ~67 ~99 dirt
fill ~98 ~68 ~99 ~102 ~68 ~99 grass_block
fill ~103 ~60 ~99 ~106 ~63 ~99 stone
fill ~103 ~64 ~99 ~106 ~66 ~99 dirt
fill ~103 ~67 ~99 ~106 ~67 ~99 grass_block
fill ~107 ~60 ~99 ~109 ~64 ~99 stone
fill ~107 ~65 ~99 ~109 ~67 ~99 dirt
fill ~107 ~68 ~99 ~109 ~68 ~99 grass_block
fill ~110 ~60 ~99 ~111 ~63 ~99 stone
fill ~110 ~64 ~99 ~111 ~66 ~99 dirt
fill ~110 ~67 ~99 ~111 ~67 ~99 grass_block
fill ~96 ~60 ~100 ~97 ~65 ~100 stone
fill ~96 ~66 ~100 ~97 ~68 ~100 dirt
fill ~96 ~69 ~100 ~97 ~69 ~100 grass_block
fill ~98 ~60 ~100 ~108 ~64 ~100 stone
fill ~98 ~65 ~100 ~108 ~67 ~100 dirt
fill ~98 ~68 ~100 ~108 ~68 ~100 grass_block
fill ~109 ~60 ~100 ~111 ~63 ~100 stone
fill ~109 ~64 ~100 ~111 ~66 ~100 dirt
fill ~109 ~67 ~100 ~111 ~67 ~100 grass_block
fill ~96 ~60 ~101 ~98 ~65 ~101 stone
fill ~96 ~66 ~101 ~98 ~68 ~101 dirt
fill ~96 ~69 ~101 ~98 ~69 ~101 grass_block
fill ~99 ~60 ~101 ~104 ~64 ~101 stone
fill ~99 ~65 ~101 ~104 ~67 ~101 dirt
fill ~99 ~68 ~101 ~104 ~68 ~101 grass_block
fill ~105 ~60 ~101 ~107 ~65 ~101 stone
fill ~105 ~66 ~101 ~107 ~68 ~101 dirt
fill ~105 ~69 ~101 ~107 ~69 ~101 grass_block
fill ~108 ~60 ~101 ~109 ~64 ~101 stone
fill ~108 ~65 ~101 ~109 ~67 ~101 dirt
fill ~108 ~68 ~101 ~109 ~68 ~101 grass_block
fill ~110 ~60 ~101 ~110 ~63 ~101 stone
fill ~110 ~64 ~101 ~110 ~66 ~101 dirt
fill ~110 ~67 ~101 ~110 ~67 ~101 grass_block
fill ~111 ~60 ~101 ~111 ~64 ~101 stone
fill ~111 ~65 ~101 ~111 ~67 ~101 dirt
fill ~111 ~68 ~101 ~111 ~68 ~101 grass_block
fill ~96 ~60 ~102 ~106 ~65 ~102 stone
fill ~96 ~66 ~102 ~106 ~68 ~102 dirt
fill ~96 ~69 ~102 ~106 ~69 ~102 grass_block
fill ~107 ~60 ~102 ~110 ~64 ~102 stone
fill ~107 ~65 ~102 ~110 ~67 ~102 dirt
fill ~107 ~68 ~102 ~110 ~68 ~102 grass_block
fill ~111 ~60 ~102 ~111 ~65 ~102 stone
fill ~111 ~66 ~102 ~111 ~68 ~102 dirt
fill ~111 ~69 ~102 ~111 ~69 ~102 grass_block
fill ~96 ~60 ~103 ~102 ~65 ~103 stone
fill ~96 ~66 ~103 ~102 ~68 ~103 dirt
fill ~96 ~69 ~103 ~102 ~69 ~103 grass_block
fill ~103 ~60 ~103 ~104 ~66 ~103 stone
fill ~103 ~67 ~103 ~104 ~69 ~103 dirt
fill ~103 ~70 ~103 ~104 ~70 ~103 grass_block
fill ~105 ~60 ~103 ~107 ~65 ~103 stone
fill ~105 ~66 ~103 ~107 ~68 ~103 dirt
fill ~105 ~69 ~103 ~107 ~69 ~103 grass_block
fill ~108 ~60 ~103 ~110 ~64 ~103 stone
fill ~108 ~65 ~103 ~110 ~67 ~103 dirt
fill ~108 ~68 ~103 ~110 ~68 ~103 grass_block
fill ~111 ~60 ~103 ~111 ~65 ~103 stone
fill ~111 ~66 ~103 ~111 ~68 ~103 dirt
fill ~111 ~69 ~103 ~111 ~69 ~103 grass_block
fill ~96 ~60 ~104 ~101 ~66 ~104 stone
fill ~96 ~67 ~104 ~101 ~69 ~104 dirt
fill ~96 ~70 ~104 ~101 ~70 ~104 grass_block
fill ~102 ~60 ~104 ~104 ~67 ~104 stone
fill ~102 ~68 ~104 ~104 ~70 ~104 dirt
fill ~102 ~71 ~104 ~104 ~71 ~104 grass_block
fill ~105 ~60 ~104 ~105 ~66 ~104 stone
fill ~105 ~67 ~104 ~105 ~69 ~104 dirt
fill ~105 ~70 ~104 ~105 ~70 ~104 grass_block
fill ~106 ~60 ~104 ~107 ~65 ~104 stone
fill ~106 ~66 ~104 ~107 ~68 ~104 dirt
fill ~106 ~69 ~104 ~107 ~69 ~104 grass_block
fill ~108 ~60 ~104 ~109 ~64 ~104 stone
fill ~108 ~65 ~104 ~109 ~67 ~104 dirt
fill ~108 ~68 ~104 ~109 ~68 ~104 grass_block
fill ~110 ~60 ~104 ~111 ~65 ~104 stone
fill ~110 ~66 ~104 ~111 ~68 ~104 dirt
fill ~110 ~69 ~104 ~111 ~69 ~104 grass_block
fill ~96 ~60 ~105 ~104 ~67 ~105 stone
fill ~96 ~68 ~105 ~104 ~70 ~105 dirt
fill ~96 ~71 ~105 ~104 ~71 ~105 grass_block
fill ~105 ~60 ~105 ~106 ~66 ~105 stone
fill ~105 ~67 ~105 ~106 ~69 ~105 dirt
fill ~105 ~70 ~105 ~106 ~70 ~105 grass_block
fill ~107 ~60 ~105 ~111 ~65 ~105 stone
fill ~107 ~66 ~105 ~111 ~68 ~105 dirt
fill ~107 ~69 ~105 ~111 ~69 ~105 grass_block
fill ~96 ~60 ~106 ~103 ~68 ~106 stone
fill ~96 ~69 ~106 ~103 ~71 ~106 dirt
fill ~96 ~72 ~106 ~103 ~72 ~106 grass_block
fill ~104 ~60 ~106 ~105 ~67 ~106 stone
fill ~104 ~68 ~106 ~105 ~70 ~106 dirt
fill ~104 ~71 ~106 ~105 ~71 ~106 grass_block
fill ~106 ~60 ~106 ~107 ~66 ~106 stone
fill ~106 ~67 ~106 ~107 ~69 ~106 dirt
fill ~106 ~70 ~106 ~107 ~70 ~106 grass_block
fill ~108 ~60 ~106 ~111 ~65 ~106 stone
fill ~108 ~66 ~106 ~111 ~68 ~106 dirt
fill ~108 ~69 ~106 ~111 ~69 ~106 grass_block
fill ~96 ~60 ~107 ~104 ~68 ~107 stone
fill ~96 ~69 ~107 ~104 ~71 ~107 dirt
fill ~96 ~72 ~107 ~104 ~72 ~107 grass_block
fill ~105 ~60 ~107 ~106 ~67 ~107 stone
fill ~105 ~68 ~107 ~106 ~70 ~107 dirt
fill ~105 ~71 ~107 ~106 ~71 ~107 grass_block
fill ~107 ~60 ~107 ~111 ~66 ~107 stone
fill ~107 ~67 ~107 ~111 ~69 ~107 dirt
fill ~107 ~70 ~107 ~111 ~70 ~107 grass_block
fill ~96 ~60 ~108 ~105 ~68 ~108 stone
fill ~96 ~69 ~108 ~105 ~71 ~108 dirt
fill ~96 ~72 ~108 ~105 ~72 ~108 grass_block
fill ~106 ~60 ~108 ~111 ~67 ~108 stone
fill ~106 ~68 ~108 ~111 ~70 ~108 dirt
fill ~106 ~71 ~108 ~111 ~71 ~108 grass_block
fill ~96 ~60 ~109 ~97 ~68 ~109 stone
fill ~96 ~69 ~109 ~97 ~71 ~109 dirt
fill ~96 ~72 ~109 ~97 ~72 ~109 grass_block
fill ~98 ~60 ~109 ~100 ~69 ~109 stone
fill ~98 ~70 ~109 ~100 ~72 ~109 dirt
fill ~98 ~73 ~109 ~100 ~73 ~109 grass_block
fill ~101 ~60 ~109 ~106 ~68 ~109 stone
fill ~101 ~69 ~109 ~106 ~71 ~109 dirt
fill ~101 ~72 ~109 ~106 ~72 ~109 grass_block
fill ~107 ~60 ~109 ~111 ~67 ~109 stone
fill ~107 ~68 ~109 ~111 ~70 ~109 dirt
fill ~107 ~71 ~109 ~111 ~71 ~109 grass_block
fill ~96 ~60 ~110 ~97 ~68 ~110 stone
fill ~96 ~69 ~110 ~97 ~71 ~110 dirt
fill ~96 ~72 ~110 ~97 ~72 ~110 grass_block
fill ~98 ~60 ~110 ~101 ~69 ~110 stone
fill ~98 ~70 ~110 ~101 ~72 ~110 dirt
fill ~98 ~73 ~110 ~101 ~73 ~110 grass_block
fill ~102 ~60 ~110 ~108 ~68 ~110 stone
fill ~102 ~69 ~110 ~108 ~71 ~110 dirt
fill ~102 ~72 ~110 ~108 ~72 ~110 grass_block
fill ~109 ~60 ~110 ~109 ~67 ~110 stone
fill ~109 ~68 ~110 ~109 ~70 ~110 dirt
fill ~109 ~71 ~110 ~109 ~71 ~110 grass_block
fill ~110 ~60 ~110 ~110 ~68 ~110 stone
fill ~110 ~69 ~110 ~110 ~71 ~110 dirt
fill ~110 ~72 ~110 ~110 ~72 ~110 grass_block
fill ~111 ~60 ~110 ~111 ~67 ~110 stone
fill ~111 ~68 ~110 ~111 ~70 ~110 dirt
fill ~111 ~71 ~110 ~111 ~71 ~110 grass_block
fill ~96 ~60 ~111 ~97 ~68 ~111 stone
fill ~96 ~69 ~111 ~97 ~71 ~111 dirt
fill ~96 ~72 ~111 ~97 ~72 ~111 grass_block
fill ~98 ~60 ~111 ~101 ~69 ~111 stone
fill ~98 ~70 ~111 ~101 ~72 ~111 dirt
fill ~98 ~73 ~111 ~101 ~73 ~111 grass_block
fill ~102 ~60 ~111 ~107 ~68 ~111 stone
fill ~102 ~69 ~111 ~107 ~71 ~111 dirt
fill ~102 ~72 ~111 ~107 ~72 ~111 grass_block
fill ~108 ~60 ~111 ~110 ~67 ~111 stone
fill ~108 ~68 ~111 ~110 ~70 ~111 dirt
fill ~108 ~71 ~111 ~110 ~71 ~111 grass_block
fill ~111 ~60 ~111 ~111 ~68 ~111 stone
fill ~111 ~69 ~111 ~111 ~71 ~111 dirt
fill ~111 ~72 ~111 ~111 ~72 ~111 grass_block