fill ~240 ~60 ~64 ~246 ~63 ~64 stone
fill ~240 ~64 ~64 ~246 ~66 ~64 dirt
fill ~240 ~67 ~64 ~246 ~67 ~64 grass_block
fill ~247 ~60 ~64 ~249 ~62 ~64 stone
fill ~247 ~63 ~64 ~249 ~65 ~64 dirt
fill ~247 ~66 ~64 ~249 ~66 ~64 grass_block
fill ~250 ~60 ~64 ~255 ~63 ~64 stone
fill ~250 ~64 ~64 ~255 ~66 ~64 dirt
fill ~250 ~67 ~64 ~255 ~67 ~64 grass_block
fill ~240 ~60 ~65 ~241 ~63 ~65 stone
fill ~240 ~64 ~65 ~241 ~66 ~65 dirt
fill ~240 ~67 ~65 ~241 ~67 ~65 grass_block
fill ~242 ~60 ~65 ~244 ~64 ~65 stone
fill ~242 ~65 ~65 ~244 ~67 ~65 dirt
fill ~242 ~68 ~65 ~244 ~68 ~65 grass_block
fill ~245 ~60 ~65 ~249 ~63 ~65 stone
fill ~245 ~64 ~65 ~249 ~66 ~65 dirt
fill ~245 ~67 ~65 ~249 ~67 ~65 grass_block
fill ~250 ~60 ~65 ~250 ~62 ~65 stone
fill ~250 ~63 ~65 ~250 ~65 ~65 dirt
fill ~250 ~66 ~65 ~250 ~66 ~65 grass_block
fill ~251 ~60 ~65 ~255 ~63 ~65 stone
fill ~251 ~64 ~65 ~255 ~66 ~65 dirt
fill ~251 ~67 ~65 ~255 ~67 ~65 grass_block
fill ~240 ~60 ~66 ~240 ~63 ~66 stone
fill ~240 ~64 ~66 ~240 ~66 ~66 dirt
fill ~240 ~67 ~66 ~240 ~67 ~66 grass_block
fill ~241 ~60 ~66 ~245 ~64 ~66 stone
fill ~241 ~65 ~66 ~245 ~67 ~66 dirt
fill ~241 ~68 ~66 ~245 ~68 ~66 grass_block
fill ~246 ~60 ~66 ~255 ~63 ~66 stone
fill ~246 ~64 ~66 ~255 ~66 ~66 dirt
fill ~246 ~67 ~66 ~255 ~67 ~66 grass_block
fill ~240 ~60 ~67 ~240 ~63 ~67 stone
fill ~240 ~64 ~67 ~240 ~66 ~67 dirt
fill ~240 ~67 ~67 ~240 ~67 ~67 grass_block
fill ~241 ~60 ~67 ~247 ~64 ~67 stone
fill ~241 ~65 ~67 ~247 ~67 ~67 dirt
fill ~241 ~68 ~67 ~247 ~68 ~67 grass_block
fill ~248 ~60 ~67 ~255 ~63 ~67 stone
fill ~248 ~64 ~67 ~255 ~66 ~67 dirt
fill ~248 ~67 ~67 ~255 ~67 ~67 grass_block
fill ~240 ~60 ~68 ~240 ~63 ~68 stone
fill ~240 ~64 ~68 ~240 ~66 ~68 dirt
fill ~240 ~67 ~68 ~240 ~67 ~68 grass_block
fill ~241 ~60 ~68 ~248 ~64 ~68 stone
fill ~241 ~65 ~68 ~248 ~67 ~68 dirt
fill ~241 ~68 ~68 ~248 ~68 ~68 grass_block
fill ~249 ~60 ~68 ~255 ~63 ~68 stone
fill ~249 ~64 ~68 ~255 ~66 ~68 dirt
fill ~249 ~67 ~68 ~255 ~67 ~68 grass_block
fill ~240 ~60 ~69 ~249 ~64 ~69 stone
fill ~240 ~65 ~69 ~249 ~67 ~69 dirt
fill ~240 ~68 ~69 ~249 ~68 ~69 grass_block
fill ~250 ~60 ~69 ~255 ~63 ~69 stone
fill ~250 ~64 ~69 ~255 ~66 ~69 dirt
fill ~250 ~67 ~69 ~255 ~67 ~69 grass_block
fill ~240 ~60 ~70 ~241 ~64 ~70 stone
fill ~240 ~65 ~70 ~241 ~67 ~70 dirt
fill ~240 ~68 ~70 ~241 ~68 ~70 grass_block
fill ~242 ~60 ~70 ~242 ~65 ~70 stone
fill ~242 ~66 ~70 ~242 ~68 ~70 dirt
fill ~242 ~69 ~70 ~242 ~69 ~70 grass_block
fill ~243 ~60 ~70 ~249 ~64 ~70 stone
fill ~243 ~65 ~70 ~249 ~67 ~70 dirt
fill ~243 ~68 ~70 ~249 ~68 ~70 grass_block
fill ~250 ~60 ~70 ~255 ~63 ~70 stone
fill ~250 ~64 ~70 ~255 ~66 ~70 dirt
fill ~250 ~67 ~70 ~255 ~67 ~70 grass_block
fill ~240 ~60 ~71 ~240 ~64 ~71 stone
fill ~240 ~65 ~71 ~240 ~67 ~71 dirt
fill ~240 ~68 ~71 ~240 ~68 ~71 grass_block
fill ~241 ~60 ~71 ~243 ~65 ~71 stone
fill ~241 ~66 ~71 ~243 ~68 ~71 dirt
fill ~241 ~69 ~71 ~243 ~69 ~71 grass_block
fill ~244 ~60 ~71 ~249 ~64 ~71 stone
fill ~244 ~65 ~71 ~249 ~67 ~71 dirt
fill ~244 ~68 ~71 ~249 ~68 ~71 grass_block
fill ~250 ~60 ~71 ~250 ~63 ~71 stone
fill ~250 ~64 ~71 ~250 ~66 ~71 dirt
fill ~250 ~67 ~71 ~250 ~67 ~71 grass_block
fill ~251 ~60 ~71 ~251 ~64 ~71 stone
fill ~251 ~65 ~71 ~251 ~67 ~71 dirt
fill ~251 ~68 ~71 ~251 ~68 ~71 grass_block
fill ~252 ~60 ~71 ~255 ~63 ~71 stone
fill ~252 ~64 ~71 ~255 ~66 ~71 dirt
fill ~252 ~67 ~71 ~255 ~67 ~71 grass_block
fill ~240 ~60 ~72 ~243 ~65 ~72 stone
fill ~240 ~66 ~72 ~243 ~68 ~72 dirt
fill ~240 ~69 ~72 ~243 ~69 ~72 grass_block
fill ~244 ~60 ~72 ~253 ~64 ~72 stone
fill ~244 ~65 ~72 ~253 ~67 ~72 dirt
fill ~244 ~68 ~72 ~253 ~68 ~72 grass_block
fill ~254 ~60 ~72 ~255 ~63 ~72 stone
fill ~254 ~64 ~72 ~255 ~66 ~72 dirt
fill ~254 ~67 ~72 ~255 ~67 ~72 grass_block
fill ~240 ~60 ~73 ~243 ~65 ~73 stone
fill ~240 ~66 ~73 ~243 ~68 ~73 dirt
fill ~240 ~69 ~73 ~243 ~69 ~73 grass_block
fill ~244 ~60 ~73 ~253 ~64 ~73 stone
fill ~244 ~65 ~73 ~253 ~67 ~73 dirt
fill ~244 ~68 ~73 ~253 ~68 ~73 grass_block
fill ~254 ~60 ~73 ~255 ~63 ~73 stone
fill ~254 ~64 ~73 ~255 ~66 ~73 dirt
fill ~254 ~67 ~73 ~255 ~67 ~73 grass_block
fill ~240 ~60 ~74 ~246 ~65 ~74 stone
fill ~240 ~66 ~74 ~246 ~68 ~74 dirt
fill ~240 ~69 ~74 ~246 ~69 ~74 grass_block
fill ~247 ~60 ~74 ~253 ~64 ~74 stone
fill ~247 ~65 ~74 ~253 ~67 ~74 dirt
fill ~247 ~68 ~74 ~253 ~68 ~74 grass_block
fill ~254 ~60 ~74 ~255 ~63 ~74 stone
fill ~254 ~64 ~74 ~255 ~66 ~74 dirt
fill ~254 ~67 ~74 ~255 ~67 ~74 grass_block
fill ~240 ~60 ~75 ~245 ~65 ~75 stone
fill ~240 ~66 ~75 ~245 ~68 ~75 dirt
fill ~240 ~69 ~75 ~245 ~69 ~75 grass_block
fill ~246 ~60 ~75 ~253 ~64 ~75 stone
fill ~246 ~65 ~75 ~253 ~67 ~75 dirt
fill ~246 ~68 ~75 ~253 ~68 ~75 grass_block
fill ~254 ~60 ~75 ~255 ~63 ~75 stone
fill ~254 ~64 ~75 ~255 ~66 ~75 dirt
fill ~254 ~67 ~75 ~255 ~67 ~75 grass_block
fill ~240 ~60 ~76 ~240 ~66 ~76 stone
fill ~240 ~67 ~76 ~240 ~69 ~76 dirt
fill ~240 ~70 ~76 ~240 ~70 ~76 grass_block
fill ~241 ~60 ~76 ~248 ~65 ~76 stone
fill ~241 ~66 ~76 ~248 ~68 ~76 dirt
fill ~241 ~69 ~76 ~248 ~69 ~76 grass_block
fill ~249 ~60 ~76 ~253 ~64 ~76 stone
fill ~249 ~65 ~76 ~253 ~67 ~76 dirt
fill ~249 ~68 ~76 ~253 ~68 ~76 grass_block
fill ~254 ~60 ~76 ~255 ~63 ~76 stone
fill ~254 ~64 ~76 ~255 ~66 ~76 dirt
fill ~254 ~67 ~76 ~255 ~67 ~76 grass_block
fill ~240 ~60 ~77 ~240 ~66 ~77 stone
fill ~240 ~67 ~77 ~240 ~69 ~77 dirt
fill ~240 ~70 ~77 ~240 ~70 ~77 grass_block
fill ~241 ~60 ~77 ~249 ~65 ~77 stone
fill ~241 ~66 ~77 ~249 ~68 ~77 dirt
fill ~241 ~69 ~77 ~249 ~69 ~77 grass_block
fill ~250 ~60 ~77 ~252 ~64 ~77 stone
fill ~250 ~65 ~77 ~252 ~67 ~77 dirt
fill ~250 ~68 ~77 ~252 ~68 ~77 grass_block
fill ~253 ~60 ~77 ~255 ~63 ~77 stone
fill ~253 ~64 ~77 ~255 ~66 ~77 dirt
fill ~253 ~67 ~77 ~255 ~67 ~77 grass_block
fill ~240 ~60 ~78 ~242 ~66 ~78 stone
fill ~240 ~67 ~78 ~242 ~69 ~78 dirt
fill ~240 ~70 ~78 ~242 ~70 ~78 grass_block
fill ~243 ~60 ~78 ~249 ~65 ~78 stone
fill ~243 ~66 ~78 ~249 ~68 ~78 dirt
fill ~243 ~69 ~78 ~249 ~69 ~78 grass_block
fill ~250 ~60 ~78 ~253 ~64 ~78 stone
fill ~250 ~65 ~78 ~253 ~67 ~78 dirt
fill ~250 ~68 ~78 ~253 ~68 ~78 grass_block
fill ~254 ~60 ~78 ~255 ~63 ~78 stone
fill ~254 ~64 ~78 ~255 ~66 ~78 dirt
fill ~254 ~67 ~78 ~255 ~67 ~78 grass_block
fill ~240 ~60 ~79 ~243 ~66 ~79 stone
fill ~240 ~67 ~79 ~243 ~69 ~79 dirt
fill ~240 ~70 ~79 ~243 ~70 ~79 grass_block
fill ~244 ~60 ~79 ~249 ~65 ~79 stone
fill ~244 ~66 ~79 ~249 ~68 ~79 dirt
fill ~244 ~69 ~79 ~249 ~69 ~79 grass_block
fill ~250 ~60 ~79 ~255 ~64 ~79 stone
fill ~250 ~65 ~79 ~255 ~67 ~79 dirt
fill ~250 ~68 ~79 ~255 ~68 ~79 grass_block