fill ~64 ~60 ~128 ~67 ~64 ~128 stone
fill ~64 ~65 ~128 ~67 ~67 ~128 dirt
fill ~64 ~68 ~128 ~67 ~68 ~128 grass_block
fill ~68 ~60 ~128 ~79 ~63 ~128 stone
fill ~68 ~64 ~128 ~79 ~66 ~128 dirt
fill ~68 ~67 ~128 ~79 ~67 ~128 grass_block
fill ~64 ~60 ~129 ~68 ~64 ~129 stone
fill ~64 ~65 ~129 ~68 ~67 ~129 dirt
fill ~64 ~68 ~129 ~68 ~68 ~129 grass_block
fill ~69 ~60 ~129 ~79 ~63 ~129 stone
fill ~69 ~64 ~129 ~79 ~66 ~129 dirt
fill ~69 ~67 ~129 ~79 ~67 ~129 grass_block
fill ~64 ~60 ~130 ~79 ~63 ~130 stone
fill ~64 ~64 ~130 ~79 ~66 ~130 dirt
fill ~64 ~67 ~130 ~79 ~67 ~130 grass_block
fill ~64 ~60 ~131 ~79 ~63 ~131 stone
fill ~64 ~64 ~131 ~79 ~66 ~131 dirt
fill ~64 ~67 ~131 ~79 ~67 ~131 grass_block
fill ~64 ~60 ~132 ~79 ~63 ~132 stone
fill ~64 ~64 ~132 ~79 ~66 ~132 dirt
fill ~64 ~67 ~132 ~79 ~67 ~132 grass_block
fill ~64 ~60 ~133 ~69 ~64 ~133 stone
fill ~64 ~65 ~133 ~69 ~67 ~133 dirt
fill ~64 ~68 ~133 ~69 ~68 ~133 grass_block
fill ~70 ~60 ~133 ~79 ~63 ~133 stone
fill ~70 ~64 ~133 ~79 ~66 ~133 dirt
fill ~70 ~67 ~133 ~79 ~67 ~133 grass_block
fill ~64 ~60 ~134 ~67 ~65 ~134 stone
fill ~64 ~66 ~134 ~67 ~68 ~134 dirt
fill ~64 ~69 ~134 ~67 ~69 ~134 grass_block
fill ~68 ~60 ~134 ~75 ~64 ~134 stone
fill ~68 ~65 ~134 ~75 ~67 ~134 dirt
fill ~68 ~68 ~134 ~75 ~68 ~134 grass_block
fill ~76 ~60 ~134 ~79 ~63 ~134 stone
fill ~76 ~64 ~134 ~79 ~66 ~134 dirt
fill ~76 ~67 ~134 ~79 ~67 ~134 grass_block
fill ~64 ~60 ~135 ~65 ~66 ~135 stone
fill ~64 ~67 ~135 ~65 ~69 ~135 dirt
fill ~64 ~70 ~135 ~65 ~70 ~135 grass_block
fill ~66 ~60 ~135 ~74 ~65 ~135 stone
fill ~66 ~66 ~135 ~74 ~68 ~135 dirt
fill ~66 ~69 ~135 ~74 ~69 ~135 grass_block
fill ~75 ~60 ~135 ~79 ~64 ~135 stone
fill ~75 ~65 ~135 ~79 ~67 ~135 dirt
fill ~75 ~68 ~135 ~79 ~68 ~135 grass_block
fill ~64 ~60 ~136 ~65 ~67 ~136 stone
fill ~64 ~68 ~136 ~65 ~70 ~136 dirt
fill ~64 ~71 ~136 ~65 ~71 ~136 grass_block
fill ~66 ~60 ~136 ~72 ~66 ~136 stone
fill ~66 ~67 ~136 ~72 ~69 ~136 dirt
fill ~66 ~70 ~136 ~72 ~70 ~136 grass_block
fill ~73 ~60 ~136 ~76 ~65 ~136 stone
fill ~73 ~66 ~136 ~76 ~68 ~136 dirt
fill ~73 ~69 ~136 ~76 ~69 ~136 grass_block
fill ~77 ~60 ~136 ~79 ~64 ~136 stone
fill ~77 ~65 ~136 ~79 ~67 ~136 dirt
fill ~77 ~68 ~136 ~79 ~68 ~136 grass_block
fill ~64 ~60 ~137 ~68 ~67 ~137 stone
fill ~64 ~68 ~137 ~68 ~70 ~137 dirt
fill ~64 ~71 ~137 ~68 ~71 ~137 grass_block
fill ~69 ~60 ~137 ~72 ~66 ~137 stone
fill ~69 ~67 ~137 ~72 ~69 ~137 dirt
fill ~69 ~70 ~137 ~72 ~70 ~137 grass_block
fill ~73 ~60 ~137 ~76 ~65 ~137 stone
fill ~73 ~66 ~137 ~76 ~68 ~137 dirt
fill ~73 ~69 ~137 ~76 ~69 ~137 grass_block
fill ~77 ~60 ~137 ~79 ~64 ~137 stone
fill ~77 ~65 ~137 ~79 ~67 ~137 dirt
fill ~77 ~68 ~137 ~79 ~68 ~137 grass_block
fill ~64 ~60 ~138 ~66 ~67 ~138 stone
fill ~64 ~68 ~138 ~66 ~70 ~138 dirt
fill ~64 ~71 ~138 ~66 ~71 ~138 grass_block
fill ~67 ~60 ~138 ~72 ~66 ~138 stone
fill ~67 ~67 ~138 ~72 ~69 ~138 dirt
fill ~67 ~70 ~138 ~72 ~70 ~138 grass_block
fill ~73 ~60 ~138 ~76 ~65 ~138 stone
fill ~73 ~66 ~138 ~76 ~68 ~138 dirt
fill ~73 ~69 ~138 ~76 ~69 ~138 grass_block
fill ~77 ~60 ~138 ~79 ~64 ~138 stone
fill ~77 ~65 ~138 ~79 ~67 ~138 dirt
fill ~77 ~68 ~138 ~79 ~68 ~138 grass_block
fill ~64 ~60 ~139 ~67 ~66 ~139 stone
fill ~64 ~67 ~139 ~67 ~69 ~139 dirt
fill ~64 ~70 ~139 ~67 ~70 ~139 grass_block
fill ~68 ~60 ~139 ~76 ~65 ~139 stone
fill ~68 ~66 ~139 ~76 ~68 ~139 dirt
fill ~68 ~69 ~139 ~76 ~69 ~139 grass_block
fill ~77 ~60 ~139 ~79 ~64 ~139 stone
fill ~77 ~65 ~139 ~79 ~67 ~139 dirt
fill ~77 ~68 ~139 ~79 ~68 ~139 grass_block
fill ~64 ~60 ~140 ~65 ~66 ~140 stone
fill ~64 ~67 ~140 ~65 ~69 ~140 dirt
fill ~64 ~70 ~140 ~65 ~70 ~140 grass_block
fill ~66 ~60 ~140 ~68 ~65 ~140 stone
fill ~66 ~66 ~140 ~68 ~68 ~140 dirt
fill ~66 ~69 ~140 ~68 ~69 ~140 grass_block
fill ~69 ~60 ~140 ~73 ~64 ~140 stone
fill ~69 ~65 ~140 ~73 ~67 ~140 dirt
fill ~69 ~68 ~140 ~73 ~68 ~140 grass_block
fill ~74 ~60 ~140 ~77 ~65 ~140 stone
fill ~74 ~66 ~140 ~77 ~68 ~140 dirt
fill ~74 ~69 ~140 ~77 ~69 ~140 grass_block
fill ~78 ~60 ~140 ~79 ~64 ~140 stone
fill ~78 ~65 ~140 ~79 ~67 ~140 dirt
fill ~78 ~68 ~140 ~79 ~68 ~140 grass_block
fill ~64 ~60 ~141 ~66 ~65 ~141 stone
fill ~64 ~66 ~141 ~66 ~68 ~141 dirt
fill ~64 ~69 ~141 ~66 ~69 ~141 grass_block
fill ~67 ~60 ~141 ~68 ~64 ~141 stone
fill ~67 ~65 ~141 ~68 ~67 ~141 dirt
fill ~67 ~68 ~141 ~68 ~68 ~141 grass_block
fill ~69 ~60 ~141 ~69 ~65 ~141 stone
fill ~69 ~66 ~141 ~69 ~68 ~141 dirt
fill ~69 ~69 ~141 ~69 ~69 ~141 grass_block
fill ~70 ~60 ~141 ~79 ~64 ~141 stone
fill ~70 ~65 ~141 ~79 ~67 ~141 dirt
fill ~70 ~68 ~141 ~79 ~68 ~141 grass_block
fill ~64 ~60 ~142 ~72 ~65 ~142 stone
fill ~64 ~66 ~142 ~72 ~68 ~142 dirt
fill ~64 ~69 ~142 ~72 ~69 ~142 grass_block
fill ~73 ~60 ~142 ~79 ~64 ~142 stone
fill ~73 ~65 ~142 ~79 ~67 ~142 dirt
fill ~73 ~68 ~142 ~79 ~68 ~142 grass_block
fill ~64 ~60 ~143 ~67 ~65 ~143 stone
fill ~64 ~66 ~143 ~67 ~68 ~143 dirt
fill ~64 ~69 ~143 ~67 ~69 ~143 grass_block
fill ~68 ~60 ~143 ~70 ~66 ~143 stone
fill ~68 ~67 ~143 ~70 ~69 ~143 dirt
fill ~68 ~70 ~143 ~70 ~70 ~143 grass_block
fill ~71 ~60 ~143 ~73 ~65 ~143 stone
fill ~71 ~66 ~143 ~73 ~68 ~143 dirt
fill ~71 ~69 ~143 ~73 ~69 ~143 grass_block
fill ~74 ~60 ~143 ~79 ~64 ~143 stone
fill ~74 ~65 ~143 ~79 ~67 ~143 dirt
fill ~74 ~68 ~143 ~79 ~68 ~143 grass_block