fill ~352 ~60 ~80 ~360 ~64 ~80 stone
fill ~352 ~65 ~80 ~360 ~67 ~80 dirt
fill ~352 ~68 ~80 ~360 ~68 ~80 grass_block
fill ~361 ~60 ~80 ~364 ~63 ~80 stone
fill ~361 ~64 ~80 ~364 ~66 ~80 dirt
fill ~361 ~67 ~80 ~364 ~67 ~80 grass_block
fill ~365 ~60 ~80 ~366 ~64 ~80 stone
fill ~365 ~65 ~80 ~366 ~67 ~80 dirt
fill ~365 ~68 ~80 ~366 ~68 ~80 grass_block
fill ~367 ~60 ~80 ~367 ~65 ~80 stone
fill ~367 ~66 ~80 ~367 ~68 ~80 dirt
fill ~367 ~69 ~80 ~367 ~69 ~80 grass_block
fill ~352 ~60 ~81 ~359 ~64 ~81 stone
fill ~352 ~65 ~81 ~359 ~67 ~81 dirt
fill ~352 ~68 ~81 ~359 ~68 ~81 grass_block
fill ~360 ~60 ~81 ~364 ~63 ~81 stone
fill ~360 ~64 ~81 ~364 ~66 ~81 dirt
fill ~360 ~67 ~81 ~364 ~67 ~81 grass_block
fill ~365 ~60 ~81 ~366 ~64 ~81 stone
fill ~365 ~65 ~81 ~366 ~67 ~81 dirt
fill ~365 ~68 ~81 ~366 ~68 ~81 grass_block
fill ~367 ~60 ~81 ~367 ~65 ~81 stone
fill ~367 ~66 ~81 ~367 ~68 ~81 dirt
fill ~367 ~69 ~81 ~367 ~69 ~81 grass_block
fill ~352 ~60 ~82 ~359 ~64 ~82 stone
fill ~352 ~65 ~82 ~359 ~67 ~82 dirt
fill ~352 ~68 ~82 ~359 ~68 ~82 grass_block
fill ~360 ~60 ~82 ~364 ~63 ~82 stone
fill ~360 ~64 ~82 ~364 ~66 ~82 dirt
fill ~360 ~67 ~82 ~364 ~67 ~82 grass_block
fill ~365 ~60 ~82 ~365 ~64 ~82 stone
fill ~365 ~65 ~82 ~365 ~67 ~82 dirt
fill ~365 ~68 ~82 ~365 ~68 ~82 grass_block
fill ~366 ~60 ~82 ~367 ~65 ~82 stone
fill ~366 ~66 ~82 ~367 ~68 ~82 dirt
fill ~366 ~69 ~82 ~367 ~69 ~82 grass_block
fill ~352 ~60 ~83 ~352 ~63 ~83 stone
fill ~352 ~64 ~83 ~352 ~66 ~83 dirt
fill ~352 ~67 ~83 ~352 ~67 ~83 grass_block
fill ~353 ~60 ~83 ~359 ~64 ~83 stone
fill ~353 ~65 ~83 ~359 ~67 ~83 dirt
fill ~353 ~68 ~83 ~359 ~68 ~83 grass_block
fill ~360 ~60 ~83 ~364 ~63 ~83 stone
fill ~360 ~64 ~83 ~364 ~66 ~83 dirt
fill ~360 ~67 ~83 ~364 ~67 ~83 grass_block
fill ~365 ~60 ~83 ~365 ~64 ~83 stone
fill ~365 ~65 ~83 ~365 ~67 ~83 dirt
fill ~365 ~68 ~83 ~365 ~68 ~83 grass_block
fill ~366 ~60 ~83 ~367 ~65 ~83 stone
fill ~366 ~66 ~83 ~367 ~68 ~83 dirt
fill ~366 ~69 ~83 ~367 ~69 ~83 grass_block
fill ~352 ~60 ~84 ~352 ~63 ~84 stone
fill ~352 ~64 ~84 ~352 ~66 ~84 dirt
fill ~352 ~67 ~84 ~352 ~67 ~84 grass_block
fill ~353 ~60 ~84 ~359 ~64 ~84 stone
fill ~353 ~65 ~84 ~359 ~67 ~84 dirt
fill ~353 ~68 ~84 ~359 ~68 ~84 grass_block
fill ~360 ~60 ~84 ~364 ~63 ~84 stone
fill ~360 ~64 ~84 ~364 ~66 ~84 dirt
fill ~360 ~67 ~84 ~364 ~67 ~84 grass_block
fill ~365 ~60 ~84 ~366 ~64 ~84 stone
fill ~365 ~65 ~84 ~366 ~67 ~84 dirt
fill ~365 ~68 ~84 ~366 ~68 ~84 grass_block
fill ~367 ~60 ~84 ~367 ~65 ~84 stone
fill ~367 ~66 ~84 ~367 ~68 ~84 dirt
fill ~367 ~69 ~84 ~367 ~69 ~84 grass_block
fill ~352 ~60 ~85 ~353 ~63 ~85 stone
fill ~352 ~64 ~85 ~353 ~66 ~85 dirt
fill ~352 ~67 ~85 ~353 ~67 ~85 grass_block
fill ~354 ~60 ~85 ~358 ~64 ~85 stone
fill ~354 ~65 ~85 ~358 ~67 ~85 dirt
fill ~354 ~68 ~85 ~358 ~68 ~85 grass_block
fill ~359 ~60 ~85 ~361 ~63 ~85 stone
fill ~359 ~64 ~85 ~361 ~66 ~85 dirt
fill ~359 ~67 ~85 ~361 ~67 ~85 grass_block
fill ~362 ~60 ~85 ~362 ~62 ~85 stone
fill ~362 ~63 ~85 ~362 ~65 ~85 dirt
fill ~362 ~66 ~85 ~362 ~66 ~85 grass_block
fill ~363 ~60 ~85 ~364 ~63 ~85 stone
fill ~363 ~64 ~85 ~364 ~66 ~85 dirt
fill ~363 ~67 ~85 ~364 ~67 ~85 grass_block
fill ~365 ~60 ~85 ~367 ~64 ~85 stone
fill ~365 ~65 ~85 ~367 ~67 ~85 dirt
fill ~365 ~68 ~85 ~367 ~68 ~85 grass_block
fill ~352 ~60 ~86 ~353 ~63 ~86 stone
fill ~352 ~64 ~86 ~353 ~66 ~86 dirt
fill ~352 ~67 ~86 ~353 ~67 ~86 grass_block
fill ~354 ~60 ~86 ~358 ~64 ~86 stone
fill ~354 ~65 ~86 ~358 ~67 ~86 dirt
fill ~354 ~68 ~86 ~358 ~68 ~86 grass_block
fill ~359 ~60 ~86 ~361 ~63 ~86 stone
fill ~359 ~64 ~86 ~361 ~66 ~86 dirt
fill ~359 ~67 ~86 ~361 ~67 ~86 grass_block
fill ~362 ~60 ~86 ~362 ~62 ~86 stone
fill ~362 ~63 ~86 ~362 ~65 ~86 dirt
fill ~362 ~66 ~86 ~362 ~66 ~86 grass_block
fill ~363 ~60 ~86 ~365 ~63 ~86 stone
fill ~363 ~64 ~86 ~365 ~66 ~86 dirt
fill ~363 ~67 ~86 ~365 ~67 ~86 grass_block
fill ~366 ~60 ~86 ~367 ~64 ~86 stone
fill ~366 ~65 ~86 ~367 ~67 ~86 dirt
fill ~366 ~68 ~86 ~367 ~68 ~86 grass_block
fill ~352 ~60 ~87 ~354 ~63 ~87 stone
fill ~352 ~64 ~87 ~354 ~66 ~87 dirt
fill ~352 ~67 ~87 ~354 ~67 ~87 grass_block
fill ~355 ~60 ~87 ~357 ~64 ~87 stone
fill ~355 ~65 ~87 ~357 ~67 ~87 dirt
fill ~355 ~68 ~87 ~357 ~68 ~87 grass_block
fill ~358 ~60 ~87 ~361 ~63 ~87 stone
fill ~358 ~64 ~87 ~361 ~66 ~87 dirt
fill ~358 ~67 ~87 ~361 ~67 ~87 grass_block
fill ~362 ~60 ~87 ~363 ~62 ~87 stone
fill ~362 ~63 ~87 ~363 ~65 ~87 dirt
fill ~362 ~66 ~87 ~363 ~66 ~87 grass_block
fill ~364 ~60 ~87 ~366 ~63 ~87 stone
fill ~364 ~64 ~87 ~366 ~66 ~87 dirt
fill ~364 ~67 ~87 ~366 ~67 ~87 grass_block
fill ~367 ~60 ~87 ~367 ~64 ~87 stone
fill ~367 ~65 ~87 ~367 ~67 ~87 dirt
fill ~367 ~68 ~87 ~367 ~68 ~87 grass_block
fill ~352 ~60 ~88 ~360 ~63 ~88 stone
fill ~352 ~64 ~88 ~360 ~66 ~88 dirt
fill ~352 ~67 ~88 ~360 ~67 ~88 grass_block
fill ~361 ~60 ~88 ~363 ~62 ~88 stone
fill ~361 ~63 ~88 ~363 ~65 ~88 dirt
fill ~361 ~66 ~88 ~363 ~66 ~88 grass_block
fill ~364 ~60 ~88 ~366 ~63 ~88 stone
fill ~364 ~64 ~88 ~366 ~66 ~88 dirt
fill ~364 ~67 ~88 ~366 ~67 ~88 grass_block
fill ~367 ~60 ~88 ~367 ~64 ~88 stone
fill ~367 ~65 ~88 ~367 ~67 ~88 dirt
fill ~367 ~68 ~88 ~367 ~68 ~88 grass_block
fill ~352 ~60 ~89 ~359 ~63 ~89 stone
fill ~352 ~64 ~89 ~359 ~66 ~89 dirt
fill ~352 ~67 ~89 ~359 ~67 ~89 grass_block
fill ~360 ~60 ~89 ~362 ~62 ~89 stone
fill ~360 ~63 ~89 ~362 ~65 ~89 dirt
fill ~360 ~66 ~89 ~362 ~66 ~89 grass_block
fill ~363 ~60 ~89 ~366 ~63 ~89 stone
fill ~363 ~64 ~89 ~366 ~66 ~89 dirt
fill ~363 ~67 ~89 ~366 ~67 ~89 grass_block
fill ~367 ~60 ~89 ~367 ~64 ~89 stone
fill ~367 ~65 ~89 ~367 ~67 ~89 dirt
fill ~367 ~68 ~89 ~367 ~68 ~89 grass_block
fill ~352 ~60 ~90 ~352 ~62 ~90 stone
fill ~352 ~63 ~90 ~352 ~65 ~90 dirt
fill ~352 ~66 ~90 ~352 ~66 ~90 grass_block
fill ~353 ~60 ~90 ~358 ~63 ~90 stone
fill ~353 ~64 ~90 ~358 ~66 ~90 dirt
fill ~353 ~67 ~90 ~358 ~67 ~90 grass_block
fill ~359 ~60 ~90 ~362 ~62 ~90 stone
fill ~359 ~63 ~90 ~362 ~65 ~90 dirt
fill ~359 ~66 ~90 ~362 ~66 ~90 grass_block
fill ~363 ~60 ~90 ~364 ~63 ~90 stone
fill ~363 ~64 ~90 ~364 ~66 ~90 dirt
fill ~363 ~67 ~90 ~364 ~67 ~90 grass_block
fill ~365 ~60 ~90 ~367 ~64 ~90 stone
fill ~365 ~65 ~90 ~367 ~67 ~90 dirt
fill ~365 ~68 ~90 ~367 ~68 ~90 grass_block
fill ~352 ~60 ~91 ~355 ~62 ~91 stone
fill ~352 ~63 ~91 ~355 ~65 ~91 dirt
fill ~352 ~66 ~91 ~355 ~66 ~91 grass_block
fill ~356 ~60 ~91 ~357 ~63 ~91 stone
fill ~356 ~64 ~91 ~357 ~66 ~91 dirt
fill ~356 ~67 ~91 ~357 ~67 ~91 grass_block
fill ~358 ~60 ~91 ~362 ~62 ~91 stone
fill ~358 ~63 ~91 ~362 ~65 ~91 dirt
fill ~358 ~66 ~91 ~362 ~66 ~91 grass_block
fill ~363 ~60 ~91 ~364 ~63 ~91 stone
fill ~363 ~64 ~91 ~364 ~66 ~91 dirt
fill ~363 ~67 ~91 ~364 ~67 ~91 grass_block
fill ~365 ~60 ~91 ~367 ~64 ~91 stone
fill ~365 ~65 ~91 ~367 ~67 ~91 dirt
fill ~365 ~68 ~91 ~367 ~68 ~91 grass_block
fill ~352 ~60 ~92 ~361 ~62 ~92 stone
fill ~352 ~63 ~92 ~361 ~65 ~92 dirt
fill ~352 ~66 ~92 ~361 ~66 ~92 grass_block
fill ~362 ~60 ~92 ~364 ~63 ~92 stone
fill ~362 ~64 ~92 ~364 ~66 ~92 dirt
fill ~362 ~67 ~92 ~364 ~67 ~92 grass_block
fill ~365 ~60 ~92 ~367 ~64 ~92 stone
fill ~365 ~65 ~92 ~367 ~67 ~92 dirt
fill ~365 ~68 ~92 ~367 ~68 ~92 grass_block
fill ~352 ~60 ~93 ~360 ~62 ~93 stone
fill ~352 ~63 ~93 ~360 ~65 ~93 dirt
fill ~352 ~66 ~93 ~360 ~66 ~93 grass_block
fill ~361 ~60 ~93 ~362 ~63 ~93 stone
fill ~361 ~64 ~93 ~362 ~66 ~93 dirt
fill ~361 ~67 ~93 ~362 ~67 ~93 grass_block
fill ~363 ~60 ~93 ~366 ~64 ~93 stone
fill ~363 ~65 ~93 ~366 ~67 ~93 dirt
fill ~363 ~68 ~93 ~366 ~68 ~93 grass_block
fill ~367 ~60 ~93 ~367 ~65 ~93 stone
fill ~367 ~66 ~93 ~367 ~68 ~93 dirt
fill ~367 ~69 ~93 ~367 ~69 ~93 grass_block
fill ~352 ~60 ~94 ~359 ~62 ~94 stone
fill ~352 ~63 ~94 ~359 ~65 ~94 dirt
fill ~352 ~66 ~94 ~359 ~66 ~94 grass_block
fill ~360 ~60 ~94 ~361 ~63 ~94 stone
fill ~360 ~64 ~94 ~361 ~66 ~94 dirt
fill ~360 ~67 ~94 ~361 ~67 ~94 grass_block
fill ~362 ~60 ~94 ~365 ~64 ~94 stone
fill ~362 ~65 ~94 ~365 ~67 ~94 dirt
fill ~362 ~68 ~94 ~365 ~68 ~94 grass_block
fill ~366 ~60 ~94 ~367 ~65 ~94 stone
fill ~366 ~66 ~94 ~367 ~68 ~94 dirt
fill ~366 ~69 ~94 ~367 ~69 ~94 grass_block
fill ~352 ~60 ~95 ~358 ~62 ~95 stone
fill ~352 ~63 ~95 ~358 ~65 ~95 dirt
fill ~352 ~66 ~95 ~358 ~66 ~95 grass_block
fill ~359 ~60 ~95 ~361 ~63 ~95 stone
fill ~359 ~64 ~95 ~361 ~66 ~95 dirt
fill ~359 ~67 ~95 ~361 ~67 ~95 grass_block
fill ~362 ~60 ~95 ~364 ~64 ~95 stone
fill ~362 ~65 ~95 ~364 ~67 ~95 dirt
fill ~362 ~68 ~95 ~364 ~68 ~95 grass_block
fill ~365 ~60 ~95 ~367 ~65 ~95 stone
fill ~365 ~66 ~95 ~367 ~68 ~95 dirt
fill ~365 ~69 ~95 ~367 ~69 ~95 grass_block