fill ~16 ~60 ~112 ~17 ~67 ~112 stone
fill ~16 ~68 ~112 ~17 ~70 ~112 dirt
fill ~16 ~71 ~112 ~17 ~71 ~112 grass_block
fill ~18 ~60 ~112 ~31 ~68 ~112 stone
fill ~18 ~69 ~112 ~31 ~71 ~112 dirt
fill ~18 ~72 ~112 ~31 ~72 ~112 grass_block
fill ~16 ~60 ~113 ~18 ~67 ~113 stone
fill ~16 ~68 ~113 ~18 ~70 ~113 dirt
fill ~16 ~71 ~113 ~18 ~71 ~113 grass_block
fill ~19 ~60 ~113 ~31 ~68 ~113 stone
fill ~19 ~69 ~113 ~31 ~71 ~113 dirt
fill ~19 ~72 ~113 ~31 ~72 ~113 grass_block
fill ~16 ~60 ~114 ~16 ~66 ~114 stone
fill ~16 ~67 ~114 ~16 ~69 ~114 dirt
fill ~16 ~70 ~114 ~16 ~70 ~114 grass_block
fill ~17 ~60 ~114 ~19 ~67 ~114 stone
fill ~17 ~68 ~114 ~19 ~70 ~114 dirt
fill ~17 ~71 ~114 ~19 ~71 ~114 grass_block
fill ~20 ~60 ~114 ~21 ~68 ~114 stone
fill ~20 ~69 ~114 ~21 ~71 ~114 dirt
fill ~20 ~72 ~114 ~21 ~72 ~114 grass_block
fill ~22 ~60 ~114 ~27 ~67 ~114 stone
fill ~22 ~68 ~114 ~27 ~70 ~114 dirt
fill ~22 ~71 ~114 ~27 ~71 ~114 grass_block
fill ~28 ~60 ~114 ~31 ~68 ~114 stone
fill ~28 ~69 ~114 ~31 ~71 ~114 dirt
fill ~28 ~72 ~114 ~31 ~72 ~114 grass_block
fill ~16 ~60 ~115 ~17 ~66 ~115 stone
fill ~16 ~67 ~115 ~17 ~69 ~115 dirt
fill ~16 ~70 ~115 ~17 ~70 ~115 grass_block
fill ~18 ~60 ~115 ~31 ~67 ~115 stone
fill ~18 ~68 ~115 ~31 ~70 ~115 dirt
fill ~18 ~71 ~115 ~31 ~71 ~115 grass_block
fill ~16 ~60 ~116 ~18 ~66 ~116 stone
fill ~16 ~67 ~116 ~18 ~69 ~116 dirt
fill ~16 ~70 ~116 ~18 ~70 ~116 grass_block
fill ~19 ~60 ~116 ~23 ~67 ~116 stone
fill ~19 ~68 ~116 ~23 ~70 ~116 dirt
fill ~19 ~71 ~116 ~23 ~71 ~116 grass_block
fill ~24 ~60 ~116 ~24 ~66 ~116 stone
fill ~24 ~67 ~116 ~24 ~69 ~116 dirt
fill ~24 ~70 ~116 ~24 ~70 ~116 grass_block
fill ~25 ~60 ~116 ~31 ~67 ~116 stone
fill ~25 ~68 ~116 ~31 ~70 ~116 dirt
fill ~25 ~71 ~116 ~31 ~71 ~116 grass_block
fill ~16 ~60 ~117 ~16 ~65 ~117 stone
fill ~16 ~66 ~117 ~16 ~68 ~117 dirt
fill ~16 ~69 ~117 ~16 ~69 ~117 grass_block
fill ~17 ~60 ~117 ~19 ~66 ~117 stone
fill ~17 ~67 ~117 ~19 ~69 ~117 dirt
fill ~17 ~70 ~117 ~19 ~70 ~117 grass_block
fill ~20 ~60 ~117 ~23 ~67 ~117 stone
fill ~20 ~68 ~117 ~23 ~70 ~117 dirt
fill ~20 ~71 ~117 ~23 ~71 ~117 grass_block
fill ~24 ~60 ~117 ~25 ~66 ~117 stone
fill ~24 ~67 ~117 ~25 ~69 ~117 dirt
fill ~24 ~70 ~117 ~25 ~70 ~117 grass_block
fill ~26 ~60 ~117 ~31 ~67 ~117 stone
fill ~26 ~68 ~117 ~31 ~70 ~117 dirt
fill ~26 ~71 ~117 ~31 ~71 ~117 grass_block
fill ~16 ~60 ~118 ~17 ~65 ~118 stone
fill ~16 ~66 ~118 ~17 ~68 ~118 dirt
fill ~16 ~69 ~118 ~17 ~69 ~118 grass_block
fill ~18 ~60 ~118 ~21 ~66 ~118 stone
fill ~18 ~67 ~118 ~21 ~69 ~118 dirt
fill ~18 ~70 ~118 ~21 ~70 ~118 grass_block
fill ~22 ~60 ~118 ~23 ~67 ~118 stone
fill ~22 ~68 ~118 ~23 ~70 ~118 dirt
fill ~22 ~71 ~118 ~23 ~71 ~118 grass_block
fill ~24 ~60 ~118 ~26 ~66 ~118 stone
fill ~24 ~67 ~118 ~26 ~69 ~118 dirt
fill ~24 ~70 ~118 ~26 ~70 ~118 grass_block
fill ~27 ~60 ~118 ~28 ~67 ~118 stone
fill ~27 ~68 ~118 ~28 ~70 ~118 dirt
fill ~27 ~71 ~118 ~28 ~71 ~118 grass_block
fill ~29 ~60 ~118 ~31 ~66 ~118 stone
fill ~29 ~67 ~118 ~31 ~69 ~118 dirt
fill ~29 ~70 ~118 ~31 ~70 ~118 grass_block
fill ~16 ~60 ~119 ~18 ~65 ~119 stone
fill ~16 ~66 ~119 ~18 ~68 ~119 dirt
fill ~16 ~69 ~119 ~18 ~69 ~119 grass_block
fill ~19 ~60 ~119 ~31 ~66 ~119 stone
fill ~19 ~67 ~119 ~31 ~69 ~119 dirt
fill ~19 ~70 ~119 ~31 ~70 ~119 grass_block
fill ~16 ~60 ~120 ~20 ~65 ~120 stone
fill ~16 ~66 ~120 ~20 ~68 ~120 dirt
fill ~16 ~69 ~120 ~20 ~69 ~120 grass_block
fill ~21 ~60 ~120 ~25 ~66 ~120 stone
fill ~21 ~67 ~120 ~25 ~69 ~120 dirt
fill ~21 ~70 ~120 ~25 ~70 ~120 grass_block
fill ~26 ~60 ~120 ~26 ~65 ~120 stone
fill ~26 ~66 ~120 ~26 ~68 ~120 dirt
fill ~26 ~69 ~120 ~26 ~69 ~120 grass_block
fill ~27 ~60 ~120 ~30 ~66 ~120 stone
fill ~27 ~67 ~120 ~30 ~69 ~120 dirt
fill ~27 ~70 ~120 ~30 ~70 ~120 grass_block
fill ~31 ~60 ~120 ~31 ~65 ~120 stone
fill ~31 ~66 ~120 ~31 ~68 ~120 dirt
fill ~31 ~69 ~120 ~31 ~69 ~120 grass_block
fill ~16 ~60 ~121 ~22 ~65 ~121 stone
fill ~16 ~66 ~121 ~22 ~68 ~121 dirt
fill ~16 ~69 ~121 ~22 ~69 ~121 grass_block
fill ~23 ~60 ~121 ~25 ~66 ~121 stone
fill ~23 ~67 ~121 ~25 ~69 ~121 dirt
fill ~23 ~70 ~121 ~25 ~70 ~121 grass_block
fill ~26 ~60 ~121 ~27 ~65 ~121 stone
fill ~26 ~66 ~121 ~27 ~68 ~121 dirt
fill ~26 ~69 ~121 ~27 ~69 ~121 grass_block
fill ~28 ~60 ~121 ~30 ~66 ~121 stone
fill ~28 ~67 ~121 ~30 ~69 ~121 dirt
fill ~28 ~70 ~121 ~30 ~70 ~121 grass_block
fill ~31 ~60 ~121 ~31 ~65 ~121 stone
fill ~31 ~66 ~121 ~31 ~68 ~121 dirt
fill ~31 ~69 ~121 ~31 ~69 ~121 grass_block
fill ~16 ~60 ~122 ~31 ~65 ~122 stone
fill ~16 ~66 ~122 ~31 ~68 ~122 dirt
fill ~16 ~69 ~122 ~31 ~69 ~122 grass_block
fill ~16 ~60 ~123 ~19 ~65 ~123 stone
fill ~16 ~66 ~123 ~19 ~68 ~123 dirt
fill ~16 ~69 ~123 ~19 ~69 ~123 grass_block
fill ~20 ~60 ~123 ~20 ~64 ~123 stone
fill ~20 ~65 ~123 ~20 ~67 ~123 dirt
fill ~20 ~68 ~123 ~20 ~68 ~123 grass_block
fill ~21 ~60 ~123 ~31 ~65 ~123 stone
fill ~21 ~66 ~123 ~31 ~68 ~123 dirt
fill ~21 ~69 ~123 ~31 ~69 ~123 grass_block
fill ~16 ~60 ~124 ~17 ~66 ~124 stone
fill ~16 ~67 ~124 ~17 ~69 ~124 dirt
fill ~16 ~70 ~124 ~17 ~70 ~124 grass_block
fill ~18 ~60 ~124 ~20 ~65 ~124 stone
fill ~18 ~66 ~124 ~20 ~68 ~124 dirt
fill ~18 ~69 ~124 ~20 ~69 ~124 grass_block
fill ~21 ~60 ~124 ~22 ~64 ~124 stone
fill ~21 ~65 ~124 ~22 ~67 ~124 dirt
fill ~21 ~68 ~124 ~22 ~68 ~124 grass_block
fill ~23 ~60 ~124 ~31 ~65 ~124 stone
fill ~23 ~66 ~124 ~31 ~68 ~124 dirt
fill ~23 ~69 ~124 ~31 ~69 ~124 grass_block
fill ~16 ~60 ~125 ~16 ~67 ~125 stone
fill ~16 ~68 ~125 ~16 ~70 ~125 dirt
fill ~16 ~71 ~125 ~16 ~71 ~125 grass_block
fill ~17 ~60 ~125 ~18 ~66 ~125 stone
fill ~17 ~67 ~125 ~18 ~69 ~125 dirt
fill ~17 ~70 ~125 ~18 ~70 ~125 grass_block
fill ~19 ~60 ~125 ~21 ~65 ~125 stone
fill ~19 ~66 ~125 ~21 ~68 ~125 dirt
fill ~19 ~69 ~125 ~21 ~69 ~125 grass_block
fill ~22 ~60 ~125 ~31 ~64 ~125 stone
fill ~22 ~65 ~125 ~31 ~67 ~125 dirt
fill ~22 ~68 ~125 ~31 ~68 ~125 grass_block
fill ~16 ~60 ~126 ~17 ~67 ~126 stone
fill ~16 ~68 ~126 ~17 ~70 ~126 dirt
fill ~16 ~71 ~126 ~17 ~71 ~126 grass_block
fill ~18 ~60 ~126 ~20 ~66 ~126 stone
fill ~18 ~67 ~126 ~20 ~69 ~126 dirt
fill ~18 ~70 ~126 ~20 ~70 ~126 grass_block
fill ~21 ~60 ~126 ~22 ~65 ~126 stone
fill ~21 ~66 ~126 ~22 ~68 ~126 dirt
fill ~21 ~69 ~126 ~22 ~69 ~126 grass_block
fill ~23 ~60 ~126 ~31 ~64 ~126 stone
fill ~23 ~65 ~126 ~31 ~67 ~126 dirt
fill ~23 ~68 ~126 ~31 ~68 ~126 grass_block
fill ~16 ~60 ~127 ~17 ~67 ~127 stone
fill ~16 ~68 ~127 ~17 ~70 ~127 dirt
fill ~16 ~71 ~127 ~17 ~71 ~127 grass_block
fill ~18 ~60 ~127 ~19 ~66 ~127 stone
fill ~18 ~67 ~127 ~19 ~69 ~127 dirt
fill ~18 ~70 ~127 ~19 ~70 ~127 grass_block
fill ~20 ~60 ~127 ~27 ~65 ~127 stone
fill ~20 ~66 ~127 ~27 ~68 ~127 dirt
fill ~20 ~69 ~127 ~27 ~69 ~127 grass_block
fill ~28 ~60 ~127 ~31 ~64 ~127 stone
fill ~28 ~65 ~127 ~31 ~67 ~127 dirt
fill ~28 ~68 ~127 ~31 ~68 ~127 grass_block