fill ~128 ~60 ~16 ~130 ~65 ~16 stone
fill ~128 ~66 ~16 ~130 ~68 ~16 dirt
fill ~128 ~69 ~16 ~130 ~69 ~16 grass_block
fill ~131 ~60 ~16 ~134 ~64 ~16 stone
fill ~131 ~65 ~16 ~134 ~67 ~16 dirt
fill ~131 ~68 ~16 ~134 ~68 ~16 grass_block
fill ~135 ~60 ~16 ~143 ~63 ~16 stone
fill ~135 ~64 ~16 ~143 ~66 ~16 dirt
fill ~135 ~67 ~16 ~143 ~67 ~16 grass_block
fill ~128 ~60 ~17 ~131 ~65 ~17 stone
fill ~128 ~66 ~17 ~131 ~68 ~17 dirt
fill ~128 ~69 ~17 ~131 ~69 ~17 grass_block
fill ~132 ~60 ~17 ~135 ~64 ~17 stone
fill ~132 ~65 ~17 ~135 ~67 ~17 dirt
fill ~132 ~68 ~17 ~135 ~68 ~17 grass_block
fill ~136 ~60 ~17 ~143 ~63 ~17 stone
fill ~136 ~64 ~17 ~143 ~66 ~17 dirt
fill ~136 ~67 ~17 ~143 ~67 ~17 grass_block
fill ~128 ~60 ~18 ~131 ~65 ~18 stone
fill ~128 ~66 ~18 ~131 ~68 ~18 dirt
fill ~128 ~69 ~18 ~131 ~69 ~18 grass_block
fill ~132 ~60 ~18 ~136 ~64 ~18 stone
fill ~132 ~65 ~18 ~136 ~67 ~18 dirt
fill ~132 ~68 ~18 ~136 ~68 ~18 grass_block
fill ~137 ~60 ~18 ~143 ~63 ~18 stone
fill ~137 ~64 ~18 ~143 ~66 ~18 dirt
fill ~137 ~67 ~18 ~143 ~67 ~18 grass_block
fill ~128 ~60 ~19 ~132 ~65 ~19 stone
fill ~128 ~66 ~19 ~132 ~68 ~19 dirt
fill ~128 ~69 ~19 ~132 ~69 ~19 grass_block
fill ~133 ~60 ~19 ~137 ~64 ~19 stone
fill ~133 ~65 ~19 ~137 ~67 ~19 dirt
fill ~133 ~68 ~19 ~137 ~68 ~19 grass_block
fill ~138 ~60 ~19 ~143 ~63 ~19 stone
fill ~138 ~64 ~19 ~143 ~66 ~19 dirt
fill ~138 ~67 ~19 ~143 ~67 ~19 grass_block
fill ~128 ~60 ~20 ~131 ~65 ~20 stone
fill ~128 ~66 ~20 ~131 ~68 ~20 dirt
fill ~128 ~69 ~20 ~131 ~69 ~20 grass_block
fill ~132 ~60 ~20 ~137 ~64 ~20 stone
fill ~132 ~65 ~20 ~137 ~67 ~20 dirt
fill ~132 ~68 ~20 ~137 ~68 ~20 grass_block
fill ~138 ~60 ~20 ~143 ~63 ~20 stone
fill ~138 ~64 ~20 ~143 ~66 ~20 dirt
fill ~138 ~67 ~20 ~143 ~67 ~20 grass_block
fill ~128 ~60 ~21 ~131 ~65 ~21 stone
fill ~128 ~66 ~21 ~131 ~68 ~21 dirt
fill ~128 ~69 ~21 ~131 ~69 ~21 grass_block
fill ~132 ~60 ~21 ~136 ~64 ~21 stone
fill ~132 ~65 ~21 ~136 ~67 ~21 dirt
fill ~132 ~68 ~21 ~136 ~68 ~21 grass_block
fill ~137 ~60 ~21 ~143 ~63 ~21 stone
fill ~137 ~64 ~21 ~143 ~66 ~21 dirt
fill ~137 ~67 ~21 ~143 ~67 ~21 grass_block
fill ~128 ~60 ~22 ~131 ~65 ~22 stone
fill ~128 ~66 ~22 ~131 ~68 ~22 dirt
fill ~128 ~69 ~22 ~131 ~69 ~22 grass_block
fill ~132 ~60 ~22 ~136 ~64 ~22 stone
fill ~132 ~65 ~22 ~136 ~67 ~22 dirt
fill ~132 ~68 ~22 ~136 ~68 ~22 grass_block
fill ~137 ~60 ~22 ~143 ~63 ~22 stone
fill ~137 ~64 ~22 ~143 ~66 ~22 dirt
fill ~137 ~67 ~22 ~143 ~67 ~22 grass_block
fill ~128 ~60 ~23 ~130 ~65 ~23 stone
fill ~128 ~66 ~23 ~130 ~68 ~23 dirt
fill ~128 ~69 ~23 ~130 ~69 ~23 grass_block
fill ~131 ~60 ~23 ~138 ~64 ~23 stone
fill ~131 ~65 ~23 ~138 ~67 ~23 dirt
fill ~131 ~68 ~23 ~138 ~68 ~23 grass_block
fill ~139 ~60 ~23 ~143 ~63 ~23 stone
fill ~139 ~64 ~23 ~143 ~66 ~23 dirt
fill ~139 ~67 ~23 ~143 ~67 ~23 grass_block
fill ~128 ~60 ~24 ~129 ~65 ~24 stone
fill ~128 ~66 ~24 ~129 ~68 ~24 dirt
fill ~128 ~69 ~24 ~129 ~69 ~24 grass_block
fill ~130 ~60 ~24 ~133 ~64 ~24 stone
fill ~130 ~65 ~24 ~133 ~67 ~24 dirt
fill ~130 ~68 ~24 ~133 ~68 ~24 grass_block
fill ~134 ~60 ~24 ~134 ~65 ~24 stone
fill ~134 ~66 ~24 ~134 ~68 ~24 dirt
fill ~134 ~69 ~24 ~134 ~69 ~24 grass_block
fill ~135 ~60 ~24 ~139 ~64 ~24 stone
fill ~135 ~65 ~24 ~139 ~67 ~24 dirt
fill ~135 ~68 ~24 ~139 ~68 ~24 grass_block
fill ~140 ~60 ~24 ~143 ~63 ~24 stone
fill ~140 ~64 ~24 ~143 ~66 ~24 dirt
fill ~140 ~67 ~24 ~143 ~67 ~24 grass_block
fill ~128 ~60 ~25 ~129 ~65 ~25 stone
fill ~128 ~66 ~25 ~129 ~68 ~25 dirt
fill ~128 ~69 ~25 ~129 ~69 ~25 grass_block
fill ~130 ~60 ~25 ~131 ~64 ~25 stone
fill ~130 ~65 ~25 ~131 ~67 ~25 dirt
fill ~130 ~68 ~25 ~131 ~68 ~25 grass_block
fill ~132 ~60 ~25 ~135 ~65 ~25 stone
fill ~132 ~66 ~25 ~135 ~68 ~25 dirt
fill ~132 ~69 ~25 ~135 ~69 ~25 grass_block
fill ~136 ~60 ~25 ~139 ~64 ~25 stone
fill ~136 ~65 ~25 ~139 ~67 ~25 dirt
fill ~136 ~68 ~25 ~139 ~68 ~25 grass_block
fill ~140 ~60 ~25 ~143 ~63 ~25 stone
fill ~140 ~64 ~25 ~143 ~66 ~25 dirt
fill ~140 ~67 ~25 ~143 ~67 ~25 grass_block
fill ~128 ~60 ~26 ~136 ~65 ~26 stone
fill ~128 ~66 ~26 ~136 ~68 ~26 dirt
fill ~128 ~69 ~26 ~136 ~69 ~26 grass_block
fill ~137 ~60 ~26 ~140 ~64 ~26 stone
fill ~137 ~65 ~26 ~140 ~67 ~26 dirt
fill ~137 ~68 ~26 ~140 ~68 ~26 grass_block
fill ~141 ~60 ~26 ~143 ~63 ~26 stone
fill ~141 ~64 ~26 ~143 ~66 ~26 dirt
fill ~141 ~67 ~26 ~143 ~67 ~26 grass_block
fill ~128 ~60 ~27 ~130 ~65 ~27 stone
fill ~128 ~66 ~27 ~130 ~68 ~27 dirt
fill ~128 ~69 ~27 ~130 ~69 ~27 grass_block
fill ~131 ~60 ~27 ~131 ~66 ~27 stone
fill ~131 ~67 ~27 ~131 ~69 ~27 dirt
fill ~131 ~70 ~27 ~131 ~70 ~27 grass_block
fill ~132 ~60 ~27 ~137 ~65 ~27 stone
fill ~132 ~66 ~27 ~137 ~68 ~27 dirt
fill ~132 ~69 ~27 ~137 ~69 ~27 grass_block
fill ~138 ~60 ~27 ~140 ~64 ~27 stone
fill ~138 ~65 ~27 ~140 ~67 ~27 dirt
fill ~138 ~68 ~27 ~140 ~68 ~27 grass_block
fill ~141 ~60 ~27 ~143 ~63 ~27 stone
fill ~141 ~64 ~27 ~143 ~66 ~27 dirt
fill ~141 ~67 ~27 ~143 ~67 ~27 grass_block
fill ~128 ~60 ~28 ~133 ~66 ~28 stone
fill ~128 ~67 ~28 ~133 ~69 ~28 dirt
fill ~128 ~70 ~28 ~133 ~70 ~28 grass_block
fill ~134 ~60 ~28 ~137 ~65 ~28 stone
fill ~134 ~66 ~28 ~137 ~68 ~28 dirt
fill ~134 ~69 ~28 ~137 ~69 ~28 grass_block
fill ~138 ~60 ~28 ~140 ~64 ~28 stone
fill ~138 ~65 ~28 ~140 ~67 ~28 dirt
fill ~138 ~68 ~28 ~140 ~68 ~28 grass_block
fill ~141 ~60 ~28 ~143 ~63 ~28 stone
fill ~141 ~64 ~28 ~143 ~66 ~28 dirt
fill ~141 ~67 ~28 ~143 ~67 ~28 grass_block
fill ~128 ~60 ~29 ~129 ~67 ~29 stone
fill ~128 ~68 ~29 ~129 ~70 ~29 dirt
fill ~128 ~71 ~29 ~129 ~71 ~29 grass_block
fill ~130 ~60 ~29 ~133 ~66 ~29 stone
fill ~130 ~67 ~29 ~133 ~69 ~29 dirt
fill ~130 ~70 ~29 ~133 ~70 ~29 grass_block
fill ~134 ~60 ~29 ~136 ~65 ~29 stone
fill ~134 ~66 ~29 ~136 ~68 ~29 dirt
fill ~134 ~69 ~29 ~136 ~69 ~29 grass_block
fill ~137 ~60 ~29 ~140 ~64 ~29 stone
fill ~137 ~65 ~29 ~140 ~67 ~29 dirt
fill ~137 ~68 ~29 ~140 ~68 ~29 grass_block
fill ~141 ~60 ~29 ~143 ~63 ~29 stone
fill ~141 ~64 ~29 ~143 ~66 ~29 dirt
fill ~141 ~67 ~29 ~143 ~67 ~29 grass_block
fill ~128 ~60 ~30 ~129 ~67 ~30 stone
fill ~128 ~68 ~30 ~129 ~70 ~30 dirt
fill ~128 ~71 ~30 ~129 ~71 ~30 grass_block
fill ~130 ~60 ~30 ~132 ~66 ~30 stone
fill ~130 ~67 ~30 ~132 ~69 ~30 dirt
fill ~130 ~70 ~30 ~132 ~70 ~30 grass_block
fill ~133 ~60 ~30 ~136 ~65 ~30 stone
fill ~133 ~66 ~30 ~136 ~68 ~30 dirt
fill ~133 ~69 ~30 ~136 ~69 ~30 grass_block
fill ~137 ~60 ~30 ~142 ~64 ~30 stone
fill ~137 ~65 ~30 ~142 ~67 ~30 dirt
fill ~137 ~68 ~30 ~142 ~68 ~30 grass_block
fill ~143 ~60 ~30 ~143 ~63 ~30 stone
fill ~143 ~64 ~30 ~143 ~66 ~30 dirt
fill ~143 ~67 ~30 ~143 ~67 ~30 grass_block
fill ~128 ~60 ~31 ~130 ~67 ~31 stone
fill ~128 ~68 ~31 ~130 ~70 ~31 dirt
fill ~128 ~71 ~31 ~130 ~71 ~31 grass_block
fill ~131 ~60 ~31 ~132 ~66 ~31 stone
fill ~131 ~67 ~31 ~132 ~69 ~31 dirt
fill ~131 ~70 ~31 ~132 ~70 ~31 grass_block
fill ~133 ~60 ~31 ~135 ~65 ~31 stone
fill ~133 ~66 ~31 ~135 ~68 ~31 dirt
fill ~133 ~69 ~31 ~135 ~69 ~31 grass_block
fill ~136 ~60 ~31 ~143 ~64 ~31 stone
fill ~136 ~65 ~31 ~143 ~67 ~31 dirt
fill ~136 ~68 ~31 ~143 ~68 ~31 grass_block