fill ~32 ~60 ~80 ~35 ~68 ~80 stone
fill ~32 ~69 ~80 ~35 ~71 ~80 dirt
fill ~32 ~72 ~80 ~35 ~72 ~80 grass_block
fill ~36 ~60 ~80 ~36 ~67 ~80 stone
fill ~36 ~68 ~80 ~36 ~70 ~80 dirt
fill ~36 ~71 ~80 ~36 ~71 ~80 grass_block
fill ~37 ~60 ~80 ~39 ~66 ~80 stone
fill ~37 ~67 ~80 ~39 ~69 ~80 dirt
fill ~37 ~70 ~80 ~39 ~70 ~80 grass_block
fill ~40 ~60 ~80 ~41 ~67 ~80 stone
fill ~40 ~68 ~80 ~41 ~70 ~80 dirt
fill ~40 ~71 ~80 ~41 ~71 ~80 grass_block
fill ~42 ~60 ~80 ~43 ~68 ~80 stone
fill ~42 ~69 ~80 ~43 ~71 ~80 dirt
fill ~42 ~72 ~80 ~43 ~72 ~80 grass_block
fill ~44 ~60 ~80 ~47 ~69 ~80 stone
fill ~44 ~70 ~80 ~47 ~72 ~80 dirt
fill ~44 ~73 ~80 ~47 ~73 ~80 grass_block
fill ~32 ~60 ~81 ~34 ~68 ~81 stone
fill ~32 ~69 ~81 ~34 ~71 ~81 dirt
fill ~32 ~72 ~81 ~34 ~72 ~81 grass_block
fill ~35 ~60 ~81 ~37 ~67 ~81 stone
fill ~35 ~68 ~81 ~37 ~70 ~81 dirt
fill ~35 ~71 ~81 ~37 ~71 ~81 grass_block
fill ~38 ~60 ~81 ~40 ~66 ~81 stone
fill ~38 ~67 ~81 ~40 ~69 ~81 dirt
fill ~38 ~70 ~81 ~40 ~70 ~81 grass_block
fill ~41 ~60 ~81 ~42 ~67 ~81 stone
fill ~41 ~68 ~81 ~42 ~70 ~81 dirt
fill ~41 ~71 ~81 ~42 ~71 ~81 grass_block
fill ~43 ~60 ~81 ~47 ~68 ~81 stone
fill ~43 ~69 ~81 ~47 ~71 ~81 dirt
fill ~43 ~72 ~81 ~47 ~72 ~81 grass_block
fill ~32 ~60 ~82 ~34 ~68 ~82 stone
fill ~32 ~69 ~82 ~34 ~71 ~82 dirt
fill ~32 ~72 ~82 ~34 ~72 ~82 grass_block
fill ~35 ~60 ~82 ~37 ~67 ~82 stone
fill ~35 ~68 ~82 ~37 ~70 ~82 dirt
fill ~35 ~71 ~82 ~37 ~71 ~82 grass_block
fill ~38 ~60 ~82 ~41 ~66 ~82 stone
fill ~38 ~67 ~82 ~41 ~69 ~82 dirt
fill ~38 ~70 ~82 ~41 ~70 ~82 grass_block
fill ~42 ~60 ~82 ~44 ~67 ~82 stone
fill ~42 ~68 ~82 ~44 ~70 ~82 dirt
fill ~42 ~71 ~82 ~44 ~71 ~82 grass_block
fill ~45 ~60 ~82 ~45 ~68 ~82 stone
fill ~45 ~69 ~82 ~45 ~71 ~82 dirt
fill ~45 ~72 ~82 ~45 ~72 ~82 grass_block
fill ~46 ~60 ~82 ~47 ~67 ~82 stone
fill ~46 ~68 ~82 ~47 ~70 ~82 dirt
fill ~46 ~71 ~82 ~47 ~71 ~82 grass_block
fill ~32 ~60 ~83 ~37 ~67 ~83 stone
fill ~32 ~68 ~83 ~37 ~70 ~83 dirt
fill ~32 ~71 ~83 ~37 ~71 ~83 grass_block
fill ~38 ~60 ~83 ~43 ~66 ~83 stone
fill ~38 ~67 ~83 ~43 ~69 ~83 dirt
fill ~38 ~70 ~83 ~43 ~70 ~83 grass_block
fill ~44 ~60 ~83 ~47 ~67 ~83 stone
fill ~44 ~68 ~83 ~47 ~70 ~83 dirt
fill ~44 ~71 ~83 ~47 ~71 ~83 grass_block
fill ~32 ~60 ~84 ~32 ~67 ~84 stone
fill ~32 ~68 ~84 ~32 ~70 ~84 dirt
fill ~32 ~71 ~84 ~32 ~71 ~84 grass_block
fill ~33 ~60 ~84 ~33 ~66 ~84 stone
fill ~33 ~67 ~84 ~33 ~69 ~84 dirt
fill ~33 ~70 ~84 ~33 ~70 ~84 grass_block
fill ~34 ~60 ~84 ~37 ~67 ~84 stone
fill ~34 ~68 ~84 ~37 ~70 ~84 dirt
fill ~34 ~71 ~84 ~37 ~71 ~84 grass_block
fill ~38 ~60 ~84 ~39 ~66 ~84 stone
fill ~38 ~67 ~84 ~39 ~69 ~84 dirt
fill ~38 ~70 ~84 ~39 ~70 ~84 grass_block
fill ~40 ~60 ~84 ~41 ~65 ~84 stone
fill ~40 ~66 ~84 ~41 ~68 ~84 dirt
fill ~40 ~69 ~84 ~41 ~69 ~84 grass_block
fill ~42 ~60 ~84 ~46 ~66 ~84 stone
fill ~42 ~67 ~84 ~46 ~69 ~84 dirt
fill ~42 ~70 ~84 ~46 ~70 ~84 grass_block
fill ~47 ~60 ~84 ~47 ~67 ~84 stone
fill ~47 ~68 ~84 ~47 ~70 ~84 dirt
fill ~47 ~71 ~84 ~47 ~71 ~84 grass_block
fill ~32 ~60 ~85 ~36 ~66 ~85 stone
fill ~32 ~67 ~85 ~36 ~69 ~85 dirt
fill ~32 ~70 ~85 ~36 ~70 ~85 grass_block
fill ~37 ~60 ~85 ~38 ~67 ~85 stone
fill ~37 ~68 ~85 ~38 ~70 ~85 dirt
fill ~37 ~71 ~85 ~38 ~71 ~85 grass_block
fill ~39 ~60 ~85 ~40 ~66 ~85 stone
fill ~39 ~67 ~85 ~40 ~69 ~85 dirt
fill ~39 ~70 ~85 ~40 ~70 ~85 grass_block
fill ~41 ~60 ~85 ~42 ~65 ~85 stone
fill ~41 ~66 ~85 ~42 ~68 ~85 dirt
fill ~41 ~69 ~85 ~42 ~69 ~85 grass_block
fill ~43 ~60 ~85 ~46 ~66 ~85 stone
fill ~43 ~67 ~85 ~46 ~69 ~85 dirt
fill ~43 ~70 ~85 ~46 ~70 ~85 grass_block
fill ~47 ~60 ~85 ~47 ~67 ~85 stone
fill ~47 ~68 ~85 ~47 ~70 ~85 dirt
fill ~47 ~71 ~85 ~47 ~71 ~85 grass_block
fill ~32 ~60 ~86 ~32 ~66 ~86 stone
fill ~32 ~67 ~86 ~32 ~69 ~86 dirt
fill ~32 ~70 ~86 ~32 ~70 ~86 grass_block
fill ~33 ~60 ~86 ~35 ~65 ~86 stone
fill ~33 ~66 ~86 ~35 ~68 ~86 dirt
fill ~33 ~69 ~86 ~35 ~69 ~86 grass_block
fill ~36 ~60 ~86 ~40 ~66 ~86 stone
fill ~36 ~67 ~86 ~40 ~69 ~86 dirt
fill ~36 ~70 ~86 ~40 ~70 ~86 grass_block
fill ~41 ~60 ~86 ~44 ~65 ~86 stone
fill ~41 ~66 ~86 ~44 ~68 ~86 dirt
fill ~41 ~69 ~86 ~44 ~69 ~86 grass_block
fill ~45 ~60 ~86 ~46 ~66 ~86 stone
fill ~45 ~67 ~86 ~46 ~69 ~86 dirt
fill ~45 ~70 ~86 ~46 ~70 ~86 grass_block
fill ~47 ~60 ~86 ~47 ~67 ~86 stone
fill ~47 ~68 ~86 ~47 ~70 ~86 dirt
fill ~47 ~71 ~86 ~47 ~71 ~86 grass_block
fill ~32 ~60 ~87 ~32 ~66 ~87 stone
fill ~32 ~67 ~87 ~32 ~69 ~87 dirt
fill ~32 ~70 ~87 ~32 ~70 ~87 grass_block
fill ~33 ~60 ~87 ~36 ~65 ~87 stone
fill ~33 ~66 ~87 ~36 ~68 ~87 dirt
fill ~33 ~69 ~87 ~36 ~69 ~87 grass_block
fill ~37 ~60 ~87 ~40 ~66 ~87 stone
fill ~37 ~67 ~87 ~40 ~69 ~87 dirt
fill ~37 ~70 ~87 ~40 ~70 ~87 grass_block
fill ~41 ~60 ~87 ~44 ~65 ~87 stone
fill ~41 ~66 ~87 ~44 ~68 ~87 dirt
fill ~41 ~69 ~87 ~44 ~69 ~87 grass_block
fill ~45 ~60 ~87 ~46 ~66 ~87 stone
fill ~45 ~67 ~87 ~46 ~69 ~87 dirt
fill ~45 ~70 ~87 ~46 ~70 ~87 grass_block
fill ~47 ~60 ~87 ~47 ~67 ~87 stone
fill ~47 ~68 ~87 ~47 ~70 ~87 dirt
fill ~47 ~71 ~87 ~47 ~71 ~87 grass_block
fill ~32 ~60 ~88 ~32 ~66 ~88 stone
fill ~32 ~67 ~88 ~32 ~69 ~88 dirt
fill ~32 ~70 ~88 ~32 ~70 ~88 grass_block
fill ~33 ~60 ~88 ~36 ~65 ~88 stone
fill ~33 ~66 ~88 ~36 ~68 ~88 dirt
fill ~33 ~69 ~88 ~36 ~69 ~88 grass_block
fill ~37 ~60 ~88 ~40 ~66 ~88 stone
fill ~37 ~67 ~88 ~40 ~69 ~88 dirt
fill ~37 ~70 ~88 ~40 ~70 ~88 grass_block
fill ~41 ~60 ~88 ~45 ~65 ~88 stone
fill ~41 ~66 ~88 ~45 ~68 ~88 dirt
fill ~41 ~69 ~88 ~45 ~69 ~88 grass_block
fill ~46 ~60 ~88 ~47 ~66 ~88 stone
fill ~46 ~67 ~88 ~47 ~69 ~88 dirt
fill ~46 ~70 ~88 ~47 ~70 ~88 grass_block
fill ~32 ~60 ~89 ~32 ~66 ~89 stone
fill ~32 ~67 ~89 ~32 ~69 ~89 dirt
fill ~32 ~70 ~89 ~32 ~70 ~89 grass_block
fill ~33 ~60 ~89 ~37 ~65 ~89 stone
fill ~33 ~66 ~89 ~37 ~68 ~89 dirt
fill ~33 ~69 ~89 ~37 ~69 ~89 grass_block
fill ~38 ~60 ~89 ~41 ~66 ~89 stone
fill ~38 ~67 ~89 ~41 ~69 ~89 dirt
fill ~38 ~70 ~89 ~41 ~70 ~89 grass_block
fill ~42 ~60 ~89 ~46 ~65 ~89 stone
fill ~42 ~66 ~89 ~46 ~68 ~89 dirt
fill ~42 ~69 ~89 ~46 ~69 ~89 grass_block
fill ~47 ~60 ~89 ~47 ~66 ~89 stone
fill ~47 ~67 ~89 ~47 ~69 ~89 dirt
fill ~47 ~70 ~89 ~47 ~70 ~89 grass_block
fill ~32 ~60 ~90 ~38 ~65 ~90 stone
fill ~32 ~66 ~90 ~38 ~68 ~90 dirt
fill ~32 ~69 ~90 ~38 ~69 ~90 grass_block
fill ~39 ~60 ~90 ~41 ~66 ~90 stone
fill ~39 ~67 ~90 ~41 ~69 ~90 dirt
fill ~39 ~70 ~90 ~41 ~70 ~90 grass_block
fill ~42 ~60 ~90 ~47 ~65 ~90 stone
fill ~42 ~66 ~90 ~47 ~68 ~90 dirt
fill ~42 ~69 ~90 ~47 ~69 ~90 grass_block
fill ~32 ~60 ~91 ~34 ~65 ~91 stone
fill ~32 ~66 ~91 ~34 ~68 ~91 dirt
fill ~32 ~69 ~91 ~34 ~69 ~91 grass_block
fill ~35 ~60 ~91 ~36 ~64 ~91 stone
fill ~35 ~65 ~91 ~36 ~67 ~91 dirt
fill ~35 ~68 ~91 ~36 ~68 ~91 grass_block
fill ~37 ~60 ~91 ~38 ~65 ~91 stone
fill ~37 ~66 ~91 ~38 ~68 ~91 dirt
fill ~37 ~69 ~91 ~38 ~69 ~91 grass_block
fill ~39 ~60 ~91 ~41 ~66 ~91 stone
fill ~39 ~67 ~91 ~41 ~69 ~91 dirt
fill ~39 ~70 ~91 ~41 ~70 ~91 grass_block
fill ~42 ~60 ~91 ~44 ~65 ~91 stone
fill ~42 ~66 ~91 ~44 ~68 ~91 dirt
fill ~42 ~69 ~91 ~44 ~69 ~91 grass_block
fill ~45 ~60 ~91 ~45 ~64 ~91 stone
fill ~45 ~65 ~91 ~45 ~67 ~91 dirt
fill ~45 ~68 ~91 ~45 ~68 ~91 grass_block
fill ~46 ~60 ~91 ~47 ~65 ~91 stone
fill ~46 ~66 ~91 ~47 ~68 ~91 dirt
fill ~46 ~69 ~91 ~47 ~69 ~91 grass_block
fill ~32 ~60 ~92 ~34 ~65 ~92 stone
fill ~32 ~66 ~92 ~34 ~68 ~92 dirt
fill ~32 ~69 ~92 ~34 ~69 ~92 grass_block
fill ~35 ~60 ~92 ~36 ~64 ~92 stone
fill ~35 ~65 ~92 ~36 ~67 ~92 dirt
fill ~35 ~68 ~92 ~36 ~68 ~92 grass_block
fill ~37 ~60 ~92 ~38 ~65 ~92 stone
fill ~37 ~66 ~92 ~38 ~68 ~92 dirt
fill ~37 ~69 ~92 ~38 ~69 ~92 grass_block
fill ~39 ~60 ~92 ~42 ~66 ~92 stone
fill ~39 ~67 ~92 ~42 ~69 ~92 dirt
fill ~39 ~70 ~92 ~42 ~70 ~92 grass_block
fill ~43 ~60 ~92 ~44 ~65 ~92 stone
fill ~43 ~66 ~92 ~44 ~68 ~92 dirt
fill ~43 ~69 ~92 ~44 ~69 ~92 grass_block
fill ~45 ~60 ~92 ~46 ~64 ~92 stone
fill ~45 ~65 ~92 ~46 ~67 ~92 dirt
fill ~45 ~68 ~92 ~46 ~68 ~92 grass_block
fill ~47 ~60 ~92 ~47 ~65 ~92 stone
fill ~47 ~66 ~92 ~47 ~68 ~92 dirt
fill ~47 ~69 ~92 ~47 ~69 ~92 grass_block
fill ~32 ~60 ~93 ~34 ~65 ~93 stone
fill ~32 ~66 ~93 ~34 ~68 ~93 dirt
fill ~32 ~69 ~93 ~34 ~69 ~93 grass_block
fill ~35 ~60 ~93 ~36 ~64 ~93 stone
fill ~35 ~65 ~93 ~36 ~67 ~93 dirt
fill ~35 ~68 ~93 ~36 ~68 ~93 grass_block
fill ~37 ~60 ~93 ~38 ~65 ~93 stone
fill ~37 ~66 ~93 ~38 ~68 ~93 dirt
fill ~37 ~69 ~93 ~38 ~69 ~93 grass_block
fill ~39 ~60 ~93 ~43 ~66 ~93 stone
fill ~39 ~67 ~93 ~43 ~69 ~93 dirt
fill ~39 ~70 ~93 ~43 ~70 ~93 grass_block
fill ~44 ~60 ~93 ~45 ~65 ~93 stone
fill ~44 ~66 ~93 ~45 ~68 ~93 dirt
fill ~44 ~69 ~93 ~45 ~69 ~93 grass_block
fill ~46 ~60 ~93 ~47 ~64 ~93 stone
fill ~46 ~65 ~93 ~47 ~67 ~93 dirt
fill ~46 ~68 ~93 ~47 ~68 ~93 grass_block
fill ~32 ~60 ~94 ~37 ~64 ~94 stone
fill ~32 ~65 ~94 ~37 ~67 ~94 dirt
fill ~32 ~68 ~94 ~37 ~68 ~94 grass_block
fill ~38 ~60 ~94 ~38 ~65 ~94 stone
fill ~38 ~66 ~94 ~38 ~68 ~94 dirt
fill ~38 ~69 ~94 ~38 ~69 ~94 grass_block
fill ~39 ~60 ~94 ~43 ~66 ~94 stone
fill ~39 ~67 ~94 ~43 ~69 ~94 dirt
fill ~39 ~70 ~94 ~43 ~70 ~94 grass_block
fill ~44 ~60 ~94 ~46 ~65 ~94 stone
fill ~44 ~66 ~94 ~46 ~68 ~94 dirt
fill ~44 ~69 ~94 ~46 ~69 ~94 grass_block
fill ~47 ~60 ~94 ~47 ~64 ~94 stone
fill ~47 ~65 ~94 ~47 ~67 ~94 dirt
fill ~47 ~68 ~94 ~47 ~68 ~94 grass_block
fill ~32 ~60 ~95 ~32 ~63 ~95 stone
fill ~32 ~64 ~95 ~32 ~66 ~95 dirt
fill ~32 ~67 ~95 ~32 ~67 ~95 grass_block
fill ~33 ~60 ~95 ~37 ~64 ~95 stone
fill ~33 ~65 ~95 ~37 ~67 ~95 dirt
fill ~33 ~68 ~95 ~37 ~68 ~95 grass_block
fill ~38 ~60 ~95 ~40 ~65 ~95 stone
fill ~38 ~66 ~95 ~40 ~68 ~95 dirt
fill ~38 ~69 ~95 ~40 ~69 ~95 grass_block
fill ~41 ~60 ~95 ~44 ~66 ~95 stone
fill ~41 ~67 ~95 ~44 ~69 ~95 dirt
fill ~41 ~70 ~95 ~44 ~70 ~95 grass_block
fill ~45 ~60 ~95 ~46 ~65 ~95 stone
fill ~45 ~66 ~95 ~46 ~68 ~95 dirt
fill ~45 ~69 ~95 ~46 ~69 ~95 grass_block
fill ~47 ~60 ~95 ~47 ~64 ~95 stone
fill ~47 ~65 ~95 ~47 ~67 ~95 dirt
fill ~47 ~68 ~95 ~47 ~68 ~95 grass_block