fill ~112 ~60 ~64 ~118 ~63 ~64 stone
fill ~112 ~64 ~64 ~118 ~66 ~64 dirt
fill ~112 ~67 ~64 ~118 ~67 ~64 grass_block
fill ~119 ~60 ~64 ~120 ~64 ~64 stone
fill ~119 ~65 ~64 ~120 ~67 ~64 dirt
fill ~119 ~68 ~64 ~120 ~68 ~64 grass_block
fill ~121 ~60 ~64 ~127 ~65 ~64 stone
fill ~121 ~66 ~64 ~127 ~68 ~64 dirt
fill ~121 ~69 ~64 ~127 ~69 ~64 grass_block
fill ~112 ~60 ~65 ~117 ~63 ~65 stone
fill ~112 ~64 ~65 ~117 ~66 ~65 dirt
fill ~112 ~67 ~65 ~117 ~67 ~65 grass_block
fill ~118 ~60 ~65 ~120 ~64 ~65 stone
fill ~118 ~65 ~65 ~120 ~67 ~65 dirt
fill ~118 ~68 ~65 ~120 ~68 ~65 grass_block
fill ~121 ~60 ~65 ~126 ~65 ~65 stone
fill ~121 ~66 ~65 ~126 ~68 ~65 dirt
fill ~121 ~69 ~65 ~126 ~69 ~65 grass_block
fill ~127 ~60 ~65 ~127 ~64 ~65 stone
fill ~127 ~65 ~65 ~127 ~67 ~65 dirt
fill ~127 ~68 ~65 ~127 ~68 ~65 grass_block
fill ~112 ~60 ~66 ~118 ~63 ~66 stone
fill ~112 ~64 ~66 ~118 ~66 ~66 dirt
fill ~112 ~67 ~66 ~118 ~67 ~66 grass_block
fill ~119 ~60 ~66 ~121 ~64 ~66 stone
fill ~119 ~65 ~66 ~121 ~67 ~66 dirt
fill ~119 ~68 ~66 ~121 ~68 ~66 grass_block
fill ~122 ~60 ~66 ~126 ~65 ~66 stone
fill ~122 ~66 ~66 ~126 ~68 ~66 dirt
fill ~122 ~69 ~66 ~126 ~69 ~66 grass_block
fill ~127 ~60 ~66 ~127 ~64 ~66 stone
fill ~127 ~65 ~66 ~127 ~67 ~66 dirt
fill ~127 ~68 ~66 ~127 ~68 ~66 grass_block
fill ~112 ~60 ~67 ~118 ~63 ~67 stone
fill ~112 ~64 ~67 ~118 ~66 ~67 dirt
fill ~112 ~67 ~67 ~118 ~67 ~67 grass_block
fill ~119 ~60 ~67 ~122 ~64 ~67 stone
fill ~119 ~65 ~67 ~122 ~67 ~67 dirt
fill ~119 ~68 ~67 ~122 ~68 ~67 grass_block
fill ~123 ~60 ~67 ~125 ~65 ~67 stone
fill ~123 ~66 ~67 ~125 ~68 ~67 dirt
fill ~123 ~69 ~67 ~125 ~69 ~67 grass_block
fill ~126 ~60 ~67 ~127 ~64 ~67 stone
fill ~126 ~65 ~67 ~127 ~67 ~67 dirt
fill ~126 ~68 ~67 ~127 ~68 ~67 grass_block
fill ~112 ~60 ~68 ~118 ~63 ~68 stone
fill ~112 ~64 ~68 ~118 ~66 ~68 dirt
fill ~112 ~67 ~68 ~118 ~67 ~68 grass_block
fill ~119 ~60 ~68 ~127 ~64 ~68 stone
fill ~119 ~65 ~68 ~127 ~67 ~68 dirt
fill ~119 ~68 ~68 ~127 ~68 ~68 grass_block
fill ~112 ~60 ~69 ~112 ~62 ~69 stone
fill ~112 ~63 ~69 ~112 ~65 ~69 dirt
fill ~112 ~66 ~69 ~112 ~66 ~69 grass_block
fill ~113 ~60 ~69 ~119 ~63 ~69 stone
fill ~113 ~64 ~69 ~119 ~66 ~69 dirt
fill ~113 ~67 ~69 ~119 ~67 ~69 grass_block
fill ~120 ~60 ~69 ~127 ~64 ~69 stone
fill ~120 ~65 ~69 ~127 ~67 ~69 dirt
fill ~120 ~68 ~69 ~127 ~68 ~69 grass_block
fill ~112 ~60 ~70 ~113 ~63 ~70 stone
fill ~112 ~64 ~70 ~113 ~66 ~70 dirt
fill ~112 ~67 ~70 ~113 ~67 ~70 grass_block
fill ~114 ~60 ~70 ~114 ~62 ~70 stone
fill ~114 ~63 ~70 ~114 ~65 ~70 dirt
fill ~114 ~66 ~70 ~114 ~66 ~70 grass_block
fill ~115 ~60 ~70 ~119 ~63 ~70 stone
fill ~115 ~64 ~70 ~119 ~66 ~70 dirt
fill ~115 ~67 ~70 ~119 ~67 ~70 grass_block
fill ~120 ~60 ~70 ~127 ~64 ~70 stone
fill ~120 ~65 ~70 ~127 ~67 ~70 dirt
fill ~120 ~68 ~70 ~127 ~68 ~70 grass_block
fill ~112 ~60 ~71 ~112 ~62 ~71 stone
fill ~112 ~63 ~71 ~112 ~65 ~71 dirt
fill ~112 ~66 ~71 ~112 ~66 ~71 grass_block
fill ~113 ~60 ~71 ~119 ~63 ~71 stone
fill ~113 ~64 ~71 ~119 ~66 ~71 dirt
fill ~113 ~67 ~71 ~119 ~67 ~71 grass_block
fill ~120 ~60 ~71 ~126 ~64 ~71 stone
fill ~120 ~65 ~71 ~126 ~67 ~71 dirt
fill ~120 ~68 ~71 ~126 ~68 ~71 grass_block
fill ~127 ~60 ~71 ~127 ~63 ~71 stone
fill ~127 ~64 ~71 ~127 ~66 ~71 dirt
fill ~127 ~67 ~71 ~127 ~67 ~71 grass_block
fill ~112 ~60 ~72 ~115 ~62 ~72 stone
fill ~112 ~63 ~72 ~115 ~65 ~72 dirt
fill ~112 ~66 ~72 ~115 ~66 ~72 grass_block
fill ~116 ~60 ~72 ~120 ~63 ~72 stone
fill ~116 ~64 ~72 ~120 ~66 ~72 dirt
fill ~116 ~67 ~72 ~120 ~67 ~72 grass_block
fill ~121 ~60 ~72 ~126 ~64 ~72 stone
fill ~121 ~65 ~72 ~126 ~67 ~72 dirt
fill ~121 ~68 ~72 ~126 ~68 ~72 grass_block
fill ~127 ~60 ~72 ~127 ~63 ~72 stone
fill ~127 ~64 ~72 ~127 ~66 ~72 dirt
fill ~127 ~67 ~72 ~127 ~67 ~72 grass_block
fill ~112 ~60 ~73 ~117 ~62 ~73 stone
fill ~112 ~63 ~73 ~117 ~65 ~73 dirt
fill ~112 ~66 ~73 ~117 ~66 ~73 grass_block
fill ~118 ~60 ~73 ~122 ~63 ~73 stone
fill ~118 ~64 ~73 ~122 ~66 ~73 dirt
fill ~118 ~67 ~73 ~122 ~67 ~73 grass_block
fill ~123 ~60 ~73 ~126 ~64 ~73 stone
fill ~123 ~65 ~73 ~126 ~67 ~73 dirt
fill ~123 ~68 ~73 ~126 ~68 ~73 grass_block
fill ~127 ~60 ~73 ~127 ~63 ~73 stone
fill ~127 ~64 ~73 ~127 ~66 ~73 dirt
fill ~127 ~67 ~73 ~127 ~67 ~73 grass_block
fill ~112 ~60 ~74 ~113 ~63 ~74 stone
fill ~112 ~64 ~74 ~113 ~66 ~74 dirt
fill ~112 ~67 ~74 ~113 ~67 ~74 grass_block
fill ~114 ~60 ~74 ~117 ~62 ~74 stone
fill ~114 ~63 ~74 ~117 ~65 ~74 dirt
fill ~114 ~66 ~74 ~117 ~66 ~74 grass_block
fill ~118 ~60 ~74 ~127 ~63 ~74 stone
fill ~118 ~64 ~74 ~127 ~66 ~74 dirt
fill ~118 ~67 ~74 ~127 ~67 ~74 grass_block
fill ~112 ~60 ~75 ~113 ~63 ~75 stone
fill ~112 ~64 ~75 ~113 ~66 ~75 dirt
fill ~112 ~67 ~75 ~113 ~67 ~75 grass_block
fill ~114 ~60 ~75 ~118 ~62 ~75 stone
fill ~114 ~63 ~75 ~118 ~65 ~75 dirt
fill ~114 ~66 ~75 ~118 ~66 ~75 grass_block
fill ~119 ~60 ~75 ~127 ~63 ~75 stone
fill ~119 ~64 ~75 ~127 ~66 ~75 dirt
fill ~119 ~67 ~75 ~127 ~67 ~75 grass_block
fill ~112 ~60 ~76 ~113 ~63 ~76 stone
fill ~112 ~64 ~76 ~113 ~66 ~76 dirt
fill ~112 ~67 ~76 ~113 ~67 ~76 grass_block
fill ~114 ~60 ~76 ~119 ~62 ~76 stone
fill ~114 ~63 ~76 ~119 ~65 ~76 dirt
fill ~114 ~66 ~76 ~119 ~66 ~76 grass_block
fill ~120 ~60 ~76 ~127 ~63 ~76 stone
fill ~120 ~64 ~76 ~127 ~66 ~76 dirt
fill ~120 ~67 ~76 ~127 ~67 ~76 grass_block
fill ~112 ~60 ~77 ~112 ~63 ~77 stone
fill ~112 ~64 ~77 ~112 ~66 ~77 dirt
fill ~112 ~67 ~77 ~112 ~67 ~77 grass_block
fill ~113 ~60 ~77 ~120 ~62 ~77 stone
fill ~113 ~63 ~77 ~120 ~65 ~77 dirt
fill ~113 ~66 ~77 ~120 ~66 ~77 grass_block
fill ~121 ~60 ~77 ~126 ~63 ~77 stone
fill ~121 ~64 ~77 ~126 ~66 ~77 dirt
fill ~121 ~67 ~77 ~126 ~67 ~77 grass_block
fill ~127 ~60 ~77 ~127 ~64 ~77 stone
fill ~127 ~65 ~77 ~127 ~67 ~77 dirt
fill ~127 ~68 ~77 ~127 ~68 ~77 grass_block
fill ~112 ~60 ~78 ~113 ~63 ~78 stone
fill ~112 ~64 ~78 ~113 ~66 ~78 dirt
fill ~112 ~67 ~78 ~113 ~67 ~78 grass_block
fill ~114 ~60 ~78 ~121 ~62 ~78 stone
fill ~114 ~63 ~78 ~121 ~65 ~78 dirt
fill ~114 ~66 ~78 ~121 ~66 ~78 grass_block
fill ~122 ~60 ~78 ~126 ~63 ~78 stone
fill ~122 ~64 ~78 ~126 ~66 ~78 dirt
fill ~122 ~67 ~78 ~126 ~67 ~78 grass_block
fill ~127 ~60 ~78 ~127 ~64 ~78 stone
fill ~127 ~65 ~78 ~127 ~67 ~78 dirt
fill ~127 ~68 ~78 ~127 ~68 ~78 grass_block
fill ~112 ~60 ~79 ~115 ~63 ~79 stone
fill ~112 ~64 ~79 ~115 ~66 ~79 dirt
fill ~112 ~67 ~79 ~115 ~67 ~79 grass_block
fill ~116 ~60 ~79 ~122 ~62 ~79 stone
fill ~116 ~63 ~79 ~122 ~65 ~79 dirt
fill ~116 ~66 ~79 ~122 ~66 ~79 grass_block
fill ~123 ~60 ~79 ~126 ~63 ~79 stone
fill ~123 ~64 ~79 ~126 ~66 ~79 dirt
fill ~123 ~67 ~79 ~126 ~67 ~79 grass_block
fill ~127 ~60 ~79 ~127 ~64 ~79 stone
fill ~127 ~65 ~79 ~127 ~67 ~79 dirt
fill ~127 ~68 ~79 ~127 ~68 ~79 grass_block