fill ~352 ~60 ~64 ~352 ~64 ~64 stone
fill ~352 ~65 ~64 ~352 ~67 ~64 dirt
fill ~352 ~68 ~64 ~352 ~68 ~64 grass_block
fill ~353 ~60 ~64 ~363 ~65 ~64 stone
fill ~353 ~66 ~64 ~363 ~68 ~64 dirt
fill ~353 ~69 ~64 ~363 ~69 ~64 grass_block
fill ~364 ~60 ~64 ~366 ~64 ~64 stone
fill ~364 ~65 ~64 ~366 ~67 ~64 dirt
fill ~364 ~68 ~64 ~366 ~68 ~64 grass_block
fill ~367 ~60 ~64 ~367 ~63 ~64 stone
fill ~367 ~64 ~64 ~367 ~66 ~64 dirt
fill ~367 ~67 ~64 ~367 ~67 ~64 grass_block
fill ~352 ~60 ~65 ~354 ~64 ~65 stone
fill ~352 ~65 ~65 ~354 ~67 ~65 dirt
fill ~352 ~68 ~65 ~354 ~68 ~65 grass_block
fill ~355 ~60 ~65 ~363 ~65 ~65 stone
fill ~355 ~66 ~65 ~363 ~68 ~65 dirt
fill ~355 ~69 ~65 ~363 ~69 ~65 grass_block
fill ~364 ~60 ~65 ~366 ~64 ~65 stone
fill ~364 ~65 ~65 ~366 ~67 ~65 dirt
fill ~364 ~68 ~65 ~366 ~68 ~65 grass_block
fill ~367 ~60 ~65 ~367 ~63 ~65 stone
fill ~367 ~64 ~65 ~367 ~66 ~65 dirt
fill ~367 ~67 ~65 ~367 ~67 ~65 grass_block
fill ~352 ~60 ~66 ~356 ~64 ~66 stone
fill ~352 ~65 ~66 ~356 ~67 ~66 dirt
fill ~352 ~68 ~66 ~356 ~68 ~66 grass_block
fill ~357 ~60 ~66 ~363 ~65 ~66 stone
fill ~357 ~66 ~66 ~363 ~68 ~66 dirt
fill ~357 ~69 ~66 ~363 ~69 ~66 grass_block
fill ~364 ~60 ~66 ~367 ~64 ~66 stone
fill ~364 ~65 ~66 ~367 ~67 ~66 dirt
fill ~364 ~68 ~66 ~367 ~68 ~66 grass_block
fill ~352 ~60 ~67 ~358 ~64 ~67 stone
fill ~352 ~65 ~67 ~358 ~67 ~67 dirt
fill ~352 ~68 ~67 ~358 ~68 ~67 grass_block
fill ~359 ~60 ~67 ~364 ~65 ~67 stone
fill ~359 ~66 ~67 ~364 ~68 ~67 dirt
fill ~359 ~69 ~67 ~364 ~69 ~67 grass_block
fill ~365 ~60 ~67 ~367 ~64 ~67 stone
fill ~365 ~65 ~67 ~367 ~67 ~67 dirt
fill ~365 ~68 ~67 ~367 ~68 ~67 grass_block
fill ~352 ~60 ~68 ~361 ~64 ~68 stone
fill ~352 ~65 ~68 ~361 ~67 ~68 dirt
fill ~352 ~68 ~68 ~361 ~68 ~68 grass_block
fill ~362 ~60 ~68 ~364 ~65 ~68 stone
fill ~362 ~66 ~68 ~364 ~68 ~68 dirt
fill ~362 ~69 ~68 ~364 ~69 ~68 grass_block
fill ~365 ~60 ~68 ~367 ~64 ~68 stone
fill ~365 ~65 ~68 ~367 ~67 ~68 dirt
fill ~365 ~68 ~68 ~367 ~68 ~68 grass_block
fill ~352 ~60 ~69 ~353 ~65 ~69 stone
fill ~352 ~66 ~69 ~353 ~68 ~69 dirt
fill ~352 ~69 ~69 ~353 ~69 ~69 grass_block
fill ~354 ~60 ~69 ~356 ~64 ~69 stone
fill ~354 ~65 ~69 ~356 ~67 ~69 dirt
fill ~354 ~68 ~69 ~356 ~68 ~69 grass_block
fill ~357 ~60 ~69 ~357 ~63 ~69 stone
fill ~357 ~64 ~69 ~357 ~66 ~69 dirt
fill ~357 ~67 ~69 ~357 ~67 ~69 grass_block
fill ~358 ~60 ~69 ~367 ~64 ~69 stone
fill ~358 ~65 ~69 ~367 ~67 ~69 dirt
fill ~358 ~68 ~69 ~367 ~68 ~69 grass_block
fill ~352 ~60 ~70 ~354 ~65 ~70 stone
fill ~352 ~66 ~70 ~354 ~68 ~70 dirt
fill ~352 ~69 ~70 ~354 ~69 ~70 grass_block
fill ~355 ~60 ~70 ~357 ~64 ~70 stone
fill ~355 ~65 ~70 ~357 ~67 ~70 dirt
fill ~355 ~68 ~70 ~357 ~68 ~70 grass_block
fill ~358 ~60 ~70 ~360 ~63 ~70 stone
fill ~358 ~64 ~70 ~360 ~66 ~70 dirt
fill ~358 ~67 ~70 ~360 ~67 ~70 grass_block
fill ~361 ~60 ~70 ~367 ~64 ~70 stone
fill ~361 ~65 ~70 ~367 ~67 ~70 dirt
fill ~361 ~68 ~70 ~367 ~68 ~70 grass_block
fill ~352 ~60 ~71 ~355 ~65 ~71 stone
fill ~352 ~66 ~71 ~355 ~68 ~71 dirt
fill ~352 ~69 ~71 ~355 ~69 ~71 grass_block
fill ~356 ~60 ~71 ~358 ~64 ~71 stone
fill ~356 ~65 ~71 ~358 ~67 ~71 dirt
fill ~356 ~68 ~71 ~358 ~68 ~71 grass_block
fill ~359 ~60 ~71 ~364 ~63 ~71 stone
fill ~359 ~64 ~71 ~364 ~66 ~71 dirt
fill ~359 ~67 ~71 ~364 ~67 ~71 grass_block
fill ~365 ~60 ~71 ~367 ~64 ~71 stone
fill ~365 ~65 ~71 ~367 ~67 ~71 dirt
fill ~365 ~68 ~71 ~367 ~68 ~71 grass_block
fill ~352 ~60 ~72 ~356 ~65 ~72 stone
fill ~352 ~66 ~72 ~356 ~68 ~72 dirt
fill ~352 ~69 ~72 ~356 ~69 ~72 grass_block
fill ~357 ~60 ~72 ~359 ~64 ~72 stone
fill ~357 ~65 ~72 ~359 ~67 ~72 dirt
fill ~357 ~68 ~72 ~359 ~68 ~72 grass_block
fill ~360 ~60 ~72 ~367 ~63 ~72 stone
fill ~360 ~64 ~72 ~367 ~66 ~72 dirt
fill ~360 ~67 ~72 ~367 ~67 ~72 grass_block
fill ~352 ~60 ~73 ~357 ~65 ~73 stone
fill ~352 ~66 ~73 ~357 ~68 ~73 dirt
fill ~352 ~69 ~73 ~357 ~69 ~73 grass_block
fill ~358 ~60 ~73 ~362 ~64 ~73 stone
fill ~358 ~65 ~73 ~362 ~67 ~73 dirt
fill ~358 ~68 ~73 ~362 ~68 ~73 grass_block
fill ~363 ~60 ~73 ~367 ~63 ~73 stone
fill ~363 ~64 ~73 ~367 ~66 ~73 dirt
fill ~363 ~67 ~73 ~367 ~67 ~73 grass_block
fill ~352 ~60 ~74 ~360 ~65 ~74 stone
fill ~352 ~66 ~74 ~360 ~68 ~74 dirt
fill ~352 ~69 ~74 ~360 ~69 ~74 grass_block
fill ~361 ~60 ~74 ~364 ~64 ~74 stone
fill ~361 ~65 ~74 ~364 ~67 ~74 dirt
fill ~361 ~68 ~74 ~364 ~68 ~74 grass_block
fill ~365 ~60 ~74 ~367 ~63 ~74 stone
fill ~365 ~64 ~74 ~367 ~66 ~74 dirt
fill ~365 ~67 ~74 ~367 ~67 ~74 grass_block
fill ~352 ~60 ~75 ~362 ~65 ~75 stone
fill ~352 ~66 ~75 ~362 ~68 ~75 dirt
fill ~352 ~69 ~75 ~362 ~69 ~75 grass_block
fill ~363 ~60 ~75 ~365 ~64 ~75 stone
fill ~363 ~65 ~75 ~365 ~67 ~75 dirt
fill ~363 ~68 ~75 ~365 ~68 ~75 grass_block
fill ~366 ~60 ~75 ~367 ~63 ~75 stone
fill ~366 ~64 ~75 ~367 ~66 ~75 dirt
fill ~366 ~67 ~75 ~367 ~67 ~75 grass_block
fill ~352 ~60 ~76 ~352 ~64 ~76 stone
fill ~352 ~65 ~76 ~352 ~67 ~76 dirt
fill ~352 ~68 ~76 ~352 ~68 ~76 grass_block
fill ~353 ~60 ~76 ~363 ~65 ~76 stone
fill ~353 ~66 ~76 ~363 ~68 ~76 dirt
fill ~353 ~69 ~76 ~363 ~69 ~76 grass_block
fill ~364 ~60 ~76 ~367 ~64 ~76 stone
fill ~364 ~65 ~76 ~367 ~67 ~76 dirt
fill ~364 ~68 ~76 ~367 ~68 ~76 grass_block
fill ~352 ~60 ~77 ~353 ~64 ~77 stone
fill ~352 ~65 ~77 ~353 ~67 ~77 dirt
fill ~352 ~68 ~77 ~353 ~68 ~77 grass_block
fill ~354 ~60 ~77 ~364 ~65 ~77 stone
fill ~354 ~66 ~77 ~364 ~68 ~77 dirt
fill ~354 ~69 ~77 ~364 ~69 ~77 grass_block
fill ~365 ~60 ~77 ~367 ~64 ~77 stone
fill ~365 ~65 ~77 ~367 ~67 ~77 dirt
fill ~365 ~68 ~77 ~367 ~68 ~77 grass_block
fill ~352 ~60 ~78 ~354 ~64 ~78 stone
fill ~352 ~65 ~78 ~354 ~67 ~78 dirt
fill ~352 ~68 ~78 ~354 ~68 ~78 grass_block
fill ~355 ~60 ~78 ~361 ~65 ~78 stone
fill ~355 ~66 ~78 ~361 ~68 ~78 dirt
fill ~355 ~69 ~78 ~361 ~69 ~78 grass_block
fill ~362 ~60 ~78 ~367 ~64 ~78 stone
fill ~362 ~65 ~78 ~367 ~67 ~78 dirt
fill ~362 ~68 ~78 ~367 ~68 ~78 grass_block
fill ~352 ~60 ~79 ~355 ~64 ~79 stone
fill ~352 ~65 ~79 ~355 ~67 ~79 dirt
fill ~352 ~68 ~79 ~355 ~68 ~79 grass_block
fill ~356 ~60 ~79 ~358 ~65 ~79 stone
fill ~356 ~66 ~79 ~358 ~68 ~79 dirt
fill ~356 ~69 ~79 ~358 ~69 ~79 grass_block
fill ~359 ~60 ~79 ~367 ~64 ~79 stone
fill ~359 ~65 ~79 ~367 ~67 ~79 dirt
fill ~359 ~68 ~79 ~367 ~68 ~79 grass_block