fill ~64 ~60 ~64 ~64 ~64 ~64 stone
fill ~64 ~65 ~64 ~64 ~67 ~64 dirt
fill ~64 ~68 ~64 ~64 ~68 ~64 grass_block
fill ~65 ~60 ~64 ~70 ~65 ~64 stone
fill ~65 ~66 ~64 ~70 ~68 ~64 dirt
fill ~65 ~69 ~64 ~70 ~69 ~64 grass_block
fill ~71 ~60 ~64 ~79 ~66 ~64 stone
fill ~71 ~67 ~64 ~79 ~69 ~64 dirt
fill ~71 ~70 ~64 ~79 ~70 ~64 grass_block
fill ~64 ~60 ~65 ~68 ~64 ~65 stone
fill ~64 ~65 ~65 ~68 ~67 ~65 dirt
fill ~64 ~68 ~65 ~68 ~68 ~65 grass_block
fill ~69 ~60 ~65 ~72 ~65 ~65 stone
fill ~69 ~66 ~65 ~72 ~68 ~65 dirt
fill ~69 ~69 ~65 ~72 ~69 ~65 grass_block
fill ~73 ~60 ~65 ~79 ~66 ~65 stone
fill ~73 ~67 ~65 ~79 ~69 ~65 dirt
fill ~73 ~70 ~65 ~79 ~70 ~65 grass_block
fill ~64 ~60 ~66 ~69 ~64 ~66 stone
fill ~64 ~65 ~66 ~69 ~67 ~66 dirt
fill ~64 ~68 ~66 ~69 ~68 ~66 grass_block
fill ~70 ~60 ~66 ~74 ~65 ~66 stone
fill ~70 ~66 ~66 ~74 ~68 ~66 dirt
fill ~70 ~69 ~66 ~74 ~69 ~66 grass_block
fill ~75 ~60 ~66 ~79 ~66 ~66 stone
fill ~75 ~67 ~66 ~79 ~69 ~66 dirt
fill ~75 ~70 ~66 ~79 ~70 ~66 grass_block
fill ~64 ~60 ~67 ~66 ~63 ~67 stone
fill ~64 ~64 ~67 ~66 ~66 ~67 dirt
fill ~64 ~67 ~67 ~66 ~67 ~67 grass_block
fill ~67 ~60 ~67 ~70 ~64 ~67 stone
fill ~67 ~65 ~67 ~70 ~67 ~67 dirt
fill ~67 ~68 ~67 ~70 ~68 ~67 grass_block
fill ~71 ~60 ~67 ~76 ~65 ~67 stone
fill ~71 ~66 ~67 ~76 ~68 ~67 dirt
fill ~71 ~69 ~67 ~76 ~69 ~67 grass_block
fill ~77 ~60 ~67 ~79 ~66 ~67 stone
fill ~77 ~67 ~67 ~79 ~69 ~67 dirt
fill ~77 ~70 ~67 ~79 ~70 ~67 grass_block
fill ~64 ~60 ~68 ~67 ~63 ~68 stone
fill ~64 ~64 ~68 ~67 ~66 ~68 dirt
fill ~64 ~67 ~68 ~67 ~67 ~68 grass_block
fill ~68 ~60 ~68 ~71 ~64 ~68 stone
fill ~68 ~65 ~68 ~71 ~67 ~68 dirt
fill ~68 ~68 ~68 ~71 ~68 ~68 grass_block
fill ~72 ~60 ~68 ~79 ~65 ~68 stone
fill ~72 ~66 ~68 ~79 ~68 ~68 dirt
fill ~72 ~69 ~68 ~79 ~69 ~68 grass_block
fill ~64 ~60 ~69 ~66 ~64 ~69 stone
fill ~64 ~65 ~69 ~66 ~67 ~69 dirt
fill ~64 ~68 ~69 ~66 ~68 ~69 grass_block
fill ~67 ~60 ~69 ~68 ~63 ~69 stone
fill ~67 ~64 ~69 ~68 ~66 ~69 dirt
fill ~67 ~67 ~69 ~68 ~67 ~69 grass_block
fill ~69 ~60 ~69 ~73 ~64 ~69 stone
fill ~69 ~65 ~69 ~73 ~67 ~69 dirt
fill ~69 ~68 ~69 ~73 ~68 ~69 grass_block
fill ~74 ~60 ~69 ~79 ~65 ~69 stone
fill ~74 ~66 ~69 ~79 ~68 ~69 dirt
fill ~74 ~69 ~69 ~79 ~69 ~69 grass_block
fill ~64 ~60 ~70 ~68 ~64 ~70 stone
fill ~64 ~65 ~70 ~68 ~67 ~70 dirt
fill ~64 ~68 ~70 ~68 ~68 ~70 grass_block
fill ~69 ~60 ~70 ~69 ~63 ~70 stone
fill ~69 ~64 ~70 ~69 ~66 ~70 dirt
fill ~69 ~67 ~70 ~69 ~67 ~70 grass_block
fill ~70 ~60 ~70 ~75 ~64 ~70 stone
fill ~70 ~65 ~70 ~75 ~67 ~70 dirt
fill ~70 ~68 ~70 ~75 ~68 ~70 grass_block
fill ~76 ~60 ~70 ~79 ~65 ~70 stone
fill ~76 ~66 ~70 ~79 ~68 ~70 dirt
fill ~76 ~69 ~70 ~79 ~69 ~70 grass_block
fill ~64 ~60 ~71 ~65 ~65 ~71 stone
fill ~64 ~66 ~71 ~65 ~68 ~71 dirt
fill ~64 ~69 ~71 ~65 ~69 ~71 grass_block
fill ~66 ~60 ~71 ~68 ~64 ~71 stone
fill ~66 ~65 ~71 ~68 ~67 ~71 dirt
fill ~66 ~68 ~71 ~68 ~68 ~71 grass_block
fill ~69 ~60 ~71 ~71 ~63 ~71 stone
fill ~69 ~64 ~71 ~71 ~66 ~71 dirt
fill ~69 ~67 ~71 ~71 ~67 ~71 grass_block
fill ~72 ~60 ~71 ~78 ~64 ~71 stone
fill ~72 ~65 ~71 ~78 ~67 ~71 dirt
fill ~72 ~68 ~71 ~78 ~68 ~71 grass_block
fill ~79 ~60 ~71 ~79 ~65 ~71 stone
fill ~79 ~66 ~71 ~79 ~68 ~71 dirt
fill ~79 ~69 ~71 ~79 ~69 ~71 grass_block
fill ~64 ~60 ~72 ~66 ~65 ~72 stone
fill ~64 ~66 ~72 ~66 ~68 ~72 dirt
fill ~64 ~69 ~72 ~66 ~69 ~72 grass_block
fill ~67 ~60 ~72 ~69 ~64 ~72 stone
fill ~67 ~65 ~72 ~69 ~67 ~72 dirt
fill ~67 ~68 ~72 ~69 ~68 ~72 grass_block
fill ~70 ~60 ~72 ~73 ~63 ~72 stone
fill ~70 ~64 ~72 ~73 ~66 ~72 dirt
fill ~70 ~67 ~72 ~73 ~67 ~72 grass_block
fill ~74 ~60 ~72 ~79 ~64 ~72 stone
fill ~74 ~65 ~72 ~79 ~67 ~72 dirt
fill ~74 ~68 ~72 ~79 ~68 ~72 grass_block
fill ~64 ~60 ~73 ~68 ~65 ~73 stone
fill ~64 ~66 ~73 ~68 ~68 ~73 dirt
fill ~64 ~69 ~73 ~68 ~69 ~73 grass_block
fill ~69 ~60 ~73 ~70 ~64 ~73 stone
fill ~69 ~65 ~73 ~70 ~67 ~73 dirt
fill ~69 ~68 ~73 ~70 ~68 ~73 grass_block
fill ~71 ~60 ~73 ~75 ~63 ~73 stone
fill ~71 ~64 ~73 ~75 ~66 ~73 dirt
fill ~71 ~67 ~73 ~75 ~67 ~73 grass_block
fill ~76 ~60 ~73 ~79 ~64 ~73 stone
fill ~76 ~65 ~73 ~79 ~67 ~73 dirt
fill ~76 ~68 ~73 ~79 ~68 ~73 grass_block
fill ~64 ~60 ~74 ~68 ~65 ~74 stone
fill ~64 ~66 ~74 ~68 ~68 ~74 dirt
fill ~64 ~69 ~74 ~68 ~69 ~74 grass_block
fill ~69 ~60 ~74 ~71 ~64 ~74 stone
fill ~69 ~65 ~74 ~71 ~67 ~74 dirt
fill ~69 ~68 ~74 ~71 ~68 ~74 grass_block
fill ~72 ~60 ~74 ~78 ~63 ~74 stone
fill ~72 ~64 ~74 ~78 ~66 ~74 dirt
fill ~72 ~67 ~74 ~78 ~67 ~74 grass_block
fill ~79 ~60 ~74 ~79 ~64 ~74 stone
fill ~79 ~65 ~74 ~79 ~67 ~74 dirt
fill ~79 ~68 ~74 ~79 ~68 ~74 grass_block
fill ~64 ~60 ~75 ~67 ~65 ~75 stone
fill ~64 ~66 ~75 ~67 ~68 ~75 dirt
fill ~64 ~69 ~75 ~67 ~69 ~75 grass_block
fill ~68 ~60 ~75 ~71 ~64 ~75 stone
fill ~68 ~65 ~75 ~71 ~67 ~75 dirt
fill ~68 ~68 ~75 ~71 ~68 ~75 grass_block
fill ~72 ~60 ~75 ~79 ~63 ~75 stone
fill ~72 ~64 ~75 ~79 ~66 ~75 dirt
fill ~72 ~67 ~75 ~79 ~67 ~75 grass_block
fill ~64 ~60 ~76 ~65 ~65 ~76 stone
fill ~64 ~66 ~76 ~65 ~68 ~76 dirt
fill ~64 ~69 ~76 ~65 ~69 ~76 grass_block
fill ~66 ~60 ~76 ~74 ~64 ~76 stone
fill ~66 ~65 ~76 ~74 ~67 ~76 dirt
fill ~66 ~68 ~76 ~74 ~68 ~76 grass_block
fill ~75 ~60 ~76 ~79 ~63 ~76 stone
fill ~75 ~64 ~76 ~79 ~66 ~76 dirt
fill ~75 ~67 ~76 ~79 ~67 ~76 grass_block
fill ~64 ~60 ~77 ~71 ~64 ~77 stone
fill ~64 ~65 ~77 ~71 ~67 ~77 dirt
fill ~64 ~68 ~77 ~71 ~68 ~77 grass_block
fill ~72 ~60 ~77 ~72 ~65 ~77 stone
fill ~72 ~66 ~77 ~72 ~68 ~77 dirt
fill ~72 ~69 ~77 ~72 ~69 ~77 grass_block
fill ~73 ~60 ~77 ~75 ~64 ~77 stone
fill ~73 ~65 ~77 ~75 ~67 ~77 dirt
fill ~73 ~68 ~77 ~75 ~68 ~77 grass_block
fill ~76 ~60 ~77 ~79 ~63 ~77 stone
fill ~76 ~64 ~77 ~79 ~66 ~77 dirt
fill ~76 ~67 ~77 ~79 ~67 ~77 grass_block
fill ~64 ~60 ~78 ~74 ~65 ~78 stone
fill ~64 ~66 ~78 ~74 ~68 ~78 dirt
fill ~64 ~69 ~78 ~74 ~69 ~78 grass_block
fill ~75 ~60 ~78 ~77 ~64 ~78 stone
fill ~75 ~65 ~78 ~77 ~67 ~78 dirt
fill ~75 ~68 ~78 ~77 ~68 ~78 grass_block
fill ~78 ~60 ~78 ~79 ~63 ~78 stone
fill ~78 ~64 ~78 ~79 ~66 ~78 dirt
fill ~78 ~67 ~78 ~79 ~67 ~78 grass_block
fill ~64 ~60 ~79 ~69 ~65 ~79 stone
fill ~64 ~66 ~79 ~69 ~68 ~79 dirt
fill ~64 ~69 ~79 ~69 ~69 ~79 grass_block
fill ~70 ~60 ~79 ~72 ~66 ~79 stone
fill ~70 ~67 ~79 ~72 ~69 ~79 dirt
fill ~70 ~70 ~79 ~72 ~70 ~79 grass_block
fill ~73 ~60 ~79 ~76 ~65 ~79 stone
fill ~73 ~66 ~79 ~76 ~68 ~79 dirt
fill ~73 ~69 ~79 ~76 ~69 ~79 grass_block
fill ~77 ~60 ~79 ~79 ~64 ~79 stone
fill ~77 ~65 ~79 ~79 ~67 ~79 dirt
fill ~77 ~68 ~79 ~79 ~68 ~79 grass_block