fill ~144 ~60 ~96 ~147 ~62 ~96 stone
fill ~144 ~63 ~96 ~147 ~65 ~96 dirt
fill ~144 ~66 ~96 ~147 ~66 ~96 grass_block
fill ~148 ~60 ~96 ~151 ~63 ~96 stone
fill ~148 ~64 ~96 ~151 ~66 ~96 dirt
fill ~148 ~67 ~96 ~151 ~67 ~96 grass_block
fill ~152 ~60 ~96 ~152 ~64 ~96 stone
fill ~152 ~65 ~96 ~152 ~67 ~96 dirt
fill ~152 ~68 ~96 ~152 ~68 ~96 grass_block
fill ~153 ~60 ~96 ~155 ~63 ~96 stone
fill ~153 ~64 ~96 ~155 ~66 ~96 dirt
fill ~153 ~67 ~96 ~155 ~67 ~96 grass_block
fill ~156 ~60 ~96 ~158 ~64 ~96 stone
fill ~156 ~65 ~96 ~158 ~67 ~96 dirt
fill ~156 ~68 ~96 ~158 ~68 ~96 grass_block
fill ~159 ~60 ~96 ~159 ~65 ~96 stone
fill ~159 ~66 ~96 ~159 ~68 ~96 dirt
fill ~159 ~69 ~96 ~159 ~69 ~96 grass_block
fill ~144 ~60 ~97 ~149 ~62 ~97 stone
fill ~144 ~63 ~97 ~149 ~65 ~97 dirt
fill ~144 ~66 ~97 ~149 ~66 ~97 grass_block
fill ~150 ~60 ~97 ~155 ~63 ~97 stone
fill ~150 ~64 ~97 ~155 ~66 ~97 dirt
fill ~150 ~67 ~97 ~155 ~67 ~97 grass_block
fill ~156 ~60 ~97 ~159 ~64 ~97 stone
fill ~156 ~65 ~97 ~159 ~67 ~97 dirt
fill ~156 ~68 ~97 ~159 ~68 ~97 grass_block
fill ~144 ~60 ~98 ~151 ~62 ~98 stone
fill ~144 ~63 ~98 ~151 ~65 ~98 dirt
fill ~144 ~66 ~98 ~151 ~66 ~98 grass_block
fill ~152 ~60 ~98 ~156 ~63 ~98 stone
fill ~152 ~64 ~98 ~156 ~66 ~98 dirt
fill ~152 ~67 ~98 ~156 ~67 ~98 grass_block
fill ~157 ~60 ~98 ~159 ~64 ~98 stone
fill ~157 ~65 ~98 ~159 ~67 ~98 dirt
fill ~157 ~68 ~98 ~159 ~68 ~98 grass_block
fill ~144 ~60 ~99 ~153 ~62 ~99 stone
fill ~144 ~63 ~99 ~153 ~65 ~99 dirt
fill ~144 ~66 ~99 ~153 ~66 ~99 grass_block
fill ~154 ~60 ~99 ~156 ~63 ~99 stone
fill ~154 ~64 ~99 ~156 ~66 ~99 dirt
fill ~154 ~67 ~99 ~156 ~67 ~99 grass_block
fill ~157 ~60 ~99 ~159 ~64 ~99 stone
fill ~157 ~65 ~99 ~159 ~67 ~99 dirt
fill ~157 ~68 ~99 ~159 ~68 ~99 grass_block
fill ~144 ~60 ~100 ~154 ~62 ~100 stone
fill ~144 ~63 ~100 ~154 ~65 ~100 dirt
fill ~144 ~66 ~100 ~154 ~66 ~100 grass_block
fill ~155 ~60 ~100 ~156 ~63 ~100 stone
fill ~155 ~64 ~100 ~156 ~66 ~100 dirt
fill ~155 ~67 ~100 ~156 ~67 ~100 grass_block
fill ~157 ~60 ~100 ~159 ~64 ~100 stone
fill ~157 ~65 ~100 ~159 ~67 ~100 dirt
fill ~157 ~68 ~100 ~159 ~68 ~100 grass_block
fill ~144 ~60 ~101 ~154 ~62 ~101 stone
fill ~144 ~63 ~101 ~154 ~65 ~101 dirt
fill ~144 ~66 ~101 ~154 ~66 ~101 grass_block
fill ~155 ~60 ~101 ~157 ~63 ~101 stone
fill ~155 ~64 ~101 ~157 ~66 ~101 dirt
fill ~155 ~67 ~101 ~157 ~67 ~101 grass_block
fill ~158 ~60 ~101 ~159 ~64 ~101 stone
fill ~158 ~65 ~101 ~159 ~67 ~101 dirt
fill ~158 ~68 ~101 ~159 ~68 ~101 grass_block
fill ~144 ~60 ~102 ~154 ~62 ~102 stone
fill ~144 ~63 ~102 ~154 ~65 ~102 dirt
fill ~144 ~66 ~102 ~154 ~66 ~102 grass_block
fill ~155 ~60 ~102 ~159 ~63 ~102 stone
fill ~155 ~64 ~102 ~159 ~66 ~102 dirt
fill ~155 ~67 ~102 ~159 ~67 ~102 grass_block
fill ~144 ~60 ~103 ~156 ~62 ~103 stone
fill ~144 ~63 ~103 ~156 ~65 ~103 dirt
fill ~144 ~66 ~103 ~156 ~66 ~103 grass_block
fill ~157 ~60 ~103 ~159 ~63 ~103 stone
fill ~157 ~64 ~103 ~159 ~66 ~103 dirt
fill ~157 ~67 ~103 ~159 ~67 ~103 grass_block
fill ~144 ~60 ~104 ~159 ~62 ~104 stone
fill ~144 ~63 ~104 ~159 ~65 ~104 dirt
fill ~144 ~66 ~104 ~159 ~66 ~104 grass_block
fill ~144 ~60 ~105 ~159 ~62 ~105 stone
fill ~144 ~63 ~105 ~159 ~65 ~105 dirt
fill ~144 ~66 ~105 ~159 ~66 ~105 grass_block
fill ~144 ~60 ~106 ~144 ~63 ~106 stone
fill ~144 ~64 ~106 ~144 ~66 ~106 dirt
fill ~144 ~67 ~106 ~144 ~67 ~106 grass_block
fill ~145 ~60 ~106 ~159 ~62 ~106 stone
fill ~145 ~63 ~106 ~159 ~65 ~106 dirt
fill ~145 ~66 ~106 ~159 ~66 ~106 grass_block
fill ~144 ~60 ~107 ~146 ~63 ~107 stone
fill ~144 ~64 ~107 ~146 ~66 ~107 dirt
fill ~144 ~67 ~107 ~146 ~67 ~107 grass_block
fill ~147 ~60 ~107 ~159 ~62 ~107 stone
fill ~147 ~63 ~107 ~159 ~65 ~107 dirt
fill ~147 ~66 ~107 ~159 ~66 ~107 grass_block
fill ~144 ~60 ~108 ~144 ~64 ~108 stone
fill ~144 ~65 ~108 ~144 ~67 ~108 dirt
fill ~144 ~68 ~108 ~144 ~68 ~108 grass_block
fill ~145 ~60 ~108 ~147 ~63 ~108 stone
fill ~145 ~64 ~108 ~147 ~66 ~108 dirt
fill ~145 ~67 ~108 ~147 ~67 ~108 grass_block
fill ~148 ~60 ~108 ~159 ~62 ~108 stone
fill ~148 ~63 ~108 ~159 ~65 ~108 dirt
fill ~148 ~66 ~108 ~159 ~66 ~108 grass_block
fill ~144 ~60 ~109 ~145 ~64 ~109 stone
fill ~144 ~65 ~109 ~145 ~67 ~109 dirt
fill ~144 ~68 ~109 ~145 ~68 ~109 grass_block
fill ~146 ~60 ~109 ~147 ~63 ~109 stone
fill ~146 ~64 ~109 ~147 ~66 ~109 dirt
fill ~146 ~67 ~109 ~147 ~67 ~109 grass_block
fill ~148 ~60 ~109 ~159 ~62 ~109 stone
fill ~148 ~63 ~109 ~159 ~65 ~109 dirt
fill ~148 ~66 ~109 ~159 ~66 ~109 grass_block
fill ~144 ~60 ~110 ~147 ~64 ~110 stone
fill ~144 ~65 ~110 ~147 ~67 ~110 dirt
fill ~144 ~68 ~110 ~147 ~68 ~110 grass_block
fill ~148 ~60 ~110 ~150 ~63 ~110 stone
fill ~148 ~64 ~110 ~150 ~66 ~110 dirt
fill ~148 ~67 ~110 ~150 ~67 ~110 grass_block
fill ~151 ~60 ~110 ~159 ~62 ~110 stone
fill ~151 ~63 ~110 ~159 ~65 ~110 dirt
fill ~151 ~66 ~110 ~159 ~66 ~110 grass_block
fill ~144 ~60 ~111 ~144 ~65 ~111 stone
fill ~144 ~66 ~111 ~144 ~68 ~111 dirt
fill ~144 ~69 ~111 ~144 ~69 ~111 grass_block
fill ~145 ~60 ~111 ~148 ~64 ~111 stone
fill ~145 ~65 ~111 ~148 ~67 ~111 dirt
fill ~145 ~68 ~111 ~148 ~68 ~111 grass_block
fill ~149 ~60 ~111 ~152 ~63 ~111 stone
fill ~149 ~64 ~111 ~152 ~66 ~111 dirt
fill ~149 ~67 ~111 ~152 ~67 ~111 grass_block
fill ~153 ~60 ~111 ~159 ~62 ~111 stone
fill ~153 ~63 ~111 ~159 ~65 ~111 dirt
fill ~153 ~66 ~111 ~159 ~66 ~111 grass_block