fill ~32 ~60 ~128 ~47 ~64 ~128 stone
fill ~32 ~65 ~128 ~47 ~67 ~128 dirt
fill ~32 ~68 ~128 ~47 ~68 ~128 grass_block
fill ~32 ~60 ~129 ~33 ~65 ~129 stone
fill ~32 ~66 ~129 ~33 ~68 ~129 dirt
fill ~32 ~69 ~129 ~33 ~69 ~129 grass_block
fill ~34 ~60 ~129 ~47 ~64 ~129 stone
fill ~34 ~65 ~129 ~47 ~67 ~129 dirt
fill ~34 ~68 ~129 ~47 ~68 ~129 grass_block
fill ~32 ~60 ~130 ~33 ~65 ~130 stone
fill ~32 ~66 ~130 ~33 ~68 ~130 dirt
fill ~32 ~69 ~130 ~33 ~69 ~130 grass_block
fill ~34 ~60 ~130 ~47 ~64 ~130 stone
fill ~34 ~65 ~130 ~47 ~67 ~130 dirt
fill ~34 ~68 ~130 ~47 ~68 ~130 grass_block
fill ~32 ~60 ~131 ~32 ~65 ~131 stone
fill ~32 ~66 ~131 ~32 ~68 ~131 dirt
fill ~32 ~69 ~131 ~32 ~69 ~131 grass_block
fill ~33 ~60 ~131 ~34 ~64 ~131 stone
fill ~33 ~65 ~131 ~34 ~67 ~131 dirt
fill ~33 ~68 ~131 ~34 ~68 ~131 grass_block
fill ~35 ~60 ~131 ~35 ~65 ~131 stone
fill ~35 ~66 ~131 ~35 ~68 ~131 dirt
fill ~35 ~69 ~131 ~35 ~69 ~131 grass_block
fill ~36 ~60 ~131 ~36 ~64 ~131 stone
fill ~36 ~65 ~131 ~36 ~67 ~131 dirt
fill ~36 ~68 ~131 ~36 ~68 ~131 grass_block
fill ~37 ~60 ~131 ~41 ~65 ~131 stone
fill ~37 ~66 ~131 ~41 ~68 ~131 dirt
fill ~37 ~69 ~131 ~41 ~69 ~131 grass_block
fill ~42 ~60 ~131 ~47 ~64 ~131 stone
fill ~42 ~65 ~131 ~47 ~67 ~131 dirt
fill ~42 ~68 ~131 ~47 ~68 ~131 grass_block
fill ~32 ~60 ~132 ~42 ~65 ~132 stone
fill ~32 ~66 ~132 ~42 ~68 ~132 dirt
fill ~32 ~69 ~132 ~42 ~69 ~132 grass_block
fill ~43 ~60 ~132 ~47 ~64 ~132 stone
fill ~43 ~65 ~132 ~47 ~67 ~132 dirt
fill ~43 ~68 ~132 ~47 ~68 ~132 grass_block
fill ~32 ~60 ~133 ~34 ~65 ~133 stone
fill ~32 ~66 ~133 ~34 ~68 ~133 dirt
fill ~32 ~69 ~133 ~34 ~69 ~133 grass_block
fill ~35 ~60 ~133 ~37 ~66 ~133 stone
fill ~35 ~67 ~133 ~37 ~69 ~133 dirt
fill ~35 ~70 ~133 ~37 ~70 ~133 grass_block
fill ~38 ~60 ~133 ~39 ~67 ~133 stone
fill ~38 ~68 ~133 ~39 ~70 ~133 dirt
fill ~38 ~71 ~133 ~39 ~71 ~133 grass_block
fill ~40 ~60 ~133 ~40 ~66 ~133 stone
fill ~40 ~67 ~133 ~40 ~69 ~133 dirt
fill ~40 ~70 ~133 ~40 ~70 ~133 grass_block
fill ~41 ~60 ~133 ~47 ~65 ~133 stone
fill ~41 ~66 ~133 ~47 ~68 ~133 dirt
fill ~41 ~69 ~133 ~47 ~69 ~133 grass_block
fill ~32 ~60 ~134 ~33 ~65 ~134 stone
fill ~32 ~66 ~134 ~33 ~68 ~134 dirt
fill ~32 ~69 ~134 ~33 ~69 ~134 grass_block
fill ~34 ~60 ~134 ~35 ~66 ~134 stone
fill ~34 ~67 ~134 ~35 ~69 ~134 dirt
fill ~34 ~70 ~134 ~35 ~70 ~134 grass_block
fill ~36 ~60 ~134 ~40 ~67 ~134 stone
fill ~36 ~68 ~134 ~40 ~70 ~134 dirt
fill ~36 ~71 ~134 ~40 ~71 ~134 grass_block
fill ~41 ~60 ~134 ~41 ~66 ~134 stone
fill ~41 ~67 ~134 ~41 ~69 ~134 dirt
fill ~41 ~70 ~134 ~41 ~70 ~134 grass_block
fill ~42 ~60 ~134 ~43 ~65 ~134 stone
fill ~42 ~66 ~134 ~43 ~68 ~134 dirt
fill ~42 ~69 ~134 ~43 ~69 ~134 grass_block
fill ~44 ~60 ~134 ~47 ~66 ~134 stone
fill ~44 ~67 ~134 ~47 ~69 ~134 dirt
fill ~44 ~70 ~134 ~47 ~70 ~134 grass_block
fill ~32 ~60 ~135 ~34 ~66 ~135 stone
fill ~32 ~67 ~135 ~34 ~69 ~135 dirt
fill ~32 ~70 ~135 ~34 ~70 ~135 grass_block
fill ~35 ~60 ~135 ~35 ~67 ~135 stone
fill ~35 ~68 ~135 ~35 ~70 ~135 dirt
fill ~35 ~71 ~135 ~35 ~71 ~135 grass_block
fill ~36 ~60 ~135 ~39 ~68 ~135 stone
fill ~36 ~69 ~135 ~39 ~71 ~135 dirt
fill ~36 ~72 ~135 ~39 ~72 ~135 grass_block
fill ~40 ~60 ~135 ~41 ~67 ~135 stone
fill ~40 ~68 ~135 ~41 ~70 ~135 dirt
fill ~40 ~71 ~135 ~41 ~71 ~135 grass_block
fill ~42 ~60 ~135 ~43 ~66 ~135 stone
fill ~42 ~67 ~135 ~43 ~69 ~135 dirt
fill ~42 ~70 ~135 ~43 ~70 ~135 grass_block
fill ~44 ~60 ~135 ~47 ~67 ~135 stone
fill ~44 ~68 ~135 ~47 ~70 ~135 dirt
fill ~44 ~71 ~135 ~47 ~71 ~135 grass_block
fill ~32 ~60 ~136 ~33 ~66 ~136 stone
fill ~32 ~67 ~136 ~33 ~69 ~136 dirt
fill ~32 ~70 ~136 ~33 ~70 ~136 grass_block
fill ~34 ~60 ~136 ~35 ~67 ~136 stone
fill ~34 ~68 ~136 ~35 ~70 ~136 dirt
fill ~34 ~71 ~136 ~35 ~71 ~136 grass_block
fill ~36 ~60 ~136 ~40 ~68 ~136 stone
fill ~36 ~69 ~136 ~40 ~71 ~136 dirt
fill ~36 ~72 ~136 ~40 ~72 ~136 grass_block
fill ~41 ~60 ~136 ~47 ~67 ~136 stone
fill ~41 ~68 ~136 ~47 ~70 ~136 dirt
fill ~41 ~71 ~136 ~47 ~71 ~136 grass_block
fill ~32 ~60 ~137 ~33 ~67 ~137 stone
fill ~32 ~68 ~137 ~33 ~70 ~137 dirt
fill ~32 ~71 ~137 ~33 ~71 ~137 grass_block
fill ~34 ~60 ~137 ~37 ~68 ~137 stone
fill ~34 ~69 ~137 ~37 ~71 ~137 dirt
fill ~34 ~72 ~137 ~37 ~72 ~137 grass_block
fill ~38 ~60 ~137 ~38 ~69 ~137 stone
fill ~38 ~70 ~137 ~38 ~72 ~137 dirt
fill ~38 ~73 ~137 ~38 ~73 ~137 grass_block
fill ~39 ~60 ~137 ~41 ~68 ~137 stone
fill ~39 ~69 ~137 ~41 ~71 ~137 dirt
fill ~39 ~72 ~137 ~41 ~72 ~137 grass_block
fill ~42 ~60 ~137 ~47 ~67 ~137 stone
fill ~42 ~68 ~137 ~47 ~70 ~137 dirt
fill ~42 ~71 ~137 ~47 ~71 ~137 grass_block
fill ~32 ~60 ~138 ~33 ~67 ~138 stone
fill ~32 ~68 ~138 ~33 ~70 ~138 dirt
fill ~32 ~71 ~138 ~33 ~71 ~138 grass_block
fill ~34 ~60 ~138 ~34 ~68 ~138 stone
fill ~34 ~69 ~138 ~34 ~71 ~138 dirt
fill ~34 ~72 ~138 ~34 ~72 ~138 grass_block
fill ~35 ~60 ~138 ~38 ~69 ~138 stone
fill ~35 ~70 ~138 ~38 ~72 ~138 dirt
fill ~35 ~73 ~138 ~38 ~73 ~138 grass_block
fill ~39 ~60 ~138 ~40 ~68 ~138 stone
fill ~39 ~69 ~138 ~40 ~71 ~138 dirt
fill ~39 ~72 ~138 ~40 ~72 ~138 grass_block
fill ~41 ~60 ~138 ~43 ~67 ~138 stone
fill ~41 ~68 ~138 ~43 ~70 ~138 dirt
fill ~41 ~71 ~138 ~43 ~71 ~138 grass_block
fill ~44 ~60 ~138 ~47 ~66 ~138 stone
fill ~44 ~67 ~138 ~47 ~69 ~138 dirt
fill ~44 ~70 ~138 ~47 ~70 ~138 grass_block
fill ~32 ~60 ~139 ~34 ~68 ~139 stone
fill ~32 ~69 ~139 ~34 ~71 ~139 dirt
fill ~32 ~72 ~139 ~34 ~72 ~139 grass_block
fill ~35 ~60 ~139 ~38 ~69 ~139 stone
fill ~35 ~70 ~139 ~38 ~72 ~139 dirt
fill ~35 ~73 ~139 ~38 ~73 ~139 grass_block
fill ~39 ~60 ~139 ~40 ~68 ~139 stone
fill ~39 ~69 ~139 ~40 ~71 ~139 dirt
fill ~39 ~72 ~139 ~40 ~72 ~139 grass_block
fill ~41 ~60 ~139 ~44 ~67 ~139 stone
fill ~41 ~68 ~139 ~44 ~70 ~139 dirt
fill ~41 ~71 ~139 ~44 ~71 ~139 grass_block
fill ~45 ~60 ~139 ~47 ~66 ~139 stone
fill ~45 ~67 ~139 ~47 ~69 ~139 dirt
fill ~45 ~70 ~139 ~47 ~70 ~139 grass_block
fill ~32 ~60 ~140 ~34 ~68 ~140 stone
fill ~32 ~69 ~140 ~34 ~71 ~140 dirt
fill ~32 ~72 ~140 ~34 ~72 ~140 grass_block
fill ~35 ~60 ~140 ~35 ~69 ~140 stone
fill ~35 ~70 ~140 ~35 ~72 ~140 dirt
fill ~35 ~73 ~140 ~35 ~73 ~140 grass_block
fill ~36 ~60 ~140 ~37 ~70 ~140 stone
fill ~36 ~71 ~140 ~37 ~73 ~140 dirt
fill ~36 ~74 ~140 ~37 ~74 ~140 grass_block
fill ~38 ~60 ~140 ~38 ~69 ~140 stone
fill ~38 ~70 ~140 ~38 ~72 ~140 dirt
fill ~38 ~73 ~140 ~38 ~73 ~140 grass_block
fill ~39 ~60 ~140 ~41 ~68 ~140 stone
fill ~39 ~69 ~140 ~41 ~71 ~140 dirt
fill ~39 ~72 ~140 ~41 ~72 ~140 grass_block
fill ~42 ~60 ~140 ~47 ~67 ~140 stone
fill ~42 ~68 ~140 ~47 ~70 ~140 dirt
fill ~42 ~71 ~140 ~47 ~71 ~140 grass_block
fill ~32 ~60 ~141 ~35 ~69 ~141 stone
fill ~32 ~70 ~141 ~35 ~72 ~141 dirt
fill ~32 ~73 ~141 ~35 ~73 ~141 grass_block
fill ~36 ~60 ~141 ~38 ~70 ~141 stone
fill ~36 ~71 ~141 ~38 ~73 ~141 dirt
fill ~36 ~74 ~141 ~38 ~74 ~141 grass_block
fill ~39 ~60 ~141 ~39 ~69 ~141 stone
fill ~39 ~70 ~141 ~39 ~72 ~141 dirt
fill ~39 ~73 ~141 ~39 ~73 ~141 grass_block
fill ~40 ~60 ~141 ~43 ~68 ~141 stone
fill ~40 ~69 ~141 ~43 ~71 ~141 dirt
fill ~40 ~72 ~141 ~43 ~72 ~141 grass_block
fill ~44 ~60 ~141 ~47 ~67 ~141 stone
fill ~44 ~68 ~141 ~47 ~70 ~141 dirt
fill ~44 ~71 ~141 ~47 ~71 ~141 grass_block
fill ~32 ~60 ~142 ~33 ~69 ~142 stone
fill ~32 ~70 ~142 ~33 ~72 ~142 dirt
fill ~32 ~73 ~142 ~33 ~73 ~142 grass_block
fill ~34 ~60 ~142 ~38 ~70 ~142 stone
fill ~34 ~71 ~142 ~38 ~73 ~142 dirt
fill ~34 ~74 ~142 ~38 ~74 ~142 grass_block
fill ~39 ~60 ~142 ~41 ~69 ~142 stone
fill ~39 ~70 ~142 ~41 ~72 ~142 dirt
fill ~39 ~73 ~142 ~41 ~73 ~142 grass_block
fill ~42 ~60 ~142 ~47 ~68 ~142 stone
fill ~42 ~69 ~142 ~47 ~71 ~142 dirt
fill ~42 ~72 ~142 ~47 ~72 ~142 grass_block
fill ~32 ~60 ~143 ~40 ~70 ~143 stone
fill ~32 ~71 ~143 ~40 ~73 ~143 dirt
fill ~32 ~74 ~143 ~40 ~74 ~143 grass_block
fill ~41 ~60 ~143 ~44 ~69 ~143 stone
fill ~41 ~70 ~143 ~44 ~72 ~143 dirt
fill ~41 ~73 ~143 ~44 ~73 ~143 grass_block
fill ~45 ~60 ~143 ~47 ~68 ~143 stone
fill ~45 ~69 ~143 ~47 ~71 ~143 dirt
fill ~45 ~72 ~143 ~47 ~72 ~143 grass_block