fill ~144 ~60 ~0 ~152 ~62 ~0 stone
fill ~144 ~63 ~0 ~152 ~65 ~0 dirt
fill ~144 ~66 ~0 ~152 ~66 ~0 grass_block
fill ~153 ~60 ~0 ~159 ~61 ~0 stone
fill ~153 ~62 ~0 ~159 ~64 ~0 dirt
fill ~153 ~65 ~0 ~159 ~65 ~0 grass_block
fill ~144 ~60 ~1 ~149 ~61 ~1 stone
fill ~144 ~62 ~1 ~149 ~64 ~1 dirt
fill ~144 ~65 ~1 ~149 ~65 ~1 grass_block
fill ~150 ~60 ~1 ~153 ~62 ~1 stone
fill ~150 ~63 ~1 ~153 ~65 ~1 dirt
fill ~150 ~66 ~1 ~153 ~66 ~1 grass_block
fill ~154 ~60 ~1 ~159 ~61 ~1 stone
fill ~154 ~62 ~1 ~159 ~64 ~1 dirt
fill ~154 ~65 ~1 ~159 ~65 ~1 grass_block
fill ~144 ~60 ~2 ~146 ~62 ~2 stone
fill ~144 ~63 ~2 ~146 ~65 ~2 dirt
fill ~144 ~66 ~2 ~146 ~66 ~2 grass_block
fill ~147 ~60 ~2 ~150 ~61 ~2 stone
fill ~147 ~62 ~2 ~150 ~64 ~2 dirt
fill ~147 ~65 ~2 ~150 ~65 ~2 grass_block
fill ~151 ~60 ~2 ~154 ~62 ~2 stone
fill ~151 ~63 ~2 ~154 ~65 ~2 dirt
fill ~151 ~66 ~2 ~154 ~66 ~2 grass_block
fill ~155 ~60 ~2 ~159 ~61 ~2 stone
fill ~155 ~62 ~2 ~159 ~64 ~2 dirt
fill ~155 ~65 ~2 ~159 ~65 ~2 grass_block
fill ~144 ~60 ~3 ~150 ~62 ~3 stone
fill ~144 ~63 ~3 ~150 ~65 ~3 dirt
fill ~144 ~66 ~3 ~150 ~66 ~3 grass_block
fill ~151 ~60 ~3 ~153 ~61 ~3 stone
fill ~151 ~62 ~3 ~153 ~64 ~3 dirt
fill ~151 ~65 ~3 ~153 ~65 ~3 grass_block
fill ~154 ~60 ~3 ~154 ~62 ~3 stone
fill ~154 ~63 ~3 ~154 ~65 ~3 dirt
fill ~154 ~66 ~3 ~154 ~66 ~3 grass_block
fill ~155 ~60 ~3 ~159 ~61 ~3 stone
fill ~155 ~62 ~3 ~159 ~64 ~3 dirt
fill ~155 ~65 ~3 ~159 ~65 ~3 grass_block
fill ~144 ~60 ~4 ~147 ~63 ~4 stone
fill ~144 ~64 ~4 ~147 ~66 ~4 dirt
fill ~144 ~67 ~4 ~147 ~67 ~4 grass_block
fill ~148 ~60 ~4 ~154 ~62 ~4 stone
fill ~148 ~63 ~4 ~154 ~65 ~4 dirt
fill ~148 ~66 ~4 ~154 ~66 ~4 grass_block
fill ~155 ~60 ~4 ~159 ~61 ~4 stone
fill ~155 ~62 ~4 ~159 ~64 ~4 dirt
fill ~155 ~65 ~4 ~159 ~65 ~4 grass_block
fill ~144 ~60 ~5 ~145 ~64 ~5 stone
fill ~144 ~65 ~5 ~145 ~67 ~5 dirt
fill ~144 ~68 ~5 ~145 ~68 ~5 grass_block
fill ~146 ~60 ~5 ~154 ~63 ~5 stone
fill ~146 ~64 ~5 ~154 ~66 ~5 dirt
fill ~146 ~67 ~5 ~154 ~67 ~5 grass_block
fill ~155 ~60 ~5 ~156 ~62 ~5 stone
fill ~155 ~63 ~5 ~156 ~65 ~5 dirt
fill ~155 ~66 ~5 ~156 ~66 ~5 grass_block
fill ~157 ~60 ~5 ~159 ~61 ~5 stone
fill ~157 ~62 ~5 ~159 ~64 ~5 dirt
fill ~157 ~65 ~5 ~159 ~65 ~5 grass_block
fill ~144 ~60 ~6 ~153 ~64 ~6 stone
fill ~144 ~65 ~6 ~153 ~67 ~6 dirt
fill ~144 ~68 ~6 ~153 ~68 ~6 grass_block
fill ~154 ~60 ~6 ~155 ~63 ~6 stone
fill ~154 ~64 ~6 ~155 ~66 ~6 dirt
fill ~154 ~67 ~6 ~155 ~67 ~6 grass_block
fill ~156 ~60 ~6 ~157 ~62 ~6 stone
fill ~156 ~63 ~6 ~157 ~65 ~6 dirt
fill ~156 ~66 ~6 ~157 ~66 ~6 grass_block
fill ~158 ~60 ~6 ~159 ~61 ~6 stone
fill ~158 ~62 ~6 ~159 ~64 ~6 dirt
fill ~158 ~65 ~6 ~159 ~65 ~6 grass_block
fill ~144 ~60 ~7 ~145 ~65 ~7 stone
fill ~144 ~66 ~7 ~145 ~68 ~7 dirt
fill ~144 ~69 ~7 ~145 ~69 ~7 grass_block
fill ~146 ~60 ~7 ~154 ~64 ~7 stone
fill ~146 ~65 ~7 ~154 ~67 ~7 dirt
fill ~146 ~68 ~7 ~154 ~68 ~7 grass_block
fill ~155 ~60 ~7 ~156 ~63 ~7 stone
fill ~155 ~64 ~7 ~156 ~66 ~7 dirt
fill ~155 ~67 ~7 ~156 ~67 ~7 grass_block
fill ~157 ~60 ~7 ~159 ~62 ~7 stone
fill ~157 ~63 ~7 ~159 ~65 ~7 dirt
fill ~157 ~66 ~7 ~159 ~66 ~7 grass_block
fill ~144 ~60 ~8 ~146 ~65 ~8 stone
fill ~144 ~66 ~8 ~146 ~68 ~8 dirt
fill ~144 ~69 ~8 ~146 ~69 ~8 grass_block
fill ~147 ~60 ~8 ~155 ~64 ~8 stone
fill ~147 ~65 ~8 ~155 ~67 ~8 dirt
fill ~147 ~68 ~8 ~155 ~68 ~8 grass_block
fill ~156 ~60 ~8 ~157 ~63 ~8 stone
fill ~156 ~64 ~8 ~157 ~66 ~8 dirt
fill ~156 ~67 ~8 ~157 ~67 ~8 grass_block
fill ~158 ~60 ~8 ~158 ~62 ~8 stone
fill ~158 ~63 ~8 ~158 ~65 ~8 dirt
fill ~158 ~66 ~8 ~158 ~66 ~8 grass_block
fill ~159 ~60 ~8 ~159 ~63 ~8 stone
fill ~159 ~64 ~8 ~159 ~66 ~8 dirt
fill ~159 ~67 ~8 ~159 ~67 ~8 grass_block
fill ~144 ~60 ~9 ~146 ~65 ~9 stone
fill ~144 ~66 ~9 ~146 ~68 ~9 dirt
fill ~144 ~69 ~9 ~146 ~69 ~9 grass_block
fill ~147 ~60 ~9 ~155 ~64 ~9 stone
fill ~147 ~65 ~9 ~155 ~67 ~9 dirt
fill ~147 ~68 ~9 ~155 ~68 ~9 grass_block
fill ~156 ~60 ~9 ~159 ~63 ~9 stone
fill ~156 ~64 ~9 ~159 ~66 ~9 dirt
fill ~156 ~67 ~9 ~159 ~67 ~9 grass_block
fill ~144 ~60 ~10 ~146 ~65 ~10 stone
fill ~144 ~66 ~10 ~146 ~68 ~10 dirt
fill ~144 ~69 ~10 ~146 ~69 ~10 grass_block
fill ~147 ~60 ~10 ~154 ~64 ~10 stone
fill ~147 ~65 ~10 ~154 ~67 ~10 dirt
fill ~147 ~68 ~10 ~154 ~68 ~10 grass_block
fill ~155 ~60 ~10 ~159 ~63 ~10 stone
fill ~155 ~64 ~10 ~159 ~66 ~10 dirt
fill ~155 ~67 ~10 ~159 ~67 ~10 grass_block
fill ~144 ~60 ~11 ~146 ~65 ~11 stone
fill ~144 ~66 ~11 ~146 ~68 ~11 dirt
fill ~144 ~69 ~11 ~146 ~69 ~11 grass_block
fill ~147 ~60 ~11 ~153 ~64 ~11 stone
fill ~147 ~65 ~11 ~153 ~67 ~11 dirt
fill ~147 ~68 ~11 ~153 ~68 ~11 grass_block
fill ~154 ~60 ~11 ~159 ~63 ~11 stone
fill ~154 ~64 ~11 ~159 ~66 ~11 dirt
fill ~154 ~67 ~11 ~159 ~67 ~11 grass_block
fill ~144 ~60 ~12 ~154 ~64 ~12 stone
fill ~144 ~65 ~12 ~154 ~67 ~12 dirt
fill ~144 ~68 ~12 ~154 ~68 ~12 grass_block
fill ~155 ~60 ~12 ~159 ~63 ~12 stone
fill ~155 ~64 ~12 ~159 ~66 ~12 dirt
fill ~155 ~67 ~12 ~159 ~67 ~12 grass_block
fill ~144 ~60 ~13 ~155 ~64 ~13 stone
fill ~144 ~65 ~13 ~155 ~67 ~13 dirt
fill ~144 ~68 ~13 ~155 ~68 ~13 grass_block
fill ~156 ~60 ~13 ~159 ~63 ~13 stone
fill ~156 ~64 ~13 ~159 ~66 ~13 dirt
fill ~156 ~67 ~13 ~159 ~67 ~13 grass_block
fill ~144 ~60 ~14 ~155 ~64 ~14 stone
fill ~144 ~65 ~14 ~155 ~67 ~14 dirt
fill ~144 ~68 ~14 ~155 ~68 ~14 grass_block
fill ~156 ~60 ~14 ~159 ~63 ~14 stone
fill ~156 ~64 ~14 ~159 ~66 ~14 dirt
fill ~156 ~67 ~14 ~159 ~67 ~14 grass_block
fill ~144 ~60 ~15 ~155 ~64 ~15 stone
fill ~144 ~65 ~15 ~155 ~67 ~15 dirt
fill ~144 ~68 ~15 ~155 ~68 ~15 grass_block
fill ~156 ~60 ~15 ~159 ~63 ~15 stone
fill ~156 ~64 ~15 ~159 ~66 ~15 dirt
fill ~156 ~67 ~15 ~159 ~67 ~15 grass_block