fill ~64 ~60 ~48 ~69 ~63 ~48 stone
fill ~64 ~64 ~48 ~69 ~66 ~48 dirt
fill ~64 ~67 ~48 ~69 ~67 ~48 grass_block
fill ~70 ~60 ~48 ~72 ~64 ~48 stone
fill ~70 ~65 ~48 ~72 ~67 ~48 dirt
fill ~70 ~68 ~48 ~72 ~68 ~48 grass_block
fill ~73 ~60 ~48 ~79 ~65 ~48 stone
fill ~73 ~66 ~48 ~79 ~68 ~48 dirt
fill ~73 ~69 ~48 ~79 ~69 ~48 grass_block
fill ~64 ~60 ~49 ~69 ~63 ~49 stone
fill ~64 ~64 ~49 ~69 ~66 ~49 dirt
fill ~64 ~67 ~49 ~69 ~67 ~49 grass_block
fill ~70 ~60 ~49 ~74 ~64 ~49 stone
fill ~70 ~65 ~49 ~74 ~67 ~49 dirt
fill ~70 ~68 ~49 ~74 ~68 ~49 grass_block
fill ~75 ~60 ~49 ~79 ~65 ~49 stone
fill ~75 ~66 ~49 ~79 ~68 ~49 dirt
fill ~75 ~69 ~49 ~79 ~69 ~49 grass_block
fill ~64 ~60 ~50 ~64 ~64 ~50 stone
fill ~64 ~65 ~50 ~64 ~67 ~50 dirt
fill ~64 ~68 ~50 ~64 ~68 ~50 grass_block
fill ~65 ~60 ~50 ~71 ~63 ~50 stone
fill ~65 ~64 ~50 ~71 ~66 ~50 dirt
fill ~65 ~67 ~50 ~71 ~67 ~50 grass_block
fill ~72 ~60 ~50 ~76 ~64 ~50 stone
fill ~72 ~65 ~50 ~76 ~67 ~50 dirt
fill ~72 ~68 ~50 ~76 ~68 ~50 grass_block
fill ~77 ~60 ~50 ~79 ~65 ~50 stone
fill ~77 ~66 ~50 ~79 ~68 ~50 dirt
fill ~77 ~69 ~50 ~79 ~69 ~50 grass_block
fill ~64 ~60 ~51 ~66 ~64 ~51 stone
fill ~64 ~65 ~51 ~66 ~67 ~51 dirt
fill ~64 ~68 ~51 ~66 ~68 ~51 grass_block
fill ~67 ~60 ~51 ~73 ~63 ~51 stone
fill ~67 ~64 ~51 ~73 ~66 ~51 dirt
fill ~67 ~67 ~51 ~73 ~67 ~51 grass_block
fill ~74 ~60 ~51 ~79 ~64 ~51 stone
fill ~74 ~65 ~51 ~79 ~67 ~51 dirt
fill ~74 ~68 ~51 ~79 ~68 ~51 grass_block
fill ~64 ~60 ~52 ~69 ~64 ~52 stone
fill ~64 ~65 ~52 ~69 ~67 ~52 dirt
fill ~64 ~68 ~52 ~69 ~68 ~52 grass_block
fill ~70 ~60 ~52 ~75 ~63 ~52 stone
fill ~70 ~64 ~52 ~75 ~66 ~52 dirt
fill ~70 ~67 ~52 ~75 ~67 ~52 grass_block
fill ~76 ~60 ~52 ~79 ~64 ~52 stone
fill ~76 ~65 ~52 ~79 ~67 ~52 dirt
fill ~76 ~68 ~52 ~79 ~68 ~52 grass_block
fill ~64 ~60 ~53 ~64 ~65 ~53 stone
fill ~64 ~66 ~53 ~64 ~68 ~53 dirt
fill ~64 ~69 ~53 ~64 ~69 ~53 grass_block
fill ~65 ~60 ~53 ~70 ~64 ~53 stone
fill ~65 ~65 ~53 ~70 ~67 ~53 dirt
fill ~65 ~68 ~53 ~70 ~68 ~53 grass_block
fill ~71 ~60 ~53 ~76 ~63 ~53 stone
fill ~71 ~64 ~53 ~76 ~66 ~53 dirt
fill ~71 ~67 ~53 ~76 ~67 ~53 grass_block
fill ~77 ~60 ~53 ~79 ~64 ~53 stone
fill ~77 ~65 ~53 ~79 ~67 ~53 dirt
fill ~77 ~68 ~53 ~79 ~68 ~53 grass_block
fill ~64 ~60 ~54 ~68 ~65 ~54 stone
fill ~64 ~66 ~54 ~68 ~68 ~54 dirt
fill ~64 ~69 ~54 ~68 ~69 ~54 grass_block
fill ~69 ~60 ~54 ~71 ~64 ~54 stone
fill ~69 ~65 ~54 ~71 ~67 ~54 dirt
fill ~69 ~68 ~54 ~71 ~68 ~54 grass_block
fill ~72 ~60 ~54 ~79 ~63 ~54 stone
fill ~72 ~64 ~54 ~79 ~66 ~54 dirt
fill ~72 ~67 ~54 ~79 ~67 ~54 grass_block
fill ~64 ~60 ~55 ~66 ~66 ~55 stone
fill ~64 ~67 ~55 ~66 ~69 ~55 dirt
fill ~64 ~70 ~55 ~66 ~70 ~55 grass_block
fill ~67 ~60 ~55 ~70 ~65 ~55 stone
fill ~67 ~66 ~55 ~70 ~68 ~55 dirt
fill ~67 ~69 ~55 ~70 ~69 ~55 grass_block
fill ~71 ~60 ~55 ~72 ~64 ~55 stone
fill ~71 ~65 ~55 ~72 ~67 ~55 dirt
fill ~71 ~68 ~55 ~72 ~68 ~55 grass_block
fill ~73 ~60 ~55 ~79 ~63 ~55 stone
fill ~73 ~64 ~55 ~79 ~66 ~55 dirt
fill ~73 ~67 ~55 ~79 ~67 ~55 grass_block
fill ~64 ~60 ~56 ~64 ~67 ~56 stone
fill ~64 ~68 ~56 ~64 ~70 ~56 dirt
fill ~64 ~71 ~56 ~64 ~71 ~56 grass_block
fill ~65 ~60 ~56 ~68 ~66 ~56 stone
fill ~65 ~67 ~56 ~68 ~69 ~56 dirt
fill ~65 ~70 ~56 ~68 ~70 ~56 grass_block
fill ~69 ~60 ~56 ~70 ~65 ~56 stone
fill ~69 ~66 ~56 ~70 ~68 ~56 dirt
fill ~69 ~69 ~56 ~70 ~69 ~56 grass_block
fill ~71 ~60 ~56 ~75 ~64 ~56 stone
fill ~71 ~65 ~56 ~75 ~67 ~56 dirt
fill ~71 ~68 ~56 ~75 ~68 ~56 grass_block
fill ~76 ~60 ~56 ~79 ~63 ~56 stone
fill ~76 ~64 ~56 ~79 ~66 ~56 dirt
fill ~76 ~67 ~56 ~79 ~67 ~56 grass_block
fill ~64 ~60 ~57 ~67 ~67 ~57 stone
fill ~64 ~68 ~57 ~67 ~70 ~57 dirt
fill ~64 ~71 ~57 ~67 ~71 ~57 grass_block
fill ~68 ~60 ~57 ~69 ~66 ~57 stone
fill ~68 ~67 ~57 ~69 ~69 ~57 dirt
fill ~68 ~70 ~57 ~69 ~70 ~57 grass_block
fill ~70 ~60 ~57 ~72 ~65 ~57 stone
fill ~70 ~66 ~57 ~72 ~68 ~57 dirt
fill ~70 ~69 ~57 ~72 ~69 ~57 grass_block
fill ~73 ~60 ~57 ~77 ~64 ~57 stone
fill ~73 ~65 ~57 ~77 ~67 ~57 dirt
fill ~73 ~68 ~57 ~77 ~68 ~57 grass_block
fill ~78 ~60 ~57 ~79 ~63 ~57 stone
fill ~78 ~64 ~57 ~79 ~66 ~57 dirt
fill ~78 ~67 ~57 ~79 ~67 ~57 grass_block
fill ~64 ~60 ~58 ~68 ~67 ~58 stone
fill ~64 ~68 ~58 ~68 ~70 ~58 dirt
fill ~64 ~71 ~58 ~68 ~71 ~58 grass_block
fill ~69 ~60 ~58 ~71 ~66 ~58 stone
fill ~69 ~67 ~58 ~71 ~69 ~58 dirt
fill ~69 ~70 ~58 ~71 ~70 ~58 grass_block
fill ~72 ~60 ~58 ~75 ~65 ~58 stone
fill ~72 ~66 ~58 ~75 ~68 ~58 dirt
fill ~72 ~69 ~58 ~75 ~69 ~58 grass_block
fill ~76 ~60 ~58 ~79 ~64 ~58 stone
fill ~76 ~65 ~58 ~79 ~67 ~58 dirt
fill ~76 ~68 ~58 ~79 ~68 ~58 grass_block
fill ~64 ~60 ~59 ~65 ~66 ~59 stone
fill ~64 ~67 ~59 ~65 ~69 ~59 dirt
fill ~64 ~70 ~59 ~65 ~70 ~59 grass_block
fill ~66 ~60 ~59 ~71 ~67 ~59 stone
fill ~66 ~68 ~59 ~71 ~70 ~59 dirt
fill ~66 ~71 ~59 ~71 ~71 ~59 grass_block
fill ~72 ~60 ~59 ~73 ~66 ~59 stone
fill ~72 ~67 ~59 ~73 ~69 ~59 dirt
fill ~72 ~70 ~59 ~73 ~70 ~59 grass_block
fill ~74 ~60 ~59 ~76 ~65 ~59 stone
fill ~74 ~66 ~59 ~76 ~68 ~59 dirt
fill ~74 ~69 ~59 ~76 ~69 ~59 grass_block
fill ~77 ~60 ~59 ~79 ~64 ~59 stone
fill ~77 ~65 ~59 ~79 ~67 ~59 dirt
fill ~77 ~68 ~59 ~79 ~68 ~59 grass_block
fill ~64 ~60 ~60 ~68 ~66 ~60 stone
fill ~64 ~67 ~60 ~68 ~69 ~60 dirt
fill ~64 ~70 ~60 ~68 ~70 ~60 grass_block
fill ~69 ~60 ~60 ~72 ~67 ~60 stone
fill ~69 ~68 ~60 ~72 ~70 ~60 dirt
fill ~69 ~71 ~60 ~72 ~71 ~60 grass_block
fill ~73 ~60 ~60 ~74 ~66 ~60 stone
fill ~73 ~67 ~60 ~74 ~69 ~60 dirt
fill ~73 ~70 ~60 ~74 ~70 ~60 grass_block
fill ~75 ~60 ~60 ~78 ~65 ~60 stone
fill ~75 ~66 ~60 ~78 ~68 ~60 dirt
fill ~75 ~69 ~60 ~78 ~69 ~60 grass_block
fill ~79 ~60 ~60 ~79 ~64 ~60 stone
fill ~79 ~65 ~60 ~79 ~67 ~60 dirt
fill ~79 ~68 ~60 ~79 ~68 ~60 grass_block
fill ~64 ~60 ~61 ~70 ~66 ~61 stone
fill ~64 ~67 ~61 ~70 ~69 ~61 dirt
fill ~64 ~70 ~61 ~70 ~70 ~61 grass_block
fill ~71 ~60 ~61 ~74 ~67 ~61 stone
fill ~71 ~68 ~61 ~74 ~70 ~61 dirt
fill ~71 ~71 ~61 ~74 ~71 ~61 grass_block
fill ~75 ~60 ~61 ~76 ~66 ~61 stone
fill ~75 ~67 ~61 ~76 ~69 ~61 dirt
fill ~75 ~70 ~61 ~76 ~70 ~61 grass_block
fill ~77 ~60 ~61 ~79 ~65 ~61 stone
fill ~77 ~66 ~61 ~79 ~68 ~61 dirt
fill ~77 ~69 ~61 ~79 ~69 ~61 grass_block
fill ~64 ~60 ~62 ~67 ~65 ~62 stone
fill ~64 ~66 ~62 ~67 ~68 ~62 dirt
fill ~64 ~69 ~62 ~67 ~69 ~62 grass_block
fill ~68 ~60 ~62 ~72 ~66 ~62 stone
fill ~68 ~67 ~62 ~72 ~69 ~62 dirt
fill ~68 ~70 ~62 ~72 ~70 ~62 grass_block
fill ~73 ~60 ~62 ~75 ~67 ~62 stone
fill ~73 ~68 ~62 ~75 ~70 ~62 dirt
fill ~73 ~71 ~62 ~75 ~71 ~62 grass_block
fill ~76 ~60 ~62 ~79 ~66 ~62 stone
fill ~76 ~67 ~62 ~79 ~69 ~62 dirt
fill ~76 ~70 ~62 ~79 ~70 ~62 grass_block
fill ~64 ~60 ~63 ~70 ~65 ~63 stone
fill ~64 ~66 ~63 ~70 ~68 ~63 dirt
fill ~64 ~69 ~63 ~70 ~69 ~63 grass_block
fill ~71 ~60 ~63 ~79 ~66 ~63 stone
fill ~71 ~67 ~63 ~79 ~69 ~63 dirt
fill ~71 ~70 ~63 ~79 ~70 ~63 grass_block