fill ~368 ~60 ~32 ~368 ~65 ~32 stone
fill ~368 ~66 ~32 ~368 ~68 ~32 dirt
fill ~368 ~69 ~32 ~368 ~69 ~32 grass_block
fill ~369 ~60 ~32 ~370 ~64 ~32 stone
fill ~369 ~65 ~32 ~370 ~67 ~32 dirt
fill ~369 ~68 ~32 ~370 ~68 ~32 grass_block
fill ~371 ~60 ~32 ~373 ~63 ~32 stone
fill ~371 ~64 ~32 ~373 ~66 ~32 dirt
fill ~371 ~67 ~32 ~373 ~67 ~32 grass_block
fill ~374 ~60 ~32 ~375 ~64 ~32 stone
fill ~374 ~65 ~32 ~375 ~67 ~32 dirt
fill ~374 ~68 ~32 ~375 ~68 ~32 grass_block
fill ~376 ~60 ~32 ~376 ~65 ~32 stone
fill ~376 ~66 ~32 ~376 ~68 ~32 dirt
fill ~376 ~69 ~32 ~376 ~69 ~32 grass_block
fill ~377 ~60 ~32 ~380 ~64 ~32 stone
fill ~377 ~65 ~32 ~380 ~67 ~32 dirt
fill ~377 ~68 ~32 ~380 ~68 ~32 grass_block
fill ~381 ~60 ~32 ~383 ~65 ~32 stone
fill ~381 ~66 ~32 ~383 ~68 ~32 dirt
fill ~381 ~69 ~32 ~383 ~69 ~32 grass_block
fill ~368 ~60 ~33 ~368 ~65 ~33 stone
fill ~368 ~66 ~33 ~368 ~68 ~33 dirt
fill ~368 ~69 ~33 ~368 ~69 ~33 grass_block
fill ~369 ~60 ~33 ~371 ~64 ~33 stone
fill ~369 ~65 ~33 ~371 ~67 ~33 dirt
fill ~369 ~68 ~33 ~371 ~68 ~33 grass_block
fill ~372 ~60 ~33 ~372 ~63 ~33 stone
fill ~372 ~64 ~33 ~372 ~66 ~33 dirt
fill ~372 ~67 ~33 ~372 ~67 ~33 grass_block
fill ~373 ~60 ~33 ~374 ~64 ~33 stone
fill ~373 ~65 ~33 ~374 ~67 ~33 dirt
fill ~373 ~68 ~33 ~374 ~68 ~33 grass_block
fill ~375 ~60 ~33 ~381 ~65 ~33 stone
fill ~375 ~66 ~33 ~381 ~68 ~33 dirt
fill ~375 ~69 ~33 ~381 ~69 ~33 grass_block
fill ~382 ~60 ~33 ~382 ~66 ~33 stone
fill ~382 ~67 ~33 ~382 ~69 ~33 dirt
fill ~382 ~70 ~33 ~382 ~70 ~33 grass_block
fill ~383 ~60 ~33 ~383 ~65 ~33 stone
fill ~383 ~66 ~33 ~383 ~68 ~33 dirt
fill ~383 ~69 ~33 ~383 ~69 ~33 grass_block
fill ~368 ~60 ~34 ~368 ~65 ~34 stone
fill ~368 ~66 ~34 ~368 ~68 ~34 dirt
fill ~368 ~69 ~34 ~368 ~69 ~34 grass_block
fill ~369 ~60 ~34 ~374 ~64 ~34 stone
fill ~369 ~65 ~34 ~374 ~67 ~34 dirt
fill ~369 ~68 ~34 ~374 ~68 ~34 grass_block
fill ~375 ~60 ~34 ~375 ~65 ~34 stone
fill ~375 ~66 ~34 ~375 ~68 ~34 dirt
fill ~375 ~69 ~34 ~375 ~69 ~34 grass_block
fill ~376 ~60 ~34 ~376 ~66 ~34 stone
fill ~376 ~67 ~34 ~376 ~69 ~34 dirt
fill ~376 ~70 ~34 ~376 ~70 ~34 grass_block
fill ~377 ~60 ~34 ~380 ~65 ~34 stone
fill ~377 ~66 ~34 ~380 ~68 ~34 dirt
fill ~377 ~69 ~34 ~380 ~69 ~34 grass_block
fill ~381 ~60 ~34 ~383 ~66 ~34 stone
fill ~381 ~67 ~34 ~383 ~69 ~34 dirt
fill ~381 ~70 ~34 ~383 ~70 ~34 grass_block
fill ~368 ~60 ~35 ~376 ~65 ~35 stone
fill ~368 ~66 ~35 ~376 ~68 ~35 dirt
fill ~368 ~69 ~35 ~376 ~69 ~35 grass_block
fill ~377 ~60 ~35 ~383 ~66 ~35 stone
fill ~377 ~67 ~35 ~383 ~69 ~35 dirt
fill ~377 ~70 ~35 ~383 ~70 ~35 grass_block
fill ~368 ~60 ~36 ~376 ~65 ~36 stone
fill ~368 ~66 ~36 ~376 ~68 ~36 dirt
fill ~368 ~69 ~36 ~376 ~69 ~36 grass_block
fill ~377 ~60 ~36 ~383 ~66 ~36 stone
fill ~377 ~67 ~36 ~383 ~69 ~36 dirt
fill ~377 ~70 ~36 ~383 ~70 ~36 grass_block
fill ~368 ~60 ~37 ~377 ~65 ~37 stone
fill ~368 ~66 ~37 ~377 ~68 ~37 dirt
fill ~368 ~69 ~37 ~377 ~69 ~37 grass_block
fill ~378 ~60 ~37 ~381 ~66 ~37 stone
fill ~378 ~67 ~37 ~381 ~69 ~37 dirt
fill ~378 ~70 ~37 ~381 ~70 ~37 grass_block
fill ~382 ~60 ~37 ~382 ~65 ~37 stone
fill ~382 ~66 ~37 ~382 ~68 ~37 dirt
fill ~382 ~69 ~37 ~382 ~69 ~37 grass_block
fill ~383 ~60 ~37 ~383 ~66 ~37 stone
fill ~383 ~67 ~37 ~383 ~69 ~37 dirt
fill ~383 ~70 ~37 ~383 ~70 ~37 grass_block
fill ~368 ~60 ~38 ~378 ~65 ~38 stone
fill ~368 ~66 ~38 ~378 ~68 ~38 dirt
fill ~368 ~69 ~38 ~378 ~69 ~38 grass_block
fill ~379 ~60 ~38 ~380 ~66 ~38 stone
fill ~379 ~67 ~38 ~380 ~69 ~38 dirt
fill ~379 ~70 ~38 ~380 ~70 ~38 grass_block
fill ~381 ~60 ~38 ~383 ~65 ~38 stone
fill ~381 ~66 ~38 ~383 ~68 ~38 dirt
fill ~381 ~69 ~38 ~383 ~69 ~38 grass_block
fill ~368 ~60 ~39 ~383 ~65 ~39 stone
fill ~368 ~66 ~39 ~383 ~68 ~39 dirt
fill ~368 ~69 ~39 ~383 ~69 ~39 grass_block
fill ~368 ~60 ~40 ~369 ~65 ~40 stone
fill ~368 ~66 ~40 ~369 ~68 ~40 dirt
fill ~368 ~69 ~40 ~369 ~69 ~40 grass_block
fill ~370 ~60 ~40 ~370 ~64 ~40 stone
fill ~370 ~65 ~40 ~370 ~67 ~40 dirt
fill ~370 ~68 ~40 ~370 ~68 ~40 grass_block
fill ~371 ~60 ~40 ~383 ~65 ~40 stone
fill ~371 ~66 ~40 ~383 ~68 ~40 dirt
fill ~371 ~69 ~40 ~383 ~69 ~40 grass_block
fill ~368 ~60 ~41 ~369 ~65 ~41 stone
fill ~368 ~66 ~41 ~369 ~68 ~41 dirt
fill ~368 ~69 ~41 ~369 ~69 ~41 grass_block
fill ~370 ~60 ~41 ~374 ~64 ~41 stone
fill ~370 ~65 ~41 ~374 ~67 ~41 dirt
fill ~370 ~68 ~41 ~374 ~68 ~41 grass_block
fill ~375 ~60 ~41 ~382 ~65 ~41 stone
fill ~375 ~66 ~41 ~382 ~68 ~41 dirt
fill ~375 ~69 ~41 ~382 ~69 ~41 grass_block
fill ~383 ~60 ~41 ~383 ~64 ~41 stone
fill ~383 ~65 ~41 ~383 ~67 ~41 dirt
fill ~383 ~68 ~41 ~383 ~68 ~41 grass_block
fill ~368 ~60 ~42 ~370 ~65 ~42 stone
fill ~368 ~66 ~42 ~370 ~68 ~42 dirt
fill ~368 ~69 ~42 ~370 ~69 ~42 grass_block
fill ~371 ~60 ~42 ~375 ~64 ~42 stone
fill ~371 ~65 ~42 ~375 ~67 ~42 dirt
fill ~371 ~68 ~42 ~375 ~68 ~42 grass_block
fill ~376 ~60 ~42 ~381 ~65 ~42 stone
fill ~376 ~66 ~42 ~381 ~68 ~42 dirt
fill ~376 ~69 ~42 ~381 ~69 ~42 grass_block
fill ~382 ~60 ~42 ~383 ~64 ~42 stone
fill ~382 ~65 ~42 ~383 ~67 ~42 dirt
fill ~382 ~68 ~42 ~383 ~68 ~42 grass_block
fill ~368 ~60 ~43 ~370 ~65 ~43 stone
fill ~368 ~66 ~43 ~370 ~68 ~43 dirt
fill ~368 ~69 ~43 ~370 ~69 ~43 grass_block
fill ~371 ~60 ~43 ~383 ~64 ~43 stone
fill ~371 ~65 ~43 ~383 ~67 ~43 dirt
fill ~371 ~68 ~43 ~383 ~68 ~43 grass_block
fill ~368 ~60 ~44 ~371 ~65 ~44 stone
fill ~368 ~66 ~44 ~371 ~68 ~44 dirt
fill ~368 ~69 ~44 ~371 ~69 ~44 grass_block
fill ~372 ~60 ~44 ~383 ~64 ~44 stone
fill ~372 ~65 ~44 ~383 ~67 ~44 dirt
fill ~372 ~68 ~44 ~383 ~68 ~44 grass_block
fill ~368 ~60 ~45 ~371 ~65 ~45 stone
fill ~368 ~66 ~45 ~371 ~68 ~45 dirt
fill ~368 ~69 ~45 ~371 ~69 ~45 grass_block
fill ~372 ~60 ~45 ~374 ~64 ~45 stone
fill ~372 ~65 ~45 ~374 ~67 ~45 dirt
fill ~372 ~68 ~45 ~374 ~68 ~45 grass_block
fill ~375 ~60 ~45 ~376 ~63 ~45 stone
fill ~375 ~64 ~45 ~376 ~66 ~45 dirt
fill ~375 ~67 ~45 ~376 ~67 ~45 grass_block
fill ~377 ~60 ~45 ~383 ~64 ~45 stone
fill ~377 ~65 ~45 ~383 ~67 ~45 dirt
fill ~377 ~68 ~45 ~383 ~68 ~45 grass_block
fill ~368 ~60 ~46 ~368 ~66 ~46 stone
fill ~368 ~67 ~46 ~368 ~69 ~46 dirt
fill ~368 ~70 ~46 ~368 ~70 ~46 grass_block
fill ~369 ~60 ~46 ~372 ~65 ~46 stone
fill ~369 ~66 ~46 ~372 ~68 ~46 dirt
fill ~369 ~69 ~46 ~372 ~69 ~46 grass_block
fill ~373 ~60 ~46 ~375 ~64 ~46 stone
fill ~373 ~65 ~46 ~375 ~67 ~46 dirt
fill ~373 ~68 ~46 ~375 ~68 ~46 grass_block
fill ~376 ~60 ~46 ~377 ~63 ~46 stone
fill ~376 ~64 ~46 ~377 ~66 ~46 dirt
fill ~376 ~67 ~46 ~377 ~67 ~46 grass_block
fill ~378 ~60 ~46 ~379 ~64 ~46 stone
fill ~378 ~65 ~46 ~379 ~67 ~46 dirt
fill ~378 ~68 ~46 ~379 ~68 ~46 grass_block
fill ~380 ~60 ~46 ~382 ~63 ~46 stone
fill ~380 ~64 ~46 ~382 ~66 ~46 dirt
fill ~380 ~67 ~46 ~382 ~67 ~46 grass_block
fill ~383 ~60 ~46 ~383 ~64 ~46 stone
fill ~383 ~65 ~46 ~383 ~67 ~46 dirt
fill ~383 ~68 ~46 ~383 ~68 ~46 grass_block
fill ~368 ~60 ~47 ~369 ~66 ~47 stone
fill ~368 ~67 ~47 ~369 ~69 ~47 dirt
fill ~368 ~70 ~47 ~369 ~70 ~47 grass_block
fill ~370 ~60 ~47 ~372 ~65 ~47 stone
fill ~370 ~66 ~47 ~372 ~68 ~47 dirt
fill ~370 ~69 ~47 ~372 ~69 ~47 grass_block
fill ~373 ~60 ~47 ~376 ~64 ~47 stone
fill ~373 ~65 ~47 ~376 ~67 ~47 dirt
fill ~373 ~68 ~47 ~376 ~68 ~47 grass_block
fill ~377 ~60 ~47 ~382 ~63 ~47 stone
fill ~377 ~64 ~47 ~382 ~66 ~47 dirt
fill ~377 ~67 ~47 ~382 ~67 ~47 grass_block
fill ~383 ~60 ~47 ~383 ~64 ~47 stone
fill ~383 ~65 ~47 ~383 ~67 ~47 dirt
fill ~383 ~68 ~47 ~383 ~68 ~47 grass_block