fill ~304 ~60 ~16 ~304 ~64 ~16 stone
fill ~304 ~65 ~16 ~304 ~67 ~16 dirt
fill ~304 ~68 ~16 ~304 ~68 ~16 grass_block
fill ~305 ~60 ~16 ~314 ~65 ~16 stone
fill ~305 ~66 ~16 ~314 ~68 ~16 dirt
fill ~305 ~69 ~16 ~314 ~69 ~16 grass_block
fill ~315 ~60 ~16 ~319 ~64 ~16 stone
fill ~315 ~65 ~16 ~319 ~67 ~16 dirt
fill ~315 ~68 ~16 ~319 ~68 ~16 grass_block
fill ~304 ~60 ~17 ~314 ~65 ~17 stone
fill ~304 ~66 ~17 ~314 ~68 ~17 dirt
fill ~304 ~69 ~17 ~314 ~69 ~17 grass_block
fill ~315 ~60 ~17 ~319 ~64 ~17 stone
fill ~315 ~65 ~17 ~319 ~67 ~17 dirt
fill ~315 ~68 ~17 ~319 ~68 ~17 grass_block
fill ~304 ~60 ~18 ~314 ~65 ~18 stone
fill ~304 ~66 ~18 ~314 ~68 ~18 dirt
fill ~304 ~69 ~18 ~314 ~69 ~18 grass_block
fill ~315 ~60 ~18 ~319 ~64 ~18 stone
fill ~315 ~65 ~18 ~319 ~67 ~18 dirt
fill ~315 ~68 ~18 ~319 ~68 ~18 grass_block
fill ~304 ~60 ~19 ~312 ~65 ~19 stone
fill ~304 ~66 ~19 ~312 ~68 ~19 dirt
fill ~304 ~69 ~19 ~312 ~69 ~19 grass_block
fill ~313 ~60 ~19 ~319 ~64 ~19 stone
fill ~313 ~65 ~19 ~319 ~67 ~19 dirt
fill ~313 ~68 ~19 ~319 ~68 ~19 grass_block
fill ~304 ~60 ~20 ~311 ~65 ~20 stone
fill ~304 ~66 ~20 ~311 ~68 ~20 dirt
fill ~304 ~69 ~20 ~311 ~69 ~20 grass_block
fill ~312 ~60 ~20 ~316 ~64 ~20 stone
fill ~312 ~65 ~20 ~316 ~67 ~20 dirt
fill ~312 ~68 ~20 ~316 ~68 ~20 grass_block
fill ~317 ~60 ~20 ~319 ~63 ~20 stone
fill ~317 ~64 ~20 ~319 ~66 ~20 dirt
fill ~317 ~67 ~20 ~319 ~67 ~20 grass_block
fill ~304 ~60 ~21 ~310 ~65 ~21 stone
fill ~304 ~66 ~21 ~310 ~68 ~21 dirt
fill ~304 ~69 ~21 ~310 ~69 ~21 grass_block
fill ~311 ~60 ~21 ~316 ~64 ~21 stone
fill ~311 ~65 ~21 ~316 ~67 ~21 dirt
fill ~311 ~68 ~21 ~316 ~68 ~21 grass_block
fill ~317 ~60 ~21 ~319 ~63 ~21 stone
fill ~317 ~64 ~21 ~319 ~66 ~21 dirt
fill ~317 ~67 ~21 ~319 ~67 ~21 grass_block
fill ~304 ~60 ~22 ~304 ~64 ~22 stone
fill ~304 ~65 ~22 ~304 ~67 ~22 dirt
fill ~304 ~68 ~22 ~304 ~68 ~22 grass_block
fill ~305 ~60 ~22 ~310 ~65 ~22 stone
fill ~305 ~66 ~22 ~310 ~68 ~22 dirt
fill ~305 ~69 ~22 ~310 ~69 ~22 grass_block
fill ~311 ~60 ~22 ~316 ~64 ~22 stone
fill ~311 ~65 ~22 ~316 ~67 ~22 dirt
fill ~311 ~68 ~22 ~316 ~68 ~22 grass_block
fill ~317 ~60 ~22 ~319 ~63 ~22 stone
fill ~317 ~64 ~22 ~319 ~66 ~22 dirt
fill ~317 ~67 ~22 ~319 ~67 ~22 grass_block
fill ~304 ~60 ~23 ~305 ~64 ~23 stone
fill ~304 ~65 ~23 ~305 ~67 ~23 dirt
fill ~304 ~68 ~23 ~305 ~68 ~23 grass_block
fill ~306 ~60 ~23 ~310 ~65 ~23 stone
fill ~306 ~66 ~23 ~310 ~68 ~23 dirt
fill ~306 ~69 ~23 ~310 ~69 ~23 grass_block
fill ~311 ~60 ~23 ~314 ~64 ~23 stone
fill ~311 ~65 ~23 ~314 ~67 ~23 dirt
fill ~311 ~68 ~23 ~314 ~68 ~23 grass_block
fill ~315 ~60 ~23 ~319 ~63 ~23 stone
fill ~315 ~64 ~23 ~319 ~66 ~23 dirt
fill ~315 ~67 ~23 ~319 ~67 ~23 grass_block
fill ~304 ~60 ~24 ~305 ~64 ~24 stone
fill ~304 ~65 ~24 ~305 ~67 ~24 dirt
fill ~304 ~68 ~24 ~305 ~68 ~24 grass_block
fill ~306 ~60 ~24 ~310 ~65 ~24 stone
fill ~306 ~66 ~24 ~310 ~68 ~24 dirt
fill ~306 ~69 ~24 ~310 ~69 ~24 grass_block
fill ~311 ~60 ~24 ~314 ~64 ~24 stone
fill ~311 ~65 ~24 ~314 ~67 ~24 dirt
fill ~311 ~68 ~24 ~314 ~68 ~24 grass_block
fill ~315 ~60 ~24 ~319 ~63 ~24 stone
fill ~315 ~64 ~24 ~319 ~66 ~24 dirt
fill ~315 ~67 ~24 ~319 ~67 ~24 grass_block
fill ~304 ~60 ~25 ~305 ~64 ~25 stone
fill ~304 ~65 ~25 ~305 ~67 ~25 dirt
fill ~304 ~68 ~25 ~305 ~68 ~25 grass_block
fill ~306 ~60 ~25 ~309 ~65 ~25 stone
fill ~306 ~66 ~25 ~309 ~68 ~25 dirt
fill ~306 ~69 ~25 ~309 ~69 ~25 grass_block
fill ~310 ~60 ~25 ~314 ~64 ~25 stone
fill ~310 ~65 ~25 ~314 ~67 ~25 dirt
fill ~310 ~68 ~25 ~314 ~68 ~25 grass_block
fill ~315 ~60 ~25 ~319 ~63 ~25 stone
fill ~315 ~64 ~25 ~319 ~66 ~25 dirt
fill ~315 ~67 ~25 ~319 ~67 ~25 grass_block
fill ~304 ~60 ~26 ~305 ~64 ~26 stone
fill ~304 ~65 ~26 ~305 ~67 ~26 dirt
fill ~304 ~68 ~26 ~305 ~68 ~26 grass_block
fill ~306 ~60 ~26 ~307 ~65 ~26 stone
fill ~306 ~66 ~26 ~307 ~68 ~26 dirt
fill ~306 ~69 ~26 ~307 ~69 ~26 grass_block
fill ~308 ~60 ~26 ~308 ~64 ~26 stone
fill ~308 ~65 ~26 ~308 ~67 ~26 dirt
fill ~308 ~68 ~26 ~308 ~68 ~26 grass_block
fill ~309 ~60 ~26 ~309 ~65 ~26 stone
fill ~309 ~66 ~26 ~309 ~68 ~26 dirt
fill ~309 ~69 ~26 ~309 ~69 ~26 grass_block
fill ~310 ~60 ~26 ~313 ~64 ~26 stone
fill ~310 ~65 ~26 ~313 ~67 ~26 dirt
fill ~310 ~68 ~26 ~313 ~68 ~26 grass_block
fill ~314 ~60 ~26 ~319 ~63 ~26 stone
fill ~314 ~64 ~26 ~319 ~66 ~26 dirt
fill ~314 ~67 ~26 ~319 ~67 ~26 grass_block
fill ~304 ~60 ~27 ~304 ~64 ~27 stone
fill ~304 ~65 ~27 ~304 ~67 ~27 dirt
fill ~304 ~68 ~27 ~304 ~68 ~27 grass_block
fill ~305 ~60 ~27 ~305 ~65 ~27 stone
fill ~305 ~66 ~27 ~305 ~68 ~27 dirt
fill ~305 ~69 ~27 ~305 ~69 ~27 grass_block
fill ~306 ~60 ~27 ~313 ~64 ~27 stone
fill ~306 ~65 ~27 ~313 ~67 ~27 dirt
fill ~306 ~68 ~27 ~313 ~68 ~27 grass_block
fill ~314 ~60 ~27 ~319 ~63 ~27 stone
fill ~314 ~64 ~27 ~319 ~66 ~27 dirt
fill ~314 ~67 ~27 ~319 ~67 ~27 grass_block
fill ~304 ~60 ~28 ~304 ~64 ~28 stone
fill ~304 ~65 ~28 ~304 ~67 ~28 dirt
fill ~304 ~68 ~28 ~304 ~68 ~28 grass_block
fill ~305 ~60 ~28 ~306 ~65 ~28 stone
fill ~305 ~66 ~28 ~306 ~68 ~28 dirt
fill ~305 ~69 ~28 ~306 ~69 ~28 grass_block
fill ~307 ~60 ~28 ~312 ~64 ~28 stone
fill ~307 ~65 ~28 ~312 ~67 ~28 dirt
fill ~307 ~68 ~28 ~312 ~68 ~28 grass_block
fill ~313 ~60 ~28 ~319 ~63 ~28 stone
fill ~313 ~64 ~28 ~319 ~66 ~28 dirt
fill ~313 ~67 ~28 ~319 ~67 ~28 grass_block
fill ~304 ~60 ~29 ~312 ~64 ~29 stone
fill ~304 ~65 ~29 ~312 ~67 ~29 dirt
fill ~304 ~68 ~29 ~312 ~68 ~29 grass_block
fill ~313 ~60 ~29 ~319 ~63 ~29 stone
fill ~313 ~64 ~29 ~319 ~66 ~29 dirt
fill ~313 ~67 ~29 ~319 ~67 ~29 grass_block
fill ~304 ~60 ~30 ~305 ~65 ~30 stone
fill ~304 ~66 ~30 ~305 ~68 ~30 dirt
fill ~304 ~69 ~30 ~305 ~69 ~30 grass_block
fill ~306 ~60 ~30 ~312 ~64 ~30 stone
fill ~306 ~65 ~30 ~312 ~67 ~30 dirt
fill ~306 ~68 ~30 ~312 ~68 ~30 grass_block
fill ~313 ~60 ~30 ~317 ~63 ~30 stone
fill ~313 ~64 ~30 ~317 ~66 ~30 dirt
fill ~313 ~67 ~30 ~317 ~67 ~30 grass_block
fill ~318 ~60 ~30 ~318 ~62 ~30 stone
fill ~318 ~63 ~30 ~318 ~65 ~30 dirt
fill ~318 ~66 ~30 ~318 ~66 ~30 grass_block
fill ~319 ~60 ~30 ~319 ~63 ~30 stone
fill ~319 ~64 ~30 ~319 ~66 ~30 dirt
fill ~319 ~67 ~30 ~319 ~67 ~30 grass_block
fill ~304 ~60 ~31 ~305 ~65 ~31 stone
fill ~304 ~66 ~31 ~305 ~68 ~31 dirt
fill ~304 ~69 ~31 ~305 ~69 ~31 grass_block
fill ~306 ~60 ~31 ~312 ~64 ~31 stone
fill ~306 ~65 ~31 ~312 ~67 ~31 dirt
fill ~306 ~68 ~31 ~312 ~68 ~31 grass_block
fill ~313 ~60 ~31 ~317 ~63 ~31 stone
fill ~313 ~64 ~31 ~317 ~66 ~31 dirt
fill ~313 ~67 ~31 ~317 ~67 ~31 grass_block
fill ~318 ~60 ~31 ~318 ~62 ~31 stone
fill ~318 ~63 ~31 ~318 ~65 ~31 dirt
fill ~318 ~66 ~31 ~318 ~66 ~31 grass_block
fill ~319 ~60 ~31 ~319 ~63 ~31 stone
fill ~319 ~64 ~31 ~319 ~66 ~31 dirt
fill ~319 ~67 ~31 ~319 ~67 ~31 grass_block