fill ~288 ~60 ~96 ~294 ~63 ~96 stone
fill ~288 ~64 ~96 ~294 ~66 ~96 dirt
fill ~288 ~67 ~96 ~294 ~67 ~96 grass_block
fill ~295 ~60 ~96 ~303 ~62 ~96 stone
fill ~295 ~63 ~96 ~303 ~65 ~96 dirt
fill ~295 ~66 ~96 ~303 ~66 ~96 grass_block
fill ~288 ~60 ~97 ~294 ~63 ~97 stone
fill ~288 ~64 ~97 ~294 ~66 ~97 dirt
fill ~288 ~67 ~97 ~294 ~67 ~97 grass_block
fill ~295 ~60 ~97 ~303 ~62 ~97 stone
fill ~295 ~63 ~97 ~303 ~65 ~97 dirt
fill ~295 ~66 ~97 ~303 ~66 ~97 grass_block
fill ~288 ~60 ~98 ~294 ~63 ~98 stone
fill ~288 ~64 ~98 ~294 ~66 ~98 dirt
fill ~288 ~67 ~98 ~294 ~67 ~98 grass_block
fill ~295 ~60 ~98 ~303 ~62 ~98 stone
fill ~295 ~63 ~98 ~303 ~65 ~98 dirt
fill ~295 ~66 ~98 ~303 ~66 ~98 grass_block
fill ~288 ~60 ~99 ~295 ~63 ~99 stone
fill ~288 ~64 ~99 ~295 ~66 ~99 dirt
fill ~288 ~67 ~99 ~295 ~67 ~99 grass_block
fill ~296 ~60 ~99 ~303 ~62 ~99 stone
fill ~296 ~63 ~99 ~303 ~65 ~99 dirt
fill ~296 ~66 ~99 ~303 ~66 ~99 grass_block
fill ~288 ~60 ~100 ~295 ~63 ~100 stone
fill ~288 ~64 ~100 ~295 ~66 ~100 dirt
fill ~288 ~67 ~100 ~295 ~67 ~100 grass_block
fill ~296 ~60 ~100 ~303 ~62 ~100 stone
fill ~296 ~63 ~100 ~303 ~65 ~100 dirt
fill ~296 ~66 ~100 ~303 ~66 ~100 grass_block
fill ~288 ~60 ~101 ~295 ~63 ~101 stone
fill ~288 ~64 ~101 ~295 ~66 ~101 dirt
fill ~288 ~67 ~101 ~295 ~67 ~101 grass_block
fill ~296 ~60 ~101 ~302 ~62 ~101 stone
fill ~296 ~63 ~101 ~302 ~65 ~101 dirt
fill ~296 ~66 ~101 ~302 ~66 ~101 grass_block
fill ~303 ~60 ~101 ~303 ~61 ~101 stone
fill ~303 ~62 ~101 ~303 ~64 ~101 dirt
fill ~303 ~65 ~101 ~303 ~65 ~101 grass_block
fill ~288 ~60 ~102 ~288 ~63 ~102 stone
fill ~288 ~64 ~102 ~288 ~66 ~102 dirt
fill ~288 ~67 ~102 ~288 ~67 ~102 grass_block
fill ~289 ~60 ~102 ~291 ~62 ~102 stone
fill ~289 ~63 ~102 ~291 ~65 ~102 dirt
fill ~289 ~66 ~102 ~291 ~66 ~102 grass_block
fill ~292 ~60 ~102 ~293 ~63 ~102 stone
fill ~292 ~64 ~102 ~293 ~66 ~102 dirt
fill ~292 ~67 ~102 ~293 ~67 ~102 grass_block
fill ~294 ~60 ~102 ~301 ~62 ~102 stone
fill ~294 ~63 ~102 ~301 ~65 ~102 dirt
fill ~294 ~66 ~102 ~301 ~66 ~102 grass_block
fill ~302 ~60 ~102 ~303 ~61 ~102 stone
fill ~302 ~62 ~102 ~303 ~64 ~102 dirt
fill ~302 ~65 ~102 ~303 ~65 ~102 grass_block
fill ~288 ~60 ~103 ~301 ~62 ~103 stone
fill ~288 ~63 ~103 ~301 ~65 ~103 dirt
fill ~288 ~66 ~103 ~301 ~66 ~103 grass_block
fill ~302 ~60 ~103 ~303 ~61 ~103 stone
fill ~302 ~62 ~103 ~303 ~64 ~103 dirt
fill ~302 ~65 ~103 ~303 ~65 ~103 grass_block
fill ~288 ~60 ~104 ~303 ~62 ~104 stone
fill ~288 ~63 ~104 ~303 ~65 ~104 dirt
fill ~288 ~66 ~104 ~303 ~66 ~104 grass_block
fill ~288 ~60 ~105 ~290 ~63 ~105 stone
fill ~288 ~64 ~105 ~290 ~66 ~105 dirt
fill ~288 ~67 ~105 ~290 ~67 ~105 grass_block
fill ~291 ~60 ~105 ~291 ~62 ~105 stone
fill ~291 ~63 ~105 ~291 ~65 ~105 dirt
fill ~291 ~66 ~105 ~291 ~66 ~105 grass_block
fill ~292 ~60 ~105 ~293 ~63 ~105 stone
fill ~292 ~64 ~105 ~293 ~66 ~105 dirt
fill ~292 ~67 ~105 ~293 ~67 ~105 grass_block
fill ~294 ~60 ~105 ~303 ~62 ~105 stone
fill ~294 ~63 ~105 ~303 ~65 ~105 dirt
fill ~294 ~66 ~105 ~303 ~66 ~105 grass_block
fill ~288 ~60 ~106 ~297 ~63 ~106 stone
fill ~288 ~64 ~106 ~297 ~66 ~106 dirt
fill ~288 ~67 ~106 ~297 ~67 ~106 grass_block
fill ~298 ~60 ~106 ~302 ~62 ~106 stone
fill ~298 ~63 ~106 ~302 ~65 ~106 dirt
fill ~298 ~66 ~106 ~302 ~66 ~106 grass_block
fill ~303 ~60 ~106 ~303 ~63 ~106 stone
fill ~303 ~64 ~106 ~303 ~66 ~106 dirt
fill ~303 ~67 ~106 ~303 ~67 ~106 grass_block
fill ~288 ~60 ~107 ~290 ~64 ~107 stone
fill ~288 ~65 ~107 ~290 ~67 ~107 dirt
fill ~288 ~68 ~107 ~290 ~68 ~107 grass_block
fill ~291 ~60 ~107 ~291 ~63 ~107 stone
fill ~291 ~64 ~107 ~291 ~66 ~107 dirt
fill ~291 ~67 ~107 ~291 ~67 ~107 grass_block
fill ~292 ~60 ~107 ~293 ~64 ~107 stone
fill ~292 ~65 ~107 ~293 ~67 ~107 dirt
fill ~292 ~68 ~107 ~293 ~68 ~107 grass_block
fill ~294 ~60 ~107 ~296 ~63 ~107 stone
fill ~294 ~64 ~107 ~296 ~66 ~107 dirt
fill ~294 ~67 ~107 ~296 ~67 ~107 grass_block
fill ~297 ~60 ~107 ~302 ~62 ~107 stone
fill ~297 ~63 ~107 ~302 ~65 ~107 dirt
fill ~297 ~66 ~107 ~302 ~66 ~107 grass_block
fill ~303 ~60 ~107 ~303 ~63 ~107 stone
fill ~303 ~64 ~107 ~303 ~66 ~107 dirt
fill ~303 ~67 ~107 ~303 ~67 ~107 grass_block
fill ~288 ~60 ~108 ~292 ~64 ~108 stone
fill ~288 ~65 ~108 ~292 ~67 ~108 dirt
fill ~288 ~68 ~108 ~292 ~68 ~108 grass_block
fill ~293 ~60 ~108 ~296 ~63 ~108 stone
fill ~293 ~64 ~108 ~296 ~66 ~108 dirt
fill ~293 ~67 ~108 ~296 ~67 ~108 grass_block
fill ~297 ~60 ~108 ~301 ~62 ~108 stone
fill ~297 ~63 ~108 ~301 ~65 ~108 dirt
fill ~297 ~66 ~108 ~301 ~66 ~108 grass_block
fill ~302 ~60 ~108 ~303 ~63 ~108 stone
fill ~302 ~64 ~108 ~303 ~66 ~108 dirt
fill ~302 ~67 ~108 ~303 ~67 ~108 grass_block
fill ~288 ~60 ~109 ~288 ~65 ~109 stone
fill ~288 ~66 ~109 ~288 ~68 ~109 dirt
fill ~288 ~69 ~109 ~288 ~69 ~109 grass_block
fill ~289 ~60 ~109 ~291 ~64 ~109 stone
fill ~289 ~65 ~109 ~291 ~67 ~109 dirt
fill ~289 ~68 ~109 ~291 ~68 ~109 grass_block
fill ~292 ~60 ~109 ~295 ~63 ~109 stone
fill ~292 ~64 ~109 ~295 ~66 ~109 dirt
fill ~292 ~67 ~109 ~295 ~67 ~109 grass_block
fill ~296 ~60 ~109 ~298 ~62 ~109 stone
fill ~296 ~63 ~109 ~298 ~65 ~109 dirt
fill ~296 ~66 ~109 ~298 ~66 ~109 grass_block
fill ~299 ~60 ~109 ~303 ~63 ~109 stone
fill ~299 ~64 ~109 ~303 ~66 ~109 dirt
fill ~299 ~67 ~109 ~303 ~67 ~109 grass_block
fill ~288 ~60 ~110 ~288 ~65 ~110 stone
fill ~288 ~66 ~110 ~288 ~68 ~110 dirt
fill ~288 ~69 ~110 ~288 ~69 ~110 grass_block
fill ~289 ~60 ~110 ~291 ~64 ~110 stone
fill ~289 ~65 ~110 ~291 ~67 ~110 dirt
fill ~289 ~68 ~110 ~291 ~68 ~110 grass_block
fill ~292 ~60 ~110 ~294 ~63 ~110 stone
fill ~292 ~64 ~110 ~294 ~66 ~110 dirt
fill ~292 ~67 ~110 ~294 ~67 ~110 grass_block
fill ~295 ~60 ~110 ~295 ~62 ~110 stone
fill ~295 ~63 ~110 ~295 ~65 ~110 dirt
fill ~295 ~66 ~110 ~295 ~66 ~110 grass_block
fill ~296 ~60 ~110 ~298 ~63 ~110 stone
fill ~296 ~64 ~110 ~298 ~66 ~110 dirt
fill ~296 ~67 ~110 ~298 ~67 ~110 grass_block
fill ~299 ~60 ~110 ~300 ~64 ~110 stone
fill ~299 ~65 ~110 ~300 ~67 ~110 dirt
fill ~299 ~68 ~110 ~300 ~68 ~110 grass_block
fill ~301 ~60 ~110 ~303 ~63 ~110 stone
fill ~301 ~64 ~110 ~303 ~66 ~110 dirt
fill ~301 ~67 ~110 ~303 ~67 ~110 grass_block
fill ~288 ~60 ~111 ~289 ~65 ~111 stone
fill ~288 ~66 ~111 ~289 ~68 ~111 dirt
fill ~288 ~69 ~111 ~289 ~69 ~111 grass_block
fill ~290 ~60 ~111 ~291 ~64 ~111 stone
fill ~290 ~65 ~111 ~291 ~67 ~111 dirt
fill ~290 ~68 ~111 ~291 ~68 ~111 grass_block
fill ~292 ~60 ~111 ~297 ~63 ~111 stone
fill ~292 ~64 ~111 ~297 ~66 ~111 dirt
fill ~292 ~67 ~111 ~297 ~67 ~111 grass_block
fill ~298 ~60 ~111 ~303 ~64 ~111 stone
fill ~298 ~65 ~111 ~303 ~67 ~111 dirt
fill ~298 ~68 ~111 ~303 ~68 ~111 grass_block