fill ~320 ~60 ~64 ~323 ~63 ~64 stone
fill ~320 ~64 ~64 ~323 ~66 ~64 dirt
fill ~320 ~67 ~64 ~323 ~67 ~64 grass_block
fill ~324 ~60 ~64 ~325 ~62 ~64 stone
fill ~324 ~63 ~64 ~325 ~65 ~64 dirt
fill ~324 ~66 ~64 ~325 ~66 ~64 grass_block
fill ~326 ~60 ~64 ~327 ~63 ~64 stone
fill ~326 ~64 ~64 ~327 ~66 ~64 dirt
fill ~326 ~67 ~64 ~327 ~67 ~64 grass_block
fill ~328 ~60 ~64 ~335 ~64 ~64 stone
fill ~328 ~65 ~64 ~335 ~67 ~64 dirt
fill ~328 ~68 ~64 ~335 ~68 ~64 grass_block
fill ~320 ~60 ~65 ~322 ~63 ~65 stone
fill ~320 ~64 ~65 ~322 ~66 ~65 dirt
fill ~320 ~67 ~65 ~322 ~67 ~65 grass_block
fill ~323 ~60 ~65 ~325 ~62 ~65 stone
fill ~323 ~63 ~65 ~325 ~65 ~65 dirt
fill ~323 ~66 ~65 ~325 ~66 ~65 grass_block
fill ~326 ~60 ~65 ~328 ~63 ~65 stone
fill ~326 ~64 ~65 ~328 ~66 ~65 dirt
fill ~326 ~67 ~65 ~328 ~67 ~65 grass_block
fill ~329 ~60 ~65 ~335 ~64 ~65 stone
fill ~329 ~65 ~65 ~335 ~67 ~65 dirt
fill ~329 ~68 ~65 ~335 ~68 ~65 grass_block
fill ~320 ~60 ~66 ~320 ~63 ~66 stone
fill ~320 ~64 ~66 ~320 ~66 ~66 dirt
fill ~320 ~67 ~66 ~320 ~67 ~66 grass_block
fill ~321 ~60 ~66 ~325 ~62 ~66 stone
fill ~321 ~63 ~66 ~325 ~65 ~66 dirt
fill ~321 ~66 ~66 ~325 ~66 ~66 grass_block
fill ~326 ~60 ~66 ~329 ~63 ~66 stone
fill ~326 ~64 ~66 ~329 ~66 ~66 dirt
fill ~326 ~67 ~66 ~329 ~67 ~66 grass_block
fill ~330 ~60 ~66 ~332 ~64 ~66 stone
fill ~330 ~65 ~66 ~332 ~67 ~66 dirt
fill ~330 ~68 ~66 ~332 ~68 ~66 grass_block
fill ~333 ~60 ~66 ~335 ~63 ~66 stone
fill ~333 ~64 ~66 ~335 ~66 ~66 dirt
fill ~333 ~67 ~66 ~335 ~67 ~66 grass_block
fill ~320 ~60 ~67 ~320 ~63 ~67 stone
fill ~320 ~64 ~67 ~320 ~66 ~67 dirt
fill ~320 ~67 ~67 ~320 ~67 ~67 grass_block
fill ~321 ~60 ~67 ~325 ~62 ~67 stone
fill ~321 ~63 ~67 ~325 ~65 ~67 dirt
fill ~321 ~66 ~67 ~325 ~66 ~67 grass_block
fill ~326 ~60 ~67 ~329 ~63 ~67 stone
fill ~326 ~64 ~67 ~329 ~66 ~67 dirt
fill ~326 ~67 ~67 ~329 ~67 ~67 grass_block
fill ~330 ~60 ~67 ~332 ~64 ~67 stone
fill ~330 ~65 ~67 ~332 ~67 ~67 dirt
fill ~330 ~68 ~67 ~332 ~68 ~67 grass_block
fill ~333 ~60 ~67 ~335 ~63 ~67 stone
fill ~333 ~64 ~67 ~335 ~66 ~67 dirt
fill ~333 ~67 ~67 ~335 ~67 ~67 grass_block
fill ~320 ~60 ~68 ~320 ~63 ~68 stone
fill ~320 ~64 ~68 ~320 ~66 ~68 dirt
fill ~320 ~67 ~68 ~320 ~67 ~68 grass_block
fill ~321 ~60 ~68 ~325 ~62 ~68 stone
fill ~321 ~63 ~68 ~325 ~65 ~68 dirt
fill ~321 ~66 ~68 ~325 ~66 ~68 grass_block
fill ~326 ~60 ~68 ~330 ~63 ~68 stone
fill ~326 ~64 ~68 ~330 ~66 ~68 dirt
fill ~326 ~67 ~68 ~330 ~67 ~68 grass_block
fill ~331 ~60 ~68 ~331 ~64 ~68 stone
fill ~331 ~65 ~68 ~331 ~67 ~68 dirt
fill ~331 ~68 ~68 ~331 ~68 ~68 grass_block
fill ~332 ~60 ~68 ~335 ~63 ~68 stone
fill ~332 ~64 ~68 ~335 ~66 ~68 dirt
fill ~332 ~67 ~68 ~335 ~67 ~68 grass_block
fill ~320 ~60 ~69 ~325 ~62 ~69 stone
fill ~320 ~63 ~69 ~325 ~65 ~69 dirt
fill ~320 ~66 ~69 ~325 ~66 ~69 grass_block
fill ~326 ~60 ~69 ~335 ~63 ~69 stone
fill ~326 ~64 ~69 ~335 ~66 ~69 dirt
fill ~326 ~67 ~69 ~335 ~67 ~69 grass_block
fill ~320 ~60 ~70 ~325 ~62 ~70 stone
fill ~320 ~63 ~70 ~325 ~65 ~70 dirt
fill ~320 ~66 ~70 ~325 ~66 ~70 grass_block
fill ~326 ~60 ~70 ~335 ~63 ~70 stone
fill ~326 ~64 ~70 ~335 ~66 ~70 dirt
fill ~326 ~67 ~70 ~335 ~67 ~70 grass_block
fill ~320 ~60 ~71 ~326 ~62 ~71 stone
fill ~320 ~63 ~71 ~326 ~65 ~71 dirt
fill ~320 ~66 ~71 ~326 ~66 ~71 grass_block
fill ~327 ~60 ~71 ~332 ~63 ~71 stone
fill ~327 ~64 ~71 ~332 ~66 ~71 dirt
fill ~327 ~67 ~71 ~332 ~67 ~71 grass_block
fill ~333 ~60 ~71 ~335 ~62 ~71 stone
fill ~333 ~63 ~71 ~335 ~65 ~71 dirt
fill ~333 ~66 ~71 ~335 ~66 ~71 grass_block
fill ~320 ~60 ~72 ~327 ~62 ~72 stone
fill ~320 ~63 ~72 ~327 ~65 ~72 dirt
fill ~320 ~66 ~72 ~327 ~66 ~72 grass_block
fill ~328 ~60 ~72 ~332 ~63 ~72 stone
fill ~328 ~64 ~72 ~332 ~66 ~72 dirt
fill ~328 ~67 ~72 ~332 ~67 ~72 grass_block
fill ~333 ~60 ~72 ~335 ~62 ~72 stone
fill ~333 ~63 ~72 ~335 ~65 ~72 dirt
fill ~333 ~66 ~72 ~335 ~66 ~72 grass_block
fill ~320 ~60 ~73 ~328 ~62 ~73 stone
fill ~320 ~63 ~73 ~328 ~65 ~73 dirt
fill ~320 ~66 ~73 ~328 ~66 ~73 grass_block
fill ~329 ~60 ~73 ~332 ~63 ~73 stone
fill ~329 ~64 ~73 ~332 ~66 ~73 dirt
fill ~329 ~67 ~73 ~332 ~67 ~73 grass_block
fill ~333 ~60 ~73 ~335 ~62 ~73 stone
fill ~333 ~63 ~73 ~335 ~65 ~73 dirt
fill ~333 ~66 ~73 ~335 ~66 ~73 grass_block
fill ~320 ~60 ~74 ~320 ~61 ~74 stone
fill ~320 ~62 ~74 ~320 ~64 ~74 dirt
fill ~320 ~65 ~74 ~320 ~65 ~74 grass_block
fill ~321 ~60 ~74 ~326 ~62 ~74 stone
fill ~321 ~63 ~74 ~326 ~65 ~74 dirt
fill ~321 ~66 ~74 ~326 ~66 ~74 grass_block
fill ~327 ~60 ~74 ~327 ~63 ~74 stone
fill ~327 ~64 ~74 ~327 ~66 ~74 dirt
fill ~327 ~67 ~74 ~327 ~67 ~74 grass_block
fill ~328 ~60 ~74 ~335 ~62 ~74 stone
fill ~328 ~63 ~74 ~335 ~65 ~74 dirt
fill ~328 ~66 ~74 ~335 ~66 ~74 grass_block
fill ~320 ~60 ~75 ~320 ~61 ~75 stone
fill ~320 ~62 ~75 ~320 ~64 ~75 dirt
fill ~320 ~65 ~75 ~320 ~65 ~75 grass_block
fill ~321 ~60 ~75 ~335 ~62 ~75 stone
fill ~321 ~63 ~75 ~335 ~65 ~75 dirt
fill ~321 ~66 ~75 ~335 ~66 ~75 grass_block
fill ~320 ~60 ~76 ~320 ~61 ~76 stone
fill ~320 ~62 ~76 ~320 ~64 ~76 dirt
fill ~320 ~65 ~76 ~320 ~65 ~76 grass_block
fill ~321 ~60 ~76 ~335 ~62 ~76 stone
fill ~321 ~63 ~76 ~335 ~65 ~76 dirt
fill ~321 ~66 ~76 ~335 ~66 ~76 grass_block
fill ~320 ~60 ~77 ~321 ~61 ~77 stone
fill ~320 ~62 ~77 ~321 ~64 ~77 dirt
fill ~320 ~65 ~77 ~321 ~65 ~77 grass_block
fill ~322 ~60 ~77 ~335 ~62 ~77 stone
fill ~322 ~63 ~77 ~335 ~65 ~77 dirt
fill ~322 ~66 ~77 ~335 ~66 ~77 grass_block
fill ~320 ~60 ~78 ~325 ~61 ~78 stone
fill ~320 ~62 ~78 ~325 ~64 ~78 dirt
fill ~320 ~65 ~78 ~325 ~65 ~78 grass_block
fill ~326 ~60 ~78 ~334 ~62 ~78 stone
fill ~326 ~63 ~78 ~334 ~65 ~78 dirt
fill ~326 ~66 ~78 ~334 ~66 ~78 grass_block
fill ~335 ~60 ~78 ~335 ~63 ~78 stone
fill ~335 ~64 ~78 ~335 ~66 ~78 dirt
fill ~335 ~67 ~78 ~335 ~67 ~78 grass_block
fill ~320 ~60 ~79 ~326 ~61 ~79 stone
fill ~320 ~62 ~79 ~326 ~64 ~79 dirt
fill ~320 ~65 ~79 ~326 ~65 ~79 grass_block
fill ~327 ~60 ~79 ~334 ~62 ~79 stone
fill ~327 ~63 ~79 ~334 ~65 ~79 dirt
fill ~327 ~66 ~79 ~334 ~66 ~79 grass_block
fill ~335 ~60 ~79 ~335 ~63 ~79 stone
fill ~335 ~64 ~79 ~335 ~66 ~79 dirt
fill ~335 ~67 ~79 ~335 ~67 ~79 grass_block