fill ~16 ~60 ~64 ~16 ~69 ~64 stone
fill ~16 ~70 ~64 ~16 ~72 ~64 dirt
fill ~16 ~73 ~64 ~16 ~73 ~64 grass_block
fill ~17 ~60 ~64 ~23 ~70 ~64 stone
fill ~17 ~71 ~64 ~23 ~73 ~64 dirt
fill ~17 ~74 ~64 ~23 ~74 ~64 grass_block
fill ~24 ~60 ~64 ~24 ~69 ~64 stone
fill ~24 ~70 ~64 ~24 ~72 ~64 dirt
fill ~24 ~73 ~64 ~24 ~73 ~64 grass_block
fill ~25 ~60 ~64 ~31 ~70 ~64 stone
fill ~25 ~71 ~64 ~31 ~73 ~64 dirt
fill ~25 ~74 ~64 ~31 ~74 ~64 grass_block
fill ~16 ~60 ~65 ~16 ~69 ~65 stone
fill ~16 ~70 ~65 ~16 ~72 ~65 dirt
fill ~16 ~73 ~65 ~16 ~73 ~65 grass_block
fill ~17 ~60 ~65 ~23 ~70 ~65 stone
fill ~17 ~71 ~65 ~23 ~73 ~65 dirt
fill ~17 ~74 ~65 ~23 ~74 ~65 grass_block
fill ~24 ~60 ~65 ~27 ~69 ~65 stone
fill ~24 ~70 ~65 ~27 ~72 ~65 dirt
fill ~24 ~73 ~65 ~27 ~73 ~65 grass_block
fill ~28 ~60 ~65 ~31 ~70 ~65 stone
fill ~28 ~71 ~65 ~31 ~73 ~65 dirt
fill ~28 ~74 ~65 ~31 ~74 ~65 grass_block
fill ~16 ~60 ~66 ~16 ~69 ~66 stone
fill ~16 ~70 ~66 ~16 ~72 ~66 dirt
fill ~16 ~73 ~66 ~16 ~73 ~66 grass_block
fill ~17 ~60 ~66 ~24 ~70 ~66 stone
fill ~17 ~71 ~66 ~24 ~73 ~66 dirt
fill ~17 ~74 ~66 ~24 ~74 ~66 grass_block
fill ~25 ~60 ~66 ~28 ~69 ~66 stone
fill ~25 ~70 ~66 ~28 ~72 ~66 dirt
fill ~25 ~73 ~66 ~28 ~73 ~66 grass_block
fill ~29 ~60 ~66 ~31 ~70 ~66 stone
fill ~29 ~71 ~66 ~31 ~73 ~66 dirt
fill ~29 ~74 ~66 ~31 ~74 ~66 grass_block
fill ~16 ~60 ~67 ~17 ~69 ~67 stone
fill ~16 ~70 ~67 ~17 ~72 ~67 dirt
fill ~16 ~73 ~67 ~17 ~73 ~67 grass_block
fill ~18 ~60 ~67 ~25 ~70 ~67 stone
fill ~18 ~71 ~67 ~25 ~73 ~67 dirt
fill ~18 ~74 ~67 ~25 ~74 ~67 grass_block
fill ~26 ~60 ~67 ~30 ~69 ~67 stone
fill ~26 ~70 ~67 ~30 ~72 ~67 dirt
fill ~26 ~73 ~67 ~30 ~73 ~67 grass_block
fill ~31 ~60 ~67 ~31 ~70 ~67 stone
fill ~31 ~71 ~67 ~31 ~73 ~67 dirt
fill ~31 ~74 ~67 ~31 ~74 ~67 grass_block
fill ~16 ~60 ~68 ~16 ~68 ~68 stone
fill ~16 ~69 ~68 ~16 ~71 ~68 dirt
fill ~16 ~72 ~68 ~16 ~72 ~68 grass_block
fill ~17 ~60 ~68 ~17 ~69 ~68 stone
fill ~17 ~70 ~68 ~17 ~72 ~68 dirt
fill ~17 ~73 ~68 ~17 ~73 ~68 grass_block
fill ~18 ~60 ~68 ~25 ~70 ~68 stone
fill ~18 ~71 ~68 ~25 ~73 ~68 dirt
fill ~18 ~74 ~68 ~25 ~74 ~68 grass_block
fill ~26 ~60 ~68 ~31 ~69 ~68 stone
fill ~26 ~70 ~68 ~31 ~72 ~68 dirt
fill ~26 ~73 ~68 ~31 ~73 ~68 grass_block
fill ~16 ~60 ~69 ~16 ~68 ~69 stone
fill ~16 ~69 ~69 ~16 ~71 ~69 dirt
fill ~16 ~72 ~69 ~16 ~72 ~69 grass_block
fill ~17 ~60 ~69 ~19 ~69 ~69 stone
fill ~17 ~70 ~69 ~19 ~72 ~69 dirt
fill ~17 ~73 ~69 ~19 ~73 ~69 grass_block
fill ~20 ~60 ~69 ~25 ~70 ~69 stone
fill ~20 ~71 ~69 ~25 ~73 ~69 dirt
fill ~20 ~74 ~69 ~25 ~74 ~69 grass_block
fill ~26 ~60 ~69 ~28 ~69 ~69 stone
fill ~26 ~70 ~69 ~28 ~72 ~69 dirt
fill ~26 ~73 ~69 ~28 ~73 ~69 grass_block
fill ~29 ~60 ~69 ~30 ~68 ~69 stone
fill ~29 ~69 ~69 ~30 ~71 ~69 dirt
fill ~29 ~72 ~69 ~30 ~72 ~69 grass_block
fill ~31 ~60 ~69 ~31 ~69 ~69 stone
fill ~31 ~70 ~69 ~31 ~72 ~69 dirt
fill ~31 ~73 ~69 ~31 ~73 ~69 grass_block
fill ~16 ~60 ~70 ~18 ~68 ~70 stone
fill ~16 ~69 ~70 ~18 ~71 ~70 dirt
fill ~16 ~72 ~70 ~18 ~72 ~70 grass_block
fill ~19 ~60 ~70 ~23 ~69 ~70 stone
fill ~19 ~70 ~70 ~23 ~72 ~70 dirt
fill ~19 ~73 ~70 ~23 ~73 ~70 grass_block
fill ~24 ~60 ~70 ~25 ~70 ~70 stone
fill ~24 ~71 ~70 ~25 ~73 ~70 dirt
fill ~24 ~74 ~70 ~25 ~74 ~70 grass_block
fill ~26 ~60 ~70 ~28 ~69 ~70 stone
fill ~26 ~70 ~70 ~28 ~72 ~70 dirt
fill ~26 ~73 ~70 ~28 ~73 ~70 grass_block
fill ~29 ~60 ~70 ~31 ~68 ~70 stone
fill ~29 ~69 ~70 ~31 ~71 ~70 dirt
fill ~29 ~72 ~70 ~31 ~72 ~70 grass_block
fill ~16 ~60 ~71 ~16 ~67 ~71 stone
fill ~16 ~68 ~71 ~16 ~70 ~71 dirt
fill ~16 ~71 ~71 ~16 ~71 ~71 grass_block
fill ~17 ~60 ~71 ~19 ~68 ~71 stone
fill ~17 ~69 ~71 ~19 ~71 ~71 dirt
fill ~17 ~72 ~71 ~19 ~72 ~71 grass_block
fill ~20 ~60 ~71 ~20 ~69 ~71 stone
fill ~20 ~70 ~71 ~20 ~72 ~71 dirt
fill ~20 ~73 ~71 ~20 ~73 ~71 grass_block
fill ~21 ~60 ~71 ~22 ~68 ~71 stone
fill ~21 ~69 ~71 ~22 ~71 ~71 dirt
fill ~21 ~72 ~71 ~22 ~72 ~71 grass_block
fill ~23 ~60 ~71 ~28 ~69 ~71 stone
fill ~23 ~70 ~71 ~28 ~72 ~71 dirt
fill ~23 ~73 ~71 ~28 ~73 ~71 grass_block
fill ~29 ~60 ~71 ~31 ~68 ~71 stone
fill ~29 ~69 ~71 ~31 ~71 ~71 dirt
fill ~29 ~72 ~71 ~31 ~72 ~71 grass_block
fill ~16 ~60 ~72 ~17 ~67 ~72 stone
fill ~16 ~68 ~72 ~17 ~70 ~72 dirt
fill ~16 ~71 ~72 ~17 ~71 ~72 grass_block
fill ~18 ~60 ~72 ~23 ~68 ~72 stone
fill ~18 ~69 ~72 ~23 ~71 ~72 dirt
fill ~18 ~72 ~72 ~23 ~72 ~72 grass_block
fill ~24 ~60 ~72 ~28 ~69 ~72 stone
fill ~24 ~70 ~72 ~28 ~72 ~72 dirt
fill ~24 ~73 ~72 ~28 ~73 ~72 grass_block
fill ~29 ~60 ~72 ~31 ~68 ~72 stone
fill ~29 ~69 ~72 ~31 ~71 ~72 dirt
fill ~29 ~72 ~72 ~31 ~72 ~72 grass_block
fill ~16 ~60 ~73 ~17 ~66 ~73 stone
fill ~16 ~67 ~73 ~17 ~69 ~73 dirt
fill ~16 ~70 ~73 ~17 ~70 ~73 grass_block
fill ~18 ~60 ~73 ~18 ~67 ~73 stone
fill ~18 ~68 ~73 ~18 ~70 ~73 dirt
fill ~18 ~71 ~73 ~18 ~71 ~73 grass_block
fill ~19 ~60 ~73 ~23 ~68 ~73 stone
fill ~19 ~69 ~73 ~23 ~71 ~73 dirt
fill ~19 ~72 ~73 ~23 ~72 ~73 grass_block
fill ~24 ~60 ~73 ~29 ~69 ~73 stone
fill ~24 ~70 ~73 ~29 ~72 ~73 dirt
fill ~24 ~73 ~73 ~29 ~73 ~73 grass_block
fill ~30 ~60 ~73 ~31 ~68 ~73 stone
fill ~30 ~69 ~73 ~31 ~71 ~73 dirt
fill ~30 ~72 ~73 ~31 ~72 ~73 grass_block
fill ~16 ~60 ~74 ~17 ~66 ~74 stone
fill ~16 ~67 ~74 ~17 ~69 ~74 dirt
fill ~16 ~70 ~74 ~17 ~70 ~74 grass_block
fill ~18 ~60 ~74 ~20 ~67 ~74 stone
fill ~18 ~68 ~74 ~20 ~70 ~74 dirt
fill ~18 ~71 ~74 ~20 ~71 ~74 grass_block
fill ~21 ~60 ~74 ~21 ~68 ~74 stone
fill ~21 ~69 ~74 ~21 ~71 ~74 dirt
fill ~21 ~72 ~74 ~21 ~72 ~74 grass_block
fill ~22 ~60 ~74 ~22 ~67 ~74 stone
fill ~22 ~68 ~74 ~22 ~70 ~74 dirt
fill ~22 ~71 ~74 ~22 ~71 ~74 grass_block
fill ~23 ~60 ~74 ~24 ~68 ~74 stone
fill ~23 ~69 ~74 ~24 ~71 ~74 dirt
fill ~23 ~72 ~74 ~24 ~72 ~74 grass_block
fill ~25 ~60 ~74 ~29 ~69 ~74 stone
fill ~25 ~70 ~74 ~29 ~72 ~74 dirt
fill ~25 ~73 ~74 ~29 ~73 ~74 grass_block
fill ~30 ~60 ~74 ~31 ~68 ~74 stone
fill ~30 ~69 ~74 ~31 ~71 ~74 dirt
fill ~30 ~72 ~74 ~31 ~72 ~74 grass_block
fill ~16 ~60 ~75 ~18 ~66 ~75 stone
fill ~16 ~67 ~75 ~18 ~69 ~75 dirt
fill ~16 ~70 ~75 ~18 ~70 ~75 grass_block
fill ~19 ~60 ~75 ~22 ~67 ~75 stone
fill ~19 ~68 ~75 ~22 ~70 ~75 dirt
fill ~19 ~71 ~75 ~22 ~71 ~75 grass_block
fill ~23 ~60 ~75 ~24 ~68 ~75 stone
fill ~23 ~69 ~75 ~24 ~71 ~75 dirt
fill ~23 ~72 ~75 ~24 ~72 ~75 grass_block
fill ~25 ~60 ~75 ~29 ~69 ~75 stone
fill ~25 ~70 ~75 ~29 ~72 ~75 dirt
fill ~25 ~73 ~75 ~29 ~73 ~75 grass_block
fill ~30 ~60 ~75 ~31 ~68 ~75 stone
fill ~30 ~69 ~75 ~31 ~71 ~75 dirt
fill ~30 ~72 ~75 ~31 ~72 ~75 grass_block
fill ~16 ~60 ~76 ~18 ~66 ~76 stone
fill ~16 ~67 ~76 ~18 ~69 ~76 dirt
fill ~16 ~70 ~76 ~18 ~70 ~76 grass_block
fill ~19 ~60 ~76 ~23 ~67 ~76 stone
fill ~19 ~68 ~76 ~23 ~70 ~76 dirt
fill ~19 ~71 ~76 ~23 ~71 ~76 grass_block
fill ~24 ~60 ~76 ~26 ~68 ~76 stone
fill ~24 ~69 ~76 ~26 ~71 ~76 dirt
fill ~24 ~72 ~76 ~26 ~72 ~76 grass_block
fill ~27 ~60 ~76 ~29 ~69 ~76 stone
fill ~27 ~70 ~76 ~29 ~72 ~76 dirt
fill ~27 ~73 ~76 ~29 ~73 ~76 grass_block
fill ~30 ~60 ~76 ~31 ~68 ~76 stone
fill ~30 ~69 ~76 ~31 ~71 ~76 dirt
fill ~30 ~72 ~76 ~31 ~72 ~76 grass_block
fill ~16 ~60 ~77 ~22 ~66 ~77 stone
fill ~16 ~67 ~77 ~22 ~69 ~77 dirt
fill ~16 ~70 ~77 ~22 ~70 ~77 grass_block
fill ~23 ~60 ~77 ~24 ~67 ~77 stone
fill ~23 ~68 ~77 ~24 ~70 ~77 dirt
fill ~23 ~71 ~77 ~24 ~71 ~77 grass_block
fill ~25 ~60 ~77 ~26 ~68 ~77 stone
fill ~25 ~69 ~77 ~26 ~71 ~77 dirt
fill ~25 ~72 ~77 ~26 ~72 ~77 grass_block
fill ~27 ~60 ~77 ~30 ~69 ~77 stone
fill ~27 ~70 ~77 ~30 ~72 ~77 dirt
fill ~27 ~73 ~77 ~30 ~73 ~77 grass_block
fill ~31 ~60 ~77 ~31 ~68 ~77 stone
fill ~31 ~69 ~77 ~31 ~71 ~77 dirt
fill ~31 ~72 ~77 ~31 ~72 ~77 grass_block
fill ~16 ~60 ~78 ~16 ~65 ~78 stone
fill ~16 ~66 ~78 ~16 ~68 ~78 dirt
fill ~16 ~69 ~78 ~16 ~69 ~78 grass_block
fill ~17 ~60 ~78 ~22 ~66 ~78 stone
fill ~17 ~67 ~78 ~22 ~69 ~78 dirt
fill ~17 ~70 ~78 ~22 ~70 ~78 grass_block
fill ~23 ~60 ~78 ~26 ~67 ~78 stone
fill ~23 ~68 ~78 ~26 ~70 ~78 dirt
fill ~23 ~71 ~78 ~26 ~71 ~78 grass_block
fill ~27 ~60 ~78 ~28 ~68 ~78 stone
fill ~27 ~69 ~78 ~28 ~71 ~78 dirt
fill ~27 ~72 ~78 ~28 ~72 ~78 grass_block
fill ~29 ~60 ~78 ~30 ~69 ~78 stone
fill ~29 ~70 ~78 ~30 ~72 ~78 dirt
fill ~29 ~73 ~78 ~30 ~73 ~78 grass_block
fill ~31 ~60 ~78 ~31 ~68 ~78 stone
fill ~31 ~69 ~78 ~31 ~71 ~78 dirt
fill ~31 ~72 ~78 ~31 ~72 ~78 grass_block
fill ~16 ~60 ~79 ~17 ~65 ~79 stone
fill ~16 ~66 ~79 ~17 ~68 ~79 dirt
fill ~16 ~69 ~79 ~17 ~69 ~79 grass_block
fill ~18 ~60 ~79 ~23 ~66 ~79 stone
fill ~18 ~67 ~79 ~23 ~69 ~79 dirt
fill ~18 ~70 ~79 ~23 ~70 ~79 grass_block
fill ~24 ~60 ~79 ~27 ~67 ~79 stone
fill ~24 ~68 ~79 ~27 ~70 ~79 dirt
fill ~24 ~71 ~79 ~27 ~71 ~79 grass_block
fill ~28 ~60 ~79 ~29 ~68 ~79 stone
fill ~28 ~69 ~79 ~29 ~71 ~79 dirt
fill ~28 ~72 ~79 ~29 ~72 ~79 grass_block
fill ~30 ~60 ~79 ~30 ~69 ~79 stone
fill ~30 ~70 ~79 ~30 ~72 ~79 dirt
fill ~30 ~73 ~79 ~30 ~73 ~79 grass_block
fill ~31 ~60 ~79 ~31 ~68 ~79 stone
fill ~31 ~69 ~79 ~31 ~71 ~79 dirt
fill ~31 ~72 ~79 ~31 ~72 ~79 grass_block