fill ~432 ~60 ~96 ~435 ~61 ~96 stone
fill ~432 ~62 ~96 ~435 ~64 ~96 dirt
fill ~432 ~65 ~96 ~435 ~65 ~96 grass_block
fill ~436 ~60 ~96 ~445 ~62 ~96 stone
fill ~436 ~63 ~96 ~445 ~65 ~96 dirt
fill ~436 ~66 ~96 ~445 ~66 ~96 grass_block
fill ~446 ~60 ~96 ~447 ~63 ~96 stone
fill ~446 ~64 ~96 ~447 ~66 ~96 dirt
fill ~446 ~67 ~96 ~447 ~67 ~96 grass_block
fill ~432 ~60 ~97 ~437 ~61 ~97 stone
fill ~432 ~62 ~97 ~437 ~64 ~97 dirt
fill ~432 ~65 ~97 ~437 ~65 ~97 grass_block
fill ~438 ~60 ~97 ~446 ~62 ~97 stone
fill ~438 ~63 ~97 ~446 ~65 ~97 dirt
fill ~438 ~66 ~97 ~446 ~66 ~97 grass_block
fill ~447 ~60 ~97 ~447 ~63 ~97 stone
fill ~447 ~64 ~97 ~447 ~66 ~97 dirt
fill ~447 ~67 ~97 ~447 ~67 ~97 grass_block
fill ~432 ~60 ~98 ~439 ~61 ~98 stone
fill ~432 ~62 ~98 ~439 ~64 ~98 dirt
fill ~432 ~65 ~98 ~439 ~65 ~98 grass_block
fill ~440 ~60 ~98 ~447 ~62 ~98 stone
fill ~440 ~63 ~98 ~447 ~65 ~98 dirt
fill ~440 ~66 ~98 ~447 ~66 ~98 grass_block
fill ~432 ~60 ~99 ~442 ~61 ~99 stone
fill ~432 ~62 ~99 ~442 ~64 ~99 dirt
fill ~432 ~65 ~99 ~442 ~65 ~99 grass_block
fill ~443 ~60 ~99 ~447 ~62 ~99 stone
fill ~443 ~63 ~99 ~447 ~65 ~99 dirt
fill ~443 ~66 ~99 ~447 ~66 ~99 grass_block
fill ~432 ~60 ~100 ~432 ~62 ~100 stone
fill ~432 ~63 ~100 ~432 ~65 ~100 dirt
fill ~432 ~66 ~100 ~432 ~66 ~100 grass_block
fill ~433 ~60 ~100 ~444 ~61 ~100 stone
fill ~433 ~62 ~100 ~444 ~64 ~100 dirt
fill ~433 ~65 ~100 ~444 ~65 ~100 grass_block
fill ~445 ~60 ~100 ~447 ~62 ~100 stone
fill ~445 ~63 ~100 ~447 ~65 ~100 dirt
fill ~445 ~66 ~100 ~447 ~66 ~100 grass_block
fill ~432 ~60 ~101 ~432 ~63 ~101 stone
fill ~432 ~64 ~101 ~432 ~66 ~101 dirt
fill ~432 ~67 ~101 ~432 ~67 ~101 grass_block
fill ~433 ~60 ~101 ~436 ~62 ~101 stone
fill ~433 ~63 ~101 ~436 ~65 ~101 dirt
fill ~433 ~66 ~101 ~436 ~66 ~101 grass_block
fill ~437 ~60 ~101 ~446 ~61 ~101 stone
fill ~437 ~62 ~101 ~446 ~64 ~101 dirt
fill ~437 ~65 ~101 ~446 ~65 ~101 grass_block
fill ~447 ~60 ~101 ~447 ~62 ~101 stone
fill ~447 ~63 ~101 ~447 ~65 ~101 dirt
fill ~447 ~66 ~101 ~447 ~66 ~101 grass_block
fill ~432 ~60 ~102 ~434 ~63 ~102 stone
fill ~432 ~64 ~102 ~434 ~66 ~102 dirt
fill ~432 ~67 ~102 ~434 ~67 ~102 grass_block
fill ~435 ~60 ~102 ~437 ~62 ~102 stone
fill ~435 ~63 ~102 ~437 ~65 ~102 dirt
fill ~435 ~66 ~102 ~437 ~66 ~102 grass_block
fill ~438 ~60 ~102 ~447 ~61 ~102 stone
fill ~438 ~62 ~102 ~447 ~64 ~102 dirt
fill ~438 ~65 ~102 ~447 ~65 ~102 grass_block
fill ~432 ~60 ~103 ~434 ~63 ~103 stone
fill ~432 ~64 ~103 ~434 ~66 ~103 dirt
fill ~432 ~67 ~103 ~434 ~67 ~103 grass_block
fill ~435 ~60 ~103 ~439 ~62 ~103 stone
fill ~435 ~63 ~103 ~439 ~65 ~103 dirt
fill ~435 ~66 ~103 ~439 ~66 ~103 grass_block
fill ~440 ~60 ~103 ~447 ~61 ~103 stone
fill ~440 ~62 ~103 ~447 ~64 ~103 dirt
fill ~440 ~65 ~103 ~447 ~65 ~103 grass_block
fill ~432 ~60 ~104 ~434 ~63 ~104 stone
fill ~432 ~64 ~104 ~434 ~66 ~104 dirt
fill ~432 ~67 ~104 ~434 ~67 ~104 grass_block
fill ~435 ~60 ~104 ~439 ~62 ~104 stone
fill ~435 ~63 ~104 ~439 ~65 ~104 dirt
fill ~435 ~66 ~104 ~439 ~66 ~104 grass_block
fill ~440 ~60 ~104 ~447 ~61 ~104 stone
fill ~440 ~62 ~104 ~447 ~64 ~104 dirt
fill ~440 ~65 ~104 ~447 ~65 ~104 grass_block
fill ~432 ~60 ~105 ~433 ~64 ~105 stone
fill ~432 ~65 ~105 ~433 ~67 ~105 dirt
fill ~432 ~68 ~105 ~433 ~68 ~105 grass_block
fill ~434 ~60 ~105 ~436 ~63 ~105 stone
fill ~434 ~64 ~105 ~436 ~66 ~105 dirt
fill ~434 ~67 ~105 ~436 ~67 ~105 grass_block
fill ~437 ~60 ~105 ~440 ~62 ~105 stone
fill ~437 ~63 ~105 ~440 ~65 ~105 dirt
fill ~437 ~66 ~105 ~440 ~66 ~105 grass_block
fill ~441 ~60 ~105 ~447 ~61 ~105 stone
fill ~441 ~62 ~105 ~447 ~64 ~105 dirt
fill ~441 ~65 ~105 ~447 ~65 ~105 grass_block
fill ~432 ~60 ~106 ~434 ~64 ~106 stone
fill ~432 ~65 ~106 ~434 ~67 ~106 dirt
fill ~432 ~68 ~106 ~434 ~68 ~106 grass_block
fill ~435 ~60 ~106 ~438 ~63 ~106 stone
fill ~435 ~64 ~106 ~438 ~66 ~106 dirt
fill ~435 ~67 ~106 ~438 ~67 ~106 grass_block
fill ~439 ~60 ~106 ~443 ~62 ~106 stone
fill ~439 ~63 ~106 ~443 ~65 ~106 dirt
fill ~439 ~66 ~106 ~443 ~66 ~106 grass_block
fill ~444 ~60 ~106 ~447 ~61 ~106 stone
fill ~444 ~62 ~106 ~447 ~64 ~106 dirt
fill ~444 ~65 ~106 ~447 ~65 ~106 grass_block
fill ~432 ~60 ~107 ~436 ~64 ~107 stone
fill ~432 ~65 ~107 ~436 ~67 ~107 dirt
fill ~432 ~68 ~107 ~436 ~68 ~107 grass_block
fill ~437 ~60 ~107 ~440 ~63 ~107 stone
fill ~437 ~64 ~107 ~440 ~66 ~107 dirt
fill ~437 ~67 ~107 ~440 ~67 ~107 grass_block
fill ~441 ~60 ~107 ~446 ~62 ~107 stone
fill ~441 ~63 ~107 ~446 ~65 ~107 dirt
fill ~441 ~66 ~107 ~446 ~66 ~107 grass_block
fill ~447 ~60 ~107 ~447 ~61 ~107 stone
fill ~447 ~62 ~107 ~447 ~64 ~107 dirt
fill ~447 ~65 ~107 ~447 ~65 ~107 grass_block
fill ~432 ~60 ~108 ~432 ~65 ~108 stone
fill ~432 ~66 ~108 ~432 ~68 ~108 dirt
fill ~432 ~69 ~108 ~432 ~69 ~108 grass_block
fill ~433 ~60 ~108 ~436 ~64 ~108 stone
fill ~433 ~65 ~108 ~436 ~67 ~108 dirt
fill ~433 ~68 ~108 ~436 ~68 ~108 grass_block
fill ~437 ~60 ~108 ~441 ~63 ~108 stone
fill ~437 ~64 ~108 ~441 ~66 ~108 dirt
fill ~437 ~67 ~108 ~441 ~67 ~108 grass_block
fill ~442 ~60 ~108 ~447 ~62 ~108 stone
fill ~442 ~63 ~108 ~447 ~65 ~108 dirt
fill ~442 ~66 ~108 ~447 ~66 ~108 grass_block
fill ~432 ~60 ~109 ~432 ~65 ~109 stone
fill ~432 ~66 ~109 ~432 ~68 ~109 dirt
fill ~432 ~69 ~109 ~432 ~69 ~109 grass_block
fill ~433 ~60 ~109 ~437 ~64 ~109 stone
fill ~433 ~65 ~109 ~437 ~67 ~109 dirt
fill ~433 ~68 ~109 ~437 ~68 ~109 grass_block
fill ~438 ~60 ~109 ~442 ~63 ~109 stone
fill ~438 ~64 ~109 ~442 ~66 ~109 dirt
fill ~438 ~67 ~109 ~442 ~67 ~109 grass_block
fill ~443 ~60 ~109 ~447 ~62 ~109 stone
fill ~443 ~63 ~109 ~447 ~65 ~109 dirt
fill ~443 ~66 ~109 ~447 ~66 ~109 grass_block
fill ~432 ~60 ~110 ~434 ~65 ~110 stone
fill ~432 ~66 ~110 ~434 ~68 ~110 dirt
fill ~432 ~69 ~110 ~434 ~69 ~110 grass_block
fill ~435 ~60 ~110 ~438 ~64 ~110 stone
fill ~435 ~65 ~110 ~438 ~67 ~110 dirt
fill ~435 ~68 ~110 ~438 ~68 ~110 grass_block
fill ~439 ~60 ~110 ~441 ~63 ~110 stone
fill ~439 ~64 ~110 ~441 ~66 ~110 dirt
fill ~439 ~67 ~110 ~441 ~67 ~110 grass_block
fill ~442 ~60 ~110 ~447 ~62 ~110 stone
fill ~442 ~63 ~110 ~447 ~65 ~110 dirt
fill ~442 ~66 ~110 ~447 ~66 ~110 grass_block
fill ~432 ~60 ~111 ~435 ~65 ~111 stone
fill ~432 ~66 ~111 ~435 ~68 ~111 dirt
fill ~432 ~69 ~111 ~435 ~69 ~111 grass_block
fill ~436 ~60 ~111 ~438 ~64 ~111 stone
fill ~436 ~65 ~111 ~438 ~67 ~111 dirt
fill ~436 ~68 ~111 ~438 ~68 ~111 grass_block
fill ~439 ~60 ~111 ~441 ~63 ~111 stone
fill ~439 ~64 ~111 ~441 ~66 ~111 dirt
fill ~439 ~67 ~111 ~441 ~67 ~111 grass_block
fill ~442 ~60 ~111 ~447 ~62 ~111 stone
fill ~442 ~63 ~111 ~447 ~65 ~111 dirt
fill ~442 ~66 ~111 ~447 ~66 ~111 grass_block