fill ~0 ~60 ~112 ~0 ~69 ~112 stone
fill ~0 ~70 ~112 ~0 ~72 ~112 dirt
fill ~0 ~73 ~112 ~0 ~73 ~112 grass_block
fill ~1 ~60 ~112 ~3 ~68 ~112 stone
fill ~1 ~69 ~112 ~3 ~71 ~112 dirt
fill ~1 ~72 ~112 ~3 ~72 ~112 grass_block
fill ~4 ~60 ~112 ~5 ~67 ~112 stone
fill ~4 ~68 ~112 ~5 ~70 ~112 dirt
fill ~4 ~71 ~112 ~5 ~71 ~112 grass_block
fill ~6 ~60 ~112 ~10 ~66 ~112 stone
fill ~6 ~67 ~112 ~10 ~69 ~112 dirt
fill ~6 ~70 ~112 ~10 ~70 ~112 grass_block
fill ~11 ~60 ~112 ~15 ~67 ~112 stone
fill ~11 ~68 ~112 ~15 ~70 ~112 dirt
fill ~11 ~71 ~112 ~15 ~71 ~112 grass_block
fill ~0 ~60 ~113 ~0 ~69 ~113 stone
fill ~0 ~70 ~113 ~0 ~72 ~113 dirt
fill ~0 ~73 ~113 ~0 ~73 ~113 grass_block
fill ~1 ~60 ~113 ~3 ~68 ~113 stone
fill ~1 ~69 ~113 ~3 ~71 ~113 dirt
fill ~1 ~72 ~113 ~3 ~72 ~113 grass_block
fill ~4 ~60 ~113 ~5 ~67 ~113 stone
fill ~4 ~68 ~113 ~5 ~70 ~113 dirt
fill ~4 ~71 ~113 ~5 ~71 ~113 grass_block
fill ~6 ~60 ~113 ~7 ~66 ~113 stone
fill ~6 ~67 ~113 ~7 ~69 ~113 dirt
fill ~6 ~70 ~113 ~7 ~70 ~113 grass_block
fill ~8 ~60 ~113 ~8 ~65 ~113 stone
fill ~8 ~66 ~113 ~8 ~68 ~113 dirt
fill ~8 ~69 ~113 ~8 ~69 ~113 grass_block
fill ~9 ~60 ~113 ~11 ~66 ~113 stone
fill ~9 ~67 ~113 ~11 ~69 ~113 dirt
fill ~9 ~70 ~113 ~11 ~70 ~113 grass_block
fill ~12 ~60 ~113 ~13 ~67 ~113 stone
fill ~12 ~68 ~113 ~13 ~70 ~113 dirt
fill ~12 ~71 ~113 ~13 ~71 ~113 grass_block
fill ~14 ~60 ~113 ~15 ~66 ~113 stone
fill ~14 ~67 ~113 ~15 ~69 ~113 dirt
fill ~14 ~70 ~113 ~15 ~70 ~113 grass_block
fill ~0 ~60 ~114 ~0 ~69 ~114 stone
fill ~0 ~70 ~114 ~0 ~72 ~114 dirt
fill ~0 ~73 ~114 ~0 ~73 ~114 grass_block
fill ~1 ~60 ~114 ~1 ~68 ~114 stone
fill ~1 ~69 ~114 ~1 ~71 ~114 dirt
fill ~1 ~72 ~114 ~1 ~72 ~114 grass_block
fill ~2 ~60 ~114 ~5 ~67 ~114 stone
fill ~2 ~68 ~114 ~5 ~70 ~114 dirt
fill ~2 ~71 ~114 ~5 ~71 ~114 grass_block
fill ~6 ~60 ~114 ~7 ~66 ~114 stone
fill ~6 ~67 ~114 ~7 ~69 ~114 dirt
fill ~6 ~70 ~114 ~7 ~70 ~114 grass_block
fill ~8 ~60 ~114 ~10 ~65 ~114 stone
fill ~8 ~66 ~114 ~10 ~68 ~114 dirt
fill ~8 ~69 ~114 ~10 ~69 ~114 grass_block
fill ~11 ~60 ~114 ~15 ~66 ~114 stone
fill ~11 ~67 ~114 ~15 ~69 ~114 dirt
fill ~11 ~70 ~114 ~15 ~70 ~114 grass_block
fill ~0 ~60 ~115 ~0 ~69 ~115 stone
fill ~0 ~70 ~115 ~0 ~72 ~115 dirt
fill ~0 ~73 ~115 ~0 ~73 ~115 grass_block
fill ~1 ~60 ~115 ~1 ~68 ~115 stone
fill ~1 ~69 ~115 ~1 ~71 ~115 dirt
fill ~1 ~72 ~115 ~1 ~72 ~115 grass_block
fill ~2 ~60 ~115 ~4 ~67 ~115 stone
fill ~2 ~68 ~115 ~4 ~70 ~115 dirt
fill ~2 ~71 ~115 ~4 ~71 ~115 grass_block
fill ~5 ~60 ~115 ~11 ~66 ~115 stone
fill ~5 ~67 ~115 ~11 ~69 ~115 dirt
fill ~5 ~70 ~115 ~11 ~70 ~115 grass_block
fill ~12 ~60 ~115 ~12 ~65 ~115 stone
fill ~12 ~66 ~115 ~12 ~68 ~115 dirt
fill ~12 ~69 ~115 ~12 ~69 ~115 grass_block
fill ~13 ~60 ~115 ~15 ~66 ~115 stone
fill ~13 ~67 ~115 ~15 ~69 ~115 dirt
fill ~13 ~70 ~115 ~15 ~70 ~115 grass_block
fill ~0 ~60 ~116 ~0 ~69 ~116 stone
fill ~0 ~70 ~116 ~0 ~72 ~116 dirt
fill ~0 ~73 ~116 ~0 ~73 ~116 grass_block
fill ~1 ~60 ~116 ~1 ~68 ~116 stone
fill ~1 ~69 ~116 ~1 ~71 ~116 dirt
fill ~1 ~72 ~116 ~1 ~72 ~116 grass_block
fill ~2 ~60 ~116 ~7 ~67 ~116 stone
fill ~2 ~68 ~116 ~7 ~70 ~116 dirt
fill ~2 ~71 ~116 ~7 ~71 ~116 grass_block
fill ~8 ~60 ~116 ~11 ~66 ~116 stone
fill ~8 ~67 ~116 ~11 ~69 ~116 dirt
fill ~8 ~70 ~116 ~11 ~70 ~116 grass_block
fill ~12 ~60 ~116 ~15 ~65 ~116 stone
fill ~12 ~66 ~116 ~15 ~68 ~116 dirt
fill ~12 ~69 ~116 ~15 ~69 ~116 grass_block
fill ~0 ~60 ~117 ~2 ~69 ~117 stone
fill ~0 ~70 ~117 ~2 ~72 ~117 dirt
fill ~0 ~73 ~117 ~2 ~73 ~117 grass_block
fill ~3 ~60 ~117 ~7 ~68 ~117 stone
fill ~3 ~69 ~117 ~7 ~71 ~117 dirt
fill ~3 ~72 ~117 ~7 ~72 ~117 grass_block
fill ~8 ~60 ~117 ~9 ~67 ~117 stone
fill ~8 ~68 ~117 ~9 ~70 ~117 dirt
fill ~8 ~71 ~117 ~9 ~71 ~117 grass_block
fill ~10 ~60 ~117 ~11 ~66 ~117 stone
fill ~10 ~67 ~117 ~11 ~69 ~117 dirt
fill ~10 ~70 ~117 ~11 ~70 ~117 grass_block
fill ~12 ~60 ~117 ~15 ~65 ~117 stone
fill ~12 ~66 ~117 ~15 ~68 ~117 dirt
fill ~12 ~69 ~117 ~15 ~69 ~117 grass_block
fill ~0 ~60 ~118 ~3 ~69 ~118 stone
fill ~0 ~70 ~118 ~3 ~72 ~118 dirt
fill ~0 ~73 ~118 ~3 ~73 ~118 grass_block
fill ~4 ~60 ~118 ~7 ~68 ~118 stone
fill ~4 ~69 ~118 ~7 ~71 ~118 dirt
fill ~4 ~72 ~118 ~7 ~72 ~118 grass_block
fill ~8 ~60 ~118 ~9 ~67 ~118 stone
fill ~8 ~68 ~118 ~9 ~70 ~118 dirt
fill ~8 ~71 ~118 ~9 ~71 ~118 grass_block
fill ~10 ~60 ~118 ~12 ~66 ~118 stone
fill ~10 ~67 ~118 ~12 ~69 ~118 dirt
fill ~10 ~70 ~118 ~12 ~70 ~118 grass_block
fill ~13 ~60 ~118 ~15 ~65 ~118 stone
fill ~13 ~66 ~118 ~15 ~68 ~118 dirt
fill ~13 ~69 ~118 ~15 ~69 ~118 grass_block
fill ~0 ~60 ~119 ~2 ~69 ~119 stone
fill ~0 ~70 ~119 ~2 ~72 ~119 dirt
fill ~0 ~73 ~119 ~2 ~73 ~119 grass_block
fill ~3 ~60 ~119 ~7 ~68 ~119 stone
fill ~3 ~69 ~119 ~7 ~71 ~119 dirt
fill ~3 ~72 ~119 ~7 ~72 ~119 grass_block
fill ~8 ~60 ~119 ~9 ~67 ~119 stone
fill ~8 ~68 ~119 ~9 ~70 ~119 dirt
fill ~8 ~71 ~119 ~9 ~71 ~119 grass_block
fill ~10 ~60 ~119 ~12 ~66 ~119 stone
fill ~10 ~67 ~119 ~12 ~69 ~119 dirt
fill ~10 ~70 ~119 ~12 ~70 ~119 grass_block
fill ~13 ~60 ~119 ~15 ~65 ~119 stone
fill ~13 ~66 ~119 ~15 ~68 ~119 dirt
fill ~13 ~69 ~119 ~15 ~69 ~119 grass_block
fill ~0 ~60 ~120 ~3 ~68 ~120 stone
fill ~0 ~69 ~120 ~3 ~71 ~120 dirt
fill ~0 ~72 ~120 ~3 ~72 ~120 grass_block
fill ~4 ~60 ~120 ~9 ~67 ~120 stone
fill ~4 ~68 ~120 ~9 ~70 ~120 dirt
fill ~4 ~71 ~120 ~9 ~71 ~120 grass_block
fill ~10 ~60 ~120 ~13 ~66 ~120 stone
fill ~10 ~67 ~120 ~13 ~69 ~120 dirt
fill ~10 ~70 ~120 ~13 ~70 ~120 grass_block
fill ~14 ~60 ~120 ~15 ~65 ~120 stone
fill ~14 ~66 ~120 ~15 ~68 ~120 dirt
fill ~14 ~69 ~120 ~15 ~69 ~120 grass_block
fill ~0 ~60 ~121 ~1 ~68 ~121 stone
fill ~0 ~69 ~121 ~1 ~71 ~121 dirt
fill ~0 ~72 ~121 ~1 ~72 ~121 grass_block
fill ~2 ~60 ~121 ~7 ~67 ~121 stone
fill ~2 ~68 ~121 ~7 ~70 ~121 dirt
fill ~2 ~71 ~121 ~7 ~71 ~121 grass_block
fill ~8 ~60 ~121 ~12 ~66 ~121 stone
fill ~8 ~67 ~121 ~12 ~69 ~121 dirt
fill ~8 ~70 ~121 ~12 ~70 ~121 grass_block
fill ~13 ~60 ~121 ~15 ~65 ~121 stone
fill ~13 ~66 ~121 ~15 ~68 ~121 dirt
fill ~13 ~69 ~121 ~15 ~69 ~121 grass_block
fill ~0 ~60 ~122 ~0 ~69 ~122 stone
fill ~0 ~70 ~122 ~0 ~72 ~122 dirt
fill ~0 ~73 ~122 ~0 ~73 ~122 grass_block
fill ~1 ~60 ~122 ~2 ~68 ~122 stone
fill ~1 ~69 ~122 ~2 ~71 ~122 dirt
fill ~1 ~72 ~122 ~2 ~72 ~122 grass_block
fill ~3 ~60 ~122 ~5 ~67 ~122 stone
fill ~3 ~68 ~122 ~5 ~70 ~122 dirt
fill ~3 ~71 ~122 ~5 ~71 ~122 grass_block
fill ~6 ~60 ~122 ~11 ~66 ~122 stone
fill ~6 ~67 ~122 ~11 ~69 ~122 dirt
fill ~6 ~70 ~122 ~11 ~70 ~122 grass_block
fill ~12 ~60 ~122 ~15 ~65 ~122 stone
fill ~12 ~66 ~122 ~15 ~68 ~122 dirt
fill ~12 ~69 ~122 ~15 ~69 ~122 grass_block
fill ~0 ~60 ~123 ~0 ~69 ~123 stone
fill ~0 ~70 ~123 ~0 ~72 ~123 dirt
fill ~0 ~73 ~123 ~0 ~73 ~123 grass_block
fill ~1 ~60 ~123 ~2 ~68 ~123 stone
fill ~1 ~69 ~123 ~2 ~71 ~123 dirt
fill ~1 ~72 ~123 ~2 ~72 ~123 grass_block
fill ~3 ~60 ~123 ~6 ~67 ~123 stone
fill ~3 ~68 ~123 ~6 ~70 ~123 dirt
fill ~3 ~71 ~123 ~6 ~71 ~123 grass_block
fill ~7 ~60 ~123 ~11 ~66 ~123 stone
fill ~7 ~67 ~123 ~11 ~69 ~123 dirt
fill ~7 ~70 ~123 ~11 ~70 ~123 grass_block
fill ~12 ~60 ~123 ~15 ~65 ~123 stone
fill ~12 ~66 ~123 ~15 ~68 ~123 dirt
fill ~12 ~69 ~123 ~15 ~69 ~123 grass_block
fill ~0 ~60 ~124 ~1 ~69 ~124 stone
fill ~0 ~70 ~124 ~1 ~72 ~124 dirt
fill ~0 ~73 ~124 ~1 ~73 ~124 grass_block
fill ~2 ~60 ~124 ~3 ~68 ~124 stone
fill ~2 ~69 ~124 ~3 ~71 ~124 dirt
fill ~2 ~72 ~124 ~3 ~72 ~124 grass_block
fill ~4 ~60 ~124 ~7 ~67 ~124 stone
fill ~4 ~68 ~124 ~7 ~70 ~124 dirt
fill ~4 ~71 ~124 ~7 ~71 ~124 grass_block
fill ~8 ~60 ~124 ~15 ~66 ~124 stone
fill ~8 ~67 ~124 ~15 ~69 ~124 dirt
fill ~8 ~70 ~124 ~15 ~70 ~124 grass_block
fill ~0 ~60 ~125 ~2 ~69 ~125 stone
fill ~0 ~70 ~125 ~2 ~72 ~125 dirt
fill ~0 ~73 ~125 ~2 ~73 ~125 grass_block
fill ~3 ~60 ~125 ~6 ~68 ~125 stone
fill ~3 ~69 ~125 ~6 ~71 ~125 dirt
fill ~3 ~72 ~125 ~6 ~72 ~125 grass_block
fill ~7 ~60 ~125 ~12 ~67 ~125 stone
fill ~7 ~68 ~125 ~12 ~70 ~125 dirt
fill ~7 ~71 ~125 ~12 ~71 ~125 grass_block
fill ~13 ~60 ~125 ~14 ~66 ~125 stone
fill ~13 ~67 ~125 ~14 ~69 ~125 dirt
fill ~13 ~70 ~125 ~14 ~70 ~125 grass_block
fill ~15 ~60 ~125 ~15 ~67 ~125 stone
fill ~15 ~68 ~125 ~15 ~70 ~125 dirt
fill ~15 ~71 ~125 ~15 ~71 ~125 grass_block
fill ~0 ~60 ~126 ~0 ~70 ~126 stone
fill ~0 ~71 ~126 ~0 ~73 ~126 dirt
fill ~0 ~74 ~126 ~0 ~74 ~126 grass_block
fill ~1 ~60 ~126 ~3 ~69 ~126 stone
fill ~1 ~70 ~126 ~3 ~72 ~126 dirt
fill ~1 ~73 ~126 ~3 ~73 ~126 grass_block
fill ~4 ~60 ~126 ~9 ~68 ~126 stone
fill ~4 ~69 ~126 ~9 ~71 ~126 dirt
fill ~4 ~72 ~126 ~9 ~72 ~126 grass_block
fill ~10 ~60 ~126 ~15 ~67 ~126 stone
fill ~10 ~68 ~126 ~15 ~70 ~126 dirt
fill ~10 ~71 ~126 ~15 ~71 ~126 grass_block
fill ~0 ~60 ~127 ~1 ~70 ~127 stone
fill ~0 ~71 ~127 ~1 ~73 ~127 dirt
fill ~0 ~74 ~127 ~1 ~74 ~127 grass_block
fill ~2 ~60 ~127 ~6 ~69 ~127 stone
fill ~2 ~70 ~127 ~6 ~72 ~127 dirt
fill ~2 ~73 ~127 ~6 ~73 ~127 grass_block
fill ~7 ~60 ~127 ~9 ~68 ~127 stone
fill ~7 ~69 ~127 ~9 ~71 ~127 dirt
fill ~7 ~72 ~127 ~9 ~72 ~127 grass_block
fill ~10 ~60 ~127 ~10 ~69 ~127 stone
fill ~10 ~70 ~127 ~10 ~72 ~127 dirt
fill ~10 ~73 ~127 ~10 ~73 ~127 grass_block
fill ~11 ~60 ~127 ~14 ~68 ~127 stone
fill ~11 ~69 ~127 ~14 ~71 ~127 dirt
fill ~11 ~72 ~127 ~14 ~72 ~127 grass_block
fill ~15 ~60 ~127 ~15 ~67 ~127 stone
fill ~15 ~68 ~127 ~15 ~70 ~127 dirt
fill ~15 ~71 ~127 ~15 ~71 ~127 grass_block