fill ~464 ~60 ~32 ~469 ~62 ~32 stone
fill ~464 ~63 ~32 ~469 ~65 ~32 dirt
fill ~464 ~66 ~32 ~469 ~66 ~32 grass_block
fill ~464 ~60 ~33 ~469 ~62 ~33 stone
fill ~464 ~63 ~33 ~469 ~65 ~33 dirt
fill ~464 ~66 ~33 ~469 ~66 ~33 grass_block
fill ~464 ~60 ~34 ~469 ~62 ~34 stone
fill ~464 ~63 ~34 ~469 ~65 ~34 dirt
fill ~464 ~66 ~34 ~469 ~66 ~34 grass_block
fill ~464 ~60 ~35 ~467 ~62 ~35 stone
fill ~464 ~63 ~35 ~467 ~65 ~35 dirt
fill ~464 ~66 ~35 ~467 ~66 ~35 grass_block
fill ~468 ~60 ~35 ~468 ~61 ~35 stone
fill ~468 ~62 ~35 ~468 ~64 ~35 dirt
fill ~468 ~65 ~35 ~468 ~65 ~35 grass_block
fill ~469 ~60 ~35 ~469 ~62 ~35 stone
fill ~469 ~63 ~35 ~469 ~65 ~35 dirt
fill ~469 ~66 ~35 ~469 ~66 ~35 grass_block
fill ~464 ~60 ~36 ~468 ~61 ~36 stone
fill ~464 ~62 ~36 ~468 ~64 ~36 dirt
fill ~464 ~65 ~36 ~468 ~65 ~36 grass_block
fill ~469 ~60 ~36 ~469 ~62 ~36 stone
fill ~469 ~63 ~36 ~469 ~65 ~36 dirt
fill ~469 ~66 ~36 ~469 ~66 ~36 grass_block
fill ~464 ~60 ~37 ~469 ~61 ~37 stone
fill ~464 ~62 ~37 ~469 ~64 ~37 dirt
fill ~464 ~65 ~37 ~469 ~65 ~37 grass_block
fill ~464 ~60 ~38 ~469 ~61 ~38 stone
fill ~464 ~62 ~38 ~469 ~64 ~38 dirt
fill ~464 ~65 ~38 ~469 ~65 ~38 grass_block
fill ~464 ~60 ~39 ~469 ~61 ~39 stone
fill ~464 ~62 ~39 ~469 ~64 ~39 dirt
fill ~464 ~65 ~39 ~469 ~65 ~39 grass_block
fill ~464 ~60 ~40 ~469 ~61 ~40 stone
fill ~464 ~62 ~40 ~469 ~64 ~40 dirt
fill ~464 ~65 ~40 ~469 ~65 ~40 grass_block
fill ~464 ~60 ~41 ~469 ~61 ~41 stone
fill ~464 ~62 ~41 ~469 ~64 ~41 dirt
fill ~464 ~65 ~41 ~469 ~65 ~41 grass_block
fill ~464 ~60 ~42 ~469 ~61 ~42 stone
fill ~464 ~62 ~42 ~469 ~64 ~42 dirt
fill ~464 ~65 ~42 ~469 ~65 ~42 grass_block
fill ~464 ~60 ~43 ~469 ~61 ~43 stone
fill ~464 ~62 ~43 ~469 ~64 ~43 dirt
fill ~464 ~65 ~43 ~469 ~65 ~43 grass_block
fill ~464 ~60 ~44 ~467 ~61 ~44 stone
fill ~464 ~62 ~44 ~467 ~64 ~44 dirt
fill ~464 ~65 ~44 ~467 ~65 ~44 grass_block
fill ~468 ~60 ~44 ~469 ~62 ~44 stone
fill ~468 ~63 ~44 ~469 ~65 ~44 dirt
fill ~468 ~66 ~44 ~469 ~66 ~44 grass_block
fill ~464 ~60 ~45 ~464 ~61 ~45 stone
fill ~464 ~62 ~45 ~464 ~64 ~45 dirt
fill ~464 ~65 ~45 ~464 ~65 ~45 grass_block
fill ~465 ~60 ~45 ~468 ~62 ~45 stone
fill ~465 ~63 ~45 ~468 ~65 ~45 dirt
fill ~465 ~66 ~45 ~468 ~66 ~45 grass_block
fill ~469 ~60 ~45 ~469 ~63 ~45 stone
fill ~469 ~64 ~45 ~469 ~66 ~45 dirt
fill ~469 ~67 ~45 ~469 ~67 ~45 grass_block
fill ~464 ~60 ~46 ~464 ~61 ~46 stone
fill ~464 ~62 ~46 ~464 ~64 ~46 dirt
fill ~464 ~65 ~46 ~464 ~65 ~46 grass_block
fill ~465 ~60 ~46 ~466 ~62 ~46 stone
fill ~465 ~63 ~46 ~466 ~65 ~46 dirt
fill ~465 ~66 ~46 ~466 ~66 ~46 grass_block
fill ~467 ~60 ~46 ~468 ~63 ~46 stone
fill ~467 ~64 ~46 ~468 ~66 ~46 dirt
fill ~467 ~67 ~46 ~468 ~67 ~46 grass_block
fill ~469 ~60 ~46 ~469 ~64 ~46 stone
fill ~469 ~65 ~46 ~469 ~67 ~46 dirt
fill ~469 ~68 ~46 ~469 ~68 ~46 grass_block
fill ~464 ~60 ~47 ~465 ~62 ~47 stone
fill ~464 ~63 ~47 ~465 ~65 ~47 dirt
fill ~464 ~66 ~47 ~465 ~66 ~47 grass_block
fill ~466 ~60 ~47 ~469 ~63 ~47 stone
fill ~466 ~64 ~47 ~469 ~66 ~47 dirt
fill ~466 ~67 ~47 ~469 ~67 ~47 grass_block