fill ~32 ~60 ~32 ~45 ~64 ~32 stone
fill ~32 ~65 ~32 ~45 ~67 ~32 dirt
fill ~32 ~68 ~32 ~45 ~68 ~32 grass_block
fill ~46 ~60 ~32 ~47 ~65 ~32 stone
fill ~46 ~66 ~32 ~47 ~68 ~32 dirt
fill ~46 ~69 ~32 ~47 ~69 ~32 grass_block
fill ~32 ~60 ~33 ~33 ~65 ~33 stone
fill ~32 ~66 ~33 ~33 ~68 ~33 dirt
fill ~32 ~69 ~33 ~33 ~69 ~33 grass_block
fill ~34 ~60 ~33 ~39 ~64 ~33 stone
fill ~34 ~65 ~33 ~39 ~67 ~33 dirt
fill ~34 ~68 ~33 ~39 ~68 ~33 grass_block
fill ~40 ~60 ~33 ~40 ~63 ~33 stone
fill ~40 ~64 ~33 ~40 ~66 ~33 dirt
fill ~40 ~67 ~33 ~40 ~67 ~33 grass_block
fill ~41 ~60 ~33 ~41 ~64 ~33 stone
fill ~41 ~65 ~33 ~41 ~67 ~33 dirt
fill ~41 ~68 ~33 ~41 ~68 ~33 grass_block
fill ~42 ~60 ~33 ~42 ~63 ~33 stone
fill ~42 ~64 ~33 ~42 ~66 ~33 dirt
fill ~42 ~67 ~33 ~42 ~67 ~33 grass_block
fill ~43 ~60 ~33 ~43 ~64 ~33 stone
fill ~43 ~65 ~33 ~43 ~67 ~33 dirt
fill ~43 ~68 ~33 ~43 ~68 ~33 grass_block
fill ~44 ~60 ~33 ~44 ~63 ~33 stone
fill ~44 ~64 ~33 ~44 ~66 ~33 dirt
fill ~44 ~67 ~33 ~44 ~67 ~33 grass_block
fill ~45 ~60 ~33 ~46 ~64 ~33 stone
fill ~45 ~65 ~33 ~46 ~67 ~33 dirt
fill ~45 ~68 ~33 ~46 ~68 ~33 grass_block
fill ~47 ~60 ~33 ~47 ~65 ~33 stone
fill ~47 ~66 ~33 ~47 ~68 ~33 dirt
fill ~47 ~69 ~33 ~47 ~69 ~33 grass_block
fill ~32 ~60 ~34 ~37 ~65 ~34 stone
fill ~32 ~66 ~34 ~37 ~68 ~34 dirt
fill ~32 ~69 ~34 ~37 ~69 ~34 grass_block
fill ~38 ~60 ~34 ~47 ~64 ~34 stone
fill ~38 ~65 ~34 ~47 ~67 ~34 dirt
fill ~38 ~68 ~34 ~47 ~68 ~34 grass_block
fill ~32 ~60 ~35 ~34 ~66 ~35 stone
fill ~32 ~67 ~35 ~34 ~69 ~35 dirt
fill ~32 ~70 ~35 ~34 ~70 ~35 grass_block
fill ~35 ~60 ~35 ~41 ~65 ~35 stone
fill ~35 ~66 ~35 ~41 ~68 ~35 dirt
fill ~35 ~69 ~35 ~41 ~69 ~35 grass_block
fill ~42 ~60 ~35 ~46 ~64 ~35 stone
fill ~42 ~65 ~35 ~46 ~67 ~35 dirt
fill ~42 ~68 ~35 ~46 ~68 ~35 grass_block
fill ~47 ~60 ~35 ~47 ~63 ~35 stone
fill ~47 ~64 ~35 ~47 ~66 ~35 dirt
fill ~47 ~67 ~35 ~47 ~67 ~35 grass_block
fill ~32 ~60 ~36 ~33 ~67 ~36 stone
fill ~32 ~68 ~36 ~33 ~70 ~36 dirt
fill ~32 ~71 ~36 ~33 ~71 ~36 grass_block
fill ~34 ~60 ~36 ~37 ~66 ~36 stone
fill ~34 ~67 ~36 ~37 ~69 ~36 dirt
fill ~34 ~70 ~36 ~37 ~70 ~36 grass_block
fill ~38 ~60 ~36 ~42 ~65 ~36 stone
fill ~38 ~66 ~36 ~42 ~68 ~36 dirt
fill ~38 ~69 ~36 ~42 ~69 ~36 grass_block
fill ~43 ~60 ~36 ~46 ~64 ~36 stone
fill ~43 ~65 ~36 ~46 ~67 ~36 dirt
fill ~43 ~68 ~36 ~46 ~68 ~36 grass_block
fill ~47 ~60 ~36 ~47 ~63 ~36 stone
fill ~47 ~64 ~36 ~47 ~66 ~36 dirt
fill ~47 ~67 ~36 ~47 ~67 ~36 grass_block
fill ~32 ~60 ~37 ~36 ~67 ~37 stone
fill ~32 ~68 ~37 ~36 ~70 ~37 dirt
fill ~32 ~71 ~37 ~36 ~71 ~37 grass_block
fill ~37 ~60 ~37 ~38 ~66 ~37 stone
fill ~37 ~67 ~37 ~38 ~69 ~37 dirt
fill ~37 ~70 ~37 ~38 ~70 ~37 grass_block
fill ~39 ~60 ~37 ~43 ~65 ~37 stone
fill ~39 ~66 ~37 ~43 ~68 ~37 dirt
fill ~39 ~69 ~37 ~43 ~69 ~37 grass_block
fill ~44 ~60 ~37 ~47 ~64 ~37 stone
fill ~44 ~65 ~37 ~47 ~67 ~37 dirt
fill ~44 ~68 ~37 ~47 ~68 ~37 grass_block
fill ~32 ~60 ~38 ~33 ~68 ~38 stone
fill ~32 ~69 ~38 ~33 ~71 ~38 dirt
fill ~32 ~72 ~38 ~33 ~72 ~38 grass_block
fill ~34 ~60 ~38 ~37 ~67 ~38 stone
fill ~34 ~68 ~38 ~37 ~70 ~38 dirt
fill ~34 ~71 ~38 ~37 ~71 ~38 grass_block
fill ~38 ~60 ~38 ~40 ~66 ~38 stone
fill ~38 ~67 ~38 ~40 ~69 ~38 dirt
fill ~38 ~70 ~38 ~40 ~70 ~38 grass_block
fill ~41 ~60 ~38 ~44 ~65 ~38 stone
fill ~41 ~66 ~38 ~44 ~68 ~38 dirt
fill ~41 ~69 ~38 ~44 ~69 ~38 grass_block
fill ~45 ~60 ~38 ~47 ~64 ~38 stone
fill ~45 ~65 ~38 ~47 ~67 ~38 dirt
fill ~45 ~68 ~38 ~47 ~68 ~38 grass_block
fill ~32 ~60 ~39 ~35 ~68 ~39 stone
fill ~32 ~69 ~39 ~35 ~71 ~39 dirt
fill ~32 ~72 ~39 ~35 ~72 ~39 grass_block
fill ~36 ~60 ~39 ~38 ~67 ~39 stone
fill ~36 ~68 ~39 ~38 ~70 ~39 dirt
fill ~36 ~71 ~39 ~38 ~71 ~39 grass_block
fill ~39 ~60 ~39 ~41 ~66 ~39 stone
fill ~39 ~67 ~39 ~41 ~69 ~39 dirt
fill ~39 ~70 ~39 ~41 ~70 ~39 grass_block
fill ~42 ~60 ~39 ~46 ~65 ~39 stone
fill ~42 ~66 ~39 ~46 ~68 ~39 dirt
fill ~42 ~69 ~39 ~46 ~69 ~39 grass_block
fill ~47 ~60 ~39 ~47 ~64 ~39 stone
fill ~47 ~65 ~39 ~47 ~67 ~39 dirt
fill ~47 ~68 ~39 ~47 ~68 ~39 grass_block
fill ~32 ~60 ~40 ~32 ~68 ~40 stone
fill ~32 ~69 ~40 ~32 ~71 ~40 dirt
fill ~32 ~72 ~40 ~32 ~72 ~40 grass_block
fill ~33 ~60 ~40 ~35 ~69 ~40 stone
fill ~33 ~70 ~40 ~35 ~72 ~40 dirt
fill ~33 ~73 ~40 ~35 ~73 ~40 grass_block
fill ~36 ~60 ~40 ~37 ~68 ~40 stone
fill ~36 ~69 ~40 ~37 ~71 ~40 dirt
fill ~36 ~72 ~40 ~37 ~72 ~40 grass_block
fill ~38 ~60 ~40 ~39 ~67 ~40 stone
fill ~38 ~68 ~40 ~39 ~70 ~40 dirt
fill ~38 ~71 ~40 ~39 ~71 ~40 grass_block
fill ~40 ~60 ~40 ~43 ~66 ~40 stone
fill ~40 ~67 ~40 ~43 ~69 ~40 dirt
fill ~40 ~70 ~40 ~43 ~70 ~40 grass_block
fill ~44 ~60 ~40 ~47 ~65 ~40 stone
fill ~44 ~66 ~40 ~47 ~68 ~40 dirt
fill ~44 ~69 ~40 ~47 ~69 ~40 grass_block
fill ~32 ~60 ~41 ~34 ~68 ~41 stone
fill ~32 ~69 ~41 ~34 ~71 ~41 dirt
fill ~32 ~72 ~41 ~34 ~72 ~41 grass_block
fill ~35 ~60 ~41 ~37 ~69 ~41 stone
fill ~35 ~70 ~41 ~37 ~72 ~41 dirt
fill ~35 ~73 ~41 ~37 ~73 ~41 grass_block
fill ~38 ~60 ~41 ~38 ~68 ~41 stone
fill ~38 ~69 ~41 ~38 ~71 ~41 dirt
fill ~38 ~72 ~41 ~38 ~72 ~41 grass_block
fill ~39 ~60 ~41 ~40 ~67 ~41 stone
fill ~39 ~68 ~41 ~40 ~70 ~41 dirt
fill ~39 ~71 ~41 ~40 ~71 ~41 grass_block
fill ~41 ~60 ~41 ~45 ~66 ~41 stone
fill ~41 ~67 ~41 ~45 ~69 ~41 dirt
fill ~41 ~70 ~41 ~45 ~70 ~41 grass_block
fill ~46 ~60 ~41 ~47 ~65 ~41 stone
fill ~46 ~66 ~41 ~47 ~68 ~41 dirt
fill ~46 ~69 ~41 ~47 ~69 ~41 grass_block
fill ~32 ~60 ~42 ~35 ~68 ~42 stone
fill ~32 ~69 ~42 ~35 ~71 ~42 dirt
fill ~32 ~72 ~42 ~35 ~72 ~42 grass_block
fill ~36 ~60 ~42 ~38 ~69 ~42 stone
fill ~36 ~70 ~42 ~38 ~72 ~42 dirt
fill ~36 ~73 ~42 ~38 ~73 ~42 grass_block
fill ~39 ~60 ~42 ~39 ~68 ~42 stone
fill ~39 ~69 ~42 ~39 ~71 ~42 dirt
fill ~39 ~72 ~42 ~39 ~72 ~42 grass_block
fill ~40 ~60 ~42 ~43 ~67 ~42 stone
fill ~40 ~68 ~42 ~43 ~70 ~42 dirt
fill ~40 ~71 ~42 ~43 ~71 ~42 grass_block
fill ~44 ~60 ~42 ~46 ~66 ~42 stone
fill ~44 ~67 ~42 ~46 ~69 ~42 dirt
fill ~44 ~70 ~42 ~46 ~70 ~42 grass_block
fill ~47 ~60 ~42 ~47 ~65 ~42 stone
fill ~47 ~66 ~42 ~47 ~68 ~42 dirt
fill ~47 ~69 ~42 ~47 ~69 ~42 grass_block
fill ~32 ~60 ~43 ~37 ~68 ~43 stone
fill ~32 ~69 ~43 ~37 ~71 ~43 dirt
fill ~32 ~72 ~43 ~37 ~72 ~43 grass_block
fill ~38 ~60 ~43 ~39 ~69 ~43 stone
fill ~38 ~70 ~43 ~39 ~72 ~43 dirt
fill ~38 ~73 ~43 ~39 ~73 ~43 grass_block
fill ~40 ~60 ~43 ~41 ~68 ~43 stone
fill ~40 ~69 ~43 ~41 ~71 ~43 dirt
fill ~40 ~72 ~43 ~41 ~72 ~43 grass_block
fill ~42 ~60 ~43 ~44 ~67 ~43 stone
fill ~42 ~68 ~43 ~44 ~70 ~43 dirt
fill ~42 ~71 ~43 ~44 ~71 ~43 grass_block
fill ~45 ~60 ~43 ~47 ~66 ~43 stone
fill ~45 ~67 ~43 ~47 ~69 ~43 dirt
fill ~45 ~70 ~43 ~47 ~70 ~43 grass_block
fill ~32 ~60 ~44 ~34 ~67 ~44 stone
fill ~32 ~68 ~44 ~34 ~70 ~44 dirt
fill ~32 ~71 ~44 ~34 ~71 ~44 grass_block
fill ~35 ~60 ~44 ~38 ~68 ~44 stone
fill ~35 ~69 ~44 ~38 ~71 ~44 dirt
fill ~35 ~72 ~44 ~38 ~72 ~44 grass_block
fill ~39 ~60 ~44 ~40 ~69 ~44 stone
fill ~39 ~70 ~44 ~40 ~72 ~44 dirt
fill ~39 ~73 ~44 ~40 ~73 ~44 grass_block
fill ~41 ~60 ~44 ~42 ~68 ~44 stone
fill ~41 ~69 ~44 ~42 ~71 ~44 dirt
fill ~41 ~72 ~44 ~42 ~72 ~44 grass_block
fill ~43 ~60 ~44 ~46 ~67 ~44 stone
fill ~43 ~68 ~44 ~46 ~70 ~44 dirt
fill ~43 ~71 ~44 ~46 ~71 ~44 grass_block
fill ~47 ~60 ~44 ~47 ~66 ~44 stone
fill ~47 ~67 ~44 ~47 ~69 ~44 dirt
fill ~47 ~70 ~44 ~47 ~70 ~44 grass_block
fill ~32 ~60 ~45 ~36 ~67 ~45 stone
fill ~32 ~68 ~45 ~36 ~70 ~45 dirt
fill ~32 ~71 ~45 ~36 ~71 ~45 grass_block
fill ~37 ~60 ~45 ~45 ~68 ~45 stone
fill ~37 ~69 ~45 ~45 ~71 ~45 dirt
fill ~37 ~72 ~45 ~45 ~72 ~45 grass_block
fill ~46 ~60 ~45 ~47 ~67 ~45 stone
fill ~46 ~68 ~45 ~47 ~70 ~45 dirt
fill ~46 ~71 ~45 ~47 ~71 ~45 grass_block
fill ~32 ~60 ~46 ~33 ~67 ~46 stone
fill ~32 ~68 ~46 ~33 ~70 ~46 dirt
fill ~32 ~71 ~46 ~33 ~71 ~46 grass_block
fill ~34 ~60 ~46 ~34 ~66 ~46 stone
fill ~34 ~67 ~46 ~34 ~69 ~46 dirt
fill ~34 ~70 ~46 ~34 ~70 ~46 grass_block
fill ~35 ~60 ~46 ~37 ~67 ~46 stone
fill ~35 ~68 ~46 ~37 ~70 ~46 dirt
fill ~35 ~71 ~46 ~37 ~71 ~46 grass_block
fill ~38 ~60 ~46 ~46 ~68 ~46 stone
fill ~38 ~69 ~46 ~46 ~71 ~46 dirt
fill ~38 ~72 ~46 ~46 ~72 ~46 grass_block
fill ~47 ~60 ~46 ~47 ~67 ~46 stone
fill ~47 ~68 ~46 ~47 ~70 ~46 dirt
fill ~47 ~71 ~46 ~47 ~71 ~46 grass_block
fill ~32 ~60 ~47 ~33 ~67 ~47 stone
fill ~32 ~68 ~47 ~33 ~70 ~47 dirt
fill ~32 ~71 ~47 ~33 ~71 ~47 grass_block
fill ~34 ~60 ~47 ~36 ~66 ~47 stone
fill ~34 ~67 ~47 ~36 ~69 ~47 dirt
fill ~34 ~70 ~47 ~36 ~70 ~47 grass_block
fill ~37 ~60 ~47 ~39 ~67 ~47 stone
fill ~37 ~68 ~47 ~39 ~70 ~47 dirt
fill ~37 ~71 ~47 ~39 ~71 ~47 grass_block
fill ~40 ~60 ~47 ~47 ~68 ~47 stone
fill ~40 ~69 ~47 ~47 ~71 ~47 dirt
fill ~40 ~72 ~47 ~47 ~72 ~47 grass_block