fill ~320 ~60 ~112 ~321 ~63 ~112 stone
fill ~320 ~64 ~112 ~321 ~66 ~112 dirt
fill ~320 ~67 ~112 ~321 ~67 ~112 grass_block
fill ~322 ~60 ~112 ~331 ~62 ~112 stone
fill ~322 ~63 ~112 ~331 ~65 ~112 dirt
fill ~322 ~66 ~112 ~331 ~66 ~112 grass_block
fill ~332 ~60 ~112 ~335 ~61 ~112 stone
fill ~332 ~62 ~112 ~335 ~64 ~112 dirt
fill ~332 ~65 ~112 ~335 ~65 ~112 grass_block
fill ~320 ~60 ~113 ~321 ~63 ~113 stone
fill ~320 ~64 ~113 ~321 ~66 ~113 dirt
fill ~320 ~67 ~113 ~321 ~67 ~113 grass_block
fill ~322 ~60 ~113 ~332 ~62 ~113 stone
fill ~322 ~63 ~113 ~332 ~65 ~113 dirt
fill ~322 ~66 ~113 ~332 ~66 ~113 grass_block
fill ~333 ~60 ~113 ~333 ~61 ~113 stone
fill ~333 ~62 ~113 ~333 ~64 ~113 dirt
fill ~333 ~65 ~113 ~333 ~65 ~113 grass_block
fill ~334 ~60 ~113 ~335 ~62 ~113 stone
fill ~334 ~63 ~113 ~335 ~65 ~113 dirt
fill ~334 ~66 ~113 ~335 ~66 ~113 grass_block
fill ~320 ~60 ~114 ~322 ~63 ~114 stone
fill ~320 ~64 ~114 ~322 ~66 ~114 dirt
fill ~320 ~67 ~114 ~322 ~67 ~114 grass_block
fill ~323 ~60 ~114 ~335 ~62 ~114 stone
fill ~323 ~63 ~114 ~335 ~65 ~114 dirt
fill ~323 ~66 ~114 ~335 ~66 ~114 grass_block
fill ~320 ~60 ~115 ~324 ~63 ~115 stone
fill ~320 ~64 ~115 ~324 ~66 ~115 dirt
fill ~320 ~67 ~115 ~324 ~67 ~115 grass_block
fill ~325 ~60 ~115 ~335 ~62 ~115 stone
fill ~325 ~63 ~115 ~335 ~65 ~115 dirt
fill ~325 ~66 ~115 ~335 ~66 ~115 grass_block
fill ~320 ~60 ~116 ~325 ~63 ~116 stone
fill ~320 ~64 ~116 ~325 ~66 ~116 dirt
fill ~320 ~67 ~116 ~325 ~67 ~116 grass_block
fill ~326 ~60 ~116 ~335 ~62 ~116 stone
fill ~326 ~63 ~116 ~335 ~65 ~116 dirt
fill ~326 ~66 ~116 ~335 ~66 ~116 grass_block
fill ~320 ~60 ~117 ~326 ~63 ~117 stone
fill ~320 ~64 ~117 ~326 ~66 ~117 dirt
fill ~320 ~67 ~117 ~326 ~67 ~117 grass_block
fill ~327 ~60 ~117 ~335 ~62 ~117 stone
fill ~327 ~63 ~117 ~335 ~65 ~117 dirt
fill ~327 ~66 ~117 ~335 ~66 ~117 grass_block
fill ~320 ~60 ~118 ~326 ~63 ~118 stone
fill ~320 ~64 ~118 ~326 ~66 ~118 dirt
fill ~320 ~67 ~118 ~326 ~67 ~118 grass_block
fill ~327 ~60 ~118 ~335 ~62 ~118 stone
fill ~327 ~63 ~118 ~335 ~65 ~118 dirt
fill ~327 ~66 ~118 ~335 ~66 ~118 grass_block
fill ~320 ~60 ~119 ~328 ~63 ~119 stone
fill ~320 ~64 ~119 ~328 ~66 ~119 dirt
fill ~320 ~67 ~119 ~328 ~67 ~119 grass_block
fill ~329 ~60 ~119 ~335 ~62 ~119 stone
fill ~329 ~63 ~119 ~335 ~65 ~119 dirt
fill ~329 ~66 ~119 ~335 ~66 ~119 grass_block
fill ~320 ~60 ~120 ~329 ~63 ~120 stone
fill ~320 ~64 ~120 ~329 ~66 ~120 dirt
fill ~320 ~67 ~120 ~329 ~67 ~120 grass_block
fill ~330 ~60 ~120 ~335 ~62 ~120 stone
fill ~330 ~63 ~120 ~335 ~65 ~120 dirt
fill ~330 ~66 ~120 ~335 ~66 ~120 grass_block
fill ~320 ~60 ~121 ~329 ~63 ~121 stone
fill ~320 ~64 ~121 ~329 ~66 ~121 dirt
fill ~320 ~67 ~121 ~329 ~67 ~121 grass_block
fill ~330 ~60 ~121 ~335 ~62 ~121 stone
fill ~330 ~63 ~121 ~335 ~65 ~121 dirt
fill ~330 ~66 ~121 ~335 ~66 ~121 grass_block
fill ~320 ~60 ~122 ~330 ~63 ~122 stone
fill ~320 ~64 ~122 ~330 ~66 ~122 dirt
fill ~320 ~67 ~122 ~330 ~67 ~122 grass_block
fill ~331 ~60 ~122 ~335 ~62 ~122 stone
fill ~331 ~63 ~122 ~335 ~65 ~122 dirt
fill ~331 ~66 ~122 ~335 ~66 ~122 grass_block
fill ~320 ~60 ~123 ~320 ~64 ~123 stone
fill ~320 ~65 ~123 ~320 ~67 ~123 dirt
fill ~320 ~68 ~123 ~320 ~68 ~123 grass_block
fill ~321 ~60 ~123 ~329 ~63 ~123 stone
fill ~321 ~64 ~123 ~329 ~66 ~123 dirt
fill ~321 ~67 ~123 ~329 ~67 ~123 grass_block
fill ~330 ~60 ~123 ~335 ~62 ~123 stone
fill ~330 ~63 ~123 ~335 ~65 ~123 dirt
fill ~330 ~66 ~123 ~335 ~66 ~123 grass_block
fill ~320 ~60 ~124 ~321 ~64 ~124 stone
fill ~320 ~65 ~124 ~321 ~67 ~124 dirt
fill ~320 ~68 ~124 ~321 ~68 ~124 grass_block
fill ~322 ~60 ~124 ~329 ~63 ~124 stone
fill ~322 ~64 ~124 ~329 ~66 ~124 dirt
fill ~322 ~67 ~124 ~329 ~67 ~124 grass_block
fill ~330 ~60 ~124 ~335 ~62 ~124 stone
fill ~330 ~63 ~124 ~335 ~65 ~124 dirt
fill ~330 ~66 ~124 ~335 ~66 ~124 grass_block
fill ~320 ~60 ~125 ~321 ~64 ~125 stone
fill ~320 ~65 ~125 ~321 ~67 ~125 dirt
fill ~320 ~68 ~125 ~321 ~68 ~125 grass_block
fill ~322 ~60 ~125 ~329 ~63 ~125 stone
fill ~322 ~64 ~125 ~329 ~66 ~125 dirt
fill ~322 ~67 ~125 ~329 ~67 ~125 grass_block
fill ~330 ~60 ~125 ~335 ~62 ~125 stone
fill ~330 ~63 ~125 ~335 ~65 ~125 dirt
fill ~330 ~66 ~125 ~335 ~66 ~125 grass_block
fill ~320 ~60 ~126 ~322 ~64 ~126 stone
fill ~320 ~65 ~126 ~322 ~67 ~126 dirt
fill ~320 ~68 ~126 ~322 ~68 ~126 grass_block
fill ~323 ~60 ~126 ~328 ~63 ~126 stone
fill ~323 ~64 ~126 ~328 ~66 ~126 dirt
fill ~323 ~67 ~126 ~328 ~67 ~126 grass_block
fill ~329 ~60 ~126 ~335 ~62 ~126 stone
fill ~329 ~63 ~126 ~335 ~65 ~126 dirt
fill ~329 ~66 ~126 ~335 ~66 ~126 grass_block
fill ~320 ~60 ~127 ~323 ~64 ~127 stone
fill ~320 ~65 ~127 ~323 ~67 ~127 dirt
fill ~320 ~68 ~127 ~323 ~68 ~127 grass_block
fill ~324 ~60 ~127 ~327 ~63 ~127 stone
fill ~324 ~64 ~127 ~327 ~66 ~127 dirt
fill ~324 ~67 ~127 ~327 ~67 ~127 grass_block
fill ~328 ~60 ~127 ~334 ~62 ~127 stone
fill ~328 ~63 ~127 ~334 ~65 ~127 dirt
fill ~328 ~66 ~127 ~334 ~66 ~127 grass_block
fill ~335 ~60 ~127 ~335 ~63 ~127 stone
fill ~335 ~64 ~127 ~335 ~66 ~127 dirt
fill ~335 ~67 ~127 ~335 ~67 ~127 grass_block