fill ~208 ~60 ~96 ~211 ~66 ~96 stone
fill ~208 ~67 ~96 ~211 ~69 ~96 dirt
fill ~208 ~70 ~96 ~211 ~70 ~96 grass_block
fill ~212 ~60 ~96 ~215 ~65 ~96 stone
fill ~212 ~66 ~96 ~215 ~68 ~96 dirt
fill ~212 ~69 ~96 ~215 ~69 ~96 grass_block
fill ~216 ~60 ~96 ~223 ~64 ~96 stone
fill ~216 ~65 ~96 ~223 ~67 ~96 dirt
fill ~216 ~68 ~96 ~223 ~68 ~96 grass_block
fill ~208 ~60 ~97 ~212 ~66 ~97 stone
fill ~208 ~67 ~97 ~212 ~69 ~97 dirt
fill ~208 ~70 ~97 ~212 ~70 ~97 grass_block
fill ~213 ~60 ~97 ~215 ~65 ~97 stone
fill ~213 ~66 ~97 ~215 ~68 ~97 dirt
fill ~213 ~69 ~97 ~215 ~69 ~97 grass_block
fill ~216 ~60 ~97 ~219 ~64 ~97 stone
fill ~216 ~65 ~97 ~219 ~67 ~97 dirt
fill ~216 ~68 ~97 ~219 ~68 ~97 grass_block
fill ~220 ~60 ~97 ~220 ~63 ~97 stone
fill ~220 ~64 ~97 ~220 ~66 ~97 dirt
fill ~220 ~67 ~97 ~220 ~67 ~97 grass_block
fill ~221 ~60 ~97 ~223 ~64 ~97 stone
fill ~221 ~65 ~97 ~223 ~67 ~97 dirt
fill ~221 ~68 ~97 ~223 ~68 ~97 grass_block
fill ~208 ~60 ~98 ~212 ~66 ~98 stone
fill ~208 ~67 ~98 ~212 ~69 ~98 dirt
fill ~208 ~70 ~98 ~212 ~70 ~98 grass_block
fill ~213 ~60 ~98 ~216 ~65 ~98 stone
fill ~213 ~66 ~98 ~216 ~68 ~98 dirt
fill ~213 ~69 ~98 ~216 ~69 ~98 grass_block
fill ~217 ~60 ~98 ~219 ~64 ~98 stone
fill ~217 ~65 ~98 ~219 ~67 ~98 dirt
fill ~217 ~68 ~98 ~219 ~68 ~98 grass_block
fill ~220 ~60 ~98 ~221 ~63 ~98 stone
fill ~220 ~64 ~98 ~221 ~66 ~98 dirt
fill ~220 ~67 ~98 ~221 ~67 ~98 grass_block
fill ~222 ~60 ~98 ~223 ~64 ~98 stone
fill ~222 ~65 ~98 ~223 ~67 ~98 dirt
fill ~222 ~68 ~98 ~223 ~68 ~98 grass_block
fill ~208 ~60 ~99 ~213 ~66 ~99 stone
fill ~208 ~67 ~99 ~213 ~69 ~99 dirt
fill ~208 ~70 ~99 ~213 ~70 ~99 grass_block
fill ~214 ~60 ~99 ~216 ~65 ~99 stone
fill ~214 ~66 ~99 ~216 ~68 ~99 dirt
fill ~214 ~69 ~99 ~216 ~69 ~99 grass_block
fill ~217 ~60 ~99 ~220 ~64 ~99 stone
fill ~217 ~65 ~99 ~220 ~67 ~99 dirt
fill ~217 ~68 ~99 ~220 ~68 ~99 grass_block
fill ~221 ~60 ~99 ~222 ~63 ~99 stone
fill ~221 ~64 ~99 ~222 ~66 ~99 dirt
fill ~221 ~67 ~99 ~222 ~67 ~99 grass_block
fill ~223 ~60 ~99 ~223 ~64 ~99 stone
fill ~223 ~65 ~99 ~223 ~67 ~99 dirt
fill ~223 ~68 ~99 ~223 ~68 ~99 grass_block
fill ~208 ~60 ~100 ~214 ~66 ~100 stone
fill ~208 ~67 ~100 ~214 ~69 ~100 dirt
fill ~208 ~70 ~100 ~214 ~70 ~100 grass_block
fill ~215 ~60 ~100 ~217 ~65 ~100 stone
fill ~215 ~66 ~100 ~217 ~68 ~100 dirt
fill ~215 ~69 ~100 ~217 ~69 ~100 grass_block
fill ~218 ~60 ~100 ~220 ~64 ~100 stone
fill ~218 ~65 ~100 ~220 ~67 ~100 dirt
fill ~218 ~68 ~100 ~220 ~68 ~100 grass_block
fill ~221 ~60 ~100 ~223 ~63 ~100 stone
fill ~221 ~64 ~100 ~223 ~66 ~100 dirt
fill ~221 ~67 ~100 ~223 ~67 ~100 grass_block
fill ~208 ~60 ~101 ~215 ~66 ~101 stone
fill ~208 ~67 ~101 ~215 ~69 ~101 dirt
fill ~208 ~70 ~101 ~215 ~70 ~101 grass_block
fill ~216 ~60 ~101 ~217 ~65 ~101 stone
fill ~216 ~66 ~101 ~217 ~68 ~101 dirt
fill ~216 ~69 ~101 ~217 ~69 ~101 grass_block
fill ~218 ~60 ~101 ~221 ~64 ~101 stone
fill ~218 ~65 ~101 ~221 ~67 ~101 dirt
fill ~218 ~68 ~101 ~221 ~68 ~101 grass_block
fill ~222 ~60 ~101 ~223 ~63 ~101 stone
fill ~222 ~64 ~101 ~223 ~66 ~101 dirt
fill ~222 ~67 ~101 ~223 ~67 ~101 grass_block
fill ~208 ~60 ~102 ~214 ~65 ~102 stone
fill ~208 ~66 ~102 ~214 ~68 ~102 dirt
fill ~208 ~69 ~102 ~214 ~69 ~102 grass_block
fill ~215 ~60 ~102 ~216 ~66 ~102 stone
fill ~215 ~67 ~102 ~216 ~69 ~102 dirt
fill ~215 ~70 ~102 ~216 ~70 ~102 grass_block
fill ~217 ~60 ~102 ~219 ~65 ~102 stone
fill ~217 ~66 ~102 ~219 ~68 ~102 dirt
fill ~217 ~69 ~102 ~219 ~69 ~102 grass_block
fill ~220 ~60 ~102 ~222 ~64 ~102 stone
fill ~220 ~65 ~102 ~222 ~67 ~102 dirt
fill ~220 ~68 ~102 ~222 ~68 ~102 grass_block
fill ~223 ~60 ~102 ~223 ~63 ~102 stone
fill ~223 ~64 ~102 ~223 ~66 ~102 dirt
fill ~223 ~67 ~102 ~223 ~67 ~102 grass_block
fill ~208 ~60 ~103 ~208 ~65 ~103 stone
fill ~208 ~66 ~103 ~208 ~68 ~103 dirt
fill ~208 ~69 ~103 ~208 ~69 ~103 grass_block
fill ~209 ~60 ~103 ~210 ~64 ~103 stone
fill ~209 ~65 ~103 ~210 ~67 ~103 dirt
fill ~209 ~68 ~103 ~210 ~68 ~103 grass_block
fill ~211 ~60 ~103 ~216 ~65 ~103 stone
fill ~211 ~66 ~103 ~216 ~68 ~103 dirt
fill ~211 ~69 ~103 ~216 ~69 ~103 grass_block
fill ~217 ~60 ~103 ~217 ~66 ~103 stone
fill ~217 ~67 ~103 ~217 ~69 ~103 dirt
fill ~217 ~70 ~103 ~217 ~70 ~103 grass_block
fill ~218 ~60 ~103 ~219 ~65 ~103 stone
fill ~218 ~66 ~103 ~219 ~68 ~103 dirt
fill ~218 ~69 ~103 ~219 ~69 ~103 grass_block
fill ~220 ~60 ~103 ~223 ~64 ~103 stone
fill ~220 ~65 ~103 ~223 ~67 ~103 dirt
fill ~220 ~68 ~103 ~223 ~68 ~103 grass_block
fill ~208 ~60 ~104 ~215 ~64 ~104 stone
fill ~208 ~65 ~104 ~215 ~67 ~104 dirt
fill ~208 ~68 ~104 ~215 ~68 ~104 grass_block
fill ~216 ~60 ~104 ~216 ~65 ~104 stone
fill ~216 ~66 ~104 ~216 ~68 ~104 dirt
fill ~216 ~69 ~104 ~216 ~69 ~104 grass_block
fill ~217 ~60 ~104 ~218 ~66 ~104 stone
fill ~217 ~67 ~104 ~218 ~69 ~104 dirt
fill ~217 ~70 ~104 ~218 ~70 ~104 grass_block
fill ~219 ~60 ~104 ~220 ~65 ~104 stone
fill ~219 ~66 ~104 ~220 ~68 ~104 dirt
fill ~219 ~69 ~104 ~220 ~69 ~104 grass_block
fill ~221 ~60 ~104 ~223 ~64 ~104 stone
fill ~221 ~65 ~104 ~223 ~67 ~104 dirt
fill ~221 ~68 ~104 ~223 ~68 ~104 grass_block
fill ~208 ~60 ~105 ~208 ~64 ~105 stone
fill ~208 ~65 ~105 ~208 ~67 ~105 dirt
fill ~208 ~68 ~105 ~208 ~68 ~105 grass_block
fill ~209 ~60 ~105 ~211 ~63 ~105 stone
fill ~209 ~64 ~105 ~211 ~66 ~105 dirt
fill ~209 ~67 ~105 ~211 ~67 ~105 grass_block
fill ~212 ~60 ~105 ~215 ~64 ~105 stone
fill ~212 ~65 ~105 ~215 ~67 ~105 dirt
fill ~212 ~68 ~105 ~215 ~68 ~105 grass_block
fill ~216 ~60 ~105 ~217 ~65 ~105 stone
fill ~216 ~66 ~105 ~217 ~68 ~105 dirt
fill ~216 ~69 ~105 ~217 ~69 ~105 grass_block
fill ~218 ~60 ~105 ~219 ~66 ~105 stone
fill ~218 ~67 ~105 ~219 ~69 ~105 dirt
fill ~218 ~70 ~105 ~219 ~70 ~105 grass_block
fill ~220 ~60 ~105 ~221 ~65 ~105 stone
fill ~220 ~66 ~105 ~221 ~68 ~105 dirt
fill ~220 ~69 ~105 ~221 ~69 ~105 grass_block
fill ~222 ~60 ~105 ~223 ~64 ~105 stone
fill ~222 ~65 ~105 ~223 ~67 ~105 dirt
fill ~222 ~68 ~105 ~223 ~68 ~105 grass_block
fill ~208 ~60 ~106 ~212 ~63 ~106 stone
fill ~208 ~64 ~106 ~212 ~66 ~106 dirt
fill ~208 ~67 ~106 ~212 ~67 ~106 grass_block
fill ~213 ~60 ~106 ~216 ~64 ~106 stone
fill ~213 ~65 ~106 ~216 ~67 ~106 dirt
fill ~213 ~68 ~106 ~216 ~68 ~106 grass_block
fill ~217 ~60 ~106 ~218 ~65 ~106 stone
fill ~217 ~66 ~106 ~218 ~68 ~106 dirt
fill ~217 ~69 ~106 ~218 ~69 ~106 grass_block
fill ~219 ~60 ~106 ~221 ~66 ~106 stone
fill ~219 ~67 ~106 ~221 ~69 ~106 dirt
fill ~219 ~70 ~106 ~221 ~70 ~106 grass_block
fill ~222 ~60 ~106 ~223 ~65 ~106 stone
fill ~222 ~66 ~106 ~223 ~68 ~106 dirt
fill ~222 ~69 ~106 ~223 ~69 ~106 grass_block
fill ~208 ~60 ~107 ~210 ~63 ~107 stone
fill ~208 ~64 ~107 ~210 ~66 ~107 dirt
fill ~208 ~67 ~107 ~210 ~67 ~107 grass_block
fill ~211 ~60 ~107 ~213 ~64 ~107 stone
fill ~211 ~65 ~107 ~213 ~67 ~107 dirt
fill ~211 ~68 ~107 ~213 ~68 ~107 grass_block
fill ~214 ~60 ~107 ~217 ~65 ~107 stone
fill ~214 ~66 ~107 ~217 ~68 ~107 dirt
fill ~214 ~69 ~107 ~217 ~69 ~107 grass_block
fill ~218 ~60 ~107 ~222 ~66 ~107 stone
fill ~218 ~67 ~107 ~222 ~69 ~107 dirt
fill ~218 ~70 ~107 ~222 ~70 ~107 grass_block
fill ~223 ~60 ~107 ~223 ~65 ~107 stone
fill ~223 ~66 ~107 ~223 ~68 ~107 dirt
fill ~223 ~69 ~107 ~223 ~69 ~107 grass_block
fill ~208 ~60 ~108 ~208 ~63 ~108 stone
fill ~208 ~64 ~108 ~208 ~66 ~108 dirt
fill ~208 ~67 ~108 ~208 ~67 ~108 grass_block
fill ~209 ~60 ~108 ~210 ~64 ~108 stone
fill ~209 ~65 ~108 ~210 ~67 ~108 dirt
fill ~209 ~68 ~108 ~210 ~68 ~108 grass_block
fill ~211 ~60 ~108 ~217 ~65 ~108 stone
fill ~211 ~66 ~108 ~217 ~68 ~108 dirt
fill ~211 ~69 ~108 ~217 ~69 ~108 grass_block
fill ~218 ~60 ~108 ~223 ~66 ~108 stone
fill ~218 ~67 ~108 ~223 ~69 ~108 dirt
fill ~218 ~70 ~108 ~223 ~70 ~108 grass_block
fill ~208 ~60 ~109 ~208 ~63 ~109 stone
fill ~208 ~64 ~109 ~208 ~66 ~109 dirt
fill ~208 ~67 ~109 ~208 ~67 ~109 grass_block
fill ~209 ~60 ~109 ~210 ~64 ~109 stone
fill ~209 ~65 ~109 ~210 ~67 ~109 dirt
fill ~209 ~68 ~109 ~210 ~68 ~109 grass_block
fill ~211 ~60 ~109 ~216 ~65 ~109 stone
fill ~211 ~66 ~109 ~216 ~68 ~109 dirt
fill ~211 ~69 ~109 ~216 ~69 ~109 grass_block
fill ~217 ~60 ~109 ~223 ~66 ~109 stone
fill ~217 ~67 ~109 ~223 ~69 ~109 dirt
fill ~217 ~70 ~109 ~223 ~70 ~109 grass_block
fill ~208 ~60 ~110 ~208 ~63 ~110 stone
fill ~208 ~64 ~110 ~208 ~66 ~110 dirt
fill ~208 ~67 ~110 ~208 ~67 ~110 grass_block
fill ~209 ~60 ~110 ~210 ~64 ~110 stone
fill ~209 ~65 ~110 ~210 ~67 ~110 dirt
fill ~209 ~68 ~110 ~210 ~68 ~110 grass_block
fill ~211 ~60 ~110 ~215 ~65 ~110 stone
fill ~211 ~66 ~110 ~215 ~68 ~110 dirt
fill ~211 ~69 ~110 ~215 ~69 ~110 grass_block
fill ~216 ~60 ~110 ~223 ~66 ~110 stone
fill ~216 ~67 ~110 ~223 ~69 ~110 dirt
fill ~216 ~70 ~110 ~223 ~70 ~110 grass_block
fill ~208 ~60 ~111 ~208 ~63 ~111 stone
fill ~208 ~64 ~111 ~208 ~66 ~111 dirt
fill ~208 ~67 ~111 ~208 ~67 ~111 grass_block
fill ~209 ~60 ~111 ~210 ~64 ~111 stone
fill ~209 ~65 ~111 ~210 ~67 ~111 dirt
fill ~209 ~68 ~111 ~210 ~68 ~111 grass_block
fill ~211 ~60 ~111 ~216 ~65 ~111 stone
fill ~211 ~66 ~111 ~216 ~68 ~111 dirt
fill ~211 ~69 ~111 ~216 ~69 ~111 grass_block
fill ~217 ~60 ~111 ~223 ~66 ~111 stone
fill ~217 ~67 ~111 ~223 ~69 ~111 dirt
fill ~217 ~70 ~111 ~223 ~70 ~111 grass_block