fill ~368 ~60 ~16 ~383 ~62 ~16 stone
fill ~368 ~63 ~16 ~383 ~65 ~16 dirt
fill ~368 ~66 ~16 ~383 ~66 ~16 grass_block
fill ~368 ~60 ~17 ~369 ~63 ~17 stone
fill ~368 ~64 ~17 ~369 ~66 ~17 dirt
fill ~368 ~67 ~17 ~369 ~67 ~17 grass_block
fill ~370 ~60 ~17 ~383 ~62 ~17 stone
fill ~370 ~63 ~17 ~383 ~65 ~17 dirt
fill ~370 ~66 ~17 ~383 ~66 ~17 grass_block
fill ~368 ~60 ~18 ~369 ~64 ~18 stone
fill ~368 ~65 ~18 ~369 ~67 ~18 dirt
fill ~368 ~68 ~18 ~369 ~68 ~18 grass_block
fill ~370 ~60 ~18 ~373 ~63 ~18 stone
fill ~370 ~64 ~18 ~373 ~66 ~18 dirt
fill ~370 ~67 ~18 ~373 ~67 ~18 grass_block
fill ~374 ~60 ~18 ~383 ~62 ~18 stone
fill ~374 ~63 ~18 ~383 ~65 ~18 dirt
fill ~374 ~66 ~18 ~383 ~66 ~18 grass_block
fill ~368 ~60 ~19 ~371 ~64 ~19 stone
fill ~368 ~65 ~19 ~371 ~67 ~19 dirt
fill ~368 ~68 ~19 ~371 ~68 ~19 grass_block
fill ~372 ~60 ~19 ~377 ~63 ~19 stone
fill ~372 ~64 ~19 ~377 ~66 ~19 dirt
fill ~372 ~67 ~19 ~377 ~67 ~19 grass_block
fill ~378 ~60 ~19 ~383 ~62 ~19 stone
fill ~378 ~63 ~19 ~383 ~65 ~19 dirt
fill ~378 ~66 ~19 ~383 ~66 ~19 grass_block
fill ~368 ~60 ~20 ~368 ~65 ~20 stone
fill ~368 ~66 ~20 ~368 ~68 ~20 dirt
fill ~368 ~69 ~20 ~368 ~69 ~20 grass_block
fill ~369 ~60 ~20 ~374 ~64 ~20 stone
fill ~369 ~65 ~20 ~374 ~67 ~20 dirt
fill ~369 ~68 ~20 ~374 ~68 ~20 grass_block
fill ~375 ~60 ~20 ~379 ~63 ~20 stone
fill ~375 ~64 ~20 ~379 ~66 ~20 dirt
fill ~375 ~67 ~20 ~379 ~67 ~20 grass_block
fill ~380 ~60 ~20 ~383 ~62 ~20 stone
fill ~380 ~63 ~20 ~383 ~65 ~20 dirt
fill ~380 ~66 ~20 ~383 ~66 ~20 grass_block
fill ~368 ~60 ~21 ~369 ~65 ~21 stone
fill ~368 ~66 ~21 ~369 ~68 ~21 dirt
fill ~368 ~69 ~21 ~369 ~69 ~21 grass_block
fill ~370 ~60 ~21 ~374 ~64 ~21 stone
fill ~370 ~65 ~21 ~374 ~67 ~21 dirt
fill ~370 ~68 ~21 ~374 ~68 ~21 grass_block
fill ~375 ~60 ~21 ~379 ~63 ~21 stone
fill ~375 ~64 ~21 ~379 ~66 ~21 dirt
fill ~375 ~67 ~21 ~379 ~67 ~21 grass_block
fill ~380 ~60 ~21 ~383 ~62 ~21 stone
fill ~380 ~63 ~21 ~383 ~65 ~21 dirt
fill ~380 ~66 ~21 ~383 ~66 ~21 grass_block
fill ~368 ~60 ~22 ~369 ~65 ~22 stone
fill ~368 ~66 ~22 ~369 ~68 ~22 dirt
fill ~368 ~69 ~22 ~369 ~69 ~22 grass_block
fill ~370 ~60 ~22 ~375 ~64 ~22 stone
fill ~370 ~65 ~22 ~375 ~67 ~22 dirt
fill ~370 ~68 ~22 ~375 ~68 ~22 grass_block
fill ~376 ~60 ~22 ~380 ~63 ~22 stone
fill ~376 ~64 ~22 ~380 ~66 ~22 dirt
fill ~376 ~67 ~22 ~380 ~67 ~22 grass_block
fill ~381 ~60 ~22 ~383 ~62 ~22 stone
fill ~381 ~63 ~22 ~383 ~65 ~22 dirt
fill ~381 ~66 ~22 ~383 ~66 ~22 grass_block
fill ~368 ~60 ~23 ~374 ~64 ~23 stone
fill ~368 ~65 ~23 ~374 ~67 ~23 dirt
fill ~368 ~68 ~23 ~374 ~68 ~23 grass_block
fill ~375 ~60 ~23 ~380 ~63 ~23 stone
fill ~375 ~64 ~23 ~380 ~66 ~23 dirt
fill ~375 ~67 ~23 ~380 ~67 ~23 grass_block
fill ~381 ~60 ~23 ~383 ~62 ~23 stone
fill ~381 ~63 ~23 ~383 ~65 ~23 dirt
fill ~381 ~66 ~23 ~383 ~66 ~23 grass_block
fill ~368 ~60 ~24 ~369 ~64 ~24 stone
fill ~368 ~65 ~24 ~369 ~67 ~24 dirt
fill ~368 ~68 ~24 ~369 ~68 ~24 grass_block
fill ~370 ~60 ~24 ~370 ~63 ~24 stone
fill ~370 ~64 ~24 ~370 ~66 ~24 dirt
fill ~370 ~67 ~24 ~370 ~67 ~24 grass_block
fill ~371 ~60 ~24 ~372 ~64 ~24 stone
fill ~371 ~65 ~24 ~372 ~67 ~24 dirt
fill ~371 ~68 ~24 ~372 ~68 ~24 grass_block
fill ~373 ~60 ~24 ~378 ~63 ~24 stone
fill ~373 ~64 ~24 ~378 ~66 ~24 dirt
fill ~373 ~67 ~24 ~378 ~67 ~24 grass_block
fill ~379 ~60 ~24 ~383 ~62 ~24 stone
fill ~379 ~63 ~24 ~383 ~65 ~24 dirt
fill ~379 ~66 ~24 ~383 ~66 ~24 grass_block
fill ~368 ~60 ~25 ~375 ~63 ~25 stone
fill ~368 ~64 ~25 ~375 ~66 ~25 dirt
fill ~368 ~67 ~25 ~375 ~67 ~25 grass_block
fill ~376 ~60 ~25 ~383 ~62 ~25 stone
fill ~376 ~63 ~25 ~383 ~65 ~25 dirt
fill ~376 ~66 ~25 ~383 ~66 ~25 grass_block
fill ~368 ~60 ~26 ~372 ~63 ~26 stone
fill ~368 ~64 ~26 ~372 ~66 ~26 dirt
fill ~368 ~67 ~26 ~372 ~67 ~26 grass_block
fill ~373 ~60 ~26 ~375 ~62 ~26 stone
fill ~373 ~63 ~26 ~375 ~65 ~26 dirt
fill ~373 ~66 ~26 ~375 ~66 ~26 grass_block
fill ~376 ~60 ~26 ~376 ~63 ~26 stone
fill ~376 ~64 ~26 ~376 ~66 ~26 dirt
fill ~376 ~67 ~26 ~376 ~67 ~26 grass_block
fill ~377 ~60 ~26 ~377 ~62 ~26 stone
fill ~377 ~63 ~26 ~377 ~65 ~26 dirt
fill ~377 ~66 ~26 ~377 ~66 ~26 grass_block
fill ~378 ~60 ~26 ~379 ~63 ~26 stone
fill ~378 ~64 ~26 ~379 ~66 ~26 dirt
fill ~378 ~67 ~26 ~379 ~67 ~26 grass_block
fill ~380 ~60 ~26 ~383 ~62 ~26 stone
fill ~380 ~63 ~26 ~383 ~65 ~26 dirt
fill ~380 ~66 ~26 ~383 ~66 ~26 grass_block
fill ~368 ~60 ~27 ~369 ~64 ~27 stone
fill ~368 ~65 ~27 ~369 ~67 ~27 dirt
fill ~368 ~68 ~27 ~369 ~68 ~27 grass_block
fill ~370 ~60 ~27 ~372 ~63 ~27 stone
fill ~370 ~64 ~27 ~372 ~66 ~27 dirt
fill ~370 ~67 ~27 ~372 ~67 ~27 grass_block
fill ~373 ~60 ~27 ~375 ~62 ~27 stone
fill ~373 ~63 ~27 ~375 ~65 ~27 dirt
fill ~373 ~66 ~27 ~375 ~66 ~27 grass_block
fill ~376 ~60 ~27 ~383 ~63 ~27 stone
fill ~376 ~64 ~27 ~383 ~66 ~27 dirt
fill ~376 ~67 ~27 ~383 ~67 ~27 grass_block
fill ~368 ~60 ~28 ~369 ~64 ~28 stone
fill ~368 ~65 ~28 ~369 ~67 ~28 dirt
fill ~368 ~68 ~28 ~369 ~68 ~28 grass_block
fill ~370 ~60 ~28 ~371 ~63 ~28 stone
fill ~370 ~64 ~28 ~371 ~66 ~28 dirt
fill ~370 ~67 ~28 ~371 ~67 ~28 grass_block
fill ~372 ~60 ~28 ~374 ~62 ~28 stone
fill ~372 ~63 ~28 ~374 ~65 ~28 dirt
fill ~372 ~66 ~28 ~374 ~66 ~28 grass_block
fill ~375 ~60 ~28 ~376 ~63 ~28 stone
fill ~375 ~64 ~28 ~376 ~66 ~28 dirt
fill ~375 ~67 ~28 ~376 ~67 ~28 grass_block
fill ~377 ~60 ~28 ~379 ~64 ~28 stone
fill ~377 ~65 ~28 ~379 ~67 ~28 dirt
fill ~377 ~68 ~28 ~379 ~68 ~28 grass_block
fill ~380 ~60 ~28 ~383 ~63 ~28 stone
fill ~380 ~64 ~28 ~383 ~66 ~28 dirt
fill ~380 ~67 ~28 ~383 ~67 ~28 grass_block
fill ~368 ~60 ~29 ~369 ~64 ~29 stone
fill ~368 ~65 ~29 ~369 ~67 ~29 dirt
fill ~368 ~68 ~29 ~369 ~68 ~29 grass_block
fill ~370 ~60 ~29 ~377 ~63 ~29 stone
fill ~370 ~64 ~29 ~377 ~66 ~29 dirt
fill ~370 ~67 ~29 ~377 ~67 ~29 grass_block
fill ~378 ~60 ~29 ~383 ~64 ~29 stone
fill ~378 ~65 ~29 ~383 ~67 ~29 dirt
fill ~378 ~68 ~29 ~383 ~68 ~29 grass_block
fill ~368 ~60 ~30 ~369 ~64 ~30 stone
fill ~368 ~65 ~30 ~369 ~67 ~30 dirt
fill ~368 ~68 ~30 ~369 ~68 ~30 grass_block
fill ~370 ~60 ~30 ~378 ~63 ~30 stone
fill ~370 ~64 ~30 ~378 ~66 ~30 dirt
fill ~370 ~67 ~30 ~378 ~67 ~30 grass_block
fill ~379 ~60 ~30 ~380 ~64 ~30 stone
fill ~379 ~65 ~30 ~380 ~67 ~30 dirt
fill ~379 ~68 ~30 ~380 ~68 ~30 grass_block
fill ~381 ~60 ~30 ~383 ~65 ~30 stone
fill ~381 ~66 ~30 ~383 ~68 ~30 dirt
fill ~381 ~69 ~30 ~383 ~69 ~30 grass_block
fill ~368 ~60 ~31 ~368 ~65 ~31 stone
fill ~368 ~66 ~31 ~368 ~68 ~31 dirt
fill ~368 ~69 ~31 ~368 ~69 ~31 grass_block
fill ~369 ~60 ~31 ~370 ~64 ~31 stone
fill ~369 ~65 ~31 ~370 ~67 ~31 dirt
fill ~369 ~68 ~31 ~370 ~68 ~31 grass_block
fill ~371 ~60 ~31 ~374 ~63 ~31 stone
fill ~371 ~64 ~31 ~374 ~66 ~31 dirt
fill ~371 ~67 ~31 ~374 ~67 ~31 grass_block
fill ~375 ~60 ~31 ~380 ~64 ~31 stone
fill ~375 ~65 ~31 ~380 ~67 ~31 dirt
fill ~375 ~68 ~31 ~380 ~68 ~31 grass_block
fill ~381 ~60 ~31 ~383 ~65 ~31 stone
fill ~381 ~66 ~31 ~383 ~68 ~31 dirt
fill ~381 ~69 ~31 ~383 ~69 ~31 grass_block