fill ~336 ~60 ~32 ~337 ~63 ~32 stone
fill ~336 ~64 ~32 ~337 ~66 ~32 dirt
fill ~336 ~67 ~32 ~337 ~67 ~32 grass_block
fill ~338 ~60 ~32 ~338 ~64 ~32 stone
fill ~338 ~65 ~32 ~338 ~67 ~32 dirt
fill ~338 ~68 ~32 ~338 ~68 ~32 grass_block
fill ~339 ~60 ~32 ~345 ~63 ~32 stone
fill ~339 ~64 ~32 ~345 ~66 ~32 dirt
fill ~339 ~67 ~32 ~345 ~67 ~32 grass_block
fill ~346 ~60 ~32 ~348 ~64 ~32 stone
fill ~346 ~65 ~32 ~348 ~67 ~32 dirt
fill ~346 ~68 ~32 ~348 ~68 ~32 grass_block
fill ~349 ~60 ~32 ~351 ~63 ~32 stone
fill ~349 ~64 ~32 ~351 ~66 ~32 dirt
fill ~349 ~67 ~32 ~351 ~67 ~32 grass_block
fill ~336 ~60 ~33 ~351 ~63 ~33 stone
fill ~336 ~64 ~33 ~351 ~66 ~33 dirt
fill ~336 ~67 ~33 ~351 ~67 ~33 grass_block
fill ~336 ~60 ~34 ~345 ~62 ~34 stone
fill ~336 ~63 ~34 ~345 ~65 ~34 dirt
fill ~336 ~66 ~34 ~345 ~66 ~34 grass_block
fill ~346 ~60 ~34 ~351 ~63 ~34 stone
fill ~346 ~64 ~34 ~351 ~66 ~34 dirt
fill ~346 ~67 ~34 ~351 ~67 ~34 grass_block
fill ~336 ~60 ~35 ~340 ~62 ~35 stone
fill ~336 ~63 ~35 ~340 ~65 ~35 dirt
fill ~336 ~66 ~35 ~340 ~66 ~35 grass_block
fill ~341 ~60 ~35 ~350 ~63 ~35 stone
fill ~341 ~64 ~35 ~350 ~66 ~35 dirt
fill ~341 ~67 ~35 ~350 ~67 ~35 grass_block
fill ~351 ~60 ~35 ~351 ~64 ~35 stone
fill ~351 ~65 ~35 ~351 ~67 ~35 dirt
fill ~351 ~68 ~35 ~351 ~68 ~35 grass_block
fill ~336 ~60 ~36 ~338 ~62 ~36 stone
fill ~336 ~63 ~36 ~338 ~65 ~36 dirt
fill ~336 ~66 ~36 ~338 ~66 ~36 grass_block
fill ~339 ~60 ~36 ~341 ~63 ~36 stone
fill ~339 ~64 ~36 ~341 ~66 ~36 dirt
fill ~339 ~67 ~36 ~341 ~67 ~36 grass_block
fill ~342 ~60 ~36 ~346 ~64 ~36 stone
fill ~342 ~65 ~36 ~346 ~67 ~36 dirt
fill ~342 ~68 ~36 ~346 ~68 ~36 grass_block
fill ~347 ~60 ~36 ~350 ~63 ~36 stone
fill ~347 ~64 ~36 ~350 ~66 ~36 dirt
fill ~347 ~67 ~36 ~350 ~67 ~36 grass_block
fill ~351 ~60 ~36 ~351 ~64 ~36 stone
fill ~351 ~65 ~36 ~351 ~67 ~36 dirt
fill ~351 ~68 ~36 ~351 ~68 ~36 grass_block
fill ~336 ~60 ~37 ~336 ~62 ~37 stone
fill ~336 ~63 ~37 ~336 ~65 ~37 dirt
fill ~336 ~66 ~37 ~336 ~66 ~37 grass_block
fill ~337 ~60 ~37 ~339 ~63 ~37 stone
fill ~337 ~64 ~37 ~339 ~66 ~37 dirt
fill ~337 ~67 ~37 ~339 ~67 ~37 grass_block
fill ~340 ~60 ~37 ~343 ~64 ~37 stone
fill ~340 ~65 ~37 ~343 ~67 ~37 dirt
fill ~340 ~68 ~37 ~343 ~68 ~37 grass_block
fill ~344 ~60 ~37 ~345 ~65 ~37 stone
fill ~344 ~66 ~37 ~345 ~68 ~37 dirt
fill ~344 ~69 ~37 ~345 ~69 ~37 grass_block
fill ~346 ~60 ~37 ~351 ~64 ~37 stone
fill ~346 ~65 ~37 ~351 ~67 ~37 dirt
fill ~346 ~68 ~37 ~351 ~68 ~37 grass_block
fill ~336 ~60 ~38 ~336 ~62 ~38 stone
fill ~336 ~63 ~38 ~336 ~65 ~38 dirt
fill ~336 ~66 ~38 ~336 ~66 ~38 grass_block
fill ~337 ~60 ~38 ~339 ~63 ~38 stone
fill ~337 ~64 ~38 ~339 ~66 ~38 dirt
fill ~337 ~67 ~38 ~339 ~67 ~38 grass_block
fill ~340 ~60 ~38 ~344 ~64 ~38 stone
fill ~340 ~65 ~38 ~344 ~67 ~38 dirt
fill ~340 ~68 ~38 ~344 ~68 ~38 grass_block
fill ~345 ~60 ~38 ~347 ~65 ~38 stone
fill ~345 ~66 ~38 ~347 ~68 ~38 dirt
fill ~345 ~69 ~38 ~347 ~69 ~38 grass_block
fill ~348 ~60 ~38 ~351 ~64 ~38 stone
fill ~348 ~65 ~38 ~351 ~67 ~38 dirt
fill ~348 ~68 ~38 ~351 ~68 ~38 grass_block
fill ~336 ~60 ~39 ~337 ~62 ~39 stone
fill ~336 ~63 ~39 ~337 ~65 ~39 dirt
fill ~336 ~66 ~39 ~337 ~66 ~39 grass_block
fill ~338 ~60 ~39 ~341 ~63 ~39 stone
fill ~338 ~64 ~39 ~341 ~66 ~39 dirt
fill ~338 ~67 ~39 ~341 ~67 ~39 grass_block
fill ~342 ~60 ~39 ~344 ~64 ~39 stone
fill ~342 ~65 ~39 ~344 ~67 ~39 dirt
fill ~342 ~68 ~39 ~344 ~68 ~39 grass_block
fill ~345 ~60 ~39 ~350 ~65 ~39 stone
fill ~345 ~66 ~39 ~350 ~68 ~39 dirt
fill ~345 ~69 ~39 ~350 ~69 ~39 grass_block
fill ~351 ~60 ~39 ~351 ~64 ~39 stone
fill ~351 ~65 ~39 ~351 ~67 ~39 dirt
fill ~351 ~68 ~39 ~351 ~68 ~39 grass_block
fill ~336 ~60 ~40 ~338 ~63 ~40 stone
fill ~336 ~64 ~40 ~338 ~66 ~40 dirt
fill ~336 ~67 ~40 ~338 ~67 ~40 grass_block
fill ~339 ~60 ~40 ~339 ~62 ~40 stone
fill ~339 ~63 ~40 ~339 ~65 ~40 dirt
fill ~339 ~66 ~40 ~339 ~66 ~40 grass_block
fill ~340 ~60 ~40 ~342 ~63 ~40 stone
fill ~340 ~64 ~40 ~342 ~66 ~40 dirt
fill ~340 ~67 ~40 ~342 ~67 ~40 grass_block
fill ~343 ~60 ~40 ~344 ~64 ~40 stone
fill ~343 ~65 ~40 ~344 ~67 ~40 dirt
fill ~343 ~68 ~40 ~344 ~68 ~40 grass_block
fill ~345 ~60 ~40 ~351 ~65 ~40 stone
fill ~345 ~66 ~40 ~351 ~68 ~40 dirt
fill ~345 ~69 ~40 ~351 ~69 ~40 grass_block
fill ~336 ~60 ~41 ~337 ~64 ~41 stone
fill ~336 ~65 ~41 ~337 ~67 ~41 dirt
fill ~336 ~68 ~41 ~337 ~68 ~41 grass_block
fill ~338 ~60 ~41 ~342 ~63 ~41 stone
fill ~338 ~64 ~41 ~342 ~66 ~41 dirt
fill ~338 ~67 ~41 ~342 ~67 ~41 grass_block
fill ~343 ~60 ~41 ~347 ~64 ~41 stone
fill ~343 ~65 ~41 ~347 ~67 ~41 dirt
fill ~343 ~68 ~41 ~347 ~68 ~41 grass_block
fill ~348 ~60 ~41 ~351 ~65 ~41 stone
fill ~348 ~66 ~41 ~351 ~68 ~41 dirt
fill ~348 ~69 ~41 ~351 ~69 ~41 grass_block
fill ~336 ~60 ~42 ~338 ~64 ~42 stone
fill ~336 ~65 ~42 ~338 ~67 ~42 dirt
fill ~336 ~68 ~42 ~338 ~68 ~42 grass_block
fill ~339 ~60 ~42 ~344 ~63 ~42 stone
fill ~339 ~64 ~42 ~344 ~66 ~42 dirt
fill ~339 ~67 ~42 ~344 ~67 ~42 grass_block
fill ~345 ~60 ~42 ~347 ~64 ~42 stone
fill ~345 ~65 ~42 ~347 ~67 ~42 dirt
fill ~345 ~68 ~42 ~347 ~68 ~42 grass_block
fill ~348 ~60 ~42 ~351 ~65 ~42 stone
fill ~348 ~66 ~42 ~351 ~68 ~42 dirt
fill ~348 ~69 ~42 ~351 ~69 ~42 grass_block
fill ~336 ~60 ~43 ~336 ~64 ~43 stone
fill ~336 ~65 ~43 ~336 ~67 ~43 dirt
fill ~336 ~68 ~43 ~336 ~68 ~43 grass_block
fill ~337 ~60 ~43 ~337 ~65 ~43 stone
fill ~337 ~66 ~43 ~337 ~68 ~43 dirt
fill ~337 ~69 ~43 ~337 ~69 ~43 grass_block
fill ~338 ~60 ~43 ~341 ~64 ~43 stone
fill ~338 ~65 ~43 ~341 ~67 ~43 dirt
fill ~338 ~68 ~43 ~341 ~68 ~43 grass_block
fill ~342 ~60 ~43 ~346 ~63 ~43 stone
fill ~342 ~64 ~43 ~346 ~66 ~43 dirt
fill ~342 ~67 ~43 ~346 ~67 ~43 grass_block
fill ~347 ~60 ~43 ~348 ~64 ~43 stone
fill ~347 ~65 ~43 ~348 ~67 ~43 dirt
fill ~347 ~68 ~43 ~348 ~68 ~43 grass_block
fill ~349 ~60 ~43 ~351 ~65 ~43 stone
fill ~349 ~66 ~43 ~351 ~68 ~43 dirt
fill ~349 ~69 ~43 ~351 ~69 ~43 grass_block
fill ~336 ~60 ~44 ~336 ~64 ~44 stone
fill ~336 ~65 ~44 ~336 ~67 ~44 dirt
fill ~336 ~68 ~44 ~336 ~68 ~44 grass_block
fill ~337 ~60 ~44 ~338 ~65 ~44 stone
fill ~337 ~66 ~44 ~338 ~68 ~44 dirt
fill ~337 ~69 ~44 ~338 ~69 ~44 grass_block
fill ~339 ~60 ~44 ~344 ~64 ~44 stone
fill ~339 ~65 ~44 ~344 ~67 ~44 dirt
fill ~339 ~68 ~44 ~344 ~68 ~44 grass_block
fill ~345 ~60 ~44 ~346 ~63 ~44 stone
fill ~345 ~64 ~44 ~346 ~66 ~44 dirt
fill ~345 ~67 ~44 ~346 ~67 ~44 grass_block
fill ~347 ~60 ~44 ~349 ~64 ~44 stone
fill ~347 ~65 ~44 ~349 ~67 ~44 dirt
fill ~347 ~68 ~44 ~349 ~68 ~44 grass_block
fill ~350 ~60 ~44 ~351 ~65 ~44 stone
fill ~350 ~66 ~44 ~351 ~68 ~44 dirt
fill ~350 ~69 ~44 ~351 ~69 ~44 grass_block
fill ~336 ~60 ~45 ~337 ~64 ~45 stone
fill ~336 ~65 ~45 ~337 ~67 ~45 dirt
fill ~336 ~68 ~45 ~337 ~68 ~45 grass_block
fill ~338 ~60 ~45 ~343 ~65 ~45 stone
fill ~338 ~66 ~45 ~343 ~68 ~45 dirt
fill ~338 ~69 ~45 ~343 ~69 ~45 grass_block
fill ~344 ~60 ~45 ~345 ~64 ~45 stone
fill ~344 ~65 ~45 ~345 ~67 ~45 dirt
fill ~344 ~68 ~45 ~345 ~68 ~45 grass_block
fill ~346 ~60 ~45 ~346 ~63 ~45 stone
fill ~346 ~64 ~45 ~346 ~66 ~45 dirt
fill ~346 ~67 ~45 ~346 ~67 ~45 grass_block
fill ~347 ~60 ~45 ~348 ~64 ~45 stone
fill ~347 ~65 ~45 ~348 ~67 ~45 dirt
fill ~347 ~68 ~45 ~348 ~68 ~45 grass_block
fill ~349 ~60 ~45 ~351 ~65 ~45 stone
fill ~349 ~66 ~45 ~351 ~68 ~45 dirt
fill ~349 ~69 ~45 ~351 ~69 ~45 grass_block
fill ~336 ~60 ~46 ~337 ~64 ~46 stone
fill ~336 ~65 ~46 ~337 ~67 ~46 dirt
fill ~336 ~68 ~46 ~337 ~68 ~46 grass_block
fill ~338 ~60 ~46 ~338 ~65 ~46 stone
fill ~338 ~66 ~46 ~338 ~68 ~46 dirt
fill ~338 ~69 ~46 ~338 ~69 ~46 grass_block
fill ~339 ~60 ~46 ~341 ~66 ~46 stone
fill ~339 ~67 ~46 ~341 ~69 ~46 dirt
fill ~339 ~70 ~46 ~341 ~70 ~46 grass_block
fill ~342 ~60 ~46 ~343 ~65 ~46 stone
fill ~342 ~66 ~46 ~343 ~68 ~46 dirt
fill ~342 ~69 ~46 ~343 ~69 ~46 grass_block
fill ~344 ~60 ~46 ~348 ~64 ~46 stone
fill ~344 ~65 ~46 ~348 ~67 ~46 dirt
fill ~344 ~68 ~46 ~348 ~68 ~46 grass_block
fill ~349 ~60 ~46 ~351 ~65 ~46 stone
fill ~349 ~66 ~46 ~351 ~68 ~46 dirt
fill ~349 ~69 ~46 ~351 ~69 ~46 grass_block
fill ~336 ~60 ~47 ~338 ~65 ~47 stone
fill ~336 ~66 ~47 ~338 ~68 ~47 dirt
fill ~336 ~69 ~47 ~338 ~69 ~47 grass_block
fill ~339 ~60 ~47 ~341 ~66 ~47 stone
fill ~339 ~67 ~47 ~341 ~69 ~47 dirt
fill ~339 ~70 ~47 ~341 ~70 ~47 grass_block
fill ~342 ~60 ~47 ~343 ~65 ~47 stone
fill ~342 ~66 ~47 ~343 ~68 ~47 dirt
fill ~342 ~69 ~47 ~343 ~69 ~47 grass_block
fill ~344 ~60 ~47 ~348 ~64 ~47 stone
fill ~344 ~65 ~47 ~348 ~67 ~47 dirt
fill ~344 ~68 ~47 ~348 ~68 ~47 grass_block
fill ~349 ~60 ~47 ~351 ~65 ~47 stone
fill ~349 ~66 ~47 ~351 ~68 ~47 dirt
fill ~349 ~69 ~47 ~351 ~69 ~47 grass_block