fill ~288 ~60 ~80 ~290 ~62 ~80 stone
fill ~288 ~63 ~80 ~290 ~65 ~80 dirt
fill ~288 ~66 ~80 ~290 ~66 ~80 grass_block
fill ~291 ~60 ~80 ~303 ~61 ~80 stone
fill ~291 ~62 ~80 ~303 ~64 ~80 dirt
fill ~291 ~65 ~80 ~303 ~65 ~80 grass_block
fill ~288 ~60 ~81 ~290 ~62 ~81 stone
fill ~288 ~63 ~81 ~290 ~65 ~81 dirt
fill ~288 ~66 ~81 ~290 ~66 ~81 grass_block
fill ~291 ~60 ~81 ~299 ~61 ~81 stone
fill ~291 ~62 ~81 ~299 ~64 ~81 dirt
fill ~291 ~65 ~81 ~299 ~65 ~81 grass_block
fill ~300 ~60 ~81 ~301 ~60 ~81 stone
fill ~300 ~61 ~81 ~301 ~63 ~81 dirt
fill ~300 ~64 ~81 ~301 ~64 ~81 grass_block
fill ~302 ~60 ~81 ~302 ~61 ~81 stone
fill ~302 ~62 ~81 ~302 ~64 ~81 dirt
fill ~302 ~65 ~81 ~302 ~65 ~81 grass_block
fill ~303 ~60 ~81 ~303 ~60 ~81 stone
fill ~303 ~61 ~81 ~303 ~63 ~81 dirt
fill ~303 ~64 ~81 ~303 ~64 ~81 grass_block
fill ~288 ~60 ~82 ~291 ~62 ~82 stone
fill ~288 ~63 ~82 ~291 ~65 ~82 dirt
fill ~288 ~66 ~82 ~291 ~66 ~82 grass_block
fill ~292 ~60 ~82 ~301 ~61 ~82 stone
fill ~292 ~62 ~82 ~301 ~64 ~82 dirt
fill ~292 ~65 ~82 ~301 ~65 ~82 grass_block
fill ~302 ~60 ~82 ~302 ~60 ~82 stone
fill ~302 ~61 ~82 ~302 ~63 ~82 dirt
fill ~302 ~64 ~82 ~302 ~64 ~82 grass_block
fill ~303 ~60 ~82 ~303 ~61 ~82 stone
fill ~303 ~62 ~82 ~303 ~64 ~82 dirt
fill ~303 ~65 ~82 ~303 ~65 ~82 grass_block
fill ~288 ~60 ~83 ~292 ~62 ~83 stone
fill ~288 ~63 ~83 ~292 ~65 ~83 dirt
fill ~288 ~66 ~83 ~292 ~66 ~83 grass_block
fill ~293 ~60 ~83 ~293 ~61 ~83 stone
fill ~293 ~62 ~83 ~293 ~64 ~83 dirt
fill ~293 ~65 ~83 ~293 ~65 ~83 grass_block
fill ~294 ~60 ~83 ~296 ~62 ~83 stone
fill ~294 ~63 ~83 ~296 ~65 ~83 dirt
fill ~294 ~66 ~83 ~296 ~66 ~83 grass_block
fill ~297 ~60 ~83 ~302 ~61 ~83 stone
fill ~297 ~62 ~83 ~302 ~64 ~83 dirt
fill ~297 ~65 ~83 ~302 ~65 ~83 grass_block
fill ~303 ~60 ~83 ~303 ~60 ~83 stone
fill ~303 ~61 ~83 ~303 ~63 ~83 dirt
fill ~303 ~64 ~83 ~303 ~64 ~83 grass_block
fill ~288 ~60 ~84 ~297 ~62 ~84 stone
fill ~288 ~63 ~84 ~297 ~65 ~84 dirt
fill ~288 ~66 ~84 ~297 ~66 ~84 grass_block
fill ~298 ~60 ~84 ~303 ~61 ~84 stone
fill ~298 ~62 ~84 ~303 ~64 ~84 dirt
fill ~298 ~65 ~84 ~303 ~65 ~84 grass_block
fill ~288 ~60 ~85 ~299 ~62 ~85 stone
fill ~288 ~63 ~85 ~299 ~65 ~85 dirt
fill ~288 ~66 ~85 ~299 ~66 ~85 grass_block
fill ~300 ~60 ~85 ~303 ~61 ~85 stone
fill ~300 ~62 ~85 ~303 ~64 ~85 dirt
fill ~300 ~65 ~85 ~303 ~65 ~85 grass_block
fill ~288 ~60 ~86 ~302 ~62 ~86 stone
fill ~288 ~63 ~86 ~302 ~65 ~86 dirt
fill ~288 ~66 ~86 ~302 ~66 ~86 grass_block
fill ~303 ~60 ~86 ~303 ~61 ~86 stone
fill ~303 ~62 ~86 ~303 ~64 ~86 dirt
fill ~303 ~65 ~86 ~303 ~65 ~86 grass_block
fill ~288 ~60 ~87 ~302 ~62 ~87 stone
fill ~288 ~63 ~87 ~302 ~65 ~87 dirt
fill ~288 ~66 ~87 ~302 ~66 ~87 grass_block
fill ~303 ~60 ~87 ~303 ~61 ~87 stone
fill ~303 ~62 ~87 ~303 ~64 ~87 dirt
fill ~303 ~65 ~87 ~303 ~65 ~87 grass_block
fill ~288 ~60 ~88 ~302 ~62 ~88 stone
fill ~288 ~63 ~88 ~302 ~65 ~88 dirt
fill ~288 ~66 ~88 ~302 ~66 ~88 grass_block
fill ~303 ~60 ~88 ~303 ~61 ~88 stone
fill ~303 ~62 ~88 ~303 ~64 ~88 dirt
fill ~303 ~65 ~88 ~303 ~65 ~88 grass_block
fill ~288 ~60 ~89 ~303 ~62 ~89 stone
fill ~288 ~63 ~89 ~303 ~65 ~89 dirt
fill ~288 ~66 ~89 ~303 ~66 ~89 grass_block
fill ~288 ~60 ~90 ~288 ~63 ~90 stone
fill ~288 ~64 ~90 ~288 ~66 ~90 dirt
fill ~288 ~67 ~90 ~288 ~67 ~90 grass_block
fill ~289 ~60 ~90 ~291 ~62 ~90 stone
fill ~289 ~63 ~90 ~291 ~65 ~90 dirt
fill ~289 ~66 ~90 ~291 ~66 ~90 grass_block
fill ~292 ~60 ~90 ~292 ~63 ~90 stone
fill ~292 ~64 ~90 ~292 ~66 ~90 dirt
fill ~292 ~67 ~90 ~292 ~67 ~90 grass_block
fill ~293 ~60 ~90 ~303 ~62 ~90 stone
fill ~293 ~63 ~90 ~303 ~65 ~90 dirt
fill ~293 ~66 ~90 ~303 ~66 ~90 grass_block
fill ~288 ~60 ~91 ~290 ~63 ~91 stone
fill ~288 ~64 ~91 ~290 ~66 ~91 dirt
fill ~288 ~67 ~91 ~290 ~67 ~91 grass_block
fill ~291 ~60 ~91 ~303 ~62 ~91 stone
fill ~291 ~63 ~91 ~303 ~65 ~91 dirt
fill ~291 ~66 ~91 ~303 ~66 ~91 grass_block
fill ~288 ~60 ~92 ~291 ~63 ~92 stone
fill ~288 ~64 ~92 ~291 ~66 ~92 dirt
fill ~288 ~67 ~92 ~291 ~67 ~92 grass_block
fill ~292 ~60 ~92 ~303 ~62 ~92 stone
fill ~292 ~63 ~92 ~303 ~65 ~92 dirt
fill ~292 ~66 ~92 ~303 ~66 ~92 grass_block
fill ~288 ~60 ~93 ~292 ~63 ~93 stone
fill ~288 ~64 ~93 ~292 ~66 ~93 dirt
fill ~288 ~67 ~93 ~292 ~67 ~93 grass_block
fill ~293 ~60 ~93 ~302 ~62 ~93 stone
fill ~293 ~63 ~93 ~302 ~65 ~93 dirt
fill ~293 ~66 ~93 ~302 ~66 ~93 grass_block
fill ~303 ~60 ~93 ~303 ~61 ~93 stone
fill ~303 ~62 ~93 ~303 ~64 ~93 dirt
fill ~303 ~65 ~93 ~303 ~65 ~93 grass_block
fill ~288 ~60 ~94 ~292 ~63 ~94 stone
fill ~288 ~64 ~94 ~292 ~66 ~94 dirt
fill ~288 ~67 ~94 ~292 ~67 ~94 grass_block
fill ~293 ~60 ~94 ~302 ~62 ~94 stone
fill ~293 ~63 ~94 ~302 ~65 ~94 dirt
fill ~293 ~66 ~94 ~302 ~66 ~94 grass_block
fill ~303 ~60 ~94 ~303 ~61 ~94 stone
fill ~303 ~62 ~94 ~303 ~64 ~94 dirt
fill ~303 ~65 ~94 ~303 ~65 ~94 grass_block
fill ~288 ~60 ~95 ~294 ~63 ~95 stone
fill ~288 ~64 ~95 ~294 ~66 ~95 dirt
fill ~288 ~67 ~95 ~294 ~67 ~95 grass_block
fill ~295 ~60 ~95 ~303 ~62 ~95 stone
fill ~295 ~63 ~95 ~303 ~65 ~95 dirt
fill ~295 ~66 ~95 ~303 ~66 ~95 grass_block