fill ~384 ~60 ~32 ~384 ~65 ~32 stone
fill ~384 ~66 ~32 ~384 ~68 ~32 dirt
fill ~384 ~69 ~32 ~384 ~69 ~32 grass_block
fill ~385 ~60 ~32 ~390 ~64 ~32 stone
fill ~385 ~65 ~32 ~390 ~67 ~32 dirt
fill ~385 ~68 ~32 ~390 ~68 ~32 grass_block
fill ~391 ~60 ~32 ~397 ~63 ~32 stone
fill ~391 ~64 ~32 ~397 ~66 ~32 dirt
fill ~391 ~67 ~32 ~397 ~67 ~32 grass_block
fill ~398 ~60 ~32 ~399 ~62 ~32 stone
fill ~398 ~63 ~32 ~399 ~65 ~32 dirt
fill ~398 ~66 ~32 ~399 ~66 ~32 grass_block
fill ~384 ~60 ~33 ~386 ~65 ~33 stone
fill ~384 ~66 ~33 ~386 ~68 ~33 dirt
fill ~384 ~69 ~33 ~386 ~69 ~33 grass_block
fill ~387 ~60 ~33 ~391 ~64 ~33 stone
fill ~387 ~65 ~33 ~391 ~67 ~33 dirt
fill ~387 ~68 ~33 ~391 ~68 ~33 grass_block
fill ~392 ~60 ~33 ~395 ~63 ~33 stone
fill ~392 ~64 ~33 ~395 ~66 ~33 dirt
fill ~392 ~67 ~33 ~395 ~67 ~33 grass_block
fill ~396 ~60 ~33 ~399 ~62 ~33 stone
fill ~396 ~63 ~33 ~399 ~65 ~33 dirt
fill ~396 ~66 ~33 ~399 ~66 ~33 grass_block
fill ~384 ~60 ~34 ~384 ~66 ~34 stone
fill ~384 ~67 ~34 ~384 ~69 ~34 dirt
fill ~384 ~70 ~34 ~384 ~70 ~34 grass_block
fill ~385 ~60 ~34 ~388 ~65 ~34 stone
fill ~385 ~66 ~34 ~388 ~68 ~34 dirt
fill ~385 ~69 ~34 ~388 ~69 ~34 grass_block
fill ~389 ~60 ~34 ~394 ~64 ~34 stone
fill ~389 ~65 ~34 ~394 ~67 ~34 dirt
fill ~389 ~68 ~34 ~394 ~68 ~34 grass_block
fill ~395 ~60 ~34 ~396 ~63 ~34 stone
fill ~395 ~64 ~34 ~396 ~66 ~34 dirt
fill ~395 ~67 ~34 ~396 ~67 ~34 grass_block
fill ~397 ~60 ~34 ~399 ~62 ~34 stone
fill ~397 ~63 ~34 ~399 ~65 ~34 dirt
fill ~397 ~66 ~34 ~399 ~66 ~34 grass_block
fill ~384 ~60 ~35 ~385 ~66 ~35 stone
fill ~384 ~67 ~35 ~385 ~69 ~35 dirt
fill ~384 ~70 ~35 ~385 ~70 ~35 grass_block
fill ~386 ~60 ~35 ~390 ~65 ~35 stone
fill ~386 ~66 ~35 ~390 ~68 ~35 dirt
fill ~386 ~69 ~35 ~390 ~69 ~35 grass_block
fill ~391 ~60 ~35 ~394 ~64 ~35 stone
fill ~391 ~65 ~35 ~394 ~67 ~35 dirt
fill ~391 ~68 ~35 ~394 ~68 ~35 grass_block
fill ~395 ~60 ~35 ~396 ~63 ~35 stone
fill ~395 ~64 ~35 ~396 ~66 ~35 dirt
fill ~395 ~67 ~35 ~396 ~67 ~35 grass_block
fill ~397 ~60 ~35 ~398 ~62 ~35 stone
fill ~397 ~63 ~35 ~398 ~65 ~35 dirt
fill ~397 ~66 ~35 ~398 ~66 ~35 grass_block
fill ~399 ~60 ~35 ~399 ~63 ~35 stone
fill ~399 ~64 ~35 ~399 ~66 ~35 dirt
fill ~399 ~67 ~35 ~399 ~67 ~35 grass_block
fill ~384 ~60 ~36 ~386 ~66 ~36 stone
fill ~384 ~67 ~36 ~386 ~69 ~36 dirt
fill ~384 ~70 ~36 ~386 ~70 ~36 grass_block
fill ~387 ~60 ~36 ~391 ~65 ~36 stone
fill ~387 ~66 ~36 ~391 ~68 ~36 dirt
fill ~387 ~69 ~36 ~391 ~69 ~36 grass_block
fill ~392 ~60 ~36 ~394 ~64 ~36 stone
fill ~392 ~65 ~36 ~394 ~67 ~36 dirt
fill ~392 ~68 ~36 ~394 ~68 ~36 grass_block
fill ~395 ~60 ~36 ~399 ~63 ~36 stone
fill ~395 ~64 ~36 ~399 ~66 ~36 dirt
fill ~395 ~67 ~36 ~399 ~67 ~36 grass_block
fill ~384 ~60 ~37 ~387 ~66 ~37 stone
fill ~384 ~67 ~37 ~387 ~69 ~37 dirt
fill ~384 ~70 ~37 ~387 ~70 ~37 grass_block
fill ~388 ~60 ~37 ~390 ~65 ~37 stone
fill ~388 ~66 ~37 ~390 ~68 ~37 dirt
fill ~388 ~69 ~37 ~390 ~69 ~37 grass_block
fill ~391 ~60 ~37 ~394 ~64 ~37 stone
fill ~391 ~65 ~37 ~394 ~67 ~37 dirt
fill ~391 ~68 ~37 ~394 ~68 ~37 grass_block
fill ~395 ~60 ~37 ~399 ~63 ~37 stone
fill ~395 ~64 ~37 ~399 ~66 ~37 dirt
fill ~395 ~67 ~37 ~399 ~67 ~37 grass_block
fill ~384 ~60 ~38 ~384 ~65 ~38 stone
fill ~384 ~66 ~38 ~384 ~68 ~38 dirt
fill ~384 ~69 ~38 ~384 ~69 ~38 grass_block
fill ~385 ~60 ~38 ~388 ~66 ~38 stone
fill ~385 ~67 ~38 ~388 ~69 ~38 dirt
fill ~385 ~70 ~38 ~388 ~70 ~38 grass_block
fill ~389 ~60 ~38 ~392 ~65 ~38 stone
fill ~389 ~66 ~38 ~392 ~68 ~38 dirt
fill ~389 ~69 ~38 ~392 ~69 ~38 grass_block
fill ~393 ~60 ~38 ~394 ~64 ~38 stone
fill ~393 ~65 ~38 ~394 ~67 ~38 dirt
fill ~393 ~68 ~38 ~394 ~68 ~38 grass_block
fill ~395 ~60 ~38 ~399 ~63 ~38 stone
fill ~395 ~64 ~38 ~399 ~66 ~38 dirt
fill ~395 ~67 ~38 ~399 ~67 ~38 grass_block
fill ~384 ~60 ~39 ~385 ~65 ~39 stone
fill ~384 ~66 ~39 ~385 ~68 ~39 dirt
fill ~384 ~69 ~39 ~385 ~69 ~39 grass_block
fill ~386 ~60 ~39 ~389 ~66 ~39 stone
fill ~386 ~67 ~39 ~389 ~69 ~39 dirt
fill ~386 ~70 ~39 ~389 ~70 ~39 grass_block
fill ~390 ~60 ~39 ~392 ~65 ~39 stone
fill ~390 ~66 ~39 ~392 ~68 ~39 dirt
fill ~390 ~69 ~39 ~392 ~69 ~39 grass_block
fill ~393 ~60 ~39 ~394 ~64 ~39 stone
fill ~393 ~65 ~39 ~394 ~67 ~39 dirt
fill ~393 ~68 ~39 ~394 ~68 ~39 grass_block
fill ~395 ~60 ~39 ~397 ~63 ~39 stone
fill ~395 ~64 ~39 ~397 ~66 ~39 dirt
fill ~395 ~67 ~39 ~397 ~67 ~39 grass_block
fill ~398 ~60 ~39 ~399 ~64 ~39 stone
fill ~398 ~65 ~39 ~399 ~67 ~39 dirt
fill ~398 ~68 ~39 ~399 ~68 ~39 grass_block
fill ~384 ~60 ~40 ~386 ~65 ~40 stone
fill ~384 ~66 ~40 ~386 ~68 ~40 dirt
fill ~384 ~69 ~40 ~386 ~69 ~40 grass_block
fill ~387 ~60 ~40 ~388 ~66 ~40 stone
fill ~387 ~67 ~40 ~388 ~69 ~40 dirt
fill ~387 ~70 ~40 ~388 ~70 ~40 grass_block
fill ~389 ~60 ~40 ~391 ~65 ~40 stone
fill ~389 ~66 ~40 ~391 ~68 ~40 dirt
fill ~389 ~69 ~40 ~391 ~69 ~40 grass_block
fill ~392 ~60 ~40 ~394 ~64 ~40 stone
fill ~392 ~65 ~40 ~394 ~67 ~40 dirt
fill ~392 ~68 ~40 ~394 ~68 ~40 grass_block
fill ~395 ~60 ~40 ~396 ~63 ~40 stone
fill ~395 ~64 ~40 ~396 ~66 ~40 dirt
fill ~395 ~67 ~40 ~396 ~67 ~40 grass_block
fill ~397 ~60 ~40 ~397 ~64 ~40 stone
fill ~397 ~65 ~40 ~397 ~67 ~40 dirt
fill ~397 ~68 ~40 ~397 ~68 ~40 grass_block
fill ~398 ~60 ~40 ~398 ~65 ~40 stone
fill ~398 ~66 ~40 ~398 ~68 ~40 dirt
fill ~398 ~69 ~40 ~398 ~69 ~40 grass_block
fill ~399 ~60 ~40 ~399 ~64 ~40 stone
fill ~399 ~65 ~40 ~399 ~67 ~40 dirt
fill ~399 ~68 ~40 ~399 ~68 ~40 grass_block
fill ~384 ~60 ~41 ~387 ~65 ~41 stone
fill ~384 ~66 ~41 ~387 ~68 ~41 dirt
fill ~384 ~69 ~41 ~387 ~69 ~41 grass_block
fill ~388 ~60 ~41 ~389 ~66 ~41 stone
fill ~388 ~67 ~41 ~389 ~69 ~41 dirt
fill ~388 ~70 ~41 ~389 ~70 ~41 grass_block
fill ~390 ~60 ~41 ~392 ~65 ~41 stone
fill ~390 ~66 ~41 ~392 ~68 ~41 dirt
fill ~390 ~69 ~41 ~392 ~69 ~41 grass_block
fill ~393 ~60 ~41 ~397 ~64 ~41 stone
fill ~393 ~65 ~41 ~397 ~67 ~41 dirt
fill ~393 ~68 ~41 ~397 ~68 ~41 grass_block
fill ~398 ~60 ~41 ~399 ~65 ~41 stone
fill ~398 ~66 ~41 ~399 ~68 ~41 dirt
fill ~398 ~69 ~41 ~399 ~69 ~41 grass_block
fill ~384 ~60 ~42 ~384 ~64 ~42 stone
fill ~384 ~65 ~42 ~384 ~67 ~42 dirt
fill ~384 ~68 ~42 ~384 ~68 ~42 grass_block
fill ~385 ~60 ~42 ~387 ~65 ~42 stone
fill ~385 ~66 ~42 ~387 ~68 ~42 dirt
fill ~385 ~69 ~42 ~387 ~69 ~42 grass_block
fill ~388 ~60 ~42 ~391 ~66 ~42 stone
fill ~388 ~67 ~42 ~391 ~69 ~42 dirt
fill ~388 ~70 ~42 ~391 ~70 ~42 grass_block
fill ~392 ~60 ~42 ~395 ~65 ~42 stone
fill ~392 ~66 ~42 ~395 ~68 ~42 dirt
fill ~392 ~69 ~42 ~395 ~69 ~42 grass_block
fill ~396 ~60 ~42 ~396 ~64 ~42 stone
fill ~396 ~65 ~42 ~396 ~67 ~42 dirt
fill ~396 ~68 ~42 ~396 ~68 ~42 grass_block
fill ~397 ~60 ~42 ~399 ~65 ~42 stone
fill ~397 ~66 ~42 ~399 ~68 ~42 dirt
fill ~397 ~69 ~42 ~399 ~69 ~42 grass_block
fill ~384 ~60 ~43 ~384 ~64 ~43 stone
fill ~384 ~65 ~43 ~384 ~67 ~43 dirt
fill ~384 ~68 ~43 ~384 ~68 ~43 grass_block
fill ~385 ~60 ~43 ~388 ~65 ~43 stone
fill ~385 ~66 ~43 ~388 ~68 ~43 dirt
fill ~385 ~69 ~43 ~388 ~69 ~43 grass_block
fill ~389 ~60 ~43 ~393 ~66 ~43 stone
fill ~389 ~67 ~43 ~393 ~69 ~43 dirt
fill ~389 ~70 ~43 ~393 ~70 ~43 grass_block
fill ~394 ~60 ~43 ~397 ~65 ~43 stone
fill ~394 ~66 ~43 ~397 ~68 ~43 dirt
fill ~394 ~69 ~43 ~397 ~69 ~43 grass_block
fill ~398 ~60 ~43 ~399 ~66 ~43 stone
fill ~398 ~67 ~43 ~399 ~69 ~43 dirt
fill ~398 ~70 ~43 ~399 ~70 ~43 grass_block
fill ~384 ~60 ~44 ~385 ~64 ~44 stone
fill ~384 ~65 ~44 ~385 ~67 ~44 dirt
fill ~384 ~68 ~44 ~385 ~68 ~44 grass_block
fill ~386 ~60 ~44 ~388 ~65 ~44 stone
fill ~386 ~66 ~44 ~388 ~68 ~44 dirt
fill ~386 ~69 ~44 ~388 ~69 ~44 grass_block
fill ~389 ~60 ~44 ~395 ~66 ~44 stone
fill ~389 ~67 ~44 ~395 ~69 ~44 dirt
fill ~389 ~70 ~44 ~395 ~70 ~44 grass_block
fill ~396 ~60 ~44 ~396 ~65 ~44 stone
fill ~396 ~66 ~44 ~396 ~68 ~44 dirt
fill ~396 ~69 ~44 ~396 ~69 ~44 grass_block
fill ~397 ~60 ~44 ~399 ~66 ~44 stone
fill ~397 ~67 ~44 ~399 ~69 ~44 dirt
fill ~397 ~70 ~44 ~399 ~70 ~44 grass_block
fill ~384 ~60 ~45 ~384 ~64 ~45 stone
fill ~384 ~65 ~45 ~384 ~67 ~45 dirt
fill ~384 ~68 ~45 ~384 ~68 ~45 grass_block
fill ~385 ~60 ~45 ~388 ~65 ~45 stone
fill ~385 ~66 ~45 ~388 ~68 ~45 dirt
fill ~385 ~69 ~45 ~388 ~69 ~45 grass_block
fill ~389 ~60 ~45 ~399 ~66 ~45 stone
fill ~389 ~67 ~45 ~399 ~69 ~45 dirt
fill ~389 ~70 ~45 ~399 ~70 ~45 grass_block
fill ~384 ~60 ~46 ~385 ~64 ~46 stone
fill ~384 ~65 ~46 ~385 ~67 ~46 dirt
fill ~384 ~68 ~46 ~385 ~68 ~46 grass_block
fill ~386 ~60 ~46 ~389 ~65 ~46 stone
fill ~386 ~66 ~46 ~389 ~68 ~46 dirt
fill ~386 ~69 ~46 ~389 ~69 ~46 grass_block
fill ~390 ~60 ~46 ~399 ~66 ~46 stone
fill ~390 ~67 ~46 ~399 ~69 ~46 dirt
fill ~390 ~70 ~46 ~399 ~70 ~46 grass_block
fill ~384 ~60 ~47 ~385 ~64 ~47 stone
fill ~384 ~65 ~47 ~385 ~67 ~47 dirt
fill ~384 ~68 ~47 ~385 ~68 ~47 grass_block
fill ~386 ~60 ~47 ~390 ~65 ~47 stone
fill ~386 ~66 ~47 ~390 ~68 ~47 dirt
fill ~386 ~69 ~47 ~390 ~69 ~47 grass_block
fill ~391 ~60 ~47 ~392 ~66 ~47 stone
fill ~391 ~67 ~47 ~392 ~69 ~47 dirt
fill ~391 ~70 ~47 ~392 ~70 ~47 grass_block
fill ~393 ~60 ~47 ~393 ~65 ~47 stone
fill ~393 ~66 ~47 ~393 ~68 ~47 dirt
fill ~393 ~69 ~47 ~393 ~69 ~47 grass_block
fill ~394 ~60 ~47 ~395 ~66 ~47 stone
fill ~394 ~67 ~47 ~395 ~69 ~47 dirt
fill ~394 ~70 ~47 ~395 ~70 ~47 grass_block
fill ~396 ~60 ~47 ~396 ~65 ~47 stone
fill ~396 ~66 ~47 ~396 ~68 ~47 dirt
fill ~396 ~69 ~47 ~396 ~69 ~47 grass_block
fill ~397 ~60 ~47 ~399 ~66 ~47 stone
fill ~397 ~67 ~47 ~399 ~69 ~47 dirt
fill ~397 ~70 ~47 ~399 ~70 ~47 grass_block