fill ~432 ~60 ~128 ~433 ~63 ~128 stone
fill ~432 ~64 ~128 ~433 ~66 ~128 dirt
fill ~432 ~67 ~128 ~433 ~67 ~128 grass_block
fill ~434 ~60 ~128 ~443 ~64 ~128 stone
fill ~434 ~65 ~128 ~443 ~67 ~128 dirt
fill ~434 ~68 ~128 ~443 ~68 ~128 grass_block
fill ~444 ~60 ~128 ~447 ~63 ~128 stone
fill ~444 ~64 ~128 ~447 ~66 ~128 dirt
fill ~444 ~67 ~128 ~447 ~67 ~128 grass_block
fill ~432 ~60 ~129 ~434 ~63 ~129 stone
fill ~432 ~64 ~129 ~434 ~66 ~129 dirt
fill ~432 ~67 ~129 ~434 ~67 ~129 grass_block
fill ~435 ~60 ~129 ~442 ~64 ~129 stone
fill ~435 ~65 ~129 ~442 ~67 ~129 dirt
fill ~435 ~68 ~129 ~442 ~68 ~129 grass_block
fill ~443 ~60 ~129 ~447 ~63 ~129 stone
fill ~443 ~64 ~129 ~447 ~66 ~129 dirt
fill ~443 ~67 ~129 ~447 ~67 ~129 grass_block
fill ~432 ~60 ~130 ~435 ~63 ~130 stone
fill ~432 ~64 ~130 ~435 ~66 ~130 dirt
fill ~432 ~67 ~130 ~435 ~67 ~130 grass_block
fill ~436 ~60 ~130 ~440 ~64 ~130 stone
fill ~436 ~65 ~130 ~440 ~67 ~130 dirt
fill ~436 ~68 ~130 ~440 ~68 ~130 grass_block
fill ~441 ~60 ~130 ~447 ~63 ~130 stone
fill ~441 ~64 ~130 ~447 ~66 ~130 dirt
fill ~441 ~67 ~130 ~447 ~67 ~130 grass_block
fill ~432 ~60 ~131 ~432 ~62 ~131 stone
fill ~432 ~63 ~131 ~432 ~65 ~131 dirt
fill ~432 ~66 ~131 ~432 ~66 ~131 grass_block
fill ~433 ~60 ~131 ~435 ~63 ~131 stone
fill ~433 ~64 ~131 ~435 ~66 ~131 dirt
fill ~433 ~67 ~131 ~435 ~67 ~131 grass_block
fill ~436 ~60 ~131 ~440 ~64 ~131 stone
fill ~436 ~65 ~131 ~440 ~67 ~131 dirt
fill ~436 ~68 ~131 ~440 ~68 ~131 grass_block
fill ~441 ~60 ~131 ~447 ~63 ~131 stone
fill ~441 ~64 ~131 ~447 ~66 ~131 dirt
fill ~441 ~67 ~131 ~447 ~67 ~131 grass_block
fill ~432 ~60 ~132 ~433 ~62 ~132 stone
fill ~432 ~63 ~132 ~433 ~65 ~132 dirt
fill ~432 ~66 ~132 ~433 ~66 ~132 grass_block
fill ~434 ~60 ~132 ~437 ~63 ~132 stone
fill ~434 ~64 ~132 ~437 ~66 ~132 dirt
fill ~434 ~67 ~132 ~437 ~67 ~132 grass_block
fill ~438 ~60 ~132 ~439 ~64 ~132 stone
fill ~438 ~65 ~132 ~439 ~67 ~132 dirt
fill ~438 ~68 ~132 ~439 ~68 ~132 grass_block
fill ~440 ~60 ~132 ~447 ~63 ~132 stone
fill ~440 ~64 ~132 ~447 ~66 ~132 dirt
fill ~440 ~67 ~132 ~447 ~67 ~132 grass_block
fill ~432 ~60 ~133 ~434 ~62 ~133 stone
fill ~432 ~63 ~133 ~434 ~65 ~133 dirt
fill ~432 ~66 ~133 ~434 ~66 ~133 grass_block
fill ~435 ~60 ~133 ~446 ~63 ~133 stone
fill ~435 ~64 ~133 ~446 ~66 ~133 dirt
fill ~435 ~67 ~133 ~446 ~67 ~133 grass_block
fill ~447 ~60 ~133 ~447 ~62 ~133 stone
fill ~447 ~63 ~133 ~447 ~65 ~133 dirt
fill ~447 ~66 ~133 ~447 ~66 ~133 grass_block
fill ~432 ~60 ~134 ~435 ~62 ~134 stone
fill ~432 ~63 ~134 ~435 ~65 ~134 dirt
fill ~432 ~66 ~134 ~435 ~66 ~134 grass_block
fill ~436 ~60 ~134 ~445 ~63 ~134 stone
fill ~436 ~64 ~134 ~445 ~66 ~134 dirt
fill ~436 ~67 ~134 ~445 ~67 ~134 grass_block
fill ~446 ~60 ~134 ~447 ~62 ~134 stone
fill ~446 ~63 ~134 ~447 ~65 ~134 dirt
fill ~446 ~66 ~134 ~447 ~66 ~134 grass_block
fill ~432 ~60 ~135 ~436 ~62 ~135 stone
fill ~432 ~63 ~135 ~436 ~65 ~135 dirt
fill ~432 ~66 ~135 ~436 ~66 ~135 grass_block
fill ~437 ~60 ~135 ~444 ~63 ~135 stone
fill ~437 ~64 ~135 ~444 ~66 ~135 dirt
fill ~437 ~67 ~135 ~444 ~67 ~135 grass_block
fill ~445 ~60 ~135 ~447 ~62 ~135 stone
fill ~445 ~63 ~135 ~447 ~65 ~135 dirt
fill ~445 ~66 ~135 ~447 ~66 ~135 grass_block
fill ~432 ~60 ~136 ~432 ~61 ~136 stone
fill ~432 ~62 ~136 ~432 ~64 ~136 dirt
fill ~432 ~65 ~136 ~432 ~65 ~136 grass_block
fill ~433 ~60 ~136 ~438 ~62 ~136 stone
fill ~433 ~63 ~136 ~438 ~65 ~136 dirt
fill ~433 ~66 ~136 ~438 ~66 ~136 grass_block
fill ~439 ~60 ~136 ~444 ~63 ~136 stone
fill ~439 ~64 ~136 ~444 ~66 ~136 dirt
fill ~439 ~67 ~136 ~444 ~67 ~136 grass_block
fill ~445 ~60 ~136 ~447 ~62 ~136 stone
fill ~445 ~63 ~136 ~447 ~65 ~136 dirt
fill ~445 ~66 ~136 ~447 ~66 ~136 grass_block
fill ~432 ~60 ~137 ~432 ~61 ~137 stone
fill ~432 ~62 ~137 ~432 ~64 ~137 dirt
fill ~432 ~65 ~137 ~432 ~65 ~137 grass_block
fill ~433 ~60 ~137 ~447 ~62 ~137 stone
fill ~433 ~63 ~137 ~447 ~65 ~137 dirt
fill ~433 ~66 ~137 ~447 ~66 ~137 grass_block
fill ~432 ~60 ~138 ~434 ~61 ~138 stone
fill ~432 ~62 ~138 ~434 ~64 ~138 dirt
fill ~432 ~65 ~138 ~434 ~65 ~138 grass_block
fill ~435 ~60 ~138 ~447 ~62 ~138 stone
fill ~435 ~63 ~138 ~447 ~65 ~138 dirt
fill ~435 ~66 ~138 ~447 ~66 ~138 grass_block
fill ~432 ~60 ~139 ~444 ~61 ~139 stone
fill ~432 ~62 ~139 ~444 ~64 ~139 dirt
fill ~432 ~65 ~139 ~444 ~65 ~139 grass_block
fill ~445 ~60 ~139 ~447 ~62 ~139 stone
fill ~445 ~63 ~139 ~447 ~65 ~139 dirt
fill ~445 ~66 ~139 ~447 ~66 ~139 grass_block
fill ~432 ~60 ~140 ~447 ~61 ~140 stone
fill ~432 ~62 ~140 ~447 ~64 ~140 dirt
fill ~432 ~65 ~140 ~447 ~65 ~140 grass_block
fill ~432 ~60 ~141 ~445 ~60 ~141 stone
fill ~432 ~61 ~141 ~445 ~63 ~141 dirt
fill ~432 ~64 ~141 ~445 ~64 ~141 grass_block
fill ~446 ~60 ~141 ~447 ~61 ~141 stone
fill ~446 ~62 ~141 ~447 ~64 ~141 dirt
fill ~446 ~65 ~141 ~447 ~65 ~141 grass_block
fill ~432 ~60 ~142 ~447 ~60 ~142 stone
fill ~432 ~61 ~142 ~447 ~63 ~142 dirt
fill ~432 ~64 ~142 ~447 ~64 ~142 grass_block
fill ~432 ~60 ~143 ~447 ~60 ~143 stone
fill ~432 ~61 ~143 ~447 ~63 ~143 dirt
fill ~432 ~64 ~143 ~447 ~64 ~143 grass_block