fill ~176 ~60 ~16 ~182 ~62 ~16 stone
fill ~176 ~63 ~16 ~182 ~65 ~16 dirt
fill ~176 ~66 ~16 ~182 ~66 ~16 grass_block
fill ~183 ~60 ~16 ~183 ~63 ~16 stone
fill ~183 ~64 ~16 ~183 ~66 ~16 dirt
fill ~183 ~67 ~16 ~183 ~67 ~16 grass_block
fill ~184 ~60 ~16 ~186 ~62 ~16 stone
fill ~184 ~63 ~16 ~186 ~65 ~16 dirt
fill ~184 ~66 ~16 ~186 ~66 ~16 grass_block
fill ~187 ~60 ~16 ~191 ~61 ~16 stone
fill ~187 ~62 ~16 ~191 ~64 ~16 dirt
fill ~187 ~65 ~16 ~191 ~65 ~16 grass_block
fill ~176 ~60 ~17 ~179 ~62 ~17 stone
fill ~176 ~63 ~17 ~179 ~65 ~17 dirt
fill ~176 ~66 ~17 ~179 ~66 ~17 grass_block
fill ~180 ~60 ~17 ~181 ~61 ~17 stone
fill ~180 ~62 ~17 ~181 ~64 ~17 dirt
fill ~180 ~65 ~17 ~181 ~65 ~17 grass_block
fill ~182 ~60 ~17 ~183 ~62 ~17 stone
fill ~182 ~63 ~17 ~183 ~65 ~17 dirt
fill ~182 ~66 ~17 ~183 ~66 ~17 grass_block
fill ~184 ~60 ~17 ~184 ~63 ~17 stone
fill ~184 ~64 ~17 ~184 ~66 ~17 dirt
fill ~184 ~67 ~17 ~184 ~67 ~17 grass_block
fill ~185 ~60 ~17 ~187 ~62 ~17 stone
fill ~185 ~63 ~17 ~187 ~65 ~17 dirt
fill ~185 ~66 ~17 ~187 ~66 ~17 grass_block
fill ~188 ~60 ~17 ~191 ~61 ~17 stone
fill ~188 ~62 ~17 ~191 ~64 ~17 dirt
fill ~188 ~65 ~17 ~191 ~65 ~17 grass_block
fill ~176 ~60 ~18 ~179 ~62 ~18 stone
fill ~176 ~63 ~18 ~179 ~65 ~18 dirt
fill ~176 ~66 ~18 ~179 ~66 ~18 grass_block
fill ~180 ~60 ~18 ~180 ~61 ~18 stone
fill ~180 ~62 ~18 ~180 ~64 ~18 dirt
fill ~180 ~65 ~18 ~180 ~65 ~18 grass_block
fill ~181 ~60 ~18 ~181 ~60 ~18 stone
fill ~181 ~61 ~18 ~181 ~63 ~18 dirt
fill ~181 ~64 ~18 ~181 ~64 ~18 grass_block
fill ~182 ~60 ~18 ~182 ~61 ~18 stone
fill ~182 ~62 ~18 ~182 ~64 ~18 dirt
fill ~182 ~65 ~18 ~182 ~65 ~18 grass_block
fill ~183 ~60 ~18 ~183 ~62 ~18 stone
fill ~183 ~63 ~18 ~183 ~65 ~18 dirt
fill ~183 ~66 ~18 ~183 ~66 ~18 grass_block
fill ~184 ~60 ~18 ~185 ~63 ~18 stone
fill ~184 ~64 ~18 ~185 ~66 ~18 dirt
fill ~184 ~67 ~18 ~185 ~67 ~18 grass_block
fill ~186 ~60 ~18 ~188 ~62 ~18 stone
fill ~186 ~63 ~18 ~188 ~65 ~18 dirt
fill ~186 ~66 ~18 ~188 ~66 ~18 grass_block
fill ~189 ~60 ~18 ~191 ~61 ~18 stone
fill ~189 ~62 ~18 ~191 ~64 ~18 dirt
fill ~189 ~65 ~18 ~191 ~65 ~18 grass_block
fill ~176 ~60 ~19 ~180 ~62 ~19 stone
fill ~176 ~63 ~19 ~180 ~65 ~19 dirt
fill ~176 ~66 ~19 ~180 ~66 ~19 grass_block
fill ~181 ~60 ~19 ~183 ~61 ~19 stone
fill ~181 ~62 ~19 ~183 ~64 ~19 dirt
fill ~181 ~65 ~19 ~183 ~65 ~19 grass_block
fill ~184 ~60 ~19 ~184 ~62 ~19 stone
fill ~184 ~63 ~19 ~184 ~65 ~19 dirt
fill ~184 ~66 ~19 ~184 ~66 ~19 grass_block
fill ~185 ~60 ~19 ~186 ~63 ~19 stone
fill ~185 ~64 ~19 ~186 ~66 ~19 dirt
fill ~185 ~67 ~19 ~186 ~67 ~19 grass_block
fill ~187 ~60 ~19 ~190 ~62 ~19 stone
fill ~187 ~63 ~19 ~190 ~65 ~19 dirt
fill ~187 ~66 ~19 ~190 ~66 ~19 grass_block
fill ~191 ~60 ~19 ~191 ~61 ~19 stone
fill ~191 ~62 ~19 ~191 ~64 ~19 dirt
fill ~191 ~65 ~19 ~191 ~65 ~19 grass_block
fill ~176 ~60 ~20 ~181 ~62 ~20 stone
fill ~176 ~63 ~20 ~181 ~65 ~20 dirt
fill ~176 ~66 ~20 ~181 ~66 ~20 grass_block
fill ~182 ~60 ~20 ~183 ~61 ~20 stone
fill ~182 ~62 ~20 ~183 ~64 ~20 dirt
fill ~182 ~65 ~20 ~183 ~65 ~20 grass_block
fill ~184 ~60 ~20 ~185 ~62 ~20 stone
fill ~184 ~63 ~20 ~185 ~65 ~20 dirt
fill ~184 ~66 ~20 ~185 ~66 ~20 grass_block
fill ~186 ~60 ~20 ~187 ~63 ~20 stone
fill ~186 ~64 ~20 ~187 ~66 ~20 dirt
fill ~186 ~67 ~20 ~187 ~67 ~20 grass_block
fill ~188 ~60 ~20 ~191 ~62 ~20 stone
fill ~188 ~63 ~20 ~191 ~65 ~20 dirt
fill ~188 ~66 ~20 ~191 ~66 ~20 grass_block
fill ~176 ~60 ~21 ~182 ~62 ~21 stone
fill ~176 ~63 ~21 ~182 ~65 ~21 dirt
fill ~176 ~66 ~21 ~182 ~66 ~21 grass_block
fill ~183 ~60 ~21 ~183 ~61 ~21 stone
fill ~183 ~62 ~21 ~183 ~64 ~21 dirt
fill ~183 ~65 ~21 ~183 ~65 ~21 grass_block
fill ~184 ~60 ~21 ~186 ~62 ~21 stone
fill ~184 ~63 ~21 ~186 ~65 ~21 dirt
fill ~184 ~66 ~21 ~186 ~66 ~21 grass_block
fill ~187 ~60 ~21 ~189 ~63 ~21 stone
fill ~187 ~64 ~21 ~189 ~66 ~21 dirt
fill ~187 ~67 ~21 ~189 ~67 ~21 grass_block
fill ~190 ~60 ~21 ~191 ~62 ~21 stone
fill ~190 ~63 ~21 ~191 ~65 ~21 dirt
fill ~190 ~66 ~21 ~191 ~66 ~21 grass_block
fill ~176 ~60 ~22 ~187 ~62 ~22 stone
fill ~176 ~63 ~22 ~187 ~65 ~22 dirt
fill ~176 ~66 ~22 ~187 ~66 ~22 grass_block
fill ~188 ~60 ~22 ~190 ~63 ~22 stone
fill ~188 ~64 ~22 ~190 ~66 ~22 dirt
fill ~188 ~67 ~22 ~190 ~67 ~22 grass_block
fill ~191 ~60 ~22 ~191 ~62 ~22 stone
fill ~191 ~63 ~22 ~191 ~65 ~22 dirt
fill ~191 ~66 ~22 ~191 ~66 ~22 grass_block
fill ~176 ~60 ~23 ~179 ~63 ~23 stone
fill ~176 ~64 ~23 ~179 ~66 ~23 dirt
fill ~176 ~67 ~23 ~179 ~67 ~23 grass_block
fill ~180 ~60 ~23 ~185 ~62 ~23 stone
fill ~180 ~63 ~23 ~185 ~65 ~23 dirt
fill ~180 ~66 ~23 ~185 ~66 ~23 grass_block
fill ~186 ~60 ~23 ~191 ~63 ~23 stone
fill ~186 ~64 ~23 ~191 ~66 ~23 dirt
fill ~186 ~67 ~23 ~191 ~67 ~23 grass_block
fill ~176 ~60 ~24 ~191 ~63 ~24 stone
fill ~176 ~64 ~24 ~191 ~66 ~24 dirt
fill ~176 ~67 ~24 ~191 ~67 ~24 grass_block
fill ~176 ~60 ~25 ~181 ~64 ~25 stone
fill ~176 ~65 ~25 ~181 ~67 ~25 dirt
fill ~176 ~68 ~25 ~181 ~68 ~25 grass_block
fill ~182 ~60 ~25 ~182 ~63 ~25 stone
fill ~182 ~64 ~25 ~182 ~66 ~25 dirt
fill ~182 ~67 ~25 ~182 ~67 ~25 grass_block
fill ~183 ~60 ~25 ~183 ~64 ~25 stone
fill ~183 ~65 ~25 ~183 ~67 ~25 dirt
fill ~183 ~68 ~25 ~183 ~68 ~25 grass_block
fill ~184 ~60 ~25 ~184 ~63 ~25 stone
fill ~184 ~64 ~25 ~184 ~66 ~25 dirt
fill ~184 ~67 ~25 ~184 ~67 ~25 grass_block
fill ~185 ~60 ~25 ~187 ~64 ~25 stone
fill ~185 ~65 ~25 ~187 ~67 ~25 dirt
fill ~185 ~68 ~25 ~187 ~68 ~25 grass_block
fill ~188 ~60 ~25 ~191 ~63 ~25 stone
fill ~188 ~64 ~25 ~191 ~66 ~25 dirt
fill ~188 ~67 ~25 ~191 ~67 ~25 grass_block
fill ~176 ~60 ~26 ~182 ~65 ~26 stone
fill ~176 ~66 ~26 ~182 ~68 ~26 dirt
fill ~176 ~69 ~26 ~182 ~69 ~26 grass_block
fill ~183 ~60 ~26 ~188 ~64 ~26 stone
fill ~183 ~65 ~26 ~188 ~67 ~26 dirt
fill ~183 ~68 ~26 ~188 ~68 ~26 grass_block
fill ~189 ~60 ~26 ~191 ~63 ~26 stone
fill ~189 ~64 ~26 ~191 ~66 ~26 dirt
fill ~189 ~67 ~26 ~191 ~67 ~26 grass_block
fill ~176 ~60 ~27 ~176 ~65 ~27 stone
fill ~176 ~66 ~27 ~176 ~68 ~27 dirt
fill ~176 ~69 ~27 ~176 ~69 ~27 grass_block
fill ~177 ~60 ~27 ~180 ~66 ~27 stone
fill ~177 ~67 ~27 ~180 ~69 ~27 dirt
fill ~177 ~70 ~27 ~180 ~70 ~27 grass_block
fill ~181 ~60 ~27 ~183 ~65 ~27 stone
fill ~181 ~66 ~27 ~183 ~68 ~27 dirt
fill ~181 ~69 ~27 ~183 ~69 ~27 grass_block
fill ~184 ~60 ~27 ~189 ~64 ~27 stone
fill ~184 ~65 ~27 ~189 ~67 ~27 dirt
fill ~184 ~68 ~27 ~189 ~68 ~27 grass_block
fill ~190 ~60 ~27 ~191 ~63 ~27 stone
fill ~190 ~64 ~27 ~191 ~66 ~27 dirt
fill ~190 ~67 ~27 ~191 ~67 ~27 grass_block
fill ~176 ~60 ~28 ~176 ~65 ~28 stone
fill ~176 ~66 ~28 ~176 ~68 ~28 dirt
fill ~176 ~69 ~28 ~176 ~69 ~28 grass_block
fill ~177 ~60 ~28 ~180 ~66 ~28 stone
fill ~177 ~67 ~28 ~180 ~69 ~28 dirt
fill ~177 ~70 ~28 ~180 ~70 ~28 grass_block
fill ~181 ~60 ~28 ~184 ~65 ~28 stone
fill ~181 ~66 ~28 ~184 ~68 ~28 dirt
fill ~181 ~69 ~28 ~184 ~69 ~28 grass_block
fill ~185 ~60 ~28 ~190 ~64 ~28 stone
fill ~185 ~65 ~28 ~190 ~67 ~28 dirt
fill ~185 ~68 ~28 ~190 ~68 ~28 grass_block
fill ~191 ~60 ~28 ~191 ~63 ~28 stone
fill ~191 ~64 ~28 ~191 ~66 ~28 dirt
fill ~191 ~67 ~28 ~191 ~67 ~28 grass_block
fill ~176 ~60 ~29 ~176 ~65 ~29 stone
fill ~176 ~66 ~29 ~176 ~68 ~29 dirt
fill ~176 ~69 ~29 ~176 ~69 ~29 grass_block
fill ~177 ~60 ~29 ~181 ~66 ~29 stone
fill ~177 ~67 ~29 ~181 ~69 ~29 dirt
fill ~177 ~70 ~29 ~181 ~70 ~29 grass_block
fill ~182 ~60 ~29 ~186 ~65 ~29 stone
fill ~182 ~66 ~29 ~186 ~68 ~29 dirt
fill ~182 ~69 ~29 ~186 ~69 ~29 grass_block
fill ~187 ~60 ~29 ~191 ~64 ~29 stone
fill ~187 ~65 ~29 ~191 ~67 ~29 dirt
fill ~187 ~68 ~29 ~191 ~68 ~29 grass_block
fill ~176 ~60 ~30 ~176 ~65 ~30 stone
fill ~176 ~66 ~30 ~176 ~68 ~30 dirt
fill ~176 ~69 ~30 ~176 ~69 ~30 grass_block
fill ~177 ~60 ~30 ~183 ~66 ~30 stone
fill ~177 ~67 ~30 ~183 ~69 ~30 dirt
fill ~177 ~70 ~30 ~183 ~70 ~30 grass_block
fill ~184 ~60 ~30 ~187 ~65 ~30 stone
fill ~184 ~66 ~30 ~187 ~68 ~30 dirt
fill ~184 ~69 ~30 ~187 ~69 ~30 grass_block
fill ~188 ~60 ~30 ~191 ~64 ~30 stone
fill ~188 ~65 ~30 ~191 ~67 ~30 dirt
fill ~188 ~68 ~30 ~191 ~68 ~30 grass_block
fill ~176 ~60 ~31 ~176 ~65 ~31 stone
fill ~176 ~66 ~31 ~176 ~68 ~31 dirt
fill ~176 ~69 ~31 ~176 ~69 ~31 grass_block
fill ~177 ~60 ~31 ~183 ~66 ~31 stone
fill ~177 ~67 ~31 ~183 ~69 ~31 dirt
fill ~177 ~70 ~31 ~183 ~70 ~31 grass_block
fill ~184 ~60 ~31 ~188 ~65 ~31 stone
fill ~184 ~66 ~31 ~188 ~68 ~31 dirt
fill ~184 ~69 ~31 ~188 ~69 ~31 grass_block
fill ~189 ~60 ~31 ~191 ~64 ~31 stone
fill ~189 ~65 ~31 ~191 ~67 ~31 dirt
fill ~189 ~68 ~31 ~191 ~68 ~31 grass_block