fill ~0 ~60 ~0 ~2 ~69 ~0 stone
fill ~0 ~70 ~0 ~2 ~72 ~0 dirt
fill ~0 ~73 ~0 ~2 ~73 ~0 grass_block
fill ~3 ~60 ~0 ~5 ~68 ~0 stone
fill ~3 ~69 ~0 ~5 ~71 ~0 dirt
fill ~3 ~72 ~0 ~5 ~72 ~0 grass_block
fill ~6 ~60 ~0 ~8 ~67 ~0 stone
fill ~6 ~68 ~0 ~8 ~70 ~0 dirt
fill ~6 ~71 ~0 ~8 ~71 ~0 grass_block
fill ~9 ~60 ~0 ~13 ~66 ~0 stone
fill ~9 ~67 ~0 ~13 ~69 ~0 dirt
fill ~9 ~70 ~0 ~13 ~70 ~0 grass_block
fill ~14 ~60 ~0 ~15 ~65 ~0 stone
fill ~14 ~66 ~0 ~15 ~68 ~0 dirt
fill ~14 ~69 ~0 ~15 ~69 ~0 grass_block
fill ~0 ~60 ~1 ~4 ~69 ~1 stone
fill ~0 ~70 ~1 ~4 ~72 ~1 dirt
fill ~0 ~73 ~1 ~4 ~73 ~1 grass_block
fill ~5 ~60 ~1 ~7 ~68 ~1 stone
fill ~5 ~69 ~1 ~7 ~71 ~1 dirt
fill ~5 ~72 ~1 ~7 ~72 ~1 grass_block
fill ~8 ~60 ~1 ~12 ~67 ~1 stone
fill ~8 ~68 ~1 ~12 ~70 ~1 dirt
fill ~8 ~71 ~1 ~12 ~71 ~1 grass_block
fill ~13 ~60 ~1 ~15 ~66 ~1 stone
fill ~13 ~67 ~1 ~15 ~69 ~1 dirt
fill ~13 ~70 ~1 ~15 ~70 ~1 grass_block
fill ~0 ~60 ~2 ~5 ~69 ~2 stone
fill ~0 ~70 ~2 ~5 ~72 ~2 dirt
fill ~0 ~73 ~2 ~5 ~73 ~2 grass_block
fill ~6 ~60 ~2 ~11 ~68 ~2 stone
fill ~6 ~69 ~2 ~11 ~71 ~2 dirt
fill ~6 ~72 ~2 ~11 ~72 ~2 grass_block
fill ~12 ~60 ~2 ~14 ~67 ~2 stone
fill ~12 ~68 ~2 ~14 ~70 ~2 dirt
fill ~12 ~71 ~2 ~14 ~71 ~2 grass_block
fill ~15 ~60 ~2 ~15 ~66 ~2 stone
fill ~15 ~67 ~2 ~15 ~69 ~2 dirt
fill ~15 ~70 ~2 ~15 ~70 ~2 grass_block
fill ~0 ~60 ~3 ~7 ~69 ~3 stone
fill ~0 ~70 ~3 ~7 ~72 ~3 dirt
fill ~0 ~73 ~3 ~7 ~73 ~3 grass_block
fill ~8 ~60 ~3 ~9 ~68 ~3 stone
fill ~8 ~69 ~3 ~9 ~71 ~3 dirt
fill ~8 ~72 ~3 ~9 ~72 ~3 grass_block
fill ~10 ~60 ~3 ~10 ~69 ~3 stone
fill ~10 ~70 ~3 ~10 ~72 ~3 dirt
fill ~10 ~73 ~3 ~10 ~73 ~3 grass_block
fill ~11 ~60 ~3 ~13 ~68 ~3 stone
fill ~11 ~69 ~3 ~13 ~71 ~3 dirt
fill ~11 ~72 ~3 ~13 ~72 ~3 grass_block
fill ~14 ~60 ~3 ~15 ~67 ~3 stone
fill ~14 ~68 ~3 ~15 ~70 ~3 dirt
fill ~14 ~71 ~3 ~15 ~71 ~3 grass_block
fill ~0 ~60 ~4 ~12 ~69 ~4 stone
fill ~0 ~70 ~4 ~12 ~72 ~4 dirt
fill ~0 ~73 ~4 ~12 ~73 ~4 grass_block
fill ~13 ~60 ~4 ~15 ~68 ~4 stone
fill ~13 ~69 ~4 ~15 ~71 ~4 dirt
fill ~13 ~72 ~4 ~15 ~72 ~4 grass_block
fill ~0 ~60 ~5 ~15 ~69 ~5 stone
fill ~0 ~70 ~5 ~15 ~72 ~5 dirt
fill ~0 ~73 ~5 ~15 ~73 ~5 grass_block
fill ~0 ~60 ~6 ~11 ~69 ~6 stone
fill ~0 ~70 ~6 ~11 ~72 ~6 dirt
fill ~0 ~73 ~6 ~11 ~73 ~6 grass_block
fill ~12 ~60 ~6 ~13 ~70 ~6 stone
fill ~12 ~71 ~6 ~13 ~73 ~6 dirt
fill ~12 ~74 ~6 ~13 ~74 ~6 grass_block
fill ~14 ~60 ~6 ~15 ~69 ~6 stone
fill ~14 ~70 ~6 ~15 ~72 ~6 dirt
fill ~14 ~73 ~6 ~15 ~73 ~6 grass_block
fill ~0 ~60 ~7 ~0 ~68 ~7 stone
fill ~0 ~69 ~7 ~0 ~71 ~7 dirt
fill ~0 ~72 ~7 ~0 ~72 ~7 grass_block
fill ~1 ~60 ~7 ~11 ~69 ~7 stone
fill ~1 ~70 ~7 ~11 ~72 ~7 dirt
fill ~1 ~73 ~7 ~11 ~73 ~7 grass_block
fill ~12 ~60 ~7 ~14 ~70 ~7 stone
fill ~12 ~71 ~7 ~14 ~73 ~7 dirt
fill ~12 ~74 ~7 ~14 ~74 ~7 grass_block
fill ~15 ~60 ~7 ~15 ~69 ~7 stone
fill ~15 ~70 ~7 ~15 ~72 ~7 dirt
fill ~15 ~73 ~7 ~15 ~73 ~7 grass_block
fill ~0 ~60 ~8 ~1 ~68 ~8 stone
fill ~0 ~69 ~8 ~1 ~71 ~8 dirt
fill ~0 ~72 ~8 ~1 ~72 ~8 grass_block
fill ~2 ~60 ~8 ~5 ~69 ~8 stone
fill ~2 ~70 ~8 ~5 ~72 ~8 dirt
fill ~2 ~73 ~8 ~5 ~73 ~8 grass_block
fill ~6 ~60 ~8 ~7 ~68 ~8 stone
fill ~6 ~69 ~8 ~7 ~71 ~8 dirt
fill ~6 ~72 ~8 ~7 ~72 ~8 grass_block
fill ~8 ~60 ~8 ~12 ~69 ~8 stone
fill ~8 ~70 ~8 ~12 ~72 ~8 dirt
fill ~8 ~73 ~8 ~12 ~73 ~8 grass_block
fill ~13 ~60 ~8 ~13 ~70 ~8 stone
fill ~13 ~71 ~8 ~13 ~73 ~8 dirt
fill ~13 ~74 ~8 ~13 ~74 ~8 grass_block
fill ~14 ~60 ~8 ~15 ~69 ~8 stone
fill ~14 ~70 ~8 ~15 ~72 ~8 dirt
fill ~14 ~73 ~8 ~15 ~73 ~8 grass_block
fill ~0 ~60 ~9 ~0 ~67 ~9 stone
fill ~0 ~68 ~9 ~0 ~70 ~9 dirt
fill ~0 ~71 ~9 ~0 ~71 ~9 grass_block
fill ~1 ~60 ~9 ~2 ~68 ~9 stone
fill ~1 ~69 ~9 ~2 ~71 ~9 dirt
fill ~1 ~72 ~9 ~2 ~72 ~9 grass_block
fill ~3 ~60 ~9 ~4 ~69 ~9 stone
fill ~3 ~70 ~9 ~4 ~72 ~9 dirt
fill ~3 ~73 ~9 ~4 ~73 ~9 grass_block
fill ~5 ~60 ~9 ~9 ~68 ~9 stone
fill ~5 ~69 ~9 ~9 ~71 ~9 dirt
fill ~5 ~72 ~9 ~9 ~72 ~9 grass_block
fill ~10 ~60 ~9 ~15 ~69 ~9 stone
fill ~10 ~70 ~9 ~15 ~72 ~9 dirt
fill ~10 ~73 ~9 ~15 ~73 ~9 grass_block
fill ~0 ~60 ~10 ~1 ~67 ~10 stone
fill ~0 ~68 ~10 ~1 ~70 ~10 dirt
fill ~0 ~71 ~10 ~1 ~71 ~10 grass_block
fill ~2 ~60 ~10 ~7 ~68 ~10 stone
fill ~2 ~69 ~10 ~7 ~71 ~10 dirt
fill ~2 ~72 ~10 ~7 ~72 ~10 grass_block
fill ~8 ~60 ~10 ~8 ~67 ~10 stone
fill ~8 ~68 ~10 ~8 ~70 ~10 dirt
fill ~8 ~71 ~10 ~8 ~71 ~10 grass_block
fill ~9 ~60 ~10 ~10 ~68 ~10 stone
fill ~9 ~69 ~10 ~10 ~71 ~10 dirt
fill ~9 ~72 ~10 ~10 ~72 ~10 grass_block
fill ~11 ~60 ~10 ~15 ~69 ~10 stone
fill ~11 ~70 ~10 ~15 ~72 ~10 dirt
fill ~11 ~73 ~10 ~15 ~73 ~10 grass_block
fill ~0 ~60 ~11 ~0 ~66 ~11 stone
fill ~0 ~67 ~11 ~0 ~69 ~11 dirt
fill ~0 ~70 ~11 ~0 ~70 ~11 grass_block
fill ~1 ~60 ~11 ~3 ~67 ~11 stone
fill ~1 ~68 ~11 ~3 ~70 ~11 dirt
fill ~1 ~71 ~11 ~3 ~71 ~11 grass_block
fill ~4 ~60 ~11 ~6 ~68 ~11 stone
fill ~4 ~69 ~11 ~6 ~71 ~11 dirt
fill ~4 ~72 ~11 ~6 ~72 ~11 grass_block
fill ~7 ~60 ~11 ~10 ~67 ~11 stone
fill ~7 ~68 ~11 ~10 ~70 ~11 dirt
fill ~7 ~71 ~11 ~10 ~71 ~11 grass_block
fill ~11 ~60 ~11 ~11 ~68 ~11 stone
fill ~11 ~69 ~11 ~11 ~71 ~11 dirt
fill ~11 ~72 ~11 ~11 ~72 ~11 grass_block
fill ~12 ~60 ~11 ~15 ~69 ~11 stone
fill ~12 ~70 ~11 ~15 ~72 ~11 dirt
fill ~12 ~73 ~11 ~15 ~73 ~11 grass_block
fill ~0 ~60 ~12 ~2 ~66 ~12 stone
fill ~0 ~67 ~12 ~2 ~69 ~12 dirt
fill ~0 ~70 ~12 ~2 ~70 ~12 grass_block
fill ~3 ~60 ~12 ~11 ~67 ~12 stone
fill ~3 ~68 ~12 ~11 ~70 ~12 dirt
fill ~3 ~71 ~12 ~11 ~71 ~12 grass_block
fill ~12 ~60 ~12 ~13 ~68 ~12 stone
fill ~12 ~69 ~12 ~13 ~71 ~12 dirt
fill ~12 ~72 ~12 ~13 ~72 ~12 grass_block
fill ~14 ~60 ~12 ~15 ~69 ~12 stone
fill ~14 ~70 ~12 ~15 ~72 ~12 dirt
fill ~14 ~73 ~12 ~15 ~73 ~12 grass_block
fill ~0 ~60 ~13 ~2 ~66 ~13 stone
fill ~0 ~67 ~13 ~2 ~69 ~13 dirt
fill ~0 ~70 ~13 ~2 ~70 ~13 grass_block
fill ~3 ~60 ~13 ~7 ~67 ~13 stone
fill ~3 ~68 ~13 ~7 ~70 ~13 dirt
fill ~3 ~71 ~13 ~7 ~71 ~13 grass_block
fill ~8 ~60 ~13 ~9 ~66 ~13 stone
fill ~8 ~67 ~13 ~9 ~69 ~13 dirt
fill ~8 ~70 ~13 ~9 ~70 ~13 grass_block
fill ~10 ~60 ~13 ~12 ~67 ~13 stone
fill ~10 ~68 ~13 ~12 ~70 ~13 dirt
fill ~10 ~71 ~13 ~12 ~71 ~13 grass_block
fill ~13 ~60 ~13 ~13 ~68 ~13 stone
fill ~13 ~69 ~13 ~13 ~71 ~13 dirt
fill ~13 ~72 ~13 ~13 ~72 ~13 grass_block
fill ~14 ~60 ~13 ~15 ~69 ~13 stone
fill ~14 ~70 ~13 ~15 ~72 ~13 dirt
fill ~14 ~73 ~13 ~15 ~73 ~13 grass_block
fill ~0 ~60 ~14 ~0 ~65 ~14 stone
fill ~0 ~66 ~14 ~0 ~68 ~14 dirt
fill ~0 ~69 ~14 ~0 ~69 ~14 grass_block
fill ~1 ~60 ~14 ~2 ~66 ~14 stone
fill ~1 ~67 ~14 ~2 ~69 ~14 dirt
fill ~1 ~70 ~14 ~2 ~70 ~14 grass_block
fill ~3 ~60 ~14 ~6 ~67 ~14 stone
fill ~3 ~68 ~14 ~6 ~70 ~14 dirt
fill ~3 ~71 ~14 ~6 ~71 ~14 grass_block
fill ~7 ~60 ~14 ~10 ~66 ~14 stone
fill ~7 ~67 ~14 ~10 ~69 ~14 dirt
fill ~7 ~70 ~14 ~10 ~70 ~14 grass_block
fill ~11 ~60 ~14 ~13 ~67 ~14 stone
fill ~11 ~68 ~14 ~13 ~70 ~14 dirt
fill ~11 ~71 ~14 ~13 ~71 ~14 grass_block
fill ~14 ~60 ~14 ~15 ~68 ~14 stone
fill ~14 ~69 ~14 ~15 ~71 ~14 dirt
fill ~14 ~72 ~14 ~15 ~72 ~14 grass_block
fill ~0 ~60 ~15 ~0 ~65 ~15 stone
fill ~0 ~66 ~15 ~0 ~68 ~15 dirt
fill ~0 ~69 ~15 ~0 ~69 ~15 grass_block
fill ~1 ~60 ~15 ~3 ~66 ~15 stone
fill ~1 ~67 ~15 ~3 ~69 ~15 dirt
fill ~1 ~70 ~15 ~3 ~70 ~15 grass_block
fill ~4 ~60 ~15 ~5 ~67 ~15 stone
fill ~4 ~68 ~15 ~5 ~70 ~15 dirt
fill ~4 ~71 ~15 ~5 ~71 ~15 grass_block
fill ~6 ~60 ~15 ~11 ~66 ~15 stone
fill ~6 ~67 ~15 ~11 ~69 ~15 dirt
fill ~6 ~70 ~15 ~11 ~70 ~15 grass_block
fill ~12 ~60 ~15 ~13 ~67 ~15 stone
fill ~12 ~68 ~15 ~13 ~70 ~15 dirt
fill ~12 ~71 ~15 ~13 ~71 ~15 grass_block
fill ~14 ~60 ~15 ~15 ~68 ~15 stone
fill ~14 ~69 ~15 ~15 ~71 ~15 dirt
fill ~14 ~72 ~15 ~15 ~72 ~15 grass_block