fill ~448 ~60 ~80 ~450 ~64 ~80 stone
fill ~448 ~65 ~80 ~450 ~67 ~80 dirt
fill ~448 ~68 ~80 ~450 ~68 ~80 grass_block
fill ~451 ~60 ~80 ~454 ~65 ~80 stone
fill ~451 ~66 ~80 ~454 ~68 ~80 dirt
fill ~451 ~69 ~80 ~454 ~69 ~80 grass_block
fill ~455 ~60 ~80 ~459 ~64 ~80 stone
fill ~455 ~65 ~80 ~459 ~67 ~80 dirt
fill ~455 ~68 ~80 ~459 ~68 ~80 grass_block
fill ~460 ~60 ~80 ~463 ~63 ~80 stone
fill ~460 ~64 ~80 ~463 ~66 ~80 dirt
fill ~460 ~67 ~80 ~463 ~67 ~80 grass_block
fill ~448 ~60 ~81 ~451 ~64 ~81 stone
fill ~448 ~65 ~81 ~451 ~67 ~81 dirt
fill ~448 ~68 ~81 ~451 ~68 ~81 grass_block
fill ~452 ~60 ~81 ~455 ~65 ~81 stone
fill ~452 ~66 ~81 ~455 ~68 ~81 dirt
fill ~452 ~69 ~81 ~455 ~69 ~81 grass_block
fill ~456 ~60 ~81 ~460 ~64 ~81 stone
fill ~456 ~65 ~81 ~460 ~67 ~81 dirt
fill ~456 ~68 ~81 ~460 ~68 ~81 grass_block
fill ~461 ~60 ~81 ~463 ~63 ~81 stone
fill ~461 ~64 ~81 ~463 ~66 ~81 dirt
fill ~461 ~67 ~81 ~463 ~67 ~81 grass_block
fill ~448 ~60 ~82 ~451 ~64 ~82 stone
fill ~448 ~65 ~82 ~451 ~67 ~82 dirt
fill ~448 ~68 ~82 ~451 ~68 ~82 grass_block
fill ~452 ~60 ~82 ~456 ~65 ~82 stone
fill ~452 ~66 ~82 ~456 ~68 ~82 dirt
fill ~452 ~69 ~82 ~456 ~69 ~82 grass_block
fill ~457 ~60 ~82 ~460 ~64 ~82 stone
fill ~457 ~65 ~82 ~460 ~67 ~82 dirt
fill ~457 ~68 ~82 ~460 ~68 ~82 grass_block
fill ~461 ~60 ~82 ~463 ~63 ~82 stone
fill ~461 ~64 ~82 ~463 ~66 ~82 dirt
fill ~461 ~67 ~82 ~463 ~67 ~82 grass_block
fill ~448 ~60 ~83 ~452 ~64 ~83 stone
fill ~448 ~65 ~83 ~452 ~67 ~83 dirt
fill ~448 ~68 ~83 ~452 ~68 ~83 grass_block
fill ~453 ~60 ~83 ~453 ~65 ~83 stone
fill ~453 ~66 ~83 ~453 ~68 ~83 dirt
fill ~453 ~69 ~83 ~453 ~69 ~83 grass_block
fill ~454 ~60 ~83 ~454 ~64 ~83 stone
fill ~454 ~65 ~83 ~454 ~67 ~83 dirt
fill ~454 ~68 ~83 ~454 ~68 ~83 grass_block
fill ~455 ~60 ~83 ~455 ~65 ~83 stone
fill ~455 ~66 ~83 ~455 ~68 ~83 dirt
fill ~455 ~69 ~83 ~455 ~69 ~83 grass_block
fill ~456 ~60 ~83 ~461 ~64 ~83 stone
fill ~456 ~65 ~83 ~461 ~67 ~83 dirt
fill ~456 ~68 ~83 ~461 ~68 ~83 grass_block
fill ~462 ~60 ~83 ~463 ~63 ~83 stone
fill ~462 ~64 ~83 ~463 ~66 ~83 dirt
fill ~462 ~67 ~83 ~463 ~67 ~83 grass_block
fill ~448 ~60 ~84 ~448 ~63 ~84 stone
fill ~448 ~64 ~84 ~448 ~66 ~84 dirt
fill ~448 ~67 ~84 ~448 ~67 ~84 grass_block
fill ~449 ~60 ~84 ~461 ~64 ~84 stone
fill ~449 ~65 ~84 ~461 ~67 ~84 dirt
fill ~449 ~68 ~84 ~461 ~68 ~84 grass_block
fill ~462 ~60 ~84 ~463 ~63 ~84 stone
fill ~462 ~64 ~84 ~463 ~66 ~84 dirt
fill ~462 ~67 ~84 ~463 ~67 ~84 grass_block
fill ~448 ~60 ~85 ~448 ~63 ~85 stone
fill ~448 ~64 ~85 ~448 ~66 ~85 dirt
fill ~448 ~67 ~85 ~448 ~67 ~85 grass_block
fill ~449 ~60 ~85 ~462 ~64 ~85 stone
fill ~449 ~65 ~85 ~462 ~67 ~85 dirt
fill ~449 ~68 ~85 ~462 ~68 ~85 grass_block
fill ~463 ~60 ~85 ~463 ~63 ~85 stone
fill ~463 ~64 ~85 ~463 ~66 ~85 dirt
fill ~463 ~67 ~85 ~463 ~67 ~85 grass_block
fill ~448 ~60 ~86 ~450 ~63 ~86 stone
fill ~448 ~64 ~86 ~450 ~66 ~86 dirt
fill ~448 ~67 ~86 ~450 ~67 ~86 grass_block
fill ~451 ~60 ~86 ~462 ~64 ~86 stone
fill ~451 ~65 ~86 ~462 ~67 ~86 dirt
fill ~451 ~68 ~86 ~462 ~68 ~86 grass_block
fill ~463 ~60 ~86 ~463 ~63 ~86 stone
fill ~463 ~64 ~86 ~463 ~66 ~86 dirt
fill ~463 ~67 ~86 ~463 ~67 ~86 grass_block
fill ~448 ~60 ~87 ~451 ~63 ~87 stone
fill ~448 ~64 ~87 ~451 ~66 ~87 dirt
fill ~448 ~67 ~87 ~451 ~67 ~87 grass_block
fill ~452 ~60 ~87 ~454 ~64 ~87 stone
fill ~452 ~65 ~87 ~454 ~67 ~87 dirt
fill ~452 ~68 ~87 ~454 ~68 ~87 grass_block
fill ~455 ~60 ~87 ~456 ~63 ~87 stone
fill ~455 ~64 ~87 ~456 ~66 ~87 dirt
fill ~455 ~67 ~87 ~456 ~67 ~87 grass_block
fill ~457 ~60 ~87 ~463 ~64 ~87 stone
fill ~457 ~65 ~87 ~463 ~67 ~87 dirt
fill ~457 ~68 ~87 ~463 ~68 ~87 grass_block
fill ~448 ~60 ~88 ~452 ~63 ~88 stone
fill ~448 ~64 ~88 ~452 ~66 ~88 dirt
fill ~448 ~67 ~88 ~452 ~67 ~88 grass_block
fill ~453 ~60 ~88 ~454 ~64 ~88 stone
fill ~453 ~65 ~88 ~454 ~67 ~88 dirt
fill ~453 ~68 ~88 ~454 ~68 ~88 grass_block
fill ~455 ~60 ~88 ~457 ~63 ~88 stone
fill ~455 ~64 ~88 ~457 ~66 ~88 dirt
fill ~455 ~67 ~88 ~457 ~67 ~88 grass_block
fill ~458 ~60 ~88 ~463 ~64 ~88 stone
fill ~458 ~65 ~88 ~463 ~67 ~88 dirt
fill ~458 ~68 ~88 ~463 ~68 ~88 grass_block
fill ~448 ~60 ~89 ~449 ~62 ~89 stone
fill ~448 ~63 ~89 ~449 ~65 ~89 dirt
fill ~448 ~66 ~89 ~449 ~66 ~89 grass_block
fill ~450 ~60 ~89 ~457 ~63 ~89 stone
fill ~450 ~64 ~89 ~457 ~66 ~89 dirt
fill ~450 ~67 ~89 ~457 ~67 ~89 grass_block
fill ~458 ~60 ~89 ~463 ~64 ~89 stone
fill ~458 ~65 ~89 ~463 ~67 ~89 dirt
fill ~458 ~68 ~89 ~463 ~68 ~89 grass_block
fill ~448 ~60 ~90 ~448 ~63 ~90 stone
fill ~448 ~64 ~90 ~448 ~66 ~90 dirt
fill ~448 ~67 ~90 ~448 ~67 ~90 grass_block
fill ~449 ~60 ~90 ~450 ~62 ~90 stone
fill ~449 ~63 ~90 ~450 ~65 ~90 dirt
fill ~449 ~66 ~90 ~450 ~66 ~90 grass_block
fill ~451 ~60 ~90 ~458 ~63 ~90 stone
fill ~451 ~64 ~90 ~458 ~66 ~90 dirt
fill ~451 ~67 ~90 ~458 ~67 ~90 grass_block
fill ~459 ~60 ~90 ~463 ~64 ~90 stone
fill ~459 ~65 ~90 ~463 ~67 ~90 dirt
fill ~459 ~68 ~90 ~463 ~68 ~90 grass_block
fill ~448 ~60 ~91 ~448 ~63 ~91 stone
fill ~448 ~64 ~91 ~448 ~66 ~91 dirt
fill ~448 ~67 ~91 ~448 ~67 ~91 grass_block
fill ~449 ~60 ~91 ~450 ~62 ~91 stone
fill ~449 ~63 ~91 ~450 ~65 ~91 dirt
fill ~449 ~66 ~91 ~450 ~66 ~91 grass_block
fill ~451 ~60 ~91 ~458 ~63 ~91 stone
fill ~451 ~64 ~91 ~458 ~66 ~91 dirt
fill ~451 ~67 ~91 ~458 ~67 ~91 grass_block
fill ~459 ~60 ~91 ~463 ~64 ~91 stone
fill ~459 ~65 ~91 ~463 ~67 ~91 dirt
fill ~459 ~68 ~91 ~463 ~68 ~91 grass_block
fill ~448 ~60 ~92 ~448 ~63 ~92 stone
fill ~448 ~64 ~92 ~448 ~66 ~92 dirt
fill ~448 ~67 ~92 ~448 ~67 ~92 grass_block
fill ~449 ~60 ~92 ~452 ~62 ~92 stone
fill ~449 ~63 ~92 ~452 ~65 ~92 dirt
fill ~449 ~66 ~92 ~452 ~66 ~92 grass_block
fill ~453 ~60 ~92 ~458 ~63 ~92 stone
fill ~453 ~64 ~92 ~458 ~66 ~92 dirt
fill ~453 ~67 ~92 ~458 ~67 ~92 grass_block
fill ~459 ~60 ~92 ~463 ~64 ~92 stone
fill ~459 ~65 ~92 ~463 ~67 ~92 dirt
fill ~459 ~68 ~92 ~463 ~68 ~92 grass_block
fill ~448 ~60 ~93 ~448 ~63 ~93 stone
fill ~448 ~64 ~93 ~448 ~66 ~93 dirt
fill ~448 ~67 ~93 ~448 ~67 ~93 grass_block
fill ~449 ~60 ~93 ~455 ~62 ~93 stone
fill ~449 ~63 ~93 ~455 ~65 ~93 dirt
fill ~449 ~66 ~93 ~455 ~66 ~93 grass_block
fill ~456 ~60 ~93 ~459 ~63 ~93 stone
fill ~456 ~64 ~93 ~459 ~66 ~93 dirt
fill ~456 ~67 ~93 ~459 ~67 ~93 grass_block
fill ~460 ~60 ~93 ~463 ~64 ~93 stone
fill ~460 ~65 ~93 ~463 ~67 ~93 dirt
fill ~460 ~68 ~93 ~463 ~68 ~93 grass_block
fill ~448 ~60 ~94 ~448 ~63 ~94 stone
fill ~448 ~64 ~94 ~448 ~66 ~94 dirt
fill ~448 ~67 ~94 ~448 ~67 ~94 grass_block
fill ~449 ~60 ~94 ~455 ~62 ~94 stone
fill ~449 ~63 ~94 ~455 ~65 ~94 dirt
fill ~449 ~66 ~94 ~455 ~66 ~94 grass_block
fill ~456 ~60 ~94 ~459 ~63 ~94 stone
fill ~456 ~64 ~94 ~459 ~66 ~94 dirt
fill ~456 ~67 ~94 ~459 ~67 ~94 grass_block
fill ~460 ~60 ~94 ~463 ~64 ~94 stone
fill ~460 ~65 ~94 ~463 ~67 ~94 dirt
fill ~460 ~68 ~94 ~463 ~68 ~94 grass_block
fill ~448 ~60 ~95 ~448 ~63 ~95 stone
fill ~448 ~64 ~95 ~448 ~66 ~95 dirt
fill ~448 ~67 ~95 ~448 ~67 ~95 grass_block
fill ~449 ~60 ~95 ~455 ~62 ~95 stone
fill ~449 ~63 ~95 ~455 ~65 ~95 dirt
fill ~449 ~66 ~95 ~455 ~66 ~95 grass_block
fill ~456 ~60 ~95 ~459 ~63 ~95 stone
fill ~456 ~64 ~95 ~459 ~66 ~95 dirt
fill ~456 ~67 ~95 ~459 ~67 ~95 grass_block
fill ~460 ~60 ~95 ~463 ~64 ~95 stone
fill ~460 ~65 ~95 ~463 ~67 ~95 dirt
fill ~460 ~68 ~95 ~463 ~68 ~95 grass_block