fill ~464 ~60 ~128 ~466 ~64 ~128 stone
fill ~464 ~65 ~128 ~466 ~67 ~128 dirt
fill ~464 ~68 ~128 ~466 ~68 ~128 grass_block
fill ~467 ~60 ~128 ~469 ~63 ~128 stone
fill ~467 ~64 ~128 ~469 ~66 ~128 dirt
fill ~467 ~67 ~128 ~469 ~67 ~128 grass_block
fill ~464 ~60 ~129 ~466 ~64 ~129 stone
fill ~464 ~65 ~129 ~466 ~67 ~129 dirt
fill ~464 ~68 ~129 ~466 ~68 ~129 grass_block
fill ~467 ~60 ~129 ~469 ~63 ~129 stone
fill ~467 ~64 ~129 ~469 ~66 ~129 dirt
fill ~467 ~67 ~129 ~469 ~67 ~129 grass_block
fill ~464 ~60 ~130 ~467 ~64 ~130 stone
fill ~464 ~65 ~130 ~467 ~67 ~130 dirt
fill ~464 ~68 ~130 ~467 ~68 ~130 grass_block
fill ~468 ~60 ~130 ~469 ~63 ~130 stone
fill ~468 ~64 ~130 ~469 ~66 ~130 dirt
fill ~468 ~67 ~130 ~469 ~67 ~130 grass_block
fill ~464 ~60 ~131 ~468 ~64 ~131 stone
fill ~464 ~65 ~131 ~468 ~67 ~131 dirt
fill ~464 ~68 ~131 ~468 ~68 ~131 grass_block
fill ~469 ~60 ~131 ~469 ~63 ~131 stone
fill ~469 ~64 ~131 ~469 ~66 ~131 dirt
fill ~469 ~67 ~131 ~469 ~67 ~131 grass_block
fill ~464 ~60 ~132 ~469 ~64 ~132 stone
fill ~464 ~65 ~132 ~469 ~67 ~132 dirt
fill ~464 ~68 ~132 ~469 ~68 ~132 grass_block
fill ~464 ~60 ~133 ~469 ~64 ~133 stone
fill ~464 ~65 ~133 ~469 ~67 ~133 dirt
fill ~464 ~68 ~133 ~469 ~68 ~133 grass_block
fill ~464 ~60 ~134 ~464 ~63 ~134 stone
fill ~464 ~64 ~134 ~464 ~66 ~134 dirt
fill ~464 ~67 ~134 ~464 ~67 ~134 grass_block
fill ~465 ~60 ~134 ~469 ~64 ~134 stone
fill ~465 ~65 ~134 ~469 ~67 ~134 dirt
fill ~465 ~68 ~134 ~469 ~68 ~134 grass_block
fill ~464 ~60 ~135 ~466 ~63 ~135 stone
fill ~464 ~64 ~135 ~466 ~66 ~135 dirt
fill ~464 ~67 ~135 ~466 ~67 ~135 grass_block
fill ~467 ~60 ~135 ~469 ~64 ~135 stone
fill ~467 ~65 ~135 ~469 ~67 ~135 dirt
fill ~467 ~68 ~135 ~469 ~68 ~135 grass_block
fill ~464 ~60 ~136 ~469 ~63 ~136 stone
fill ~464 ~64 ~136 ~469 ~66 ~136 dirt
fill ~464 ~67 ~136 ~469 ~67 ~136 grass_block
fill ~464 ~60 ~137 ~469 ~63 ~137 stone
fill ~464 ~64 ~137 ~469 ~66 ~137 dirt
fill ~464 ~67 ~137 ~469 ~67 ~137 grass_block
fill ~464 ~60 ~138 ~469 ~63 ~138 stone
fill ~464 ~64 ~138 ~469 ~66 ~138 dirt
fill ~464 ~67 ~138 ~469 ~67 ~138 grass_block
fill ~464 ~60 ~139 ~468 ~62 ~139 stone
fill ~464 ~63 ~139 ~468 ~65 ~139 dirt
fill ~464 ~66 ~139 ~468 ~66 ~139 grass_block
fill ~469 ~60 ~139 ~469 ~63 ~139 stone
fill ~469 ~64 ~139 ~469 ~66 ~139 dirt
fill ~469 ~67 ~139 ~469 ~67 ~139 grass_block
fill ~464 ~60 ~140 ~469 ~62 ~140 stone
fill ~464 ~63 ~140 ~469 ~65 ~140 dirt
fill ~464 ~66 ~140 ~469 ~66 ~140 grass_block
fill ~464 ~60 ~141 ~469 ~62 ~141 stone
fill ~464 ~63 ~141 ~469 ~65 ~141 dirt
fill ~464 ~66 ~141 ~469 ~66 ~141 grass_block
fill ~464 ~60 ~142 ~469 ~62 ~142 stone
fill ~464 ~63 ~142 ~469 ~65 ~142 dirt
fill ~464 ~66 ~142 ~469 ~66 ~142 grass_block
fill ~464 ~60 ~143 ~466 ~62 ~143 stone
fill ~464 ~63 ~143 ~466 ~65 ~143 dirt
fill ~464 ~66 ~143 ~466 ~66 ~143 grass_block
fill ~467 ~60 ~143 ~469 ~61 ~143 stone
fill ~467 ~62 ~143 ~469 ~64 ~143 dirt
fill ~467 ~65 ~143 ~469 ~65 ~143 grass_block