fill ~128 ~60 ~32 ~130 ~67 ~32 stone
fill ~128 ~68 ~32 ~130 ~70 ~32 dirt
fill ~128 ~71 ~32 ~130 ~71 ~32 grass_block
fill ~131 ~60 ~32 ~131 ~66 ~32 stone
fill ~131 ~67 ~32 ~131 ~69 ~32 dirt
fill ~131 ~70 ~32 ~131 ~70 ~32 grass_block
fill ~132 ~60 ~32 ~135 ~65 ~32 stone
fill ~132 ~66 ~32 ~135 ~68 ~32 dirt
fill ~132 ~69 ~32 ~135 ~69 ~32 grass_block
fill ~136 ~60 ~32 ~140 ~64 ~32 stone
fill ~136 ~65 ~32 ~140 ~67 ~32 dirt
fill ~136 ~68 ~32 ~140 ~68 ~32 grass_block
fill ~141 ~60 ~32 ~141 ~65 ~32 stone
fill ~141 ~66 ~32 ~141 ~68 ~32 dirt
fill ~141 ~69 ~32 ~141 ~69 ~32 grass_block
fill ~142 ~60 ~32 ~143 ~64 ~32 stone
fill ~142 ~65 ~32 ~143 ~67 ~32 dirt
fill ~142 ~68 ~32 ~143 ~68 ~32 grass_block
fill ~128 ~60 ~33 ~129 ~67 ~33 stone
fill ~128 ~68 ~33 ~129 ~70 ~33 dirt
fill ~128 ~71 ~33 ~129 ~71 ~33 grass_block
fill ~130 ~60 ~33 ~131 ~66 ~33 stone
fill ~130 ~67 ~33 ~131 ~69 ~33 dirt
fill ~130 ~70 ~33 ~131 ~70 ~33 grass_block
fill ~132 ~60 ~33 ~135 ~65 ~33 stone
fill ~132 ~66 ~33 ~135 ~68 ~33 dirt
fill ~132 ~69 ~33 ~135 ~69 ~33 grass_block
fill ~136 ~60 ~33 ~137 ~64 ~33 stone
fill ~136 ~65 ~33 ~137 ~67 ~33 dirt
fill ~136 ~68 ~33 ~137 ~68 ~33 grass_block
fill ~138 ~60 ~33 ~142 ~65 ~33 stone
fill ~138 ~66 ~33 ~142 ~68 ~33 dirt
fill ~138 ~69 ~33 ~142 ~69 ~33 grass_block
fill ~143 ~60 ~33 ~143 ~64 ~33 stone
fill ~143 ~65 ~33 ~143 ~67 ~33 dirt
fill ~143 ~68 ~33 ~143 ~68 ~33 grass_block
fill ~128 ~60 ~34 ~128 ~68 ~34 stone
fill ~128 ~69 ~34 ~128 ~71 ~34 dirt
fill ~128 ~72 ~34 ~128 ~72 ~34 grass_block
fill ~129 ~60 ~34 ~129 ~67 ~34 stone
fill ~129 ~68 ~34 ~129 ~70 ~34 dirt
fill ~129 ~71 ~34 ~129 ~71 ~34 grass_block
fill ~130 ~60 ~34 ~131 ~66 ~34 stone
fill ~130 ~67 ~34 ~131 ~69 ~34 dirt
fill ~130 ~70 ~34 ~131 ~70 ~34 grass_block
fill ~132 ~60 ~34 ~138 ~65 ~34 stone
fill ~132 ~66 ~34 ~138 ~68 ~34 dirt
fill ~132 ~69 ~34 ~138 ~69 ~34 grass_block
fill ~139 ~60 ~34 ~139 ~66 ~34 stone
fill ~139 ~67 ~34 ~139 ~69 ~34 dirt
fill ~139 ~70 ~34 ~139 ~70 ~34 grass_block
fill ~140 ~60 ~34 ~143 ~65 ~34 stone
fill ~140 ~66 ~34 ~143 ~68 ~34 dirt
fill ~140 ~69 ~34 ~143 ~69 ~34 grass_block
fill ~128 ~60 ~35 ~129 ~68 ~35 stone
fill ~128 ~69 ~35 ~129 ~71 ~35 dirt
fill ~128 ~72 ~35 ~129 ~72 ~35 grass_block
fill ~130 ~60 ~35 ~130 ~67 ~35 stone
fill ~130 ~68 ~35 ~130 ~70 ~35 dirt
fill ~130 ~71 ~35 ~130 ~71 ~35 grass_block
fill ~131 ~60 ~35 ~132 ~66 ~35 stone
fill ~131 ~67 ~35 ~132 ~69 ~35 dirt
fill ~131 ~70 ~35 ~132 ~70 ~35 grass_block
fill ~133 ~60 ~35 ~136 ~65 ~35 stone
fill ~133 ~66 ~35 ~136 ~68 ~35 dirt
fill ~133 ~69 ~35 ~136 ~69 ~35 grass_block
fill ~137 ~60 ~35 ~140 ~66 ~35 stone
fill ~137 ~67 ~35 ~140 ~69 ~35 dirt
fill ~137 ~70 ~35 ~140 ~70 ~35 grass_block
fill ~141 ~60 ~35 ~143 ~65 ~35 stone
fill ~141 ~66 ~35 ~143 ~68 ~35 dirt
fill ~141 ~69 ~35 ~143 ~69 ~35 grass_block
fill ~128 ~60 ~36 ~129 ~68 ~36 stone
fill ~128 ~69 ~36 ~129 ~71 ~36 dirt
fill ~128 ~72 ~36 ~129 ~72 ~36 grass_block
fill ~130 ~60 ~36 ~131 ~67 ~36 stone
fill ~130 ~68 ~36 ~131 ~70 ~36 dirt
fill ~130 ~71 ~36 ~131 ~71 ~36 grass_block
fill ~132 ~60 ~36 ~137 ~66 ~36 stone
fill ~132 ~67 ~36 ~137 ~69 ~36 dirt
fill ~132 ~70 ~36 ~137 ~70 ~36 grass_block
fill ~138 ~60 ~36 ~140 ~67 ~36 stone
fill ~138 ~68 ~36 ~140 ~70 ~36 dirt
fill ~138 ~71 ~36 ~140 ~71 ~36 grass_block
fill ~141 ~60 ~36 ~142 ~66 ~36 stone
fill ~141 ~67 ~36 ~142 ~69 ~36 dirt
fill ~141 ~70 ~36 ~142 ~70 ~36 grass_block
fill ~143 ~60 ~36 ~143 ~65 ~36 stone
fill ~143 ~66 ~36 ~143 ~68 ~36 dirt
fill ~143 ~69 ~36 ~143 ~69 ~36 grass_block
fill ~128 ~60 ~37 ~130 ~68 ~37 stone
fill ~128 ~69 ~37 ~130 ~71 ~37 dirt
fill ~128 ~72 ~37 ~130 ~72 ~37 grass_block
fill ~131 ~60 ~37 ~132 ~67 ~37 stone
fill ~131 ~68 ~37 ~132 ~70 ~37 dirt
fill ~131 ~71 ~37 ~132 ~71 ~37 grass_block
fill ~133 ~60 ~37 ~135 ~66 ~37 stone
fill ~133 ~67 ~37 ~135 ~69 ~37 dirt
fill ~133 ~70 ~37 ~135 ~70 ~37 grass_block
fill ~136 ~60 ~37 ~141 ~67 ~37 stone
fill ~136 ~68 ~37 ~141 ~70 ~37 dirt
fill ~136 ~71 ~37 ~141 ~71 ~37 grass_block
fill ~142 ~60 ~37 ~142 ~66 ~37 stone
fill ~142 ~67 ~37 ~142 ~69 ~37 dirt
fill ~142 ~70 ~37 ~142 ~70 ~37 grass_block
fill ~143 ~60 ~37 ~143 ~65 ~37 stone
fill ~143 ~66 ~37 ~143 ~68 ~37 dirt
fill ~143 ~69 ~37 ~143 ~69 ~37 grass_block
fill ~128 ~60 ~38 ~131 ~68 ~38 stone
fill ~128 ~69 ~38 ~131 ~71 ~38 dirt
fill ~128 ~72 ~38 ~131 ~72 ~38 grass_block
fill ~132 ~60 ~38 ~134 ~67 ~38 stone
fill ~132 ~68 ~38 ~134 ~70 ~38 dirt
fill ~132 ~71 ~38 ~134 ~71 ~38 grass_block
fill ~135 ~60 ~38 ~135 ~66 ~38 stone
fill ~135 ~67 ~38 ~135 ~69 ~38 dirt
fill ~135 ~70 ~38 ~135 ~70 ~38 grass_block
fill ~136 ~60 ~38 ~142 ~67 ~38 stone
fill ~136 ~68 ~38 ~142 ~70 ~38 dirt
fill ~136 ~71 ~38 ~142 ~71 ~38 grass_block
fill ~143 ~60 ~38 ~143 ~66 ~38 stone
fill ~143 ~67 ~38 ~143 ~69 ~38 dirt
fill ~143 ~70 ~38 ~143 ~70 ~38 grass_block
fill ~128 ~60 ~39 ~132 ~68 ~39 stone
fill ~128 ~69 ~39 ~132 ~71 ~39 dirt
fill ~128 ~72 ~39 ~132 ~72 ~39 grass_block
fill ~133 ~60 ~39 ~138 ~67 ~39 stone
fill ~133 ~68 ~39 ~138 ~70 ~39 dirt
fill ~133 ~71 ~39 ~138 ~71 ~39 grass_block
fill ~139 ~60 ~39 ~139 ~68 ~39 stone
fill ~139 ~69 ~39 ~139 ~71 ~39 dirt
fill ~139 ~72 ~39 ~139 ~72 ~39 grass_block
fill ~140 ~60 ~39 ~142 ~67 ~39 stone
fill ~140 ~68 ~39 ~142 ~70 ~39 dirt
fill ~140 ~71 ~39 ~142 ~71 ~39 grass_block
fill ~143 ~60 ~39 ~143 ~66 ~39 stone
fill ~143 ~67 ~39 ~143 ~69 ~39 dirt
fill ~143 ~70 ~39 ~143 ~70 ~39 grass_block
fill ~128 ~60 ~40 ~128 ~67 ~40 stone
fill ~128 ~68 ~40 ~128 ~70 ~40 dirt
fill ~128 ~71 ~40 ~128 ~71 ~40 grass_block
fill ~129 ~60 ~40 ~132 ~68 ~40 stone
fill ~129 ~69 ~40 ~132 ~71 ~40 dirt
fill ~129 ~72 ~40 ~132 ~72 ~40 grass_block
fill ~133 ~60 ~40 ~139 ~67 ~40 stone
fill ~133 ~68 ~40 ~139 ~70 ~40 dirt
fill ~133 ~71 ~40 ~139 ~71 ~40 grass_block
fill ~140 ~60 ~40 ~141 ~68 ~40 stone
fill ~140 ~69 ~40 ~141 ~71 ~40 dirt
fill ~140 ~72 ~40 ~141 ~72 ~40 grass_block
fill ~142 ~60 ~40 ~143 ~67 ~40 stone
fill ~142 ~68 ~40 ~143 ~70 ~40 dirt
fill ~142 ~71 ~40 ~143 ~71 ~40 grass_block
fill ~128 ~60 ~41 ~131 ~67 ~41 stone
fill ~128 ~68 ~41 ~131 ~70 ~41 dirt
fill ~128 ~71 ~41 ~131 ~71 ~41 grass_block
fill ~132 ~60 ~41 ~132 ~68 ~41 stone
fill ~132 ~69 ~41 ~132 ~71 ~41 dirt
fill ~132 ~72 ~41 ~132 ~72 ~41 grass_block
fill ~133 ~60 ~41 ~139 ~67 ~41 stone
fill ~133 ~68 ~41 ~139 ~70 ~41 dirt
fill ~133 ~71 ~41 ~139 ~71 ~41 grass_block
fill ~140 ~60 ~41 ~142 ~68 ~41 stone
fill ~140 ~69 ~41 ~142 ~71 ~41 dirt
fill ~140 ~72 ~41 ~142 ~72 ~41 grass_block
fill ~143 ~60 ~41 ~143 ~67 ~41 stone
fill ~143 ~68 ~41 ~143 ~70 ~41 dirt
fill ~143 ~71 ~41 ~143 ~71 ~41 grass_block
fill ~128 ~60 ~42 ~142 ~67 ~42 stone
fill ~128 ~68 ~42 ~142 ~70 ~42 dirt
fill ~128 ~71 ~42 ~142 ~71 ~42 grass_block
fill ~143 ~60 ~42 ~143 ~68 ~42 stone
fill ~143 ~69 ~42 ~143 ~71 ~42 dirt
fill ~143 ~72 ~42 ~143 ~72 ~42 grass_block
fill ~128 ~60 ~43 ~128 ~66 ~43 stone
fill ~128 ~67 ~43 ~128 ~69 ~43 dirt
fill ~128 ~70 ~43 ~128 ~70 ~43 grass_block
fill ~129 ~60 ~43 ~142 ~67 ~43 stone
fill ~129 ~68 ~43 ~142 ~70 ~43 dirt
fill ~129 ~71 ~43 ~142 ~71 ~43 grass_block
fill ~143 ~60 ~43 ~143 ~68 ~43 stone
fill ~143 ~69 ~43 ~143 ~71 ~43 dirt
fill ~143 ~72 ~43 ~143 ~72 ~43 grass_block
fill ~128 ~60 ~44 ~129 ~66 ~44 stone
fill ~128 ~67 ~44 ~129 ~69 ~44 dirt
fill ~128 ~70 ~44 ~129 ~70 ~44 grass_block
fill ~130 ~60 ~44 ~143 ~67 ~44 stone
fill ~130 ~68 ~44 ~143 ~70 ~44 dirt
fill ~130 ~71 ~44 ~143 ~71 ~44 grass_block
fill ~128 ~60 ~45 ~128 ~65 ~45 stone
fill ~128 ~66 ~45 ~128 ~68 ~45 dirt
fill ~128 ~69 ~45 ~128 ~69 ~45 grass_block
fill ~129 ~60 ~45 ~130 ~66 ~45 stone
fill ~129 ~67 ~45 ~130 ~69 ~45 dirt
fill ~129 ~70 ~45 ~130 ~70 ~45 grass_block
fill ~131 ~60 ~45 ~143 ~67 ~45 stone
fill ~131 ~68 ~45 ~143 ~70 ~45 dirt
fill ~131 ~71 ~45 ~143 ~71 ~45 grass_block
fill ~128 ~60 ~46 ~129 ~65 ~46 stone
fill ~128 ~66 ~46 ~129 ~68 ~46 dirt
fill ~128 ~69 ~46 ~129 ~69 ~46 grass_block
fill ~130 ~60 ~46 ~132 ~66 ~46 stone
fill ~130 ~67 ~46 ~132 ~69 ~46 dirt
fill ~130 ~70 ~46 ~132 ~70 ~46 grass_block
fill ~133 ~60 ~46 ~133 ~67 ~46 stone
fill ~133 ~68 ~46 ~133 ~70 ~46 dirt
fill ~133 ~71 ~46 ~133 ~71 ~46 grass_block
fill ~134 ~60 ~46 ~137 ~66 ~46 stone
fill ~134 ~67 ~46 ~137 ~69 ~46 dirt
fill ~134 ~70 ~46 ~137 ~70 ~46 grass_block
fill ~138 ~60 ~46 ~143 ~67 ~46 stone
fill ~138 ~68 ~46 ~143 ~70 ~46 dirt
fill ~138 ~71 ~46 ~143 ~71 ~46 grass_block
fill ~128 ~60 ~47 ~130 ~65 ~47 stone
fill ~128 ~66 ~47 ~130 ~68 ~47 dirt
fill ~128 ~69 ~47 ~130 ~69 ~47 grass_block
fill ~131 ~60 ~47 ~140 ~66 ~47 stone
fill ~131 ~67 ~47 ~140 ~69 ~47 dirt
fill ~131 ~70 ~47 ~140 ~70 ~47 grass_block
fill ~141 ~60 ~47 ~143 ~67 ~47 stone
fill ~141 ~68 ~47 ~143 ~70 ~47 dirt
fill ~141 ~71 ~47 ~143 ~71 ~47 grass_block