fill ~288 ~60 ~128 ~288 ~66 ~128 stone
fill ~288 ~67 ~128 ~288 ~69 ~128 dirt
fill ~288 ~70 ~128 ~288 ~70 ~128 grass_block
fill ~289 ~60 ~128 ~289 ~65 ~128 stone
fill ~289 ~66 ~128 ~289 ~68 ~128 dirt
fill ~289 ~69 ~128 ~289 ~69 ~128 grass_block
fill ~290 ~60 ~128 ~290 ~66 ~128 stone
fill ~290 ~67 ~128 ~290 ~69 ~128 dirt
fill ~290 ~70 ~128 ~290 ~70 ~128 grass_block
fill ~291 ~60 ~128 ~303 ~65 ~128 stone
fill ~291 ~66 ~128 ~303 ~68 ~128 dirt
fill ~291 ~69 ~128 ~303 ~69 ~128 grass_block
fill ~288 ~60 ~129 ~303 ~65 ~129 stone
fill ~288 ~66 ~129 ~303 ~68 ~129 dirt
fill ~288 ~69 ~129 ~303 ~69 ~129 grass_block
fill ~288 ~60 ~130 ~300 ~65 ~130 stone
fill ~288 ~66 ~130 ~300 ~68 ~130 dirt
fill ~288 ~69 ~130 ~300 ~69 ~130 grass_block
fill ~301 ~60 ~130 ~303 ~64 ~130 stone
fill ~301 ~65 ~130 ~303 ~67 ~130 dirt
fill ~301 ~68 ~130 ~303 ~68 ~130 grass_block
fill ~288 ~60 ~131 ~300 ~65 ~131 stone
fill ~288 ~66 ~131 ~300 ~68 ~131 dirt
fill ~288 ~69 ~131 ~300 ~69 ~131 grass_block
fill ~301 ~60 ~131 ~303 ~64 ~131 stone
fill ~301 ~65 ~131 ~303 ~67 ~131 dirt
fill ~301 ~68 ~131 ~303 ~68 ~131 grass_block
fill ~288 ~60 ~132 ~300 ~65 ~132 stone
fill ~288 ~66 ~132 ~300 ~68 ~132 dirt
fill ~288 ~69 ~132 ~300 ~69 ~132 grass_block
fill ~301 ~60 ~132 ~303 ~64 ~132 stone
fill ~301 ~65 ~132 ~303 ~67 ~132 dirt
fill ~301 ~68 ~132 ~303 ~68 ~132 grass_block
fill ~288 ~60 ~133 ~301 ~65 ~133 stone
fill ~288 ~66 ~133 ~301 ~68 ~133 dirt
fill ~288 ~69 ~133 ~301 ~69 ~133 grass_block
fill ~302 ~60 ~133 ~303 ~64 ~133 stone
fill ~302 ~65 ~133 ~303 ~67 ~133 dirt
fill ~302 ~68 ~133 ~303 ~68 ~133 grass_block
fill ~288 ~60 ~134 ~288 ~64 ~134 stone
fill ~288 ~65 ~134 ~288 ~67 ~134 dirt
fill ~288 ~68 ~134 ~288 ~68 ~134 grass_block
fill ~289 ~60 ~134 ~301 ~65 ~134 stone
fill ~289 ~66 ~134 ~301 ~68 ~134 dirt
fill ~289 ~69 ~134 ~301 ~69 ~134 grass_block
fill ~302 ~60 ~134 ~303 ~64 ~134 stone
fill ~302 ~65 ~134 ~303 ~67 ~134 dirt
fill ~302 ~68 ~134 ~303 ~68 ~134 grass_block
fill ~288 ~60 ~135 ~294 ~64 ~135 stone
fill ~288 ~65 ~135 ~294 ~67 ~135 dirt
fill ~288 ~68 ~135 ~294 ~68 ~135 grass_block
fill ~295 ~60 ~135 ~302 ~65 ~135 stone
fill ~295 ~66 ~135 ~302 ~68 ~135 dirt
fill ~295 ~69 ~135 ~302 ~69 ~135 grass_block
fill ~303 ~60 ~135 ~303 ~64 ~135 stone
fill ~303 ~65 ~135 ~303 ~67 ~135 dirt
fill ~303 ~68 ~135 ~303 ~68 ~135 grass_block
fill ~288 ~60 ~136 ~296 ~64 ~136 stone
fill ~288 ~65 ~136 ~296 ~67 ~136 dirt
fill ~288 ~68 ~136 ~296 ~68 ~136 grass_block
fill ~297 ~60 ~136 ~302 ~65 ~136 stone
fill ~297 ~66 ~136 ~302 ~68 ~136 dirt
fill ~297 ~69 ~136 ~302 ~69 ~136 grass_block
fill ~303 ~60 ~136 ~303 ~64 ~136 stone
fill ~303 ~65 ~136 ~303 ~67 ~136 dirt
fill ~303 ~68 ~136 ~303 ~68 ~136 grass_block
fill ~288 ~60 ~137 ~291 ~64 ~137 stone
fill ~288 ~65 ~137 ~291 ~67 ~137 dirt
fill ~288 ~68 ~137 ~291 ~68 ~137 grass_block
fill ~292 ~60 ~137 ~294 ~63 ~137 stone
fill ~292 ~64 ~137 ~294 ~66 ~137 dirt
fill ~292 ~67 ~137 ~294 ~67 ~137 grass_block
fill ~295 ~60 ~137 ~300 ~64 ~137 stone
fill ~295 ~65 ~137 ~300 ~67 ~137 dirt
fill ~295 ~68 ~137 ~300 ~68 ~137 grass_block
fill ~301 ~60 ~137 ~302 ~65 ~137 stone
fill ~301 ~66 ~137 ~302 ~68 ~137 dirt
fill ~301 ~69 ~137 ~302 ~69 ~137 grass_block
fill ~303 ~60 ~137 ~303 ~64 ~137 stone
fill ~303 ~65 ~137 ~303 ~67 ~137 dirt
fill ~303 ~68 ~137 ~303 ~68 ~137 grass_block
fill ~288 ~60 ~138 ~291 ~64 ~138 stone
fill ~288 ~65 ~138 ~291 ~67 ~138 dirt
fill ~288 ~68 ~138 ~291 ~68 ~138 grass_block
fill ~292 ~60 ~138 ~295 ~63 ~138 stone
fill ~292 ~64 ~138 ~295 ~66 ~138 dirt
fill ~292 ~67 ~138 ~295 ~67 ~138 grass_block
fill ~296 ~60 ~138 ~303 ~64 ~138 stone
fill ~296 ~65 ~138 ~303 ~67 ~138 dirt
fill ~296 ~68 ~138 ~303 ~68 ~138 grass_block
fill ~288 ~60 ~139 ~291 ~64 ~139 stone
fill ~288 ~65 ~139 ~291 ~67 ~139 dirt
fill ~288 ~68 ~139 ~291 ~68 ~139 grass_block
fill ~292 ~60 ~139 ~299 ~63 ~139 stone
fill ~292 ~64 ~139 ~299 ~66 ~139 dirt
fill ~292 ~67 ~139 ~299 ~67 ~139 grass_block
fill ~300 ~60 ~139 ~303 ~64 ~139 stone
fill ~300 ~65 ~139 ~303 ~67 ~139 dirt
fill ~300 ~68 ~139 ~303 ~68 ~139 grass_block
fill ~288 ~60 ~140 ~292 ~64 ~140 stone
fill ~288 ~65 ~140 ~292 ~67 ~140 dirt
fill ~288 ~68 ~140 ~292 ~68 ~140 grass_block
fill ~293 ~60 ~140 ~295 ~63 ~140 stone
fill ~293 ~64 ~140 ~295 ~66 ~140 dirt
fill ~293 ~67 ~140 ~295 ~67 ~140 grass_block
fill ~296 ~60 ~140 ~297 ~62 ~140 stone
fill ~296 ~63 ~140 ~297 ~65 ~140 dirt
fill ~296 ~66 ~140 ~297 ~66 ~140 grass_block
fill ~298 ~60 ~140 ~299 ~63 ~140 stone
fill ~298 ~64 ~140 ~299 ~66 ~140 dirt
fill ~298 ~67 ~140 ~299 ~67 ~140 grass_block
fill ~300 ~60 ~140 ~303 ~64 ~140 stone
fill ~300 ~65 ~140 ~303 ~67 ~140 dirt
fill ~300 ~68 ~140 ~303 ~68 ~140 grass_block
fill ~288 ~60 ~141 ~288 ~63 ~141 stone
fill ~288 ~64 ~141 ~288 ~66 ~141 dirt
fill ~288 ~67 ~141 ~288 ~67 ~141 grass_block
fill ~289 ~60 ~141 ~293 ~64 ~141 stone
fill ~289 ~65 ~141 ~293 ~67 ~141 dirt
fill ~289 ~68 ~141 ~293 ~68 ~141 grass_block
fill ~294 ~60 ~141 ~295 ~63 ~141 stone
fill ~294 ~64 ~141 ~295 ~66 ~141 dirt
fill ~294 ~67 ~141 ~295 ~67 ~141 grass_block
fill ~296 ~60 ~141 ~297 ~62 ~141 stone
fill ~296 ~63 ~141 ~297 ~65 ~141 dirt
fill ~296 ~66 ~141 ~297 ~66 ~141 grass_block
fill ~298 ~60 ~141 ~300 ~63 ~141 stone
fill ~298 ~64 ~141 ~300 ~66 ~141 dirt
fill ~298 ~67 ~141 ~300 ~67 ~141 grass_block
fill ~301 ~60 ~141 ~303 ~64 ~141 stone
fill ~301 ~65 ~141 ~303 ~67 ~141 dirt
fill ~301 ~68 ~141 ~303 ~68 ~141 grass_block
fill ~288 ~60 ~142 ~290 ~63 ~142 stone
fill ~288 ~64 ~142 ~290 ~66 ~142 dirt
fill ~288 ~67 ~142 ~290 ~67 ~142 grass_block
fill ~291 ~60 ~142 ~292 ~64 ~142 stone
fill ~291 ~65 ~142 ~292 ~67 ~142 dirt
fill ~291 ~68 ~142 ~292 ~68 ~142 grass_block
fill ~293 ~60 ~142 ~295 ~63 ~142 stone
fill ~293 ~64 ~142 ~295 ~66 ~142 dirt
fill ~293 ~67 ~142 ~295 ~67 ~142 grass_block
fill ~296 ~60 ~142 ~298 ~62 ~142 stone
fill ~296 ~63 ~142 ~298 ~65 ~142 dirt
fill ~296 ~66 ~142 ~298 ~66 ~142 grass_block
fill ~299 ~60 ~142 ~302 ~63 ~142 stone
fill ~299 ~64 ~142 ~302 ~66 ~142 dirt
fill ~299 ~67 ~142 ~302 ~67 ~142 grass_block
fill ~303 ~60 ~142 ~303 ~64 ~142 stone
fill ~303 ~65 ~142 ~303 ~67 ~142 dirt
fill ~303 ~68 ~142 ~303 ~68 ~142 grass_block
fill ~288 ~60 ~143 ~295 ~63 ~143 stone
fill ~288 ~64 ~143 ~295 ~66 ~143 dirt
fill ~288 ~67 ~143 ~295 ~67 ~143 grass_block
fill ~296 ~60 ~143 ~299 ~62 ~143 stone
fill ~296 ~63 ~143 ~299 ~65 ~143 dirt
fill ~296 ~66 ~143 ~299 ~66 ~143 grass_block
fill ~300 ~60 ~143 ~303 ~63 ~143 stone
fill ~300 ~64 ~143 ~303 ~66 ~143 dirt
fill ~300 ~67 ~143 ~303 ~67 ~143 grass_block