fill ~32 ~60 ~48 ~38 ~66 ~48 stone
fill ~32 ~67 ~48 ~38 ~69 ~48 dirt
fill ~32 ~70 ~48 ~38 ~70 ~48 grass_block
fill ~39 ~60 ~48 ~40 ~67 ~48 stone
fill ~39 ~68 ~48 ~40 ~70 ~48 dirt
fill ~39 ~71 ~48 ~40 ~71 ~48 grass_block
fill ~41 ~60 ~48 ~47 ~68 ~48 stone
fill ~41 ~69 ~48 ~47 ~71 ~48 dirt
fill ~41 ~72 ~48 ~47 ~72 ~48 grass_block
fill ~32 ~60 ~49 ~39 ~66 ~49 stone
fill ~32 ~67 ~49 ~39 ~69 ~49 dirt
fill ~32 ~70 ~49 ~39 ~70 ~49 grass_block
fill ~40 ~60 ~49 ~45 ~67 ~49 stone
fill ~40 ~68 ~49 ~45 ~70 ~49 dirt
fill ~40 ~71 ~49 ~45 ~71 ~49 grass_block
fill ~46 ~60 ~49 ~47 ~68 ~49 stone
fill ~46 ~69 ~49 ~47 ~71 ~49 dirt
fill ~46 ~72 ~49 ~47 ~72 ~49 grass_block
fill ~32 ~60 ~50 ~34 ~65 ~50 stone
fill ~32 ~66 ~50 ~34 ~68 ~50 dirt
fill ~32 ~69 ~50 ~34 ~69 ~50 grass_block
fill ~35 ~60 ~50 ~36 ~66 ~50 stone
fill ~35 ~67 ~50 ~36 ~69 ~50 dirt
fill ~35 ~70 ~50 ~36 ~70 ~50 grass_block
fill ~37 ~60 ~50 ~38 ~65 ~50 stone
fill ~37 ~66 ~50 ~38 ~68 ~50 dirt
fill ~37 ~69 ~50 ~38 ~69 ~50 grass_block
fill ~39 ~60 ~50 ~42 ~66 ~50 stone
fill ~39 ~67 ~50 ~42 ~69 ~50 dirt
fill ~39 ~70 ~50 ~42 ~70 ~50 grass_block
fill ~43 ~60 ~50 ~46 ~67 ~50 stone
fill ~43 ~68 ~50 ~46 ~70 ~50 dirt
fill ~43 ~71 ~50 ~46 ~71 ~50 grass_block
fill ~47 ~60 ~50 ~47 ~68 ~50 stone
fill ~47 ~69 ~50 ~47 ~71 ~50 dirt
fill ~47 ~72 ~50 ~47 ~72 ~50 grass_block
fill ~32 ~60 ~51 ~40 ~65 ~51 stone
fill ~32 ~66 ~51 ~40 ~68 ~51 dirt
fill ~32 ~69 ~51 ~40 ~69 ~51 grass_block
fill ~41 ~60 ~51 ~44 ~66 ~51 stone
fill ~41 ~67 ~51 ~44 ~69 ~51 dirt
fill ~41 ~70 ~51 ~44 ~70 ~51 grass_block
fill ~45 ~60 ~51 ~47 ~67 ~51 stone
fill ~45 ~68 ~51 ~47 ~70 ~51 dirt
fill ~45 ~71 ~51 ~47 ~71 ~51 grass_block
fill ~32 ~60 ~52 ~42 ~65 ~52 stone
fill ~32 ~66 ~52 ~42 ~68 ~52 dirt
fill ~32 ~69 ~52 ~42 ~69 ~52 grass_block
fill ~43 ~60 ~52 ~45 ~66 ~52 stone
fill ~43 ~67 ~52 ~45 ~69 ~52 dirt
fill ~43 ~70 ~52 ~45 ~70 ~52 grass_block
fill ~46 ~60 ~52 ~47 ~67 ~52 stone
fill ~46 ~68 ~52 ~47 ~70 ~52 dirt
fill ~46 ~71 ~52 ~47 ~71 ~52 grass_block
fill ~32 ~60 ~53 ~35 ~65 ~53 stone
fill ~32 ~66 ~53 ~35 ~68 ~53 dirt
fill ~32 ~69 ~53 ~35 ~69 ~53 grass_block
fill ~36 ~60 ~53 ~36 ~64 ~53 stone
fill ~36 ~65 ~53 ~36 ~67 ~53 dirt
fill ~36 ~68 ~53 ~36 ~68 ~53 grass_block
fill ~37 ~60 ~53 ~43 ~65 ~53 stone
fill ~37 ~66 ~53 ~43 ~68 ~53 dirt
fill ~37 ~69 ~53 ~43 ~69 ~53 grass_block
fill ~44 ~60 ~53 ~47 ~66 ~53 stone
fill ~44 ~67 ~53 ~47 ~69 ~53 dirt
fill ~44 ~70 ~53 ~47 ~70 ~53 grass_block
fill ~32 ~60 ~54 ~33 ~66 ~54 stone
fill ~32 ~67 ~54 ~33 ~69 ~54 dirt
fill ~32 ~70 ~54 ~33 ~70 ~54 grass_block
fill ~34 ~60 ~54 ~36 ~65 ~54 stone
fill ~34 ~66 ~54 ~36 ~68 ~54 dirt
fill ~34 ~69 ~54 ~36 ~69 ~54 grass_block
fill ~37 ~60 ~54 ~39 ~64 ~54 stone
fill ~37 ~65 ~54 ~39 ~67 ~54 dirt
fill ~37 ~68 ~54 ~39 ~68 ~54 grass_block
fill ~40 ~60 ~54 ~44 ~65 ~54 stone
fill ~40 ~66 ~54 ~44 ~68 ~54 dirt
fill ~40 ~69 ~54 ~44 ~69 ~54 grass_block
fill ~45 ~60 ~54 ~47 ~66 ~54 stone
fill ~45 ~67 ~54 ~47 ~69 ~54 dirt
fill ~45 ~70 ~54 ~47 ~70 ~54 grass_block
fill ~32 ~60 ~55 ~34 ~66 ~55 stone
fill ~32 ~67 ~55 ~34 ~69 ~55 dirt
fill ~32 ~70 ~55 ~34 ~70 ~55 grass_block
fill ~35 ~60 ~55 ~37 ~65 ~55 stone
fill ~35 ~66 ~55 ~37 ~68 ~55 dirt
fill ~35 ~69 ~55 ~37 ~69 ~55 grass_block
fill ~38 ~60 ~55 ~41 ~64 ~55 stone
fill ~38 ~65 ~55 ~41 ~67 ~55 dirt
fill ~38 ~68 ~55 ~41 ~68 ~55 grass_block
fill ~42 ~60 ~55 ~47 ~65 ~55 stone
fill ~42 ~66 ~55 ~47 ~68 ~55 dirt
fill ~42 ~69 ~55 ~47 ~69 ~55 grass_block
fill ~32 ~60 ~56 ~32 ~67 ~56 stone
fill ~32 ~68 ~56 ~32 ~70 ~56 dirt
fill ~32 ~71 ~56 ~32 ~71 ~56 grass_block
fill ~33 ~60 ~56 ~35 ~66 ~56 stone
fill ~33 ~67 ~56 ~35 ~69 ~56 dirt
fill ~33 ~70 ~56 ~35 ~70 ~56 grass_block
fill ~36 ~60 ~56 ~38 ~65 ~56 stone
fill ~36 ~66 ~56 ~38 ~68 ~56 dirt
fill ~36 ~69 ~56 ~38 ~69 ~56 grass_block
fill ~39 ~60 ~56 ~43 ~64 ~56 stone
fill ~39 ~65 ~56 ~43 ~67 ~56 dirt
fill ~39 ~68 ~56 ~43 ~68 ~56 grass_block
fill ~44 ~60 ~56 ~47 ~65 ~56 stone
fill ~44 ~66 ~56 ~47 ~68 ~56 dirt
fill ~44 ~69 ~56 ~47 ~69 ~56 grass_block
fill ~32 ~60 ~57 ~32 ~67 ~57 stone
fill ~32 ~68 ~57 ~32 ~70 ~57 dirt
fill ~32 ~71 ~57 ~32 ~71 ~57 grass_block
fill ~33 ~60 ~57 ~36 ~66 ~57 stone
fill ~33 ~67 ~57 ~36 ~69 ~57 dirt
fill ~33 ~70 ~57 ~36 ~70 ~57 grass_block
fill ~37 ~60 ~57 ~40 ~65 ~57 stone
fill ~37 ~66 ~57 ~40 ~68 ~57 dirt
fill ~37 ~69 ~57 ~40 ~69 ~57 grass_block
fill ~41 ~60 ~57 ~47 ~64 ~57 stone
fill ~41 ~65 ~57 ~47 ~67 ~57 dirt
fill ~41 ~68 ~57 ~47 ~68 ~57 grass_block
fill ~32 ~60 ~58 ~33 ~67 ~58 stone
fill ~32 ~68 ~58 ~33 ~70 ~58 dirt
fill ~32 ~71 ~58 ~33 ~71 ~58 grass_block
fill ~34 ~60 ~58 ~39 ~66 ~58 stone
fill ~34 ~67 ~58 ~39 ~69 ~58 dirt
fill ~34 ~70 ~58 ~39 ~70 ~58 grass_block
fill ~40 ~60 ~58 ~41 ~65 ~58 stone
fill ~40 ~66 ~58 ~41 ~68 ~58 dirt
fill ~40 ~69 ~58 ~41 ~69 ~58 grass_block
fill ~42 ~60 ~58 ~47 ~64 ~58 stone
fill ~42 ~65 ~58 ~47 ~67 ~58 dirt
fill ~42 ~68 ~58 ~47 ~68 ~58 grass_block
fill ~32 ~60 ~59 ~32 ~68 ~59 stone
fill ~32 ~69 ~59 ~32 ~71 ~59 dirt
fill ~32 ~72 ~59 ~32 ~72 ~59 grass_block
fill ~33 ~60 ~59 ~35 ~67 ~59 stone
fill ~33 ~68 ~59 ~35 ~70 ~59 dirt
fill ~33 ~71 ~59 ~35 ~71 ~59 grass_block
fill ~36 ~60 ~59 ~40 ~66 ~59 stone
fill ~36 ~67 ~59 ~40 ~69 ~59 dirt
fill ~36 ~70 ~59 ~40 ~70 ~59 grass_block
fill ~41 ~60 ~59 ~44 ~65 ~59 stone
fill ~41 ~66 ~59 ~44 ~68 ~59 dirt
fill ~41 ~69 ~59 ~44 ~69 ~59 grass_block
fill ~45 ~60 ~59 ~47 ~64 ~59 stone
fill ~45 ~65 ~59 ~47 ~67 ~59 dirt
fill ~45 ~68 ~59 ~47 ~68 ~59 grass_block
fill ~32 ~60 ~60 ~32 ~69 ~60 stone
fill ~32 ~70 ~60 ~32 ~72 ~60 dirt
fill ~32 ~73 ~60 ~32 ~73 ~60 grass_block
fill ~33 ~60 ~60 ~33 ~68 ~60 stone
fill ~33 ~69 ~60 ~33 ~71 ~60 dirt
fill ~33 ~72 ~60 ~33 ~72 ~60 grass_block
fill ~34 ~60 ~60 ~38 ~67 ~60 stone
fill ~34 ~68 ~60 ~38 ~70 ~60 dirt
fill ~34 ~71 ~60 ~38 ~71 ~60 grass_block
fill ~39 ~60 ~60 ~40 ~66 ~60 stone
fill ~39 ~67 ~60 ~40 ~69 ~60 dirt
fill ~39 ~70 ~60 ~40 ~70 ~60 grass_block
fill ~41 ~60 ~60 ~45 ~65 ~60 stone
fill ~41 ~66 ~60 ~45 ~68 ~60 dirt
fill ~41 ~69 ~60 ~45 ~69 ~60 grass_block
fill ~46 ~60 ~60 ~47 ~64 ~60 stone
fill ~46 ~65 ~60 ~47 ~67 ~60 dirt
fill ~46 ~68 ~60 ~47 ~68 ~60 grass_block
fill ~32 ~60 ~61 ~33 ~69 ~61 stone
fill ~32 ~70 ~61 ~33 ~72 ~61 dirt
fill ~32 ~73 ~61 ~33 ~73 ~61 grass_block
fill ~34 ~60 ~61 ~36 ~68 ~61 stone
fill ~34 ~69 ~61 ~36 ~71 ~61 dirt
fill ~34 ~72 ~61 ~36 ~72 ~61 grass_block
fill ~37 ~60 ~61 ~39 ~67 ~61 stone
fill ~37 ~68 ~61 ~39 ~70 ~61 dirt
fill ~37 ~71 ~61 ~39 ~71 ~61 grass_block
fill ~40 ~60 ~61 ~43 ~66 ~61 stone
fill ~40 ~67 ~61 ~43 ~69 ~61 dirt
fill ~40 ~70 ~61 ~43 ~70 ~61 grass_block
fill ~44 ~60 ~61 ~46 ~65 ~61 stone
fill ~44 ~66 ~61 ~46 ~68 ~61 dirt
fill ~44 ~69 ~61 ~46 ~69 ~61 grass_block
fill ~47 ~60 ~61 ~47 ~64 ~61 stone
fill ~47 ~65 ~61 ~47 ~67 ~61 dirt
fill ~47 ~68 ~61 ~47 ~68 ~61 grass_block
fill ~32 ~60 ~62 ~34 ~69 ~62 stone
fill ~32 ~70 ~62 ~34 ~72 ~62 dirt
fill ~32 ~73 ~62 ~34 ~73 ~62 grass_block
fill ~35 ~60 ~62 ~37 ~68 ~62 stone
fill ~35 ~69 ~62 ~37 ~71 ~62 dirt
fill ~35 ~72 ~62 ~37 ~72 ~62 grass_block
fill ~38 ~60 ~62 ~39 ~67 ~62 stone
fill ~38 ~68 ~62 ~39 ~70 ~62 dirt
fill ~38 ~71 ~62 ~39 ~71 ~62 grass_block
fill ~40 ~60 ~62 ~43 ~66 ~62 stone
fill ~40 ~67 ~62 ~43 ~69 ~62 dirt
fill ~40 ~70 ~62 ~43 ~70 ~62 grass_block
fill ~44 ~60 ~62 ~46 ~65 ~62 stone
fill ~44 ~66 ~62 ~46 ~68 ~62 dirt
fill ~44 ~69 ~62 ~46 ~69 ~62 grass_block
fill ~47 ~60 ~62 ~47 ~64 ~62 stone
fill ~47 ~65 ~62 ~47 ~67 ~62 dirt
fill ~47 ~68 ~62 ~47 ~68 ~62 grass_block
fill ~32 ~60 ~63 ~32 ~70 ~63 stone
fill ~32 ~71 ~63 ~32 ~73 ~63 dirt
fill ~32 ~74 ~63 ~32 ~74 ~63 grass_block
fill ~33 ~60 ~63 ~35 ~69 ~63 stone
fill ~33 ~70 ~63 ~35 ~72 ~63 dirt
fill ~33 ~73 ~63 ~35 ~73 ~63 grass_block
fill ~36 ~60 ~63 ~37 ~68 ~63 stone
fill ~36 ~69 ~63 ~37 ~71 ~63 dirt
fill ~36 ~72 ~63 ~37 ~72 ~63 grass_block
fill ~38 ~60 ~63 ~39 ~67 ~63 stone
fill ~38 ~68 ~63 ~39 ~70 ~63 dirt
fill ~38 ~71 ~63 ~39 ~71 ~63 grass_block
fill ~40 ~60 ~63 ~42 ~66 ~63 stone
fill ~40 ~67 ~63 ~42 ~69 ~63 dirt
fill ~40 ~70 ~63 ~42 ~70 ~63 grass_block
fill ~43 ~60 ~63 ~46 ~65 ~63 stone
fill ~43 ~66 ~63 ~46 ~68 ~63 dirt
fill ~43 ~69 ~63 ~46 ~69 ~63 grass_block
fill ~47 ~60 ~63 ~47 ~64 ~63 stone
fill ~47 ~65 ~63 ~47 ~67 ~63 dirt
fill ~47 ~68 ~63 ~47 ~68 ~63 grass_block