fill ~144 ~60 ~128 ~145 ~67 ~128 stone
fill ~144 ~68 ~128 ~145 ~70 ~128 dirt
fill ~144 ~71 ~128 ~145 ~71 ~128 grass_block
fill ~146 ~60 ~128 ~151 ~66 ~128 stone
fill ~146 ~67 ~128 ~151 ~69 ~128 dirt
fill ~146 ~70 ~128 ~151 ~70 ~128 grass_block
fill ~152 ~60 ~128 ~157 ~65 ~128 stone
fill ~152 ~66 ~128 ~157 ~68 ~128 dirt
fill ~152 ~69 ~128 ~157 ~69 ~128 grass_block
fill ~158 ~60 ~128 ~159 ~64 ~128 stone
fill ~158 ~65 ~128 ~159 ~67 ~128 dirt
fill ~158 ~68 ~128 ~159 ~68 ~128 grass_block
fill ~144 ~60 ~129 ~152 ~66 ~129 stone
fill ~144 ~67 ~129 ~152 ~69 ~129 dirt
fill ~144 ~70 ~129 ~152 ~70 ~129 grass_block
fill ~153 ~60 ~129 ~157 ~65 ~129 stone
fill ~153 ~66 ~129 ~157 ~68 ~129 dirt
fill ~153 ~69 ~129 ~157 ~69 ~129 grass_block
fill ~158 ~60 ~129 ~159 ~64 ~129 stone
fill ~158 ~65 ~129 ~159 ~67 ~129 dirt
fill ~158 ~68 ~129 ~159 ~68 ~129 grass_block
fill ~144 ~60 ~130 ~146 ~65 ~130 stone
fill ~144 ~66 ~130 ~146 ~68 ~130 dirt
fill ~144 ~69 ~130 ~146 ~69 ~130 grass_block
fill ~147 ~60 ~130 ~152 ~66 ~130 stone
fill ~147 ~67 ~130 ~152 ~69 ~130 dirt
fill ~147 ~70 ~130 ~152 ~70 ~130 grass_block
fill ~153 ~60 ~130 ~156 ~65 ~130 stone
fill ~153 ~66 ~130 ~156 ~68 ~130 dirt
fill ~153 ~69 ~130 ~156 ~69 ~130 grass_block
fill ~157 ~60 ~130 ~159 ~64 ~130 stone
fill ~157 ~65 ~130 ~159 ~67 ~130 dirt
fill ~157 ~68 ~130 ~159 ~68 ~130 grass_block
fill ~144 ~60 ~131 ~146 ~65 ~131 stone
fill ~144 ~66 ~131 ~146 ~68 ~131 dirt
fill ~144 ~69 ~131 ~146 ~69 ~131 grass_block
fill ~147 ~60 ~131 ~151 ~66 ~131 stone
fill ~147 ~67 ~131 ~151 ~69 ~131 dirt
fill ~147 ~70 ~131 ~151 ~70 ~131 grass_block
fill ~152 ~60 ~131 ~156 ~65 ~131 stone
fill ~152 ~66 ~131 ~156 ~68 ~131 dirt
fill ~152 ~69 ~131 ~156 ~69 ~131 grass_block
fill ~157 ~60 ~131 ~159 ~64 ~131 stone
fill ~157 ~65 ~131 ~159 ~67 ~131 dirt
fill ~157 ~68 ~131 ~159 ~68 ~131 grass_block
fill ~144 ~60 ~132 ~147 ~65 ~132 stone
fill ~144 ~66 ~132 ~147 ~68 ~132 dirt
fill ~144 ~69 ~132 ~147 ~69 ~132 grass_block
fill ~148 ~60 ~132 ~151 ~66 ~132 stone
fill ~148 ~67 ~132 ~151 ~69 ~132 dirt
fill ~148 ~70 ~132 ~151 ~70 ~132 grass_block
fill ~152 ~60 ~132 ~155 ~65 ~132 stone
fill ~152 ~66 ~132 ~155 ~68 ~132 dirt
fill ~152 ~69 ~132 ~155 ~69 ~132 grass_block
fill ~156 ~60 ~132 ~159 ~64 ~132 stone
fill ~156 ~65 ~132 ~159 ~67 ~132 dirt
fill ~156 ~68 ~132 ~159 ~68 ~132 grass_block
fill ~144 ~60 ~133 ~145 ~64 ~133 stone
fill ~144 ~65 ~133 ~145 ~67 ~133 dirt
fill ~144 ~68 ~133 ~145 ~68 ~133 grass_block
fill ~146 ~60 ~133 ~147 ~65 ~133 stone
fill ~146 ~66 ~133 ~147 ~68 ~133 dirt
fill ~146 ~69 ~133 ~147 ~69 ~133 grass_block
fill ~148 ~60 ~133 ~151 ~66 ~133 stone
fill ~148 ~67 ~133 ~151 ~69 ~133 dirt
fill ~148 ~70 ~133 ~151 ~70 ~133 grass_block
fill ~152 ~60 ~133 ~154 ~65 ~133 stone
fill ~152 ~66 ~133 ~154 ~68 ~133 dirt
fill ~152 ~69 ~133 ~154 ~69 ~133 grass_block
fill ~155 ~60 ~133 ~158 ~64 ~133 stone
fill ~155 ~65 ~133 ~158 ~67 ~133 dirt
fill ~155 ~68 ~133 ~158 ~68 ~133 grass_block
fill ~159 ~60 ~133 ~159 ~63 ~133 stone
fill ~159 ~64 ~133 ~159 ~66 ~133 dirt
fill ~159 ~67 ~133 ~159 ~67 ~133 grass_block
fill ~144 ~60 ~134 ~145 ~64 ~134 stone
fill ~144 ~65 ~134 ~145 ~67 ~134 dirt
fill ~144 ~68 ~134 ~145 ~68 ~134 grass_block
fill ~146 ~60 ~134 ~146 ~65 ~134 stone
fill ~146 ~66 ~134 ~146 ~68 ~134 dirt
fill ~146 ~69 ~134 ~146 ~69 ~134 grass_block
fill ~147 ~60 ~134 ~152 ~66 ~134 stone
fill ~147 ~67 ~134 ~152 ~69 ~134 dirt
fill ~147 ~70 ~134 ~152 ~70 ~134 grass_block
fill ~153 ~60 ~134 ~154 ~65 ~134 stone
fill ~153 ~66 ~134 ~154 ~68 ~134 dirt
fill ~153 ~69 ~134 ~154 ~69 ~134 grass_block
fill ~155 ~60 ~134 ~159 ~64 ~134 stone
fill ~155 ~65 ~134 ~159 ~67 ~134 dirt
fill ~155 ~68 ~134 ~159 ~68 ~134 grass_block
fill ~144 ~60 ~135 ~145 ~64 ~135 stone
fill ~144 ~65 ~135 ~145 ~67 ~135 dirt
fill ~144 ~68 ~135 ~145 ~68 ~135 grass_block
fill ~146 ~60 ~135 ~146 ~65 ~135 stone
fill ~146 ~66 ~135 ~146 ~68 ~135 dirt
fill ~146 ~69 ~135 ~146 ~69 ~135 grass_block
fill ~147 ~60 ~135 ~148 ~66 ~135 stone
fill ~147 ~67 ~135 ~148 ~69 ~135 dirt
fill ~147 ~70 ~135 ~148 ~70 ~135 grass_block
fill ~149 ~60 ~135 ~149 ~67 ~135 stone
fill ~149 ~68 ~135 ~149 ~70 ~135 dirt
fill ~149 ~71 ~135 ~149 ~71 ~135 grass_block
fill ~150 ~60 ~135 ~152 ~66 ~135 stone
fill ~150 ~67 ~135 ~152 ~69 ~135 dirt
fill ~150 ~70 ~135 ~152 ~70 ~135 grass_block
fill ~153 ~60 ~135 ~154 ~65 ~135 stone
fill ~153 ~66 ~135 ~154 ~68 ~135 dirt
fill ~153 ~69 ~135 ~154 ~69 ~135 grass_block
fill ~155 ~60 ~135 ~159 ~64 ~135 stone
fill ~155 ~65 ~135 ~159 ~67 ~135 dirt
fill ~155 ~68 ~135 ~159 ~68 ~135 grass_block
fill ~144 ~60 ~136 ~144 ~64 ~136 stone
fill ~144 ~65 ~136 ~144 ~67 ~136 dirt
fill ~144 ~68 ~136 ~144 ~68 ~136 grass_block
fill ~145 ~60 ~136 ~145 ~65 ~136 stone
fill ~145 ~66 ~136 ~145 ~68 ~136 dirt
fill ~145 ~69 ~136 ~145 ~69 ~136 grass_block
fill ~146 ~60 ~136 ~149 ~66 ~136 stone
fill ~146 ~67 ~136 ~149 ~69 ~136 dirt
fill ~146 ~70 ~136 ~149 ~70 ~136 grass_block
fill ~150 ~60 ~136 ~150 ~67 ~136 stone
fill ~150 ~68 ~136 ~150 ~70 ~136 dirt
fill ~150 ~71 ~136 ~150 ~71 ~136 grass_block
fill ~151 ~60 ~136 ~152 ~66 ~136 stone
fill ~151 ~67 ~136 ~152 ~69 ~136 dirt
fill ~151 ~70 ~136 ~152 ~70 ~136 grass_block
fill ~153 ~60 ~136 ~157 ~65 ~136 stone
fill ~153 ~66 ~136 ~157 ~68 ~136 dirt
fill ~153 ~69 ~136 ~157 ~69 ~136 grass_block
fill ~158 ~60 ~136 ~159 ~64 ~136 stone
fill ~158 ~65 ~136 ~159 ~67 ~136 dirt
fill ~158 ~68 ~136 ~159 ~68 ~136 grass_block
fill ~144 ~60 ~137 ~144 ~64 ~137 stone
fill ~144 ~65 ~137 ~144 ~67 ~137 dirt
fill ~144 ~68 ~137 ~144 ~68 ~137 grass_block
fill ~145 ~60 ~137 ~148 ~65 ~137 stone
fill ~145 ~66 ~137 ~148 ~68 ~137 dirt
fill ~145 ~69 ~137 ~148 ~69 ~137 grass_block
fill ~149 ~60 ~137 ~150 ~66 ~137 stone
fill ~149 ~67 ~137 ~150 ~69 ~137 dirt
fill ~149 ~70 ~137 ~150 ~70 ~137 grass_block
fill ~151 ~60 ~137 ~152 ~67 ~137 stone
fill ~151 ~68 ~137 ~152 ~70 ~137 dirt
fill ~151 ~71 ~137 ~152 ~71 ~137 grass_block
fill ~153 ~60 ~137 ~155 ~66 ~137 stone
fill ~153 ~67 ~137 ~155 ~69 ~137 dirt
fill ~153 ~70 ~137 ~155 ~70 ~137 grass_block
fill ~156 ~60 ~137 ~158 ~65 ~137 stone
fill ~156 ~66 ~137 ~158 ~68 ~137 dirt
fill ~156 ~69 ~137 ~158 ~69 ~137 grass_block
fill ~159 ~60 ~137 ~159 ~64 ~137 stone
fill ~159 ~65 ~137 ~159 ~67 ~137 dirt
fill ~159 ~68 ~137 ~159 ~68 ~137 grass_block
fill ~144 ~60 ~138 ~145 ~64 ~138 stone
fill ~144 ~65 ~138 ~145 ~67 ~138 dirt
fill ~144 ~68 ~138 ~145 ~68 ~138 grass_block
fill ~146 ~60 ~138 ~146 ~65 ~138 stone
fill ~146 ~66 ~138 ~146 ~68 ~138 dirt
fill ~146 ~69 ~138 ~146 ~69 ~138 grass_block
fill ~147 ~60 ~138 ~149 ~66 ~138 stone
fill ~147 ~67 ~138 ~149 ~69 ~138 dirt
fill ~147 ~70 ~138 ~149 ~70 ~138 grass_block
fill ~150 ~60 ~138 ~153 ~67 ~138 stone
fill ~150 ~68 ~138 ~153 ~70 ~138 dirt
fill ~150 ~71 ~138 ~153 ~71 ~138 grass_block
fill ~154 ~60 ~138 ~155 ~66 ~138 stone
fill ~154 ~67 ~138 ~155 ~69 ~138 dirt
fill ~154 ~70 ~138 ~155 ~70 ~138 grass_block
fill ~156 ~60 ~138 ~158 ~65 ~138 stone
fill ~156 ~66 ~138 ~158 ~68 ~138 dirt
fill ~156 ~69 ~138 ~158 ~69 ~138 grass_block
fill ~159 ~60 ~138 ~159 ~64 ~138 stone
fill ~159 ~65 ~138 ~159 ~67 ~138 dirt
fill ~159 ~68 ~138 ~159 ~68 ~138 grass_block
fill ~144 ~60 ~139 ~146 ~65 ~139 stone
fill ~144 ~66 ~139 ~146 ~68 ~139 dirt
fill ~144 ~69 ~139 ~146 ~69 ~139 grass_block
fill ~147 ~60 ~139 ~148 ~66 ~139 stone
fill ~147 ~67 ~139 ~148 ~69 ~139 dirt
fill ~147 ~70 ~139 ~148 ~70 ~139 grass_block
fill ~149 ~60 ~139 ~154 ~67 ~139 stone
fill ~149 ~68 ~139 ~154 ~70 ~139 dirt
fill ~149 ~71 ~139 ~154 ~71 ~139 grass_block
fill ~155 ~60 ~139 ~155 ~66 ~139 stone
fill ~155 ~67 ~139 ~155 ~69 ~139 dirt
fill ~155 ~70 ~139 ~155 ~70 ~139 grass_block
fill ~156 ~60 ~139 ~158 ~65 ~139 stone
fill ~156 ~66 ~139 ~158 ~68 ~139 dirt
fill ~156 ~69 ~139 ~158 ~69 ~139 grass_block
fill ~159 ~60 ~139 ~159 ~64 ~139 stone
fill ~159 ~65 ~139 ~159 ~67 ~139 dirt
fill ~159 ~68 ~139 ~159 ~68 ~139 grass_block
fill ~144 ~60 ~140 ~144 ~65 ~140 stone
fill ~144 ~66 ~140 ~144 ~68 ~140 dirt
fill ~144 ~69 ~140 ~144 ~69 ~140 grass_block
fill ~145 ~60 ~140 ~147 ~66 ~140 stone
fill ~145 ~67 ~140 ~147 ~69 ~140 dirt
fill ~145 ~70 ~140 ~147 ~70 ~140 grass_block
fill ~148 ~60 ~140 ~154 ~67 ~140 stone
fill ~148 ~68 ~140 ~154 ~70 ~140 dirt
fill ~148 ~71 ~140 ~154 ~71 ~140 grass_block
fill ~155 ~60 ~140 ~156 ~66 ~140 stone
fill ~155 ~67 ~140 ~156 ~69 ~140 dirt
fill ~155 ~70 ~140 ~156 ~70 ~140 grass_block
fill ~157 ~60 ~140 ~159 ~65 ~140 stone
fill ~157 ~66 ~140 ~159 ~68 ~140 dirt
fill ~157 ~69 ~140 ~159 ~69 ~140 grass_block
fill ~144 ~60 ~141 ~148 ~66 ~141 stone
fill ~144 ~67 ~141 ~148 ~69 ~141 dirt
fill ~144 ~70 ~141 ~148 ~70 ~141 grass_block
fill ~149 ~60 ~141 ~154 ~67 ~141 stone
fill ~149 ~68 ~141 ~154 ~70 ~141 dirt
fill ~149 ~71 ~141 ~154 ~71 ~141 grass_block
fill ~155 ~60 ~141 ~158 ~66 ~141 stone
fill ~155 ~67 ~141 ~158 ~69 ~141 dirt
fill ~155 ~70 ~141 ~158 ~70 ~141 grass_block
fill ~159 ~60 ~141 ~159 ~65 ~141 stone
fill ~159 ~66 ~141 ~159 ~68 ~141 dirt
fill ~159 ~69 ~141 ~159 ~69 ~141 grass_block
fill ~144 ~60 ~142 ~144 ~65 ~142 stone
fill ~144 ~66 ~142 ~144 ~68 ~142 dirt
fill ~144 ~69 ~142 ~144 ~69 ~142 grass_block
fill ~145 ~60 ~142 ~149 ~66 ~142 stone
fill ~145 ~67 ~142 ~149 ~69 ~142 dirt
fill ~145 ~70 ~142 ~149 ~70 ~142 grass_block
fill ~150 ~60 ~142 ~154 ~67 ~142 stone
fill ~150 ~68 ~142 ~154 ~70 ~142 dirt
fill ~150 ~71 ~142 ~154 ~71 ~142 grass_block
fill ~155 ~60 ~142 ~159 ~66 ~142 stone
fill ~155 ~67 ~142 ~159 ~69 ~142 dirt
fill ~155 ~70 ~142 ~159 ~70 ~142 grass_block
fill ~144 ~60 ~143 ~144 ~65 ~143 stone
fill ~144 ~66 ~143 ~144 ~68 ~143 dirt
fill ~144 ~69 ~143 ~144 ~69 ~143 grass_block
fill ~145 ~60 ~143 ~159 ~66 ~143 stone
fill ~145 ~67 ~143 ~159 ~69 ~143 dirt
fill ~145 ~70 ~143 ~159 ~70 ~143 grass_block