fill ~304 ~60 ~64 ~304 ~63 ~64 stone
fill ~304 ~64 ~64 ~304 ~66 ~64 dirt
fill ~304 ~67 ~64 ~304 ~67 ~64 grass_block
fill ~305 ~60 ~64 ~305 ~62 ~64 stone
fill ~305 ~63 ~64 ~305 ~65 ~64 dirt
fill ~305 ~66 ~64 ~305 ~66 ~64 grass_block
fill ~306 ~60 ~64 ~306 ~63 ~64 stone
fill ~306 ~64 ~64 ~306 ~66 ~64 dirt
fill ~306 ~67 ~64 ~306 ~67 ~64 grass_block
fill ~307 ~60 ~64 ~313 ~62 ~64 stone
fill ~307 ~63 ~64 ~313 ~65 ~64 dirt
fill ~307 ~66 ~64 ~313 ~66 ~64 grass_block
fill ~314 ~60 ~64 ~317 ~61 ~64 stone
fill ~314 ~62 ~64 ~317 ~64 ~64 dirt
fill ~314 ~65 ~64 ~317 ~65 ~64 grass_block
fill ~318 ~60 ~64 ~319 ~62 ~64 stone
fill ~318 ~63 ~64 ~319 ~65 ~64 dirt
fill ~318 ~66 ~64 ~319 ~66 ~64 grass_block
fill ~304 ~60 ~65 ~304 ~63 ~65 stone
fill ~304 ~64 ~65 ~304 ~66 ~65 dirt
fill ~304 ~67 ~65 ~304 ~67 ~65 grass_block
fill ~305 ~60 ~65 ~313 ~62 ~65 stone
fill ~305 ~63 ~65 ~313 ~65 ~65 dirt
fill ~305 ~66 ~65 ~313 ~66 ~65 grass_block
fill ~314 ~60 ~65 ~317 ~61 ~65 stone
fill ~314 ~62 ~65 ~317 ~64 ~65 dirt
fill ~314 ~65 ~65 ~317 ~65 ~65 grass_block
fill ~318 ~60 ~65 ~319 ~62 ~65 stone
fill ~318 ~63 ~65 ~319 ~65 ~65 dirt
fill ~318 ~66 ~65 ~319 ~66 ~65 grass_block
fill ~304 ~60 ~66 ~305 ~63 ~66 stone
fill ~304 ~64 ~66 ~305 ~66 ~66 dirt
fill ~304 ~67 ~66 ~305 ~67 ~66 grass_block
fill ~306 ~60 ~66 ~313 ~62 ~66 stone
fill ~306 ~63 ~66 ~313 ~65 ~66 dirt
fill ~306 ~66 ~66 ~313 ~66 ~66 grass_block
fill ~314 ~60 ~66 ~317 ~61 ~66 stone
fill ~314 ~62 ~66 ~317 ~64 ~66 dirt
fill ~314 ~65 ~66 ~317 ~65 ~66 grass_block
fill ~318 ~60 ~66 ~319 ~62 ~66 stone
fill ~318 ~63 ~66 ~319 ~65 ~66 dirt
fill ~318 ~66 ~66 ~319 ~66 ~66 grass_block
fill ~304 ~60 ~67 ~304 ~62 ~67 stone
fill ~304 ~63 ~67 ~304 ~65 ~67 dirt
fill ~304 ~66 ~67 ~304 ~66 ~67 grass_block
fill ~305 ~60 ~67 ~305 ~63 ~67 stone
fill ~305 ~64 ~67 ~305 ~66 ~67 dirt
fill ~305 ~67 ~67 ~305 ~67 ~67 grass_block
fill ~306 ~60 ~67 ~312 ~62 ~67 stone
fill ~306 ~63 ~67 ~312 ~65 ~67 dirt
fill ~306 ~66 ~67 ~312 ~66 ~67 grass_block
fill ~313 ~60 ~67 ~317 ~61 ~67 stone
fill ~313 ~62 ~67 ~317 ~64 ~67 dirt
fill ~313 ~65 ~67 ~317 ~65 ~67 grass_block
fill ~318 ~60 ~67 ~319 ~62 ~67 stone
fill ~318 ~63 ~67 ~319 ~65 ~67 dirt
fill ~318 ~66 ~67 ~319 ~66 ~67 grass_block
fill ~304 ~60 ~68 ~312 ~62 ~68 stone
fill ~304 ~63 ~68 ~312 ~65 ~68 dirt
fill ~304 ~66 ~68 ~312 ~66 ~68 grass_block
fill ~313 ~60 ~68 ~317 ~61 ~68 stone
fill ~313 ~62 ~68 ~317 ~64 ~68 dirt
fill ~313 ~65 ~68 ~317 ~65 ~68 grass_block
fill ~318 ~60 ~68 ~318 ~62 ~68 stone
fill ~318 ~63 ~68 ~318 ~65 ~68 dirt
fill ~318 ~66 ~68 ~318 ~66 ~68 grass_block
fill ~319 ~60 ~68 ~319 ~63 ~68 stone
fill ~319 ~64 ~68 ~319 ~66 ~68 dirt
fill ~319 ~67 ~68 ~319 ~67 ~68 grass_block
fill ~304 ~60 ~69 ~304 ~61 ~69 stone
fill ~304 ~62 ~69 ~304 ~64 ~69 dirt
fill ~304 ~65 ~69 ~304 ~65 ~69 grass_block
fill ~305 ~60 ~69 ~312 ~62 ~69 stone
fill ~305 ~63 ~69 ~312 ~65 ~69 dirt
fill ~305 ~66 ~69 ~312 ~66 ~69 grass_block
fill ~313 ~60 ~69 ~316 ~61 ~69 stone
fill ~313 ~62 ~69 ~316 ~64 ~69 dirt
fill ~313 ~65 ~69 ~316 ~65 ~69 grass_block
fill ~317 ~60 ~69 ~319 ~62 ~69 stone
fill ~317 ~63 ~69 ~319 ~65 ~69 dirt
fill ~317 ~66 ~69 ~319 ~66 ~69 grass_block
fill ~304 ~60 ~70 ~306 ~61 ~70 stone
fill ~304 ~62 ~70 ~306 ~64 ~70 dirt
fill ~304 ~65 ~70 ~306 ~65 ~70 grass_block
fill ~307 ~60 ~70 ~313 ~62 ~70 stone
fill ~307 ~63 ~70 ~313 ~65 ~70 dirt
fill ~307 ~66 ~70 ~313 ~66 ~70 grass_block
fill ~314 ~60 ~70 ~317 ~61 ~70 stone
fill ~314 ~62 ~70 ~317 ~64 ~70 dirt
fill ~314 ~65 ~70 ~317 ~65 ~70 grass_block
fill ~318 ~60 ~70 ~319 ~62 ~70 stone
fill ~318 ~63 ~70 ~319 ~65 ~70 dirt
fill ~318 ~66 ~70 ~319 ~66 ~70 grass_block
fill ~304 ~60 ~71 ~308 ~61 ~71 stone
fill ~304 ~62 ~71 ~308 ~64 ~71 dirt
fill ~304 ~65 ~71 ~308 ~65 ~71 grass_block
fill ~309 ~60 ~71 ~313 ~62 ~71 stone
fill ~309 ~63 ~71 ~313 ~65 ~71 dirt
fill ~309 ~66 ~71 ~313 ~66 ~71 grass_block
fill ~314 ~60 ~71 ~317 ~61 ~71 stone
fill ~314 ~62 ~71 ~317 ~64 ~71 dirt
fill ~314 ~65 ~71 ~317 ~65 ~71 grass_block
fill ~318 ~60 ~71 ~319 ~62 ~71 stone
fill ~318 ~63 ~71 ~319 ~65 ~71 dirt
fill ~318 ~66 ~71 ~319 ~66 ~71 grass_block
fill ~304 ~60 ~72 ~309 ~61 ~72 stone
fill ~304 ~62 ~72 ~309 ~64 ~72 dirt
fill ~304 ~65 ~72 ~309 ~65 ~72 grass_block
fill ~310 ~60 ~72 ~313 ~62 ~72 stone
fill ~310 ~63 ~72 ~313 ~65 ~72 dirt
fill ~310 ~66 ~72 ~313 ~66 ~72 grass_block
fill ~314 ~60 ~72 ~318 ~61 ~72 stone
fill ~314 ~62 ~72 ~318 ~64 ~72 dirt
fill ~314 ~65 ~72 ~318 ~65 ~72 grass_block
fill ~319 ~60 ~72 ~319 ~62 ~72 stone
fill ~319 ~63 ~72 ~319 ~65 ~72 dirt
fill ~319 ~66 ~72 ~319 ~66 ~72 grass_block
fill ~304 ~60 ~73 ~311 ~61 ~73 stone
fill ~304 ~62 ~73 ~311 ~64 ~73 dirt
fill ~304 ~65 ~73 ~311 ~65 ~73 grass_block
fill ~312 ~60 ~73 ~313 ~62 ~73 stone
fill ~312 ~63 ~73 ~313 ~65 ~73 dirt
fill ~312 ~66 ~73 ~313 ~66 ~73 grass_block
fill ~314 ~60 ~73 ~319 ~61 ~73 stone
fill ~314 ~62 ~73 ~319 ~64 ~73 dirt
fill ~314 ~65 ~73 ~319 ~65 ~73 grass_block
fill ~304 ~60 ~74 ~319 ~61 ~74 stone
fill ~304 ~62 ~74 ~319 ~64 ~74 dirt
fill ~304 ~65 ~74 ~319 ~65 ~74 grass_block
fill ~304 ~60 ~75 ~319 ~61 ~75 stone
fill ~304 ~62 ~75 ~319 ~64 ~75 dirt
fill ~304 ~65 ~75 ~319 ~65 ~75 grass_block
fill ~304 ~60 ~76 ~305 ~61 ~76 stone
fill ~304 ~62 ~76 ~305 ~64 ~76 dirt
fill ~304 ~65 ~76 ~305 ~65 ~76 grass_block
fill ~306 ~60 ~76 ~307 ~60 ~76 stone
fill ~306 ~61 ~76 ~307 ~63 ~76 dirt
fill ~306 ~64 ~76 ~307 ~64 ~76 grass_block
fill ~308 ~60 ~76 ~319 ~61 ~76 stone
fill ~308 ~62 ~76 ~319 ~64 ~76 dirt
fill ~308 ~65 ~76 ~319 ~65 ~76 grass_block
fill ~304 ~60 ~77 ~305 ~60 ~77 stone
fill ~304 ~61 ~77 ~305 ~63 ~77 dirt
fill ~304 ~64 ~77 ~305 ~64 ~77 grass_block
fill ~306 ~60 ~77 ~319 ~61 ~77 stone
fill ~306 ~62 ~77 ~319 ~64 ~77 dirt
fill ~306 ~65 ~77 ~319 ~65 ~77 grass_block
fill ~304 ~60 ~78 ~305 ~60 ~78 stone
fill ~304 ~61 ~78 ~305 ~63 ~78 dirt
fill ~304 ~64 ~78 ~305 ~64 ~78 grass_block
fill ~306 ~60 ~78 ~319 ~61 ~78 stone
fill ~306 ~62 ~78 ~319 ~64 ~78 dirt
fill ~306 ~65 ~78 ~319 ~65 ~78 grass_block
fill ~304 ~60 ~79 ~308 ~61 ~79 stone
fill ~304 ~62 ~79 ~308 ~64 ~79 dirt
fill ~304 ~65 ~79 ~308 ~65 ~79 grass_block
fill ~309 ~60 ~79 ~309 ~60 ~79 stone
fill ~309 ~61 ~79 ~309 ~63 ~79 dirt
fill ~309 ~64 ~79 ~309 ~64 ~79 grass_block
fill ~310 ~60 ~79 ~319 ~61 ~79 stone
fill ~310 ~62 ~79 ~319 ~64 ~79 dirt
fill ~310 ~65 ~79 ~319 ~65 ~79 grass_block