fill ~448 ~60 ~128 ~455 ~63 ~128 stone
fill ~448 ~64 ~128 ~455 ~66 ~128 dirt
fill ~448 ~67 ~128 ~455 ~67 ~128 grass_block
fill ~456 ~60 ~128 ~456 ~62 ~128 stone
fill ~456 ~63 ~128 ~456 ~65 ~128 dirt
fill ~456 ~66 ~128 ~456 ~66 ~128 grass_block
fill ~457 ~60 ~128 ~461 ~63 ~128 stone
fill ~457 ~64 ~128 ~461 ~66 ~128 dirt
fill ~457 ~67 ~128 ~461 ~67 ~128 grass_block
fill ~462 ~60 ~128 ~463 ~64 ~128 stone
fill ~462 ~65 ~128 ~463 ~67 ~128 dirt
fill ~462 ~68 ~128 ~463 ~68 ~128 grass_block
fill ~448 ~60 ~129 ~450 ~63 ~129 stone
fill ~448 ~64 ~129 ~450 ~66 ~129 dirt
fill ~448 ~67 ~129 ~450 ~67 ~129 grass_block
fill ~451 ~60 ~129 ~451 ~62 ~129 stone
fill ~451 ~63 ~129 ~451 ~65 ~129 dirt
fill ~451 ~66 ~129 ~451 ~66 ~129 grass_block
fill ~452 ~60 ~129 ~452 ~63 ~129 stone
fill ~452 ~64 ~129 ~452 ~66 ~129 dirt
fill ~452 ~67 ~129 ~452 ~67 ~129 grass_block
fill ~453 ~60 ~129 ~457 ~62 ~129 stone
fill ~453 ~63 ~129 ~457 ~65 ~129 dirt
fill ~453 ~66 ~129 ~457 ~66 ~129 grass_block
fill ~458 ~60 ~129 ~461 ~63 ~129 stone
fill ~458 ~64 ~129 ~461 ~66 ~129 dirt
fill ~458 ~67 ~129 ~461 ~67 ~129 grass_block
fill ~462 ~60 ~129 ~463 ~64 ~129 stone
fill ~462 ~65 ~129 ~463 ~67 ~129 dirt
fill ~462 ~68 ~129 ~463 ~68 ~129 grass_block
fill ~448 ~60 ~130 ~448 ~63 ~130 stone
fill ~448 ~64 ~130 ~448 ~66 ~130 dirt
fill ~448 ~67 ~130 ~448 ~67 ~130 grass_block
fill ~449 ~60 ~130 ~456 ~62 ~130 stone
fill ~449 ~63 ~130 ~456 ~65 ~130 dirt
fill ~449 ~66 ~130 ~456 ~66 ~130 grass_block
fill ~457 ~60 ~130 ~461 ~63 ~130 stone
fill ~457 ~64 ~130 ~461 ~66 ~130 dirt
fill ~457 ~67 ~130 ~461 ~67 ~130 grass_block
fill ~462 ~60 ~130 ~463 ~64 ~130 stone
fill ~462 ~65 ~130 ~463 ~67 ~130 dirt
fill ~462 ~68 ~130 ~463 ~68 ~130 grass_block
fill ~448 ~60 ~131 ~448 ~63 ~131 stone
fill ~448 ~64 ~131 ~448 ~66 ~131 dirt
fill ~448 ~67 ~131 ~448 ~67 ~131 grass_block
fill ~449 ~60 ~131 ~456 ~62 ~131 stone
fill ~449 ~63 ~131 ~456 ~65 ~131 dirt
fill ~449 ~66 ~131 ~456 ~66 ~131 grass_block
fill ~457 ~60 ~131 ~461 ~63 ~131 stone
fill ~457 ~64 ~131 ~461 ~66 ~131 dirt
fill ~457 ~67 ~131 ~461 ~67 ~131 grass_block
fill ~462 ~60 ~131 ~463 ~64 ~131 stone
fill ~462 ~65 ~131 ~463 ~67 ~131 dirt
fill ~462 ~68 ~131 ~463 ~68 ~131 grass_block
fill ~448 ~60 ~132 ~457 ~62 ~132 stone
fill ~448 ~63 ~132 ~457 ~65 ~132 dirt
fill ~448 ~66 ~132 ~457 ~66 ~132 grass_block
fill ~458 ~60 ~132 ~462 ~63 ~132 stone
fill ~458 ~64 ~132 ~462 ~66 ~132 dirt
fill ~458 ~67 ~132 ~462 ~67 ~132 grass_block
fill ~463 ~60 ~132 ~463 ~64 ~132 stone
fill ~463 ~65 ~132 ~463 ~67 ~132 dirt
fill ~463 ~68 ~132 ~463 ~68 ~132 grass_block
fill ~448 ~60 ~133 ~457 ~62 ~133 stone
fill ~448 ~63 ~133 ~457 ~65 ~133 dirt
fill ~448 ~66 ~133 ~457 ~66 ~133 grass_block
fill ~458 ~60 ~133 ~463 ~63 ~133 stone
fill ~458 ~64 ~133 ~463 ~66 ~133 dirt
fill ~458 ~67 ~133 ~463 ~67 ~133 grass_block
fill ~448 ~60 ~134 ~458 ~62 ~134 stone
fill ~448 ~63 ~134 ~458 ~65 ~134 dirt
fill ~448 ~66 ~134 ~458 ~66 ~134 grass_block
fill ~459 ~60 ~134 ~463 ~63 ~134 stone
fill ~459 ~64 ~134 ~463 ~66 ~134 dirt
fill ~459 ~67 ~134 ~463 ~67 ~134 grass_block
fill ~448 ~60 ~135 ~458 ~62 ~135 stone
fill ~448 ~63 ~135 ~458 ~65 ~135 dirt
fill ~448 ~66 ~135 ~458 ~66 ~135 grass_block
fill ~459 ~60 ~135 ~463 ~63 ~135 stone
fill ~459 ~64 ~135 ~463 ~66 ~135 dirt
fill ~459 ~67 ~135 ~463 ~67 ~135 grass_block
fill ~448 ~60 ~136 ~459 ~62 ~136 stone
fill ~448 ~63 ~136 ~459 ~65 ~136 dirt
fill ~448 ~66 ~136 ~459 ~66 ~136 grass_block
fill ~460 ~60 ~136 ~463 ~63 ~136 stone
fill ~460 ~64 ~136 ~463 ~66 ~136 dirt
fill ~460 ~67 ~136 ~463 ~67 ~136 grass_block
fill ~448 ~60 ~137 ~451 ~62 ~137 stone
fill ~448 ~63 ~137 ~451 ~65 ~137 dirt
fill ~448 ~66 ~137 ~451 ~66 ~137 grass_block
fill ~452 ~60 ~137 ~453 ~61 ~137 stone
fill ~452 ~62 ~137 ~453 ~64 ~137 dirt
fill ~452 ~65 ~137 ~453 ~65 ~137 grass_block
fill ~454 ~60 ~137 ~460 ~62 ~137 stone
fill ~454 ~63 ~137 ~460 ~65 ~137 dirt
fill ~454 ~66 ~137 ~460 ~66 ~137 grass_block
fill ~461 ~60 ~137 ~463 ~63 ~137 stone
fill ~461 ~64 ~137 ~463 ~66 ~137 dirt
fill ~461 ~67 ~137 ~463 ~67 ~137 grass_block
fill ~448 ~60 ~138 ~451 ~62 ~138 stone
fill ~448 ~63 ~138 ~451 ~65 ~138 dirt
fill ~448 ~66 ~138 ~451 ~66 ~138 grass_block
fill ~452 ~60 ~138 ~453 ~61 ~138 stone
fill ~452 ~62 ~138 ~453 ~64 ~138 dirt
fill ~452 ~65 ~138 ~453 ~65 ~138 grass_block
fill ~454 ~60 ~138 ~462 ~62 ~138 stone
fill ~454 ~63 ~138 ~462 ~65 ~138 dirt
fill ~454 ~66 ~138 ~462 ~66 ~138 grass_block
fill ~463 ~60 ~138 ~463 ~63 ~138 stone
fill ~463 ~64 ~138 ~463 ~66 ~138 dirt
fill ~463 ~67 ~138 ~463 ~67 ~138 grass_block
fill ~448 ~60 ~139 ~450 ~62 ~139 stone
fill ~448 ~63 ~139 ~450 ~65 ~139 dirt
fill ~448 ~66 ~139 ~450 ~66 ~139 grass_block
fill ~451 ~60 ~139 ~454 ~61 ~139 stone
fill ~451 ~62 ~139 ~454 ~64 ~139 dirt
fill ~451 ~65 ~139 ~454 ~65 ~139 grass_block
fill ~455 ~60 ~139 ~463 ~62 ~139 stone
fill ~455 ~63 ~139 ~463 ~65 ~139 dirt
fill ~455 ~66 ~139 ~463 ~66 ~139 grass_block
fill ~448 ~60 ~140 ~450 ~62 ~140 stone
fill ~448 ~63 ~140 ~450 ~65 ~140 dirt
fill ~448 ~66 ~140 ~450 ~66 ~140 grass_block
fill ~451 ~60 ~140 ~455 ~61 ~140 stone
fill ~451 ~62 ~140 ~455 ~64 ~140 dirt
fill ~451 ~65 ~140 ~455 ~65 ~140 grass_block
fill ~456 ~60 ~140 ~463 ~62 ~140 stone
fill ~456 ~63 ~140 ~463 ~65 ~140 dirt
fill ~456 ~66 ~140 ~463 ~66 ~140 grass_block
fill ~448 ~60 ~141 ~455 ~61 ~141 stone
fill ~448 ~62 ~141 ~455 ~64 ~141 dirt
fill ~448 ~65 ~141 ~455 ~65 ~141 grass_block
fill ~456 ~60 ~141 ~463 ~62 ~141 stone
fill ~456 ~63 ~141 ~463 ~65 ~141 dirt
fill ~456 ~66 ~141 ~463 ~66 ~141 grass_block
fill ~448 ~60 ~142 ~456 ~61 ~142 stone
fill ~448 ~62 ~142 ~456 ~64 ~142 dirt
fill ~448 ~65 ~142 ~456 ~65 ~142 grass_block
fill ~457 ~60 ~142 ~463 ~62 ~142 stone
fill ~457 ~63 ~142 ~463 ~65 ~142 dirt
fill ~457 ~66 ~142 ~463 ~66 ~142 grass_block
fill ~448 ~60 ~143 ~450 ~60 ~143 stone
fill ~448 ~61 ~143 ~450 ~63 ~143 dirt
fill ~448 ~64 ~143 ~450 ~64 ~143 grass_block
fill ~451 ~60 ~143 ~456 ~61 ~143 stone
fill ~451 ~62 ~143 ~456 ~64 ~143 dirt
fill ~451 ~65 ~143 ~456 ~65 ~143 grass_block
fill ~457 ~60 ~143 ~463 ~62 ~143 stone
fill ~457 ~63 ~143 ~463 ~65 ~143 dirt
fill ~457 ~66 ~143 ~463 ~66 ~143 grass_block