fill ~432 ~60 ~64 ~439 ~65 ~64 stone
fill ~432 ~66 ~64 ~439 ~68 ~64 dirt
fill ~432 ~69 ~64 ~439 ~69 ~64 grass_block
fill ~440 ~60 ~64 ~445 ~66 ~64 stone
fill ~440 ~67 ~64 ~445 ~69 ~64 dirt
fill ~440 ~70 ~64 ~445 ~70 ~64 grass_block
fill ~446 ~60 ~64 ~447 ~65 ~64 stone
fill ~446 ~66 ~64 ~447 ~68 ~64 dirt
fill ~446 ~69 ~64 ~447 ~69 ~64 grass_block
fill ~432 ~60 ~65 ~440 ~65 ~65 stone
fill ~432 ~66 ~65 ~440 ~68 ~65 dirt
fill ~432 ~69 ~65 ~440 ~69 ~65 grass_block
fill ~441 ~60 ~65 ~445 ~66 ~65 stone
fill ~441 ~67 ~65 ~445 ~69 ~65 dirt
fill ~441 ~70 ~65 ~445 ~70 ~65 grass_block
fill ~446 ~60 ~65 ~447 ~65 ~65 stone
fill ~446 ~66 ~65 ~447 ~68 ~65 dirt
fill ~446 ~69 ~65 ~447 ~69 ~65 grass_block
fill ~432 ~60 ~66 ~440 ~65 ~66 stone
fill ~432 ~66 ~66 ~440 ~68 ~66 dirt
fill ~432 ~69 ~66 ~440 ~69 ~66 grass_block
fill ~441 ~60 ~66 ~445 ~66 ~66 stone
fill ~441 ~67 ~66 ~445 ~69 ~66 dirt
fill ~441 ~70 ~66 ~445 ~70 ~66 grass_block
fill ~446 ~60 ~66 ~447 ~65 ~66 stone
fill ~446 ~66 ~66 ~447 ~68 ~66 dirt
fill ~446 ~69 ~66 ~447 ~69 ~66 grass_block
fill ~432 ~60 ~67 ~441 ~65 ~67 stone
fill ~432 ~66 ~67 ~441 ~68 ~67 dirt
fill ~432 ~69 ~67 ~441 ~69 ~67 grass_block
fill ~442 ~60 ~67 ~445 ~66 ~67 stone
fill ~442 ~67 ~67 ~445 ~69 ~67 dirt
fill ~442 ~70 ~67 ~445 ~70 ~67 grass_block
fill ~446 ~60 ~67 ~447 ~65 ~67 stone
fill ~446 ~66 ~67 ~447 ~68 ~67 dirt
fill ~446 ~69 ~67 ~447 ~69 ~67 grass_block
fill ~432 ~60 ~68 ~441 ~65 ~68 stone
fill ~432 ~66 ~68 ~441 ~68 ~68 dirt
fill ~432 ~69 ~68 ~441 ~69 ~68 grass_block
fill ~442 ~60 ~68 ~445 ~66 ~68 stone
fill ~442 ~67 ~68 ~445 ~69 ~68 dirt
fill ~442 ~70 ~68 ~445 ~70 ~68 grass_block
fill ~446 ~60 ~68 ~447 ~65 ~68 stone
fill ~446 ~66 ~68 ~447 ~68 ~68 dirt
fill ~446 ~69 ~68 ~447 ~69 ~68 grass_block
fill ~432 ~60 ~69 ~447 ~65 ~69 stone
fill ~432 ~66 ~69 ~447 ~68 ~69 dirt
fill ~432 ~69 ~69 ~447 ~69 ~69 grass_block
fill ~432 ~60 ~70 ~447 ~65 ~70 stone
fill ~432 ~66 ~70 ~447 ~68 ~70 dirt
fill ~432 ~69 ~70 ~447 ~69 ~70 grass_block
fill ~432 ~60 ~71 ~447 ~65 ~71 stone
fill ~432 ~66 ~71 ~447 ~68 ~71 dirt
fill ~432 ~69 ~71 ~447 ~69 ~71 grass_block
fill ~432 ~60 ~72 ~447 ~65 ~72 stone
fill ~432 ~66 ~72 ~447 ~68 ~72 dirt
fill ~432 ~69 ~72 ~447 ~69 ~72 grass_block
fill ~432 ~60 ~73 ~436 ~65 ~73 stone
fill ~432 ~66 ~73 ~436 ~68 ~73 dirt
fill ~432 ~69 ~73 ~436 ~69 ~73 grass_block
fill ~437 ~60 ~73 ~437 ~64 ~73 stone
fill ~437 ~65 ~73 ~437 ~67 ~73 dirt
fill ~437 ~68 ~73 ~437 ~68 ~73 grass_block
fill ~438 ~60 ~73 ~447 ~65 ~73 stone
fill ~438 ~66 ~73 ~447 ~68 ~73 dirt
fill ~438 ~69 ~73 ~447 ~69 ~73 grass_block
fill ~432 ~60 ~74 ~434 ~64 ~74 stone
fill ~432 ~65 ~74 ~434 ~67 ~74 dirt
fill ~432 ~68 ~74 ~434 ~68 ~74 grass_block
fill ~435 ~60 ~74 ~436 ~65 ~74 stone
fill ~435 ~66 ~74 ~436 ~68 ~74 dirt
fill ~435 ~69 ~74 ~436 ~69 ~74 grass_block
fill ~437 ~60 ~74 ~441 ~64 ~74 stone
fill ~437 ~65 ~74 ~441 ~67 ~74 dirt
fill ~437 ~68 ~74 ~441 ~68 ~74 grass_block
fill ~442 ~60 ~74 ~447 ~65 ~74 stone
fill ~442 ~66 ~74 ~447 ~68 ~74 dirt
fill ~442 ~69 ~74 ~447 ~69 ~74 grass_block
fill ~432 ~60 ~75 ~445 ~64 ~75 stone
fill ~432 ~65 ~75 ~445 ~67 ~75 dirt
fill ~432 ~68 ~75 ~445 ~68 ~75 grass_block
fill ~446 ~60 ~75 ~447 ~65 ~75 stone
fill ~446 ~66 ~75 ~447 ~68 ~75 dirt
fill ~446 ~69 ~75 ~447 ~69 ~75 grass_block
fill ~432 ~60 ~76 ~446 ~64 ~76 stone
fill ~432 ~65 ~76 ~446 ~67 ~76 dirt
fill ~432 ~68 ~76 ~446 ~68 ~76 grass_block
fill ~447 ~60 ~76 ~447 ~65 ~76 stone
fill ~447 ~66 ~76 ~447 ~68 ~76 dirt
fill ~447 ~69 ~76 ~447 ~69 ~76 grass_block
fill ~432 ~60 ~77 ~447 ~64 ~77 stone
fill ~432 ~65 ~77 ~447 ~67 ~77 dirt
fill ~432 ~68 ~77 ~447 ~68 ~77 grass_block
fill ~432 ~60 ~78 ~433 ~63 ~78 stone
fill ~432 ~64 ~78 ~433 ~66 ~78 dirt
fill ~432 ~67 ~78 ~433 ~67 ~78 grass_block
fill ~434 ~60 ~78 ~447 ~64 ~78 stone
fill ~434 ~65 ~78 ~447 ~67 ~78 dirt
fill ~434 ~68 ~78 ~447 ~68 ~78 grass_block
fill ~432 ~60 ~79 ~433 ~63 ~79 stone
fill ~432 ~64 ~79 ~433 ~66 ~79 dirt
fill ~432 ~67 ~79 ~433 ~67 ~79 grass_block
fill ~434 ~60 ~79 ~447 ~64 ~79 stone
fill ~434 ~65 ~79 ~447 ~67 ~79 dirt
fill ~434 ~68 ~79 ~447 ~68 ~79 grass_block