fill ~320 ~60 ~32 ~321 ~63 ~32 stone
fill ~320 ~64 ~32 ~321 ~66 ~32 dirt
fill ~320 ~67 ~32 ~321 ~67 ~32 grass_block
fill ~322 ~60 ~32 ~326 ~64 ~32 stone
fill ~322 ~65 ~32 ~326 ~67 ~32 dirt
fill ~322 ~68 ~32 ~326 ~68 ~32 grass_block
fill ~327 ~60 ~32 ~335 ~63 ~32 stone
fill ~327 ~64 ~32 ~335 ~66 ~32 dirt
fill ~327 ~67 ~32 ~335 ~67 ~32 grass_block
fill ~320 ~60 ~33 ~321 ~63 ~33 stone
fill ~320 ~64 ~33 ~321 ~66 ~33 dirt
fill ~320 ~67 ~33 ~321 ~67 ~33 grass_block
fill ~322 ~60 ~33 ~325 ~64 ~33 stone
fill ~322 ~65 ~33 ~325 ~67 ~33 dirt
fill ~322 ~68 ~33 ~325 ~68 ~33 grass_block
fill ~326 ~60 ~33 ~335 ~63 ~33 stone
fill ~326 ~64 ~33 ~335 ~66 ~33 dirt
fill ~326 ~67 ~33 ~335 ~67 ~33 grass_block
fill ~320 ~60 ~34 ~321 ~63 ~34 stone
fill ~320 ~64 ~34 ~321 ~66 ~34 dirt
fill ~320 ~67 ~34 ~321 ~67 ~34 grass_block
fill ~322 ~60 ~34 ~323 ~64 ~34 stone
fill ~322 ~65 ~34 ~323 ~67 ~34 dirt
fill ~322 ~68 ~34 ~323 ~68 ~34 grass_block
fill ~324 ~60 ~34 ~332 ~63 ~34 stone
fill ~324 ~64 ~34 ~332 ~66 ~34 dirt
fill ~324 ~67 ~34 ~332 ~67 ~34 grass_block
fill ~333 ~60 ~34 ~333 ~62 ~34 stone
fill ~333 ~63 ~34 ~333 ~65 ~34 dirt
fill ~333 ~66 ~34 ~333 ~66 ~34 grass_block
fill ~334 ~60 ~34 ~335 ~63 ~34 stone
fill ~334 ~64 ~34 ~335 ~66 ~34 dirt
fill ~334 ~67 ~34 ~335 ~67 ~34 grass_block
fill ~320 ~60 ~35 ~331 ~63 ~35 stone
fill ~320 ~64 ~35 ~331 ~66 ~35 dirt
fill ~320 ~67 ~35 ~331 ~67 ~35 grass_block
fill ~332 ~60 ~35 ~335 ~62 ~35 stone
fill ~332 ~63 ~35 ~335 ~65 ~35 dirt
fill ~332 ~66 ~35 ~335 ~66 ~35 grass_block
fill ~320 ~60 ~36 ~327 ~63 ~36 stone
fill ~320 ~64 ~36 ~327 ~66 ~36 dirt
fill ~320 ~67 ~36 ~327 ~67 ~36 grass_block
fill ~328 ~60 ~36 ~335 ~62 ~36 stone
fill ~328 ~63 ~36 ~335 ~65 ~36 dirt
fill ~328 ~66 ~36 ~335 ~66 ~36 grass_block
fill ~320 ~60 ~37 ~326 ~63 ~37 stone
fill ~320 ~64 ~37 ~326 ~66 ~37 dirt
fill ~320 ~67 ~37 ~326 ~67 ~37 grass_block
fill ~327 ~60 ~37 ~335 ~62 ~37 stone
fill ~327 ~63 ~37 ~335 ~65 ~37 dirt
fill ~327 ~66 ~37 ~335 ~66 ~37 grass_block
fill ~320 ~60 ~38 ~320 ~62 ~38 stone
fill ~320 ~63 ~38 ~320 ~65 ~38 dirt
fill ~320 ~66 ~38 ~320 ~66 ~38 grass_block
fill ~321 ~60 ~38 ~325 ~63 ~38 stone
fill ~321 ~64 ~38 ~325 ~66 ~38 dirt
fill ~321 ~67 ~38 ~325 ~67 ~38 grass_block
fill ~326 ~60 ~38 ~335 ~62 ~38 stone
fill ~326 ~63 ~38 ~335 ~65 ~38 dirt
fill ~326 ~66 ~38 ~335 ~66 ~38 grass_block
fill ~320 ~60 ~39 ~320 ~62 ~39 stone
fill ~320 ~63 ~39 ~320 ~65 ~39 dirt
fill ~320 ~66 ~39 ~320 ~66 ~39 grass_block
fill ~321 ~60 ~39 ~325 ~63 ~39 stone
fill ~321 ~64 ~39 ~325 ~66 ~39 dirt
fill ~321 ~67 ~39 ~325 ~67 ~39 grass_block
fill ~326 ~60 ~39 ~335 ~62 ~39 stone
fill ~326 ~63 ~39 ~335 ~65 ~39 dirt
fill ~326 ~66 ~39 ~335 ~66 ~39 grass_block
fill ~320 ~60 ~40 ~321 ~62 ~40 stone
fill ~320 ~63 ~40 ~321 ~65 ~40 dirt
fill ~320 ~66 ~40 ~321 ~66 ~40 grass_block
fill ~322 ~60 ~40 ~325 ~63 ~40 stone
fill ~322 ~64 ~40 ~325 ~66 ~40 dirt
fill ~322 ~67 ~40 ~325 ~67 ~40 grass_block
fill ~326 ~60 ~40 ~333 ~62 ~40 stone
fill ~326 ~63 ~40 ~333 ~65 ~40 dirt
fill ~326 ~66 ~40 ~333 ~66 ~40 grass_block
fill ~334 ~60 ~40 ~335 ~63 ~40 stone
fill ~334 ~64 ~40 ~335 ~66 ~40 dirt
fill ~334 ~67 ~40 ~335 ~67 ~40 grass_block
fill ~320 ~60 ~41 ~321 ~62 ~41 stone
fill ~320 ~63 ~41 ~321 ~65 ~41 dirt
fill ~320 ~66 ~41 ~321 ~66 ~41 grass_block
fill ~322 ~60 ~41 ~324 ~63 ~41 stone
fill ~322 ~64 ~41 ~324 ~66 ~41 dirt
fill ~322 ~67 ~41 ~324 ~67 ~41 grass_block
fill ~325 ~60 ~41 ~332 ~62 ~41 stone
fill ~325 ~63 ~41 ~332 ~65 ~41 dirt
fill ~325 ~66 ~41 ~332 ~66 ~41 grass_block
fill ~333 ~60 ~41 ~334 ~63 ~41 stone
fill ~333 ~64 ~41 ~334 ~66 ~41 dirt
fill ~333 ~67 ~41 ~334 ~67 ~41 grass_block
fill ~335 ~60 ~41 ~335 ~64 ~41 stone
fill ~335 ~65 ~41 ~335 ~67 ~41 dirt
fill ~335 ~68 ~41 ~335 ~68 ~41 grass_block
fill ~320 ~60 ~42 ~329 ~62 ~42 stone
fill ~320 ~63 ~42 ~329 ~65 ~42 dirt
fill ~320 ~66 ~42 ~329 ~66 ~42 grass_block
fill ~330 ~60 ~42 ~334 ~63 ~42 stone
fill ~330 ~64 ~42 ~334 ~66 ~42 dirt
fill ~330 ~67 ~42 ~334 ~67 ~42 grass_block
fill ~335 ~60 ~42 ~335 ~64 ~42 stone
fill ~335 ~65 ~42 ~335 ~67 ~42 dirt
fill ~335 ~68 ~42 ~335 ~68 ~42 grass_block
fill ~320 ~60 ~43 ~328 ~62 ~43 stone
fill ~320 ~63 ~43 ~328 ~65 ~43 dirt
fill ~320 ~66 ~43 ~328 ~66 ~43 grass_block
fill ~329 ~60 ~43 ~334 ~63 ~43 stone
fill ~329 ~64 ~43 ~334 ~66 ~43 dirt
fill ~329 ~67 ~43 ~334 ~67 ~43 grass_block
fill ~335 ~60 ~43 ~335 ~64 ~43 stone
fill ~335 ~65 ~43 ~335 ~67 ~43 dirt
fill ~335 ~68 ~43 ~335 ~68 ~43 grass_block
fill ~320 ~60 ~44 ~328 ~62 ~44 stone
fill ~320 ~63 ~44 ~328 ~65 ~44 dirt
fill ~320 ~66 ~44 ~328 ~66 ~44 grass_block
fill ~329 ~60 ~44 ~331 ~63 ~44 stone
fill ~329 ~64 ~44 ~331 ~66 ~44 dirt
fill ~329 ~67 ~44 ~331 ~67 ~44 grass_block
fill ~332 ~60 ~44 ~333 ~64 ~44 stone
fill ~332 ~65 ~44 ~333 ~67 ~44 dirt
fill ~332 ~68 ~44 ~333 ~68 ~44 grass_block
fill ~334 ~60 ~44 ~335 ~63 ~44 stone
fill ~334 ~64 ~44 ~335 ~66 ~44 dirt
fill ~334 ~67 ~44 ~335 ~67 ~44 grass_block
fill ~320 ~60 ~45 ~328 ~62 ~45 stone
fill ~320 ~63 ~45 ~328 ~65 ~45 dirt
fill ~320 ~66 ~45 ~328 ~66 ~45 grass_block
fill ~329 ~60 ~45 ~330 ~63 ~45 stone
fill ~329 ~64 ~45 ~330 ~66 ~45 dirt
fill ~329 ~67 ~45 ~330 ~67 ~45 grass_block
fill ~331 ~60 ~45 ~335 ~64 ~45 stone
fill ~331 ~65 ~45 ~335 ~67 ~45 dirt
fill ~331 ~68 ~45 ~335 ~68 ~45 grass_block
fill ~320 ~60 ~46 ~327 ~62 ~46 stone
fill ~320 ~63 ~46 ~327 ~65 ~46 dirt
fill ~320 ~66 ~46 ~327 ~66 ~46 grass_block
fill ~328 ~60 ~46 ~329 ~63 ~46 stone
fill ~328 ~64 ~46 ~329 ~66 ~46 dirt
fill ~328 ~67 ~46 ~329 ~67 ~46 grass_block
fill ~330 ~60 ~46 ~331 ~64 ~46 stone
fill ~330 ~65 ~46 ~331 ~67 ~46 dirt
fill ~330 ~68 ~46 ~331 ~68 ~46 grass_block
fill ~332 ~60 ~46 ~333 ~65 ~46 stone
fill ~332 ~66 ~46 ~333 ~68 ~46 dirt
fill ~332 ~69 ~46 ~333 ~69 ~46 grass_block
fill ~334 ~60 ~46 ~335 ~64 ~46 stone
fill ~334 ~65 ~46 ~335 ~67 ~46 dirt
fill ~334 ~68 ~46 ~335 ~68 ~46 grass_block
fill ~320 ~60 ~47 ~327 ~62 ~47 stone
fill ~320 ~63 ~47 ~327 ~65 ~47 dirt
fill ~320 ~66 ~47 ~327 ~66 ~47 grass_block
fill ~328 ~60 ~47 ~330 ~63 ~47 stone
fill ~328 ~64 ~47 ~330 ~66 ~47 dirt
fill ~328 ~67 ~47 ~330 ~67 ~47 grass_block
fill ~331 ~60 ~47 ~332 ~64 ~47 stone
fill ~331 ~65 ~47 ~332 ~67 ~47 dirt
fill ~331 ~68 ~47 ~332 ~68 ~47 grass_block
fill ~333 ~60 ~47 ~335 ~65 ~47 stone
fill ~333 ~66 ~47 ~335 ~68 ~47 dirt
fill ~333 ~69 ~47 ~335 ~69 ~47 grass_block