fill ~128 ~60 ~128 ~130 ~66 ~128 stone
fill ~128 ~67 ~128 ~130 ~69 ~128 dirt
fill ~128 ~70 ~128 ~130 ~70 ~128 grass_block
fill ~131 ~60 ~128 ~134 ~65 ~128 stone
fill ~131 ~66 ~128 ~134 ~68 ~128 dirt
fill ~131 ~69 ~128 ~134 ~69 ~128 grass_block
fill ~135 ~60 ~128 ~138 ~66 ~128 stone
fill ~135 ~67 ~128 ~138 ~69 ~128 dirt
fill ~135 ~70 ~128 ~138 ~70 ~128 grass_block
fill ~139 ~60 ~128 ~143 ~67 ~128 stone
fill ~139 ~68 ~128 ~143 ~70 ~128 dirt
fill ~139 ~71 ~128 ~143 ~71 ~128 grass_block
fill ~128 ~60 ~129 ~130 ~66 ~129 stone
fill ~128 ~67 ~129 ~130 ~69 ~129 dirt
fill ~128 ~70 ~129 ~130 ~70 ~129 grass_block
fill ~131 ~60 ~129 ~136 ~65 ~129 stone
fill ~131 ~66 ~129 ~136 ~68 ~129 dirt
fill ~131 ~69 ~129 ~136 ~69 ~129 grass_block
fill ~137 ~60 ~129 ~139 ~66 ~129 stone
fill ~137 ~67 ~129 ~139 ~69 ~129 dirt
fill ~137 ~70 ~129 ~139 ~70 ~129 grass_block
fill ~140 ~60 ~129 ~142 ~67 ~129 stone
fill ~140 ~68 ~129 ~142 ~70 ~129 dirt
fill ~140 ~71 ~129 ~142 ~71 ~129 grass_block
fill ~143 ~60 ~129 ~143 ~66 ~129 stone
fill ~143 ~67 ~129 ~143 ~69 ~129 dirt
fill ~143 ~70 ~129 ~143 ~70 ~129 grass_block
fill ~128 ~60 ~130 ~130 ~66 ~130 stone
fill ~128 ~67 ~130 ~130 ~69 ~130 dirt
fill ~128 ~70 ~130 ~130 ~70 ~130 grass_block
fill ~131 ~60 ~130 ~136 ~65 ~130 stone
fill ~131 ~66 ~130 ~136 ~68 ~130 dirt
fill ~131 ~69 ~130 ~136 ~69 ~130 grass_block
fill ~137 ~60 ~130 ~143 ~66 ~130 stone
fill ~137 ~67 ~130 ~143 ~69 ~130 dirt
fill ~137 ~70 ~130 ~143 ~70 ~130 grass_block
fill ~128 ~60 ~131 ~130 ~66 ~131 stone
fill ~128 ~67 ~131 ~130 ~69 ~131 dirt
fill ~128 ~70 ~131 ~130 ~70 ~131 grass_block
fill ~131 ~60 ~131 ~132 ~65 ~131 stone
fill ~131 ~66 ~131 ~132 ~68 ~131 dirt
fill ~131 ~69 ~131 ~132 ~69 ~131 grass_block
fill ~133 ~60 ~131 ~134 ~64 ~131 stone
fill ~133 ~65 ~131 ~134 ~67 ~131 dirt
fill ~133 ~68 ~131 ~134 ~68 ~131 grass_block
fill ~135 ~60 ~131 ~136 ~65 ~131 stone
fill ~135 ~66 ~131 ~136 ~68 ~131 dirt
fill ~135 ~69 ~131 ~136 ~69 ~131 grass_block
fill ~137 ~60 ~131 ~142 ~66 ~131 stone
fill ~137 ~67 ~131 ~142 ~69 ~131 dirt
fill ~137 ~70 ~131 ~142 ~70 ~131 grass_block
fill ~143 ~60 ~131 ~143 ~65 ~131 stone
fill ~143 ~66 ~131 ~143 ~68 ~131 dirt
fill ~143 ~69 ~131 ~143 ~69 ~131 grass_block
fill ~128 ~60 ~132 ~130 ~66 ~132 stone
fill ~128 ~67 ~132 ~130 ~69 ~132 dirt
fill ~128 ~70 ~132 ~130 ~70 ~132 grass_block
fill ~131 ~60 ~132 ~132 ~65 ~132 stone
fill ~131 ~66 ~132 ~132 ~68 ~132 dirt
fill ~131 ~69 ~132 ~132 ~69 ~132 grass_block
fill ~133 ~60 ~132 ~135 ~64 ~132 stone
fill ~133 ~65 ~132 ~135 ~67 ~132 dirt
fill ~133 ~68 ~132 ~135 ~68 ~132 grass_block
fill ~136 ~60 ~132 ~137 ~65 ~132 stone
fill ~136 ~66 ~132 ~137 ~68 ~132 dirt
fill ~136 ~69 ~132 ~137 ~69 ~132 grass_block
fill ~138 ~60 ~132 ~142 ~66 ~132 stone
fill ~138 ~67 ~132 ~142 ~69 ~132 dirt
fill ~138 ~70 ~132 ~142 ~70 ~132 grass_block
fill ~143 ~60 ~132 ~143 ~65 ~132 stone
fill ~143 ~66 ~132 ~143 ~68 ~132 dirt
fill ~143 ~69 ~132 ~143 ~69 ~132 grass_block
fill ~128 ~60 ~133 ~130 ~66 ~133 stone
fill ~128 ~67 ~133 ~130 ~69 ~133 dirt
fill ~128 ~70 ~133 ~130 ~70 ~133 grass_block
fill ~131 ~60 ~133 ~132 ~65 ~133 stone
fill ~131 ~66 ~133 ~132 ~68 ~133 dirt
fill ~131 ~69 ~133 ~132 ~69 ~133 grass_block
fill ~133 ~60 ~133 ~135 ~64 ~133 stone
fill ~133 ~65 ~133 ~135 ~67 ~133 dirt
fill ~133 ~68 ~133 ~135 ~68 ~133 grass_block
fill ~136 ~60 ~133 ~138 ~65 ~133 stone
fill ~136 ~66 ~133 ~138 ~68 ~133 dirt
fill ~136 ~69 ~133 ~138 ~69 ~133 grass_block
fill ~139 ~60 ~133 ~140 ~66 ~133 stone
fill ~139 ~67 ~133 ~140 ~69 ~133 dirt
fill ~139 ~70 ~133 ~140 ~70 ~133 grass_block
fill ~141 ~60 ~133 ~143 ~65 ~133 stone
fill ~141 ~66 ~133 ~143 ~68 ~133 dirt
fill ~141 ~69 ~133 ~143 ~69 ~133 grass_block
fill ~128 ~60 ~134 ~128 ~65 ~134 stone
fill ~128 ~66 ~134 ~128 ~68 ~134 dirt
fill ~128 ~69 ~134 ~128 ~69 ~134 grass_block
fill ~129 ~60 ~134 ~130 ~66 ~134 stone
fill ~129 ~67 ~134 ~130 ~69 ~134 dirt
fill ~129 ~70 ~134 ~130 ~70 ~134 grass_block
fill ~131 ~60 ~134 ~133 ~65 ~134 stone
fill ~131 ~66 ~134 ~133 ~68 ~134 dirt
fill ~131 ~69 ~134 ~133 ~69 ~134 grass_block
fill ~134 ~60 ~134 ~136 ~64 ~134 stone
fill ~134 ~65 ~134 ~136 ~67 ~134 dirt
fill ~134 ~68 ~134 ~136 ~68 ~134 grass_block
fill ~137 ~60 ~134 ~143 ~65 ~134 stone
fill ~137 ~66 ~134 ~143 ~68 ~134 dirt
fill ~137 ~69 ~134 ~143 ~69 ~134 grass_block
fill ~128 ~60 ~135 ~129 ~65 ~135 stone
fill ~128 ~66 ~135 ~129 ~68 ~135 dirt
fill ~128 ~69 ~135 ~129 ~69 ~135 grass_block
fill ~130 ~60 ~135 ~130 ~66 ~135 stone
fill ~130 ~67 ~135 ~130 ~69 ~135 dirt
fill ~130 ~70 ~135 ~130 ~70 ~135 grass_block
fill ~131 ~60 ~135 ~133 ~65 ~135 stone
fill ~131 ~66 ~135 ~133 ~68 ~135 dirt
fill ~131 ~69 ~135 ~133 ~69 ~135 grass_block
fill ~134 ~60 ~135 ~136 ~64 ~135 stone
fill ~134 ~65 ~135 ~136 ~67 ~135 dirt
fill ~134 ~68 ~135 ~136 ~68 ~135 grass_block
fill ~137 ~60 ~135 ~141 ~65 ~135 stone
fill ~137 ~66 ~135 ~141 ~68 ~135 dirt
fill ~137 ~69 ~135 ~141 ~69 ~135 grass_block
fill ~142 ~60 ~135 ~143 ~64 ~135 stone
fill ~142 ~65 ~135 ~143 ~67 ~135 dirt
fill ~142 ~68 ~135 ~143 ~68 ~135 grass_block
fill ~128 ~60 ~136 ~128 ~64 ~136 stone
fill ~128 ~65 ~136 ~128 ~67 ~136 dirt
fill ~128 ~68 ~136 ~128 ~68 ~136 grass_block
fill ~129 ~60 ~136 ~133 ~65 ~136 stone
fill ~129 ~66 ~136 ~133 ~68 ~136 dirt
fill ~129 ~69 ~136 ~133 ~69 ~136 grass_block
fill ~134 ~60 ~136 ~137 ~64 ~136 stone
fill ~134 ~65 ~136 ~137 ~67 ~136 dirt
fill ~134 ~68 ~136 ~137 ~68 ~136 grass_block
fill ~138 ~60 ~136 ~141 ~65 ~136 stone
fill ~138 ~66 ~136 ~141 ~68 ~136 dirt
fill ~138 ~69 ~136 ~141 ~69 ~136 grass_block
fill ~142 ~60 ~136 ~143 ~64 ~136 stone
fill ~142 ~65 ~136 ~143 ~67 ~136 dirt
fill ~142 ~68 ~136 ~143 ~68 ~136 grass_block
fill ~128 ~60 ~137 ~128 ~64 ~137 stone
fill ~128 ~65 ~137 ~128 ~67 ~137 dirt
fill ~128 ~68 ~137 ~128 ~68 ~137 grass_block
fill ~129 ~60 ~137 ~132 ~65 ~137 stone
fill ~129 ~66 ~137 ~132 ~68 ~137 dirt
fill ~129 ~69 ~137 ~132 ~69 ~137 grass_block
fill ~133 ~60 ~137 ~137 ~64 ~137 stone
fill ~133 ~65 ~137 ~137 ~67 ~137 dirt
fill ~133 ~68 ~137 ~137 ~68 ~137 grass_block
fill ~138 ~60 ~137 ~139 ~65 ~137 stone
fill ~138 ~66 ~137 ~139 ~68 ~137 dirt
fill ~138 ~69 ~137 ~139 ~69 ~137 grass_block
fill ~140 ~60 ~137 ~143 ~64 ~137 stone
fill ~140 ~65 ~137 ~143 ~67 ~137 dirt
fill ~140 ~68 ~137 ~143 ~68 ~137 grass_block
fill ~128 ~60 ~138 ~128 ~64 ~138 stone
fill ~128 ~65 ~138 ~128 ~67 ~138 dirt
fill ~128 ~68 ~138 ~128 ~68 ~138 grass_block
fill ~129 ~60 ~138 ~132 ~65 ~138 stone
fill ~129 ~66 ~138 ~132 ~68 ~138 dirt
fill ~129 ~69 ~138 ~132 ~69 ~138 grass_block
fill ~133 ~60 ~138 ~143 ~64 ~138 stone
fill ~133 ~65 ~138 ~143 ~67 ~138 dirt
fill ~133 ~68 ~138 ~143 ~68 ~138 grass_block
fill ~128 ~60 ~139 ~129 ~64 ~139 stone
fill ~128 ~65 ~139 ~129 ~67 ~139 dirt
fill ~128 ~68 ~139 ~129 ~68 ~139 grass_block
fill ~130 ~60 ~139 ~131 ~65 ~139 stone
fill ~130 ~66 ~139 ~131 ~68 ~139 dirt
fill ~130 ~69 ~139 ~131 ~69 ~139 grass_block
fill ~132 ~60 ~139 ~135 ~64 ~139 stone
fill ~132 ~65 ~139 ~135 ~67 ~139 dirt
fill ~132 ~68 ~139 ~135 ~68 ~139 grass_block
fill ~136 ~60 ~139 ~136 ~63 ~139 stone
fill ~136 ~64 ~139 ~136 ~66 ~139 dirt
fill ~136 ~67 ~139 ~136 ~67 ~139 grass_block
fill ~137 ~60 ~139 ~143 ~64 ~139 stone
fill ~137 ~65 ~139 ~143 ~67 ~139 dirt
fill ~137 ~68 ~139 ~143 ~68 ~139 grass_block
fill ~128 ~60 ~140 ~129 ~64 ~140 stone
fill ~128 ~65 ~140 ~129 ~67 ~140 dirt
fill ~128 ~68 ~140 ~129 ~68 ~140 grass_block
fill ~130 ~60 ~140 ~132 ~65 ~140 stone
fill ~130 ~66 ~140 ~132 ~68 ~140 dirt
fill ~130 ~69 ~140 ~132 ~69 ~140 grass_block
fill ~133 ~60 ~140 ~135 ~64 ~140 stone
fill ~133 ~65 ~140 ~135 ~67 ~140 dirt
fill ~133 ~68 ~140 ~135 ~68 ~140 grass_block
fill ~136 ~60 ~140 ~137 ~63 ~140 stone
fill ~136 ~64 ~140 ~137 ~66 ~140 dirt
fill ~136 ~67 ~140 ~137 ~67 ~140 grass_block
fill ~138 ~60 ~140 ~139 ~64 ~140 stone
fill ~138 ~65 ~140 ~139 ~67 ~140 dirt
fill ~138 ~68 ~140 ~139 ~68 ~140 grass_block
fill ~140 ~60 ~140 ~140 ~63 ~140 stone
fill ~140 ~64 ~140 ~140 ~66 ~140 dirt
fill ~140 ~67 ~140 ~140 ~67 ~140 grass_block
fill ~141 ~60 ~140 ~142 ~64 ~140 stone
fill ~141 ~65 ~140 ~142 ~67 ~140 dirt
fill ~141 ~68 ~140 ~142 ~68 ~140 grass_block
fill ~143 ~60 ~140 ~143 ~65 ~140 stone
fill ~143 ~66 ~140 ~143 ~68 ~140 dirt
fill ~143 ~69 ~140 ~143 ~69 ~140 grass_block
fill ~128 ~60 ~141 ~128 ~63 ~141 stone
fill ~128 ~64 ~141 ~128 ~66 ~141 dirt
fill ~128 ~67 ~141 ~128 ~67 ~141 grass_block
fill ~129 ~60 ~141 ~130 ~64 ~141 stone
fill ~129 ~65 ~141 ~130 ~67 ~141 dirt
fill ~129 ~68 ~141 ~130 ~68 ~141 grass_block
fill ~131 ~60 ~141 ~132 ~65 ~141 stone
fill ~131 ~66 ~141 ~132 ~68 ~141 dirt
fill ~131 ~69 ~141 ~132 ~69 ~141 grass_block
fill ~133 ~60 ~141 ~135 ~64 ~141 stone
fill ~133 ~65 ~141 ~135 ~67 ~141 dirt
fill ~133 ~68 ~141 ~135 ~68 ~141 grass_block
fill ~136 ~60 ~141 ~140 ~63 ~141 stone
fill ~136 ~64 ~141 ~140 ~66 ~141 dirt
fill ~136 ~67 ~141 ~140 ~67 ~141 grass_block
fill ~141 ~60 ~141 ~142 ~64 ~141 stone
fill ~141 ~65 ~141 ~142 ~67 ~141 dirt
fill ~141 ~68 ~141 ~142 ~68 ~141 grass_block
fill ~143 ~60 ~141 ~143 ~65 ~141 stone
fill ~143 ~66 ~141 ~143 ~68 ~141 dirt
fill ~143 ~69 ~141 ~143 ~69 ~141 grass_block
fill ~128 ~60 ~142 ~129 ~63 ~142 stone
fill ~128 ~64 ~142 ~129 ~66 ~142 dirt
fill ~128 ~67 ~142 ~129 ~67 ~142 grass_block
fill ~130 ~60 ~142 ~130 ~64 ~142 stone
fill ~130 ~65 ~142 ~130 ~67 ~142 dirt
fill ~130 ~68 ~142 ~130 ~68 ~142 grass_block
fill ~131 ~60 ~142 ~132 ~65 ~142 stone
fill ~131 ~66 ~142 ~132 ~68 ~142 dirt
fill ~131 ~69 ~142 ~132 ~69 ~142 grass_block
fill ~133 ~60 ~142 ~135 ~64 ~142 stone
fill ~133 ~65 ~142 ~135 ~67 ~142 dirt
fill ~133 ~68 ~142 ~135 ~68 ~142 grass_block
fill ~136 ~60 ~142 ~139 ~63 ~142 stone
fill ~136 ~64 ~142 ~139 ~66 ~142 dirt
fill ~136 ~67 ~142 ~139 ~67 ~142 grass_block
fill ~140 ~60 ~142 ~141 ~64 ~142 stone
fill ~140 ~65 ~142 ~141 ~67 ~142 dirt
fill ~140 ~68 ~142 ~141 ~68 ~142 grass_block
fill ~142 ~60 ~142 ~143 ~65 ~142 stone
fill ~142 ~66 ~142 ~143 ~68 ~142 dirt
fill ~142 ~69 ~142 ~143 ~69 ~142 grass_block
fill ~128 ~60 ~143 ~129 ~63 ~143 stone
fill ~128 ~64 ~143 ~129 ~66 ~143 dirt
fill ~128 ~67 ~143 ~129 ~67 ~143 grass_block
fill ~130 ~60 ~143 ~130 ~64 ~143 stone
fill ~130 ~65 ~143 ~130 ~67 ~143 dirt
fill ~130 ~68 ~143 ~130 ~68 ~143 grass_block
fill ~131 ~60 ~143 ~132 ~65 ~143 stone
fill ~131 ~66 ~143 ~132 ~68 ~143 dirt
fill ~131 ~69 ~143 ~132 ~69 ~143 grass_block
fill ~133 ~60 ~143 ~135 ~64 ~143 stone
fill ~133 ~65 ~143 ~135 ~67 ~143 dirt
fill ~133 ~68 ~143 ~135 ~68 ~143 grass_block
fill ~136 ~60 ~143 ~138 ~63 ~143 stone
fill ~136 ~64 ~143 ~138 ~66 ~143 dirt
fill ~136 ~67 ~143 ~138 ~67 ~143 grass_block
fill ~139 ~60 ~143 ~141 ~64 ~143 stone
fill ~139 ~65 ~143 ~141 ~67 ~143 dirt
fill ~139 ~68 ~143 ~141 ~68 ~143 grass_block
fill ~142 ~60 ~143 ~143 ~65 ~143 stone
fill ~142 ~66 ~143 ~143 ~68 ~143 dirt
fill ~142 ~69 ~143 ~143 ~69 ~143 grass_block