fill ~432 ~60 ~112 ~433 ~64 ~112 stone
fill ~432 ~65 ~112 ~433 ~67 ~112 dirt
fill ~432 ~68 ~112 ~433 ~68 ~112 grass_block
fill ~434 ~60 ~112 ~435 ~65 ~112 stone
fill ~434 ~66 ~112 ~435 ~68 ~112 dirt
fill ~434 ~69 ~112 ~435 ~69 ~112 grass_block
fill ~436 ~60 ~112 ~439 ~64 ~112 stone
fill ~436 ~65 ~112 ~439 ~67 ~112 dirt
fill ~436 ~68 ~112 ~439 ~68 ~112 grass_block
fill ~440 ~60 ~112 ~443 ~63 ~112 stone
fill ~440 ~64 ~112 ~443 ~66 ~112 dirt
fill ~440 ~67 ~112 ~443 ~67 ~112 grass_block
fill ~444 ~60 ~112 ~447 ~62 ~112 stone
fill ~444 ~63 ~112 ~447 ~65 ~112 dirt
fill ~444 ~66 ~112 ~447 ~66 ~112 grass_block
fill ~432 ~60 ~113 ~434 ~64 ~113 stone
fill ~432 ~65 ~113 ~434 ~67 ~113 dirt
fill ~432 ~68 ~113 ~434 ~68 ~113 grass_block
fill ~435 ~60 ~113 ~435 ~65 ~113 stone
fill ~435 ~66 ~113 ~435 ~68 ~113 dirt
fill ~435 ~69 ~113 ~435 ~69 ~113 grass_block
fill ~436 ~60 ~113 ~440 ~64 ~113 stone
fill ~436 ~65 ~113 ~440 ~67 ~113 dirt
fill ~436 ~68 ~113 ~440 ~68 ~113 grass_block
fill ~441 ~60 ~113 ~444 ~63 ~113 stone
fill ~441 ~64 ~113 ~444 ~66 ~113 dirt
fill ~441 ~67 ~113 ~444 ~67 ~113 grass_block
fill ~445 ~60 ~113 ~447 ~62 ~113 stone
fill ~445 ~63 ~113 ~447 ~65 ~113 dirt
fill ~445 ~66 ~113 ~447 ~66 ~113 grass_block
fill ~432 ~60 ~114 ~441 ~64 ~114 stone
fill ~432 ~65 ~114 ~441 ~67 ~114 dirt
fill ~432 ~68 ~114 ~441 ~68 ~114 grass_block
fill ~442 ~60 ~114 ~445 ~63 ~114 stone
fill ~442 ~64 ~114 ~445 ~66 ~114 dirt
fill ~442 ~67 ~114 ~445 ~67 ~114 grass_block
fill ~446 ~60 ~114 ~447 ~62 ~114 stone
fill ~446 ~63 ~114 ~447 ~65 ~114 dirt
fill ~446 ~66 ~114 ~447 ~66 ~114 grass_block
fill ~432 ~60 ~115 ~433 ~63 ~115 stone
fill ~432 ~64 ~115 ~433 ~66 ~115 dirt
fill ~432 ~67 ~115 ~433 ~67 ~115 grass_block
fill ~434 ~60 ~115 ~439 ~64 ~115 stone
fill ~434 ~65 ~115 ~439 ~67 ~115 dirt
fill ~434 ~68 ~115 ~439 ~68 ~115 grass_block
fill ~440 ~60 ~115 ~446 ~63 ~115 stone
fill ~440 ~64 ~115 ~446 ~66 ~115 dirt
fill ~440 ~67 ~115 ~446 ~67 ~115 grass_block
fill ~447 ~60 ~115 ~447 ~62 ~115 stone
fill ~447 ~63 ~115 ~447 ~65 ~115 dirt
fill ~447 ~66 ~115 ~447 ~66 ~115 grass_block
fill ~432 ~60 ~116 ~432 ~63 ~116 stone
fill ~432 ~64 ~116 ~432 ~66 ~116 dirt
fill ~432 ~67 ~116 ~432 ~67 ~116 grass_block
fill ~433 ~60 ~116 ~437 ~64 ~116 stone
fill ~433 ~65 ~116 ~437 ~67 ~116 dirt
fill ~433 ~68 ~116 ~437 ~68 ~116 grass_block
fill ~438 ~60 ~116 ~446 ~63 ~116 stone
fill ~438 ~64 ~116 ~446 ~66 ~116 dirt
fill ~438 ~67 ~116 ~446 ~67 ~116 grass_block
fill ~447 ~60 ~116 ~447 ~62 ~116 stone
fill ~447 ~63 ~116 ~447 ~65 ~116 dirt
fill ~447 ~66 ~116 ~447 ~66 ~116 grass_block
fill ~432 ~60 ~117 ~432 ~63 ~117 stone
fill ~432 ~64 ~117 ~432 ~66 ~117 dirt
fill ~432 ~67 ~117 ~432 ~67 ~117 grass_block
fill ~433 ~60 ~117 ~437 ~64 ~117 stone
fill ~433 ~65 ~117 ~437 ~67 ~117 dirt
fill ~433 ~68 ~117 ~437 ~68 ~117 grass_block
fill ~438 ~60 ~117 ~439 ~63 ~117 stone
fill ~438 ~64 ~117 ~439 ~66 ~117 dirt
fill ~438 ~67 ~117 ~439 ~67 ~117 grass_block
fill ~440 ~60 ~117 ~447 ~62 ~117 stone
fill ~440 ~63 ~117 ~447 ~65 ~117 dirt
fill ~440 ~66 ~117 ~447 ~66 ~117 grass_block
fill ~432 ~60 ~118 ~432 ~63 ~118 stone
fill ~432 ~64 ~118 ~432 ~66 ~118 dirt
fill ~432 ~67 ~118 ~432 ~67 ~118 grass_block
fill ~433 ~60 ~118 ~438 ~64 ~118 stone
fill ~433 ~65 ~118 ~438 ~67 ~118 dirt
fill ~433 ~68 ~118 ~438 ~68 ~118 grass_block
fill ~439 ~60 ~118 ~441 ~63 ~118 stone
fill ~439 ~64 ~118 ~441 ~66 ~118 dirt
fill ~439 ~67 ~118 ~441 ~67 ~118 grass_block
fill ~442 ~60 ~118 ~447 ~62 ~118 stone
fill ~442 ~63 ~118 ~447 ~65 ~118 dirt
fill ~442 ~66 ~118 ~447 ~66 ~118 grass_block
fill ~432 ~60 ~119 ~432 ~63 ~119 stone
fill ~432 ~64 ~119 ~432 ~66 ~119 dirt
fill ~432 ~67 ~119 ~432 ~67 ~119 grass_block
fill ~433 ~60 ~119 ~439 ~64 ~119 stone
fill ~433 ~65 ~119 ~439 ~67 ~119 dirt
fill ~433 ~68 ~119 ~439 ~68 ~119 grass_block
fill ~440 ~60 ~119 ~442 ~63 ~119 stone
fill ~440 ~64 ~119 ~442 ~66 ~119 dirt
fill ~440 ~67 ~119 ~442 ~67 ~119 grass_block
fill ~443 ~60 ~119 ~446 ~62 ~119 stone
fill ~443 ~63 ~119 ~446 ~65 ~119 dirt
fill ~443 ~66 ~119 ~446 ~66 ~119 grass_block
fill ~447 ~60 ~119 ~447 ~63 ~119 stone
fill ~447 ~64 ~119 ~447 ~66 ~119 dirt
fill ~447 ~67 ~119 ~447 ~67 ~119 grass_block
fill ~432 ~60 ~120 ~432 ~63 ~120 stone
fill ~432 ~64 ~120 ~432 ~66 ~120 dirt
fill ~432 ~67 ~120 ~432 ~67 ~120 grass_block
fill ~433 ~60 ~120 ~436 ~64 ~120 stone
fill ~433 ~65 ~120 ~436 ~67 ~120 dirt
fill ~433 ~68 ~120 ~436 ~68 ~120 grass_block
fill ~437 ~60 ~120 ~437 ~65 ~120 stone
fill ~437 ~66 ~120 ~437 ~68 ~120 dirt
fill ~437 ~69 ~120 ~437 ~69 ~120 grass_block
fill ~438 ~60 ~120 ~440 ~64 ~120 stone
fill ~438 ~65 ~120 ~440 ~67 ~120 dirt
fill ~438 ~68 ~120 ~440 ~68 ~120 grass_block
fill ~441 ~60 ~120 ~442 ~63 ~120 stone
fill ~441 ~64 ~120 ~442 ~66 ~120 dirt
fill ~441 ~67 ~120 ~442 ~67 ~120 grass_block
fill ~443 ~60 ~120 ~445 ~62 ~120 stone
fill ~443 ~63 ~120 ~445 ~65 ~120 dirt
fill ~443 ~66 ~120 ~445 ~66 ~120 grass_block
fill ~446 ~60 ~120 ~447 ~63 ~120 stone
fill ~446 ~64 ~120 ~447 ~66 ~120 dirt
fill ~446 ~67 ~120 ~447 ~67 ~120 grass_block
fill ~432 ~60 ~121 ~432 ~63 ~121 stone
fill ~432 ~64 ~121 ~432 ~66 ~121 dirt
fill ~432 ~67 ~121 ~432 ~67 ~121 grass_block
fill ~433 ~60 ~121 ~436 ~64 ~121 stone
fill ~433 ~65 ~121 ~436 ~67 ~121 dirt
fill ~433 ~68 ~121 ~436 ~68 ~121 grass_block
fill ~437 ~60 ~121 ~438 ~65 ~121 stone
fill ~437 ~66 ~121 ~438 ~68 ~121 dirt
fill ~437 ~69 ~121 ~438 ~69 ~121 grass_block
fill ~439 ~60 ~121 ~441 ~64 ~121 stone
fill ~439 ~65 ~121 ~441 ~67 ~121 dirt
fill ~439 ~68 ~121 ~441 ~68 ~121 grass_block
fill ~442 ~60 ~121 ~443 ~63 ~121 stone
fill ~442 ~64 ~121 ~443 ~66 ~121 dirt
fill ~442 ~67 ~121 ~443 ~67 ~121 grass_block
fill ~444 ~60 ~121 ~444 ~62 ~121 stone
fill ~444 ~63 ~121 ~444 ~65 ~121 dirt
fill ~444 ~66 ~121 ~444 ~66 ~121 grass_block
fill ~445 ~60 ~121 ~447 ~63 ~121 stone
fill ~445 ~64 ~121 ~447 ~66 ~121 dirt
fill ~445 ~67 ~121 ~447 ~67 ~121 grass_block
fill ~432 ~60 ~122 ~432 ~63 ~122 stone
fill ~432 ~64 ~122 ~432 ~66 ~122 dirt
fill ~432 ~67 ~122 ~432 ~67 ~122 grass_block
fill ~433 ~60 ~122 ~437 ~64 ~122 stone
fill ~433 ~65 ~122 ~437 ~67 ~122 dirt
fill ~433 ~68 ~122 ~437 ~68 ~122 grass_block
fill ~438 ~60 ~122 ~438 ~65 ~122 stone
fill ~438 ~66 ~122 ~438 ~68 ~122 dirt
fill ~438 ~69 ~122 ~438 ~69 ~122 grass_block
fill ~439 ~60 ~122 ~441 ~64 ~122 stone
fill ~439 ~65 ~122 ~441 ~67 ~122 dirt
fill ~439 ~68 ~122 ~441 ~68 ~122 grass_block
fill ~442 ~60 ~122 ~447 ~63 ~122 stone
fill ~442 ~64 ~122 ~447 ~66 ~122 dirt
fill ~442 ~67 ~122 ~447 ~67 ~122 grass_block
fill ~432 ~60 ~123 ~432 ~63 ~123 stone
fill ~432 ~64 ~123 ~432 ~66 ~123 dirt
fill ~432 ~67 ~123 ~432 ~67 ~123 grass_block
fill ~433 ~60 ~123 ~442 ~64 ~123 stone
fill ~433 ~65 ~123 ~442 ~67 ~123 dirt
fill ~433 ~68 ~123 ~442 ~68 ~123 grass_block
fill ~443 ~60 ~123 ~447 ~63 ~123 stone
fill ~443 ~64 ~123 ~447 ~66 ~123 dirt
fill ~443 ~67 ~123 ~447 ~67 ~123 grass_block
fill ~432 ~60 ~124 ~442 ~64 ~124 stone
fill ~432 ~65 ~124 ~442 ~67 ~124 dirt
fill ~432 ~68 ~124 ~442 ~68 ~124 grass_block
fill ~443 ~60 ~124 ~447 ~63 ~124 stone
fill ~443 ~64 ~124 ~447 ~66 ~124 dirt
fill ~443 ~67 ~124 ~447 ~67 ~124 grass_block
fill ~432 ~60 ~125 ~443 ~64 ~125 stone
fill ~432 ~65 ~125 ~443 ~67 ~125 dirt
fill ~432 ~68 ~125 ~443 ~68 ~125 grass_block
fill ~444 ~60 ~125 ~447 ~63 ~125 stone
fill ~444 ~64 ~125 ~447 ~66 ~125 dirt
fill ~444 ~67 ~125 ~447 ~67 ~125 grass_block
fill ~432 ~60 ~126 ~443 ~64 ~126 stone
fill ~432 ~65 ~126 ~443 ~67 ~126 dirt
fill ~432 ~68 ~126 ~443 ~68 ~126 grass_block
fill ~444 ~60 ~126 ~447 ~63 ~126 stone
fill ~444 ~64 ~126 ~447 ~66 ~126 dirt
fill ~444 ~67 ~126 ~447 ~67 ~126 grass_block
fill ~432 ~60 ~127 ~432 ~63 ~127 stone
fill ~432 ~64 ~127 ~432 ~66 ~127 dirt
fill ~432 ~67 ~127 ~432 ~67 ~127 grass_block
fill ~433 ~60 ~127 ~443 ~64 ~127 stone
fill ~433 ~65 ~127 ~443 ~67 ~127 dirt
fill ~433 ~68 ~127 ~443 ~68 ~127 grass_block
fill ~444 ~60 ~127 ~447 ~63 ~127 stone
fill ~444 ~64 ~127 ~447 ~66 ~127 dirt
fill ~444 ~67 ~127 ~447 ~67 ~127 grass_block