fill ~416 ~60 ~32 ~417 ~63 ~32 stone
fill ~416 ~64 ~32 ~417 ~66 ~32 dirt
fill ~416 ~67 ~32 ~417 ~67 ~32 grass_block
fill ~418 ~60 ~32 ~422 ~62 ~32 stone
fill ~418 ~63 ~32 ~422 ~65 ~32 dirt
fill ~418 ~66 ~32 ~422 ~66 ~32 grass_block
fill ~423 ~60 ~32 ~425 ~63 ~32 stone
fill ~423 ~64 ~32 ~425 ~66 ~32 dirt
fill ~423 ~67 ~32 ~425 ~67 ~32 grass_block
fill ~426 ~60 ~32 ~427 ~64 ~32 stone
fill ~426 ~65 ~32 ~427 ~67 ~32 dirt
fill ~426 ~68 ~32 ~427 ~68 ~32 grass_block
fill ~428 ~60 ~32 ~431 ~63 ~32 stone
fill ~428 ~64 ~32 ~431 ~66 ~32 dirt
fill ~428 ~67 ~32 ~431 ~67 ~32 grass_block
fill ~416 ~60 ~33 ~416 ~63 ~33 stone
fill ~416 ~64 ~33 ~416 ~66 ~33 dirt
fill ~416 ~67 ~33 ~416 ~67 ~33 grass_block
fill ~417 ~60 ~33 ~422 ~62 ~33 stone
fill ~417 ~63 ~33 ~422 ~65 ~33 dirt
fill ~417 ~66 ~33 ~422 ~66 ~33 grass_block
fill ~423 ~60 ~33 ~424 ~63 ~33 stone
fill ~423 ~64 ~33 ~424 ~66 ~33 dirt
fill ~423 ~67 ~33 ~424 ~67 ~33 grass_block
fill ~425 ~60 ~33 ~427 ~64 ~33 stone
fill ~425 ~65 ~33 ~427 ~67 ~33 dirt
fill ~425 ~68 ~33 ~427 ~68 ~33 grass_block
fill ~428 ~60 ~33 ~431 ~63 ~33 stone
fill ~428 ~64 ~33 ~431 ~66 ~33 dirt
fill ~428 ~67 ~33 ~431 ~67 ~33 grass_block
fill ~416 ~60 ~34 ~416 ~63 ~34 stone
fill ~416 ~64 ~34 ~416 ~66 ~34 dirt
fill ~416 ~67 ~34 ~416 ~67 ~34 grass_block
fill ~417 ~60 ~34 ~421 ~62 ~34 stone
fill ~417 ~63 ~34 ~421 ~65 ~34 dirt
fill ~417 ~66 ~34 ~421 ~66 ~34 grass_block
fill ~422 ~60 ~34 ~424 ~63 ~34 stone
fill ~422 ~64 ~34 ~424 ~66 ~34 dirt
fill ~422 ~67 ~34 ~424 ~67 ~34 grass_block
fill ~425 ~60 ~34 ~428 ~64 ~34 stone
fill ~425 ~65 ~34 ~428 ~67 ~34 dirt
fill ~425 ~68 ~34 ~428 ~68 ~34 grass_block
fill ~429 ~60 ~34 ~431 ~63 ~34 stone
fill ~429 ~64 ~34 ~431 ~66 ~34 dirt
fill ~429 ~67 ~34 ~431 ~67 ~34 grass_block
fill ~416 ~60 ~35 ~416 ~63 ~35 stone
fill ~416 ~64 ~35 ~416 ~66 ~35 dirt
fill ~416 ~67 ~35 ~416 ~67 ~35 grass_block
fill ~417 ~60 ~35 ~421 ~62 ~35 stone
fill ~417 ~63 ~35 ~421 ~65 ~35 dirt
fill ~417 ~66 ~35 ~421 ~66 ~35 grass_block
fill ~422 ~60 ~35 ~423 ~63 ~35 stone
fill ~422 ~64 ~35 ~423 ~66 ~35 dirt
fill ~422 ~67 ~35 ~423 ~67 ~35 grass_block
fill ~424 ~60 ~35 ~428 ~64 ~35 stone
fill ~424 ~65 ~35 ~428 ~67 ~35 dirt
fill ~424 ~68 ~35 ~428 ~68 ~35 grass_block
fill ~429 ~60 ~35 ~431 ~63 ~35 stone
fill ~429 ~64 ~35 ~431 ~66 ~35 dirt
fill ~429 ~67 ~35 ~431 ~67 ~35 grass_block
fill ~416 ~60 ~36 ~416 ~63 ~36 stone
fill ~416 ~64 ~36 ~416 ~66 ~36 dirt
fill ~416 ~67 ~36 ~416 ~67 ~36 grass_block
fill ~417 ~60 ~36 ~422 ~62 ~36 stone
fill ~417 ~63 ~36 ~422 ~65 ~36 dirt
fill ~417 ~66 ~36 ~422 ~66 ~36 grass_block
fill ~423 ~60 ~36 ~423 ~63 ~36 stone
fill ~423 ~64 ~36 ~423 ~66 ~36 dirt
fill ~423 ~67 ~36 ~423 ~67 ~36 grass_block
fill ~424 ~60 ~36 ~429 ~64 ~36 stone
fill ~424 ~65 ~36 ~429 ~67 ~36 dirt
fill ~424 ~68 ~36 ~429 ~68 ~36 grass_block
fill ~430 ~60 ~36 ~431 ~63 ~36 stone
fill ~430 ~64 ~36 ~431 ~66 ~36 dirt
fill ~430 ~67 ~36 ~431 ~67 ~36 grass_block
fill ~416 ~60 ~37 ~419 ~62 ~37 stone
fill ~416 ~63 ~37 ~419 ~65 ~37 dirt
fill ~416 ~66 ~37 ~419 ~66 ~37 grass_block
fill ~420 ~60 ~37 ~423 ~63 ~37 stone
fill ~420 ~64 ~37 ~423 ~66 ~37 dirt
fill ~420 ~67 ~37 ~423 ~67 ~37 grass_block
fill ~424 ~60 ~37 ~430 ~64 ~37 stone
fill ~424 ~65 ~37 ~430 ~67 ~37 dirt
fill ~424 ~68 ~37 ~430 ~68 ~37 grass_block
fill ~431 ~60 ~37 ~431 ~63 ~37 stone
fill ~431 ~64 ~37 ~431 ~66 ~37 dirt
fill ~431 ~67 ~37 ~431 ~67 ~37 grass_block
fill ~416 ~60 ~38 ~416 ~62 ~38 stone
fill ~416 ~63 ~38 ~416 ~65 ~38 dirt
fill ~416 ~66 ~38 ~416 ~66 ~38 grass_block
fill ~417 ~60 ~38 ~420 ~63 ~38 stone
fill ~417 ~64 ~38 ~420 ~66 ~38 dirt
fill ~417 ~67 ~38 ~420 ~67 ~38 grass_block
fill ~421 ~60 ~38 ~424 ~64 ~38 stone
fill ~421 ~65 ~38 ~424 ~67 ~38 dirt
fill ~421 ~68 ~38 ~424 ~68 ~38 grass_block
fill ~425 ~60 ~38 ~426 ~65 ~38 stone
fill ~425 ~66 ~38 ~426 ~68 ~38 dirt
fill ~425 ~69 ~38 ~426 ~69 ~38 grass_block
fill ~427 ~60 ~38 ~430 ~64 ~38 stone
fill ~427 ~65 ~38 ~430 ~67 ~38 dirt
fill ~427 ~68 ~38 ~430 ~68 ~38 grass_block
fill ~431 ~60 ~38 ~431 ~63 ~38 stone
fill ~431 ~64 ~38 ~431 ~66 ~38 dirt
fill ~431 ~67 ~38 ~431 ~67 ~38 grass_block
fill ~416 ~60 ~39 ~417 ~63 ~39 stone
fill ~416 ~64 ~39 ~417 ~66 ~39 dirt
fill ~416 ~67 ~39 ~417 ~67 ~39 grass_block
fill ~418 ~60 ~39 ~420 ~64 ~39 stone
fill ~418 ~65 ~39 ~420 ~67 ~39 dirt
fill ~418 ~68 ~39 ~420 ~68 ~39 grass_block
fill ~421 ~60 ~39 ~426 ~65 ~39 stone
fill ~421 ~66 ~39 ~426 ~68 ~39 dirt
fill ~421 ~69 ~39 ~426 ~69 ~39 grass_block
fill ~427 ~60 ~39 ~430 ~64 ~39 stone
fill ~427 ~65 ~39 ~430 ~67 ~39 dirt
fill ~427 ~68 ~39 ~430 ~68 ~39 grass_block
fill ~431 ~60 ~39 ~431 ~63 ~39 stone
fill ~431 ~64 ~39 ~431 ~66 ~39 dirt
fill ~431 ~67 ~39 ~431 ~67 ~39 grass_block
fill ~416 ~60 ~40 ~416 ~62 ~40 stone
fill ~416 ~63 ~40 ~416 ~65 ~40 dirt
fill ~416 ~66 ~40 ~416 ~66 ~40 grass_block
fill ~417 ~60 ~40 ~417 ~63 ~40 stone
fill ~417 ~64 ~40 ~417 ~66 ~40 dirt
fill ~417 ~67 ~40 ~417 ~67 ~40 grass_block
fill ~418 ~60 ~40 ~420 ~64 ~40 stone
fill ~418 ~65 ~40 ~420 ~67 ~40 dirt
fill ~418 ~68 ~40 ~420 ~68 ~40 grass_block
fill ~421 ~60 ~40 ~425 ~65 ~40 stone
fill ~421 ~66 ~40 ~425 ~68 ~40 dirt
fill ~421 ~69 ~40 ~425 ~69 ~40 grass_block
fill ~426 ~60 ~40 ~429 ~64 ~40 stone
fill ~426 ~65 ~40 ~429 ~67 ~40 dirt
fill ~426 ~68 ~40 ~429 ~68 ~40 grass_block
fill ~430 ~60 ~40 ~431 ~63 ~40 stone
fill ~430 ~64 ~40 ~431 ~66 ~40 dirt
fill ~430 ~67 ~40 ~431 ~67 ~40 grass_block
fill ~416 ~60 ~41 ~416 ~62 ~41 stone
fill ~416 ~63 ~41 ~416 ~65 ~41 dirt
fill ~416 ~66 ~41 ~416 ~66 ~41 grass_block
fill ~417 ~60 ~41 ~419 ~63 ~41 stone
fill ~417 ~64 ~41 ~419 ~66 ~41 dirt
fill ~417 ~67 ~41 ~419 ~67 ~41 grass_block
fill ~420 ~60 ~41 ~420 ~64 ~41 stone
fill ~420 ~65 ~41 ~420 ~67 ~41 dirt
fill ~420 ~68 ~41 ~420 ~68 ~41 grass_block
fill ~421 ~60 ~41 ~425 ~65 ~41 stone
fill ~421 ~66 ~41 ~425 ~68 ~41 dirt
fill ~421 ~69 ~41 ~425 ~69 ~41 grass_block
fill ~426 ~60 ~41 ~428 ~64 ~41 stone
fill ~426 ~65 ~41 ~428 ~67 ~41 dirt
fill ~426 ~68 ~41 ~428 ~68 ~41 grass_block
fill ~429 ~60 ~41 ~431 ~63 ~41 stone
fill ~429 ~64 ~41 ~431 ~66 ~41 dirt
fill ~429 ~67 ~41 ~431 ~67 ~41 grass_block
fill ~416 ~60 ~42 ~416 ~62 ~42 stone
fill ~416 ~63 ~42 ~416 ~65 ~42 dirt
fill ~416 ~66 ~42 ~416 ~66 ~42 grass_block
fill ~417 ~60 ~42 ~419 ~63 ~42 stone
fill ~417 ~64 ~42 ~419 ~66 ~42 dirt
fill ~417 ~67 ~42 ~419 ~67 ~42 grass_block
fill ~420 ~60 ~42 ~420 ~64 ~42 stone
fill ~420 ~65 ~42 ~420 ~67 ~42 dirt
fill ~420 ~68 ~42 ~420 ~68 ~42 grass_block
fill ~421 ~60 ~42 ~424 ~65 ~42 stone
fill ~421 ~66 ~42 ~424 ~68 ~42 dirt
fill ~421 ~69 ~42 ~424 ~69 ~42 grass_block
fill ~425 ~60 ~42 ~427 ~64 ~42 stone
fill ~425 ~65 ~42 ~427 ~67 ~42 dirt
fill ~425 ~68 ~42 ~427 ~68 ~42 grass_block
fill ~428 ~60 ~42 ~431 ~63 ~42 stone
fill ~428 ~64 ~42 ~431 ~66 ~42 dirt
fill ~428 ~67 ~42 ~431 ~67 ~42 grass_block
fill ~416 ~60 ~43 ~416 ~62 ~43 stone
fill ~416 ~63 ~43 ~416 ~65 ~43 dirt
fill ~416 ~66 ~43 ~416 ~66 ~43 grass_block
fill ~417 ~60 ~43 ~418 ~63 ~43 stone
fill ~417 ~64 ~43 ~418 ~66 ~43 dirt
fill ~417 ~67 ~43 ~418 ~67 ~43 grass_block
fill ~419 ~60 ~43 ~420 ~64 ~43 stone
fill ~419 ~65 ~43 ~420 ~67 ~43 dirt
fill ~419 ~68 ~43 ~420 ~68 ~43 grass_block
fill ~421 ~60 ~43 ~423 ~65 ~43 stone
fill ~421 ~66 ~43 ~423 ~68 ~43 dirt
fill ~421 ~69 ~43 ~423 ~69 ~43 grass_block
fill ~424 ~60 ~43 ~426 ~64 ~43 stone
fill ~424 ~65 ~43 ~426 ~67 ~43 dirt
fill ~424 ~68 ~43 ~426 ~68 ~43 grass_block
fill ~427 ~60 ~43 ~431 ~63 ~43 stone
fill ~427 ~64 ~43 ~431 ~66 ~43 dirt
fill ~427 ~67 ~43 ~431 ~67 ~43 grass_block
fill ~416 ~60 ~44 ~416 ~62 ~44 stone
fill ~416 ~63 ~44 ~416 ~65 ~44 dirt
fill ~416 ~66 ~44 ~416 ~66 ~44 grass_block
fill ~417 ~60 ~44 ~418 ~63 ~44 stone
fill ~417 ~64 ~44 ~418 ~66 ~44 dirt
fill ~417 ~67 ~44 ~418 ~67 ~44 grass_block
fill ~419 ~60 ~44 ~420 ~64 ~44 stone
fill ~419 ~65 ~44 ~420 ~67 ~44 dirt
fill ~419 ~68 ~44 ~420 ~68 ~44 grass_block
fill ~421 ~60 ~44 ~423 ~65 ~44 stone
fill ~421 ~66 ~44 ~423 ~68 ~44 dirt
fill ~421 ~69 ~44 ~423 ~69 ~44 grass_block
fill ~424 ~60 ~44 ~430 ~64 ~44 stone
fill ~424 ~65 ~44 ~430 ~67 ~44 dirt
fill ~424 ~68 ~44 ~430 ~68 ~44 grass_block
fill ~431 ~60 ~44 ~431 ~63 ~44 stone
fill ~431 ~64 ~44 ~431 ~66 ~44 dirt
fill ~431 ~67 ~44 ~431 ~67 ~44 grass_block
fill ~416 ~60 ~45 ~417 ~63 ~45 stone
fill ~416 ~64 ~45 ~417 ~66 ~45 dirt
fill ~416 ~67 ~45 ~417 ~67 ~45 grass_block
fill ~418 ~60 ~45 ~419 ~64 ~45 stone
fill ~418 ~65 ~45 ~419 ~67 ~45 dirt
fill ~418 ~68 ~45 ~419 ~68 ~45 grass_block
fill ~420 ~60 ~45 ~424 ~65 ~45 stone
fill ~420 ~66 ~45 ~424 ~68 ~45 dirt
fill ~420 ~69 ~45 ~424 ~69 ~45 grass_block
fill ~425 ~60 ~45 ~431 ~64 ~45 stone
fill ~425 ~65 ~45 ~431 ~67 ~45 dirt
fill ~425 ~68 ~45 ~431 ~68 ~45 grass_block
fill ~416 ~60 ~46 ~417 ~63 ~46 stone
fill ~416 ~64 ~46 ~417 ~66 ~46 dirt
fill ~416 ~67 ~46 ~417 ~67 ~46 grass_block
fill ~418 ~60 ~46 ~419 ~64 ~46 stone
fill ~418 ~65 ~46 ~419 ~67 ~46 dirt
fill ~418 ~68 ~46 ~419 ~68 ~46 grass_block
fill ~420 ~60 ~46 ~424 ~65 ~46 stone
fill ~420 ~66 ~46 ~424 ~68 ~46 dirt
fill ~420 ~69 ~46 ~424 ~69 ~46 grass_block
fill ~425 ~60 ~46 ~431 ~64 ~46 stone
fill ~425 ~65 ~46 ~431 ~67 ~46 dirt
fill ~425 ~68 ~46 ~431 ~68 ~46 grass_block
fill ~416 ~60 ~47 ~417 ~64 ~47 stone
fill ~416 ~65 ~47 ~417 ~67 ~47 dirt
fill ~416 ~68 ~47 ~417 ~68 ~47 grass_block
fill ~418 ~60 ~47 ~421 ~65 ~47 stone
fill ~418 ~66 ~47 ~421 ~68 ~47 dirt
fill ~418 ~69 ~47 ~421 ~69 ~47 grass_block
fill ~422 ~60 ~47 ~430 ~64 ~47 stone
fill ~422 ~65 ~47 ~430 ~67 ~47 dirt
fill ~422 ~68 ~47 ~430 ~68 ~47 grass_block
fill ~431 ~60 ~47 ~431 ~63 ~47 stone
fill ~431 ~64 ~47 ~431 ~66 ~47 dirt
fill ~431 ~67 ~47 ~431 ~67 ~47 grass_block