fill ~352 ~60 ~16 ~353 ~63 ~16 stone
fill ~352 ~64 ~16 ~353 ~66 ~16 dirt
fill ~352 ~67 ~16 ~353 ~67 ~16 grass_block
fill ~354 ~60 ~16 ~361 ~62 ~16 stone
fill ~354 ~63 ~16 ~361 ~65 ~16 dirt
fill ~354 ~66 ~16 ~361 ~66 ~16 grass_block
fill ~362 ~60 ~16 ~366 ~63 ~16 stone
fill ~362 ~64 ~16 ~366 ~66 ~16 dirt
fill ~362 ~67 ~16 ~366 ~67 ~16 grass_block
fill ~367 ~60 ~16 ~367 ~62 ~16 stone
fill ~367 ~63 ~16 ~367 ~65 ~16 dirt
fill ~367 ~66 ~16 ~367 ~66 ~16 grass_block
fill ~352 ~60 ~17 ~353 ~63 ~17 stone
fill ~352 ~64 ~17 ~353 ~66 ~17 dirt
fill ~352 ~67 ~17 ~353 ~67 ~17 grass_block
fill ~354 ~60 ~17 ~354 ~62 ~17 stone
fill ~354 ~63 ~17 ~354 ~65 ~17 dirt
fill ~354 ~66 ~17 ~354 ~66 ~17 grass_block
fill ~355 ~60 ~17 ~361 ~63 ~17 stone
fill ~355 ~64 ~17 ~361 ~66 ~17 dirt
fill ~355 ~67 ~17 ~361 ~67 ~17 grass_block
fill ~362 ~60 ~17 ~366 ~64 ~17 stone
fill ~362 ~65 ~17 ~366 ~67 ~17 dirt
fill ~362 ~68 ~17 ~366 ~68 ~17 grass_block
fill ~367 ~60 ~17 ~367 ~63 ~17 stone
fill ~367 ~64 ~17 ~367 ~66 ~17 dirt
fill ~367 ~67 ~17 ~367 ~67 ~17 grass_block
fill ~352 ~60 ~18 ~360 ~63 ~18 stone
fill ~352 ~64 ~18 ~360 ~66 ~18 dirt
fill ~352 ~67 ~18 ~360 ~67 ~18 grass_block
fill ~361 ~60 ~18 ~363 ~64 ~18 stone
fill ~361 ~65 ~18 ~363 ~67 ~18 dirt
fill ~361 ~68 ~18 ~363 ~68 ~18 grass_block
fill ~364 ~60 ~18 ~364 ~65 ~18 stone
fill ~364 ~66 ~18 ~364 ~68 ~18 dirt
fill ~364 ~69 ~18 ~364 ~69 ~18 grass_block
fill ~365 ~60 ~18 ~367 ~64 ~18 stone
fill ~365 ~65 ~18 ~367 ~67 ~18 dirt
fill ~365 ~68 ~18 ~367 ~68 ~18 grass_block
fill ~352 ~60 ~19 ~357 ~64 ~19 stone
fill ~352 ~65 ~19 ~357 ~67 ~19 dirt
fill ~352 ~68 ~19 ~357 ~68 ~19 grass_block
fill ~358 ~60 ~19 ~360 ~63 ~19 stone
fill ~358 ~64 ~19 ~360 ~66 ~19 dirt
fill ~358 ~67 ~19 ~360 ~67 ~19 grass_block
fill ~361 ~60 ~19 ~362 ~64 ~19 stone
fill ~361 ~65 ~19 ~362 ~67 ~19 dirt
fill ~361 ~68 ~19 ~362 ~68 ~19 grass_block
fill ~363 ~60 ~19 ~365 ~65 ~19 stone
fill ~363 ~66 ~19 ~365 ~68 ~19 dirt
fill ~363 ~69 ~19 ~365 ~69 ~19 grass_block
fill ~366 ~60 ~19 ~367 ~64 ~19 stone
fill ~366 ~65 ~19 ~367 ~67 ~19 dirt
fill ~366 ~68 ~19 ~367 ~68 ~19 grass_block
fill ~352 ~60 ~20 ~362 ~64 ~20 stone
fill ~352 ~65 ~20 ~362 ~67 ~20 dirt
fill ~352 ~68 ~20 ~362 ~68 ~20 grass_block
fill ~363 ~60 ~20 ~367 ~65 ~20 stone
fill ~363 ~66 ~20 ~367 ~68 ~20 dirt
fill ~363 ~69 ~20 ~367 ~69 ~20 grass_block
fill ~352 ~60 ~21 ~357 ~65 ~21 stone
fill ~352 ~66 ~21 ~357 ~68 ~21 dirt
fill ~352 ~69 ~21 ~357 ~69 ~21 grass_block
fill ~358 ~60 ~21 ~361 ~64 ~21 stone
fill ~358 ~65 ~21 ~361 ~67 ~21 dirt
fill ~358 ~68 ~21 ~361 ~68 ~21 grass_block
fill ~362 ~60 ~21 ~367 ~65 ~21 stone
fill ~362 ~66 ~21 ~367 ~68 ~21 dirt
fill ~362 ~69 ~21 ~367 ~69 ~21 grass_block
fill ~352 ~60 ~22 ~367 ~65 ~22 stone
fill ~352 ~66 ~22 ~367 ~68 ~22 dirt
fill ~352 ~69 ~22 ~367 ~69 ~22 grass_block
fill ~352 ~60 ~23 ~365 ~65 ~23 stone
fill ~352 ~66 ~23 ~365 ~68 ~23 dirt
fill ~352 ~69 ~23 ~365 ~69 ~23 grass_block
fill ~366 ~60 ~23 ~367 ~64 ~23 stone
fill ~366 ~65 ~23 ~367 ~67 ~23 dirt
fill ~366 ~68 ~23 ~367 ~68 ~23 grass_block
fill ~352 ~60 ~24 ~352 ~65 ~24 stone
fill ~352 ~66 ~24 ~352 ~68 ~24 dirt
fill ~352 ~69 ~24 ~352 ~69 ~24 grass_block
fill ~353 ~60 ~24 ~354 ~66 ~24 stone
fill ~353 ~67 ~24 ~354 ~69 ~24 dirt
fill ~353 ~70 ~24 ~354 ~70 ~24 grass_block
fill ~355 ~60 ~24 ~362 ~65 ~24 stone
fill ~355 ~66 ~24 ~362 ~68 ~24 dirt
fill ~355 ~69 ~24 ~362 ~69 ~24 grass_block
fill ~363 ~60 ~24 ~367 ~64 ~24 stone
fill ~363 ~65 ~24 ~367 ~67 ~24 dirt
fill ~363 ~68 ~24 ~367 ~68 ~24 grass_block
fill ~352 ~60 ~25 ~352 ~65 ~25 stone
fill ~352 ~66 ~25 ~352 ~68 ~25 dirt
fill ~352 ~69 ~25 ~352 ~69 ~25 grass_block
fill ~353 ~60 ~25 ~353 ~66 ~25 stone
fill ~353 ~67 ~25 ~353 ~69 ~25 dirt
fill ~353 ~70 ~25 ~353 ~70 ~25 grass_block
fill ~354 ~60 ~25 ~362 ~65 ~25 stone
fill ~354 ~66 ~25 ~362 ~68 ~25 dirt
fill ~354 ~69 ~25 ~362 ~69 ~25 grass_block
fill ~363 ~60 ~25 ~364 ~64 ~25 stone
fill ~363 ~65 ~25 ~364 ~67 ~25 dirt
fill ~363 ~68 ~25 ~364 ~68 ~25 grass_block
fill ~365 ~60 ~25 ~367 ~63 ~25 stone
fill ~365 ~64 ~25 ~367 ~66 ~25 dirt
fill ~365 ~67 ~25 ~367 ~67 ~25 grass_block
fill ~352 ~60 ~26 ~361 ~65 ~26 stone
fill ~352 ~66 ~26 ~361 ~68 ~26 dirt
fill ~352 ~69 ~26 ~361 ~69 ~26 grass_block
fill ~362 ~60 ~26 ~365 ~64 ~26 stone
fill ~362 ~65 ~26 ~365 ~67 ~26 dirt
fill ~362 ~68 ~26 ~365 ~68 ~26 grass_block
fill ~366 ~60 ~26 ~367 ~63 ~26 stone
fill ~366 ~64 ~26 ~367 ~66 ~26 dirt
fill ~366 ~67 ~26 ~367 ~67 ~26 grass_block
fill ~352 ~60 ~27 ~353 ~65 ~27 stone
fill ~352 ~66 ~27 ~353 ~68 ~27 dirt
fill ~352 ~69 ~27 ~353 ~69 ~27 grass_block
fill ~354 ~60 ~27 ~358 ~64 ~27 stone
fill ~354 ~65 ~27 ~358 ~67 ~27 dirt
fill ~354 ~68 ~27 ~358 ~68 ~27 grass_block
fill ~359 ~60 ~27 ~362 ~65 ~27 stone
fill ~359 ~66 ~27 ~362 ~68 ~27 dirt
fill ~359 ~69 ~27 ~362 ~69 ~27 grass_block
fill ~363 ~60 ~27 ~367 ~64 ~27 stone
fill ~363 ~65 ~27 ~367 ~67 ~27 dirt
fill ~363 ~68 ~27 ~367 ~68 ~27 grass_block
fill ~352 ~60 ~28 ~357 ~64 ~28 stone
fill ~352 ~65 ~28 ~357 ~67 ~28 dirt
fill ~352 ~68 ~28 ~357 ~68 ~28 grass_block
fill ~358 ~60 ~28 ~360 ~65 ~28 stone
fill ~358 ~66 ~28 ~360 ~68 ~28 dirt
fill ~358 ~69 ~28 ~360 ~69 ~28 grass_block
fill ~361 ~60 ~28 ~361 ~66 ~28 stone
fill ~361 ~67 ~28 ~361 ~69 ~28 dirt
fill ~361 ~70 ~28 ~361 ~70 ~28 grass_block
fill ~362 ~60 ~28 ~366 ~65 ~28 stone
fill ~362 ~66 ~28 ~366 ~68 ~28 dirt
fill ~362 ~69 ~28 ~366 ~69 ~28 grass_block
fill ~367 ~60 ~28 ~367 ~64 ~28 stone
fill ~367 ~65 ~28 ~367 ~67 ~28 dirt
fill ~367 ~68 ~28 ~367 ~68 ~28 grass_block
fill ~352 ~60 ~29 ~357 ~64 ~29 stone
fill ~352 ~65 ~29 ~357 ~67 ~29 dirt
fill ~352 ~68 ~29 ~357 ~68 ~29 grass_block
fill ~358 ~60 ~29 ~359 ~65 ~29 stone
fill ~358 ~66 ~29 ~359 ~68 ~29 dirt
fill ~358 ~69 ~29 ~359 ~69 ~29 grass_block
fill ~360 ~60 ~29 ~365 ~66 ~29 stone
fill ~360 ~67 ~29 ~365 ~69 ~29 dirt
fill ~360 ~70 ~29 ~365 ~70 ~29 grass_block
fill ~366 ~60 ~29 ~367 ~65 ~29 stone
fill ~366 ~66 ~29 ~367 ~68 ~29 dirt
fill ~366 ~69 ~29 ~367 ~69 ~29 grass_block
fill ~352 ~60 ~30 ~356 ~64 ~30 stone
fill ~352 ~65 ~30 ~356 ~67 ~30 dirt
fill ~352 ~68 ~30 ~356 ~68 ~30 grass_block
fill ~357 ~60 ~30 ~358 ~65 ~30 stone
fill ~357 ~66 ~30 ~358 ~68 ~30 dirt
fill ~357 ~69 ~30 ~358 ~69 ~30 grass_block
fill ~359 ~60 ~30 ~365 ~66 ~30 stone
fill ~359 ~67 ~30 ~365 ~69 ~30 dirt
fill ~359 ~70 ~30 ~365 ~70 ~30 grass_block
fill ~366 ~60 ~30 ~367 ~65 ~30 stone
fill ~366 ~66 ~30 ~367 ~68 ~30 dirt
fill ~366 ~69 ~30 ~367 ~69 ~30 grass_block
fill ~352 ~60 ~31 ~353 ~63 ~31 stone
fill ~352 ~64 ~31 ~353 ~66 ~31 dirt
fill ~352 ~67 ~31 ~353 ~67 ~31 grass_block
fill ~354 ~60 ~31 ~355 ~64 ~31 stone
fill ~354 ~65 ~31 ~355 ~67 ~31 dirt
fill ~354 ~68 ~31 ~355 ~68 ~31 grass_block
fill ~356 ~60 ~31 ~358 ~65 ~31 stone
fill ~356 ~66 ~31 ~358 ~68 ~31 dirt
fill ~356 ~69 ~31 ~358 ~69 ~31 grass_block
fill ~359 ~60 ~31 ~366 ~66 ~31 stone
fill ~359 ~67 ~31 ~366 ~69 ~31 dirt
fill ~359 ~70 ~31 ~366 ~70 ~31 grass_block
fill ~367 ~60 ~31 ~367 ~65 ~31 stone
fill ~367 ~66 ~31 ~367 ~68 ~31 dirt
fill ~367 ~69 ~31 ~367 ~69 ~31 grass_block