fill ~416 ~60 ~112 ~423 ~63 ~112 stone
fill ~416 ~64 ~112 ~423 ~66 ~112 dirt
fill ~416 ~67 ~112 ~423 ~67 ~112 grass_block
fill ~424 ~60 ~112 ~431 ~64 ~112 stone
fill ~424 ~65 ~112 ~431 ~67 ~112 dirt
fill ~424 ~68 ~112 ~431 ~68 ~112 grass_block
fill ~416 ~60 ~113 ~424 ~63 ~113 stone
fill ~416 ~64 ~113 ~424 ~66 ~113 dirt
fill ~416 ~67 ~113 ~424 ~67 ~113 grass_block
fill ~425 ~60 ~113 ~431 ~64 ~113 stone
fill ~425 ~65 ~113 ~431 ~67 ~113 dirt
fill ~425 ~68 ~113 ~431 ~68 ~113 grass_block
fill ~416 ~60 ~114 ~425 ~63 ~114 stone
fill ~416 ~64 ~114 ~425 ~66 ~114 dirt
fill ~416 ~67 ~114 ~425 ~67 ~114 grass_block
fill ~426 ~60 ~114 ~426 ~64 ~114 stone
fill ~426 ~65 ~114 ~426 ~67 ~114 dirt
fill ~426 ~68 ~114 ~426 ~68 ~114 grass_block
fill ~427 ~60 ~114 ~427 ~63 ~114 stone
fill ~427 ~64 ~114 ~427 ~66 ~114 dirt
fill ~427 ~67 ~114 ~427 ~67 ~114 grass_block
fill ~428 ~60 ~114 ~428 ~64 ~114 stone
fill ~428 ~65 ~114 ~428 ~67 ~114 dirt
fill ~428 ~68 ~114 ~428 ~68 ~114 grass_block
fill ~429 ~60 ~114 ~431 ~63 ~114 stone
fill ~429 ~64 ~114 ~431 ~66 ~114 dirt
fill ~429 ~67 ~114 ~431 ~67 ~114 grass_block
fill ~416 ~60 ~115 ~431 ~63 ~115 stone
fill ~416 ~64 ~115 ~431 ~66 ~115 dirt
fill ~416 ~67 ~115 ~431 ~67 ~115 grass_block
fill ~416 ~60 ~116 ~418 ~63 ~116 stone
fill ~416 ~64 ~116 ~418 ~66 ~116 dirt
fill ~416 ~67 ~116 ~418 ~67 ~116 grass_block
fill ~419 ~60 ~116 ~419 ~62 ~116 stone
fill ~419 ~63 ~116 ~419 ~65 ~116 dirt
fill ~419 ~66 ~116 ~419 ~66 ~116 grass_block
fill ~420 ~60 ~116 ~431 ~63 ~116 stone
fill ~420 ~64 ~116 ~431 ~66 ~116 dirt
fill ~420 ~67 ~116 ~431 ~67 ~116 grass_block
fill ~416 ~60 ~117 ~418 ~63 ~117 stone
fill ~416 ~64 ~117 ~418 ~66 ~117 dirt
fill ~416 ~67 ~117 ~418 ~67 ~117 grass_block
fill ~419 ~60 ~117 ~420 ~62 ~117 stone
fill ~419 ~63 ~117 ~420 ~65 ~117 dirt
fill ~419 ~66 ~117 ~420 ~66 ~117 grass_block
fill ~421 ~60 ~117 ~431 ~63 ~117 stone
fill ~421 ~64 ~117 ~431 ~66 ~117 dirt
fill ~421 ~67 ~117 ~431 ~67 ~117 grass_block
fill ~416 ~60 ~118 ~418 ~63 ~118 stone
fill ~416 ~64 ~118 ~418 ~66 ~118 dirt
fill ~416 ~67 ~118 ~418 ~67 ~118 grass_block
fill ~419 ~60 ~118 ~421 ~62 ~118 stone
fill ~419 ~63 ~118 ~421 ~65 ~118 dirt
fill ~419 ~66 ~118 ~421 ~66 ~118 grass_block
fill ~422 ~60 ~118 ~427 ~63 ~118 stone
fill ~422 ~64 ~118 ~427 ~66 ~118 dirt
fill ~422 ~67 ~118 ~427 ~67 ~118 grass_block
fill ~428 ~60 ~118 ~428 ~62 ~118 stone
fill ~428 ~63 ~118 ~428 ~65 ~118 dirt
fill ~428 ~66 ~118 ~428 ~66 ~118 grass_block
fill ~429 ~60 ~118 ~431 ~63 ~118 stone
fill ~429 ~64 ~118 ~431 ~66 ~118 dirt
fill ~429 ~67 ~118 ~431 ~67 ~118 grass_block
fill ~416 ~60 ~119 ~419 ~63 ~119 stone
fill ~416 ~64 ~119 ~419 ~66 ~119 dirt
fill ~416 ~67 ~119 ~419 ~67 ~119 grass_block
fill ~420 ~60 ~119 ~422 ~62 ~119 stone
fill ~420 ~63 ~119 ~422 ~65 ~119 dirt
fill ~420 ~66 ~119 ~422 ~66 ~119 grass_block
fill ~423 ~60 ~119 ~425 ~63 ~119 stone
fill ~423 ~64 ~119 ~425 ~66 ~119 dirt
fill ~423 ~67 ~119 ~425 ~67 ~119 grass_block
fill ~426 ~60 ~119 ~428 ~62 ~119 stone
fill ~426 ~63 ~119 ~428 ~65 ~119 dirt
fill ~426 ~66 ~119 ~428 ~66 ~119 grass_block
fill ~429 ~60 ~119 ~431 ~63 ~119 stone
fill ~429 ~64 ~119 ~431 ~66 ~119 dirt
fill ~429 ~67 ~119 ~431 ~67 ~119 grass_block
fill ~416 ~60 ~120 ~419 ~63 ~120 stone
fill ~416 ~64 ~120 ~419 ~66 ~120 dirt
fill ~416 ~67 ~120 ~419 ~67 ~120 grass_block
fill ~420 ~60 ~120 ~423 ~62 ~120 stone
fill ~420 ~63 ~120 ~423 ~65 ~120 dirt
fill ~420 ~66 ~120 ~423 ~66 ~120 grass_block
fill ~424 ~60 ~120 ~424 ~63 ~120 stone
fill ~424 ~64 ~120 ~424 ~66 ~120 dirt
fill ~424 ~67 ~120 ~424 ~67 ~120 grass_block
fill ~425 ~60 ~120 ~428 ~62 ~120 stone
fill ~425 ~63 ~120 ~428 ~65 ~120 dirt
fill ~425 ~66 ~120 ~428 ~66 ~120 grass_block
fill ~429 ~60 ~120 ~431 ~63 ~120 stone
fill ~429 ~64 ~120 ~431 ~66 ~120 dirt
fill ~429 ~67 ~120 ~431 ~67 ~120 grass_block
fill ~416 ~60 ~121 ~416 ~64 ~121 stone
fill ~416 ~65 ~121 ~416 ~67 ~121 dirt
fill ~416 ~68 ~121 ~416 ~68 ~121 grass_block
fill ~417 ~60 ~121 ~419 ~63 ~121 stone
fill ~417 ~64 ~121 ~419 ~66 ~121 dirt
fill ~417 ~67 ~121 ~419 ~67 ~121 grass_block
fill ~420 ~60 ~121 ~428 ~62 ~121 stone
fill ~420 ~63 ~121 ~428 ~65 ~121 dirt
fill ~420 ~66 ~121 ~428 ~66 ~121 grass_block
fill ~429 ~60 ~121 ~431 ~63 ~121 stone
fill ~429 ~64 ~121 ~431 ~66 ~121 dirt
fill ~429 ~67 ~121 ~431 ~67 ~121 grass_block
fill ~416 ~60 ~122 ~416 ~64 ~122 stone
fill ~416 ~65 ~122 ~416 ~67 ~122 dirt
fill ~416 ~68 ~122 ~416 ~68 ~122 grass_block
fill ~417 ~60 ~122 ~419 ~63 ~122 stone
fill ~417 ~64 ~122 ~419 ~66 ~122 dirt
fill ~417 ~67 ~122 ~419 ~67 ~122 grass_block
fill ~420 ~60 ~122 ~427 ~62 ~122 stone
fill ~420 ~63 ~122 ~427 ~65 ~122 dirt
fill ~420 ~66 ~122 ~427 ~66 ~122 grass_block
fill ~428 ~60 ~122 ~431 ~63 ~122 stone
fill ~428 ~64 ~122 ~431 ~66 ~122 dirt
fill ~428 ~67 ~122 ~431 ~67 ~122 grass_block
fill ~416 ~60 ~123 ~416 ~64 ~123 stone
fill ~416 ~65 ~123 ~416 ~67 ~123 dirt
fill ~416 ~68 ~123 ~416 ~68 ~123 grass_block
fill ~417 ~60 ~123 ~420 ~63 ~123 stone
fill ~417 ~64 ~123 ~420 ~66 ~123 dirt
fill ~417 ~67 ~123 ~420 ~67 ~123 grass_block
fill ~421 ~60 ~123 ~427 ~62 ~123 stone
fill ~421 ~63 ~123 ~427 ~65 ~123 dirt
fill ~421 ~66 ~123 ~427 ~66 ~123 grass_block
fill ~428 ~60 ~123 ~431 ~63 ~123 stone
fill ~428 ~64 ~123 ~431 ~66 ~123 dirt
fill ~428 ~67 ~123 ~431 ~67 ~123 grass_block
fill ~416 ~60 ~124 ~416 ~64 ~124 stone
fill ~416 ~65 ~124 ~416 ~67 ~124 dirt
fill ~416 ~68 ~124 ~416 ~68 ~124 grass_block
fill ~417 ~60 ~124 ~420 ~63 ~124 stone
fill ~417 ~64 ~124 ~420 ~66 ~124 dirt
fill ~417 ~67 ~124 ~420 ~67 ~124 grass_block
fill ~421 ~60 ~124 ~427 ~62 ~124 stone
fill ~421 ~63 ~124 ~427 ~65 ~124 dirt
fill ~421 ~66 ~124 ~427 ~66 ~124 grass_block
fill ~428 ~60 ~124 ~431 ~63 ~124 stone
fill ~428 ~64 ~124 ~431 ~66 ~124 dirt
fill ~428 ~67 ~124 ~431 ~67 ~124 grass_block
fill ~416 ~60 ~125 ~417 ~64 ~125 stone
fill ~416 ~65 ~125 ~417 ~67 ~125 dirt
fill ~416 ~68 ~125 ~417 ~68 ~125 grass_block
fill ~418 ~60 ~125 ~420 ~63 ~125 stone
fill ~418 ~64 ~125 ~420 ~66 ~125 dirt
fill ~418 ~67 ~125 ~420 ~67 ~125 grass_block
fill ~421 ~60 ~125 ~428 ~62 ~125 stone
fill ~421 ~63 ~125 ~428 ~65 ~125 dirt
fill ~421 ~66 ~125 ~428 ~66 ~125 grass_block
fill ~429 ~60 ~125 ~431 ~63 ~125 stone
fill ~429 ~64 ~125 ~431 ~66 ~125 dirt
fill ~429 ~67 ~125 ~431 ~67 ~125 grass_block
fill ~416 ~60 ~126 ~416 ~64 ~126 stone
fill ~416 ~65 ~126 ~416 ~67 ~126 dirt
fill ~416 ~68 ~126 ~416 ~68 ~126 grass_block
fill ~417 ~60 ~126 ~420 ~63 ~126 stone
fill ~417 ~64 ~126 ~420 ~66 ~126 dirt
fill ~417 ~67 ~126 ~420 ~67 ~126 grass_block
fill ~421 ~60 ~126 ~428 ~62 ~126 stone
fill ~421 ~63 ~126 ~428 ~65 ~126 dirt
fill ~421 ~66 ~126 ~428 ~66 ~126 grass_block
fill ~429 ~60 ~126 ~431 ~63 ~126 stone
fill ~429 ~64 ~126 ~431 ~66 ~126 dirt
fill ~429 ~67 ~126 ~431 ~67 ~126 grass_block
fill ~416 ~60 ~127 ~416 ~64 ~127 stone
fill ~416 ~65 ~127 ~416 ~67 ~127 dirt
fill ~416 ~68 ~127 ~416 ~68 ~127 grass_block
fill ~417 ~60 ~127 ~421 ~63 ~127 stone
fill ~417 ~64 ~127 ~421 ~66 ~127 dirt
fill ~417 ~67 ~127 ~421 ~67 ~127 grass_block
fill ~422 ~60 ~127 ~429 ~62 ~127 stone
fill ~422 ~63 ~127 ~429 ~65 ~127 dirt
fill ~422 ~66 ~127 ~429 ~66 ~127 grass_block
fill ~430 ~60 ~127 ~431 ~63 ~127 stone
fill ~430 ~64 ~127 ~431 ~66 ~127 dirt
fill ~430 ~67 ~127 ~431 ~67 ~127 grass_block