fill ~160 ~60 ~96 ~170 ~65 ~96 stone
fill ~160 ~66 ~96 ~170 ~68 ~96 dirt
fill ~160 ~69 ~96 ~170 ~69 ~96 grass_block
fill ~171 ~60 ~96 ~172 ~64 ~96 stone
fill ~171 ~65 ~96 ~172 ~67 ~96 dirt
fill ~171 ~68 ~96 ~172 ~68 ~96 grass_block
fill ~173 ~60 ~96 ~175 ~63 ~96 stone
fill ~173 ~64 ~96 ~175 ~66 ~96 dirt
fill ~173 ~67 ~96 ~175 ~67 ~96 grass_block
fill ~160 ~60 ~97 ~160 ~64 ~97 stone
fill ~160 ~65 ~97 ~160 ~67 ~97 dirt
fill ~160 ~68 ~97 ~160 ~68 ~97 grass_block
fill ~161 ~60 ~97 ~162 ~65 ~97 stone
fill ~161 ~66 ~97 ~162 ~68 ~97 dirt
fill ~161 ~69 ~97 ~162 ~69 ~97 grass_block
fill ~163 ~60 ~97 ~165 ~64 ~97 stone
fill ~163 ~65 ~97 ~165 ~67 ~97 dirt
fill ~163 ~68 ~97 ~165 ~68 ~97 grass_block
fill ~166 ~60 ~97 ~171 ~65 ~97 stone
fill ~166 ~66 ~97 ~171 ~68 ~97 dirt
fill ~166 ~69 ~97 ~171 ~69 ~97 grass_block
fill ~172 ~60 ~97 ~174 ~64 ~97 stone
fill ~172 ~65 ~97 ~174 ~67 ~97 dirt
fill ~172 ~68 ~97 ~174 ~68 ~97 grass_block
fill ~175 ~60 ~97 ~175 ~63 ~97 stone
fill ~175 ~64 ~97 ~175 ~66 ~97 dirt
fill ~175 ~67 ~97 ~175 ~67 ~97 grass_block
fill ~160 ~60 ~98 ~166 ~64 ~98 stone
fill ~160 ~65 ~98 ~166 ~67 ~98 dirt
fill ~160 ~68 ~98 ~166 ~68 ~98 grass_block
fill ~167 ~60 ~98 ~172 ~65 ~98 stone
fill ~167 ~66 ~98 ~172 ~68 ~98 dirt
fill ~167 ~69 ~98 ~172 ~69 ~98 grass_block
fill ~173 ~60 ~98 ~175 ~64 ~98 stone
fill ~173 ~65 ~98 ~175 ~67 ~98 dirt
fill ~173 ~68 ~98 ~175 ~68 ~98 grass_block
fill ~160 ~60 ~99 ~163 ~64 ~99 stone
fill ~160 ~65 ~99 ~163 ~67 ~99 dirt
fill ~160 ~68 ~99 ~163 ~68 ~99 grass_block
fill ~164 ~60 ~99 ~164 ~63 ~99 stone
fill ~164 ~64 ~99 ~164 ~66 ~99 dirt
fill ~164 ~67 ~99 ~164 ~67 ~99 grass_block
fill ~165 ~60 ~99 ~166 ~64 ~99 stone
fill ~165 ~65 ~99 ~166 ~67 ~99 dirt
fill ~165 ~68 ~99 ~166 ~68 ~99 grass_block
fill ~167 ~60 ~99 ~172 ~65 ~99 stone
fill ~167 ~66 ~99 ~172 ~68 ~99 dirt
fill ~167 ~69 ~99 ~172 ~69 ~99 grass_block
fill ~173 ~60 ~99 ~175 ~64 ~99 stone
fill ~173 ~65 ~99 ~175 ~67 ~99 dirt
fill ~173 ~68 ~99 ~175 ~68 ~99 grass_block
fill ~160 ~60 ~100 ~162 ~64 ~100 stone
fill ~160 ~65 ~100 ~162 ~67 ~100 dirt
fill ~160 ~68 ~100 ~162 ~68 ~100 grass_block
fill ~163 ~60 ~100 ~164 ~63 ~100 stone
fill ~163 ~64 ~100 ~164 ~66 ~100 dirt
fill ~163 ~67 ~100 ~164 ~67 ~100 grass_block
fill ~165 ~60 ~100 ~167 ~64 ~100 stone
fill ~165 ~65 ~100 ~167 ~67 ~100 dirt
fill ~165 ~68 ~100 ~167 ~68 ~100 grass_block
fill ~168 ~60 ~100 ~173 ~65 ~100 stone
fill ~168 ~66 ~100 ~173 ~68 ~100 dirt
fill ~168 ~69 ~100 ~173 ~69 ~100 grass_block
fill ~174 ~60 ~100 ~175 ~64 ~100 stone
fill ~174 ~65 ~100 ~175 ~67 ~100 dirt
fill ~174 ~68 ~100 ~175 ~68 ~100 grass_block
fill ~160 ~60 ~101 ~160 ~64 ~101 stone
fill ~160 ~65 ~101 ~160 ~67 ~101 dirt
fill ~160 ~68 ~101 ~160 ~68 ~101 grass_block
fill ~161 ~60 ~101 ~164 ~63 ~101 stone
fill ~161 ~64 ~101 ~164 ~66 ~101 dirt
fill ~161 ~67 ~101 ~164 ~67 ~101 grass_block
fill ~165 ~60 ~101 ~167 ~64 ~101 stone
fill ~165 ~65 ~101 ~167 ~67 ~101 dirt
fill ~165 ~68 ~101 ~167 ~68 ~101 grass_block
fill ~168 ~60 ~101 ~173 ~65 ~101 stone
fill ~168 ~66 ~101 ~173 ~68 ~101 dirt
fill ~168 ~69 ~101 ~173 ~69 ~101 grass_block
fill ~174 ~60 ~101 ~175 ~64 ~101 stone
fill ~174 ~65 ~101 ~175 ~67 ~101 dirt
fill ~174 ~68 ~101 ~175 ~68 ~101 grass_block
fill ~160 ~60 ~102 ~164 ~63 ~102 stone
fill ~160 ~64 ~102 ~164 ~66 ~102 dirt
fill ~160 ~67 ~102 ~164 ~67 ~102 grass_block
fill ~165 ~60 ~102 ~168 ~64 ~102 stone
fill ~165 ~65 ~102 ~168 ~67 ~102 dirt
fill ~165 ~68 ~102 ~168 ~68 ~102 grass_block
fill ~169 ~60 ~102 ~174 ~65 ~102 stone
fill ~169 ~66 ~102 ~174 ~68 ~102 dirt
fill ~169 ~69 ~102 ~174 ~69 ~102 grass_block
fill ~175 ~60 ~102 ~175 ~64 ~102 stone
fill ~175 ~65 ~102 ~175 ~67 ~102 dirt
fill ~175 ~68 ~102 ~175 ~68 ~102 grass_block
fill ~160 ~60 ~103 ~163 ~63 ~103 stone
fill ~160 ~64 ~103 ~163 ~66 ~103 dirt
fill ~160 ~67 ~103 ~163 ~67 ~103 grass_block
fill ~164 ~60 ~103 ~168 ~64 ~103 stone
fill ~164 ~65 ~103 ~168 ~67 ~103 dirt
fill ~164 ~68 ~103 ~168 ~68 ~103 grass_block
fill ~169 ~60 ~103 ~175 ~65 ~103 stone
fill ~169 ~66 ~103 ~175 ~68 ~103 dirt
fill ~169 ~69 ~103 ~175 ~69 ~103 grass_block
fill ~160 ~60 ~104 ~164 ~63 ~104 stone
fill ~160 ~64 ~104 ~164 ~66 ~104 dirt
fill ~160 ~67 ~104 ~164 ~67 ~104 grass_block
fill ~165 ~60 ~104 ~169 ~64 ~104 stone
fill ~165 ~65 ~104 ~169 ~67 ~104 dirt
fill ~165 ~68 ~104 ~169 ~68 ~104 grass_block
fill ~170 ~60 ~104 ~175 ~65 ~104 stone
fill ~170 ~66 ~104 ~175 ~68 ~104 dirt
fill ~170 ~69 ~104 ~175 ~69 ~104 grass_block
fill ~160 ~60 ~105 ~161 ~62 ~105 stone
fill ~160 ~63 ~105 ~161 ~65 ~105 dirt
fill ~160 ~66 ~105 ~161 ~66 ~105 grass_block
fill ~162 ~60 ~105 ~164 ~63 ~105 stone
fill ~162 ~64 ~105 ~164 ~66 ~105 dirt
fill ~162 ~67 ~105 ~164 ~67 ~105 grass_block
fill ~165 ~60 ~105 ~171 ~64 ~105 stone
fill ~165 ~65 ~105 ~171 ~67 ~105 dirt
fill ~165 ~68 ~105 ~171 ~68 ~105 grass_block
fill ~172 ~60 ~105 ~175 ~65 ~105 stone
fill ~172 ~66 ~105 ~175 ~68 ~105 dirt
fill ~172 ~69 ~105 ~175 ~69 ~105 grass_block
fill ~160 ~60 ~106 ~161 ~62 ~106 stone
fill ~160 ~63 ~106 ~161 ~65 ~106 dirt
fill ~160 ~66 ~106 ~161 ~66 ~106 grass_block
fill ~162 ~60 ~106 ~166 ~63 ~106 stone
fill ~162 ~64 ~106 ~166 ~66 ~106 dirt
fill ~162 ~67 ~106 ~166 ~67 ~106 grass_block
fill ~167 ~60 ~106 ~172 ~64 ~106 stone
fill ~167 ~65 ~106 ~172 ~67 ~106 dirt
fill ~167 ~68 ~106 ~172 ~68 ~106 grass_block
fill ~173 ~60 ~106 ~175 ~65 ~106 stone
fill ~173 ~66 ~106 ~175 ~68 ~106 dirt
fill ~173 ~69 ~106 ~175 ~69 ~106 grass_block
fill ~160 ~60 ~107 ~162 ~62 ~107 stone
fill ~160 ~63 ~107 ~162 ~65 ~107 dirt
fill ~160 ~66 ~107 ~162 ~66 ~107 grass_block
fill ~163 ~60 ~107 ~167 ~63 ~107 stone
fill ~163 ~64 ~107 ~167 ~66 ~107 dirt
fill ~163 ~67 ~107 ~167 ~67 ~107 grass_block
fill ~168 ~60 ~107 ~174 ~64 ~107 stone
fill ~168 ~65 ~107 ~174 ~67 ~107 dirt
fill ~168 ~68 ~107 ~174 ~68 ~107 grass_block
fill ~175 ~60 ~107 ~175 ~65 ~107 stone
fill ~175 ~66 ~107 ~175 ~68 ~107 dirt
fill ~175 ~69 ~107 ~175 ~69 ~107 grass_block
fill ~160 ~60 ~108 ~162 ~62 ~108 stone
fill ~160 ~63 ~108 ~162 ~65 ~108 dirt
fill ~160 ~66 ~108 ~162 ~66 ~108 grass_block
fill ~163 ~60 ~108 ~168 ~63 ~108 stone
fill ~163 ~64 ~108 ~168 ~66 ~108 dirt
fill ~163 ~67 ~108 ~168 ~67 ~108 grass_block
fill ~169 ~60 ~108 ~175 ~64 ~108 stone
fill ~169 ~65 ~108 ~175 ~67 ~108 dirt
fill ~169 ~68 ~108 ~175 ~68 ~108 grass_block
fill ~160 ~60 ~109 ~164 ~62 ~109 stone
fill ~160 ~63 ~109 ~164 ~65 ~109 dirt
fill ~160 ~66 ~109 ~164 ~66 ~109 grass_block
fill ~165 ~60 ~109 ~171 ~63 ~109 stone
fill ~165 ~64 ~109 ~171 ~66 ~109 dirt
fill ~165 ~67 ~109 ~171 ~67 ~109 grass_block
fill ~172 ~60 ~109 ~175 ~64 ~109 stone
fill ~172 ~65 ~109 ~175 ~67 ~109 dirt
fill ~172 ~68 ~109 ~175 ~68 ~109 grass_block
fill ~160 ~60 ~110 ~165 ~62 ~110 stone
fill ~160 ~63 ~110 ~165 ~65 ~110 dirt
fill ~160 ~66 ~110 ~165 ~66 ~110 grass_block
fill ~166 ~60 ~110 ~173 ~63 ~110 stone
fill ~166 ~64 ~110 ~173 ~66 ~110 dirt
fill ~166 ~67 ~110 ~173 ~67 ~110 grass_block
fill ~174 ~60 ~110 ~175 ~64 ~110 stone
fill ~174 ~65 ~110 ~175 ~67 ~110 dirt
fill ~174 ~68 ~110 ~175 ~68 ~110 grass_block
fill ~160 ~60 ~111 ~167 ~62 ~111 stone
fill ~160 ~63 ~111 ~167 ~65 ~111 dirt
fill ~160 ~66 ~111 ~167 ~66 ~111 grass_block
fill ~168 ~60 ~111 ~175 ~63 ~111 stone
fill ~168 ~64 ~111 ~175 ~66 ~111 dirt
fill ~168 ~67 ~111 ~175 ~67 ~111 grass_block