fill ~16 ~60 ~96 ~18 ~65 ~96 stone
fill ~16 ~66 ~96 ~18 ~68 ~96 dirt
fill ~16 ~69 ~96 ~18 ~69 ~96 grass_block
fill ~19 ~60 ~96 ~21 ~64 ~96 stone
fill ~19 ~65 ~96 ~21 ~67 ~96 dirt
fill ~19 ~68 ~96 ~21 ~68 ~96 grass_block
fill ~22 ~60 ~96 ~31 ~63 ~96 stone
fill ~22 ~64 ~96 ~31 ~66 ~96 dirt
fill ~22 ~67 ~96 ~31 ~67 ~96 grass_block
fill ~16 ~60 ~97 ~19 ~65 ~97 stone
fill ~16 ~66 ~97 ~19 ~68 ~97 dirt
fill ~16 ~69 ~97 ~19 ~69 ~97 grass_block
fill ~20 ~60 ~97 ~21 ~64 ~97 stone
fill ~20 ~65 ~97 ~21 ~67 ~97 dirt
fill ~20 ~68 ~97 ~21 ~68 ~97 grass_block
fill ~22 ~60 ~97 ~31 ~63 ~97 stone
fill ~22 ~64 ~97 ~31 ~66 ~97 dirt
fill ~22 ~67 ~97 ~31 ~67 ~97 grass_block
fill ~16 ~60 ~98 ~19 ~65 ~98 stone
fill ~16 ~66 ~98 ~19 ~68 ~98 dirt
fill ~16 ~69 ~98 ~19 ~69 ~98 grass_block
fill ~20 ~60 ~98 ~24 ~64 ~98 stone
fill ~20 ~65 ~98 ~24 ~67 ~98 dirt
fill ~20 ~68 ~98 ~24 ~68 ~98 grass_block
fill ~25 ~60 ~98 ~31 ~63 ~98 stone
fill ~25 ~64 ~98 ~31 ~66 ~98 dirt
fill ~25 ~67 ~98 ~31 ~67 ~98 grass_block
fill ~16 ~60 ~99 ~21 ~65 ~99 stone
fill ~16 ~66 ~99 ~21 ~68 ~99 dirt
fill ~16 ~69 ~99 ~21 ~69 ~99 grass_block
fill ~22 ~60 ~99 ~29 ~64 ~99 stone
fill ~22 ~65 ~99 ~29 ~67 ~99 dirt
fill ~22 ~68 ~99 ~29 ~68 ~99 grass_block
fill ~30 ~60 ~99 ~31 ~63 ~99 stone
fill ~30 ~64 ~99 ~31 ~66 ~99 dirt
fill ~30 ~67 ~99 ~31 ~67 ~99 grass_block
fill ~16 ~60 ~100 ~22 ~64 ~100 stone
fill ~16 ~65 ~100 ~22 ~67 ~100 dirt
fill ~16 ~68 ~100 ~22 ~68 ~100 grass_block
fill ~23 ~60 ~100 ~23 ~65 ~100 stone
fill ~23 ~66 ~100 ~23 ~68 ~100 dirt
fill ~23 ~69 ~100 ~23 ~69 ~100 grass_block
fill ~24 ~60 ~100 ~30 ~64 ~100 stone
fill ~24 ~65 ~100 ~30 ~67 ~100 dirt
fill ~24 ~68 ~100 ~30 ~68 ~100 grass_block
fill ~31 ~60 ~100 ~31 ~63 ~100 stone
fill ~31 ~64 ~100 ~31 ~66 ~100 dirt
fill ~31 ~67 ~100 ~31 ~67 ~100 grass_block
fill ~16 ~60 ~101 ~31 ~64 ~101 stone
fill ~16 ~65 ~101 ~31 ~67 ~101 dirt
fill ~16 ~68 ~101 ~31 ~68 ~101 grass_block
fill ~16 ~60 ~102 ~20 ~65 ~102 stone
fill ~16 ~66 ~102 ~20 ~68 ~102 dirt
fill ~16 ~69 ~102 ~20 ~69 ~102 grass_block
fill ~21 ~60 ~102 ~31 ~64 ~102 stone
fill ~21 ~65 ~102 ~31 ~67 ~102 dirt
fill ~21 ~68 ~102 ~31 ~68 ~102 grass_block
fill ~16 ~60 ~103 ~16 ~65 ~103 stone
fill ~16 ~66 ~103 ~16 ~68 ~103 dirt
fill ~16 ~69 ~103 ~16 ~69 ~103 grass_block
fill ~17 ~60 ~103 ~19 ~66 ~103 stone
fill ~17 ~67 ~103 ~19 ~69 ~103 dirt
fill ~17 ~70 ~103 ~19 ~70 ~103 grass_block
fill ~20 ~60 ~103 ~22 ~65 ~103 stone
fill ~20 ~66 ~103 ~22 ~68 ~103 dirt
fill ~20 ~69 ~103 ~22 ~69 ~103 grass_block
fill ~23 ~60 ~103 ~31 ~64 ~103 stone
fill ~23 ~65 ~103 ~31 ~67 ~103 dirt
fill ~23 ~68 ~103 ~31 ~68 ~103 grass_block
fill ~16 ~60 ~104 ~17 ~66 ~104 stone
fill ~16 ~67 ~104 ~17 ~69 ~104 dirt
fill ~16 ~70 ~104 ~17 ~70 ~104 grass_block
fill ~18 ~60 ~104 ~19 ~67 ~104 stone
fill ~18 ~68 ~104 ~19 ~70 ~104 dirt
fill ~18 ~71 ~104 ~19 ~71 ~104 grass_block
fill ~20 ~60 ~104 ~21 ~66 ~104 stone
fill ~20 ~67 ~104 ~21 ~69 ~104 dirt
fill ~20 ~70 ~104 ~21 ~70 ~104 grass_block
fill ~22 ~60 ~104 ~25 ~65 ~104 stone
fill ~22 ~66 ~104 ~25 ~68 ~104 dirt
fill ~22 ~69 ~104 ~25 ~69 ~104 grass_block
fill ~26 ~60 ~104 ~31 ~64 ~104 stone
fill ~26 ~65 ~104 ~31 ~67 ~104 dirt
fill ~26 ~68 ~104 ~31 ~68 ~104 grass_block
fill ~16 ~60 ~105 ~16 ~66 ~105 stone
fill ~16 ~67 ~105 ~16 ~69 ~105 dirt
fill ~16 ~70 ~105 ~16 ~70 ~105 grass_block
fill ~17 ~60 ~105 ~18 ~67 ~105 stone
fill ~17 ~68 ~105 ~18 ~70 ~105 dirt
fill ~17 ~71 ~105 ~18 ~71 ~105 grass_block
fill ~19 ~60 ~105 ~19 ~68 ~105 stone
fill ~19 ~69 ~105 ~19 ~71 ~105 dirt
fill ~19 ~72 ~105 ~19 ~72 ~105 grass_block
fill ~20 ~60 ~105 ~21 ~67 ~105 stone
fill ~20 ~68 ~105 ~21 ~70 ~105 dirt
fill ~20 ~71 ~105 ~21 ~71 ~105 grass_block
fill ~22 ~60 ~105 ~24 ~66 ~105 stone
fill ~22 ~67 ~105 ~24 ~69 ~105 dirt
fill ~22 ~70 ~105 ~24 ~70 ~105 grass_block
fill ~25 ~60 ~105 ~26 ~65 ~105 stone
fill ~25 ~66 ~105 ~26 ~68 ~105 dirt
fill ~25 ~69 ~105 ~26 ~69 ~105 grass_block
fill ~27 ~60 ~105 ~31 ~64 ~105 stone
fill ~27 ~65 ~105 ~31 ~67 ~105 dirt
fill ~27 ~68 ~105 ~31 ~68 ~105 grass_block
fill ~16 ~60 ~106 ~16 ~67 ~106 stone
fill ~16 ~68 ~106 ~16 ~70 ~106 dirt
fill ~16 ~71 ~106 ~16 ~71 ~106 grass_block
fill ~17 ~60 ~106 ~20 ~68 ~106 stone
fill ~17 ~69 ~106 ~20 ~71 ~106 dirt
fill ~17 ~72 ~106 ~20 ~72 ~106 grass_block
fill ~21 ~60 ~106 ~22 ~67 ~106 stone
fill ~21 ~68 ~106 ~22 ~70 ~106 dirt
fill ~21 ~71 ~106 ~22 ~71 ~106 grass_block
fill ~23 ~60 ~106 ~24 ~66 ~106 stone
fill ~23 ~67 ~106 ~24 ~69 ~106 dirt
fill ~23 ~70 ~106 ~24 ~70 ~106 grass_block
fill ~25 ~60 ~106 ~26 ~65 ~106 stone
fill ~25 ~66 ~106 ~26 ~68 ~106 dirt
fill ~25 ~69 ~106 ~26 ~69 ~106 grass_block
fill ~27 ~60 ~106 ~28 ~64 ~106 stone
fill ~27 ~65 ~106 ~28 ~67 ~106 dirt
fill ~27 ~68 ~106 ~28 ~68 ~106 grass_block
fill ~29 ~60 ~106 ~31 ~65 ~106 stone
fill ~29 ~66 ~106 ~31 ~68 ~106 dirt
fill ~29 ~69 ~106 ~31 ~69 ~106 grass_block
fill ~16 ~60 ~107 ~21 ~68 ~107 stone
fill ~16 ~69 ~107 ~21 ~71 ~107 dirt
fill ~16 ~72 ~107 ~21 ~72 ~107 grass_block
fill ~22 ~60 ~107 ~22 ~67 ~107 stone
fill ~22 ~68 ~107 ~22 ~70 ~107 dirt
fill ~22 ~71 ~107 ~22 ~71 ~107 grass_block
fill ~23 ~60 ~107 ~24 ~66 ~107 stone
fill ~23 ~67 ~107 ~24 ~69 ~107 dirt
fill ~23 ~70 ~107 ~24 ~70 ~107 grass_block
fill ~25 ~60 ~107 ~31 ~65 ~107 stone
fill ~25 ~66 ~107 ~31 ~68 ~107 dirt
fill ~25 ~69 ~107 ~31 ~69 ~107 grass_block
fill ~16 ~60 ~108 ~21 ~68 ~108 stone
fill ~16 ~69 ~108 ~21 ~71 ~108 dirt
fill ~16 ~72 ~108 ~21 ~72 ~108 grass_block
fill ~22 ~60 ~108 ~22 ~67 ~108 stone
fill ~22 ~68 ~108 ~22 ~70 ~108 dirt
fill ~22 ~71 ~108 ~22 ~71 ~108 grass_block
fill ~23 ~60 ~108 ~25 ~66 ~108 stone
fill ~23 ~67 ~108 ~25 ~69 ~108 dirt
fill ~23 ~70 ~108 ~25 ~70 ~108 grass_block
fill ~26 ~60 ~108 ~27 ~65 ~108 stone
fill ~26 ~66 ~108 ~27 ~68 ~108 dirt
fill ~26 ~69 ~108 ~27 ~69 ~108 grass_block
fill ~28 ~60 ~108 ~29 ~66 ~108 stone
fill ~28 ~67 ~108 ~29 ~69 ~108 dirt
fill ~28 ~70 ~108 ~29 ~70 ~108 grass_block
fill ~30 ~60 ~108 ~30 ~67 ~108 stone
fill ~30 ~68 ~108 ~30 ~70 ~108 dirt
fill ~30 ~71 ~108 ~30 ~71 ~108 grass_block
fill ~31 ~60 ~108 ~31 ~66 ~108 stone
fill ~31 ~67 ~108 ~31 ~69 ~108 dirt
fill ~31 ~70 ~108 ~31 ~70 ~108 grass_block
fill ~16 ~60 ~109 ~21 ~68 ~109 stone
fill ~16 ~69 ~109 ~21 ~71 ~109 dirt
fill ~16 ~72 ~109 ~21 ~72 ~109 grass_block
fill ~22 ~60 ~109 ~23 ~67 ~109 stone
fill ~22 ~68 ~109 ~23 ~70 ~109 dirt
fill ~22 ~71 ~109 ~23 ~71 ~109 grass_block
fill ~24 ~60 ~109 ~28 ~66 ~109 stone
fill ~24 ~67 ~109 ~28 ~69 ~109 dirt
fill ~24 ~70 ~109 ~28 ~70 ~109 grass_block
fill ~29 ~60 ~109 ~31 ~67 ~109 stone
fill ~29 ~68 ~109 ~31 ~70 ~109 dirt
fill ~29 ~71 ~109 ~31 ~71 ~109 grass_block
fill ~16 ~60 ~110 ~22 ~68 ~110 stone
fill ~16 ~69 ~110 ~22 ~71 ~110 dirt
fill ~16 ~72 ~110 ~22 ~72 ~110 grass_block
fill ~23 ~60 ~110 ~30 ~67 ~110 stone
fill ~23 ~68 ~110 ~30 ~70 ~110 dirt
fill ~23 ~71 ~110 ~30 ~71 ~110 grass_block
fill ~31 ~60 ~110 ~31 ~68 ~110 stone
fill ~31 ~69 ~110 ~31 ~71 ~110 dirt
fill ~31 ~72 ~110 ~31 ~72 ~110 grass_block
fill ~16 ~60 ~111 ~16 ~67 ~111 stone
fill ~16 ~68 ~111 ~16 ~70 ~111 dirt
fill ~16 ~71 ~111 ~16 ~71 ~111 grass_block
fill ~17 ~60 ~111 ~27 ~68 ~111 stone
fill ~17 ~69 ~111 ~27 ~71 ~111 dirt
fill ~17 ~72 ~111 ~27 ~72 ~111 grass_block
fill ~28 ~60 ~111 ~29 ~67 ~111 stone
fill ~28 ~68 ~111 ~29 ~70 ~111 dirt
fill ~28 ~71 ~111 ~29 ~71 ~111 grass_block
fill ~30 ~60 ~111 ~31 ~68 ~111 stone
fill ~30 ~69 ~111 ~31 ~71 ~111 dirt
fill ~30 ~72 ~111 ~31 ~72 ~111 grass_block