fill ~192 ~60 ~0 ~194 ~63 ~0 stone
fill ~192 ~64 ~0 ~194 ~66 ~0 dirt
fill ~192 ~67 ~0 ~194 ~67 ~0 grass_block
fill ~195 ~60 ~0 ~200 ~62 ~0 stone
fill ~195 ~63 ~0 ~200 ~65 ~0 dirt
fill ~195 ~66 ~0 ~200 ~66 ~0 grass_block
fill ~201 ~60 ~0 ~202 ~61 ~0 stone
fill ~201 ~62 ~0 ~202 ~64 ~0 dirt
fill ~201 ~65 ~0 ~202 ~65 ~0 grass_block
fill ~203 ~60 ~0 ~207 ~62 ~0 stone
fill ~203 ~63 ~0 ~207 ~65 ~0 dirt
fill ~203 ~66 ~0 ~207 ~66 ~0 grass_block
fill ~192 ~60 ~1 ~193 ~63 ~1 stone
fill ~192 ~64 ~1 ~193 ~66 ~1 dirt
fill ~192 ~67 ~1 ~193 ~67 ~1 grass_block
fill ~194 ~60 ~1 ~199 ~62 ~1 stone
fill ~194 ~63 ~1 ~199 ~65 ~1 dirt
fill ~194 ~66 ~1 ~199 ~66 ~1 grass_block
fill ~200 ~60 ~1 ~201 ~61 ~1 stone
fill ~200 ~62 ~1 ~201 ~64 ~1 dirt
fill ~200 ~65 ~1 ~201 ~65 ~1 grass_block
fill ~202 ~60 ~1 ~206 ~62 ~1 stone
fill ~202 ~63 ~1 ~206 ~65 ~1 dirt
fill ~202 ~66 ~1 ~206 ~66 ~1 grass_block
fill ~207 ~60 ~1 ~207 ~63 ~1 stone
fill ~207 ~64 ~1 ~207 ~66 ~1 dirt
fill ~207 ~67 ~1 ~207 ~67 ~1 grass_block
fill ~192 ~60 ~2 ~193 ~63 ~2 stone
fill ~192 ~64 ~2 ~193 ~66 ~2 dirt
fill ~192 ~67 ~2 ~193 ~67 ~2 grass_block
fill ~194 ~60 ~2 ~199 ~62 ~2 stone
fill ~194 ~63 ~2 ~199 ~65 ~2 dirt
fill ~194 ~66 ~2 ~199 ~66 ~2 grass_block
fill ~200 ~60 ~2 ~201 ~61 ~2 stone
fill ~200 ~62 ~2 ~201 ~64 ~2 dirt
fill ~200 ~65 ~2 ~201 ~65 ~2 grass_block
fill ~202 ~60 ~2 ~205 ~62 ~2 stone
fill ~202 ~63 ~2 ~205 ~65 ~2 dirt
fill ~202 ~66 ~2 ~205 ~66 ~2 grass_block
fill ~206 ~60 ~2 ~206 ~63 ~2 stone
fill ~206 ~64 ~2 ~206 ~66 ~2 dirt
fill ~206 ~67 ~2 ~206 ~67 ~2 grass_block
fill ~207 ~60 ~2 ~207 ~64 ~2 stone
fill ~207 ~65 ~2 ~207 ~67 ~2 dirt
fill ~207 ~68 ~2 ~207 ~68 ~2 grass_block
fill ~192 ~60 ~3 ~194 ~63 ~3 stone
fill ~192 ~64 ~3 ~194 ~66 ~3 dirt
fill ~192 ~67 ~3 ~194 ~67 ~3 grass_block
fill ~195 ~60 ~3 ~198 ~62 ~3 stone
fill ~195 ~63 ~3 ~198 ~65 ~3 dirt
fill ~195 ~66 ~3 ~198 ~66 ~3 grass_block
fill ~199 ~60 ~3 ~200 ~61 ~3 stone
fill ~199 ~62 ~3 ~200 ~64 ~3 dirt
fill ~199 ~65 ~3 ~200 ~65 ~3 grass_block
fill ~201 ~60 ~3 ~203 ~62 ~3 stone
fill ~201 ~63 ~3 ~203 ~65 ~3 dirt
fill ~201 ~66 ~3 ~203 ~66 ~3 grass_block
fill ~204 ~60 ~3 ~206 ~63 ~3 stone
fill ~204 ~64 ~3 ~206 ~66 ~3 dirt
fill ~204 ~67 ~3 ~206 ~67 ~3 grass_block
fill ~207 ~60 ~3 ~207 ~64 ~3 stone
fill ~207 ~65 ~3 ~207 ~67 ~3 dirt
fill ~207 ~68 ~3 ~207 ~68 ~3 grass_block
fill ~192 ~60 ~4 ~194 ~63 ~4 stone
fill ~192 ~64 ~4 ~194 ~66 ~4 dirt
fill ~192 ~67 ~4 ~194 ~67 ~4 grass_block
fill ~195 ~60 ~4 ~198 ~62 ~4 stone
fill ~195 ~63 ~4 ~198 ~65 ~4 dirt
fill ~195 ~66 ~4 ~198 ~66 ~4 grass_block
fill ~199 ~60 ~4 ~200 ~61 ~4 stone
fill ~199 ~62 ~4 ~200 ~64 ~4 dirt
fill ~199 ~65 ~4 ~200 ~65 ~4 grass_block
fill ~201 ~60 ~4 ~203 ~62 ~4 stone
fill ~201 ~63 ~4 ~203 ~65 ~4 dirt
fill ~201 ~66 ~4 ~203 ~66 ~4 grass_block
fill ~204 ~60 ~4 ~204 ~63 ~4 stone
fill ~204 ~64 ~4 ~204 ~66 ~4 dirt
fill ~204 ~67 ~4 ~204 ~67 ~4 grass_block
fill ~205 ~60 ~4 ~207 ~64 ~4 stone
fill ~205 ~65 ~4 ~207 ~67 ~4 dirt
fill ~205 ~68 ~4 ~207 ~68 ~4 grass_block
fill ~192 ~60 ~5 ~194 ~63 ~5 stone
fill ~192 ~64 ~5 ~194 ~66 ~5 dirt
fill ~192 ~67 ~5 ~194 ~67 ~5 grass_block
fill ~195 ~60 ~5 ~198 ~62 ~5 stone
fill ~195 ~63 ~5 ~198 ~65 ~5 dirt
fill ~195 ~66 ~5 ~198 ~66 ~5 grass_block
fill ~199 ~60 ~5 ~200 ~61 ~5 stone
fill ~199 ~62 ~5 ~200 ~64 ~5 dirt
fill ~199 ~65 ~5 ~200 ~65 ~5 grass_block
fill ~201 ~60 ~5 ~203 ~62 ~5 stone
fill ~201 ~63 ~5 ~203 ~65 ~5 dirt
fill ~201 ~66 ~5 ~203 ~66 ~5 grass_block
fill ~204 ~60 ~5 ~204 ~63 ~5 stone
fill ~204 ~64 ~5 ~204 ~66 ~5 dirt
fill ~204 ~67 ~5 ~204 ~67 ~5 grass_block
fill ~205 ~60 ~5 ~207 ~64 ~5 stone
fill ~205 ~65 ~5 ~207 ~67 ~5 dirt
fill ~205 ~68 ~5 ~207 ~68 ~5 grass_block
fill ~192 ~60 ~6 ~194 ~63 ~6 stone
fill ~192 ~64 ~6 ~194 ~66 ~6 dirt
fill ~192 ~67 ~6 ~194 ~67 ~6 grass_block
fill ~195 ~60 ~6 ~198 ~62 ~6 stone
fill ~195 ~63 ~6 ~198 ~65 ~6 dirt
fill ~195 ~66 ~6 ~198 ~66 ~6 grass_block
fill ~199 ~60 ~6 ~201 ~61 ~6 stone
fill ~199 ~62 ~6 ~201 ~64 ~6 dirt
fill ~199 ~65 ~6 ~201 ~65 ~6 grass_block
fill ~202 ~60 ~6 ~203 ~62 ~6 stone
fill ~202 ~63 ~6 ~203 ~65 ~6 dirt
fill ~202 ~66 ~6 ~203 ~66 ~6 grass_block
fill ~204 ~60 ~6 ~204 ~63 ~6 stone
fill ~204 ~64 ~6 ~204 ~66 ~6 dirt
fill ~204 ~67 ~6 ~204 ~67 ~6 grass_block
fill ~205 ~60 ~6 ~207 ~64 ~6 stone
fill ~205 ~65 ~6 ~207 ~67 ~6 dirt
fill ~205 ~68 ~6 ~207 ~68 ~6 grass_block
fill ~192 ~60 ~7 ~194 ~63 ~7 stone
fill ~192 ~64 ~7 ~194 ~66 ~7 dirt
fill ~192 ~67 ~7 ~194 ~67 ~7 grass_block
fill ~195 ~60 ~7 ~198 ~62 ~7 stone
fill ~195 ~63 ~7 ~198 ~65 ~7 dirt
fill ~195 ~66 ~7 ~198 ~66 ~7 grass_block
fill ~199 ~60 ~7 ~201 ~61 ~7 stone
fill ~199 ~62 ~7 ~201 ~64 ~7 dirt
fill ~199 ~65 ~7 ~201 ~65 ~7 grass_block
fill ~202 ~60 ~7 ~203 ~62 ~7 stone
fill ~202 ~63 ~7 ~203 ~65 ~7 dirt
fill ~202 ~66 ~7 ~203 ~66 ~7 grass_block
fill ~204 ~60 ~7 ~205 ~63 ~7 stone
fill ~204 ~64 ~7 ~205 ~66 ~7 dirt
fill ~204 ~67 ~7 ~205 ~67 ~7 grass_block
fill ~206 ~60 ~7 ~207 ~64 ~7 stone
fill ~206 ~65 ~7 ~207 ~67 ~7 dirt
fill ~206 ~68 ~7 ~207 ~68 ~7 grass_block
fill ~192 ~60 ~8 ~199 ~62 ~8 stone
fill ~192 ~63 ~8 ~199 ~65 ~8 dirt
fill ~192 ~66 ~8 ~199 ~66 ~8 grass_block
fill ~200 ~60 ~8 ~201 ~61 ~8 stone
fill ~200 ~62 ~8 ~201 ~64 ~8 dirt
fill ~200 ~65 ~8 ~201 ~65 ~8 grass_block
fill ~202 ~60 ~8 ~204 ~62 ~8 stone
fill ~202 ~63 ~8 ~204 ~65 ~8 dirt
fill ~202 ~66 ~8 ~204 ~66 ~8 grass_block
fill ~205 ~60 ~8 ~205 ~63 ~8 stone
fill ~205 ~64 ~8 ~205 ~66 ~8 dirt
fill ~205 ~67 ~8 ~205 ~67 ~8 grass_block
fill ~206 ~60 ~8 ~207 ~64 ~8 stone
fill ~206 ~65 ~8 ~207 ~67 ~8 dirt
fill ~206 ~68 ~8 ~207 ~68 ~8 grass_block
fill ~192 ~60 ~9 ~198 ~62 ~9 stone
fill ~192 ~63 ~9 ~198 ~65 ~9 dirt
fill ~192 ~66 ~9 ~198 ~66 ~9 grass_block
fill ~199 ~60 ~9 ~202 ~61 ~9 stone
fill ~199 ~62 ~9 ~202 ~64 ~9 dirt
fill ~199 ~65 ~9 ~202 ~65 ~9 grass_block
fill ~203 ~60 ~9 ~204 ~62 ~9 stone
fill ~203 ~63 ~9 ~204 ~65 ~9 dirt
fill ~203 ~66 ~9 ~204 ~66 ~9 grass_block
fill ~205 ~60 ~9 ~207 ~63 ~9 stone
fill ~205 ~64 ~9 ~207 ~66 ~9 dirt
fill ~205 ~67 ~9 ~207 ~67 ~9 grass_block
fill ~192 ~60 ~10 ~202 ~61 ~10 stone
fill ~192 ~62 ~10 ~202 ~64 ~10 dirt
fill ~192 ~65 ~10 ~202 ~65 ~10 grass_block
fill ~203 ~60 ~10 ~205 ~62 ~10 stone
fill ~203 ~63 ~10 ~205 ~65 ~10 dirt
fill ~203 ~66 ~10 ~205 ~66 ~10 grass_block
fill ~206 ~60 ~10 ~207 ~63 ~10 stone
fill ~206 ~64 ~10 ~207 ~66 ~10 dirt
fill ~206 ~67 ~10 ~207 ~67 ~10 grass_block
fill ~192 ~60 ~11 ~202 ~61 ~11 stone
fill ~192 ~62 ~11 ~202 ~64 ~11 dirt
fill ~192 ~65 ~11 ~202 ~65 ~11 grass_block
fill ~203 ~60 ~11 ~205 ~62 ~11 stone
fill ~203 ~63 ~11 ~205 ~65 ~11 dirt
fill ~203 ~66 ~11 ~205 ~66 ~11 grass_block
fill ~206 ~60 ~11 ~207 ~63 ~11 stone
fill ~206 ~64 ~11 ~207 ~66 ~11 dirt
fill ~206 ~67 ~11 ~207 ~67 ~11 grass_block
fill ~192 ~60 ~12 ~203 ~61 ~12 stone
fill ~192 ~62 ~12 ~203 ~64 ~12 dirt
fill ~192 ~65 ~12 ~203 ~65 ~12 grass_block
fill ~204 ~60 ~12 ~207 ~62 ~12 stone
fill ~204 ~63 ~12 ~207 ~65 ~12 dirt
fill ~204 ~66 ~12 ~207 ~66 ~12 grass_block
fill ~192 ~60 ~13 ~205 ~61 ~13 stone
fill ~192 ~62 ~13 ~205 ~64 ~13 dirt
fill ~192 ~65 ~13 ~205 ~65 ~13 grass_block
fill ~206 ~60 ~13 ~207 ~62 ~13 stone
fill ~206 ~63 ~13 ~207 ~65 ~13 dirt
fill ~206 ~66 ~13 ~207 ~66 ~13 grass_block
fill ~192 ~60 ~14 ~207 ~61 ~14 stone
fill ~192 ~62 ~14 ~207 ~64 ~14 dirt
fill ~192 ~65 ~14 ~207 ~65 ~14 grass_block
fill ~192 ~60 ~15 ~207 ~61 ~15 stone
fill ~192 ~62 ~15 ~207 ~64 ~15 dirt
fill ~192 ~65 ~15 ~207 ~65 ~15 grass_block