fill ~144 ~60 ~80 ~148 ~65 ~80 stone
fill ~144 ~66 ~80 ~148 ~68 ~80 dirt
fill ~144 ~69 ~80 ~148 ~69 ~80 grass_block
fill ~149 ~60 ~80 ~154 ~66 ~80 stone
fill ~149 ~67 ~80 ~154 ~69 ~80 dirt
fill ~149 ~70 ~80 ~154 ~70 ~80 grass_block
fill ~155 ~60 ~80 ~158 ~65 ~80 stone
fill ~155 ~66 ~80 ~158 ~68 ~80 dirt
fill ~155 ~69 ~80 ~158 ~69 ~80 grass_block
fill ~159 ~60 ~80 ~159 ~64 ~80 stone
fill ~159 ~65 ~80 ~159 ~67 ~80 dirt
fill ~159 ~68 ~80 ~159 ~68 ~80 grass_block
fill ~144 ~60 ~81 ~150 ~65 ~81 stone
fill ~144 ~66 ~81 ~150 ~68 ~81 dirt
fill ~144 ~69 ~81 ~150 ~69 ~81 grass_block
fill ~151 ~60 ~81 ~152 ~66 ~81 stone
fill ~151 ~67 ~81 ~152 ~69 ~81 dirt
fill ~151 ~70 ~81 ~152 ~70 ~81 grass_block
fill ~153 ~60 ~81 ~159 ~65 ~81 stone
fill ~153 ~66 ~81 ~159 ~68 ~81 dirt
fill ~153 ~69 ~81 ~159 ~69 ~81 grass_block
fill ~144 ~60 ~82 ~159 ~65 ~82 stone
fill ~144 ~66 ~82 ~159 ~68 ~82 dirt
fill ~144 ~69 ~82 ~159 ~69 ~82 grass_block
fill ~144 ~60 ~83 ~151 ~65 ~83 stone
fill ~144 ~66 ~83 ~151 ~68 ~83 dirt
fill ~144 ~69 ~83 ~151 ~69 ~83 grass_block
fill ~152 ~60 ~83 ~155 ~64 ~83 stone
fill ~152 ~65 ~83 ~155 ~67 ~83 dirt
fill ~152 ~68 ~83 ~155 ~68 ~83 grass_block
fill ~156 ~60 ~83 ~159 ~65 ~83 stone
fill ~156 ~66 ~83 ~159 ~68 ~83 dirt
fill ~156 ~69 ~83 ~159 ~69 ~83 grass_block
fill ~144 ~60 ~84 ~144 ~64 ~84 stone
fill ~144 ~65 ~84 ~144 ~67 ~84 dirt
fill ~144 ~68 ~84 ~144 ~68 ~84 grass_block
fill ~145 ~60 ~84 ~149 ~65 ~84 stone
fill ~145 ~66 ~84 ~149 ~68 ~84 dirt
fill ~145 ~69 ~84 ~149 ~69 ~84 grass_block
fill ~150 ~60 ~84 ~155 ~64 ~84 stone
fill ~150 ~65 ~84 ~155 ~67 ~84 dirt
fill ~150 ~68 ~84 ~155 ~68 ~84 grass_block
fill ~156 ~60 ~84 ~159 ~65 ~84 stone
fill ~156 ~66 ~84 ~159 ~68 ~84 dirt
fill ~156 ~69 ~84 ~159 ~69 ~84 grass_block
fill ~144 ~60 ~85 ~155 ~64 ~85 stone
fill ~144 ~65 ~85 ~155 ~67 ~85 dirt
fill ~144 ~68 ~85 ~155 ~68 ~85 grass_block
fill ~156 ~60 ~85 ~159 ~65 ~85 stone
fill ~156 ~66 ~85 ~159 ~68 ~85 dirt
fill ~156 ~69 ~85 ~159 ~69 ~85 grass_block
fill ~144 ~60 ~86 ~150 ~64 ~86 stone
fill ~144 ~65 ~86 ~150 ~67 ~86 dirt
fill ~144 ~68 ~86 ~150 ~68 ~86 grass_block
fill ~151 ~60 ~86 ~152 ~63 ~86 stone
fill ~151 ~64 ~86 ~152 ~66 ~86 dirt
fill ~151 ~67 ~86 ~152 ~67 ~86 grass_block
fill ~153 ~60 ~86 ~155 ~64 ~86 stone
fill ~153 ~65 ~86 ~155 ~67 ~86 dirt
fill ~153 ~68 ~86 ~155 ~68 ~86 grass_block
fill ~156 ~60 ~86 ~159 ~65 ~86 stone
fill ~156 ~66 ~86 ~159 ~68 ~86 dirt
fill ~156 ~69 ~86 ~159 ~69 ~86 grass_block
fill ~144 ~60 ~87 ~149 ~64 ~87 stone
fill ~144 ~65 ~87 ~149 ~67 ~87 dirt
fill ~144 ~68 ~87 ~149 ~68 ~87 grass_block
fill ~150 ~60 ~87 ~151 ~63 ~87 stone
fill ~150 ~64 ~87 ~151 ~66 ~87 dirt
fill ~150 ~67 ~87 ~151 ~67 ~87 grass_block
fill ~152 ~60 ~87 ~153 ~64 ~87 stone
fill ~152 ~65 ~87 ~153 ~67 ~87 dirt
fill ~152 ~68 ~87 ~153 ~68 ~87 grass_block
fill ~154 ~60 ~87 ~159 ~65 ~87 stone
fill ~154 ~66 ~87 ~159 ~68 ~87 dirt
fill ~154 ~69 ~87 ~159 ~69 ~87 grass_block
fill ~144 ~60 ~88 ~146 ~64 ~88 stone
fill ~144 ~65 ~88 ~146 ~67 ~88 dirt
fill ~144 ~68 ~88 ~146 ~68 ~88 grass_block
fill ~147 ~60 ~88 ~150 ~63 ~88 stone
fill ~147 ~64 ~88 ~150 ~66 ~88 dirt
fill ~147 ~67 ~88 ~150 ~67 ~88 grass_block
fill ~151 ~60 ~88 ~152 ~64 ~88 stone
fill ~151 ~65 ~88 ~152 ~67 ~88 dirt
fill ~151 ~68 ~88 ~152 ~68 ~88 grass_block
fill ~153 ~60 ~88 ~159 ~65 ~88 stone
fill ~153 ~66 ~88 ~159 ~68 ~88 dirt
fill ~153 ~69 ~88 ~159 ~69 ~88 grass_block
fill ~144 ~60 ~89 ~145 ~64 ~89 stone
fill ~144 ~65 ~89 ~145 ~67 ~89 dirt
fill ~144 ~68 ~89 ~145 ~68 ~89 grass_block
fill ~146 ~60 ~89 ~150 ~63 ~89 stone
fill ~146 ~64 ~89 ~150 ~66 ~89 dirt
fill ~146 ~67 ~89 ~150 ~67 ~89 grass_block
fill ~151 ~60 ~89 ~152 ~64 ~89 stone
fill ~151 ~65 ~89 ~152 ~67 ~89 dirt
fill ~151 ~68 ~89 ~152 ~68 ~89 grass_block
fill ~153 ~60 ~89 ~159 ~65 ~89 stone
fill ~153 ~66 ~89 ~159 ~68 ~89 dirt
fill ~153 ~69 ~89 ~159 ~69 ~89 grass_block
fill ~144 ~60 ~90 ~149 ~63 ~90 stone
fill ~144 ~64 ~90 ~149 ~66 ~90 dirt
fill ~144 ~67 ~90 ~149 ~67 ~90 grass_block
fill ~150 ~60 ~90 ~152 ~64 ~90 stone
fill ~150 ~65 ~90 ~152 ~67 ~90 dirt
fill ~150 ~68 ~90 ~152 ~68 ~90 grass_block
fill ~153 ~60 ~90 ~156 ~65 ~90 stone
fill ~153 ~66 ~90 ~156 ~68 ~90 dirt
fill ~153 ~69 ~90 ~156 ~69 ~90 grass_block
fill ~157 ~60 ~90 ~159 ~66 ~90 stone
fill ~157 ~67 ~90 ~159 ~69 ~90 dirt
fill ~157 ~70 ~90 ~159 ~70 ~90 grass_block
fill ~144 ~60 ~91 ~149 ~63 ~91 stone
fill ~144 ~64 ~91 ~149 ~66 ~91 dirt
fill ~144 ~67 ~91 ~149 ~67 ~91 grass_block
fill ~150 ~60 ~91 ~152 ~64 ~91 stone
fill ~150 ~65 ~91 ~152 ~67 ~91 dirt
fill ~150 ~68 ~91 ~152 ~68 ~91 grass_block
fill ~153 ~60 ~91 ~157 ~65 ~91 stone
fill ~153 ~66 ~91 ~157 ~68 ~91 dirt
fill ~153 ~69 ~91 ~157 ~69 ~91 grass_block
fill ~158 ~60 ~91 ~159 ~66 ~91 stone
fill ~158 ~67 ~91 ~159 ~69 ~91 dirt
fill ~158 ~70 ~91 ~159 ~70 ~91 grass_block
fill ~144 ~60 ~92 ~149 ~63 ~92 stone
fill ~144 ~64 ~92 ~149 ~66 ~92 dirt
fill ~144 ~67 ~92 ~149 ~67 ~92 grass_block
fill ~150 ~60 ~92 ~153 ~64 ~92 stone
fill ~150 ~65 ~92 ~153 ~67 ~92 dirt
fill ~150 ~68 ~92 ~153 ~68 ~92 grass_block
fill ~154 ~60 ~92 ~158 ~65 ~92 stone
fill ~154 ~66 ~92 ~158 ~68 ~92 dirt
fill ~154 ~69 ~92 ~158 ~69 ~92 grass_block
fill ~159 ~60 ~92 ~159 ~66 ~92 stone
fill ~159 ~67 ~92 ~159 ~69 ~92 dirt
fill ~159 ~70 ~92 ~159 ~70 ~92 grass_block
fill ~144 ~60 ~93 ~146 ~63 ~93 stone
fill ~144 ~64 ~93 ~146 ~66 ~93 dirt
fill ~144 ~67 ~93 ~146 ~67 ~93 grass_block
fill ~147 ~60 ~93 ~147 ~62 ~93 stone
fill ~147 ~63 ~93 ~147 ~65 ~93 dirt
fill ~147 ~66 ~93 ~147 ~66 ~93 grass_block
fill ~148 ~60 ~93 ~149 ~63 ~93 stone
fill ~148 ~64 ~93 ~149 ~66 ~93 dirt
fill ~148 ~67 ~93 ~149 ~67 ~93 grass_block
fill ~150 ~60 ~93 ~154 ~64 ~93 stone
fill ~150 ~65 ~93 ~154 ~67 ~93 dirt
fill ~150 ~68 ~93 ~154 ~68 ~93 grass_block
fill ~155 ~60 ~93 ~159 ~65 ~93 stone
fill ~155 ~66 ~93 ~159 ~68 ~93 dirt
fill ~155 ~69 ~93 ~159 ~69 ~93 grass_block
fill ~144 ~60 ~94 ~147 ~62 ~94 stone
fill ~144 ~63 ~94 ~147 ~65 ~94 dirt
fill ~144 ~66 ~94 ~147 ~66 ~94 grass_block
fill ~148 ~60 ~94 ~149 ~63 ~94 stone
fill ~148 ~64 ~94 ~149 ~66 ~94 dirt
fill ~148 ~67 ~94 ~149 ~67 ~94 grass_block
fill ~150 ~60 ~94 ~156 ~64 ~94 stone
fill ~150 ~65 ~94 ~156 ~67 ~94 dirt
fill ~150 ~68 ~94 ~156 ~68 ~94 grass_block
fill ~157 ~60 ~94 ~159 ~65 ~94 stone
fill ~157 ~66 ~94 ~159 ~68 ~94 dirt
fill ~157 ~69 ~94 ~159 ~69 ~94 grass_block
fill ~144 ~60 ~95 ~147 ~62 ~95 stone
fill ~144 ~63 ~95 ~147 ~65 ~95 dirt
fill ~144 ~66 ~95 ~147 ~66 ~95 grass_block
fill ~148 ~60 ~95 ~150 ~63 ~95 stone
fill ~148 ~64 ~95 ~150 ~66 ~95 dirt
fill ~148 ~67 ~95 ~150 ~67 ~95 grass_block
fill ~151 ~60 ~95 ~157 ~64 ~95 stone
fill ~151 ~65 ~95 ~157 ~67 ~95 dirt
fill ~151 ~68 ~95 ~157 ~68 ~95 grass_block
fill ~158 ~60 ~95 ~159 ~65 ~95 stone
fill ~158 ~66 ~95 ~159 ~68 ~95 dirt
fill ~158 ~69 ~95 ~159 ~69 ~95 grass_block