fill ~112 ~60 ~96 ~119 ~62 ~96 stone
fill ~112 ~63 ~96 ~119 ~65 ~96 dirt
fill ~112 ~66 ~96 ~119 ~66 ~96 grass_block
fill ~120 ~60 ~96 ~127 ~63 ~96 stone
fill ~120 ~64 ~96 ~127 ~66 ~96 dirt
fill ~120 ~67 ~96 ~127 ~67 ~96 grass_block
fill ~112 ~60 ~97 ~113 ~63 ~97 stone
fill ~112 ~64 ~97 ~113 ~66 ~97 dirt
fill ~112 ~67 ~97 ~113 ~67 ~97 grass_block
fill ~114 ~60 ~97 ~123 ~62 ~97 stone
fill ~114 ~63 ~97 ~123 ~65 ~97 dirt
fill ~114 ~66 ~97 ~123 ~66 ~97 grass_block
fill ~124 ~60 ~97 ~127 ~63 ~97 stone
fill ~124 ~64 ~97 ~127 ~66 ~97 dirt
fill ~124 ~67 ~97 ~127 ~67 ~97 grass_block
fill ~112 ~60 ~98 ~116 ~63 ~98 stone
fill ~112 ~64 ~98 ~116 ~66 ~98 dirt
fill ~112 ~67 ~98 ~116 ~67 ~98 grass_block
fill ~117 ~60 ~98 ~119 ~62 ~98 stone
fill ~117 ~63 ~98 ~119 ~65 ~98 dirt
fill ~117 ~66 ~98 ~119 ~66 ~98 grass_block
fill ~120 ~60 ~98 ~121 ~63 ~98 stone
fill ~120 ~64 ~98 ~121 ~66 ~98 dirt
fill ~120 ~67 ~98 ~121 ~67 ~98 grass_block
fill ~122 ~60 ~98 ~127 ~62 ~98 stone
fill ~122 ~63 ~98 ~127 ~65 ~98 dirt
fill ~122 ~66 ~98 ~127 ~66 ~98 grass_block
fill ~112 ~60 ~99 ~112 ~63 ~99 stone
fill ~112 ~64 ~99 ~112 ~66 ~99 dirt
fill ~112 ~67 ~99 ~112 ~67 ~99 grass_block
fill ~113 ~60 ~99 ~116 ~64 ~99 stone
fill ~113 ~65 ~99 ~116 ~67 ~99 dirt
fill ~113 ~68 ~99 ~116 ~68 ~99 grass_block
fill ~117 ~60 ~99 ~123 ~63 ~99 stone
fill ~117 ~64 ~99 ~123 ~66 ~99 dirt
fill ~117 ~67 ~99 ~123 ~67 ~99 grass_block
fill ~124 ~60 ~99 ~127 ~62 ~99 stone
fill ~124 ~63 ~99 ~127 ~65 ~99 dirt
fill ~124 ~66 ~99 ~127 ~66 ~99 grass_block
fill ~112 ~60 ~100 ~112 ~63 ~100 stone
fill ~112 ~64 ~100 ~112 ~66 ~100 dirt
fill ~112 ~67 ~100 ~112 ~67 ~100 grass_block
fill ~113 ~60 ~100 ~114 ~64 ~100 stone
fill ~113 ~65 ~100 ~114 ~67 ~100 dirt
fill ~113 ~68 ~100 ~114 ~68 ~100 grass_block
fill ~115 ~60 ~100 ~115 ~65 ~100 stone
fill ~115 ~66 ~100 ~115 ~68 ~100 dirt
fill ~115 ~69 ~100 ~115 ~69 ~100 grass_block
fill ~116 ~60 ~100 ~120 ~64 ~100 stone
fill ~116 ~65 ~100 ~120 ~67 ~100 dirt
fill ~116 ~68 ~100 ~120 ~68 ~100 grass_block
fill ~121 ~60 ~100 ~124 ~63 ~100 stone
fill ~121 ~64 ~100 ~124 ~66 ~100 dirt
fill ~121 ~67 ~100 ~124 ~67 ~100 grass_block
fill ~125 ~60 ~100 ~127 ~62 ~100 stone
fill ~125 ~63 ~100 ~127 ~65 ~100 dirt
fill ~125 ~66 ~100 ~127 ~66 ~100 grass_block
fill ~112 ~60 ~101 ~113 ~64 ~101 stone
fill ~112 ~65 ~101 ~113 ~67 ~101 dirt
fill ~112 ~68 ~101 ~113 ~68 ~101 grass_block
fill ~114 ~60 ~101 ~117 ~65 ~101 stone
fill ~114 ~66 ~101 ~117 ~68 ~101 dirt
fill ~114 ~69 ~101 ~117 ~69 ~101 grass_block
fill ~118 ~60 ~101 ~120 ~64 ~101 stone
fill ~118 ~65 ~101 ~120 ~67 ~101 dirt
fill ~118 ~68 ~101 ~120 ~68 ~101 grass_block
fill ~121 ~60 ~101 ~127 ~63 ~101 stone
fill ~121 ~64 ~101 ~127 ~66 ~101 dirt
fill ~121 ~67 ~101 ~127 ~67 ~101 grass_block
fill ~112 ~60 ~102 ~114 ~65 ~102 stone
fill ~112 ~66 ~102 ~114 ~68 ~102 dirt
fill ~112 ~69 ~102 ~114 ~69 ~102 grass_block
fill ~115 ~60 ~102 ~115 ~66 ~102 stone
fill ~115 ~67 ~102 ~115 ~69 ~102 dirt
fill ~115 ~70 ~102 ~115 ~70 ~102 grass_block
fill ~116 ~60 ~102 ~117 ~65 ~102 stone
fill ~116 ~66 ~102 ~117 ~68 ~102 dirt
fill ~116 ~69 ~102 ~117 ~69 ~102 grass_block
fill ~118 ~60 ~102 ~120 ~64 ~102 stone
fill ~118 ~65 ~102 ~120 ~67 ~102 dirt
fill ~118 ~68 ~102 ~120 ~68 ~102 grass_block
fill ~121 ~60 ~102 ~124 ~63 ~102 stone
fill ~121 ~64 ~102 ~124 ~66 ~102 dirt
fill ~121 ~67 ~102 ~124 ~67 ~102 grass_block
fill ~125 ~60 ~102 ~126 ~64 ~102 stone
fill ~125 ~65 ~102 ~126 ~67 ~102 dirt
fill ~125 ~68 ~102 ~126 ~68 ~102 grass_block
fill ~127 ~60 ~102 ~127 ~63 ~102 stone
fill ~127 ~64 ~102 ~127 ~66 ~102 dirt
fill ~127 ~67 ~102 ~127 ~67 ~102 grass_block
fill ~112 ~60 ~103 ~115 ~66 ~103 stone
fill ~112 ~67 ~103 ~115 ~69 ~103 dirt
fill ~112 ~70 ~103 ~115 ~70 ~103 grass_block
fill ~116 ~60 ~103 ~117 ~65 ~103 stone
fill ~116 ~66 ~103 ~117 ~68 ~103 dirt
fill ~116 ~69 ~103 ~117 ~69 ~103 grass_block
fill ~118 ~60 ~103 ~120 ~64 ~103 stone
fill ~118 ~65 ~103 ~120 ~67 ~103 dirt
fill ~118 ~68 ~103 ~120 ~68 ~103 grass_block
fill ~121 ~60 ~103 ~123 ~63 ~103 stone
fill ~121 ~64 ~103 ~123 ~66 ~103 dirt
fill ~121 ~67 ~103 ~123 ~67 ~103 grass_block
fill ~124 ~60 ~103 ~127 ~64 ~103 stone
fill ~124 ~65 ~103 ~127 ~67 ~103 dirt
fill ~124 ~68 ~103 ~127 ~68 ~103 grass_block
fill ~112 ~60 ~104 ~112 ~66 ~104 stone
fill ~112 ~67 ~104 ~112 ~69 ~104 dirt
fill ~112 ~70 ~104 ~112 ~70 ~104 grass_block
fill ~113 ~60 ~104 ~113 ~67 ~104 stone
fill ~113 ~68 ~104 ~113 ~70 ~104 dirt
fill ~113 ~71 ~104 ~113 ~71 ~104 grass_block
fill ~114 ~60 ~104 ~115 ~66 ~104 stone
fill ~114 ~67 ~104 ~115 ~69 ~104 dirt
fill ~114 ~70 ~104 ~115 ~70 ~104 grass_block
fill ~116 ~60 ~104 ~117 ~65 ~104 stone
fill ~116 ~66 ~104 ~117 ~68 ~104 dirt
fill ~116 ~69 ~104 ~117 ~69 ~104 grass_block
fill ~118 ~60 ~104 ~121 ~64 ~104 stone
fill ~118 ~65 ~104 ~121 ~67 ~104 dirt
fill ~118 ~68 ~104 ~121 ~68 ~104 grass_block
fill ~122 ~60 ~104 ~123 ~63 ~104 stone
fill ~122 ~64 ~104 ~123 ~66 ~104 dirt
fill ~122 ~67 ~104 ~123 ~67 ~104 grass_block
fill ~124 ~60 ~104 ~125 ~64 ~104 stone
fill ~124 ~65 ~104 ~125 ~67 ~104 dirt
fill ~124 ~68 ~104 ~125 ~68 ~104 grass_block
fill ~126 ~60 ~104 ~127 ~65 ~104 stone
fill ~126 ~66 ~104 ~127 ~68 ~104 dirt
fill ~126 ~69 ~104 ~127 ~69 ~104 grass_block
fill ~112 ~60 ~105 ~112 ~66 ~105 stone
fill ~112 ~67 ~105 ~112 ~69 ~105 dirt
fill ~112 ~70 ~105 ~112 ~70 ~105 grass_block
fill ~113 ~60 ~105 ~114 ~67 ~105 stone
fill ~113 ~68 ~105 ~114 ~70 ~105 dirt
fill ~113 ~71 ~105 ~114 ~71 ~105 grass_block
fill ~115 ~60 ~105 ~116 ~66 ~105 stone
fill ~115 ~67 ~105 ~116 ~69 ~105 dirt
fill ~115 ~70 ~105 ~116 ~70 ~105 grass_block
fill ~117 ~60 ~105 ~118 ~65 ~105 stone
fill ~117 ~66 ~105 ~118 ~68 ~105 dirt
fill ~117 ~69 ~105 ~118 ~69 ~105 grass_block
fill ~119 ~60 ~105 ~121 ~64 ~105 stone
fill ~119 ~65 ~105 ~121 ~67 ~105 dirt
fill ~119 ~68 ~105 ~121 ~68 ~105 grass_block
fill ~122 ~60 ~105 ~122 ~63 ~105 stone
fill ~122 ~64 ~105 ~122 ~66 ~105 dirt
fill ~122 ~67 ~105 ~122 ~67 ~105 grass_block
fill ~123 ~60 ~105 ~124 ~64 ~105 stone
fill ~123 ~65 ~105 ~124 ~67 ~105 dirt
fill ~123 ~68 ~105 ~124 ~68 ~105 grass_block
fill ~125 ~60 ~105 ~127 ~65 ~105 stone
fill ~125 ~66 ~105 ~127 ~68 ~105 dirt
fill ~125 ~69 ~105 ~127 ~69 ~105 grass_block
fill ~112 ~60 ~106 ~112 ~66 ~106 stone
fill ~112 ~67 ~106 ~112 ~69 ~106 dirt
fill ~112 ~70 ~106 ~112 ~70 ~106 grass_block
fill ~113 ~60 ~106 ~115 ~67 ~106 stone
fill ~113 ~68 ~106 ~115 ~70 ~106 dirt
fill ~113 ~71 ~106 ~115 ~71 ~106 grass_block
fill ~116 ~60 ~106 ~117 ~66 ~106 stone
fill ~116 ~67 ~106 ~117 ~69 ~106 dirt
fill ~116 ~70 ~106 ~117 ~70 ~106 grass_block
fill ~118 ~60 ~106 ~119 ~65 ~106 stone
fill ~118 ~66 ~106 ~119 ~68 ~106 dirt
fill ~118 ~69 ~106 ~119 ~69 ~106 grass_block
fill ~120 ~60 ~106 ~124 ~64 ~106 stone
fill ~120 ~65 ~106 ~124 ~67 ~106 dirt
fill ~120 ~68 ~106 ~124 ~68 ~106 grass_block
fill ~125 ~60 ~106 ~127 ~65 ~106 stone
fill ~125 ~66 ~106 ~127 ~68 ~106 dirt
fill ~125 ~69 ~106 ~127 ~69 ~106 grass_block
fill ~112 ~60 ~107 ~112 ~66 ~107 stone
fill ~112 ~67 ~107 ~112 ~69 ~107 dirt
fill ~112 ~70 ~107 ~112 ~70 ~107 grass_block
fill ~113 ~60 ~107 ~117 ~67 ~107 stone
fill ~113 ~68 ~107 ~117 ~70 ~107 dirt
fill ~113 ~71 ~107 ~117 ~71 ~107 grass_block
fill ~118 ~60 ~107 ~118 ~66 ~107 stone
fill ~118 ~67 ~107 ~118 ~69 ~107 dirt
fill ~118 ~70 ~107 ~118 ~70 ~107 grass_block
fill ~119 ~60 ~107 ~120 ~65 ~107 stone
fill ~119 ~66 ~107 ~120 ~68 ~107 dirt
fill ~119 ~69 ~107 ~120 ~69 ~107 grass_block
fill ~121 ~60 ~107 ~124 ~64 ~107 stone
fill ~121 ~65 ~107 ~124 ~67 ~107 dirt
fill ~121 ~68 ~107 ~124 ~68 ~107 grass_block
fill ~125 ~60 ~107 ~127 ~65 ~107 stone
fill ~125 ~66 ~107 ~127 ~68 ~107 dirt
fill ~125 ~69 ~107 ~127 ~69 ~107 grass_block
fill ~112 ~60 ~108 ~112 ~66 ~108 stone
fill ~112 ~67 ~108 ~112 ~69 ~108 dirt
fill ~112 ~70 ~108 ~112 ~70 ~108 grass_block
fill ~113 ~60 ~108 ~117 ~67 ~108 stone
fill ~113 ~68 ~108 ~117 ~70 ~108 dirt
fill ~113 ~71 ~108 ~117 ~71 ~108 grass_block
fill ~118 ~60 ~108 ~118 ~66 ~108 stone
fill ~118 ~67 ~108 ~118 ~69 ~108 dirt
fill ~118 ~70 ~108 ~118 ~70 ~108 grass_block
fill ~119 ~60 ~108 ~120 ~65 ~108 stone
fill ~119 ~66 ~108 ~120 ~68 ~108 dirt
fill ~119 ~69 ~108 ~120 ~69 ~108 grass_block
fill ~121 ~60 ~108 ~122 ~64 ~108 stone
fill ~121 ~65 ~108 ~122 ~67 ~108 dirt
fill ~121 ~68 ~108 ~122 ~68 ~108 grass_block
fill ~123 ~60 ~108 ~127 ~65 ~108 stone
fill ~123 ~66 ~108 ~127 ~68 ~108 dirt
fill ~123 ~69 ~108 ~127 ~69 ~108 grass_block
fill ~112 ~60 ~109 ~117 ~67 ~109 stone
fill ~112 ~68 ~109 ~117 ~70 ~109 dirt
fill ~112 ~71 ~109 ~117 ~71 ~109 grass_block
fill ~118 ~60 ~109 ~119 ~66 ~109 stone
fill ~118 ~67 ~109 ~119 ~69 ~109 dirt
fill ~118 ~70 ~109 ~119 ~70 ~109 grass_block
fill ~120 ~60 ~109 ~126 ~65 ~109 stone
fill ~120 ~66 ~109 ~126 ~68 ~109 dirt
fill ~120 ~69 ~109 ~126 ~69 ~109 grass_block
fill ~127 ~60 ~109 ~127 ~64 ~109 stone
fill ~127 ~65 ~109 ~127 ~67 ~109 dirt
fill ~127 ~68 ~109 ~127 ~68 ~109 grass_block
fill ~112 ~60 ~110 ~112 ~68 ~110 stone
fill ~112 ~69 ~110 ~112 ~71 ~110 dirt
fill ~112 ~72 ~110 ~112 ~72 ~110 grass_block
fill ~113 ~60 ~110 ~113 ~67 ~110 stone
fill ~113 ~68 ~110 ~113 ~70 ~110 dirt
fill ~113 ~71 ~110 ~113 ~71 ~110 grass_block
fill ~114 ~60 ~110 ~116 ~68 ~110 stone
fill ~114 ~69 ~110 ~116 ~71 ~110 dirt
fill ~114 ~72 ~110 ~116 ~72 ~110 grass_block
fill ~117 ~60 ~110 ~117 ~67 ~110 stone
fill ~117 ~68 ~110 ~117 ~70 ~110 dirt
fill ~117 ~71 ~110 ~117 ~71 ~110 grass_block
fill ~118 ~60 ~110 ~122 ~66 ~110 stone
fill ~118 ~67 ~110 ~122 ~69 ~110 dirt
fill ~118 ~70 ~110 ~122 ~70 ~110 grass_block
fill ~123 ~60 ~110 ~125 ~65 ~110 stone
fill ~123 ~66 ~110 ~125 ~68 ~110 dirt
fill ~123 ~69 ~110 ~125 ~69 ~110 grass_block
fill ~126 ~60 ~110 ~127 ~64 ~110 stone
fill ~126 ~65 ~110 ~127 ~67 ~110 dirt
fill ~126 ~68 ~110 ~127 ~68 ~110 grass_block
fill ~112 ~60 ~111 ~117 ~68 ~111 stone
fill ~112 ~69 ~111 ~117 ~71 ~111 dirt
fill ~112 ~72 ~111 ~117 ~72 ~111 grass_block
fill ~118 ~60 ~111 ~121 ~67 ~111 stone
fill ~118 ~68 ~111 ~121 ~70 ~111 dirt
fill ~118 ~71 ~111 ~121 ~71 ~111 grass_block
fill ~122 ~60 ~111 ~123 ~66 ~111 stone
fill ~122 ~67 ~111 ~123 ~69 ~111 dirt
fill ~122 ~70 ~111 ~123 ~70 ~111 grass_block
fill ~124 ~60 ~111 ~125 ~65 ~111 stone
fill ~124 ~66 ~111 ~125 ~68 ~111 dirt
fill ~124 ~69 ~111 ~125 ~69 ~111 grass_block
fill ~126 ~60 ~111 ~127 ~64 ~111 stone
fill ~126 ~65 ~111 ~127 ~67 ~111 dirt
fill ~126 ~68 ~111 ~127 ~68 ~111 grass_block