fill ~64 ~60 ~0 ~64 ~68 ~0 stone
fill ~64 ~69 ~0 ~64 ~71 ~0 dirt
fill ~64 ~72 ~0 ~64 ~72 ~0 grass_block
fill ~65 ~60 ~0 ~66 ~69 ~0 stone
fill ~65 ~70 ~0 ~66 ~72 ~0 dirt
fill ~65 ~73 ~0 ~66 ~73 ~0 grass_block
fill ~67 ~60 ~0 ~70 ~68 ~0 stone
fill ~67 ~69 ~0 ~70 ~71 ~0 dirt
fill ~67 ~72 ~0 ~70 ~72 ~0 grass_block
fill ~71 ~60 ~0 ~72 ~67 ~0 stone
fill ~71 ~68 ~0 ~72 ~70 ~0 dirt
fill ~71 ~71 ~0 ~72 ~71 ~0 grass_block
fill ~73 ~60 ~0 ~75 ~66 ~0 stone
fill ~73 ~67 ~0 ~75 ~69 ~0 dirt
fill ~73 ~70 ~0 ~75 ~70 ~0 grass_block
fill ~76 ~60 ~0 ~79 ~65 ~0 stone
fill ~76 ~66 ~0 ~79 ~68 ~0 dirt
fill ~76 ~69 ~0 ~79 ~69 ~0 grass_block
fill ~64 ~60 ~1 ~65 ~68 ~1 stone
fill ~64 ~69 ~1 ~65 ~71 ~1 dirt
fill ~64 ~72 ~1 ~65 ~72 ~1 grass_block
fill ~66 ~60 ~1 ~68 ~69 ~1 stone
fill ~66 ~70 ~1 ~68 ~72 ~1 dirt
fill ~66 ~73 ~1 ~68 ~73 ~1 grass_block
fill ~69 ~60 ~1 ~71 ~68 ~1 stone
fill ~69 ~69 ~1 ~71 ~71 ~1 dirt
fill ~69 ~72 ~1 ~71 ~72 ~1 grass_block
fill ~72 ~60 ~1 ~73 ~67 ~1 stone
fill ~72 ~68 ~1 ~73 ~70 ~1 dirt
fill ~72 ~71 ~1 ~73 ~71 ~1 grass_block
fill ~74 ~60 ~1 ~76 ~66 ~1 stone
fill ~74 ~67 ~1 ~76 ~69 ~1 dirt
fill ~74 ~70 ~1 ~76 ~70 ~1 grass_block
fill ~77 ~60 ~1 ~77 ~65 ~1 stone
fill ~77 ~66 ~1 ~77 ~68 ~1 dirt
fill ~77 ~69 ~1 ~77 ~69 ~1 grass_block
fill ~78 ~60 ~1 ~79 ~66 ~1 stone
fill ~78 ~67 ~1 ~79 ~69 ~1 dirt
fill ~78 ~70 ~1 ~79 ~70 ~1 grass_block
fill ~64 ~60 ~2 ~64 ~67 ~2 stone
fill ~64 ~68 ~2 ~64 ~70 ~2 dirt
fill ~64 ~71 ~2 ~64 ~71 ~2 grass_block
fill ~65 ~60 ~2 ~66 ~68 ~2 stone
fill ~65 ~69 ~2 ~66 ~71 ~2 dirt
fill ~65 ~72 ~2 ~66 ~72 ~2 grass_block
fill ~67 ~60 ~2 ~71 ~69 ~2 stone
fill ~67 ~70 ~2 ~71 ~72 ~2 dirt
fill ~67 ~73 ~2 ~71 ~73 ~2 grass_block
fill ~72 ~60 ~2 ~73 ~68 ~2 stone
fill ~72 ~69 ~2 ~73 ~71 ~2 dirt
fill ~72 ~72 ~2 ~73 ~72 ~2 grass_block
fill ~74 ~60 ~2 ~75 ~67 ~2 stone
fill ~74 ~68 ~2 ~75 ~70 ~2 dirt
fill ~74 ~71 ~2 ~75 ~71 ~2 grass_block
fill ~76 ~60 ~2 ~79 ~66 ~2 stone
fill ~76 ~67 ~2 ~79 ~69 ~2 dirt
fill ~76 ~70 ~2 ~79 ~70 ~2 grass_block
fill ~64 ~60 ~3 ~65 ~67 ~3 stone
fill ~64 ~68 ~3 ~65 ~70 ~3 dirt
fill ~64 ~71 ~3 ~65 ~71 ~3 grass_block
fill ~66 ~60 ~3 ~67 ~68 ~3 stone
fill ~66 ~69 ~3 ~67 ~71 ~3 dirt
fill ~66 ~72 ~3 ~67 ~72 ~3 grass_block
fill ~68 ~60 ~3 ~72 ~69 ~3 stone
fill ~68 ~70 ~3 ~72 ~72 ~3 dirt
fill ~68 ~73 ~3 ~72 ~73 ~3 grass_block
fill ~73 ~60 ~3 ~75 ~68 ~3 stone
fill ~73 ~69 ~3 ~75 ~71 ~3 dirt
fill ~73 ~72 ~3 ~75 ~72 ~3 grass_block
fill ~76 ~60 ~3 ~79 ~67 ~3 stone
fill ~76 ~68 ~3 ~79 ~70 ~3 dirt
fill ~76 ~71 ~3 ~79 ~71 ~3 grass_block
fill ~64 ~60 ~4 ~64 ~66 ~4 stone
fill ~64 ~67 ~4 ~64 ~69 ~4 dirt
fill ~64 ~70 ~4 ~64 ~70 ~4 grass_block
fill ~65 ~60 ~4 ~66 ~67 ~4 stone
fill ~65 ~68 ~4 ~66 ~70 ~4 dirt
fill ~65 ~71 ~4 ~66 ~71 ~4 grass_block
fill ~67 ~60 ~4 ~67 ~68 ~4 stone
fill ~67 ~69 ~4 ~67 ~71 ~4 dirt
fill ~67 ~72 ~4 ~67 ~72 ~4 grass_block
fill ~68 ~60 ~4 ~73 ~69 ~4 stone
fill ~68 ~70 ~4 ~73 ~72 ~4 dirt
fill ~68 ~73 ~4 ~73 ~73 ~4 grass_block
fill ~74 ~60 ~4 ~76 ~68 ~4 stone
fill ~74 ~69 ~4 ~76 ~71 ~4 dirt
fill ~74 ~72 ~4 ~76 ~72 ~4 grass_block
fill ~77 ~60 ~4 ~78 ~67 ~4 stone
fill ~77 ~68 ~4 ~78 ~70 ~4 dirt
fill ~77 ~71 ~4 ~78 ~71 ~4 grass_block
fill ~79 ~60 ~4 ~79 ~68 ~4 stone
fill ~79 ~69 ~4 ~79 ~71 ~4 dirt
fill ~79 ~72 ~4 ~79 ~72 ~4 grass_block
fill ~64 ~60 ~5 ~65 ~66 ~5 stone
fill ~64 ~67 ~5 ~65 ~69 ~5 dirt
fill ~64 ~70 ~5 ~65 ~70 ~5 grass_block
fill ~66 ~60 ~5 ~66 ~67 ~5 stone
fill ~66 ~68 ~5 ~66 ~70 ~5 dirt
fill ~66 ~71 ~5 ~66 ~71 ~5 grass_block
fill ~67 ~60 ~5 ~68 ~68 ~5 stone
fill ~67 ~69 ~5 ~68 ~71 ~5 dirt
fill ~67 ~72 ~5 ~68 ~72 ~5 grass_block
fill ~69 ~60 ~5 ~75 ~69 ~5 stone
fill ~69 ~70 ~5 ~75 ~72 ~5 dirt
fill ~69 ~73 ~5 ~75 ~73 ~5 grass_block
fill ~76 ~60 ~5 ~79 ~68 ~5 stone
fill ~76 ~69 ~5 ~79 ~71 ~5 dirt
fill ~76 ~72 ~5 ~79 ~72 ~5 grass_block
fill ~64 ~60 ~6 ~65 ~66 ~6 stone
fill ~64 ~67 ~6 ~65 ~69 ~6 dirt
fill ~64 ~70 ~6 ~65 ~70 ~6 grass_block
fill ~66 ~60 ~6 ~67 ~67 ~6 stone
fill ~66 ~68 ~6 ~67 ~70 ~6 dirt
fill ~66 ~71 ~6 ~67 ~71 ~6 grass_block
fill ~68 ~60 ~6 ~69 ~68 ~6 stone
fill ~68 ~69 ~6 ~69 ~71 ~6 dirt
fill ~68 ~72 ~6 ~69 ~72 ~6 grass_block
fill ~70 ~60 ~6 ~75 ~69 ~6 stone
fill ~70 ~70 ~6 ~75 ~72 ~6 dirt
fill ~70 ~73 ~6 ~75 ~73 ~6 grass_block
fill ~76 ~60 ~6 ~79 ~68 ~6 stone
fill ~76 ~69 ~6 ~79 ~71 ~6 dirt
fill ~76 ~72 ~6 ~79 ~72 ~6 grass_block
fill ~64 ~60 ~7 ~64 ~65 ~7 stone
fill ~64 ~66 ~7 ~64 ~68 ~7 dirt
fill ~64 ~69 ~7 ~64 ~69 ~7 grass_block
fill ~65 ~60 ~7 ~66 ~66 ~7 stone
fill ~65 ~67 ~7 ~66 ~69 ~7 dirt
fill ~65 ~70 ~7 ~66 ~70 ~7 grass_block
fill ~67 ~60 ~7 ~68 ~67 ~7 stone
fill ~67 ~68 ~7 ~68 ~70 ~7 dirt
fill ~67 ~71 ~7 ~68 ~71 ~7 grass_block
fill ~69 ~60 ~7 ~72 ~68 ~7 stone
fill ~69 ~69 ~7 ~72 ~71 ~7 dirt
fill ~69 ~72 ~7 ~72 ~72 ~7 grass_block
fill ~73 ~60 ~7 ~79 ~69 ~7 stone
fill ~73 ~70 ~7 ~79 ~72 ~7 dirt
fill ~73 ~73 ~7 ~79 ~73 ~7 grass_block
fill ~64 ~60 ~8 ~65 ~65 ~8 stone
fill ~64 ~66 ~8 ~65 ~68 ~8 dirt
fill ~64 ~69 ~8 ~65 ~69 ~8 grass_block
fill ~66 ~60 ~8 ~67 ~66 ~8 stone
fill ~66 ~67 ~8 ~67 ~69 ~8 dirt
fill ~66 ~70 ~8 ~67 ~70 ~8 grass_block
fill ~68 ~60 ~8 ~71 ~67 ~8 stone
fill ~68 ~68 ~8 ~71 ~70 ~8 dirt
fill ~68 ~71 ~8 ~71 ~71 ~8 grass_block
fill ~72 ~60 ~8 ~72 ~68 ~8 stone
fill ~72 ~69 ~8 ~72 ~71 ~8 dirt
fill ~72 ~72 ~8 ~72 ~72 ~8 grass_block
fill ~73 ~60 ~8 ~79 ~69 ~8 stone
fill ~73 ~70 ~8 ~79 ~72 ~8 dirt
fill ~73 ~73 ~8 ~79 ~73 ~8 grass_block
fill ~64 ~60 ~9 ~67 ~65 ~9 stone
fill ~64 ~66 ~9 ~67 ~68 ~9 dirt
fill ~64 ~69 ~9 ~67 ~69 ~9 grass_block
fill ~68 ~60 ~9 ~69 ~66 ~9 stone
fill ~68 ~67 ~9 ~69 ~69 ~9 dirt
fill ~68 ~70 ~9 ~69 ~70 ~9 grass_block
fill ~70 ~60 ~9 ~71 ~67 ~9 stone
fill ~70 ~68 ~9 ~71 ~70 ~9 dirt
fill ~70 ~71 ~9 ~71 ~71 ~9 grass_block
fill ~72 ~60 ~9 ~73 ~68 ~9 stone
fill ~72 ~69 ~9 ~73 ~71 ~9 dirt
fill ~72 ~72 ~9 ~73 ~72 ~9 grass_block
fill ~74 ~60 ~9 ~79 ~69 ~9 stone
fill ~74 ~70 ~9 ~79 ~72 ~9 dirt
fill ~74 ~73 ~9 ~79 ~73 ~9 grass_block
fill ~64 ~60 ~10 ~64 ~65 ~10 stone
fill ~64 ~66 ~10 ~64 ~68 ~10 dirt
fill ~64 ~69 ~10 ~64 ~69 ~10 grass_block
fill ~65 ~60 ~10 ~65 ~64 ~10 stone
fill ~65 ~65 ~10 ~65 ~67 ~10 dirt
fill ~65 ~68 ~10 ~65 ~68 ~10 grass_block
fill ~66 ~60 ~10 ~67 ~65 ~10 stone
fill ~66 ~66 ~10 ~67 ~68 ~10 dirt
fill ~66 ~69 ~10 ~67 ~69 ~10 grass_block
fill ~68 ~60 ~10 ~70 ~66 ~10 stone
fill ~68 ~67 ~10 ~70 ~69 ~10 dirt
fill ~68 ~70 ~10 ~70 ~70 ~10 grass_block
fill ~71 ~60 ~10 ~72 ~67 ~10 stone
fill ~71 ~68 ~10 ~72 ~70 ~10 dirt
fill ~71 ~71 ~10 ~72 ~71 ~10 grass_block
fill ~73 ~60 ~10 ~75 ~68 ~10 stone
fill ~73 ~69 ~10 ~75 ~71 ~10 dirt
fill ~73 ~72 ~10 ~75 ~72 ~10 grass_block
fill ~76 ~60 ~10 ~79 ~69 ~10 stone
fill ~76 ~70 ~10 ~79 ~72 ~10 dirt
fill ~76 ~73 ~10 ~79 ~73 ~10 grass_block
fill ~64 ~60 ~11 ~64 ~65 ~11 stone
fill ~64 ~66 ~11 ~64 ~68 ~11 dirt
fill ~64 ~69 ~11 ~64 ~69 ~11 grass_block
fill ~65 ~60 ~11 ~66 ~64 ~11 stone
fill ~65 ~65 ~11 ~66 ~67 ~11 dirt
fill ~65 ~68 ~11 ~66 ~68 ~11 grass_block
fill ~67 ~60 ~11 ~69 ~65 ~11 stone
fill ~67 ~66 ~11 ~69 ~68 ~11 dirt
fill ~67 ~69 ~11 ~69 ~69 ~11 grass_block
fill ~70 ~60 ~11 ~71 ~66 ~11 stone
fill ~70 ~67 ~11 ~71 ~69 ~11 dirt
fill ~70 ~70 ~11 ~71 ~70 ~11 grass_block
fill ~72 ~60 ~11 ~74 ~67 ~11 stone
fill ~72 ~68 ~11 ~74 ~70 ~11 dirt
fill ~72 ~71 ~11 ~74 ~71 ~11 grass_block
fill ~75 ~60 ~11 ~76 ~68 ~11 stone
fill ~75 ~69 ~11 ~76 ~71 ~11 dirt
fill ~75 ~72 ~11 ~76 ~72 ~11 grass_block
fill ~77 ~60 ~11 ~79 ~69 ~11 stone
fill ~77 ~70 ~11 ~79 ~72 ~11 dirt
fill ~77 ~73 ~11 ~79 ~73 ~11 grass_block
fill ~64 ~60 ~12 ~64 ~65 ~12 stone
fill ~64 ~66 ~12 ~64 ~68 ~12 dirt
fill ~64 ~69 ~12 ~64 ~69 ~12 grass_block
fill ~65 ~60 ~12 ~67 ~64 ~12 stone
fill ~65 ~65 ~12 ~67 ~67 ~12 dirt
fill ~65 ~68 ~12 ~67 ~68 ~12 grass_block
fill ~68 ~60 ~12 ~70 ~65 ~12 stone
fill ~68 ~66 ~12 ~70 ~68 ~12 dirt
fill ~68 ~69 ~12 ~70 ~69 ~12 grass_block
fill ~71 ~60 ~12 ~73 ~66 ~12 stone
fill ~71 ~67 ~12 ~73 ~69 ~12 dirt
fill ~71 ~70 ~12 ~73 ~70 ~12 grass_block
fill ~74 ~60 ~12 ~74 ~67 ~12 stone
fill ~74 ~68 ~12 ~74 ~70 ~12 dirt
fill ~74 ~71 ~12 ~74 ~71 ~12 grass_block
fill ~75 ~60 ~12 ~78 ~68 ~12 stone
fill ~75 ~69 ~12 ~78 ~71 ~12 dirt
fill ~75 ~72 ~12 ~78 ~72 ~12 grass_block
fill ~79 ~60 ~12 ~79 ~69 ~12 stone
fill ~79 ~70 ~12 ~79 ~72 ~12 dirt
fill ~79 ~73 ~12 ~79 ~73 ~12 grass_block
fill ~64 ~60 ~13 ~65 ~65 ~13 stone
fill ~64 ~66 ~13 ~65 ~68 ~13 dirt
fill ~64 ~69 ~13 ~65 ~69 ~13 grass_block
fill ~66 ~60 ~13 ~68 ~64 ~13 stone
fill ~66 ~65 ~13 ~68 ~67 ~13 dirt
fill ~66 ~68 ~13 ~68 ~68 ~13 grass_block
fill ~69 ~60 ~13 ~71 ~65 ~13 stone
fill ~69 ~66 ~13 ~71 ~68 ~13 dirt
fill ~69 ~69 ~13 ~71 ~69 ~13 grass_block
fill ~72 ~60 ~13 ~73 ~66 ~13 stone
fill ~72 ~67 ~13 ~73 ~69 ~13 dirt
fill ~72 ~70 ~13 ~73 ~70 ~13 grass_block
fill ~74 ~60 ~13 ~76 ~67 ~13 stone
fill ~74 ~68 ~13 ~76 ~70 ~13 dirt
fill ~74 ~71 ~13 ~76 ~71 ~13 grass_block
fill ~77 ~60 ~13 ~78 ~68 ~13 stone
fill ~77 ~69 ~13 ~78 ~71 ~13 dirt
fill ~77 ~72 ~13 ~78 ~72 ~13 grass_block
fill ~79 ~60 ~13 ~79 ~69 ~13 stone
fill ~79 ~70 ~13 ~79 ~72 ~13 dirt
fill ~79 ~73 ~13 ~79 ~73 ~13 grass_block
fill ~64 ~60 ~14 ~65 ~65 ~14 stone
fill ~64 ~66 ~14 ~65 ~68 ~14 dirt
fill ~64 ~69 ~14 ~65 ~69 ~14 grass_block
fill ~66 ~60 ~14 ~70 ~64 ~14 stone
fill ~66 ~65 ~14 ~70 ~67 ~14 dirt
fill ~66 ~68 ~14 ~70 ~68 ~14 grass_block
fill ~71 ~60 ~14 ~72 ~65 ~14 stone
fill ~71 ~66 ~14 ~72 ~68 ~14 dirt
fill ~71 ~69 ~14 ~72 ~69 ~14 grass_block
fill ~73 ~60 ~14 ~75 ~66 ~14 stone
fill ~73 ~67 ~14 ~75 ~69 ~14 dirt
fill ~73 ~70 ~14 ~75 ~70 ~14 grass_block
fill ~76 ~60 ~14 ~77 ~67 ~14 stone
fill ~76 ~68 ~14 ~77 ~70 ~14 dirt
fill ~76 ~71 ~14 ~77 ~71 ~14 grass_block
fill ~78 ~60 ~14 ~79 ~68 ~14 stone
fill ~78 ~69 ~14 ~79 ~71 ~14 dirt
fill ~78 ~72 ~14 ~79 ~72 ~14 grass_block
fill ~64 ~60 ~15 ~65 ~65 ~15 stone
fill ~64 ~66 ~15 ~65 ~68 ~15 dirt
fill ~64 ~69 ~15 ~65 ~69 ~15 grass_block
fill ~66 ~60 ~15 ~70 ~64 ~15 stone
fill ~66 ~65 ~15 ~70 ~67 ~15 dirt
fill ~66 ~68 ~15 ~70 ~68 ~15 grass_block
fill ~71 ~60 ~15 ~73 ~65 ~15 stone
fill ~71 ~66 ~15 ~73 ~68 ~15 dirt
fill ~71 ~69 ~15 ~73 ~69 ~15 grass_block
fill ~74 ~60 ~15 ~75 ~66 ~15 stone
fill ~74 ~67 ~15 ~75 ~69 ~15 dirt
fill ~74 ~70 ~15 ~75 ~70 ~15 grass_block
fill ~76 ~60 ~15 ~77 ~67 ~15 stone
fill ~76 ~68 ~15 ~77 ~70 ~15 dirt
fill ~76 ~71 ~15 ~77 ~71 ~15 grass_block
fill ~78 ~60 ~15 ~79 ~68 ~15 stone
fill ~78 ~69 ~15 ~79 ~71 ~15 dirt
fill ~78 ~72 ~15 ~79 ~72 ~15 grass_block