fill ~64 ~60 ~96 ~64 ~66 ~96 stone
fill ~64 ~67 ~96 ~64 ~69 ~96 dirt
fill ~64 ~70 ~96 ~64 ~70 ~96 grass_block
fill ~65 ~60 ~96 ~66 ~67 ~96 stone
fill ~65 ~68 ~96 ~66 ~70 ~96 dirt
fill ~65 ~71 ~96 ~66 ~71 ~96 grass_block
fill ~67 ~60 ~96 ~68 ~68 ~96 stone
fill ~67 ~69 ~96 ~68 ~71 ~96 dirt
fill ~67 ~72 ~96 ~68 ~72 ~96 grass_block
fill ~69 ~60 ~96 ~71 ~69 ~96 stone
fill ~69 ~70 ~96 ~71 ~72 ~96 dirt
fill ~69 ~73 ~96 ~71 ~73 ~96 grass_block
fill ~72 ~60 ~96 ~72 ~70 ~96 stone
fill ~72 ~71 ~96 ~72 ~73 ~96 dirt
fill ~72 ~74 ~96 ~72 ~74 ~96 grass_block
fill ~73 ~60 ~96 ~76 ~69 ~96 stone
fill ~73 ~70 ~96 ~76 ~72 ~96 dirt
fill ~73 ~73 ~96 ~76 ~73 ~96 grass_block
fill ~77 ~60 ~96 ~79 ~68 ~96 stone
fill ~77 ~69 ~96 ~79 ~71 ~96 dirt
fill ~77 ~72 ~96 ~79 ~72 ~96 grass_block
fill ~64 ~60 ~97 ~64 ~66 ~97 stone
fill ~64 ~67 ~97 ~64 ~69 ~97 dirt
fill ~64 ~70 ~97 ~64 ~70 ~97 grass_block
fill ~65 ~60 ~97 ~66 ~67 ~97 stone
fill ~65 ~68 ~97 ~66 ~70 ~97 dirt
fill ~65 ~71 ~97 ~66 ~71 ~97 grass_block
fill ~67 ~60 ~97 ~69 ~68 ~97 stone
fill ~67 ~69 ~97 ~69 ~71 ~97 dirt
fill ~67 ~72 ~97 ~69 ~72 ~97 grass_block
fill ~70 ~60 ~97 ~72 ~69 ~97 stone
fill ~70 ~70 ~97 ~72 ~72 ~97 dirt
fill ~70 ~73 ~97 ~72 ~73 ~97 grass_block
fill ~73 ~60 ~97 ~73 ~70 ~97 stone
fill ~73 ~71 ~97 ~73 ~73 ~97 dirt
fill ~73 ~74 ~97 ~73 ~74 ~97 grass_block
fill ~74 ~60 ~97 ~77 ~69 ~97 stone
fill ~74 ~70 ~97 ~77 ~72 ~97 dirt
fill ~74 ~73 ~97 ~77 ~73 ~97 grass_block
fill ~78 ~60 ~97 ~79 ~68 ~97 stone
fill ~78 ~69 ~97 ~79 ~71 ~97 dirt
fill ~78 ~72 ~97 ~79 ~72 ~97 grass_block
fill ~64 ~60 ~98 ~64 ~66 ~98 stone
fill ~64 ~67 ~98 ~64 ~69 ~98 dirt
fill ~64 ~70 ~98 ~64 ~70 ~98 grass_block
fill ~65 ~60 ~98 ~66 ~67 ~98 stone
fill ~65 ~68 ~98 ~66 ~70 ~98 dirt
fill ~65 ~71 ~98 ~66 ~71 ~98 grass_block
fill ~67 ~60 ~98 ~70 ~68 ~98 stone
fill ~67 ~69 ~98 ~70 ~71 ~98 dirt
fill ~67 ~72 ~98 ~70 ~72 ~98 grass_block
fill ~71 ~60 ~98 ~73 ~69 ~98 stone
fill ~71 ~70 ~98 ~73 ~72 ~98 dirt
fill ~71 ~73 ~98 ~73 ~73 ~98 grass_block
fill ~74 ~60 ~98 ~74 ~70 ~98 stone
fill ~74 ~71 ~98 ~74 ~73 ~98 dirt
fill ~74 ~74 ~98 ~74 ~74 ~98 grass_block
fill ~75 ~60 ~98 ~78 ~69 ~98 stone
fill ~75 ~70 ~98 ~78 ~72 ~98 dirt
fill ~75 ~73 ~98 ~78 ~73 ~98 grass_block
fill ~79 ~60 ~98 ~79 ~68 ~98 stone
fill ~79 ~69 ~98 ~79 ~71 ~98 dirt
fill ~79 ~72 ~98 ~79 ~72 ~98 grass_block
fill ~64 ~60 ~99 ~64 ~66 ~99 stone
fill ~64 ~67 ~99 ~64 ~69 ~99 dirt
fill ~64 ~70 ~99 ~64 ~70 ~99 grass_block
fill ~65 ~60 ~99 ~67 ~67 ~99 stone
fill ~65 ~68 ~99 ~67 ~70 ~99 dirt
fill ~65 ~71 ~99 ~67 ~71 ~99 grass_block
fill ~68 ~60 ~99 ~71 ~68 ~99 stone
fill ~68 ~69 ~99 ~71 ~71 ~99 dirt
fill ~68 ~72 ~99 ~71 ~72 ~99 grass_block
fill ~72 ~60 ~99 ~77 ~69 ~99 stone
fill ~72 ~70 ~99 ~77 ~72 ~99 dirt
fill ~72 ~73 ~99 ~77 ~73 ~99 grass_block
fill ~78 ~60 ~99 ~79 ~68 ~99 stone
fill ~78 ~69 ~99 ~79 ~71 ~99 dirt
fill ~78 ~72 ~99 ~79 ~72 ~99 grass_block
fill ~64 ~60 ~100 ~64 ~66 ~100 stone
fill ~64 ~67 ~100 ~64 ~69 ~100 dirt
fill ~64 ~70 ~100 ~64 ~70 ~100 grass_block
fill ~65 ~60 ~100 ~69 ~67 ~100 stone
fill ~65 ~68 ~100 ~69 ~70 ~100 dirt
fill ~65 ~71 ~100 ~69 ~71 ~100 grass_block
fill ~70 ~60 ~100 ~71 ~68 ~100 stone
fill ~70 ~69 ~100 ~71 ~71 ~100 dirt
fill ~70 ~72 ~100 ~71 ~72 ~100 grass_block
fill ~72 ~60 ~100 ~77 ~69 ~100 stone
fill ~72 ~70 ~100 ~77 ~72 ~100 dirt
fill ~72 ~73 ~100 ~77 ~73 ~100 grass_block
fill ~78 ~60 ~100 ~79 ~68 ~100 stone
fill ~78 ~69 ~100 ~79 ~71 ~100 dirt
fill ~78 ~72 ~100 ~79 ~72 ~100 grass_block
fill ~64 ~60 ~101 ~64 ~66 ~101 stone
fill ~64 ~67 ~101 ~64 ~69 ~101 dirt
fill ~64 ~70 ~101 ~64 ~70 ~101 grass_block
fill ~65 ~60 ~101 ~70 ~67 ~101 stone
fill ~65 ~68 ~101 ~70 ~70 ~101 dirt
fill ~65 ~71 ~101 ~70 ~71 ~101 grass_block
fill ~71 ~60 ~101 ~72 ~68 ~101 stone
fill ~71 ~69 ~101 ~72 ~71 ~101 dirt
fill ~71 ~72 ~101 ~72 ~72 ~101 grass_block
fill ~73 ~60 ~101 ~78 ~69 ~101 stone
fill ~73 ~70 ~101 ~78 ~72 ~101 dirt
fill ~73 ~73 ~101 ~78 ~73 ~101 grass_block
fill ~79 ~60 ~101 ~79 ~68 ~101 stone
fill ~79 ~69 ~101 ~79 ~71 ~101 dirt
fill ~79 ~72 ~101 ~79 ~72 ~101 grass_block
fill ~64 ~60 ~102 ~68 ~66 ~102 stone
fill ~64 ~67 ~102 ~68 ~69 ~102 dirt
fill ~64 ~70 ~102 ~68 ~70 ~102 grass_block
fill ~69 ~60 ~102 ~71 ~67 ~102 stone
fill ~69 ~68 ~102 ~71 ~70 ~102 dirt
fill ~69 ~71 ~102 ~71 ~71 ~102 grass_block
fill ~72 ~60 ~102 ~73 ~68 ~102 stone
fill ~72 ~69 ~102 ~73 ~71 ~102 dirt
fill ~72 ~72 ~102 ~73 ~72 ~102 grass_block
fill ~74 ~60 ~102 ~79 ~69 ~102 stone
fill ~74 ~70 ~102 ~79 ~72 ~102 dirt
fill ~74 ~73 ~102 ~79 ~73 ~102 grass_block
fill ~64 ~60 ~103 ~68 ~66 ~103 stone
fill ~64 ~67 ~103 ~68 ~69 ~103 dirt
fill ~64 ~70 ~103 ~68 ~70 ~103 grass_block
fill ~69 ~60 ~103 ~70 ~67 ~103 stone
fill ~69 ~68 ~103 ~70 ~70 ~103 dirt
fill ~69 ~71 ~103 ~70 ~71 ~103 grass_block
fill ~71 ~60 ~103 ~73 ~68 ~103 stone
fill ~71 ~69 ~103 ~73 ~71 ~103 dirt
fill ~71 ~72 ~103 ~73 ~72 ~103 grass_block
fill ~74 ~60 ~103 ~79 ~69 ~103 stone
fill ~74 ~70 ~103 ~79 ~72 ~103 dirt
fill ~74 ~73 ~103 ~79 ~73 ~103 grass_block
fill ~64 ~60 ~104 ~65 ~66 ~104 stone
fill ~64 ~67 ~104 ~65 ~69 ~104 dirt
fill ~64 ~70 ~104 ~65 ~70 ~104 grass_block
fill ~66 ~60 ~104 ~66 ~65 ~104 stone
fill ~66 ~66 ~104 ~66 ~68 ~104 dirt
fill ~66 ~69 ~104 ~66 ~69 ~104 grass_block
fill ~67 ~60 ~104 ~68 ~66 ~104 stone
fill ~67 ~67 ~104 ~68 ~69 ~104 dirt
fill ~67 ~70 ~104 ~68 ~70 ~104 grass_block
fill ~69 ~60 ~104 ~70 ~67 ~104 stone
fill ~69 ~68 ~104 ~70 ~70 ~104 dirt
fill ~69 ~71 ~104 ~70 ~71 ~104 grass_block
fill ~71 ~60 ~104 ~74 ~68 ~104 stone
fill ~71 ~69 ~104 ~74 ~71 ~104 dirt
fill ~71 ~72 ~104 ~74 ~72 ~104 grass_block
fill ~75 ~60 ~104 ~78 ~69 ~104 stone
fill ~75 ~70 ~104 ~78 ~72 ~104 dirt
fill ~75 ~73 ~104 ~78 ~73 ~104 grass_block
fill ~79 ~60 ~104 ~79 ~68 ~104 stone
fill ~79 ~69 ~104 ~79 ~71 ~104 dirt
fill ~79 ~72 ~104 ~79 ~72 ~104 grass_block
fill ~64 ~60 ~105 ~66 ~65 ~105 stone
fill ~64 ~66 ~105 ~66 ~68 ~105 dirt
fill ~64 ~69 ~105 ~66 ~69 ~105 grass_block
fill ~67 ~60 ~105 ~69 ~66 ~105 stone
fill ~67 ~67 ~105 ~69 ~69 ~105 dirt
fill ~67 ~70 ~105 ~69 ~70 ~105 grass_block
fill ~70 ~60 ~105 ~71 ~67 ~105 stone
fill ~70 ~68 ~105 ~71 ~70 ~105 dirt
fill ~70 ~71 ~105 ~71 ~71 ~105 grass_block
fill ~72 ~60 ~105 ~75 ~68 ~105 stone
fill ~72 ~69 ~105 ~75 ~71 ~105 dirt
fill ~72 ~72 ~105 ~75 ~72 ~105 grass_block
fill ~76 ~60 ~105 ~78 ~69 ~105 stone
fill ~76 ~70 ~105 ~78 ~72 ~105 dirt
fill ~76 ~73 ~105 ~78 ~73 ~105 grass_block
fill ~79 ~60 ~105 ~79 ~68 ~105 stone
fill ~79 ~69 ~105 ~79 ~71 ~105 dirt
fill ~79 ~72 ~105 ~79 ~72 ~105 grass_block
fill ~64 ~60 ~106 ~67 ~65 ~106 stone
fill ~64 ~66 ~106 ~67 ~68 ~106 dirt
fill ~64 ~69 ~106 ~67 ~69 ~106 grass_block
fill ~68 ~60 ~106 ~69 ~66 ~106 stone
fill ~68 ~67 ~106 ~69 ~69 ~106 dirt
fill ~68 ~70 ~106 ~69 ~70 ~106 grass_block
fill ~70 ~60 ~106 ~71 ~67 ~106 stone
fill ~70 ~68 ~106 ~71 ~70 ~106 dirt
fill ~70 ~71 ~106 ~71 ~71 ~106 grass_block
fill ~72 ~60 ~106 ~79 ~68 ~106 stone
fill ~72 ~69 ~106 ~79 ~71 ~106 dirt
fill ~72 ~72 ~106 ~79 ~72 ~106 grass_block
fill ~64 ~60 ~107 ~67 ~65 ~107 stone
fill ~64 ~66 ~107 ~67 ~68 ~107 dirt
fill ~64 ~69 ~107 ~67 ~69 ~107 grass_block
fill ~68 ~60 ~107 ~69 ~66 ~107 stone
fill ~68 ~67 ~107 ~69 ~69 ~107 dirt
fill ~68 ~70 ~107 ~69 ~70 ~107 grass_block
fill ~70 ~60 ~107 ~71 ~67 ~107 stone
fill ~70 ~68 ~107 ~71 ~70 ~107 dirt
fill ~70 ~71 ~107 ~71 ~71 ~107 grass_block
fill ~72 ~60 ~107 ~79 ~68 ~107 stone
fill ~72 ~69 ~107 ~79 ~71 ~107 dirt
fill ~72 ~72 ~107 ~79 ~72 ~107 grass_block
fill ~64 ~60 ~108 ~65 ~64 ~108 stone
fill ~64 ~65 ~108 ~65 ~67 ~108 dirt
fill ~64 ~68 ~108 ~65 ~68 ~108 grass_block
fill ~66 ~60 ~108 ~68 ~65 ~108 stone
fill ~66 ~66 ~108 ~68 ~68 ~108 dirt
fill ~66 ~69 ~108 ~68 ~69 ~108 grass_block
fill ~69 ~60 ~108 ~70 ~66 ~108 stone
fill ~69 ~67 ~108 ~70 ~69 ~108 dirt
fill ~69 ~70 ~108 ~70 ~70 ~108 grass_block
fill ~71 ~60 ~108 ~72 ~67 ~108 stone
fill ~71 ~68 ~108 ~72 ~70 ~108 dirt
fill ~71 ~71 ~108 ~72 ~71 ~108 grass_block
fill ~73 ~60 ~108 ~79 ~68 ~108 stone
fill ~73 ~69 ~108 ~79 ~71 ~108 dirt
fill ~73 ~72 ~108 ~79 ~72 ~108 grass_block
fill ~64 ~60 ~109 ~66 ~64 ~109 stone
fill ~64 ~65 ~109 ~66 ~67 ~109 dirt
fill ~64 ~68 ~109 ~66 ~68 ~109 grass_block
fill ~67 ~60 ~109 ~68 ~65 ~109 stone
fill ~67 ~66 ~109 ~68 ~68 ~109 dirt
fill ~67 ~69 ~109 ~68 ~69 ~109 grass_block
fill ~69 ~60 ~109 ~70 ~66 ~109 stone
fill ~69 ~67 ~109 ~70 ~69 ~109 dirt
fill ~69 ~70 ~109 ~70 ~70 ~109 grass_block
fill ~71 ~60 ~109 ~73 ~67 ~109 stone
fill ~71 ~68 ~109 ~73 ~70 ~109 dirt
fill ~71 ~71 ~109 ~73 ~71 ~109 grass_block
fill ~74 ~60 ~109 ~79 ~68 ~109 stone
fill ~74 ~69 ~109 ~79 ~71 ~109 dirt
fill ~74 ~72 ~109 ~79 ~72 ~109 grass_block
fill ~64 ~60 ~110 ~66 ~64 ~110 stone
fill ~64 ~65 ~110 ~66 ~67 ~110 dirt
fill ~64 ~68 ~110 ~66 ~68 ~110 grass_block
fill ~67 ~60 ~110 ~68 ~65 ~110 stone
fill ~67 ~66 ~110 ~68 ~68 ~110 dirt
fill ~67 ~69 ~110 ~68 ~69 ~110 grass_block
fill ~69 ~60 ~110 ~70 ~66 ~110 stone
fill ~69 ~67 ~110 ~70 ~69 ~110 dirt
fill ~69 ~70 ~110 ~70 ~70 ~110 grass_block
fill ~71 ~60 ~110 ~73 ~67 ~110 stone
fill ~71 ~68 ~110 ~73 ~70 ~110 dirt
fill ~71 ~71 ~110 ~73 ~71 ~110 grass_block
fill ~74 ~60 ~110 ~77 ~68 ~110 stone
fill ~74 ~69 ~110 ~77 ~71 ~110 dirt
fill ~74 ~72 ~110 ~77 ~72 ~110 grass_block
fill ~78 ~60 ~110 ~79 ~67 ~110 stone
fill ~78 ~68 ~110 ~79 ~70 ~110 dirt
fill ~78 ~71 ~110 ~79 ~71 ~110 grass_block
fill ~64 ~60 ~111 ~65 ~64 ~111 stone
fill ~64 ~65 ~111 ~65 ~67 ~111 dirt
fill ~64 ~68 ~111 ~65 ~68 ~111 grass_block
fill ~66 ~60 ~111 ~69 ~65 ~111 stone
fill ~66 ~66 ~111 ~69 ~68 ~111 dirt
fill ~66 ~69 ~111 ~69 ~69 ~111 grass_block
fill ~70 ~60 ~111 ~71 ~66 ~111 stone
fill ~70 ~67 ~111 ~71 ~69 ~111 dirt
fill ~70 ~70 ~111 ~71 ~70 ~111 grass_block
fill ~72 ~60 ~111 ~75 ~67 ~111 stone
fill ~72 ~68 ~111 ~75 ~70 ~111 dirt
fill ~72 ~71 ~111 ~75 ~71 ~111 grass_block
fill ~76 ~60 ~111 ~76 ~68 ~111 stone
fill ~76 ~69 ~111 ~76 ~71 ~111 dirt
fill ~76 ~72 ~111 ~76 ~72 ~111 grass_block
fill ~77 ~60 ~111 ~79 ~67 ~111 stone
fill ~77 ~68 ~111 ~79 ~70 ~111 dirt
fill ~77 ~71 ~111 ~79 ~71 ~111 grass_block