fill ~0 ~60 ~32 ~5 ~70 ~32 stone
fill ~0 ~71 ~32 ~5 ~73 ~32 dirt
fill ~0 ~74 ~32 ~5 ~74 ~32 grass_block
fill ~6 ~60 ~32 ~11 ~69 ~32 stone
fill ~6 ~70 ~32 ~11 ~72 ~32 dirt
fill ~6 ~73 ~32 ~11 ~73 ~32 grass_block
fill ~12 ~60 ~32 ~14 ~68 ~32 stone
fill ~12 ~69 ~32 ~14 ~71 ~32 dirt
fill ~12 ~72 ~32 ~14 ~72 ~32 grass_block
fill ~15 ~60 ~32 ~15 ~67 ~32 stone
fill ~15 ~68 ~32 ~15 ~70 ~32 dirt
fill ~15 ~71 ~32 ~15 ~71 ~32 grass_block
fill ~0 ~60 ~33 ~1 ~69 ~33 stone
fill ~0 ~70 ~33 ~1 ~72 ~33 dirt
fill ~0 ~73 ~33 ~1 ~73 ~33 grass_block
fill ~2 ~60 ~33 ~6 ~70 ~33 stone
fill ~2 ~71 ~33 ~6 ~73 ~33 dirt
fill ~2 ~74 ~33 ~6 ~74 ~33 grass_block
fill ~7 ~60 ~33 ~13 ~69 ~33 stone
fill ~7 ~70 ~33 ~13 ~72 ~33 dirt
fill ~7 ~73 ~33 ~13 ~73 ~33 grass_block
fill ~14 ~60 ~33 ~15 ~68 ~33 stone
fill ~14 ~69 ~33 ~15 ~71 ~33 dirt
fill ~14 ~72 ~33 ~15 ~72 ~33 grass_block
fill ~0 ~60 ~34 ~2 ~69 ~34 stone
fill ~0 ~70 ~34 ~2 ~72 ~34 dirt
fill ~0 ~73 ~34 ~2 ~73 ~34 grass_block
fill ~3 ~60 ~34 ~7 ~70 ~34 stone
fill ~3 ~71 ~34 ~7 ~73 ~34 dirt
fill ~3 ~74 ~34 ~7 ~74 ~34 grass_block
fill ~8 ~60 ~34 ~15 ~69 ~34 stone
fill ~8 ~70 ~34 ~15 ~72 ~34 dirt
fill ~8 ~73 ~34 ~15 ~73 ~34 grass_block
fill ~0 ~60 ~35 ~0 ~68 ~35 stone
fill ~0 ~69 ~35 ~0 ~71 ~35 dirt
fill ~0 ~72 ~35 ~0 ~72 ~35 grass_block
fill ~1 ~60 ~35 ~3 ~69 ~35 stone
fill ~1 ~70 ~35 ~3 ~72 ~35 dirt
fill ~1 ~73 ~35 ~3 ~73 ~35 grass_block
fill ~4 ~60 ~35 ~6 ~70 ~35 stone
fill ~4 ~71 ~35 ~6 ~73 ~35 dirt
fill ~4 ~74 ~35 ~6 ~74 ~35 grass_block
fill ~7 ~60 ~35 ~14 ~69 ~35 stone
fill ~7 ~70 ~35 ~14 ~72 ~35 dirt
fill ~7 ~73 ~35 ~14 ~73 ~35 grass_block
fill ~15 ~60 ~35 ~15 ~68 ~35 stone
fill ~15 ~69 ~35 ~15 ~71 ~35 dirt
fill ~15 ~72 ~35 ~15 ~72 ~35 grass_block
fill ~0 ~60 ~36 ~1 ~68 ~36 stone
fill ~0 ~69 ~36 ~1 ~71 ~36 dirt
fill ~0 ~72 ~36 ~1 ~72 ~36 grass_block
fill ~2 ~60 ~36 ~10 ~69 ~36 stone
fill ~2 ~70 ~36 ~10 ~72 ~36 dirt
fill ~2 ~73 ~36 ~10 ~73 ~36 grass_block
fill ~11 ~60 ~36 ~13 ~68 ~36 stone
fill ~11 ~69 ~36 ~13 ~71 ~36 dirt
fill ~11 ~72 ~36 ~13 ~72 ~36 grass_block
fill ~14 ~60 ~36 ~15 ~69 ~36 stone
fill ~14 ~70 ~36 ~15 ~72 ~36 dirt
fill ~14 ~73 ~36 ~15 ~73 ~36 grass_block
fill ~0 ~60 ~37 ~4 ~68 ~37 stone
fill ~0 ~69 ~37 ~4 ~71 ~37 dirt
fill ~0 ~72 ~37 ~4 ~72 ~37 grass_block
fill ~5 ~60 ~37 ~10 ~69 ~37 stone
fill ~5 ~70 ~37 ~10 ~72 ~37 dirt
fill ~5 ~73 ~37 ~10 ~73 ~37 grass_block
fill ~11 ~60 ~37 ~15 ~68 ~37 stone
fill ~11 ~69 ~37 ~15 ~71 ~37 dirt
fill ~11 ~72 ~37 ~15 ~72 ~37 grass_block
fill ~0 ~60 ~38 ~2 ~67 ~38 stone
fill ~0 ~68 ~38 ~2 ~70 ~38 dirt
fill ~0 ~71 ~38 ~2 ~71 ~38 grass_block
fill ~3 ~60 ~38 ~5 ~68 ~38 stone
fill ~3 ~69 ~38 ~5 ~71 ~38 dirt
fill ~3 ~72 ~38 ~5 ~72 ~38 grass_block
fill ~6 ~60 ~38 ~9 ~69 ~38 stone
fill ~6 ~70 ~38 ~9 ~72 ~38 dirt
fill ~6 ~73 ~38 ~9 ~73 ~38 grass_block
fill ~10 ~60 ~38 ~15 ~68 ~38 stone
fill ~10 ~69 ~38 ~15 ~71 ~38 dirt
fill ~10 ~72 ~38 ~15 ~72 ~38 grass_block
fill ~0 ~60 ~39 ~4 ~67 ~39 stone
fill ~0 ~68 ~39 ~4 ~70 ~39 dirt
fill ~0 ~71 ~39 ~4 ~71 ~39 grass_block
fill ~5 ~60 ~39 ~12 ~68 ~39 stone
fill ~5 ~69 ~39 ~12 ~71 ~39 dirt
fill ~5 ~72 ~39 ~12 ~72 ~39 grass_block
fill ~13 ~60 ~39 ~14 ~67 ~39 stone
fill ~13 ~68 ~39 ~14 ~70 ~39 dirt
fill ~13 ~71 ~39 ~14 ~71 ~39 grass_block
fill ~15 ~60 ~39 ~15 ~68 ~39 stone
fill ~15 ~69 ~39 ~15 ~71 ~39 dirt
fill ~15 ~72 ~39 ~15 ~72 ~39 grass_block
fill ~0 ~60 ~40 ~1 ~68 ~40 stone
fill ~0 ~69 ~40 ~1 ~71 ~40 dirt
fill ~0 ~72 ~40 ~1 ~72 ~40 grass_block
fill ~2 ~60 ~40 ~6 ~67 ~40 stone
fill ~2 ~68 ~40 ~6 ~70 ~40 dirt
fill ~2 ~71 ~40 ~6 ~71 ~40 grass_block
fill ~7 ~60 ~40 ~11 ~68 ~40 stone
fill ~7 ~69 ~40 ~11 ~71 ~40 dirt
fill ~7 ~72 ~40 ~11 ~72 ~40 grass_block
fill ~12 ~60 ~40 ~15 ~67 ~40 stone
fill ~12 ~68 ~40 ~15 ~70 ~40 dirt
fill ~12 ~71 ~40 ~15 ~71 ~40 grass_block
fill ~0 ~60 ~41 ~1 ~68 ~41 stone
fill ~0 ~69 ~41 ~1 ~71 ~41 dirt
fill ~0 ~72 ~41 ~1 ~72 ~41 grass_block
fill ~2 ~60 ~41 ~13 ~67 ~41 stone
fill ~2 ~68 ~41 ~13 ~70 ~41 dirt
fill ~2 ~71 ~41 ~13 ~71 ~41 grass_block
fill ~14 ~60 ~41 ~14 ~66 ~41 stone
fill ~14 ~67 ~41 ~14 ~69 ~41 dirt
fill ~14 ~70 ~41 ~14 ~70 ~41 grass_block
fill ~15 ~60 ~41 ~15 ~67 ~41 stone
fill ~15 ~68 ~41 ~15 ~70 ~41 dirt
fill ~15 ~71 ~41 ~15 ~71 ~41 grass_block
fill ~0 ~60 ~42 ~2 ~68 ~42 stone
fill ~0 ~69 ~42 ~2 ~71 ~42 dirt
fill ~0 ~72 ~42 ~2 ~72 ~42 grass_block
fill ~3 ~60 ~42 ~5 ~67 ~42 stone
fill ~3 ~68 ~42 ~5 ~70 ~42 dirt
fill ~3 ~71 ~42 ~5 ~71 ~42 grass_block
fill ~6 ~60 ~42 ~7 ~66 ~42 stone
fill ~6 ~67 ~42 ~7 ~69 ~42 dirt
fill ~6 ~70 ~42 ~7 ~70 ~42 grass_block
fill ~8 ~60 ~42 ~13 ~67 ~42 stone
fill ~8 ~68 ~42 ~13 ~70 ~42 dirt
fill ~8 ~71 ~42 ~13 ~71 ~42 grass_block
fill ~14 ~60 ~42 ~15 ~66 ~42 stone
fill ~14 ~67 ~42 ~15 ~69 ~42 dirt
fill ~14 ~70 ~42 ~15 ~70 ~42 grass_block
fill ~0 ~60 ~43 ~1 ~69 ~43 stone
fill ~0 ~70 ~43 ~1 ~72 ~43 dirt
fill ~0 ~73 ~43 ~1 ~73 ~43 grass_block
fill ~2 ~60 ~43 ~3 ~68 ~43 stone
fill ~2 ~69 ~43 ~3 ~71 ~43 dirt
fill ~2 ~72 ~43 ~3 ~72 ~43 grass_block
fill ~4 ~60 ~43 ~6 ~67 ~43 stone
fill ~4 ~68 ~43 ~6 ~70 ~43 dirt
fill ~4 ~71 ~43 ~6 ~71 ~43 grass_block
fill ~7 ~60 ~43 ~15 ~66 ~43 stone
fill ~7 ~67 ~43 ~15 ~69 ~43 dirt
fill ~7 ~70 ~43 ~15 ~70 ~43 grass_block
fill ~0 ~60 ~44 ~1 ~69 ~44 stone
fill ~0 ~70 ~44 ~1 ~72 ~44 dirt
fill ~0 ~73 ~44 ~1 ~73 ~44 grass_block
fill ~2 ~60 ~44 ~3 ~68 ~44 stone
fill ~2 ~69 ~44 ~3 ~71 ~44 dirt
fill ~2 ~72 ~44 ~3 ~72 ~44 grass_block
fill ~4 ~60 ~44 ~8 ~67 ~44 stone
fill ~4 ~68 ~44 ~8 ~70 ~44 dirt
fill ~4 ~71 ~44 ~8 ~71 ~44 grass_block
fill ~9 ~60 ~44 ~14 ~66 ~44 stone
fill ~9 ~67 ~44 ~14 ~69 ~44 dirt
fill ~9 ~70 ~44 ~14 ~70 ~44 grass_block
fill ~15 ~60 ~44 ~15 ~65 ~44 stone
fill ~15 ~66 ~44 ~15 ~68 ~44 dirt
fill ~15 ~69 ~44 ~15 ~69 ~44 grass_block
fill ~0 ~60 ~45 ~3 ~69 ~45 stone
fill ~0 ~70 ~45 ~3 ~72 ~45 dirt
fill ~0 ~73 ~45 ~3 ~73 ~45 grass_block
fill ~4 ~60 ~45 ~4 ~68 ~45 stone
fill ~4 ~69 ~45 ~4 ~71 ~45 dirt
fill ~4 ~72 ~45 ~4 ~72 ~45 grass_block
fill ~5 ~60 ~45 ~9 ~67 ~45 stone
fill ~5 ~68 ~45 ~9 ~70 ~45 dirt
fill ~5 ~71 ~45 ~9 ~71 ~45 grass_block
fill ~10 ~60 ~45 ~14 ~66 ~45 stone
fill ~10 ~67 ~45 ~14 ~69 ~45 dirt
fill ~10 ~70 ~45 ~14 ~70 ~45 grass_block
fill ~15 ~60 ~45 ~15 ~65 ~45 stone
fill ~15 ~66 ~45 ~15 ~68 ~45 dirt
fill ~15 ~69 ~45 ~15 ~69 ~45 grass_block
fill ~0 ~60 ~46 ~4 ~69 ~46 stone
fill ~0 ~70 ~46 ~4 ~72 ~46 dirt
fill ~0 ~73 ~46 ~4 ~73 ~46 grass_block
fill ~5 ~60 ~46 ~6 ~68 ~46 stone
fill ~5 ~69 ~46 ~6 ~71 ~46 dirt
fill ~5 ~72 ~46 ~6 ~72 ~46 grass_block
fill ~7 ~60 ~46 ~11 ~67 ~46 stone
fill ~7 ~68 ~46 ~11 ~70 ~46 dirt
fill ~7 ~71 ~46 ~11 ~71 ~46 grass_block
fill ~12 ~60 ~46 ~14 ~66 ~46 stone
fill ~12 ~67 ~46 ~14 ~69 ~46 dirt
fill ~12 ~70 ~46 ~14 ~70 ~46 grass_block
fill ~15 ~60 ~46 ~15 ~65 ~46 stone
fill ~15 ~66 ~46 ~15 ~68 ~46 dirt
fill ~15 ~69 ~46 ~15 ~69 ~46 grass_block
fill ~0 ~60 ~47 ~6 ~69 ~47 stone
fill ~0 ~70 ~47 ~6 ~72 ~47 dirt
fill ~0 ~73 ~47 ~6 ~73 ~47 grass_block
fill ~7 ~60 ~47 ~8 ~68 ~47 stone
fill ~7 ~69 ~47 ~8 ~71 ~47 dirt
fill ~7 ~72 ~47 ~8 ~72 ~47 grass_block
fill ~9 ~60 ~47 ~12 ~67 ~47 stone
fill ~9 ~68 ~47 ~12 ~70 ~47 dirt
fill ~9 ~71 ~47 ~12 ~71 ~47 grass_block
fill ~13 ~60 ~47 ~15 ~66 ~47 stone
fill ~13 ~67 ~47 ~15 ~69 ~47 dirt
fill ~13 ~70 ~47 ~15 ~70 ~47 grass_block