fill ~80 ~60 ~80 ~81 ~64 ~80 stone
fill ~80 ~65 ~80 ~81 ~67 ~80 dirt
fill ~80 ~68 ~80 ~81 ~68 ~80 grass_block
fill ~82 ~60 ~80 ~91 ~63 ~80 stone
fill ~82 ~64 ~80 ~91 ~66 ~80 dirt
fill ~82 ~67 ~80 ~91 ~67 ~80 grass_block
fill ~92 ~60 ~80 ~95 ~64 ~80 stone
fill ~92 ~65 ~80 ~95 ~67 ~80 dirt
fill ~92 ~68 ~80 ~95 ~68 ~80 grass_block
fill ~80 ~60 ~81 ~80 ~64 ~81 stone
fill ~80 ~65 ~81 ~80 ~67 ~81 dirt
fill ~80 ~68 ~81 ~80 ~68 ~81 grass_block
fill ~81 ~60 ~81 ~92 ~63 ~81 stone
fill ~81 ~64 ~81 ~92 ~66 ~81 dirt
fill ~81 ~67 ~81 ~92 ~67 ~81 grass_block
fill ~93 ~60 ~81 ~95 ~64 ~81 stone
fill ~93 ~65 ~81 ~95 ~67 ~81 dirt
fill ~93 ~68 ~81 ~95 ~68 ~81 grass_block
fill ~80 ~60 ~82 ~86 ~64 ~82 stone
fill ~80 ~65 ~82 ~86 ~67 ~82 dirt
fill ~80 ~68 ~82 ~86 ~68 ~82 grass_block
fill ~87 ~60 ~82 ~94 ~63 ~82 stone
fill ~87 ~64 ~82 ~94 ~66 ~82 dirt
fill ~87 ~67 ~82 ~94 ~67 ~82 grass_block
fill ~95 ~60 ~82 ~95 ~64 ~82 stone
fill ~95 ~65 ~82 ~95 ~67 ~82 dirt
fill ~95 ~68 ~82 ~95 ~68 ~82 grass_block
fill ~80 ~60 ~83 ~81 ~64 ~83 stone
fill ~80 ~65 ~83 ~81 ~67 ~83 dirt
fill ~80 ~68 ~83 ~81 ~68 ~83 grass_block
fill ~82 ~60 ~83 ~84 ~65 ~83 stone
fill ~82 ~66 ~83 ~84 ~68 ~83 dirt
fill ~82 ~69 ~83 ~84 ~69 ~83 grass_block
fill ~85 ~60 ~83 ~87 ~64 ~83 stone
fill ~85 ~65 ~83 ~87 ~67 ~83 dirt
fill ~85 ~68 ~83 ~87 ~68 ~83 grass_block
fill ~88 ~60 ~83 ~95 ~63 ~83 stone
fill ~88 ~64 ~83 ~95 ~66 ~83 dirt
fill ~88 ~67 ~83 ~95 ~67 ~83 grass_block
fill ~80 ~60 ~84 ~85 ~65 ~84 stone
fill ~80 ~66 ~84 ~85 ~68 ~84 dirt
fill ~80 ~69 ~84 ~85 ~69 ~84 grass_block
fill ~86 ~60 ~84 ~89 ~64 ~84 stone
fill ~86 ~65 ~84 ~89 ~67 ~84 dirt
fill ~86 ~68 ~84 ~89 ~68 ~84 grass_block
fill ~90 ~60 ~84 ~95 ~63 ~84 stone
fill ~90 ~64 ~84 ~95 ~66 ~84 dirt
fill ~90 ~67 ~84 ~95 ~67 ~84 grass_block
fill ~80 ~60 ~85 ~80 ~65 ~85 stone
fill ~80 ~66 ~85 ~80 ~68 ~85 dirt
fill ~80 ~69 ~85 ~80 ~69 ~85 grass_block
fill ~81 ~60 ~85 ~83 ~66 ~85 stone
fill ~81 ~67 ~85 ~83 ~69 ~85 dirt
fill ~81 ~70 ~85 ~83 ~70 ~85 grass_block
fill ~84 ~60 ~85 ~86 ~65 ~85 stone
fill ~84 ~66 ~85 ~86 ~68 ~85 dirt
fill ~84 ~69 ~85 ~86 ~69 ~85 grass_block
fill ~87 ~60 ~85 ~91 ~64 ~85 stone
fill ~87 ~65 ~85 ~91 ~67 ~85 dirt
fill ~87 ~68 ~85 ~91 ~68 ~85 grass_block
fill ~92 ~60 ~85 ~95 ~63 ~85 stone
fill ~92 ~64 ~85 ~95 ~66 ~85 dirt
fill ~92 ~67 ~85 ~95 ~67 ~85 grass_block
fill ~80 ~60 ~86 ~81 ~65 ~86 stone
fill ~80 ~66 ~86 ~81 ~68 ~86 dirt
fill ~80 ~69 ~86 ~81 ~69 ~86 grass_block
fill ~82 ~60 ~86 ~84 ~66 ~86 stone
fill ~82 ~67 ~86 ~84 ~69 ~86 dirt
fill ~82 ~70 ~86 ~84 ~70 ~86 grass_block
fill ~85 ~60 ~86 ~88 ~65 ~86 stone
fill ~85 ~66 ~86 ~88 ~68 ~86 dirt
fill ~85 ~69 ~86 ~88 ~69 ~86 grass_block
fill ~89 ~60 ~86 ~93 ~64 ~86 stone
fill ~89 ~65 ~86 ~93 ~67 ~86 dirt
fill ~89 ~68 ~86 ~93 ~68 ~86 grass_block
fill ~94 ~60 ~86 ~95 ~63 ~86 stone
fill ~94 ~64 ~86 ~95 ~66 ~86 dirt
fill ~94 ~67 ~86 ~95 ~67 ~86 grass_block
fill ~80 ~60 ~87 ~81 ~65 ~87 stone
fill ~80 ~66 ~87 ~81 ~68 ~87 dirt
fill ~80 ~69 ~87 ~81 ~69 ~87 grass_block
fill ~82 ~60 ~87 ~84 ~66 ~87 stone
fill ~82 ~67 ~87 ~84 ~69 ~87 dirt
fill ~82 ~70 ~87 ~84 ~70 ~87 grass_block
fill ~85 ~60 ~87 ~89 ~65 ~87 stone
fill ~85 ~66 ~87 ~89 ~68 ~87 dirt
fill ~85 ~69 ~87 ~89 ~69 ~87 grass_block
fill ~90 ~60 ~87 ~93 ~64 ~87 stone
fill ~90 ~65 ~87 ~93 ~67 ~87 dirt
fill ~90 ~68 ~87 ~93 ~68 ~87 grass_block
fill ~94 ~60 ~87 ~95 ~63 ~87 stone
fill ~94 ~64 ~87 ~95 ~66 ~87 dirt
fill ~94 ~67 ~87 ~95 ~67 ~87 grass_block
fill ~80 ~60 ~88 ~81 ~65 ~88 stone
fill ~80 ~66 ~88 ~81 ~68 ~88 dirt
fill ~80 ~69 ~88 ~81 ~69 ~88 grass_block
fill ~82 ~60 ~88 ~85 ~66 ~88 stone
fill ~82 ~67 ~88 ~85 ~69 ~88 dirt
fill ~82 ~70 ~88 ~85 ~70 ~88 grass_block
fill ~86 ~60 ~88 ~89 ~65 ~88 stone
fill ~86 ~66 ~88 ~89 ~68 ~88 dirt
fill ~86 ~69 ~88 ~89 ~69 ~88 grass_block
fill ~90 ~60 ~88 ~93 ~64 ~88 stone
fill ~90 ~65 ~88 ~93 ~67 ~88 dirt
fill ~90 ~68 ~88 ~93 ~68 ~88 grass_block
fill ~94 ~60 ~88 ~95 ~63 ~88 stone
fill ~94 ~64 ~88 ~95 ~66 ~88 dirt
fill ~94 ~67 ~88 ~95 ~67 ~88 grass_block
fill ~80 ~60 ~89 ~80 ~65 ~89 stone
fill ~80 ~66 ~89 ~80 ~68 ~89 dirt
fill ~80 ~69 ~89 ~80 ~69 ~89 grass_block
fill ~81 ~60 ~89 ~85 ~66 ~89 stone
fill ~81 ~67 ~89 ~85 ~69 ~89 dirt
fill ~81 ~70 ~89 ~85 ~70 ~89 grass_block
fill ~86 ~60 ~89 ~89 ~65 ~89 stone
fill ~86 ~66 ~89 ~89 ~68 ~89 dirt
fill ~86 ~69 ~89 ~89 ~69 ~89 grass_block
fill ~90 ~60 ~89 ~93 ~64 ~89 stone
fill ~90 ~65 ~89 ~93 ~67 ~89 dirt
fill ~90 ~68 ~89 ~93 ~68 ~89 grass_block
fill ~94 ~60 ~89 ~95 ~63 ~89 stone
fill ~94 ~64 ~89 ~95 ~66 ~89 dirt
fill ~94 ~67 ~89 ~95 ~67 ~89 grass_block
fill ~80 ~60 ~90 ~80 ~65 ~90 stone
fill ~80 ~66 ~90 ~80 ~68 ~90 dirt
fill ~80 ~69 ~90 ~80 ~69 ~90 grass_block
fill ~81 ~60 ~90 ~84 ~66 ~90 stone
fill ~81 ~67 ~90 ~84 ~69 ~90 dirt
fill ~81 ~70 ~90 ~84 ~70 ~90 grass_block
fill ~85 ~60 ~90 ~89 ~65 ~90 stone
fill ~85 ~66 ~90 ~89 ~68 ~90 dirt
fill ~85 ~69 ~90 ~89 ~69 ~90 grass_block
fill ~90 ~60 ~90 ~91 ~64 ~90 stone
fill ~90 ~65 ~90 ~91 ~67 ~90 dirt
fill ~90 ~68 ~90 ~91 ~68 ~90 grass_block
fill ~92 ~60 ~90 ~95 ~63 ~90 stone
fill ~92 ~64 ~90 ~95 ~66 ~90 dirt
fill ~92 ~67 ~90 ~95 ~67 ~90 grass_block
fill ~80 ~60 ~91 ~84 ~66 ~91 stone
fill ~80 ~67 ~91 ~84 ~69 ~91 dirt
fill ~80 ~70 ~91 ~84 ~70 ~91 grass_block
fill ~85 ~60 ~91 ~87 ~65 ~91 stone
fill ~85 ~66 ~91 ~87 ~68 ~91 dirt
fill ~85 ~69 ~91 ~87 ~69 ~91 grass_block
fill ~88 ~60 ~91 ~90 ~64 ~91 stone
fill ~88 ~65 ~91 ~90 ~67 ~91 dirt
fill ~88 ~68 ~91 ~90 ~68 ~91 grass_block
fill ~91 ~60 ~91 ~91 ~63 ~91 stone
fill ~91 ~64 ~91 ~91 ~66 ~91 dirt
fill ~91 ~67 ~91 ~91 ~67 ~91 grass_block
fill ~92 ~60 ~91 ~95 ~64 ~91 stone
fill ~92 ~65 ~91 ~95 ~67 ~91 dirt
fill ~92 ~68 ~91 ~95 ~68 ~91 grass_block
fill ~80 ~60 ~92 ~84 ~66 ~92 stone
fill ~80 ~67 ~92 ~84 ~69 ~92 dirt
fill ~80 ~70 ~92 ~84 ~70 ~92 grass_block
fill ~85 ~60 ~92 ~86 ~65 ~92 stone
fill ~85 ~66 ~92 ~86 ~68 ~92 dirt
fill ~85 ~69 ~92 ~86 ~69 ~92 grass_block
fill ~87 ~60 ~92 ~94 ~64 ~92 stone
fill ~87 ~65 ~92 ~94 ~67 ~92 dirt
fill ~87 ~68 ~92 ~94 ~68 ~92 grass_block
fill ~95 ~60 ~92 ~95 ~65 ~92 stone
fill ~95 ~66 ~92 ~95 ~68 ~92 dirt
fill ~95 ~69 ~92 ~95 ~69 ~92 grass_block
fill ~80 ~60 ~93 ~80 ~67 ~93 stone
fill ~80 ~68 ~93 ~80 ~70 ~93 dirt
fill ~80 ~71 ~93 ~80 ~71 ~93 grass_block
fill ~81 ~60 ~93 ~83 ~66 ~93 stone
fill ~81 ~67 ~93 ~83 ~69 ~93 dirt
fill ~81 ~70 ~93 ~83 ~70 ~93 grass_block
fill ~84 ~60 ~93 ~86 ~65 ~93 stone
fill ~84 ~66 ~93 ~86 ~68 ~93 dirt
fill ~84 ~69 ~93 ~86 ~69 ~93 grass_block
fill ~87 ~60 ~93 ~92 ~64 ~93 stone
fill ~87 ~65 ~93 ~92 ~67 ~93 dirt
fill ~87 ~68 ~93 ~92 ~68 ~93 grass_block
fill ~93 ~60 ~93 ~95 ~65 ~93 stone
fill ~93 ~66 ~93 ~95 ~68 ~93 dirt
fill ~93 ~69 ~93 ~95 ~69 ~93 grass_block
fill ~80 ~60 ~94 ~82 ~66 ~94 stone
fill ~80 ~67 ~94 ~82 ~69 ~94 dirt
fill ~80 ~70 ~94 ~82 ~70 ~94 grass_block
fill ~83 ~60 ~94 ~86 ~65 ~94 stone
fill ~83 ~66 ~94 ~86 ~68 ~94 dirt
fill ~83 ~69 ~94 ~86 ~69 ~94 grass_block
fill ~87 ~60 ~94 ~89 ~64 ~94 stone
fill ~87 ~65 ~94 ~89 ~67 ~94 dirt
fill ~87 ~68 ~94 ~89 ~68 ~94 grass_block
fill ~90 ~60 ~94 ~93 ~65 ~94 stone
fill ~90 ~66 ~94 ~93 ~68 ~94 dirt
fill ~90 ~69 ~94 ~93 ~69 ~94 grass_block
fill ~94 ~60 ~94 ~95 ~66 ~94 stone
fill ~94 ~67 ~94 ~95 ~69 ~94 dirt
fill ~94 ~70 ~94 ~95 ~70 ~94 grass_block
fill ~80 ~60 ~95 ~80 ~67 ~95 stone
fill ~80 ~68 ~95 ~80 ~70 ~95 dirt
fill ~80 ~71 ~95 ~80 ~71 ~95 grass_block
fill ~81 ~60 ~95 ~83 ~66 ~95 stone
fill ~81 ~67 ~95 ~83 ~69 ~95 dirt
fill ~81 ~70 ~95 ~83 ~70 ~95 grass_block
fill ~84 ~60 ~95 ~91 ~65 ~95 stone
fill ~84 ~66 ~95 ~91 ~68 ~95 dirt
fill ~84 ~69 ~95 ~91 ~69 ~95 grass_block
fill ~92 ~60 ~95 ~95 ~66 ~95 stone
fill ~92 ~67 ~95 ~95 ~69 ~95 dirt
fill ~92 ~70 ~95 ~95 ~70 ~95 grass_block