fill ~224 ~60 ~16 ~230 ~64 ~16 stone
fill ~224 ~65 ~16 ~230 ~67 ~16 dirt
fill ~224 ~68 ~16 ~230 ~68 ~16 grass_block
fill ~231 ~60 ~16 ~231 ~63 ~16 stone
fill ~231 ~64 ~16 ~231 ~66 ~16 dirt
fill ~231 ~67 ~16 ~231 ~67 ~16 grass_block
fill ~232 ~60 ~16 ~232 ~64 ~16 stone
fill ~232 ~65 ~16 ~232 ~67 ~16 dirt
fill ~232 ~68 ~16 ~232 ~68 ~16 grass_block
fill ~233 ~60 ~16 ~236 ~63 ~16 stone
fill ~233 ~64 ~16 ~236 ~66 ~16 dirt
fill ~233 ~67 ~16 ~236 ~67 ~16 grass_block
fill ~237 ~60 ~16 ~239 ~62 ~16 stone
fill ~237 ~63 ~16 ~239 ~65 ~16 dirt
fill ~237 ~66 ~16 ~239 ~66 ~16 grass_block
fill ~224 ~60 ~17 ~233 ~64 ~17 stone
fill ~224 ~65 ~17 ~233 ~67 ~17 dirt
fill ~224 ~68 ~17 ~233 ~68 ~17 grass_block
fill ~234 ~60 ~17 ~237 ~63 ~17 stone
fill ~234 ~64 ~17 ~237 ~66 ~17 dirt
fill ~234 ~67 ~17 ~237 ~67 ~17 grass_block
fill ~238 ~60 ~17 ~239 ~62 ~17 stone
fill ~238 ~63 ~17 ~239 ~65 ~17 dirt
fill ~238 ~66 ~17 ~239 ~66 ~17 grass_block
fill ~224 ~60 ~18 ~234 ~64 ~18 stone
fill ~224 ~65 ~18 ~234 ~67 ~18 dirt
fill ~224 ~68 ~18 ~234 ~68 ~18 grass_block
fill ~235 ~60 ~18 ~237 ~63 ~18 stone
fill ~235 ~64 ~18 ~237 ~66 ~18 dirt
fill ~235 ~67 ~18 ~237 ~67 ~18 grass_block
fill ~238 ~60 ~18 ~239 ~62 ~18 stone
fill ~238 ~63 ~18 ~239 ~65 ~18 dirt
fill ~238 ~66 ~18 ~239 ~66 ~18 grass_block
fill ~224 ~60 ~19 ~226 ~64 ~19 stone
fill ~224 ~65 ~19 ~226 ~67 ~19 dirt
fill ~224 ~68 ~19 ~226 ~68 ~19 grass_block
fill ~227 ~60 ~19 ~229 ~63 ~19 stone
fill ~227 ~64 ~19 ~229 ~66 ~19 dirt
fill ~227 ~67 ~19 ~229 ~67 ~19 grass_block
fill ~230 ~60 ~19 ~235 ~64 ~19 stone
fill ~230 ~65 ~19 ~235 ~67 ~19 dirt
fill ~230 ~68 ~19 ~235 ~68 ~19 grass_block
fill ~236 ~60 ~19 ~238 ~63 ~19 stone
fill ~236 ~64 ~19 ~238 ~66 ~19 dirt
fill ~236 ~67 ~19 ~238 ~67 ~19 grass_block
fill ~239 ~60 ~19 ~239 ~62 ~19 stone
fill ~239 ~63 ~19 ~239 ~65 ~19 dirt
fill ~239 ~66 ~19 ~239 ~66 ~19 grass_block
fill ~224 ~60 ~20 ~231 ~63 ~20 stone
fill ~224 ~64 ~20 ~231 ~66 ~20 dirt
fill ~224 ~67 ~20 ~231 ~67 ~20 grass_block
fill ~232 ~60 ~20 ~236 ~64 ~20 stone
fill ~232 ~65 ~20 ~236 ~67 ~20 dirt
fill ~232 ~68 ~20 ~236 ~68 ~20 grass_block
fill ~237 ~60 ~20 ~239 ~63 ~20 stone
fill ~237 ~64 ~20 ~239 ~66 ~20 dirt
fill ~237 ~67 ~20 ~239 ~67 ~20 grass_block
fill ~224 ~60 ~21 ~232 ~63 ~21 stone
fill ~224 ~64 ~21 ~232 ~66 ~21 dirt
fill ~224 ~67 ~21 ~232 ~67 ~21 grass_block
fill ~233 ~60 ~21 ~238 ~64 ~21 stone
fill ~233 ~65 ~21 ~238 ~67 ~21 dirt
fill ~233 ~68 ~21 ~238 ~68 ~21 grass_block
fill ~239 ~60 ~21 ~239 ~63 ~21 stone
fill ~239 ~64 ~21 ~239 ~66 ~21 dirt
fill ~239 ~67 ~21 ~239 ~67 ~21 grass_block
fill ~224 ~60 ~22 ~226 ~63 ~22 stone
fill ~224 ~64 ~22 ~226 ~66 ~22 dirt
fill ~224 ~67 ~22 ~226 ~67 ~22 grass_block
fill ~227 ~60 ~22 ~227 ~62 ~22 stone
fill ~227 ~63 ~22 ~227 ~65 ~22 dirt
fill ~227 ~66 ~22 ~227 ~66 ~22 grass_block
fill ~228 ~60 ~22 ~233 ~63 ~22 stone
fill ~228 ~64 ~22 ~233 ~66 ~22 dirt
fill ~228 ~67 ~22 ~233 ~67 ~22 grass_block
fill ~234 ~60 ~22 ~239 ~64 ~22 stone
fill ~234 ~65 ~22 ~239 ~67 ~22 dirt
fill ~234 ~68 ~22 ~239 ~68 ~22 grass_block
fill ~224 ~60 ~23 ~228 ~62 ~23 stone
fill ~224 ~63 ~23 ~228 ~65 ~23 dirt
fill ~224 ~66 ~23 ~228 ~66 ~23 grass_block
fill ~229 ~60 ~23 ~233 ~63 ~23 stone
fill ~229 ~64 ~23 ~233 ~66 ~23 dirt
fill ~229 ~67 ~23 ~233 ~67 ~23 grass_block
fill ~234 ~60 ~23 ~239 ~64 ~23 stone
fill ~234 ~65 ~23 ~239 ~67 ~23 dirt
fill ~234 ~68 ~23 ~239 ~68 ~23 grass_block
fill ~224 ~60 ~24 ~229 ~62 ~24 stone
fill ~224 ~63 ~24 ~229 ~65 ~24 dirt
fill ~224 ~66 ~24 ~229 ~66 ~24 grass_block
fill ~230 ~60 ~24 ~236 ~63 ~24 stone
fill ~230 ~64 ~24 ~236 ~66 ~24 dirt
fill ~230 ~67 ~24 ~236 ~67 ~24 grass_block
fill ~237 ~60 ~24 ~239 ~64 ~24 stone
fill ~237 ~65 ~24 ~239 ~67 ~24 dirt
fill ~237 ~68 ~24 ~239 ~68 ~24 grass_block
fill ~224 ~60 ~25 ~230 ~62 ~25 stone
fill ~224 ~63 ~25 ~230 ~65 ~25 dirt
fill ~224 ~66 ~25 ~230 ~66 ~25 grass_block
fill ~231 ~60 ~25 ~239 ~63 ~25 stone
fill ~231 ~64 ~25 ~239 ~66 ~25 dirt
fill ~231 ~67 ~25 ~239 ~67 ~25 grass_block
fill ~224 ~60 ~26 ~224 ~61 ~26 stone
fill ~224 ~62 ~26 ~224 ~64 ~26 dirt
fill ~224 ~65 ~26 ~224 ~65 ~26 grass_block
fill ~225 ~60 ~26 ~225 ~62 ~26 stone
fill ~225 ~63 ~26 ~225 ~65 ~26 dirt
fill ~225 ~66 ~26 ~225 ~66 ~26 grass_block
fill ~226 ~60 ~26 ~226 ~61 ~26 stone
fill ~226 ~62 ~26 ~226 ~64 ~26 dirt
fill ~226 ~65 ~26 ~226 ~65 ~26 grass_block
fill ~227 ~60 ~26 ~231 ~62 ~26 stone
fill ~227 ~63 ~26 ~231 ~65 ~26 dirt
fill ~227 ~66 ~26 ~231 ~66 ~26 grass_block
fill ~232 ~60 ~26 ~235 ~63 ~26 stone
fill ~232 ~64 ~26 ~235 ~66 ~26 dirt
fill ~232 ~67 ~26 ~235 ~67 ~26 grass_block
fill ~236 ~60 ~26 ~237 ~62 ~26 stone
fill ~236 ~63 ~26 ~237 ~65 ~26 dirt
fill ~236 ~66 ~26 ~237 ~66 ~26 grass_block
fill ~238 ~60 ~26 ~239 ~63 ~26 stone
fill ~238 ~64 ~26 ~239 ~66 ~26 dirt
fill ~238 ~67 ~26 ~239 ~67 ~26 grass_block
fill ~224 ~60 ~27 ~229 ~61 ~27 stone
fill ~224 ~62 ~27 ~229 ~64 ~27 dirt
fill ~224 ~65 ~27 ~229 ~65 ~27 grass_block
fill ~230 ~60 ~27 ~239 ~62 ~27 stone
fill ~230 ~63 ~27 ~239 ~65 ~27 dirt
fill ~230 ~66 ~27 ~239 ~66 ~27 grass_block
fill ~224 ~60 ~28 ~233 ~61 ~28 stone
fill ~224 ~62 ~28 ~233 ~64 ~28 dirt
fill ~224 ~65 ~28 ~233 ~65 ~28 grass_block
fill ~234 ~60 ~28 ~239 ~62 ~28 stone
fill ~234 ~63 ~28 ~239 ~65 ~28 dirt
fill ~234 ~66 ~28 ~239 ~66 ~28 grass_block
fill ~224 ~60 ~29 ~239 ~61 ~29 stone
fill ~224 ~62 ~29 ~239 ~64 ~29 dirt
fill ~224 ~65 ~29 ~239 ~65 ~29 grass_block
fill ~224 ~60 ~30 ~239 ~61 ~30 stone
fill ~224 ~62 ~30 ~239 ~64 ~30 dirt
fill ~224 ~65 ~30 ~239 ~65 ~30 grass_block
fill ~224 ~60 ~31 ~239 ~61 ~31 stone
fill ~224 ~62 ~31 ~239 ~64 ~31 dirt
fill ~224 ~65 ~31 ~239 ~65 ~31 grass_block