fill ~256 ~60 ~112 ~257 ~63 ~112 stone
fill ~256 ~64 ~112 ~257 ~66 ~112 dirt
fill ~256 ~67 ~112 ~257 ~67 ~112 grass_block
fill ~258 ~60 ~112 ~261 ~62 ~112 stone
fill ~258 ~63 ~112 ~261 ~65 ~112 dirt
fill ~258 ~66 ~112 ~261 ~66 ~112 grass_block
fill ~262 ~60 ~112 ~266 ~63 ~112 stone
fill ~262 ~64 ~112 ~266 ~66 ~112 dirt
fill ~262 ~67 ~112 ~266 ~67 ~112 grass_block
fill ~267 ~60 ~112 ~267 ~62 ~112 stone
fill ~267 ~63 ~112 ~267 ~65 ~112 dirt
fill ~267 ~66 ~112 ~267 ~66 ~112 grass_block
fill ~268 ~60 ~112 ~270 ~63 ~112 stone
fill ~268 ~64 ~112 ~270 ~66 ~112 dirt
fill ~268 ~67 ~112 ~270 ~67 ~112 grass_block
fill ~271 ~60 ~112 ~271 ~64 ~112 stone
fill ~271 ~65 ~112 ~271 ~67 ~112 dirt
fill ~271 ~68 ~112 ~271 ~68 ~112 grass_block
fill ~256 ~60 ~113 ~257 ~63 ~113 stone
fill ~256 ~64 ~113 ~257 ~66 ~113 dirt
fill ~256 ~67 ~113 ~257 ~67 ~113 grass_block
fill ~258 ~60 ~113 ~266 ~62 ~113 stone
fill ~258 ~63 ~113 ~266 ~65 ~113 dirt
fill ~258 ~66 ~113 ~266 ~66 ~113 grass_block
fill ~267 ~60 ~113 ~268 ~63 ~113 stone
fill ~267 ~64 ~113 ~268 ~66 ~113 dirt
fill ~267 ~67 ~113 ~268 ~67 ~113 grass_block
fill ~269 ~60 ~113 ~271 ~64 ~113 stone
fill ~269 ~65 ~113 ~271 ~67 ~113 dirt
fill ~269 ~68 ~113 ~271 ~68 ~113 grass_block
fill ~256 ~60 ~114 ~258 ~63 ~114 stone
fill ~256 ~64 ~114 ~258 ~66 ~114 dirt
fill ~256 ~67 ~114 ~258 ~67 ~114 grass_block
fill ~259 ~60 ~114 ~265 ~62 ~114 stone
fill ~259 ~63 ~114 ~265 ~65 ~114 dirt
fill ~259 ~66 ~114 ~265 ~66 ~114 grass_block
fill ~266 ~60 ~114 ~267 ~63 ~114 stone
fill ~266 ~64 ~114 ~267 ~66 ~114 dirt
fill ~266 ~67 ~114 ~267 ~67 ~114 grass_block
fill ~268 ~60 ~114 ~271 ~64 ~114 stone
fill ~268 ~65 ~114 ~271 ~67 ~114 dirt
fill ~268 ~68 ~114 ~271 ~68 ~114 grass_block
fill ~256 ~60 ~115 ~258 ~63 ~115 stone
fill ~256 ~64 ~115 ~258 ~66 ~115 dirt
fill ~256 ~67 ~115 ~258 ~67 ~115 grass_block
fill ~259 ~60 ~115 ~264 ~62 ~115 stone
fill ~259 ~63 ~115 ~264 ~65 ~115 dirt
fill ~259 ~66 ~115 ~264 ~66 ~115 grass_block
fill ~265 ~60 ~115 ~267 ~63 ~115 stone
fill ~265 ~64 ~115 ~267 ~66 ~115 dirt
fill ~265 ~67 ~115 ~267 ~67 ~115 grass_block
fill ~268 ~60 ~115 ~271 ~64 ~115 stone
fill ~268 ~65 ~115 ~271 ~67 ~115 dirt
fill ~268 ~68 ~115 ~271 ~68 ~115 grass_block
fill ~256 ~60 ~116 ~259 ~63 ~116 stone
fill ~256 ~64 ~116 ~259 ~66 ~116 dirt
fill ~256 ~67 ~116 ~259 ~67 ~116 grass_block
fill ~260 ~60 ~116 ~263 ~62 ~116 stone
fill ~260 ~63 ~116 ~263 ~65 ~116 dirt
fill ~260 ~66 ~116 ~263 ~66 ~116 grass_block
fill ~264 ~60 ~116 ~267 ~63 ~116 stone
fill ~264 ~64 ~116 ~267 ~66 ~116 dirt
fill ~264 ~67 ~116 ~267 ~67 ~116 grass_block
fill ~268 ~60 ~116 ~271 ~64 ~116 stone
fill ~268 ~65 ~116 ~271 ~67 ~116 dirt
fill ~268 ~68 ~116 ~271 ~68 ~116 grass_block
fill ~256 ~60 ~117 ~256 ~62 ~117 stone
fill ~256 ~63 ~117 ~256 ~65 ~117 dirt
fill ~256 ~66 ~117 ~256 ~66 ~117 grass_block
fill ~257 ~60 ~117 ~259 ~63 ~117 stone
fill ~257 ~64 ~117 ~259 ~66 ~117 dirt
fill ~257 ~67 ~117 ~259 ~67 ~117 grass_block
fill ~260 ~60 ~117 ~263 ~62 ~117 stone
fill ~260 ~63 ~117 ~263 ~65 ~117 dirt
fill ~260 ~66 ~117 ~263 ~66 ~117 grass_block
fill ~264 ~60 ~117 ~266 ~63 ~117 stone
fill ~264 ~64 ~117 ~266 ~66 ~117 dirt
fill ~264 ~67 ~117 ~266 ~67 ~117 grass_block
fill ~267 ~60 ~117 ~269 ~64 ~117 stone
fill ~267 ~65 ~117 ~269 ~67 ~117 dirt
fill ~267 ~68 ~117 ~269 ~68 ~117 grass_block
fill ~270 ~60 ~117 ~271 ~63 ~117 stone
fill ~270 ~64 ~117 ~271 ~66 ~117 dirt
fill ~270 ~67 ~117 ~271 ~67 ~117 grass_block
fill ~256 ~60 ~118 ~256 ~62 ~118 stone
fill ~256 ~63 ~118 ~256 ~65 ~118 dirt
fill ~256 ~66 ~118 ~256 ~66 ~118 grass_block
fill ~257 ~60 ~118 ~260 ~63 ~118 stone
fill ~257 ~64 ~118 ~260 ~66 ~118 dirt
fill ~257 ~67 ~118 ~260 ~67 ~118 grass_block
fill ~261 ~60 ~118 ~263 ~62 ~118 stone
fill ~261 ~63 ~118 ~263 ~65 ~118 dirt
fill ~261 ~66 ~118 ~263 ~66 ~118 grass_block
fill ~264 ~60 ~118 ~267 ~63 ~118 stone
fill ~264 ~64 ~118 ~267 ~66 ~118 dirt
fill ~264 ~67 ~118 ~267 ~67 ~118 grass_block
fill ~268 ~60 ~118 ~268 ~64 ~118 stone
fill ~268 ~65 ~118 ~268 ~67 ~118 dirt
fill ~268 ~68 ~118 ~268 ~68 ~118 grass_block
fill ~269 ~60 ~118 ~271 ~63 ~118 stone
fill ~269 ~64 ~118 ~271 ~66 ~118 dirt
fill ~269 ~67 ~118 ~271 ~67 ~118 grass_block
fill ~256 ~60 ~119 ~258 ~62 ~119 stone
fill ~256 ~63 ~119 ~258 ~65 ~119 dirt
fill ~256 ~66 ~119 ~258 ~66 ~119 grass_block
fill ~259 ~60 ~119 ~260 ~63 ~119 stone
fill ~259 ~64 ~119 ~260 ~66 ~119 dirt
fill ~259 ~67 ~119 ~260 ~67 ~119 grass_block
fill ~261 ~60 ~119 ~264 ~62 ~119 stone
fill ~261 ~63 ~119 ~264 ~65 ~119 dirt
fill ~261 ~66 ~119 ~264 ~66 ~119 grass_block
fill ~265 ~60 ~119 ~271 ~63 ~119 stone
fill ~265 ~64 ~119 ~271 ~66 ~119 dirt
fill ~265 ~67 ~119 ~271 ~67 ~119 grass_block
fill ~256 ~60 ~120 ~259 ~62 ~120 stone
fill ~256 ~63 ~120 ~259 ~65 ~120 dirt
fill ~256 ~66 ~120 ~259 ~66 ~120 grass_block
fill ~260 ~60 ~120 ~260 ~63 ~120 stone
fill ~260 ~64 ~120 ~260 ~66 ~120 dirt
fill ~260 ~67 ~120 ~260 ~67 ~120 grass_block
fill ~261 ~60 ~120 ~265 ~62 ~120 stone
fill ~261 ~63 ~120 ~265 ~65 ~120 dirt
fill ~261 ~66 ~120 ~265 ~66 ~120 grass_block
fill ~266 ~60 ~120 ~271 ~63 ~120 stone
fill ~266 ~64 ~120 ~271 ~66 ~120 dirt
fill ~266 ~67 ~120 ~271 ~67 ~120 grass_block
fill ~256 ~60 ~121 ~256 ~63 ~121 stone
fill ~256 ~64 ~121 ~256 ~66 ~121 dirt
fill ~256 ~67 ~121 ~256 ~67 ~121 grass_block
fill ~257 ~60 ~121 ~265 ~62 ~121 stone
fill ~257 ~63 ~121 ~265 ~65 ~121 dirt
fill ~257 ~66 ~121 ~265 ~66 ~121 grass_block
fill ~266 ~60 ~121 ~270 ~63 ~121 stone
fill ~266 ~64 ~121 ~270 ~66 ~121 dirt
fill ~266 ~67 ~121 ~270 ~67 ~121 grass_block
fill ~271 ~60 ~121 ~271 ~62 ~121 stone
fill ~271 ~63 ~121 ~271 ~65 ~121 dirt
fill ~271 ~66 ~121 ~271 ~66 ~121 grass_block
fill ~256 ~60 ~122 ~256 ~63 ~122 stone
fill ~256 ~64 ~122 ~256 ~66 ~122 dirt
fill ~256 ~67 ~122 ~256 ~67 ~122 grass_block
fill ~257 ~60 ~122 ~266 ~62 ~122 stone
fill ~257 ~63 ~122 ~266 ~65 ~122 dirt
fill ~257 ~66 ~122 ~266 ~66 ~122 grass_block
fill ~267 ~60 ~122 ~270 ~63 ~122 stone
fill ~267 ~64 ~122 ~270 ~66 ~122 dirt
fill ~267 ~67 ~122 ~270 ~67 ~122 grass_block
fill ~271 ~60 ~122 ~271 ~62 ~122 stone
fill ~271 ~63 ~122 ~271 ~65 ~122 dirt
fill ~271 ~66 ~122 ~271 ~66 ~122 grass_block
fill ~256 ~60 ~123 ~257 ~63 ~123 stone
fill ~256 ~64 ~123 ~257 ~66 ~123 dirt
fill ~256 ~67 ~123 ~257 ~67 ~123 grass_block
fill ~258 ~60 ~123 ~266 ~62 ~123 stone
fill ~258 ~63 ~123 ~266 ~65 ~123 dirt
fill ~258 ~66 ~123 ~266 ~66 ~123 grass_block
fill ~267 ~60 ~123 ~269 ~63 ~123 stone
fill ~267 ~64 ~123 ~269 ~66 ~123 dirt
fill ~267 ~67 ~123 ~269 ~67 ~123 grass_block
fill ~270 ~60 ~123 ~271 ~62 ~123 stone
fill ~270 ~63 ~123 ~271 ~65 ~123 dirt
fill ~270 ~66 ~123 ~271 ~66 ~123 grass_block
fill ~256 ~60 ~124 ~258 ~63 ~124 stone
fill ~256 ~64 ~124 ~258 ~66 ~124 dirt
fill ~256 ~67 ~124 ~258 ~67 ~124 grass_block
fill ~259 ~60 ~124 ~266 ~62 ~124 stone
fill ~259 ~63 ~124 ~266 ~65 ~124 dirt
fill ~259 ~66 ~124 ~266 ~66 ~124 grass_block
fill ~267 ~60 ~124 ~269 ~63 ~124 stone
fill ~267 ~64 ~124 ~269 ~66 ~124 dirt
fill ~267 ~67 ~124 ~269 ~67 ~124 grass_block
fill ~270 ~60 ~124 ~271 ~62 ~124 stone
fill ~270 ~63 ~124 ~271 ~65 ~124 dirt
fill ~270 ~66 ~124 ~271 ~66 ~124 grass_block
fill ~256 ~60 ~125 ~259 ~63 ~125 stone
fill ~256 ~64 ~125 ~259 ~66 ~125 dirt
fill ~256 ~67 ~125 ~259 ~67 ~125 grass_block
fill ~260 ~60 ~125 ~267 ~62 ~125 stone
fill ~260 ~63 ~125 ~267 ~65 ~125 dirt
fill ~260 ~66 ~125 ~267 ~66 ~125 grass_block
fill ~268 ~60 ~125 ~268 ~63 ~125 stone
fill ~268 ~64 ~125 ~268 ~66 ~125 dirt
fill ~268 ~67 ~125 ~268 ~67 ~125 grass_block
fill ~269 ~60 ~125 ~271 ~62 ~125 stone
fill ~269 ~63 ~125 ~271 ~65 ~125 dirt
fill ~269 ~66 ~125 ~271 ~66 ~125 grass_block
fill ~256 ~60 ~126 ~257 ~64 ~126 stone
fill ~256 ~65 ~126 ~257 ~67 ~126 dirt
fill ~256 ~68 ~126 ~257 ~68 ~126 grass_block
fill ~258 ~60 ~126 ~260 ~63 ~126 stone
fill ~258 ~64 ~126 ~260 ~66 ~126 dirt
fill ~258 ~67 ~126 ~260 ~67 ~126 grass_block
fill ~261 ~60 ~126 ~271 ~62 ~126 stone
fill ~261 ~63 ~126 ~271 ~65 ~126 dirt
fill ~261 ~66 ~126 ~271 ~66 ~126 grass_block
fill ~256 ~60 ~127 ~258 ~64 ~127 stone
fill ~256 ~65 ~127 ~258 ~67 ~127 dirt
fill ~256 ~68 ~127 ~258 ~68 ~127 grass_block
fill ~259 ~60 ~127 ~261 ~63 ~127 stone
fill ~259 ~64 ~127 ~261 ~66 ~127 dirt
fill ~259 ~67 ~127 ~261 ~67 ~127 grass_block
fill ~262 ~60 ~127 ~271 ~62 ~127 stone
fill ~262 ~63 ~127 ~271 ~65 ~127 dirt
fill ~262 ~66 ~127 ~271 ~66 ~127 grass_block