fill ~400 ~60 ~112 ~405 ~63 ~112 stone
fill ~400 ~64 ~112 ~405 ~66 ~112 dirt
fill ~400 ~67 ~112 ~405 ~67 ~112 grass_block
fill ~406 ~60 ~112 ~414 ~64 ~112 stone
fill ~406 ~65 ~112 ~414 ~67 ~112 dirt
fill ~406 ~68 ~112 ~414 ~68 ~112 grass_block
fill ~415 ~60 ~112 ~415 ~63 ~112 stone
fill ~415 ~64 ~112 ~415 ~66 ~112 dirt
fill ~415 ~67 ~112 ~415 ~67 ~112 grass_block
fill ~400 ~60 ~113 ~404 ~63 ~113 stone
fill ~400 ~64 ~113 ~404 ~66 ~113 dirt
fill ~400 ~67 ~113 ~404 ~67 ~113 grass_block
fill ~405 ~60 ~113 ~414 ~64 ~113 stone
fill ~405 ~65 ~113 ~414 ~67 ~113 dirt
fill ~405 ~68 ~113 ~414 ~68 ~113 grass_block
fill ~415 ~60 ~113 ~415 ~63 ~113 stone
fill ~415 ~64 ~113 ~415 ~66 ~113 dirt
fill ~415 ~67 ~113 ~415 ~67 ~113 grass_block
fill ~400 ~60 ~114 ~413 ~64 ~114 stone
fill ~400 ~65 ~114 ~413 ~67 ~114 dirt
fill ~400 ~68 ~114 ~413 ~68 ~114 grass_block
fill ~414 ~60 ~114 ~415 ~63 ~114 stone
fill ~414 ~64 ~114 ~415 ~66 ~114 dirt
fill ~414 ~67 ~114 ~415 ~67 ~114 grass_block
fill ~400 ~60 ~115 ~413 ~64 ~115 stone
fill ~400 ~65 ~115 ~413 ~67 ~115 dirt
fill ~400 ~68 ~115 ~413 ~68 ~115 grass_block
fill ~414 ~60 ~115 ~415 ~63 ~115 stone
fill ~414 ~64 ~115 ~415 ~66 ~115 dirt
fill ~414 ~67 ~115 ~415 ~67 ~115 grass_block
fill ~400 ~60 ~116 ~414 ~64 ~116 stone
fill ~400 ~65 ~116 ~414 ~67 ~116 dirt
fill ~400 ~68 ~116 ~414 ~68 ~116 grass_block
fill ~415 ~60 ~116 ~415 ~63 ~116 stone
fill ~415 ~64 ~116 ~415 ~66 ~116 dirt
fill ~415 ~67 ~116 ~415 ~67 ~116 grass_block
fill ~400 ~60 ~117 ~414 ~64 ~117 stone
fill ~400 ~65 ~117 ~414 ~67 ~117 dirt
fill ~400 ~68 ~117 ~414 ~68 ~117 grass_block
fill ~415 ~60 ~117 ~415 ~63 ~117 stone
fill ~415 ~64 ~117 ~415 ~66 ~117 dirt
fill ~415 ~67 ~117 ~415 ~67 ~117 grass_block
fill ~400 ~60 ~118 ~400 ~63 ~118 stone
fill ~400 ~64 ~118 ~400 ~66 ~118 dirt
fill ~400 ~67 ~118 ~400 ~67 ~118 grass_block
fill ~401 ~60 ~118 ~406 ~64 ~118 stone
fill ~401 ~65 ~118 ~406 ~67 ~118 dirt
fill ~401 ~68 ~118 ~406 ~68 ~118 grass_block
fill ~407 ~60 ~118 ~407 ~65 ~118 stone
fill ~407 ~66 ~118 ~407 ~68 ~118 dirt
fill ~407 ~69 ~118 ~407 ~69 ~118 grass_block
fill ~408 ~60 ~118 ~408 ~64 ~118 stone
fill ~408 ~65 ~118 ~408 ~67 ~118 dirt
fill ~408 ~68 ~118 ~408 ~68 ~118 grass_block
fill ~409 ~60 ~118 ~409 ~65 ~118 stone
fill ~409 ~66 ~118 ~409 ~68 ~118 dirt
fill ~409 ~69 ~118 ~409 ~69 ~118 grass_block
fill ~410 ~60 ~118 ~414 ~64 ~118 stone
fill ~410 ~65 ~118 ~414 ~67 ~118 dirt
fill ~410 ~68 ~118 ~414 ~68 ~118 grass_block
fill ~415 ~60 ~118 ~415 ~63 ~118 stone
fill ~415 ~64 ~118 ~415 ~66 ~118 dirt
fill ~415 ~67 ~118 ~415 ~67 ~118 grass_block
fill ~400 ~60 ~119 ~400 ~63 ~119 stone
fill ~400 ~64 ~119 ~400 ~66 ~119 dirt
fill ~400 ~67 ~119 ~400 ~67 ~119 grass_block
fill ~401 ~60 ~119 ~406 ~64 ~119 stone
fill ~401 ~65 ~119 ~406 ~67 ~119 dirt
fill ~401 ~68 ~119 ~406 ~68 ~119 grass_block
fill ~407 ~60 ~119 ~410 ~65 ~119 stone
fill ~407 ~66 ~119 ~410 ~68 ~119 dirt
fill ~407 ~69 ~119 ~410 ~69 ~119 grass_block
fill ~411 ~60 ~119 ~415 ~64 ~119 stone
fill ~411 ~65 ~119 ~415 ~67 ~119 dirt
fill ~411 ~68 ~119 ~415 ~68 ~119 grass_block
fill ~400 ~60 ~120 ~401 ~63 ~120 stone
fill ~400 ~64 ~120 ~401 ~66 ~120 dirt
fill ~400 ~67 ~120 ~401 ~67 ~120 grass_block
fill ~402 ~60 ~120 ~407 ~64 ~120 stone
fill ~402 ~65 ~120 ~407 ~67 ~120 dirt
fill ~402 ~68 ~120 ~407 ~68 ~120 grass_block
fill ~408 ~60 ~120 ~410 ~65 ~120 stone
fill ~408 ~66 ~120 ~410 ~68 ~120 dirt
fill ~408 ~69 ~120 ~410 ~69 ~120 grass_block
fill ~411 ~60 ~120 ~415 ~64 ~120 stone
fill ~411 ~65 ~120 ~415 ~67 ~120 dirt
fill ~411 ~68 ~120 ~415 ~68 ~120 grass_block
fill ~400 ~60 ~121 ~403 ~63 ~121 stone
fill ~400 ~64 ~121 ~403 ~66 ~121 dirt
fill ~400 ~67 ~121 ~403 ~67 ~121 grass_block
fill ~404 ~60 ~121 ~415 ~64 ~121 stone
fill ~404 ~65 ~121 ~415 ~67 ~121 dirt
fill ~404 ~68 ~121 ~415 ~68 ~121 grass_block
fill ~400 ~60 ~122 ~403 ~63 ~122 stone
fill ~400 ~64 ~122 ~403 ~66 ~122 dirt
fill ~400 ~67 ~122 ~403 ~67 ~122 grass_block
fill ~404 ~60 ~122 ~415 ~64 ~122 stone
fill ~404 ~65 ~122 ~415 ~67 ~122 dirt
fill ~404 ~68 ~122 ~415 ~68 ~122 grass_block
fill ~400 ~60 ~123 ~415 ~64 ~123 stone
fill ~400 ~65 ~123 ~415 ~67 ~123 dirt
fill ~400 ~68 ~123 ~415 ~68 ~123 grass_block
fill ~400 ~60 ~124 ~403 ~64 ~124 stone
fill ~400 ~65 ~124 ~403 ~67 ~124 dirt
fill ~400 ~68 ~124 ~403 ~68 ~124 grass_block
fill ~404 ~60 ~124 ~404 ~63 ~124 stone
fill ~404 ~64 ~124 ~404 ~66 ~124 dirt
fill ~404 ~67 ~124 ~404 ~67 ~124 grass_block
fill ~405 ~60 ~124 ~408 ~64 ~124 stone
fill ~405 ~65 ~124 ~408 ~67 ~124 dirt
fill ~405 ~68 ~124 ~408 ~68 ~124 grass_block
fill ~409 ~60 ~124 ~411 ~63 ~124 stone
fill ~409 ~64 ~124 ~411 ~66 ~124 dirt
fill ~409 ~67 ~124 ~411 ~67 ~124 grass_block
fill ~412 ~60 ~124 ~415 ~64 ~124 stone
fill ~412 ~65 ~124 ~415 ~67 ~124 dirt
fill ~412 ~68 ~124 ~415 ~68 ~124 grass_block
fill ~400 ~60 ~125 ~403 ~64 ~125 stone
fill ~400 ~65 ~125 ~403 ~67 ~125 dirt
fill ~400 ~68 ~125 ~403 ~68 ~125 grass_block
fill ~404 ~60 ~125 ~413 ~63 ~125 stone
fill ~404 ~64 ~125 ~413 ~66 ~125 dirt
fill ~404 ~67 ~125 ~413 ~67 ~125 grass_block
fill ~414 ~60 ~125 ~415 ~64 ~125 stone
fill ~414 ~65 ~125 ~415 ~67 ~125 dirt
fill ~414 ~68 ~125 ~415 ~68 ~125 grass_block
fill ~400 ~60 ~126 ~402 ~64 ~126 stone
fill ~400 ~65 ~126 ~402 ~67 ~126 dirt
fill ~400 ~68 ~126 ~402 ~68 ~126 grass_block
fill ~403 ~60 ~126 ~410 ~63 ~126 stone
fill ~403 ~64 ~126 ~410 ~66 ~126 dirt
fill ~403 ~67 ~126 ~410 ~67 ~126 grass_block
fill ~411 ~60 ~126 ~411 ~62 ~126 stone
fill ~411 ~63 ~126 ~411 ~65 ~126 dirt
fill ~411 ~66 ~126 ~411 ~66 ~126 grass_block
fill ~412 ~60 ~126 ~413 ~63 ~126 stone
fill ~412 ~64 ~126 ~413 ~66 ~126 dirt
fill ~412 ~67 ~126 ~413 ~67 ~126 grass_block
fill ~414 ~60 ~126 ~415 ~64 ~126 stone
fill ~414 ~65 ~126 ~415 ~67 ~126 dirt
fill ~414 ~68 ~126 ~415 ~68 ~126 grass_block
fill ~400 ~60 ~127 ~402 ~64 ~127 stone
fill ~400 ~65 ~127 ~402 ~67 ~127 dirt
fill ~400 ~68 ~127 ~402 ~68 ~127 grass_block
fill ~403 ~60 ~127 ~408 ~63 ~127 stone
fill ~403 ~64 ~127 ~408 ~66 ~127 dirt
fill ~403 ~67 ~127 ~408 ~67 ~127 grass_block
fill ~409 ~60 ~127 ~411 ~62 ~127 stone
fill ~409 ~63 ~127 ~411 ~65 ~127 dirt
fill ~409 ~66 ~127 ~411 ~66 ~127 grass_block
fill ~412 ~60 ~127 ~414 ~63 ~127 stone
fill ~412 ~64 ~127 ~414 ~66 ~127 dirt
fill ~412 ~67 ~127 ~414 ~67 ~127 grass_block
fill ~415 ~60 ~127 ~415 ~64 ~127 stone
fill ~415 ~65 ~127 ~415 ~67 ~127 dirt
fill ~415 ~68 ~127 ~415 ~68 ~127 grass_block