fill ~400 ~60 ~64 ~401 ~63 ~64 stone
fill ~400 ~64 ~64 ~401 ~66 ~64 dirt
fill ~400 ~67 ~64 ~401 ~67 ~64 grass_block
fill ~402 ~60 ~64 ~407 ~62 ~64 stone
fill ~402 ~63 ~64 ~407 ~65 ~64 dirt
fill ~402 ~66 ~64 ~407 ~66 ~64 grass_block
fill ~408 ~60 ~64 ~410 ~63 ~64 stone
fill ~408 ~64 ~64 ~410 ~66 ~64 dirt
fill ~408 ~67 ~64 ~410 ~67 ~64 grass_block
fill ~411 ~60 ~64 ~412 ~64 ~64 stone
fill ~411 ~65 ~64 ~412 ~67 ~64 dirt
fill ~411 ~68 ~64 ~412 ~68 ~64 grass_block
fill ~413 ~60 ~64 ~415 ~65 ~64 stone
fill ~413 ~66 ~64 ~415 ~68 ~64 dirt
fill ~413 ~69 ~64 ~415 ~69 ~64 grass_block
fill ~400 ~60 ~65 ~401 ~63 ~65 stone
fill ~400 ~64 ~65 ~401 ~66 ~65 dirt
fill ~400 ~67 ~65 ~401 ~67 ~65 grass_block
fill ~402 ~60 ~65 ~406 ~62 ~65 stone
fill ~402 ~63 ~65 ~406 ~65 ~65 dirt
fill ~402 ~66 ~65 ~406 ~66 ~65 grass_block
fill ~407 ~60 ~65 ~410 ~63 ~65 stone
fill ~407 ~64 ~65 ~410 ~66 ~65 dirt
fill ~407 ~67 ~65 ~410 ~67 ~65 grass_block
fill ~411 ~60 ~65 ~413 ~64 ~65 stone
fill ~411 ~65 ~65 ~413 ~67 ~65 dirt
fill ~411 ~68 ~65 ~413 ~68 ~65 grass_block
fill ~414 ~60 ~65 ~415 ~65 ~65 stone
fill ~414 ~66 ~65 ~415 ~68 ~65 dirt
fill ~414 ~69 ~65 ~415 ~69 ~65 grass_block
fill ~400 ~60 ~66 ~401 ~63 ~66 stone
fill ~400 ~64 ~66 ~401 ~66 ~66 dirt
fill ~400 ~67 ~66 ~401 ~67 ~66 grass_block
fill ~402 ~60 ~66 ~405 ~62 ~66 stone
fill ~402 ~63 ~66 ~405 ~65 ~66 dirt
fill ~402 ~66 ~66 ~405 ~66 ~66 grass_block
fill ~406 ~60 ~66 ~406 ~63 ~66 stone
fill ~406 ~64 ~66 ~406 ~66 ~66 dirt
fill ~406 ~67 ~66 ~406 ~67 ~66 grass_block
fill ~407 ~60 ~66 ~407 ~64 ~66 stone
fill ~407 ~65 ~66 ~407 ~67 ~66 dirt
fill ~407 ~68 ~66 ~407 ~68 ~66 grass_block
fill ~408 ~60 ~66 ~408 ~63 ~66 stone
fill ~408 ~64 ~66 ~408 ~66 ~66 dirt
fill ~408 ~67 ~66 ~408 ~67 ~66 grass_block
fill ~409 ~60 ~66 ~414 ~64 ~66 stone
fill ~409 ~65 ~66 ~414 ~67 ~66 dirt
fill ~409 ~68 ~66 ~414 ~68 ~66 grass_block
fill ~415 ~60 ~66 ~415 ~65 ~66 stone
fill ~415 ~66 ~66 ~415 ~68 ~66 dirt
fill ~415 ~69 ~66 ~415 ~69 ~66 grass_block
fill ~400 ~60 ~67 ~400 ~63 ~67 stone
fill ~400 ~64 ~67 ~400 ~66 ~67 dirt
fill ~400 ~67 ~67 ~400 ~67 ~67 grass_block
fill ~401 ~60 ~67 ~405 ~62 ~67 stone
fill ~401 ~63 ~67 ~405 ~65 ~67 dirt
fill ~401 ~66 ~67 ~405 ~66 ~67 grass_block
fill ~406 ~60 ~67 ~406 ~63 ~67 stone
fill ~406 ~64 ~67 ~406 ~66 ~67 dirt
fill ~406 ~67 ~67 ~406 ~67 ~67 grass_block
fill ~407 ~60 ~67 ~415 ~64 ~67 stone
fill ~407 ~65 ~67 ~415 ~67 ~67 dirt
fill ~407 ~68 ~67 ~415 ~68 ~67 grass_block
fill ~400 ~60 ~68 ~400 ~63 ~68 stone
fill ~400 ~64 ~68 ~400 ~66 ~68 dirt
fill ~400 ~67 ~68 ~400 ~67 ~68 grass_block
fill ~401 ~60 ~68 ~405 ~62 ~68 stone
fill ~401 ~63 ~68 ~405 ~65 ~68 dirt
fill ~401 ~66 ~68 ~405 ~66 ~68 grass_block
fill ~406 ~60 ~68 ~406 ~63 ~68 stone
fill ~406 ~64 ~68 ~406 ~66 ~68 dirt
fill ~406 ~67 ~68 ~406 ~67 ~68 grass_block
fill ~407 ~60 ~68 ~415 ~64 ~68 stone
fill ~407 ~65 ~68 ~415 ~67 ~68 dirt
fill ~407 ~68 ~68 ~415 ~68 ~68 grass_block
fill ~400 ~60 ~69 ~405 ~62 ~69 stone
fill ~400 ~63 ~69 ~405 ~65 ~69 dirt
fill ~400 ~66 ~69 ~405 ~66 ~69 grass_block
fill ~406 ~60 ~69 ~407 ~63 ~69 stone
fill ~406 ~64 ~69 ~407 ~66 ~69 dirt
fill ~406 ~67 ~69 ~407 ~67 ~69 grass_block
fill ~408 ~60 ~69 ~415 ~64 ~69 stone
fill ~408 ~65 ~69 ~415 ~67 ~69 dirt
fill ~408 ~68 ~69 ~415 ~68 ~69 grass_block
fill ~400 ~60 ~70 ~405 ~62 ~70 stone
fill ~400 ~63 ~70 ~405 ~65 ~70 dirt
fill ~400 ~66 ~70 ~405 ~66 ~70 grass_block
fill ~406 ~60 ~70 ~408 ~63 ~70 stone
fill ~406 ~64 ~70 ~408 ~66 ~70 dirt
fill ~406 ~67 ~70 ~408 ~67 ~70 grass_block
fill ~409 ~60 ~70 ~415 ~64 ~70 stone
fill ~409 ~65 ~70 ~415 ~67 ~70 dirt
fill ~409 ~68 ~70 ~415 ~68 ~70 grass_block
fill ~400 ~60 ~71 ~405 ~62 ~71 stone
fill ~400 ~63 ~71 ~405 ~65 ~71 dirt
fill ~400 ~66 ~71 ~405 ~66 ~71 grass_block
fill ~406 ~60 ~71 ~407 ~63 ~71 stone
fill ~406 ~64 ~71 ~407 ~66 ~71 dirt
fill ~406 ~67 ~71 ~407 ~67 ~71 grass_block
fill ~408 ~60 ~71 ~415 ~64 ~71 stone
fill ~408 ~65 ~71 ~415 ~67 ~71 dirt
fill ~408 ~68 ~71 ~415 ~68 ~71 grass_block
fill ~400 ~60 ~72 ~406 ~62 ~72 stone
fill ~400 ~63 ~72 ~406 ~65 ~72 dirt
fill ~400 ~66 ~72 ~406 ~66 ~72 grass_block
fill ~407 ~60 ~72 ~407 ~63 ~72 stone
fill ~407 ~64 ~72 ~407 ~66 ~72 dirt
fill ~407 ~67 ~72 ~407 ~67 ~72 grass_block
fill ~408 ~60 ~72 ~415 ~64 ~72 stone
fill ~408 ~65 ~72 ~415 ~67 ~72 dirt
fill ~408 ~68 ~72 ~415 ~68 ~72 grass_block
fill ~400 ~60 ~73 ~405 ~62 ~73 stone
fill ~400 ~63 ~73 ~405 ~65 ~73 dirt
fill ~400 ~66 ~73 ~405 ~66 ~73 grass_block
fill ~406 ~60 ~73 ~408 ~63 ~73 stone
fill ~406 ~64 ~73 ~408 ~66 ~73 dirt
fill ~406 ~67 ~73 ~408 ~67 ~73 grass_block
fill ~409 ~60 ~73 ~415 ~64 ~73 stone
fill ~409 ~65 ~73 ~415 ~67 ~73 dirt
fill ~409 ~68 ~73 ~415 ~68 ~73 grass_block
fill ~400 ~60 ~74 ~406 ~62 ~74 stone
fill ~400 ~63 ~74 ~406 ~65 ~74 dirt
fill ~400 ~66 ~74 ~406 ~66 ~74 grass_block
fill ~407 ~60 ~74 ~409 ~63 ~74 stone
fill ~407 ~64 ~74 ~409 ~66 ~74 dirt
fill ~407 ~67 ~74 ~409 ~67 ~74 grass_block
fill ~410 ~60 ~74 ~415 ~64 ~74 stone
fill ~410 ~65 ~74 ~415 ~67 ~74 dirt
fill ~410 ~68 ~74 ~415 ~68 ~74 grass_block
fill ~400 ~60 ~75 ~400 ~63 ~75 stone
fill ~400 ~64 ~75 ~400 ~66 ~75 dirt
fill ~400 ~67 ~75 ~400 ~67 ~75 grass_block
fill ~401 ~60 ~75 ~408 ~62 ~75 stone
fill ~401 ~63 ~75 ~408 ~65 ~75 dirt
fill ~401 ~66 ~75 ~408 ~66 ~75 grass_block
fill ~409 ~60 ~75 ~411 ~63 ~75 stone
fill ~409 ~64 ~75 ~411 ~66 ~75 dirt
fill ~409 ~67 ~75 ~411 ~67 ~75 grass_block
fill ~412 ~60 ~75 ~413 ~64 ~75 stone
fill ~412 ~65 ~75 ~413 ~67 ~75 dirt
fill ~412 ~68 ~75 ~413 ~68 ~75 grass_block
fill ~414 ~60 ~75 ~415 ~63 ~75 stone
fill ~414 ~64 ~75 ~415 ~66 ~75 dirt
fill ~414 ~67 ~75 ~415 ~67 ~75 grass_block
fill ~400 ~60 ~76 ~402 ~63 ~76 stone
fill ~400 ~64 ~76 ~402 ~66 ~76 dirt
fill ~400 ~67 ~76 ~402 ~67 ~76 grass_block
fill ~403 ~60 ~76 ~409 ~62 ~76 stone
fill ~403 ~63 ~76 ~409 ~65 ~76 dirt
fill ~403 ~66 ~76 ~409 ~66 ~76 grass_block
fill ~410 ~60 ~76 ~415 ~63 ~76 stone
fill ~410 ~64 ~76 ~415 ~66 ~76 dirt
fill ~410 ~67 ~76 ~415 ~67 ~76 grass_block
fill ~400 ~60 ~77 ~403 ~63 ~77 stone
fill ~400 ~64 ~77 ~403 ~66 ~77 dirt
fill ~400 ~67 ~77 ~403 ~67 ~77 grass_block
fill ~404 ~60 ~77 ~409 ~62 ~77 stone
fill ~404 ~63 ~77 ~409 ~65 ~77 dirt
fill ~404 ~66 ~77 ~409 ~66 ~77 grass_block
fill ~410 ~60 ~77 ~415 ~63 ~77 stone
fill ~410 ~64 ~77 ~415 ~66 ~77 dirt
fill ~410 ~67 ~77 ~415 ~67 ~77 grass_block
fill ~400 ~60 ~78 ~403 ~63 ~78 stone
fill ~400 ~64 ~78 ~403 ~66 ~78 dirt
fill ~400 ~67 ~78 ~403 ~67 ~78 grass_block
fill ~404 ~60 ~78 ~406 ~62 ~78 stone
fill ~404 ~63 ~78 ~406 ~65 ~78 dirt
fill ~404 ~66 ~78 ~406 ~66 ~78 grass_block
fill ~407 ~60 ~78 ~407 ~61 ~78 stone
fill ~407 ~62 ~78 ~407 ~64 ~78 dirt
fill ~407 ~65 ~78 ~407 ~65 ~78 grass_block
fill ~408 ~60 ~78 ~410 ~62 ~78 stone
fill ~408 ~63 ~78 ~410 ~65 ~78 dirt
fill ~408 ~66 ~78 ~410 ~66 ~78 grass_block
fill ~411 ~60 ~78 ~415 ~63 ~78 stone
fill ~411 ~64 ~78 ~415 ~66 ~78 dirt
fill ~411 ~67 ~78 ~415 ~67 ~78 grass_block
fill ~400 ~60 ~79 ~404 ~63 ~79 stone
fill ~400 ~64 ~79 ~404 ~66 ~79 dirt
fill ~400 ~67 ~79 ~404 ~67 ~79 grass_block
fill ~405 ~60 ~79 ~407 ~62 ~79 stone
fill ~405 ~63 ~79 ~407 ~65 ~79 dirt
fill ~405 ~66 ~79 ~407 ~66 ~79 grass_block
fill ~408 ~60 ~79 ~408 ~61 ~79 stone
fill ~408 ~62 ~79 ~408 ~64 ~79 dirt
fill ~408 ~65 ~79 ~408 ~65 ~79 grass_block
fill ~409 ~60 ~79 ~411 ~62 ~79 stone
fill ~409 ~63 ~79 ~411 ~65 ~79 dirt
fill ~409 ~66 ~79 ~411 ~66 ~79 grass_block
fill ~412 ~60 ~79 ~415 ~63 ~79 stone
fill ~412 ~64 ~79 ~415 ~66 ~79 dirt
fill ~412 ~67 ~79 ~415 ~67 ~79 grass_block