fill ~240 ~60 ~16 ~242 ~63 ~16 stone
fill ~240 ~64 ~16 ~242 ~66 ~16 dirt
fill ~240 ~67 ~16 ~242 ~67 ~16 grass_block
fill ~243 ~60 ~16 ~255 ~64 ~16 stone
fill ~243 ~65 ~16 ~255 ~67 ~16 dirt
fill ~243 ~68 ~16 ~255 ~68 ~16 grass_block
fill ~240 ~60 ~17 ~241 ~62 ~17 stone
fill ~240 ~63 ~17 ~241 ~65 ~17 dirt
fill ~240 ~66 ~17 ~241 ~66 ~17 grass_block
fill ~242 ~60 ~17 ~246 ~63 ~17 stone
fill ~242 ~64 ~17 ~246 ~66 ~17 dirt
fill ~242 ~67 ~17 ~246 ~67 ~17 grass_block
fill ~247 ~60 ~17 ~255 ~64 ~17 stone
fill ~247 ~65 ~17 ~255 ~67 ~17 dirt
fill ~247 ~68 ~17 ~255 ~68 ~17 grass_block
fill ~240 ~60 ~18 ~243 ~62 ~18 stone
fill ~240 ~63 ~18 ~243 ~65 ~18 dirt
fill ~240 ~66 ~18 ~243 ~66 ~18 grass_block
fill ~244 ~60 ~18 ~248 ~63 ~18 stone
fill ~244 ~64 ~18 ~248 ~66 ~18 dirt
fill ~244 ~67 ~18 ~248 ~67 ~18 grass_block
fill ~249 ~60 ~18 ~255 ~64 ~18 stone
fill ~249 ~65 ~18 ~255 ~67 ~18 dirt
fill ~249 ~68 ~18 ~255 ~68 ~18 grass_block
fill ~240 ~60 ~19 ~246 ~62 ~19 stone
fill ~240 ~63 ~19 ~246 ~65 ~19 dirt
fill ~240 ~66 ~19 ~246 ~66 ~19 grass_block
fill ~247 ~60 ~19 ~255 ~63 ~19 stone
fill ~247 ~64 ~19 ~255 ~66 ~19 dirt
fill ~247 ~67 ~19 ~255 ~67 ~19 grass_block
fill ~240 ~60 ~20 ~240 ~63 ~20 stone
fill ~240 ~64 ~20 ~240 ~66 ~20 dirt
fill ~240 ~67 ~20 ~240 ~67 ~20 grass_block
fill ~241 ~60 ~20 ~247 ~62 ~20 stone
fill ~241 ~63 ~20 ~247 ~65 ~20 dirt
fill ~241 ~66 ~20 ~247 ~66 ~20 grass_block
fill ~248 ~60 ~20 ~255 ~63 ~20 stone
fill ~248 ~64 ~20 ~255 ~66 ~20 dirt
fill ~248 ~67 ~20 ~255 ~67 ~20 grass_block
fill ~240 ~60 ~21 ~241 ~63 ~21 stone
fill ~240 ~64 ~21 ~241 ~66 ~21 dirt
fill ~240 ~67 ~21 ~241 ~67 ~21 grass_block
fill ~242 ~60 ~21 ~249 ~62 ~21 stone
fill ~242 ~63 ~21 ~249 ~65 ~21 dirt
fill ~242 ~66 ~21 ~249 ~66 ~21 grass_block
fill ~250 ~60 ~21 ~255 ~63 ~21 stone
fill ~250 ~64 ~21 ~255 ~66 ~21 dirt
fill ~250 ~67 ~21 ~255 ~67 ~21 grass_block
fill ~240 ~60 ~22 ~243 ~63 ~22 stone
fill ~240 ~64 ~22 ~243 ~66 ~22 dirt
fill ~240 ~67 ~22 ~243 ~67 ~22 grass_block
fill ~244 ~60 ~22 ~250 ~62 ~22 stone
fill ~244 ~63 ~22 ~250 ~65 ~22 dirt
fill ~244 ~66 ~22 ~250 ~66 ~22 grass_block
fill ~251 ~60 ~22 ~254 ~63 ~22 stone
fill ~251 ~64 ~22 ~254 ~66 ~22 dirt
fill ~251 ~67 ~22 ~254 ~67 ~22 grass_block
fill ~255 ~60 ~22 ~255 ~62 ~22 stone
fill ~255 ~63 ~22 ~255 ~65 ~22 dirt
fill ~255 ~66 ~22 ~255 ~66 ~22 grass_block
fill ~240 ~60 ~23 ~241 ~64 ~23 stone
fill ~240 ~65 ~23 ~241 ~67 ~23 dirt
fill ~240 ~68 ~23 ~241 ~68 ~23 grass_block
fill ~242 ~60 ~23 ~244 ~63 ~23 stone
fill ~242 ~64 ~23 ~244 ~66 ~23 dirt
fill ~242 ~67 ~23 ~244 ~67 ~23 grass_block
fill ~245 ~60 ~23 ~255 ~62 ~23 stone
fill ~245 ~63 ~23 ~255 ~65 ~23 dirt
fill ~245 ~66 ~23 ~255 ~66 ~23 grass_block
fill ~240 ~60 ~24 ~243 ~64 ~24 stone
fill ~240 ~65 ~24 ~243 ~67 ~24 dirt
fill ~240 ~68 ~24 ~243 ~68 ~24 grass_block
fill ~244 ~60 ~24 ~247 ~63 ~24 stone
fill ~244 ~64 ~24 ~247 ~66 ~24 dirt
fill ~244 ~67 ~24 ~247 ~67 ~24 grass_block
fill ~248 ~60 ~24 ~255 ~62 ~24 stone
fill ~248 ~63 ~24 ~255 ~65 ~24 dirt
fill ~248 ~66 ~24 ~255 ~66 ~24 grass_block
fill ~240 ~60 ~25 ~245 ~64 ~25 stone
fill ~240 ~65 ~25 ~245 ~67 ~25 dirt
fill ~240 ~68 ~25 ~245 ~68 ~25 grass_block
fill ~246 ~60 ~25 ~248 ~63 ~25 stone
fill ~246 ~64 ~25 ~248 ~66 ~25 dirt
fill ~246 ~67 ~25 ~248 ~67 ~25 grass_block
fill ~249 ~60 ~25 ~255 ~62 ~25 stone
fill ~249 ~63 ~25 ~255 ~65 ~25 dirt
fill ~249 ~66 ~25 ~255 ~66 ~25 grass_block
fill ~240 ~60 ~26 ~241 ~63 ~26 stone
fill ~240 ~64 ~26 ~241 ~66 ~26 dirt
fill ~240 ~67 ~26 ~241 ~67 ~26 grass_block
fill ~242 ~60 ~26 ~247 ~64 ~26 stone
fill ~242 ~65 ~26 ~247 ~67 ~26 dirt
fill ~242 ~68 ~26 ~247 ~68 ~26 grass_block
fill ~248 ~60 ~26 ~249 ~63 ~26 stone
fill ~248 ~64 ~26 ~249 ~66 ~26 dirt
fill ~248 ~67 ~26 ~249 ~67 ~26 grass_block
fill ~250 ~60 ~26 ~255 ~62 ~26 stone
fill ~250 ~63 ~26 ~255 ~65 ~26 dirt
fill ~250 ~66 ~26 ~255 ~66 ~26 grass_block
fill ~240 ~60 ~27 ~243 ~63 ~27 stone
fill ~240 ~64 ~27 ~243 ~66 ~27 dirt
fill ~240 ~67 ~27 ~243 ~67 ~27 grass_block
fill ~244 ~60 ~27 ~248 ~64 ~27 stone
fill ~244 ~65 ~27 ~248 ~67 ~27 dirt
fill ~244 ~68 ~27 ~248 ~68 ~27 grass_block
fill ~249 ~60 ~27 ~250 ~63 ~27 stone
fill ~249 ~64 ~27 ~250 ~66 ~27 dirt
fill ~249 ~67 ~27 ~250 ~67 ~27 grass_block
fill ~251 ~60 ~27 ~254 ~62 ~27 stone
fill ~251 ~63 ~27 ~254 ~65 ~27 dirt
fill ~251 ~66 ~27 ~254 ~66 ~27 grass_block
fill ~255 ~60 ~27 ~255 ~61 ~27 stone
fill ~255 ~62 ~27 ~255 ~64 ~27 dirt
fill ~255 ~65 ~27 ~255 ~65 ~27 grass_block
fill ~240 ~60 ~28 ~242 ~62 ~28 stone
fill ~240 ~63 ~28 ~242 ~65 ~28 dirt
fill ~240 ~66 ~28 ~242 ~66 ~28 grass_block
fill ~243 ~60 ~28 ~246 ~63 ~28 stone
fill ~243 ~64 ~28 ~246 ~66 ~28 dirt
fill ~243 ~67 ~28 ~246 ~67 ~28 grass_block
fill ~247 ~60 ~28 ~250 ~64 ~28 stone
fill ~247 ~65 ~28 ~250 ~67 ~28 dirt
fill ~247 ~68 ~28 ~250 ~68 ~28 grass_block
fill ~251 ~60 ~28 ~252 ~63 ~28 stone
fill ~251 ~64 ~28 ~252 ~66 ~28 dirt
fill ~251 ~67 ~28 ~252 ~67 ~28 grass_block
fill ~253 ~60 ~28 ~255 ~62 ~28 stone
fill ~253 ~63 ~28 ~255 ~65 ~28 dirt
fill ~253 ~66 ~28 ~255 ~66 ~28 grass_block
fill ~240 ~60 ~29 ~245 ~62 ~29 stone
fill ~240 ~63 ~29 ~245 ~65 ~29 dirt
fill ~240 ~66 ~29 ~245 ~66 ~29 grass_block
fill ~246 ~60 ~29 ~248 ~63 ~29 stone
fill ~246 ~64 ~29 ~248 ~66 ~29 dirt
fill ~246 ~67 ~29 ~248 ~67 ~29 grass_block
fill ~249 ~60 ~29 ~250 ~64 ~29 stone
fill ~249 ~65 ~29 ~250 ~67 ~29 dirt
fill ~249 ~68 ~29 ~250 ~68 ~29 grass_block
fill ~251 ~60 ~29 ~253 ~63 ~29 stone
fill ~251 ~64 ~29 ~253 ~66 ~29 dirt
fill ~251 ~67 ~29 ~253 ~67 ~29 grass_block
fill ~254 ~60 ~29 ~255 ~62 ~29 stone
fill ~254 ~63 ~29 ~255 ~65 ~29 dirt
fill ~254 ~66 ~29 ~255 ~66 ~29 grass_block
fill ~240 ~60 ~30 ~243 ~61 ~30 stone
fill ~240 ~62 ~30 ~243 ~64 ~30 dirt
fill ~240 ~65 ~30 ~243 ~65 ~30 grass_block
fill ~244 ~60 ~30 ~247 ~62 ~30 stone
fill ~244 ~63 ~30 ~247 ~65 ~30 dirt
fill ~244 ~66 ~30 ~247 ~66 ~30 grass_block
fill ~248 ~60 ~30 ~254 ~63 ~30 stone
fill ~248 ~64 ~30 ~254 ~66 ~30 dirt
fill ~248 ~67 ~30 ~254 ~67 ~30 grass_block
fill ~255 ~60 ~30 ~255 ~62 ~30 stone
fill ~255 ~63 ~30 ~255 ~65 ~30 dirt
fill ~255 ~66 ~30 ~255 ~66 ~30 grass_block
fill ~240 ~60 ~31 ~246 ~61 ~31 stone
fill ~240 ~62 ~31 ~246 ~64 ~31 dirt
fill ~240 ~65 ~31 ~246 ~65 ~31 grass_block
fill ~247 ~60 ~31 ~249 ~62 ~31 stone
fill ~247 ~63 ~31 ~249 ~65 ~31 dirt
fill ~247 ~66 ~31 ~249 ~66 ~31 grass_block
fill ~250 ~60 ~31 ~255 ~63 ~31 stone
fill ~250 ~64 ~31 ~255 ~66 ~31 dirt
fill ~250 ~67 ~31 ~255 ~67 ~31 grass_block