fill ~192 ~60 ~48 ~194 ~64 ~48 stone
fill ~192 ~65 ~48 ~194 ~67 ~48 dirt
fill ~192 ~68 ~48 ~194 ~68 ~48 grass_block
fill ~195 ~60 ~48 ~199 ~63 ~48 stone
fill ~195 ~64 ~48 ~199 ~66 ~48 dirt
fill ~195 ~67 ~48 ~199 ~67 ~48 grass_block
fill ~200 ~60 ~48 ~207 ~64 ~48 stone
fill ~200 ~65 ~48 ~207 ~67 ~48 dirt
fill ~200 ~68 ~48 ~207 ~68 ~48 grass_block
fill ~192 ~60 ~49 ~195 ~64 ~49 stone
fill ~192 ~65 ~49 ~195 ~67 ~49 dirt
fill ~192 ~68 ~49 ~195 ~68 ~49 grass_block
fill ~196 ~60 ~49 ~200 ~63 ~49 stone
fill ~196 ~64 ~49 ~200 ~66 ~49 dirt
fill ~196 ~67 ~49 ~200 ~67 ~49 grass_block
fill ~201 ~60 ~49 ~207 ~64 ~49 stone
fill ~201 ~65 ~49 ~207 ~67 ~49 dirt
fill ~201 ~68 ~49 ~207 ~68 ~49 grass_block
fill ~192 ~60 ~50 ~196 ~64 ~50 stone
fill ~192 ~65 ~50 ~196 ~67 ~50 dirt
fill ~192 ~68 ~50 ~196 ~68 ~50 grass_block
fill ~197 ~60 ~50 ~201 ~63 ~50 stone
fill ~197 ~64 ~50 ~201 ~66 ~50 dirt
fill ~197 ~67 ~50 ~201 ~67 ~50 grass_block
fill ~202 ~60 ~50 ~207 ~64 ~50 stone
fill ~202 ~65 ~50 ~207 ~67 ~50 dirt
fill ~202 ~68 ~50 ~207 ~68 ~50 grass_block
fill ~192 ~60 ~51 ~193 ~65 ~51 stone
fill ~192 ~66 ~51 ~193 ~68 ~51 dirt
fill ~192 ~69 ~51 ~193 ~69 ~51 grass_block
fill ~194 ~60 ~51 ~197 ~64 ~51 stone
fill ~194 ~65 ~51 ~197 ~67 ~51 dirt
fill ~194 ~68 ~51 ~197 ~68 ~51 grass_block
fill ~198 ~60 ~51 ~203 ~63 ~51 stone
fill ~198 ~64 ~51 ~203 ~66 ~51 dirt
fill ~198 ~67 ~51 ~203 ~67 ~51 grass_block
fill ~204 ~60 ~51 ~207 ~64 ~51 stone
fill ~204 ~65 ~51 ~207 ~67 ~51 dirt
fill ~204 ~68 ~51 ~207 ~68 ~51 grass_block
fill ~192 ~60 ~52 ~193 ~65 ~52 stone
fill ~192 ~66 ~52 ~193 ~68 ~52 dirt
fill ~192 ~69 ~52 ~193 ~69 ~52 grass_block
fill ~194 ~60 ~52 ~198 ~64 ~52 stone
fill ~194 ~65 ~52 ~198 ~67 ~52 dirt
fill ~194 ~68 ~52 ~198 ~68 ~52 grass_block
fill ~199 ~60 ~52 ~204 ~63 ~52 stone
fill ~199 ~64 ~52 ~204 ~66 ~52 dirt
fill ~199 ~67 ~52 ~204 ~67 ~52 grass_block
fill ~205 ~60 ~52 ~207 ~64 ~52 stone
fill ~205 ~65 ~52 ~207 ~67 ~52 dirt
fill ~205 ~68 ~52 ~207 ~68 ~52 grass_block
fill ~192 ~60 ~53 ~194 ~65 ~53 stone
fill ~192 ~66 ~53 ~194 ~68 ~53 dirt
fill ~192 ~69 ~53 ~194 ~69 ~53 grass_block
fill ~195 ~60 ~53 ~199 ~64 ~53 stone
fill ~195 ~65 ~53 ~199 ~67 ~53 dirt
fill ~195 ~68 ~53 ~199 ~68 ~53 grass_block
fill ~200 ~60 ~53 ~207 ~63 ~53 stone
fill ~200 ~64 ~53 ~207 ~66 ~53 dirt
fill ~200 ~67 ~53 ~207 ~67 ~53 grass_block
fill ~192 ~60 ~54 ~194 ~65 ~54 stone
fill ~192 ~66 ~54 ~194 ~68 ~54 dirt
fill ~192 ~69 ~54 ~194 ~69 ~54 grass_block
fill ~195 ~60 ~54 ~199 ~64 ~54 stone
fill ~195 ~65 ~54 ~199 ~67 ~54 dirt
fill ~195 ~68 ~54 ~199 ~68 ~54 grass_block
fill ~200 ~60 ~54 ~207 ~63 ~54 stone
fill ~200 ~64 ~54 ~207 ~66 ~54 dirt
fill ~200 ~67 ~54 ~207 ~67 ~54 grass_block
fill ~192 ~60 ~55 ~194 ~65 ~55 stone
fill ~192 ~66 ~55 ~194 ~68 ~55 dirt
fill ~192 ~69 ~55 ~194 ~69 ~55 grass_block
fill ~195 ~60 ~55 ~199 ~64 ~55 stone
fill ~195 ~65 ~55 ~199 ~67 ~55 dirt
fill ~195 ~68 ~55 ~199 ~68 ~55 grass_block
fill ~200 ~60 ~55 ~207 ~63 ~55 stone
fill ~200 ~64 ~55 ~207 ~66 ~55 dirt
fill ~200 ~67 ~55 ~207 ~67 ~55 grass_block
fill ~192 ~60 ~56 ~194 ~65 ~56 stone
fill ~192 ~66 ~56 ~194 ~68 ~56 dirt
fill ~192 ~69 ~56 ~194 ~69 ~56 grass_block
fill ~195 ~60 ~56 ~199 ~64 ~56 stone
fill ~195 ~65 ~56 ~199 ~67 ~56 dirt
fill ~195 ~68 ~56 ~199 ~68 ~56 grass_block
fill ~200 ~60 ~56 ~207 ~63 ~56 stone
fill ~200 ~64 ~56 ~207 ~66 ~56 dirt
fill ~200 ~67 ~56 ~207 ~67 ~56 grass_block
fill ~192 ~60 ~57 ~195 ~65 ~57 stone
fill ~192 ~66 ~57 ~195 ~68 ~57 dirt
fill ~192 ~69 ~57 ~195 ~69 ~57 grass_block
fill ~196 ~60 ~57 ~198 ~64 ~57 stone
fill ~196 ~65 ~57 ~198 ~67 ~57 dirt
fill ~196 ~68 ~57 ~198 ~68 ~57 grass_block
fill ~199 ~60 ~57 ~203 ~63 ~57 stone
fill ~199 ~64 ~57 ~203 ~66 ~57 dirt
fill ~199 ~67 ~57 ~203 ~67 ~57 grass_block
fill ~204 ~60 ~57 ~207 ~64 ~57 stone
fill ~204 ~65 ~57 ~207 ~67 ~57 dirt
fill ~204 ~68 ~57 ~207 ~68 ~57 grass_block
fill ~192 ~60 ~58 ~195 ~65 ~58 stone
fill ~192 ~66 ~58 ~195 ~68 ~58 dirt
fill ~192 ~69 ~58 ~195 ~69 ~58 grass_block
fill ~196 ~60 ~58 ~198 ~64 ~58 stone
fill ~196 ~65 ~58 ~198 ~67 ~58 dirt
fill ~196 ~68 ~58 ~198 ~68 ~58 grass_block
fill ~199 ~60 ~58 ~202 ~63 ~58 stone
fill ~199 ~64 ~58 ~202 ~66 ~58 dirt
fill ~199 ~67 ~58 ~202 ~67 ~58 grass_block
fill ~203 ~60 ~58 ~205 ~64 ~58 stone
fill ~203 ~65 ~58 ~205 ~67 ~58 dirt
fill ~203 ~68 ~58 ~205 ~68 ~58 grass_block
fill ~206 ~60 ~58 ~207 ~65 ~58 stone
fill ~206 ~66 ~58 ~207 ~68 ~58 dirt
fill ~206 ~69 ~58 ~207 ~69 ~58 grass_block
fill ~192 ~60 ~59 ~194 ~65 ~59 stone
fill ~192 ~66 ~59 ~194 ~68 ~59 dirt
fill ~192 ~69 ~59 ~194 ~69 ~59 grass_block
fill ~195 ~60 ~59 ~197 ~64 ~59 stone
fill ~195 ~65 ~59 ~197 ~67 ~59 dirt
fill ~195 ~68 ~59 ~197 ~68 ~59 grass_block
fill ~198 ~60 ~59 ~201 ~63 ~59 stone
fill ~198 ~64 ~59 ~201 ~66 ~59 dirt
fill ~198 ~67 ~59 ~201 ~67 ~59 grass_block
fill ~202 ~60 ~59 ~204 ~64 ~59 stone
fill ~202 ~65 ~59 ~204 ~67 ~59 dirt
fill ~202 ~68 ~59 ~204 ~68 ~59 grass_block
fill ~205 ~60 ~59 ~207 ~65 ~59 stone
fill ~205 ~66 ~59 ~207 ~68 ~59 dirt
fill ~205 ~69 ~59 ~207 ~69 ~59 grass_block
fill ~192 ~60 ~60 ~195 ~65 ~60 stone
fill ~192 ~66 ~60 ~195 ~68 ~60 dirt
fill ~192 ~69 ~60 ~195 ~69 ~60 grass_block
fill ~196 ~60 ~60 ~198 ~64 ~60 stone
fill ~196 ~65 ~60 ~198 ~67 ~60 dirt
fill ~196 ~68 ~60 ~198 ~68 ~60 grass_block
fill ~199 ~60 ~60 ~200 ~63 ~60 stone
fill ~199 ~64 ~60 ~200 ~66 ~60 dirt
fill ~199 ~67 ~60 ~200 ~67 ~60 grass_block
fill ~201 ~60 ~60 ~203 ~64 ~60 stone
fill ~201 ~65 ~60 ~203 ~67 ~60 dirt
fill ~201 ~68 ~60 ~203 ~68 ~60 grass_block
fill ~204 ~60 ~60 ~207 ~65 ~60 stone
fill ~204 ~66 ~60 ~207 ~68 ~60 dirt
fill ~204 ~69 ~60 ~207 ~69 ~60 grass_block
fill ~192 ~60 ~61 ~195 ~65 ~61 stone
fill ~192 ~66 ~61 ~195 ~68 ~61 dirt
fill ~192 ~69 ~61 ~195 ~69 ~61 grass_block
fill ~196 ~60 ~61 ~198 ~64 ~61 stone
fill ~196 ~65 ~61 ~198 ~67 ~61 dirt
fill ~196 ~68 ~61 ~198 ~68 ~61 grass_block
fill ~199 ~60 ~61 ~200 ~63 ~61 stone
fill ~199 ~64 ~61 ~200 ~66 ~61 dirt
fill ~199 ~67 ~61 ~200 ~67 ~61 grass_block
fill ~201 ~60 ~61 ~202 ~64 ~61 stone
fill ~201 ~65 ~61 ~202 ~67 ~61 dirt
fill ~201 ~68 ~61 ~202 ~68 ~61 grass_block
fill ~203 ~60 ~61 ~207 ~65 ~61 stone
fill ~203 ~66 ~61 ~207 ~68 ~61 dirt
fill ~203 ~69 ~61 ~207 ~69 ~61 grass_block
fill ~192 ~60 ~62 ~195 ~65 ~62 stone
fill ~192 ~66 ~62 ~195 ~68 ~62 dirt
fill ~192 ~69 ~62 ~195 ~69 ~62 grass_block
fill ~196 ~60 ~62 ~198 ~64 ~62 stone
fill ~196 ~65 ~62 ~198 ~67 ~62 dirt
fill ~196 ~68 ~62 ~198 ~68 ~62 grass_block
fill ~199 ~60 ~62 ~199 ~63 ~62 stone
fill ~199 ~64 ~62 ~199 ~66 ~62 dirt
fill ~199 ~67 ~62 ~199 ~67 ~62 grass_block
fill ~200 ~60 ~62 ~201 ~64 ~62 stone
fill ~200 ~65 ~62 ~201 ~67 ~62 dirt
fill ~200 ~68 ~62 ~201 ~68 ~62 grass_block
fill ~202 ~60 ~62 ~205 ~65 ~62 stone
fill ~202 ~66 ~62 ~205 ~68 ~62 dirt
fill ~202 ~69 ~62 ~205 ~69 ~62 grass_block
fill ~206 ~60 ~62 ~207 ~66 ~62 stone
fill ~206 ~67 ~62 ~207 ~69 ~62 dirt
fill ~206 ~70 ~62 ~207 ~70 ~62 grass_block
fill ~192 ~60 ~63 ~194 ~65 ~63 stone
fill ~192 ~66 ~63 ~194 ~68 ~63 dirt
fill ~192 ~69 ~63 ~194 ~69 ~63 grass_block
fill ~195 ~60 ~63 ~198 ~64 ~63 stone
fill ~195 ~65 ~63 ~198 ~67 ~63 dirt
fill ~195 ~68 ~63 ~198 ~68 ~63 grass_block
fill ~199 ~60 ~63 ~199 ~63 ~63 stone
fill ~199 ~64 ~63 ~199 ~66 ~63 dirt
fill ~199 ~67 ~63 ~199 ~67 ~63 grass_block
fill ~200 ~60 ~63 ~201 ~64 ~63 stone
fill ~200 ~65 ~63 ~201 ~67 ~63 dirt
fill ~200 ~68 ~63 ~201 ~68 ~63 grass_block
fill ~202 ~60 ~63 ~203 ~65 ~63 stone
fill ~202 ~66 ~63 ~203 ~68 ~63 dirt
fill ~202 ~69 ~63 ~203 ~69 ~63 grass_block
fill ~204 ~60 ~63 ~207 ~66 ~63 stone
fill ~204 ~67 ~63 ~207 ~69 ~63 dirt
fill ~204 ~70 ~63 ~207 ~70 ~63 grass_block