fill ~400 ~60 ~0 ~405 ~65 ~0 stone
fill ~400 ~66 ~0 ~405 ~68 ~0 dirt
fill ~400 ~69 ~0 ~405 ~69 ~0 grass_block
fill ~406 ~60 ~0 ~410 ~64 ~0 stone
fill ~406 ~65 ~0 ~410 ~67 ~0 dirt
fill ~406 ~68 ~0 ~410 ~68 ~0 grass_block
fill ~411 ~60 ~0 ~415 ~63 ~0 stone
fill ~411 ~64 ~0 ~415 ~66 ~0 dirt
fill ~411 ~67 ~0 ~415 ~67 ~0 grass_block
fill ~400 ~60 ~1 ~401 ~64 ~1 stone
fill ~400 ~65 ~1 ~401 ~67 ~1 dirt
fill ~400 ~68 ~1 ~401 ~68 ~1 grass_block
fill ~402 ~60 ~1 ~403 ~65 ~1 stone
fill ~402 ~66 ~1 ~403 ~68 ~1 dirt
fill ~402 ~69 ~1 ~403 ~69 ~1 grass_block
fill ~404 ~60 ~1 ~409 ~64 ~1 stone
fill ~404 ~65 ~1 ~409 ~67 ~1 dirt
fill ~404 ~68 ~1 ~409 ~68 ~1 grass_block
fill ~410 ~60 ~1 ~415 ~63 ~1 stone
fill ~410 ~64 ~1 ~415 ~66 ~1 dirt
fill ~410 ~67 ~1 ~415 ~67 ~1 grass_block
fill ~400 ~60 ~2 ~408 ~64 ~2 stone
fill ~400 ~65 ~2 ~408 ~67 ~2 dirt
fill ~400 ~68 ~2 ~408 ~68 ~2 grass_block
fill ~409 ~60 ~2 ~412 ~63 ~2 stone
fill ~409 ~64 ~2 ~412 ~66 ~2 dirt
fill ~409 ~67 ~2 ~412 ~67 ~2 grass_block
fill ~413 ~60 ~2 ~413 ~62 ~2 stone
fill ~413 ~63 ~2 ~413 ~65 ~2 dirt
fill ~413 ~66 ~2 ~413 ~66 ~2 grass_block
fill ~414 ~60 ~2 ~415 ~63 ~2 stone
fill ~414 ~64 ~2 ~415 ~66 ~2 dirt
fill ~414 ~67 ~2 ~415 ~67 ~2 grass_block
fill ~400 ~60 ~3 ~408 ~64 ~3 stone
fill ~400 ~65 ~3 ~408 ~67 ~3 dirt
fill ~400 ~68 ~3 ~408 ~68 ~3 grass_block
fill ~409 ~60 ~3 ~412 ~63 ~3 stone
fill ~409 ~64 ~3 ~412 ~66 ~3 dirt
fill ~409 ~67 ~3 ~412 ~67 ~3 grass_block
fill ~413 ~60 ~3 ~413 ~62 ~3 stone
fill ~413 ~63 ~3 ~413 ~65 ~3 dirt
fill ~413 ~66 ~3 ~413 ~66 ~3 grass_block
fill ~414 ~60 ~3 ~414 ~63 ~3 stone
fill ~414 ~64 ~3 ~414 ~66 ~3 dirt
fill ~414 ~67 ~3 ~414 ~67 ~3 grass_block
fill ~415 ~60 ~3 ~415 ~64 ~3 stone
fill ~415 ~65 ~3 ~415 ~67 ~3 dirt
fill ~415 ~68 ~3 ~415 ~68 ~3 grass_block
fill ~400 ~60 ~4 ~400 ~63 ~4 stone
fill ~400 ~64 ~4 ~400 ~66 ~4 dirt
fill ~400 ~67 ~4 ~400 ~67 ~4 grass_block
fill ~401 ~60 ~4 ~407 ~64 ~4 stone
fill ~401 ~65 ~4 ~407 ~67 ~4 dirt
fill ~401 ~68 ~4 ~407 ~68 ~4 grass_block
fill ~408 ~60 ~4 ~411 ~63 ~4 stone
fill ~408 ~64 ~4 ~411 ~66 ~4 dirt
fill ~408 ~67 ~4 ~411 ~67 ~4 grass_block
fill ~412 ~60 ~4 ~413 ~62 ~4 stone
fill ~412 ~63 ~4 ~413 ~65 ~4 dirt
fill ~412 ~66 ~4 ~413 ~66 ~4 grass_block
fill ~414 ~60 ~4 ~414 ~63 ~4 stone
fill ~414 ~64 ~4 ~414 ~66 ~4 dirt
fill ~414 ~67 ~4 ~414 ~67 ~4 grass_block
fill ~415 ~60 ~4 ~415 ~64 ~4 stone
fill ~415 ~65 ~4 ~415 ~67 ~4 dirt
fill ~415 ~68 ~4 ~415 ~68 ~4 grass_block
fill ~400 ~60 ~5 ~401 ~63 ~5 stone
fill ~400 ~64 ~5 ~401 ~66 ~5 dirt
fill ~400 ~67 ~5 ~401 ~67 ~5 grass_block
fill ~402 ~60 ~5 ~407 ~64 ~5 stone
fill ~402 ~65 ~5 ~407 ~67 ~5 dirt
fill ~402 ~68 ~5 ~407 ~68 ~5 grass_block
fill ~408 ~60 ~5 ~411 ~63 ~5 stone
fill ~408 ~64 ~5 ~411 ~66 ~5 dirt
fill ~408 ~67 ~5 ~411 ~67 ~5 grass_block
fill ~412 ~60 ~5 ~413 ~62 ~5 stone
fill ~412 ~63 ~5 ~413 ~65 ~5 dirt
fill ~412 ~66 ~5 ~413 ~66 ~5 grass_block
fill ~414 ~60 ~5 ~414 ~63 ~5 stone
fill ~414 ~64 ~5 ~414 ~66 ~5 dirt
fill ~414 ~67 ~5 ~414 ~67 ~5 grass_block
fill ~415 ~60 ~5 ~415 ~64 ~5 stone
fill ~415 ~65 ~5 ~415 ~67 ~5 dirt
fill ~415 ~68 ~5 ~415 ~68 ~5 grass_block
fill ~400 ~60 ~6 ~403 ~63 ~6 stone
fill ~400 ~64 ~6 ~403 ~66 ~6 dirt
fill ~400 ~67 ~6 ~403 ~67 ~6 grass_block
fill ~404 ~60 ~6 ~406 ~64 ~6 stone
fill ~404 ~65 ~6 ~406 ~67 ~6 dirt
fill ~404 ~68 ~6 ~406 ~68 ~6 grass_block
fill ~407 ~60 ~6 ~410 ~63 ~6 stone
fill ~407 ~64 ~6 ~410 ~66 ~6 dirt
fill ~407 ~67 ~6 ~410 ~67 ~6 grass_block
fill ~411 ~60 ~6 ~412 ~62 ~6 stone
fill ~411 ~63 ~6 ~412 ~65 ~6 dirt
fill ~411 ~66 ~6 ~412 ~66 ~6 grass_block
fill ~413 ~60 ~6 ~414 ~63 ~6 stone
fill ~413 ~64 ~6 ~414 ~66 ~6 dirt
fill ~413 ~67 ~6 ~414 ~67 ~6 grass_block
fill ~415 ~60 ~6 ~415 ~64 ~6 stone
fill ~415 ~65 ~6 ~415 ~67 ~6 dirt
fill ~415 ~68 ~6 ~415 ~68 ~6 grass_block
fill ~400 ~60 ~7 ~404 ~63 ~7 stone
fill ~400 ~64 ~7 ~404 ~66 ~7 dirt
fill ~400 ~67 ~7 ~404 ~67 ~7 grass_block
fill ~405 ~60 ~7 ~405 ~64 ~7 stone
fill ~405 ~65 ~7 ~405 ~67 ~7 dirt
fill ~405 ~68 ~7 ~405 ~68 ~7 grass_block
fill ~406 ~60 ~7 ~410 ~63 ~7 stone
fill ~406 ~64 ~7 ~410 ~66 ~7 dirt
fill ~406 ~67 ~7 ~410 ~67 ~7 grass_block
fill ~411 ~60 ~7 ~412 ~62 ~7 stone
fill ~411 ~63 ~7 ~412 ~65 ~7 dirt
fill ~411 ~66 ~7 ~412 ~66 ~7 grass_block
fill ~413 ~60 ~7 ~414 ~63 ~7 stone
fill ~413 ~64 ~7 ~414 ~66 ~7 dirt
fill ~413 ~67 ~7 ~414 ~67 ~7 grass_block
fill ~415 ~60 ~7 ~415 ~64 ~7 stone
fill ~415 ~65 ~7 ~415 ~67 ~7 dirt
fill ~415 ~68 ~7 ~415 ~68 ~7 grass_block
fill ~400 ~60 ~8 ~400 ~62 ~8 stone
fill ~400 ~63 ~8 ~400 ~65 ~8 dirt
fill ~400 ~66 ~8 ~400 ~66 ~8 grass_block
fill ~401 ~60 ~8 ~409 ~63 ~8 stone
fill ~401 ~64 ~8 ~409 ~66 ~8 dirt
fill ~401 ~67 ~8 ~409 ~67 ~8 grass_block
fill ~410 ~60 ~8 ~412 ~62 ~8 stone
fill ~410 ~63 ~8 ~412 ~65 ~8 dirt
fill ~410 ~66 ~8 ~412 ~66 ~8 grass_block
fill ~413 ~60 ~8 ~415 ~63 ~8 stone
fill ~413 ~64 ~8 ~415 ~66 ~8 dirt
fill ~413 ~67 ~8 ~415 ~67 ~8 grass_block
fill ~400 ~60 ~9 ~401 ~62 ~9 stone
fill ~400 ~63 ~9 ~401 ~65 ~9 dirt
fill ~400 ~66 ~9 ~401 ~66 ~9 grass_block
fill ~402 ~60 ~9 ~408 ~63 ~9 stone
fill ~402 ~64 ~9 ~408 ~66 ~9 dirt
fill ~402 ~67 ~9 ~408 ~67 ~9 grass_block
fill ~409 ~60 ~9 ~411 ~62 ~9 stone
fill ~409 ~63 ~9 ~411 ~65 ~9 dirt
fill ~409 ~66 ~9 ~411 ~66 ~9 grass_block
fill ~412 ~60 ~9 ~414 ~63 ~9 stone
fill ~412 ~64 ~9 ~414 ~66 ~9 dirt
fill ~412 ~67 ~9 ~414 ~67 ~9 grass_block
fill ~415 ~60 ~9 ~415 ~64 ~9 stone
fill ~415 ~65 ~9 ~415 ~67 ~9 dirt
fill ~415 ~68 ~9 ~415 ~68 ~9 grass_block
fill ~400 ~60 ~10 ~402 ~62 ~10 stone
fill ~400 ~63 ~10 ~402 ~65 ~10 dirt
fill ~400 ~66 ~10 ~402 ~66 ~10 grass_block
fill ~403 ~60 ~10 ~408 ~63 ~10 stone
fill ~403 ~64 ~10 ~408 ~66 ~10 dirt
fill ~403 ~67 ~10 ~408 ~67 ~10 grass_block
fill ~409 ~60 ~10 ~411 ~62 ~10 stone
fill ~409 ~63 ~10 ~411 ~65 ~10 dirt
fill ~409 ~66 ~10 ~411 ~66 ~10 grass_block
fill ~412 ~60 ~10 ~414 ~63 ~10 stone
fill ~412 ~64 ~10 ~414 ~66 ~10 dirt
fill ~412 ~67 ~10 ~414 ~67 ~10 grass_block
fill ~415 ~60 ~10 ~415 ~64 ~10 stone
fill ~415 ~65 ~10 ~415 ~67 ~10 dirt
fill ~415 ~68 ~10 ~415 ~68 ~10 grass_block
fill ~400 ~60 ~11 ~403 ~62 ~11 stone
fill ~400 ~63 ~11 ~403 ~65 ~11 dirt
fill ~400 ~66 ~11 ~403 ~66 ~11 grass_block
fill ~404 ~60 ~11 ~408 ~63 ~11 stone
fill ~404 ~64 ~11 ~408 ~66 ~11 dirt
fill ~404 ~67 ~11 ~408 ~67 ~11 grass_block
fill ~409 ~60 ~11 ~412 ~62 ~11 stone
fill ~409 ~63 ~11 ~412 ~65 ~11 dirt
fill ~409 ~66 ~11 ~412 ~66 ~11 grass_block
fill ~413 ~60 ~11 ~415 ~63 ~11 stone
fill ~413 ~64 ~11 ~415 ~66 ~11 dirt
fill ~413 ~67 ~11 ~415 ~67 ~11 grass_block
fill ~400 ~60 ~12 ~403 ~62 ~12 stone
fill ~400 ~63 ~12 ~403 ~65 ~12 dirt
fill ~400 ~66 ~12 ~403 ~66 ~12 grass_block
fill ~404 ~60 ~12 ~408 ~63 ~12 stone
fill ~404 ~64 ~12 ~408 ~66 ~12 dirt
fill ~404 ~67 ~12 ~408 ~67 ~12 grass_block
fill ~409 ~60 ~12 ~412 ~62 ~12 stone
fill ~409 ~63 ~12 ~412 ~65 ~12 dirt
fill ~409 ~66 ~12 ~412 ~66 ~12 grass_block
fill ~413 ~60 ~12 ~415 ~63 ~12 stone
fill ~413 ~64 ~12 ~415 ~66 ~12 dirt
fill ~413 ~67 ~12 ~415 ~67 ~12 grass_block
fill ~400 ~60 ~13 ~400 ~63 ~13 stone
fill ~400 ~64 ~13 ~400 ~66 ~13 dirt
fill ~400 ~67 ~13 ~400 ~67 ~13 grass_block
fill ~401 ~60 ~13 ~405 ~62 ~13 stone
fill ~401 ~63 ~13 ~405 ~65 ~13 dirt
fill ~401 ~66 ~13 ~405 ~66 ~13 grass_block
fill ~406 ~60 ~13 ~408 ~63 ~13 stone
fill ~406 ~64 ~13 ~408 ~66 ~13 dirt
fill ~406 ~67 ~13 ~408 ~67 ~13 grass_block
fill ~409 ~60 ~13 ~412 ~62 ~13 stone
fill ~409 ~63 ~13 ~412 ~65 ~13 dirt
fill ~409 ~66 ~13 ~412 ~66 ~13 grass_block
fill ~413 ~60 ~13 ~415 ~63 ~13 stone
fill ~413 ~64 ~13 ~415 ~66 ~13 dirt
fill ~413 ~67 ~13 ~415 ~67 ~13 grass_block
fill ~400 ~60 ~14 ~401 ~63 ~14 stone
fill ~400 ~64 ~14 ~401 ~66 ~14 dirt
fill ~400 ~67 ~14 ~401 ~67 ~14 grass_block
fill ~402 ~60 ~14 ~406 ~62 ~14 stone
fill ~402 ~63 ~14 ~406 ~65 ~14 dirt
fill ~402 ~66 ~14 ~406 ~66 ~14 grass_block
fill ~407 ~60 ~14 ~408 ~63 ~14 stone
fill ~407 ~64 ~14 ~408 ~66 ~14 dirt
fill ~407 ~67 ~14 ~408 ~67 ~14 grass_block
fill ~409 ~60 ~14 ~413 ~62 ~14 stone
fill ~409 ~63 ~14 ~413 ~65 ~14 dirt
fill ~409 ~66 ~14 ~413 ~66 ~14 grass_block
fill ~414 ~60 ~14 ~415 ~63 ~14 stone
fill ~414 ~64 ~14 ~415 ~66 ~14 dirt
fill ~414 ~67 ~14 ~415 ~67 ~14 grass_block
fill ~400 ~60 ~15 ~402 ~63 ~15 stone
fill ~400 ~64 ~15 ~402 ~66 ~15 dirt
fill ~400 ~67 ~15 ~402 ~67 ~15 grass_block
fill ~403 ~60 ~15 ~413 ~62 ~15 stone
fill ~403 ~63 ~15 ~413 ~65 ~15 dirt
fill ~403 ~66 ~15 ~413 ~66 ~15 grass_block
fill ~414 ~60 ~15 ~415 ~63 ~15 stone
fill ~414 ~64 ~15 ~415 ~66 ~15 dirt
fill ~414 ~67 ~15 ~415 ~67 ~15 grass_block