fill ~48 ~60 ~80 ~52 ~69 ~80 stone
fill ~48 ~70 ~80 ~52 ~72 ~80 dirt
fill ~48 ~73 ~80 ~52 ~73 ~80 grass_block
fill ~53 ~60 ~80 ~54 ~68 ~80 stone
fill ~53 ~69 ~80 ~54 ~71 ~80 dirt
fill ~53 ~72 ~80 ~54 ~72 ~80 grass_block
fill ~55 ~60 ~80 ~56 ~67 ~80 stone
fill ~55 ~68 ~80 ~56 ~70 ~80 dirt
fill ~55 ~71 ~80 ~56 ~71 ~80 grass_block
fill ~57 ~60 ~80 ~63 ~66 ~80 stone
fill ~57 ~67 ~80 ~63 ~69 ~80 dirt
fill ~57 ~70 ~80 ~63 ~70 ~80 grass_block
fill ~48 ~60 ~81 ~49 ~68 ~81 stone
fill ~48 ~69 ~81 ~49 ~71 ~81 dirt
fill ~48 ~72 ~81 ~49 ~72 ~81 grass_block
fill ~50 ~60 ~81 ~53 ~69 ~81 stone
fill ~50 ~70 ~81 ~53 ~72 ~81 dirt
fill ~50 ~73 ~81 ~53 ~73 ~81 grass_block
fill ~54 ~60 ~81 ~55 ~68 ~81 stone
fill ~54 ~69 ~81 ~55 ~71 ~81 dirt
fill ~54 ~72 ~81 ~55 ~72 ~81 grass_block
fill ~56 ~60 ~81 ~62 ~67 ~81 stone
fill ~56 ~68 ~81 ~62 ~70 ~81 dirt
fill ~56 ~71 ~81 ~62 ~71 ~81 grass_block
fill ~63 ~60 ~81 ~63 ~66 ~81 stone
fill ~63 ~67 ~81 ~63 ~69 ~81 dirt
fill ~63 ~70 ~81 ~63 ~70 ~81 grass_block
fill ~48 ~60 ~82 ~48 ~67 ~82 stone
fill ~48 ~68 ~82 ~48 ~70 ~82 dirt
fill ~48 ~71 ~82 ~48 ~71 ~82 grass_block
fill ~49 ~60 ~82 ~49 ~68 ~82 stone
fill ~49 ~69 ~82 ~49 ~71 ~82 dirt
fill ~49 ~72 ~82 ~49 ~72 ~82 grass_block
fill ~50 ~60 ~82 ~54 ~69 ~82 stone
fill ~50 ~70 ~82 ~54 ~72 ~82 dirt
fill ~50 ~73 ~82 ~54 ~73 ~82 grass_block
fill ~55 ~60 ~82 ~59 ~68 ~82 stone
fill ~55 ~69 ~82 ~59 ~71 ~82 dirt
fill ~55 ~72 ~82 ~59 ~72 ~82 grass_block
fill ~60 ~60 ~82 ~63 ~67 ~82 stone
fill ~60 ~68 ~82 ~63 ~70 ~82 dirt
fill ~60 ~71 ~82 ~63 ~71 ~82 grass_block
fill ~48 ~60 ~83 ~48 ~67 ~83 stone
fill ~48 ~68 ~83 ~48 ~70 ~83 dirt
fill ~48 ~71 ~83 ~48 ~71 ~83 grass_block
fill ~49 ~60 ~83 ~49 ~68 ~83 stone
fill ~49 ~69 ~83 ~49 ~71 ~83 dirt
fill ~49 ~72 ~83 ~49 ~72 ~83 grass_block
fill ~50 ~60 ~83 ~58 ~69 ~83 stone
fill ~50 ~70 ~83 ~58 ~72 ~83 dirt
fill ~50 ~73 ~83 ~58 ~73 ~83 grass_block
fill ~59 ~60 ~83 ~62 ~68 ~83 stone
fill ~59 ~69 ~83 ~62 ~71 ~83 dirt
fill ~59 ~72 ~83 ~62 ~72 ~83 grass_block
fill ~63 ~60 ~83 ~63 ~67 ~83 stone
fill ~63 ~68 ~83 ~63 ~70 ~83 dirt
fill ~63 ~71 ~83 ~63 ~71 ~83 grass_block
fill ~48 ~60 ~84 ~52 ~68 ~84 stone
fill ~48 ~69 ~84 ~52 ~71 ~84 dirt
fill ~48 ~72 ~84 ~52 ~72 ~84 grass_block
fill ~53 ~60 ~84 ~59 ~69 ~84 stone
fill ~53 ~70 ~84 ~59 ~72 ~84 dirt
fill ~53 ~73 ~84 ~59 ~73 ~84 grass_block
fill ~60 ~60 ~84 ~63 ~68 ~84 stone
fill ~60 ~69 ~84 ~63 ~71 ~84 dirt
fill ~60 ~72 ~84 ~63 ~72 ~84 grass_block
fill ~48 ~60 ~85 ~55 ~68 ~85 stone
fill ~48 ~69 ~85 ~55 ~71 ~85 dirt
fill ~48 ~72 ~85 ~55 ~72 ~85 grass_block
fill ~56 ~60 ~85 ~60 ~69 ~85 stone
fill ~56 ~70 ~85 ~60 ~72 ~85 dirt
fill ~56 ~73 ~85 ~60 ~73 ~85 grass_block
fill ~61 ~60 ~85 ~63 ~68 ~85 stone
fill ~61 ~69 ~85 ~63 ~71 ~85 dirt
fill ~61 ~72 ~85 ~63 ~72 ~85 grass_block
fill ~48 ~60 ~86 ~48 ~67 ~86 stone
fill ~48 ~68 ~86 ~48 ~70 ~86 dirt
fill ~48 ~71 ~86 ~48 ~71 ~86 grass_block
fill ~49 ~60 ~86 ~49 ~68 ~86 stone
fill ~49 ~69 ~86 ~49 ~71 ~86 dirt
fill ~49 ~72 ~86 ~49 ~72 ~86 grass_block
fill ~50 ~60 ~86 ~52 ~67 ~86 stone
fill ~50 ~68 ~86 ~52 ~70 ~86 dirt
fill ~50 ~71 ~86 ~52 ~71 ~86 grass_block
fill ~53 ~60 ~86 ~58 ~68 ~86 stone
fill ~53 ~69 ~86 ~58 ~71 ~86 dirt
fill ~53 ~72 ~86 ~58 ~72 ~86 grass_block
fill ~59 ~60 ~86 ~61 ~69 ~86 stone
fill ~59 ~70 ~86 ~61 ~72 ~86 dirt
fill ~59 ~73 ~86 ~61 ~73 ~86 grass_block
fill ~62 ~60 ~86 ~63 ~68 ~86 stone
fill ~62 ~69 ~86 ~63 ~71 ~86 dirt
fill ~62 ~72 ~86 ~63 ~72 ~86 grass_block
fill ~48 ~60 ~87 ~53 ~67 ~87 stone
fill ~48 ~68 ~87 ~53 ~70 ~87 dirt
fill ~48 ~71 ~87 ~53 ~71 ~87 grass_block
fill ~54 ~60 ~87 ~63 ~68 ~87 stone
fill ~54 ~69 ~87 ~63 ~71 ~87 dirt
fill ~54 ~72 ~87 ~63 ~72 ~87 grass_block
fill ~48 ~60 ~88 ~56 ~67 ~88 stone
fill ~48 ~68 ~88 ~56 ~70 ~88 dirt
fill ~48 ~71 ~88 ~56 ~71 ~88 grass_block
fill ~57 ~60 ~88 ~63 ~68 ~88 stone
fill ~57 ~69 ~88 ~63 ~71 ~88 dirt
fill ~57 ~72 ~88 ~63 ~72 ~88 grass_block
fill ~48 ~60 ~89 ~57 ~67 ~89 stone
fill ~48 ~68 ~89 ~57 ~70 ~89 dirt
fill ~48 ~71 ~89 ~57 ~71 ~89 grass_block
fill ~58 ~60 ~89 ~63 ~68 ~89 stone
fill ~58 ~69 ~89 ~63 ~71 ~89 dirt
fill ~58 ~72 ~89 ~63 ~72 ~89 grass_block
fill ~48 ~60 ~90 ~49 ~66 ~90 stone
fill ~48 ~67 ~90 ~49 ~69 ~90 dirt
fill ~48 ~70 ~90 ~49 ~70 ~90 grass_block
fill ~50 ~60 ~90 ~51 ~67 ~90 stone
fill ~50 ~68 ~90 ~51 ~70 ~90 dirt
fill ~50 ~71 ~90 ~51 ~71 ~90 grass_block
fill ~52 ~60 ~90 ~53 ~66 ~90 stone
fill ~52 ~67 ~90 ~53 ~69 ~90 dirt
fill ~52 ~70 ~90 ~53 ~70 ~90 grass_block
fill ~54 ~60 ~90 ~58 ~67 ~90 stone
fill ~54 ~68 ~90 ~58 ~70 ~90 dirt
fill ~54 ~71 ~90 ~58 ~71 ~90 grass_block
fill ~59 ~60 ~90 ~63 ~68 ~90 stone
fill ~59 ~69 ~90 ~63 ~71 ~90 dirt
fill ~59 ~72 ~90 ~63 ~72 ~90 grass_block
fill ~48 ~60 ~91 ~48 ~65 ~91 stone
fill ~48 ~66 ~91 ~48 ~68 ~91 dirt
fill ~48 ~69 ~91 ~48 ~69 ~91 grass_block
fill ~49 ~60 ~91 ~50 ~66 ~91 stone
fill ~49 ~67 ~91 ~50 ~69 ~91 dirt
fill ~49 ~70 ~91 ~50 ~70 ~91 grass_block
fill ~51 ~60 ~91 ~51 ~67 ~91 stone
fill ~51 ~68 ~91 ~51 ~70 ~91 dirt
fill ~51 ~71 ~91 ~51 ~71 ~91 grass_block
fill ~52 ~60 ~91 ~56 ~66 ~91 stone
fill ~52 ~67 ~91 ~56 ~69 ~91 dirt
fill ~52 ~70 ~91 ~56 ~70 ~91 grass_block
fill ~57 ~60 ~91 ~59 ~67 ~91 stone
fill ~57 ~68 ~91 ~59 ~70 ~91 dirt
fill ~57 ~71 ~91 ~59 ~71 ~91 grass_block
fill ~60 ~60 ~91 ~63 ~68 ~91 stone
fill ~60 ~69 ~91 ~63 ~71 ~91 dirt
fill ~60 ~72 ~91 ~63 ~72 ~91 grass_block
fill ~48 ~60 ~92 ~49 ~65 ~92 stone
fill ~48 ~66 ~92 ~49 ~68 ~92 dirt
fill ~48 ~69 ~92 ~49 ~69 ~92 grass_block
fill ~50 ~60 ~92 ~56 ~66 ~92 stone
fill ~50 ~67 ~92 ~56 ~69 ~92 dirt
fill ~50 ~70 ~92 ~56 ~70 ~92 grass_block
fill ~57 ~60 ~92 ~60 ~67 ~92 stone
fill ~57 ~68 ~92 ~60 ~70 ~92 dirt
fill ~57 ~71 ~92 ~60 ~71 ~92 grass_block
fill ~61 ~60 ~92 ~63 ~68 ~92 stone
fill ~61 ~69 ~92 ~63 ~71 ~92 dirt
fill ~61 ~72 ~92 ~63 ~72 ~92 grass_block
fill ~48 ~60 ~93 ~49 ~65 ~93 stone
fill ~48 ~66 ~93 ~49 ~68 ~93 dirt
fill ~48 ~69 ~93 ~49 ~69 ~93 grass_block
fill ~50 ~60 ~93 ~57 ~66 ~93 stone
fill ~50 ~67 ~93 ~57 ~69 ~93 dirt
fill ~50 ~70 ~93 ~57 ~70 ~93 grass_block
fill ~58 ~60 ~93 ~63 ~67 ~93 stone
fill ~58 ~68 ~93 ~63 ~70 ~93 dirt
fill ~58 ~71 ~93 ~63 ~71 ~93 grass_block
fill ~48 ~60 ~94 ~48 ~64 ~94 stone
fill ~48 ~65 ~94 ~48 ~67 ~94 dirt
fill ~48 ~68 ~94 ~48 ~68 ~94 grass_block
fill ~49 ~60 ~94 ~51 ~65 ~94 stone
fill ~49 ~66 ~94 ~51 ~68 ~94 dirt
fill ~49 ~69 ~94 ~51 ~69 ~94 grass_block
fill ~52 ~60 ~94 ~57 ~66 ~94 stone
fill ~52 ~67 ~94 ~57 ~69 ~94 dirt
fill ~52 ~70 ~94 ~57 ~70 ~94 grass_block
fill ~58 ~60 ~94 ~63 ~67 ~94 stone
fill ~58 ~68 ~94 ~63 ~70 ~94 dirt
fill ~58 ~71 ~94 ~63 ~71 ~94 grass_block
fill ~48 ~60 ~95 ~49 ~64 ~95 stone
fill ~48 ~65 ~95 ~49 ~67 ~95 dirt
fill ~48 ~68 ~95 ~49 ~68 ~95 grass_block
fill ~50 ~60 ~95 ~51 ~65 ~95 stone
fill ~50 ~66 ~95 ~51 ~68 ~95 dirt
fill ~50 ~69 ~95 ~51 ~69 ~95 grass_block
fill ~52 ~60 ~95 ~54 ~66 ~95 stone
fill ~52 ~67 ~95 ~54 ~69 ~95 dirt
fill ~52 ~70 ~95 ~54 ~70 ~95 grass_block
fill ~55 ~60 ~95 ~55 ~65 ~95 stone
fill ~55 ~66 ~95 ~55 ~68 ~95 dirt
fill ~55 ~69 ~95 ~55 ~69 ~95 grass_block
fill ~56 ~60 ~95 ~59 ~66 ~95 stone
fill ~56 ~67 ~95 ~59 ~69 ~95 dirt
fill ~56 ~70 ~95 ~59 ~70 ~95 grass_block
fill ~60 ~60 ~95 ~62 ~67 ~95 stone
fill ~60 ~68 ~95 ~62 ~70 ~95 dirt
fill ~60 ~71 ~95 ~62 ~71 ~95 grass_block
fill ~63 ~60 ~95 ~63 ~66 ~95 stone
fill ~63 ~67 ~95 ~63 ~69 ~95 dirt
fill ~63 ~70 ~95 ~63 ~70 ~95 grass_block