fill ~368 ~60 ~80 ~374 ~64 ~80 stone
fill ~368 ~65 ~80 ~374 ~67 ~80 dirt
fill ~368 ~68 ~80 ~374 ~68 ~80 grass_block
fill ~375 ~60 ~80 ~378 ~63 ~80 stone
fill ~375 ~64 ~80 ~378 ~66 ~80 dirt
fill ~375 ~67 ~80 ~378 ~67 ~80 grass_block
fill ~379 ~60 ~80 ~383 ~62 ~80 stone
fill ~379 ~63 ~80 ~383 ~65 ~80 dirt
fill ~379 ~66 ~80 ~383 ~66 ~80 grass_block
fill ~368 ~60 ~81 ~369 ~65 ~81 stone
fill ~368 ~66 ~81 ~369 ~68 ~81 dirt
fill ~368 ~69 ~81 ~369 ~69 ~81 grass_block
fill ~370 ~60 ~81 ~371 ~64 ~81 stone
fill ~370 ~65 ~81 ~371 ~67 ~81 dirt
fill ~370 ~68 ~81 ~371 ~68 ~81 grass_block
fill ~372 ~60 ~81 ~373 ~65 ~81 stone
fill ~372 ~66 ~81 ~373 ~68 ~81 dirt
fill ~372 ~69 ~81 ~373 ~69 ~81 grass_block
fill ~374 ~60 ~81 ~377 ~64 ~81 stone
fill ~374 ~65 ~81 ~377 ~67 ~81 dirt
fill ~374 ~68 ~81 ~377 ~68 ~81 grass_block
fill ~378 ~60 ~81 ~380 ~63 ~81 stone
fill ~378 ~64 ~81 ~380 ~66 ~81 dirt
fill ~378 ~67 ~81 ~380 ~67 ~81 grass_block
fill ~381 ~60 ~81 ~383 ~62 ~81 stone
fill ~381 ~63 ~81 ~383 ~65 ~81 dirt
fill ~381 ~66 ~81 ~383 ~66 ~81 grass_block
fill ~368 ~60 ~82 ~375 ~65 ~82 stone
fill ~368 ~66 ~82 ~375 ~68 ~82 dirt
fill ~368 ~69 ~82 ~375 ~69 ~82 grass_block
fill ~376 ~60 ~82 ~378 ~64 ~82 stone
fill ~376 ~65 ~82 ~378 ~67 ~82 dirt
fill ~376 ~68 ~82 ~378 ~68 ~82 grass_block
fill ~379 ~60 ~82 ~382 ~63 ~82 stone
fill ~379 ~64 ~82 ~382 ~66 ~82 dirt
fill ~379 ~67 ~82 ~382 ~67 ~82 grass_block
fill ~383 ~60 ~82 ~383 ~62 ~82 stone
fill ~383 ~63 ~82 ~383 ~65 ~82 dirt
fill ~383 ~66 ~82 ~383 ~66 ~82 grass_block
fill ~368 ~60 ~83 ~376 ~65 ~83 stone
fill ~368 ~66 ~83 ~376 ~68 ~83 dirt
fill ~368 ~69 ~83 ~376 ~69 ~83 grass_block
fill ~377 ~60 ~83 ~380 ~64 ~83 stone
fill ~377 ~65 ~83 ~380 ~67 ~83 dirt
fill ~377 ~68 ~83 ~380 ~68 ~83 grass_block
fill ~381 ~60 ~83 ~383 ~63 ~83 stone
fill ~381 ~64 ~83 ~383 ~66 ~83 dirt
fill ~381 ~67 ~83 ~383 ~67 ~83 grass_block
fill ~368 ~60 ~84 ~373 ~65 ~84 stone
fill ~368 ~66 ~84 ~373 ~68 ~84 dirt
fill ~368 ~69 ~84 ~373 ~69 ~84 grass_block
fill ~374 ~60 ~84 ~375 ~66 ~84 stone
fill ~374 ~67 ~84 ~375 ~69 ~84 dirt
fill ~374 ~70 ~84 ~375 ~70 ~84 grass_block
fill ~376 ~60 ~84 ~378 ~65 ~84 stone
fill ~376 ~66 ~84 ~378 ~68 ~84 dirt
fill ~376 ~69 ~84 ~378 ~69 ~84 grass_block
fill ~379 ~60 ~84 ~383 ~64 ~84 stone
fill ~379 ~65 ~84 ~383 ~67 ~84 dirt
fill ~379 ~68 ~84 ~383 ~68 ~84 grass_block
fill ~368 ~60 ~85 ~373 ~65 ~85 stone
fill ~368 ~66 ~85 ~373 ~68 ~85 dirt
fill ~368 ~69 ~85 ~373 ~69 ~85 grass_block
fill ~374 ~60 ~85 ~376 ~66 ~85 stone
fill ~374 ~67 ~85 ~376 ~69 ~85 dirt
fill ~374 ~70 ~85 ~376 ~70 ~85 grass_block
fill ~377 ~60 ~85 ~377 ~65 ~85 stone
fill ~377 ~66 ~85 ~377 ~68 ~85 dirt
fill ~377 ~69 ~85 ~377 ~69 ~85 grass_block
fill ~378 ~60 ~85 ~381 ~64 ~85 stone
fill ~378 ~65 ~85 ~381 ~67 ~85 dirt
fill ~378 ~68 ~85 ~381 ~68 ~85 grass_block
fill ~382 ~60 ~85 ~383 ~63 ~85 stone
fill ~382 ~64 ~85 ~383 ~66 ~85 dirt
fill ~382 ~67 ~85 ~383 ~67 ~85 grass_block
fill ~368 ~60 ~86 ~368 ~64 ~86 stone
fill ~368 ~65 ~86 ~368 ~67 ~86 dirt
fill ~368 ~68 ~86 ~368 ~68 ~86 grass_block
fill ~369 ~60 ~86 ~373 ~65 ~86 stone
fill ~369 ~66 ~86 ~373 ~68 ~86 dirt
fill ~369 ~69 ~86 ~373 ~69 ~86 grass_block
fill ~374 ~60 ~86 ~376 ~66 ~86 stone
fill ~374 ~67 ~86 ~376 ~69 ~86 dirt
fill ~374 ~70 ~86 ~376 ~70 ~86 grass_block
fill ~377 ~60 ~86 ~378 ~65 ~86 stone
fill ~377 ~66 ~86 ~378 ~68 ~86 dirt
fill ~377 ~69 ~86 ~378 ~69 ~86 grass_block
fill ~379 ~60 ~86 ~380 ~64 ~86 stone
fill ~379 ~65 ~86 ~380 ~67 ~86 dirt
fill ~379 ~68 ~86 ~380 ~68 ~86 grass_block
fill ~381 ~60 ~86 ~383 ~63 ~86 stone
fill ~381 ~64 ~86 ~383 ~66 ~86 dirt
fill ~381 ~67 ~86 ~383 ~67 ~86 grass_block
fill ~368 ~60 ~87 ~368 ~64 ~87 stone
fill ~368 ~65 ~87 ~368 ~67 ~87 dirt
fill ~368 ~68 ~87 ~368 ~68 ~87 grass_block
fill ~369 ~60 ~87 ~373 ~65 ~87 stone
fill ~369 ~66 ~87 ~373 ~68 ~87 dirt
fill ~369 ~69 ~87 ~373 ~69 ~87 grass_block
fill ~374 ~60 ~87 ~377 ~66 ~87 stone
fill ~374 ~67 ~87 ~377 ~69 ~87 dirt
fill ~374 ~70 ~87 ~377 ~70 ~87 grass_block
fill ~378 ~60 ~87 ~379 ~65 ~87 stone
fill ~378 ~66 ~87 ~379 ~68 ~87 dirt
fill ~378 ~69 ~87 ~379 ~69 ~87 grass_block
fill ~380 ~60 ~87 ~381 ~64 ~87 stone
fill ~380 ~65 ~87 ~381 ~67 ~87 dirt
fill ~380 ~68 ~87 ~381 ~68 ~87 grass_block
fill ~382 ~60 ~87 ~382 ~63 ~87 stone
fill ~382 ~64 ~87 ~382 ~66 ~87 dirt
fill ~382 ~67 ~87 ~382 ~67 ~87 grass_block
fill ~383 ~60 ~87 ~383 ~64 ~87 stone
fill ~383 ~65 ~87 ~383 ~67 ~87 dirt
fill ~383 ~68 ~87 ~383 ~68 ~87 grass_block
fill ~368 ~60 ~88 ~368 ~64 ~88 stone
fill ~368 ~65 ~88 ~368 ~67 ~88 dirt
fill ~368 ~68 ~88 ~368 ~68 ~88 grass_block
fill ~369 ~60 ~88 ~377 ~65 ~88 stone
fill ~369 ~66 ~88 ~377 ~68 ~88 dirt
fill ~369 ~69 ~88 ~377 ~69 ~88 grass_block
fill ~378 ~60 ~88 ~378 ~66 ~88 stone
fill ~378 ~67 ~88 ~378 ~69 ~88 dirt
fill ~378 ~70 ~88 ~378 ~70 ~88 grass_block
fill ~379 ~60 ~88 ~383 ~65 ~88 stone
fill ~379 ~66 ~88 ~383 ~68 ~88 dirt
fill ~379 ~69 ~88 ~383 ~69 ~88 grass_block
fill ~368 ~60 ~89 ~368 ~64 ~89 stone
fill ~368 ~65 ~89 ~368 ~67 ~89 dirt
fill ~368 ~68 ~89 ~368 ~68 ~89 grass_block
fill ~369 ~60 ~89 ~383 ~65 ~89 stone
fill ~369 ~66 ~89 ~383 ~68 ~89 dirt
fill ~369 ~69 ~89 ~383 ~69 ~89 grass_block
fill ~368 ~60 ~90 ~368 ~64 ~90 stone
fill ~368 ~65 ~90 ~368 ~67 ~90 dirt
fill ~368 ~68 ~90 ~368 ~68 ~90 grass_block
fill ~369 ~60 ~90 ~383 ~65 ~90 stone
fill ~369 ~66 ~90 ~383 ~68 ~90 dirt
fill ~369 ~69 ~90 ~383 ~69 ~90 grass_block
fill ~368 ~60 ~91 ~368 ~64 ~91 stone
fill ~368 ~65 ~91 ~368 ~67 ~91 dirt
fill ~368 ~68 ~91 ~368 ~68 ~91 grass_block
fill ~369 ~60 ~91 ~378 ~65 ~91 stone
fill ~369 ~66 ~91 ~378 ~68 ~91 dirt
fill ~369 ~69 ~91 ~378 ~69 ~91 grass_block
fill ~379 ~60 ~91 ~379 ~64 ~91 stone
fill ~379 ~65 ~91 ~379 ~67 ~91 dirt
fill ~379 ~68 ~91 ~379 ~68 ~91 grass_block
fill ~380 ~60 ~91 ~383 ~65 ~91 stone
fill ~380 ~66 ~91 ~383 ~68 ~91 dirt
fill ~380 ~69 ~91 ~383 ~69 ~91 grass_block
fill ~368 ~60 ~92 ~371 ~65 ~92 stone
fill ~368 ~66 ~92 ~371 ~68 ~92 dirt
fill ~368 ~69 ~92 ~371 ~69 ~92 grass_block
fill ~372 ~60 ~92 ~381 ~64 ~92 stone
fill ~372 ~65 ~92 ~381 ~67 ~92 dirt
fill ~372 ~68 ~92 ~381 ~68 ~92 grass_block
fill ~382 ~60 ~92 ~383 ~65 ~92 stone
fill ~382 ~66 ~92 ~383 ~68 ~92 dirt
fill ~382 ~69 ~92 ~383 ~69 ~92 grass_block
fill ~368 ~60 ~93 ~371 ~65 ~93 stone
fill ~368 ~66 ~93 ~371 ~68 ~93 dirt
fill ~368 ~69 ~93 ~371 ~69 ~93 grass_block
fill ~372 ~60 ~93 ~382 ~64 ~93 stone
fill ~372 ~65 ~93 ~382 ~67 ~93 dirt
fill ~372 ~68 ~93 ~382 ~68 ~93 grass_block
fill ~383 ~60 ~93 ~383 ~65 ~93 stone
fill ~383 ~66 ~93 ~383 ~68 ~93 dirt
fill ~383 ~69 ~93 ~383 ~69 ~93 grass_block
fill ~368 ~60 ~94 ~371 ~65 ~94 stone
fill ~368 ~66 ~94 ~371 ~68 ~94 dirt
fill ~368 ~69 ~94 ~371 ~69 ~94 grass_block
fill ~372 ~60 ~94 ~382 ~64 ~94 stone
fill ~372 ~65 ~94 ~382 ~67 ~94 dirt
fill ~372 ~68 ~94 ~382 ~68 ~94 grass_block
fill ~383 ~60 ~94 ~383 ~65 ~94 stone
fill ~383 ~66 ~94 ~383 ~68 ~94 dirt
fill ~383 ~69 ~94 ~383 ~69 ~94 grass_block
fill ~368 ~60 ~95 ~371 ~65 ~95 stone
fill ~368 ~66 ~95 ~371 ~68 ~95 dirt
fill ~368 ~69 ~95 ~371 ~69 ~95 grass_block
fill ~372 ~60 ~95 ~376 ~64 ~95 stone
fill ~372 ~65 ~95 ~376 ~67 ~95 dirt
fill ~372 ~68 ~95 ~376 ~68 ~95 grass_block
fill ~377 ~60 ~95 ~377 ~63 ~95 stone
fill ~377 ~64 ~95 ~377 ~66 ~95 dirt
fill ~377 ~67 ~95 ~377 ~67 ~95 grass_block
fill ~378 ~60 ~95 ~383 ~64 ~95 stone
fill ~378 ~65 ~95 ~383 ~67 ~95 dirt
fill ~378 ~68 ~95 ~383 ~68 ~95 grass_block