fill ~336 ~60 ~80 ~337 ~63 ~80 stone
fill ~336 ~64 ~80 ~337 ~66 ~80 dirt
fill ~336 ~67 ~80 ~337 ~67 ~80 grass_block
fill ~338 ~60 ~80 ~344 ~64 ~80 stone
fill ~338 ~65 ~80 ~344 ~67 ~80 dirt
fill ~338 ~68 ~80 ~344 ~68 ~80 grass_block
fill ~345 ~60 ~80 ~349 ~63 ~80 stone
fill ~345 ~64 ~80 ~349 ~66 ~80 dirt
fill ~345 ~67 ~80 ~349 ~67 ~80 grass_block
fill ~350 ~60 ~80 ~351 ~64 ~80 stone
fill ~350 ~65 ~80 ~351 ~67 ~80 dirt
fill ~350 ~68 ~80 ~351 ~68 ~80 grass_block
fill ~336 ~60 ~81 ~337 ~63 ~81 stone
fill ~336 ~64 ~81 ~337 ~66 ~81 dirt
fill ~336 ~67 ~81 ~337 ~67 ~81 grass_block
fill ~338 ~60 ~81 ~343 ~64 ~81 stone
fill ~338 ~65 ~81 ~343 ~67 ~81 dirt
fill ~338 ~68 ~81 ~343 ~68 ~81 grass_block
fill ~344 ~60 ~81 ~350 ~63 ~81 stone
fill ~344 ~64 ~81 ~350 ~66 ~81 dirt
fill ~344 ~67 ~81 ~350 ~67 ~81 grass_block
fill ~351 ~60 ~81 ~351 ~64 ~81 stone
fill ~351 ~65 ~81 ~351 ~67 ~81 dirt
fill ~351 ~68 ~81 ~351 ~68 ~81 grass_block
fill ~336 ~60 ~82 ~337 ~63 ~82 stone
fill ~336 ~64 ~82 ~337 ~66 ~82 dirt
fill ~336 ~67 ~82 ~337 ~67 ~82 grass_block
fill ~338 ~60 ~82 ~343 ~64 ~82 stone
fill ~338 ~65 ~82 ~343 ~67 ~82 dirt
fill ~338 ~68 ~82 ~343 ~68 ~82 grass_block
fill ~344 ~60 ~82 ~351 ~63 ~82 stone
fill ~344 ~64 ~82 ~351 ~66 ~82 dirt
fill ~344 ~67 ~82 ~351 ~67 ~82 grass_block
fill ~336 ~60 ~83 ~337 ~63 ~83 stone
fill ~336 ~64 ~83 ~337 ~66 ~83 dirt
fill ~336 ~67 ~83 ~337 ~67 ~83 grass_block
fill ~338 ~60 ~83 ~342 ~64 ~83 stone
fill ~338 ~65 ~83 ~342 ~67 ~83 dirt
fill ~338 ~68 ~83 ~342 ~68 ~83 grass_block
fill ~343 ~60 ~83 ~351 ~63 ~83 stone
fill ~343 ~64 ~83 ~351 ~66 ~83 dirt
fill ~343 ~67 ~83 ~351 ~67 ~83 grass_block
fill ~336 ~60 ~84 ~340 ~63 ~84 stone
fill ~336 ~64 ~84 ~340 ~66 ~84 dirt
fill ~336 ~67 ~84 ~340 ~67 ~84 grass_block
fill ~341 ~60 ~84 ~343 ~64 ~84 stone
fill ~341 ~65 ~84 ~343 ~67 ~84 dirt
fill ~341 ~68 ~84 ~343 ~68 ~84 grass_block
fill ~344 ~60 ~84 ~351 ~63 ~84 stone
fill ~344 ~64 ~84 ~351 ~66 ~84 dirt
fill ~344 ~67 ~84 ~351 ~67 ~84 grass_block
fill ~336 ~60 ~85 ~341 ~63 ~85 stone
fill ~336 ~64 ~85 ~341 ~66 ~85 dirt
fill ~336 ~67 ~85 ~341 ~67 ~85 grass_block
fill ~342 ~60 ~85 ~342 ~64 ~85 stone
fill ~342 ~65 ~85 ~342 ~67 ~85 dirt
fill ~342 ~68 ~85 ~342 ~68 ~85 grass_block
fill ~343 ~60 ~85 ~351 ~63 ~85 stone
fill ~343 ~64 ~85 ~351 ~66 ~85 dirt
fill ~343 ~67 ~85 ~351 ~67 ~85 grass_block
fill ~336 ~60 ~86 ~351 ~63 ~86 stone
fill ~336 ~64 ~86 ~351 ~66 ~86 dirt
fill ~336 ~67 ~86 ~351 ~67 ~86 grass_block
fill ~336 ~60 ~87 ~347 ~63 ~87 stone
fill ~336 ~64 ~87 ~347 ~66 ~87 dirt
fill ~336 ~67 ~87 ~347 ~67 ~87 grass_block
fill ~348 ~60 ~87 ~348 ~62 ~87 stone
fill ~348 ~63 ~87 ~348 ~65 ~87 dirt
fill ~348 ~66 ~87 ~348 ~66 ~87 grass_block
fill ~349 ~60 ~87 ~351 ~63 ~87 stone
fill ~349 ~64 ~87 ~351 ~66 ~87 dirt
fill ~349 ~67 ~87 ~351 ~67 ~87 grass_block
fill ~336 ~60 ~88 ~338 ~62 ~88 stone
fill ~336 ~63 ~88 ~338 ~65 ~88 dirt
fill ~336 ~66 ~88 ~338 ~66 ~88 grass_block
fill ~339 ~60 ~88 ~347 ~63 ~88 stone
fill ~339 ~64 ~88 ~347 ~66 ~88 dirt
fill ~339 ~67 ~88 ~347 ~67 ~88 grass_block
fill ~348 ~60 ~88 ~349 ~62 ~88 stone
fill ~348 ~63 ~88 ~349 ~65 ~88 dirt
fill ~348 ~66 ~88 ~349 ~66 ~88 grass_block
fill ~350 ~60 ~88 ~351 ~63 ~88 stone
fill ~350 ~64 ~88 ~351 ~66 ~88 dirt
fill ~350 ~67 ~88 ~351 ~67 ~88 grass_block
fill ~336 ~60 ~89 ~339 ~62 ~89 stone
fill ~336 ~63 ~89 ~339 ~65 ~89 dirt
fill ~336 ~66 ~89 ~339 ~66 ~89 grass_block
fill ~340 ~60 ~89 ~348 ~63 ~89 stone
fill ~340 ~64 ~89 ~348 ~66 ~89 dirt
fill ~340 ~67 ~89 ~348 ~67 ~89 grass_block
fill ~349 ~60 ~89 ~350 ~62 ~89 stone
fill ~349 ~63 ~89 ~350 ~65 ~89 dirt
fill ~349 ~66 ~89 ~350 ~66 ~89 grass_block
fill ~351 ~60 ~89 ~351 ~63 ~89 stone
fill ~351 ~64 ~89 ~351 ~66 ~89 dirt
fill ~351 ~67 ~89 ~351 ~67 ~89 grass_block
fill ~336 ~60 ~90 ~341 ~62 ~90 stone
fill ~336 ~63 ~90 ~341 ~65 ~90 dirt
fill ~336 ~66 ~90 ~341 ~66 ~90 grass_block
fill ~342 ~60 ~90 ~348 ~63 ~90 stone
fill ~342 ~64 ~90 ~348 ~66 ~90 dirt
fill ~342 ~67 ~90 ~348 ~67 ~90 grass_block
fill ~349 ~60 ~90 ~351 ~62 ~90 stone
fill ~349 ~63 ~90 ~351 ~65 ~90 dirt
fill ~349 ~66 ~90 ~351 ~66 ~90 grass_block
fill ~336 ~60 ~91 ~338 ~61 ~91 stone
fill ~336 ~62 ~91 ~338 ~64 ~91 dirt
fill ~336 ~65 ~91 ~338 ~65 ~91 grass_block
fill ~339 ~60 ~91 ~342 ~62 ~91 stone
fill ~339 ~63 ~91 ~342 ~65 ~91 dirt
fill ~339 ~66 ~91 ~342 ~66 ~91 grass_block
fill ~343 ~60 ~91 ~348 ~63 ~91 stone
fill ~343 ~64 ~91 ~348 ~66 ~91 dirt
fill ~343 ~67 ~91 ~348 ~67 ~91 grass_block
fill ~349 ~60 ~91 ~351 ~62 ~91 stone
fill ~349 ~63 ~91 ~351 ~65 ~91 dirt
fill ~349 ~66 ~91 ~351 ~66 ~91 grass_block
fill ~336 ~60 ~92 ~339 ~61 ~92 stone
fill ~336 ~62 ~92 ~339 ~64 ~92 dirt
fill ~336 ~65 ~92 ~339 ~65 ~92 grass_block
fill ~340 ~60 ~92 ~343 ~62 ~92 stone
fill ~340 ~63 ~92 ~343 ~65 ~92 dirt
fill ~340 ~66 ~92 ~343 ~66 ~92 grass_block
fill ~344 ~60 ~92 ~348 ~63 ~92 stone
fill ~344 ~64 ~92 ~348 ~66 ~92 dirt
fill ~344 ~67 ~92 ~348 ~67 ~92 grass_block
fill ~349 ~60 ~92 ~351 ~62 ~92 stone
fill ~349 ~63 ~92 ~351 ~65 ~92 dirt
fill ~349 ~66 ~92 ~351 ~66 ~92 grass_block
fill ~336 ~60 ~93 ~340 ~61 ~93 stone
fill ~336 ~62 ~93 ~340 ~64 ~93 dirt
fill ~336 ~65 ~93 ~340 ~65 ~93 grass_block
fill ~341 ~60 ~93 ~344 ~62 ~93 stone
fill ~341 ~63 ~93 ~344 ~65 ~93 dirt
fill ~341 ~66 ~93 ~344 ~66 ~93 grass_block
fill ~345 ~60 ~93 ~349 ~63 ~93 stone
fill ~345 ~64 ~93 ~349 ~66 ~93 dirt
fill ~345 ~67 ~93 ~349 ~67 ~93 grass_block
fill ~350 ~60 ~93 ~351 ~62 ~93 stone
fill ~350 ~63 ~93 ~351 ~65 ~93 dirt
fill ~350 ~66 ~93 ~351 ~66 ~93 grass_block
fill ~336 ~60 ~94 ~340 ~61 ~94 stone
fill ~336 ~62 ~94 ~340 ~64 ~94 dirt
fill ~336 ~65 ~94 ~340 ~65 ~94 grass_block
fill ~341 ~60 ~94 ~344 ~62 ~94 stone
fill ~341 ~63 ~94 ~344 ~65 ~94 dirt
fill ~341 ~66 ~94 ~344 ~66 ~94 grass_block
fill ~345 ~60 ~94 ~349 ~63 ~94 stone
fill ~345 ~64 ~94 ~349 ~66 ~94 dirt
fill ~345 ~67 ~94 ~349 ~67 ~94 grass_block
fill ~350 ~60 ~94 ~351 ~62 ~94 stone
fill ~350 ~63 ~94 ~351 ~65 ~94 dirt
fill ~350 ~66 ~94 ~351 ~66 ~94 grass_block
fill ~336 ~60 ~95 ~336 ~60 ~95 stone
fill ~336 ~61 ~95 ~336 ~63 ~95 dirt
fill ~336 ~64 ~95 ~336 ~64 ~95 grass_block
fill ~337 ~60 ~95 ~342 ~61 ~95 stone
fill ~337 ~62 ~95 ~342 ~64 ~95 dirt
fill ~337 ~65 ~95 ~342 ~65 ~95 grass_block
fill ~343 ~60 ~95 ~346 ~62 ~95 stone
fill ~343 ~63 ~95 ~346 ~65 ~95 dirt
fill ~343 ~66 ~95 ~346 ~66 ~95 grass_block
fill ~347 ~60 ~95 ~349 ~63 ~95 stone
fill ~347 ~64 ~95 ~349 ~66 ~95 dirt
fill ~347 ~67 ~95 ~349 ~67 ~95 grass_block
fill ~350 ~60 ~95 ~351 ~62 ~95 stone
fill ~350 ~63 ~95 ~351 ~65 ~95 dirt
fill ~350 ~66 ~95 ~351 ~66 ~95 grass_block