fill ~272 ~60 ~48 ~287 ~61 ~48 stone
fill ~272 ~62 ~48 ~287 ~64 ~48 dirt
fill ~272 ~65 ~48 ~287 ~65 ~48 grass_block
fill ~272 ~60 ~49 ~287 ~61 ~49 stone
fill ~272 ~62 ~49 ~287 ~64 ~49 dirt
fill ~272 ~65 ~49 ~287 ~65 ~49 grass_block
fill ~272 ~60 ~50 ~287 ~61 ~50 stone
fill ~272 ~62 ~50 ~287 ~64 ~50 dirt
fill ~272 ~65 ~50 ~287 ~65 ~50 grass_block
fill ~272 ~60 ~51 ~287 ~61 ~51 stone
fill ~272 ~62 ~51 ~287 ~64 ~51 dirt
fill ~272 ~65 ~51 ~287 ~65 ~51 grass_block
fill ~272 ~60 ~52 ~287 ~61 ~52 stone
fill ~272 ~62 ~52 ~287 ~64 ~52 dirt
fill ~272 ~65 ~52 ~287 ~65 ~52 grass_block
fill ~272 ~60 ~53 ~287 ~61 ~53 stone
fill ~272 ~62 ~53 ~287 ~64 ~53 dirt
fill ~272 ~65 ~53 ~287 ~65 ~53 grass_block
fill ~272 ~60 ~54 ~287 ~61 ~54 stone
fill ~272 ~62 ~54 ~287 ~64 ~54 dirt
fill ~272 ~65 ~54 ~287 ~65 ~54 grass_block
fill ~272 ~60 ~55 ~287 ~61 ~55 stone
fill ~272 ~62 ~55 ~287 ~64 ~55 dirt
fill ~272 ~65 ~55 ~287 ~65 ~55 grass_block
fill ~272 ~60 ~56 ~287 ~61 ~56 stone
fill ~272 ~62 ~56 ~287 ~64 ~56 dirt
fill ~272 ~65 ~56 ~287 ~65 ~56 grass_block
fill ~272 ~60 ~57 ~283 ~61 ~57 stone
fill ~272 ~62 ~57 ~283 ~64 ~57 dirt
fill ~272 ~65 ~57 ~283 ~65 ~57 grass_block
fill ~284 ~60 ~57 ~285 ~60 ~57 stone
fill ~284 ~61 ~57 ~285 ~63 ~57 dirt
fill ~284 ~64 ~57 ~285 ~64 ~57 grass_block
fill ~286 ~60 ~57 ~287 ~61 ~57 stone
fill ~286 ~62 ~57 ~287 ~64 ~57 dirt
fill ~286 ~65 ~57 ~287 ~65 ~57 grass_block
fill ~272 ~60 ~58 ~272 ~62 ~58 stone
fill ~272 ~63 ~58 ~272 ~65 ~58 dirt
fill ~272 ~66 ~58 ~272 ~66 ~58 grass_block
fill ~273 ~60 ~58 ~282 ~61 ~58 stone
fill ~273 ~62 ~58 ~282 ~64 ~58 dirt
fill ~273 ~65 ~58 ~282 ~65 ~58 grass_block
fill ~283 ~60 ~58 ~283 ~60 ~58 stone
fill ~283 ~61 ~58 ~283 ~63 ~58 dirt
fill ~283 ~64 ~58 ~283 ~64 ~58 grass_block
fill ~284 ~60 ~58 ~287 ~61 ~58 stone
fill ~284 ~62 ~58 ~287 ~64 ~58 dirt
fill ~284 ~65 ~58 ~287 ~65 ~58 grass_block
fill ~272 ~60 ~59 ~273 ~62 ~59 stone
fill ~272 ~63 ~59 ~273 ~65 ~59 dirt
fill ~272 ~66 ~59 ~273 ~66 ~59 grass_block
fill ~274 ~60 ~59 ~287 ~61 ~59 stone
fill ~274 ~62 ~59 ~287 ~64 ~59 dirt
fill ~274 ~65 ~59 ~287 ~65 ~59 grass_block
fill ~272 ~60 ~60 ~273 ~62 ~60 stone
fill ~272 ~63 ~60 ~273 ~65 ~60 dirt
fill ~272 ~66 ~60 ~273 ~66 ~60 grass_block
fill ~274 ~60 ~60 ~287 ~61 ~60 stone
fill ~274 ~62 ~60 ~287 ~64 ~60 dirt
fill ~274 ~65 ~60 ~287 ~65 ~60 grass_block
fill ~272 ~60 ~61 ~273 ~62 ~61 stone
fill ~272 ~63 ~61 ~273 ~65 ~61 dirt
fill ~272 ~66 ~61 ~273 ~66 ~61 grass_block
fill ~274 ~60 ~61 ~287 ~61 ~61 stone
fill ~274 ~62 ~61 ~287 ~64 ~61 dirt
fill ~274 ~65 ~61 ~287 ~65 ~61 grass_block
fill ~272 ~60 ~62 ~272 ~62 ~62 stone
fill ~272 ~63 ~62 ~272 ~65 ~62 dirt
fill ~272 ~66 ~62 ~272 ~66 ~62 grass_block
fill ~273 ~60 ~62 ~273 ~61 ~62 stone
fill ~273 ~62 ~62 ~273 ~64 ~62 dirt
fill ~273 ~65 ~62 ~273 ~65 ~62 grass_block
fill ~274 ~60 ~62 ~274 ~62 ~62 stone
fill ~274 ~63 ~62 ~274 ~65 ~62 dirt
fill ~274 ~66 ~62 ~274 ~66 ~62 grass_block
fill ~275 ~60 ~62 ~287 ~61 ~62 stone
fill ~275 ~62 ~62 ~287 ~64 ~62 dirt
fill ~275 ~65 ~62 ~287 ~65 ~62 grass_block
fill ~272 ~60 ~63 ~273 ~62 ~63 stone
fill ~272 ~63 ~63 ~273 ~65 ~63 dirt
fill ~272 ~66 ~63 ~273 ~66 ~63 grass_block
fill ~274 ~60 ~63 ~287 ~61 ~63 stone
fill ~274 ~62 ~63 ~287 ~64 ~63 dirt
fill ~274 ~65 ~63 ~287 ~65 ~63 grass_block