fill ~304 ~60 ~96 ~312 ~61 ~96 stone
fill ~304 ~62 ~96 ~312 ~64 ~96 dirt
fill ~304 ~65 ~96 ~312 ~65 ~96 grass_block
fill ~313 ~60 ~96 ~315 ~62 ~96 stone
fill ~313 ~63 ~96 ~315 ~65 ~96 dirt
fill ~313 ~66 ~96 ~315 ~66 ~96 grass_block
fill ~316 ~60 ~96 ~319 ~61 ~96 stone
fill ~316 ~62 ~96 ~319 ~64 ~96 dirt
fill ~316 ~65 ~96 ~319 ~65 ~96 grass_block
fill ~304 ~60 ~97 ~304 ~62 ~97 stone
fill ~304 ~63 ~97 ~304 ~65 ~97 dirt
fill ~304 ~66 ~97 ~304 ~66 ~97 grass_block
fill ~305 ~60 ~97 ~309 ~61 ~97 stone
fill ~305 ~62 ~97 ~309 ~64 ~97 dirt
fill ~305 ~65 ~97 ~309 ~65 ~97 grass_block
fill ~310 ~60 ~97 ~317 ~62 ~97 stone
fill ~310 ~63 ~97 ~317 ~65 ~97 dirt
fill ~310 ~66 ~97 ~317 ~66 ~97 grass_block
fill ~318 ~60 ~97 ~319 ~61 ~97 stone
fill ~318 ~62 ~97 ~319 ~64 ~97 dirt
fill ~318 ~65 ~97 ~319 ~65 ~97 grass_block
fill ~304 ~60 ~98 ~304 ~62 ~98 stone
fill ~304 ~63 ~98 ~304 ~65 ~98 dirt
fill ~304 ~66 ~98 ~304 ~66 ~98 grass_block
fill ~305 ~60 ~98 ~309 ~61 ~98 stone
fill ~305 ~62 ~98 ~309 ~64 ~98 dirt
fill ~305 ~65 ~98 ~309 ~65 ~98 grass_block
fill ~310 ~60 ~98 ~318 ~62 ~98 stone
fill ~310 ~63 ~98 ~318 ~65 ~98 dirt
fill ~310 ~66 ~98 ~318 ~66 ~98 grass_block
fill ~319 ~60 ~98 ~319 ~61 ~98 stone
fill ~319 ~62 ~98 ~319 ~64 ~98 dirt
fill ~319 ~65 ~98 ~319 ~65 ~98 grass_block
fill ~304 ~60 ~99 ~304 ~62 ~99 stone
fill ~304 ~63 ~99 ~304 ~65 ~99 dirt
fill ~304 ~66 ~99 ~304 ~66 ~99 grass_block
fill ~305 ~60 ~99 ~309 ~61 ~99 stone
fill ~305 ~62 ~99 ~309 ~64 ~99 dirt
fill ~305 ~65 ~99 ~309 ~65 ~99 grass_block
fill ~310 ~60 ~99 ~319 ~62 ~99 stone
fill ~310 ~63 ~99 ~319 ~65 ~99 dirt
fill ~310 ~66 ~99 ~319 ~66 ~99 grass_block
fill ~304 ~60 ~100 ~306 ~61 ~100 stone
fill ~304 ~62 ~100 ~306 ~64 ~100 dirt
fill ~304 ~65 ~100 ~306 ~65 ~100 grass_block
fill ~307 ~60 ~100 ~307 ~62 ~100 stone
fill ~307 ~63 ~100 ~307 ~65 ~100 dirt
fill ~307 ~66 ~100 ~307 ~66 ~100 grass_block
fill ~308 ~60 ~100 ~308 ~61 ~100 stone
fill ~308 ~62 ~100 ~308 ~64 ~100 dirt
fill ~308 ~65 ~100 ~308 ~65 ~100 grass_block
fill ~309 ~60 ~100 ~319 ~62 ~100 stone
fill ~309 ~63 ~100 ~319 ~65 ~100 dirt
fill ~309 ~66 ~100 ~319 ~66 ~100 grass_block
fill ~304 ~60 ~101 ~305 ~61 ~101 stone
fill ~304 ~62 ~101 ~305 ~64 ~101 dirt
fill ~304 ~65 ~101 ~305 ~65 ~101 grass_block
fill ~306 ~60 ~101 ~319 ~62 ~101 stone
fill ~306 ~63 ~101 ~319 ~65 ~101 dirt
fill ~306 ~66 ~101 ~319 ~66 ~101 grass_block
fill ~304 ~60 ~102 ~304 ~61 ~102 stone
fill ~304 ~62 ~102 ~304 ~64 ~102 dirt
fill ~304 ~65 ~102 ~304 ~65 ~102 grass_block
fill ~305 ~60 ~102 ~319 ~62 ~102 stone
fill ~305 ~63 ~102 ~319 ~65 ~102 dirt
fill ~305 ~66 ~102 ~319 ~66 ~102 grass_block
fill ~304 ~60 ~103 ~319 ~62 ~103 stone
fill ~304 ~63 ~103 ~319 ~65 ~103 dirt
fill ~304 ~66 ~103 ~319 ~66 ~103 grass_block
fill ~304 ~60 ~104 ~308 ~63 ~104 stone
fill ~304 ~64 ~104 ~308 ~66 ~104 dirt
fill ~304 ~67 ~104 ~308 ~67 ~104 grass_block
fill ~309 ~60 ~104 ~319 ~62 ~104 stone
fill ~309 ~63 ~104 ~319 ~65 ~104 dirt
fill ~309 ~66 ~104 ~319 ~66 ~104 grass_block
fill ~304 ~60 ~105 ~308 ~63 ~105 stone
fill ~304 ~64 ~105 ~308 ~66 ~105 dirt
fill ~304 ~67 ~105 ~308 ~67 ~105 grass_block
fill ~309 ~60 ~105 ~310 ~62 ~105 stone
fill ~309 ~63 ~105 ~310 ~65 ~105 dirt
fill ~309 ~66 ~105 ~310 ~66 ~105 grass_block
fill ~311 ~60 ~105 ~311 ~63 ~105 stone
fill ~311 ~64 ~105 ~311 ~66 ~105 dirt
fill ~311 ~67 ~105 ~311 ~67 ~105 grass_block
fill ~312 ~60 ~105 ~319 ~62 ~105 stone
fill ~312 ~63 ~105 ~319 ~65 ~105 dirt
fill ~312 ~66 ~105 ~319 ~66 ~105 grass_block
fill ~304 ~60 ~106 ~309 ~63 ~106 stone
fill ~304 ~64 ~106 ~309 ~66 ~106 dirt
fill ~304 ~67 ~106 ~309 ~67 ~106 grass_block
fill ~310 ~60 ~106 ~319 ~62 ~106 stone
fill ~310 ~63 ~106 ~319 ~65 ~106 dirt
fill ~310 ~66 ~106 ~319 ~66 ~106 grass_block
fill ~304 ~60 ~107 ~311 ~63 ~107 stone
fill ~304 ~64 ~107 ~311 ~66 ~107 dirt
fill ~304 ~67 ~107 ~311 ~67 ~107 grass_block
fill ~312 ~60 ~107 ~319 ~62 ~107 stone
fill ~312 ~63 ~107 ~319 ~65 ~107 dirt
fill ~312 ~66 ~107 ~319 ~66 ~107 grass_block
fill ~304 ~60 ~108 ~313 ~63 ~108 stone
fill ~304 ~64 ~108 ~313 ~66 ~108 dirt
fill ~304 ~67 ~108 ~313 ~67 ~108 grass_block
fill ~314 ~60 ~108 ~319 ~62 ~108 stone
fill ~314 ~63 ~108 ~319 ~65 ~108 dirt
fill ~314 ~66 ~108 ~319 ~66 ~108 grass_block
fill ~304 ~60 ~109 ~315 ~63 ~109 stone
fill ~304 ~64 ~109 ~315 ~66 ~109 dirt
fill ~304 ~67 ~109 ~315 ~67 ~109 grass_block
fill ~316 ~60 ~109 ~319 ~62 ~109 stone
fill ~316 ~63 ~109 ~319 ~65 ~109 dirt
fill ~316 ~66 ~109 ~319 ~66 ~109 grass_block
fill ~304 ~60 ~110 ~304 ~64 ~110 stone
fill ~304 ~65 ~110 ~304 ~67 ~110 dirt
fill ~304 ~68 ~110 ~304 ~68 ~110 grass_block
fill ~305 ~60 ~110 ~317 ~63 ~110 stone
fill ~305 ~64 ~110 ~317 ~66 ~110 dirt
fill ~305 ~67 ~110 ~317 ~67 ~110 grass_block
fill ~318 ~60 ~110 ~319 ~62 ~110 stone
fill ~318 ~63 ~110 ~319 ~65 ~110 dirt
fill ~318 ~66 ~110 ~319 ~66 ~110 grass_block
fill ~304 ~60 ~111 ~308 ~64 ~111 stone
fill ~304 ~65 ~111 ~308 ~67 ~111 dirt
fill ~304 ~68 ~111 ~308 ~68 ~111 grass_block
fill ~309 ~60 ~111 ~318 ~63 ~111 stone
fill ~309 ~64 ~111 ~318 ~66 ~111 dirt
fill ~309 ~67 ~111 ~318 ~67 ~111 grass_block
fill ~319 ~60 ~111 ~319 ~62 ~111 stone
fill ~319 ~63 ~111 ~319 ~65 ~111 dirt
fill ~319 ~66 ~111 ~319 ~66 ~111 grass_block