fill ~384 ~60 ~96 ~390 ~65 ~96 stone
fill ~384 ~66 ~96 ~390 ~68 ~96 dirt
fill ~384 ~69 ~96 ~390 ~69 ~96 grass_block
fill ~391 ~60 ~96 ~399 ~64 ~96 stone
fill ~391 ~65 ~96 ~399 ~67 ~96 dirt
fill ~391 ~68 ~96 ~399 ~68 ~96 grass_block
fill ~384 ~60 ~97 ~384 ~64 ~97 stone
fill ~384 ~65 ~97 ~384 ~67 ~97 dirt
fill ~384 ~68 ~97 ~384 ~68 ~97 grass_block
fill ~385 ~60 ~97 ~390 ~65 ~97 stone
fill ~385 ~66 ~97 ~390 ~68 ~97 dirt
fill ~385 ~69 ~97 ~390 ~69 ~97 grass_block
fill ~391 ~60 ~97 ~399 ~64 ~97 stone
fill ~391 ~65 ~97 ~399 ~67 ~97 dirt
fill ~391 ~68 ~97 ~399 ~68 ~97 grass_block
fill ~384 ~60 ~98 ~385 ~64 ~98 stone
fill ~384 ~65 ~98 ~385 ~67 ~98 dirt
fill ~384 ~68 ~98 ~385 ~68 ~98 grass_block
fill ~386 ~60 ~98 ~390 ~65 ~98 stone
fill ~386 ~66 ~98 ~390 ~68 ~98 dirt
fill ~386 ~69 ~98 ~390 ~69 ~98 grass_block
fill ~391 ~60 ~98 ~395 ~64 ~98 stone
fill ~391 ~65 ~98 ~395 ~67 ~98 dirt
fill ~391 ~68 ~98 ~395 ~68 ~98 grass_block
fill ~396 ~60 ~98 ~396 ~63 ~98 stone
fill ~396 ~64 ~98 ~396 ~66 ~98 dirt
fill ~396 ~67 ~98 ~396 ~67 ~98 grass_block
fill ~397 ~60 ~98 ~399 ~64 ~98 stone
fill ~397 ~65 ~98 ~399 ~67 ~98 dirt
fill ~397 ~68 ~98 ~399 ~68 ~98 grass_block
fill ~384 ~60 ~99 ~386 ~64 ~99 stone
fill ~384 ~65 ~99 ~386 ~67 ~99 dirt
fill ~384 ~68 ~99 ~386 ~68 ~99 grass_block
fill ~387 ~60 ~99 ~390 ~65 ~99 stone
fill ~387 ~66 ~99 ~390 ~68 ~99 dirt
fill ~387 ~69 ~99 ~390 ~69 ~99 grass_block
fill ~391 ~60 ~99 ~395 ~64 ~99 stone
fill ~391 ~65 ~99 ~395 ~67 ~99 dirt
fill ~391 ~68 ~99 ~395 ~68 ~99 grass_block
fill ~396 ~60 ~99 ~397 ~63 ~99 stone
fill ~396 ~64 ~99 ~397 ~66 ~99 dirt
fill ~396 ~67 ~99 ~397 ~67 ~99 grass_block
fill ~398 ~60 ~99 ~399 ~64 ~99 stone
fill ~398 ~65 ~99 ~399 ~67 ~99 dirt
fill ~398 ~68 ~99 ~399 ~68 ~99 grass_block
fill ~384 ~60 ~100 ~387 ~64 ~100 stone
fill ~384 ~65 ~100 ~387 ~67 ~100 dirt
fill ~384 ~68 ~100 ~387 ~68 ~100 grass_block
fill ~388 ~60 ~100 ~390 ~65 ~100 stone
fill ~388 ~66 ~100 ~390 ~68 ~100 dirt
fill ~388 ~69 ~100 ~390 ~69 ~100 grass_block
fill ~391 ~60 ~100 ~395 ~64 ~100 stone
fill ~391 ~65 ~100 ~395 ~67 ~100 dirt
fill ~391 ~68 ~100 ~395 ~68 ~100 grass_block
fill ~396 ~60 ~100 ~399 ~63 ~100 stone
fill ~396 ~64 ~100 ~399 ~66 ~100 dirt
fill ~396 ~67 ~100 ~399 ~67 ~100 grass_block
fill ~384 ~60 ~101 ~388 ~64 ~101 stone
fill ~384 ~65 ~101 ~388 ~67 ~101 dirt
fill ~384 ~68 ~101 ~388 ~68 ~101 grass_block
fill ~389 ~60 ~101 ~389 ~65 ~101 stone
fill ~389 ~66 ~101 ~389 ~68 ~101 dirt
fill ~389 ~69 ~101 ~389 ~69 ~101 grass_block
fill ~390 ~60 ~101 ~395 ~64 ~101 stone
fill ~390 ~65 ~101 ~395 ~67 ~101 dirt
fill ~390 ~68 ~101 ~395 ~68 ~101 grass_block
fill ~396 ~60 ~101 ~399 ~63 ~101 stone
fill ~396 ~64 ~101 ~399 ~66 ~101 dirt
fill ~396 ~67 ~101 ~399 ~67 ~101 grass_block
fill ~384 ~60 ~102 ~394 ~64 ~102 stone
fill ~384 ~65 ~102 ~394 ~67 ~102 dirt
fill ~384 ~68 ~102 ~394 ~68 ~102 grass_block
fill ~395 ~60 ~102 ~399 ~63 ~102 stone
fill ~395 ~64 ~102 ~399 ~66 ~102 dirt
fill ~395 ~67 ~102 ~399 ~67 ~102 grass_block
fill ~384 ~60 ~103 ~394 ~64 ~103 stone
fill ~384 ~65 ~103 ~394 ~67 ~103 dirt
fill ~384 ~68 ~103 ~394 ~68 ~103 grass_block
fill ~395 ~60 ~103 ~399 ~63 ~103 stone
fill ~395 ~64 ~103 ~399 ~66 ~103 dirt
fill ~395 ~67 ~103 ~399 ~67 ~103 grass_block
fill ~384 ~60 ~104 ~384 ~63 ~104 stone
fill ~384 ~64 ~104 ~384 ~66 ~104 dirt
fill ~384 ~67 ~104 ~384 ~67 ~104 grass_block
fill ~385 ~60 ~104 ~393 ~64 ~104 stone
fill ~385 ~65 ~104 ~393 ~67 ~104 dirt
fill ~385 ~68 ~104 ~393 ~68 ~104 grass_block
fill ~394 ~60 ~104 ~399 ~63 ~104 stone
fill ~394 ~64 ~104 ~399 ~66 ~104 dirt
fill ~394 ~67 ~104 ~399 ~67 ~104 grass_block
fill ~384 ~60 ~105 ~384 ~63 ~105 stone
fill ~384 ~64 ~105 ~384 ~66 ~105 dirt
fill ~384 ~67 ~105 ~384 ~67 ~105 grass_block
fill ~385 ~60 ~105 ~391 ~64 ~105 stone
fill ~385 ~65 ~105 ~391 ~67 ~105 dirt
fill ~385 ~68 ~105 ~391 ~68 ~105 grass_block
fill ~392 ~60 ~105 ~399 ~63 ~105 stone
fill ~392 ~64 ~105 ~399 ~66 ~105 dirt
fill ~392 ~67 ~105 ~399 ~67 ~105 grass_block
fill ~384 ~60 ~106 ~384 ~63 ~106 stone
fill ~384 ~64 ~106 ~384 ~66 ~106 dirt
fill ~384 ~67 ~106 ~384 ~67 ~106 grass_block
fill ~385 ~60 ~106 ~391 ~64 ~106 stone
fill ~385 ~65 ~106 ~391 ~67 ~106 dirt
fill ~385 ~68 ~106 ~391 ~68 ~106 grass_block
fill ~392 ~60 ~106 ~399 ~63 ~106 stone
fill ~392 ~64 ~106 ~399 ~66 ~106 dirt
fill ~392 ~67 ~106 ~399 ~67 ~106 grass_block
fill ~384 ~60 ~107 ~385 ~63 ~107 stone
fill ~384 ~64 ~107 ~385 ~66 ~107 dirt
fill ~384 ~67 ~107 ~385 ~67 ~107 grass_block
fill ~386 ~60 ~107 ~390 ~64 ~107 stone
fill ~386 ~65 ~107 ~390 ~67 ~107 dirt
fill ~386 ~68 ~107 ~390 ~68 ~107 grass_block
fill ~391 ~60 ~107 ~399 ~63 ~107 stone
fill ~391 ~64 ~107 ~399 ~66 ~107 dirt
fill ~391 ~67 ~107 ~399 ~67 ~107 grass_block
fill ~384 ~60 ~108 ~386 ~63 ~108 stone
fill ~384 ~64 ~108 ~386 ~66 ~108 dirt
fill ~384 ~67 ~108 ~386 ~67 ~108 grass_block
fill ~387 ~60 ~108 ~388 ~64 ~108 stone
fill ~387 ~65 ~108 ~388 ~67 ~108 dirt
fill ~387 ~68 ~108 ~388 ~68 ~108 grass_block
fill ~389 ~60 ~108 ~399 ~63 ~108 stone
fill ~389 ~64 ~108 ~399 ~66 ~108 dirt
fill ~389 ~67 ~108 ~399 ~67 ~108 grass_block
fill ~384 ~60 ~109 ~399 ~63 ~109 stone
fill ~384 ~64 ~109 ~399 ~66 ~109 dirt
fill ~384 ~67 ~109 ~399 ~67 ~109 grass_block
fill ~384 ~60 ~110 ~395 ~63 ~110 stone
fill ~384 ~64 ~110 ~395 ~66 ~110 dirt
fill ~384 ~67 ~110 ~395 ~67 ~110 grass_block
fill ~396 ~60 ~110 ~396 ~62 ~110 stone
fill ~396 ~63 ~110 ~396 ~65 ~110 dirt
fill ~396 ~66 ~110 ~396 ~66 ~110 grass_block
fill ~397 ~60 ~110 ~399 ~63 ~110 stone
fill ~397 ~64 ~110 ~399 ~66 ~110 dirt
fill ~397 ~67 ~110 ~399 ~67 ~110 grass_block
fill ~384 ~60 ~111 ~395 ~63 ~111 stone
fill ~384 ~64 ~111 ~395 ~66 ~111 dirt
fill ~384 ~67 ~111 ~395 ~67 ~111 grass_block
fill ~396 ~60 ~111 ~397 ~62 ~111 stone
fill ~396 ~63 ~111 ~397 ~65 ~111 dirt
fill ~396 ~66 ~111 ~397 ~66 ~111 grass_block
fill ~398 ~60 ~111 ~399 ~63 ~111 stone
fill ~398 ~64 ~111 ~399 ~66 ~111 dirt
fill ~398 ~67 ~111 ~399 ~67 ~111 grass_block