fill ~192 ~60 ~128 ~207 ~62 ~128 stone
fill ~192 ~63 ~128 ~207 ~65 ~128 dirt
fill ~192 ~66 ~128 ~207 ~66 ~128 grass_block
fill ~192 ~60 ~129 ~192 ~63 ~129 stone
fill ~192 ~64 ~129 ~192 ~66 ~129 dirt
fill ~192 ~67 ~129 ~192 ~67 ~129 grass_block
fill ~193 ~60 ~129 ~207 ~62 ~129 stone
fill ~193 ~63 ~129 ~207 ~65 ~129 dirt
fill ~193 ~66 ~129 ~207 ~66 ~129 grass_block
fill ~192 ~60 ~130 ~194 ~63 ~130 stone
fill ~192 ~64 ~130 ~194 ~66 ~130 dirt
fill ~192 ~67 ~130 ~194 ~67 ~130 grass_block
fill ~195 ~60 ~130 ~207 ~62 ~130 stone
fill ~195 ~63 ~130 ~207 ~65 ~130 dirt
fill ~195 ~66 ~130 ~207 ~66 ~130 grass_block
fill ~192 ~60 ~131 ~194 ~63 ~131 stone
fill ~192 ~64 ~131 ~194 ~66 ~131 dirt
fill ~192 ~67 ~131 ~194 ~67 ~131 grass_block
fill ~195 ~60 ~131 ~207 ~62 ~131 stone
fill ~195 ~63 ~131 ~207 ~65 ~131 dirt
fill ~195 ~66 ~131 ~207 ~66 ~131 grass_block
fill ~192 ~60 ~132 ~207 ~62 ~132 stone
fill ~192 ~63 ~132 ~207 ~65 ~132 dirt
fill ~192 ~66 ~132 ~207 ~66 ~132 grass_block
fill ~192 ~60 ~133 ~207 ~62 ~133 stone
fill ~192 ~63 ~133 ~207 ~65 ~133 dirt
fill ~192 ~66 ~133 ~207 ~66 ~133 grass_block
fill ~192 ~60 ~134 ~196 ~63 ~134 stone
fill ~192 ~64 ~134 ~196 ~66 ~134 dirt
fill ~192 ~67 ~134 ~196 ~67 ~134 grass_block
fill ~197 ~60 ~134 ~207 ~62 ~134 stone
fill ~197 ~63 ~134 ~207 ~65 ~134 dirt
fill ~197 ~66 ~134 ~207 ~66 ~134 grass_block
fill ~192 ~60 ~135 ~201 ~63 ~135 stone
fill ~192 ~64 ~135 ~201 ~66 ~135 dirt
fill ~192 ~67 ~135 ~201 ~67 ~135 grass_block
fill ~202 ~60 ~135 ~207 ~62 ~135 stone
fill ~202 ~63 ~135 ~207 ~65 ~135 dirt
fill ~202 ~66 ~135 ~207 ~66 ~135 grass_block
fill ~192 ~60 ~136 ~199 ~64 ~136 stone
fill ~192 ~65 ~136 ~199 ~67 ~136 dirt
fill ~192 ~68 ~136 ~199 ~68 ~136 grass_block
fill ~200 ~60 ~136 ~203 ~63 ~136 stone
fill ~200 ~64 ~136 ~203 ~66 ~136 dirt
fill ~200 ~67 ~136 ~203 ~67 ~136 grass_block
fill ~204 ~60 ~136 ~207 ~62 ~136 stone
fill ~204 ~63 ~136 ~207 ~65 ~136 dirt
fill ~204 ~66 ~136 ~207 ~66 ~136 grass_block
fill ~192 ~60 ~137 ~192 ~65 ~137 stone
fill ~192 ~66 ~137 ~192 ~68 ~137 dirt
fill ~192 ~69 ~137 ~192 ~69 ~137 grass_block
fill ~193 ~60 ~137 ~201 ~64 ~137 stone
fill ~193 ~65 ~137 ~201 ~67 ~137 dirt
fill ~193 ~68 ~137 ~201 ~68 ~137 grass_block
fill ~202 ~60 ~137 ~206 ~63 ~137 stone
fill ~202 ~64 ~137 ~206 ~66 ~137 dirt
fill ~202 ~67 ~137 ~206 ~67 ~137 grass_block
fill ~207 ~60 ~137 ~207 ~62 ~137 stone
fill ~207 ~63 ~137 ~207 ~65 ~137 dirt
fill ~207 ~66 ~137 ~207 ~66 ~137 grass_block
fill ~192 ~60 ~138 ~197 ~65 ~138 stone
fill ~192 ~66 ~138 ~197 ~68 ~138 dirt
fill ~192 ~69 ~138 ~197 ~69 ~138 grass_block
fill ~198 ~60 ~138 ~202 ~64 ~138 stone
fill ~198 ~65 ~138 ~202 ~67 ~138 dirt
fill ~198 ~68 ~138 ~202 ~68 ~138 grass_block
fill ~203 ~60 ~138 ~207 ~63 ~138 stone
fill ~203 ~64 ~138 ~207 ~66 ~138 dirt
fill ~203 ~67 ~138 ~207 ~67 ~138 grass_block
fill ~192 ~60 ~139 ~199 ~65 ~139 stone
fill ~192 ~66 ~139 ~199 ~68 ~139 dirt
fill ~192 ~69 ~139 ~199 ~69 ~139 grass_block
fill ~200 ~60 ~139 ~204 ~64 ~139 stone
fill ~200 ~65 ~139 ~204 ~67 ~139 dirt
fill ~200 ~68 ~139 ~204 ~68 ~139 grass_block
fill ~205 ~60 ~139 ~207 ~63 ~139 stone
fill ~205 ~64 ~139 ~207 ~66 ~139 dirt
fill ~205 ~67 ~139 ~207 ~67 ~139 grass_block
fill ~192 ~60 ~140 ~198 ~65 ~140 stone
fill ~192 ~66 ~140 ~198 ~68 ~140 dirt
fill ~192 ~69 ~140 ~198 ~69 ~140 grass_block
fill ~199 ~60 ~140 ~205 ~64 ~140 stone
fill ~199 ~65 ~140 ~205 ~67 ~140 dirt
fill ~199 ~68 ~140 ~205 ~68 ~140 grass_block
fill ~206 ~60 ~140 ~207 ~63 ~140 stone
fill ~206 ~64 ~140 ~207 ~66 ~140 dirt
fill ~206 ~67 ~140 ~207 ~67 ~140 grass_block
fill ~192 ~60 ~141 ~198 ~65 ~141 stone
fill ~192 ~66 ~141 ~198 ~68 ~141 dirt
fill ~192 ~69 ~141 ~198 ~69 ~141 grass_block
fill ~199 ~60 ~141 ~205 ~64 ~141 stone
fill ~199 ~65 ~141 ~205 ~67 ~141 dirt
fill ~199 ~68 ~141 ~205 ~68 ~141 grass_block
fill ~206 ~60 ~141 ~207 ~63 ~141 stone
fill ~206 ~64 ~141 ~207 ~66 ~141 dirt
fill ~206 ~67 ~141 ~207 ~67 ~141 grass_block
fill ~192 ~60 ~142 ~198 ~65 ~142 stone
fill ~192 ~66 ~142 ~198 ~68 ~142 dirt
fill ~192 ~69 ~142 ~198 ~69 ~142 grass_block
fill ~199 ~60 ~142 ~203 ~64 ~142 stone
fill ~199 ~65 ~142 ~203 ~67 ~142 dirt
fill ~199 ~68 ~142 ~203 ~68 ~142 grass_block
fill ~204 ~60 ~142 ~207 ~63 ~142 stone
fill ~204 ~64 ~142 ~207 ~66 ~142 dirt
fill ~204 ~67 ~142 ~207 ~67 ~142 grass_block
fill ~192 ~60 ~143 ~197 ~65 ~143 stone
fill ~192 ~66 ~143 ~197 ~68 ~143 dirt
fill ~192 ~69 ~143 ~197 ~69 ~143 grass_block
fill ~198 ~60 ~143 ~203 ~64 ~143 stone
fill ~198 ~65 ~143 ~203 ~67 ~143 dirt
fill ~198 ~68 ~143 ~203 ~68 ~143 grass_block
fill ~204 ~60 ~143 ~207 ~63 ~143 stone
fill ~204 ~64 ~143 ~207 ~66 ~143 dirt
fill ~204 ~67 ~143 ~207 ~67 ~143 grass_block