fill ~144 ~60 ~32 ~147 ~64 ~32 stone
fill ~144 ~65 ~32 ~147 ~67 ~32 dirt
fill ~144 ~68 ~32 ~147 ~68 ~32 grass_block
fill ~148 ~60 ~32 ~152 ~65 ~32 stone
fill ~148 ~66 ~32 ~152 ~68 ~32 dirt
fill ~148 ~69 ~32 ~152 ~69 ~32 grass_block
fill ~153 ~60 ~32 ~155 ~64 ~32 stone
fill ~153 ~65 ~32 ~155 ~67 ~32 dirt
fill ~153 ~68 ~32 ~155 ~68 ~32 grass_block
fill ~156 ~60 ~32 ~159 ~63 ~32 stone
fill ~156 ~64 ~32 ~159 ~66 ~32 dirt
fill ~156 ~67 ~32 ~159 ~67 ~32 grass_block
fill ~144 ~60 ~33 ~148 ~64 ~33 stone
fill ~144 ~65 ~33 ~148 ~67 ~33 dirt
fill ~144 ~68 ~33 ~148 ~68 ~33 grass_block
fill ~149 ~60 ~33 ~152 ~65 ~33 stone
fill ~149 ~66 ~33 ~152 ~68 ~33 dirt
fill ~149 ~69 ~33 ~152 ~69 ~33 grass_block
fill ~153 ~60 ~33 ~156 ~64 ~33 stone
fill ~153 ~65 ~33 ~156 ~67 ~33 dirt
fill ~153 ~68 ~33 ~156 ~68 ~33 grass_block
fill ~157 ~60 ~33 ~159 ~63 ~33 stone
fill ~157 ~64 ~33 ~159 ~66 ~33 dirt
fill ~157 ~67 ~33 ~159 ~67 ~33 grass_block
fill ~144 ~60 ~34 ~148 ~64 ~34 stone
fill ~144 ~65 ~34 ~148 ~67 ~34 dirt
fill ~144 ~68 ~34 ~148 ~68 ~34 grass_block
fill ~149 ~60 ~34 ~153 ~65 ~34 stone
fill ~149 ~66 ~34 ~153 ~68 ~34 dirt
fill ~149 ~69 ~34 ~153 ~69 ~34 grass_block
fill ~154 ~60 ~34 ~156 ~64 ~34 stone
fill ~154 ~65 ~34 ~156 ~67 ~34 dirt
fill ~154 ~68 ~34 ~156 ~68 ~34 grass_block
fill ~157 ~60 ~34 ~159 ~63 ~34 stone
fill ~157 ~64 ~34 ~159 ~66 ~34 dirt
fill ~157 ~67 ~34 ~159 ~67 ~34 grass_block
fill ~144 ~60 ~35 ~144 ~65 ~35 stone
fill ~144 ~66 ~35 ~144 ~68 ~35 dirt
fill ~144 ~69 ~35 ~144 ~69 ~35 grass_block
fill ~145 ~60 ~35 ~148 ~64 ~35 stone
fill ~145 ~65 ~35 ~148 ~67 ~35 dirt
fill ~145 ~68 ~35 ~148 ~68 ~35 grass_block
fill ~149 ~60 ~35 ~149 ~65 ~35 stone
fill ~149 ~66 ~35 ~149 ~68 ~35 dirt
fill ~149 ~69 ~35 ~149 ~69 ~35 grass_block
fill ~150 ~60 ~35 ~150 ~66 ~35 stone
fill ~150 ~67 ~35 ~150 ~69 ~35 dirt
fill ~150 ~70 ~35 ~150 ~70 ~35 grass_block
fill ~151 ~60 ~35 ~153 ~65 ~35 stone
fill ~151 ~66 ~35 ~153 ~68 ~35 dirt
fill ~151 ~69 ~35 ~153 ~69 ~35 grass_block
fill ~154 ~60 ~35 ~156 ~64 ~35 stone
fill ~154 ~65 ~35 ~156 ~67 ~35 dirt
fill ~154 ~68 ~35 ~156 ~68 ~35 grass_block
fill ~157 ~60 ~35 ~159 ~63 ~35 stone
fill ~157 ~64 ~35 ~159 ~66 ~35 dirt
fill ~157 ~67 ~35 ~159 ~67 ~35 grass_block
fill ~144 ~60 ~36 ~145 ~65 ~36 stone
fill ~144 ~66 ~36 ~145 ~68 ~36 dirt
fill ~144 ~69 ~36 ~145 ~69 ~36 grass_block
fill ~146 ~60 ~36 ~147 ~64 ~36 stone
fill ~146 ~65 ~36 ~147 ~67 ~36 dirt
fill ~146 ~68 ~36 ~147 ~68 ~36 grass_block
fill ~148 ~60 ~36 ~149 ~65 ~36 stone
fill ~148 ~66 ~36 ~149 ~68 ~36 dirt
fill ~148 ~69 ~36 ~149 ~69 ~36 grass_block
fill ~150 ~60 ~36 ~150 ~66 ~36 stone
fill ~150 ~67 ~36 ~150 ~69 ~36 dirt
fill ~150 ~70 ~36 ~150 ~70 ~36 grass_block
fill ~151 ~60 ~36 ~153 ~65 ~36 stone
fill ~151 ~66 ~36 ~153 ~68 ~36 dirt
fill ~151 ~69 ~36 ~153 ~69 ~36 grass_block
fill ~154 ~60 ~36 ~156 ~64 ~36 stone
fill ~154 ~65 ~36 ~156 ~67 ~36 dirt
fill ~154 ~68 ~36 ~156 ~68 ~36 grass_block
fill ~157 ~60 ~36 ~158 ~63 ~36 stone
fill ~157 ~64 ~36 ~158 ~66 ~36 dirt
fill ~157 ~67 ~36 ~158 ~67 ~36 grass_block
fill ~159 ~60 ~36 ~159 ~64 ~36 stone
fill ~159 ~65 ~36 ~159 ~67 ~36 dirt
fill ~159 ~68 ~36 ~159 ~68 ~36 grass_block
fill ~144 ~60 ~37 ~148 ~65 ~37 stone
fill ~144 ~66 ~37 ~148 ~68 ~37 dirt
fill ~144 ~69 ~37 ~148 ~69 ~37 grass_block
fill ~149 ~60 ~37 ~150 ~66 ~37 stone
fill ~149 ~67 ~37 ~150 ~69 ~37 dirt
fill ~149 ~70 ~37 ~150 ~70 ~37 grass_block
fill ~151 ~60 ~37 ~153 ~65 ~37 stone
fill ~151 ~66 ~37 ~153 ~68 ~37 dirt
fill ~151 ~69 ~37 ~153 ~69 ~37 grass_block
fill ~154 ~60 ~37 ~159 ~64 ~37 stone
fill ~154 ~65 ~37 ~159 ~67 ~37 dirt
fill ~154 ~68 ~37 ~159 ~68 ~37 grass_block
fill ~144 ~60 ~38 ~148 ~65 ~38 stone
fill ~144 ~66 ~38 ~148 ~68 ~38 dirt
fill ~144 ~69 ~38 ~148 ~69 ~38 grass_block
fill ~149 ~60 ~38 ~150 ~66 ~38 stone
fill ~149 ~67 ~38 ~150 ~69 ~38 dirt
fill ~149 ~70 ~38 ~150 ~70 ~38 grass_block
fill ~151 ~60 ~38 ~154 ~65 ~38 stone
fill ~151 ~66 ~38 ~154 ~68 ~38 dirt
fill ~151 ~69 ~38 ~154 ~69 ~38 grass_block
fill ~155 ~60 ~38 ~159 ~64 ~38 stone
fill ~155 ~65 ~38 ~159 ~67 ~38 dirt
fill ~155 ~68 ~38 ~159 ~68 ~38 grass_block
fill ~144 ~60 ~39 ~148 ~65 ~39 stone
fill ~144 ~66 ~39 ~148 ~68 ~39 dirt
fill ~144 ~69 ~39 ~148 ~69 ~39 grass_block
fill ~149 ~60 ~39 ~151 ~66 ~39 stone
fill ~149 ~67 ~39 ~151 ~69 ~39 dirt
fill ~149 ~70 ~39 ~151 ~70 ~39 grass_block
fill ~152 ~60 ~39 ~154 ~65 ~39 stone
fill ~152 ~66 ~39 ~154 ~68 ~39 dirt
fill ~152 ~69 ~39 ~154 ~69 ~39 grass_block
fill ~155 ~60 ~39 ~158 ~64 ~39 stone
fill ~155 ~65 ~39 ~158 ~67 ~39 dirt
fill ~155 ~68 ~39 ~158 ~68 ~39 grass_block
fill ~159 ~60 ~39 ~159 ~65 ~39 stone
fill ~159 ~66 ~39 ~159 ~68 ~39 dirt
fill ~159 ~69 ~39 ~159 ~69 ~39 grass_block
fill ~144 ~60 ~40 ~149 ~66 ~40 stone
fill ~144 ~67 ~40 ~149 ~69 ~40 dirt
fill ~144 ~70 ~40 ~149 ~70 ~40 grass_block
fill ~150 ~60 ~40 ~150 ~67 ~40 stone
fill ~150 ~68 ~40 ~150 ~70 ~40 dirt
fill ~150 ~71 ~40 ~150 ~71 ~40 grass_block
fill ~151 ~60 ~40 ~152 ~66 ~40 stone
fill ~151 ~67 ~40 ~152 ~69 ~40 dirt
fill ~151 ~70 ~40 ~152 ~70 ~40 grass_block
fill ~153 ~60 ~40 ~154 ~65 ~40 stone
fill ~153 ~66 ~40 ~154 ~68 ~40 dirt
fill ~153 ~69 ~40 ~154 ~69 ~40 grass_block
fill ~155 ~60 ~40 ~158 ~64 ~40 stone
fill ~155 ~65 ~40 ~158 ~67 ~40 dirt
fill ~155 ~68 ~40 ~158 ~68 ~40 grass_block
fill ~159 ~60 ~40 ~159 ~65 ~40 stone
fill ~159 ~66 ~40 ~159 ~68 ~40 dirt
fill ~159 ~69 ~40 ~159 ~69 ~40 grass_block
fill ~144 ~60 ~41 ~144 ~67 ~41 stone
fill ~144 ~68 ~41 ~144 ~70 ~41 dirt
fill ~144 ~71 ~41 ~144 ~71 ~41 grass_block
fill ~145 ~60 ~41 ~146 ~66 ~41 stone
fill ~145 ~67 ~41 ~146 ~69 ~41 dirt
fill ~145 ~70 ~41 ~146 ~70 ~41 grass_block
fill ~147 ~60 ~41 ~150 ~67 ~41 stone
fill ~147 ~68 ~41 ~150 ~70 ~41 dirt
fill ~147 ~71 ~41 ~150 ~71 ~41 grass_block
fill ~151 ~60 ~41 ~152 ~66 ~41 stone
fill ~151 ~67 ~41 ~152 ~69 ~41 dirt
fill ~151 ~70 ~41 ~152 ~70 ~41 grass_block
fill ~153 ~60 ~41 ~155 ~65 ~41 stone
fill ~153 ~66 ~41 ~155 ~68 ~41 dirt
fill ~153 ~69 ~41 ~155 ~69 ~41 grass_block
fill ~156 ~60 ~41 ~157 ~64 ~41 stone
fill ~156 ~65 ~41 ~157 ~67 ~41 dirt
fill ~156 ~68 ~41 ~157 ~68 ~41 grass_block
fill ~158 ~60 ~41 ~159 ~65 ~41 stone
fill ~158 ~66 ~41 ~159 ~68 ~41 dirt
fill ~158 ~69 ~41 ~159 ~69 ~41 grass_block
fill ~144 ~60 ~42 ~151 ~67 ~42 stone
fill ~144 ~68 ~42 ~151 ~70 ~42 dirt
fill ~144 ~71 ~42 ~151 ~71 ~42 grass_block
fill ~152 ~60 ~42 ~153 ~66 ~42 stone
fill ~152 ~67 ~42 ~153 ~69 ~42 dirt
fill ~152 ~70 ~42 ~153 ~70 ~42 grass_block
fill ~154 ~60 ~42 ~159 ~65 ~42 stone
fill ~154 ~66 ~42 ~159 ~68 ~42 dirt
fill ~154 ~69 ~42 ~159 ~69 ~42 grass_block
fill ~144 ~60 ~43 ~145 ~68 ~43 stone
fill ~144 ~69 ~43 ~145 ~71 ~43 dirt
fill ~144 ~72 ~43 ~145 ~72 ~43 grass_block
fill ~146 ~60 ~43 ~146 ~67 ~43 stone
fill ~146 ~68 ~43 ~146 ~70 ~43 dirt
fill ~146 ~71 ~43 ~146 ~71 ~43 grass_block
fill ~147 ~60 ~43 ~147 ~68 ~43 stone
fill ~147 ~69 ~43 ~147 ~71 ~43 dirt
fill ~147 ~72 ~43 ~147 ~72 ~43 grass_block
fill ~148 ~60 ~43 ~148 ~67 ~43 stone
fill ~148 ~68 ~43 ~148 ~70 ~43 dirt
fill ~148 ~71 ~43 ~148 ~71 ~43 grass_block
fill ~149 ~60 ~43 ~150 ~68 ~43 stone
fill ~149 ~69 ~43 ~150 ~71 ~43 dirt
fill ~149 ~72 ~43 ~150 ~72 ~43 grass_block
fill ~151 ~60 ~43 ~152 ~67 ~43 stone
fill ~151 ~68 ~43 ~152 ~70 ~43 dirt
fill ~151 ~71 ~43 ~152 ~71 ~43 grass_block
fill ~153 ~60 ~43 ~154 ~66 ~43 stone
fill ~153 ~67 ~43 ~154 ~69 ~43 dirt
fill ~153 ~70 ~43 ~154 ~70 ~43 grass_block
fill ~155 ~60 ~43 ~158 ~65 ~43 stone
fill ~155 ~66 ~43 ~158 ~68 ~43 dirt
fill ~155 ~69 ~43 ~158 ~69 ~43 grass_block
fill ~159 ~60 ~43 ~159 ~66 ~43 stone
fill ~159 ~67 ~43 ~159 ~69 ~43 dirt
fill ~159 ~70 ~43 ~159 ~70 ~43 grass_block
fill ~144 ~60 ~44 ~151 ~68 ~44 stone
fill ~144 ~69 ~44 ~151 ~71 ~44 dirt
fill ~144 ~72 ~44 ~151 ~72 ~44 grass_block
fill ~152 ~60 ~44 ~152 ~67 ~44 stone
fill ~152 ~68 ~44 ~152 ~70 ~44 dirt
fill ~152 ~71 ~44 ~152 ~71 ~44 grass_block
fill ~153 ~60 ~44 ~155 ~66 ~44 stone
fill ~153 ~67 ~44 ~155 ~69 ~44 dirt
fill ~153 ~70 ~44 ~155 ~70 ~44 grass_block
fill ~156 ~60 ~44 ~158 ~65 ~44 stone
fill ~156 ~66 ~44 ~158 ~68 ~44 dirt
fill ~156 ~69 ~44 ~158 ~69 ~44 grass_block
fill ~159 ~60 ~44 ~159 ~66 ~44 stone
fill ~159 ~67 ~44 ~159 ~69 ~44 dirt
fill ~159 ~70 ~44 ~159 ~70 ~44 grass_block
fill ~144 ~60 ~45 ~145 ~67 ~45 stone
fill ~144 ~68 ~45 ~145 ~70 ~45 dirt
fill ~144 ~71 ~45 ~145 ~71 ~45 grass_block
fill ~146 ~60 ~45 ~146 ~68 ~45 stone
fill ~146 ~69 ~45 ~146 ~71 ~45 dirt
fill ~146 ~72 ~45 ~146 ~72 ~45 grass_block
fill ~147 ~60 ~45 ~147 ~67 ~45 stone
fill ~147 ~68 ~45 ~147 ~70 ~45 dirt
fill ~147 ~71 ~45 ~147 ~71 ~45 grass_block
fill ~148 ~60 ~45 ~151 ~68 ~45 stone
fill ~148 ~69 ~45 ~151 ~71 ~45 dirt
fill ~148 ~72 ~45 ~151 ~72 ~45 grass_block
fill ~152 ~60 ~45 ~153 ~67 ~45 stone
fill ~152 ~68 ~45 ~153 ~70 ~45 dirt
fill ~152 ~71 ~45 ~153 ~71 ~45 grass_block
fill ~154 ~60 ~45 ~156 ~66 ~45 stone
fill ~154 ~67 ~45 ~156 ~69 ~45 dirt
fill ~154 ~70 ~45 ~156 ~70 ~45 grass_block
fill ~157 ~60 ~45 ~157 ~65 ~45 stone
fill ~157 ~66 ~45 ~157 ~68 ~45 dirt
fill ~157 ~69 ~45 ~157 ~69 ~45 grass_block
fill ~158 ~60 ~45 ~159 ~66 ~45 stone
fill ~158 ~67 ~45 ~159 ~69 ~45 dirt
fill ~158 ~70 ~45 ~159 ~70 ~45 grass_block
fill ~144 ~60 ~46 ~147 ~67 ~46 stone
fill ~144 ~68 ~46 ~147 ~70 ~46 dirt
fill ~144 ~71 ~46 ~147 ~71 ~46 grass_block
fill ~148 ~60 ~46 ~152 ~68 ~46 stone
fill ~148 ~69 ~46 ~152 ~71 ~46 dirt
fill ~148 ~72 ~46 ~152 ~72 ~46 grass_block
fill ~153 ~60 ~46 ~154 ~67 ~46 stone
fill ~153 ~68 ~46 ~154 ~70 ~46 dirt
fill ~153 ~71 ~46 ~154 ~71 ~46 grass_block
fill ~155 ~60 ~46 ~158 ~66 ~46 stone
fill ~155 ~67 ~46 ~158 ~69 ~46 dirt
fill ~155 ~70 ~46 ~158 ~70 ~46 grass_block
fill ~159 ~60 ~46 ~159 ~67 ~46 stone
fill ~159 ~68 ~46 ~159 ~70 ~46 dirt
fill ~159 ~71 ~46 ~159 ~71 ~46 grass_block
fill ~144 ~60 ~47 ~147 ~67 ~47 stone
fill ~144 ~68 ~47 ~147 ~70 ~47 dirt
fill ~144 ~71 ~47 ~147 ~71 ~47 grass_block
fill ~148 ~60 ~47 ~151 ~68 ~47 stone
fill ~148 ~69 ~47 ~151 ~71 ~47 dirt
fill ~148 ~72 ~47 ~151 ~72 ~47 grass_block
fill ~152 ~60 ~47 ~159 ~67 ~47 stone
fill ~152 ~68 ~47 ~159 ~70 ~47 dirt
fill ~152 ~71 ~47 ~159 ~71 ~47 grass_block