fill ~400 ~60 ~96 ~402 ~64 ~96 stone
fill ~400 ~65 ~96 ~402 ~67 ~96 dirt
fill ~400 ~68 ~96 ~402 ~68 ~96 grass_block
fill ~403 ~60 ~96 ~411 ~65 ~96 stone
fill ~403 ~66 ~96 ~411 ~68 ~96 dirt
fill ~403 ~69 ~96 ~411 ~69 ~96 grass_block
fill ~412 ~60 ~96 ~415 ~64 ~96 stone
fill ~412 ~65 ~96 ~415 ~67 ~96 dirt
fill ~412 ~68 ~96 ~415 ~68 ~96 grass_block
fill ~400 ~60 ~97 ~404 ~64 ~97 stone
fill ~400 ~65 ~97 ~404 ~67 ~97 dirt
fill ~400 ~68 ~97 ~404 ~68 ~97 grass_block
fill ~405 ~60 ~97 ~411 ~65 ~97 stone
fill ~405 ~66 ~97 ~411 ~68 ~97 dirt
fill ~405 ~69 ~97 ~411 ~69 ~97 grass_block
fill ~412 ~60 ~97 ~415 ~64 ~97 stone
fill ~412 ~65 ~97 ~415 ~67 ~97 dirt
fill ~412 ~68 ~97 ~415 ~68 ~97 grass_block
fill ~400 ~60 ~98 ~405 ~64 ~98 stone
fill ~400 ~65 ~98 ~405 ~67 ~98 dirt
fill ~400 ~68 ~98 ~405 ~68 ~98 grass_block
fill ~406 ~60 ~98 ~410 ~65 ~98 stone
fill ~406 ~66 ~98 ~410 ~68 ~98 dirt
fill ~406 ~69 ~98 ~410 ~69 ~98 grass_block
fill ~411 ~60 ~98 ~413 ~64 ~98 stone
fill ~411 ~65 ~98 ~413 ~67 ~98 dirt
fill ~411 ~68 ~98 ~413 ~68 ~98 grass_block
fill ~414 ~60 ~98 ~415 ~63 ~98 stone
fill ~414 ~64 ~98 ~415 ~66 ~98 dirt
fill ~414 ~67 ~98 ~415 ~67 ~98 grass_block
fill ~400 ~60 ~99 ~406 ~64 ~99 stone
fill ~400 ~65 ~99 ~406 ~67 ~99 dirt
fill ~400 ~68 ~99 ~406 ~68 ~99 grass_block
fill ~407 ~60 ~99 ~410 ~65 ~99 stone
fill ~407 ~66 ~99 ~410 ~68 ~99 dirt
fill ~407 ~69 ~99 ~410 ~69 ~99 grass_block
fill ~411 ~60 ~99 ~411 ~64 ~99 stone
fill ~411 ~65 ~99 ~411 ~67 ~99 dirt
fill ~411 ~68 ~99 ~411 ~68 ~99 grass_block
fill ~412 ~60 ~99 ~415 ~63 ~99 stone
fill ~412 ~64 ~99 ~415 ~66 ~99 dirt
fill ~412 ~67 ~99 ~415 ~67 ~99 grass_block
fill ~400 ~60 ~100 ~406 ~64 ~100 stone
fill ~400 ~65 ~100 ~406 ~67 ~100 dirt
fill ~400 ~68 ~100 ~406 ~68 ~100 grass_block
fill ~407 ~60 ~100 ~410 ~65 ~100 stone
fill ~407 ~66 ~100 ~410 ~68 ~100 dirt
fill ~407 ~69 ~100 ~410 ~69 ~100 grass_block
fill ~411 ~60 ~100 ~411 ~64 ~100 stone
fill ~411 ~65 ~100 ~411 ~67 ~100 dirt
fill ~411 ~68 ~100 ~411 ~68 ~100 grass_block
fill ~412 ~60 ~100 ~415 ~63 ~100 stone
fill ~412 ~64 ~100 ~415 ~66 ~100 dirt
fill ~412 ~67 ~100 ~415 ~67 ~100 grass_block
fill ~400 ~60 ~101 ~406 ~64 ~101 stone
fill ~400 ~65 ~101 ~406 ~67 ~101 dirt
fill ~400 ~68 ~101 ~406 ~68 ~101 grass_block
fill ~407 ~60 ~101 ~410 ~65 ~101 stone
fill ~407 ~66 ~101 ~410 ~68 ~101 dirt
fill ~407 ~69 ~101 ~410 ~69 ~101 grass_block
fill ~411 ~60 ~101 ~411 ~64 ~101 stone
fill ~411 ~65 ~101 ~411 ~67 ~101 dirt
fill ~411 ~68 ~101 ~411 ~68 ~101 grass_block
fill ~412 ~60 ~101 ~414 ~63 ~101 stone
fill ~412 ~64 ~101 ~414 ~66 ~101 dirt
fill ~412 ~67 ~101 ~414 ~67 ~101 grass_block
fill ~415 ~60 ~101 ~415 ~64 ~101 stone
fill ~415 ~65 ~101 ~415 ~67 ~101 dirt
fill ~415 ~68 ~101 ~415 ~68 ~101 grass_block
fill ~400 ~60 ~102 ~402 ~63 ~102 stone
fill ~400 ~64 ~102 ~402 ~66 ~102 dirt
fill ~400 ~67 ~102 ~402 ~67 ~102 grass_block
fill ~403 ~60 ~102 ~406 ~64 ~102 stone
fill ~403 ~65 ~102 ~406 ~67 ~102 dirt
fill ~403 ~68 ~102 ~406 ~68 ~102 grass_block
fill ~407 ~60 ~102 ~410 ~65 ~102 stone
fill ~407 ~66 ~102 ~410 ~68 ~102 dirt
fill ~407 ~69 ~102 ~410 ~69 ~102 grass_block
fill ~411 ~60 ~102 ~412 ~64 ~102 stone
fill ~411 ~65 ~102 ~412 ~67 ~102 dirt
fill ~411 ~68 ~102 ~412 ~68 ~102 grass_block
fill ~413 ~60 ~102 ~413 ~63 ~102 stone
fill ~413 ~64 ~102 ~413 ~66 ~102 dirt
fill ~413 ~67 ~102 ~413 ~67 ~102 grass_block
fill ~414 ~60 ~102 ~415 ~64 ~102 stone
fill ~414 ~65 ~102 ~415 ~67 ~102 dirt
fill ~414 ~68 ~102 ~415 ~68 ~102 grass_block
fill ~400 ~60 ~103 ~402 ~63 ~103 stone
fill ~400 ~64 ~103 ~402 ~66 ~103 dirt
fill ~400 ~67 ~103 ~402 ~67 ~103 grass_block
fill ~403 ~60 ~103 ~406 ~64 ~103 stone
fill ~403 ~65 ~103 ~406 ~67 ~103 dirt
fill ~403 ~68 ~103 ~406 ~68 ~103 grass_block
fill ~407 ~60 ~103 ~409 ~65 ~103 stone
fill ~407 ~66 ~103 ~409 ~68 ~103 dirt
fill ~407 ~69 ~103 ~409 ~69 ~103 grass_block
fill ~410 ~60 ~103 ~415 ~64 ~103 stone
fill ~410 ~65 ~103 ~415 ~67 ~103 dirt
fill ~410 ~68 ~103 ~415 ~68 ~103 grass_block
fill ~400 ~60 ~104 ~401 ~63 ~104 stone
fill ~400 ~64 ~104 ~401 ~66 ~104 dirt
fill ~400 ~67 ~104 ~401 ~67 ~104 grass_block
fill ~402 ~60 ~104 ~406 ~64 ~104 stone
fill ~402 ~65 ~104 ~406 ~67 ~104 dirt
fill ~402 ~68 ~104 ~406 ~68 ~104 grass_block
fill ~407 ~60 ~104 ~415 ~65 ~104 stone
fill ~407 ~66 ~104 ~415 ~68 ~104 dirt
fill ~407 ~69 ~104 ~415 ~69 ~104 grass_block
fill ~400 ~60 ~105 ~400 ~63 ~105 stone
fill ~400 ~64 ~105 ~400 ~66 ~105 dirt
fill ~400 ~67 ~105 ~400 ~67 ~105 grass_block
fill ~401 ~60 ~105 ~406 ~64 ~105 stone
fill ~401 ~65 ~105 ~406 ~67 ~105 dirt
fill ~401 ~68 ~105 ~406 ~68 ~105 grass_block
fill ~407 ~60 ~105 ~415 ~65 ~105 stone
fill ~407 ~66 ~105 ~415 ~68 ~105 dirt
fill ~407 ~69 ~105 ~415 ~69 ~105 grass_block
fill ~400 ~60 ~106 ~400 ~63 ~106 stone
fill ~400 ~64 ~106 ~400 ~66 ~106 dirt
fill ~400 ~67 ~106 ~400 ~67 ~106 grass_block
fill ~401 ~60 ~106 ~405 ~64 ~106 stone
fill ~401 ~65 ~106 ~405 ~67 ~106 dirt
fill ~401 ~68 ~106 ~405 ~68 ~106 grass_block
fill ~406 ~60 ~106 ~415 ~65 ~106 stone
fill ~406 ~66 ~106 ~415 ~68 ~106 dirt
fill ~406 ~69 ~106 ~415 ~69 ~106 grass_block
fill ~400 ~60 ~107 ~400 ~63 ~107 stone
fill ~400 ~64 ~107 ~400 ~66 ~107 dirt
fill ~400 ~67 ~107 ~400 ~67 ~107 grass_block
fill ~401 ~60 ~107 ~405 ~64 ~107 stone
fill ~401 ~65 ~107 ~405 ~67 ~107 dirt
fill ~401 ~68 ~107 ~405 ~68 ~107 grass_block
fill ~406 ~60 ~107 ~415 ~65 ~107 stone
fill ~406 ~66 ~107 ~415 ~68 ~107 dirt
fill ~406 ~69 ~107 ~415 ~69 ~107 grass_block
fill ~400 ~60 ~108 ~400 ~63 ~108 stone
fill ~400 ~64 ~108 ~400 ~66 ~108 dirt
fill ~400 ~67 ~108 ~400 ~67 ~108 grass_block
fill ~401 ~60 ~108 ~405 ~64 ~108 stone
fill ~401 ~65 ~108 ~405 ~67 ~108 dirt
fill ~401 ~68 ~108 ~405 ~68 ~108 grass_block
fill ~406 ~60 ~108 ~414 ~65 ~108 stone
fill ~406 ~66 ~108 ~414 ~68 ~108 dirt
fill ~406 ~69 ~108 ~414 ~69 ~108 grass_block
fill ~415 ~60 ~108 ~415 ~64 ~108 stone
fill ~415 ~65 ~108 ~415 ~67 ~108 dirt
fill ~415 ~68 ~108 ~415 ~68 ~108 grass_block
fill ~400 ~60 ~109 ~400 ~63 ~109 stone
fill ~400 ~64 ~109 ~400 ~66 ~109 dirt
fill ~400 ~67 ~109 ~400 ~67 ~109 grass_block
fill ~401 ~60 ~109 ~405 ~64 ~109 stone
fill ~401 ~65 ~109 ~405 ~67 ~109 dirt
fill ~401 ~68 ~109 ~405 ~68 ~109 grass_block
fill ~406 ~60 ~109 ~413 ~65 ~109 stone
fill ~406 ~66 ~109 ~413 ~68 ~109 dirt
fill ~406 ~69 ~109 ~413 ~69 ~109 grass_block
fill ~414 ~60 ~109 ~415 ~64 ~109 stone
fill ~414 ~65 ~109 ~415 ~67 ~109 dirt
fill ~414 ~68 ~109 ~415 ~68 ~109 grass_block
fill ~400 ~60 ~110 ~401 ~63 ~110 stone
fill ~400 ~64 ~110 ~401 ~66 ~110 dirt
fill ~400 ~67 ~110 ~401 ~67 ~110 grass_block
fill ~402 ~60 ~110 ~407 ~64 ~110 stone
fill ~402 ~65 ~110 ~407 ~67 ~110 dirt
fill ~402 ~68 ~110 ~407 ~68 ~110 grass_block
fill ~408 ~60 ~110 ~412 ~65 ~110 stone
fill ~408 ~66 ~110 ~412 ~68 ~110 dirt
fill ~408 ~69 ~110 ~412 ~69 ~110 grass_block
fill ~413 ~60 ~110 ~415 ~64 ~110 stone
fill ~413 ~65 ~110 ~415 ~67 ~110 dirt
fill ~413 ~68 ~110 ~415 ~68 ~110 grass_block
fill ~400 ~60 ~111 ~404 ~63 ~111 stone
fill ~400 ~64 ~111 ~404 ~66 ~111 dirt
fill ~400 ~67 ~111 ~404 ~67 ~111 grass_block
fill ~405 ~60 ~111 ~408 ~64 ~111 stone
fill ~405 ~65 ~111 ~408 ~67 ~111 dirt
fill ~405 ~68 ~111 ~408 ~68 ~111 grass_block
fill ~409 ~60 ~111 ~411 ~65 ~111 stone
fill ~409 ~66 ~111 ~411 ~68 ~111 dirt
fill ~409 ~69 ~111 ~411 ~69 ~111 grass_block
fill ~412 ~60 ~111 ~415 ~64 ~111 stone
fill ~412 ~65 ~111 ~415 ~67 ~111 dirt
fill ~412 ~68 ~111 ~415 ~68 ~111 grass_block