fill ~256 ~60 ~64 ~259 ~63 ~64 stone
fill ~256 ~64 ~64 ~259 ~66 ~64 dirt
fill ~256 ~67 ~64 ~259 ~67 ~64 grass_block
fill ~260 ~60 ~64 ~271 ~62 ~64 stone
fill ~260 ~63 ~64 ~271 ~65 ~64 dirt
fill ~260 ~66 ~64 ~271 ~66 ~64 grass_block
fill ~256 ~60 ~65 ~258 ~63 ~65 stone
fill ~256 ~64 ~65 ~258 ~66 ~65 dirt
fill ~256 ~67 ~65 ~258 ~67 ~65 grass_block
fill ~259 ~60 ~65 ~259 ~62 ~65 stone
fill ~259 ~63 ~65 ~259 ~65 ~65 dirt
fill ~259 ~66 ~65 ~259 ~66 ~65 grass_block
fill ~260 ~60 ~65 ~260 ~63 ~65 stone
fill ~260 ~64 ~65 ~260 ~66 ~65 dirt
fill ~260 ~67 ~65 ~260 ~67 ~65 grass_block
fill ~261 ~60 ~65 ~271 ~62 ~65 stone
fill ~261 ~63 ~65 ~271 ~65 ~65 dirt
fill ~261 ~66 ~65 ~271 ~66 ~65 grass_block
fill ~256 ~60 ~66 ~260 ~63 ~66 stone
fill ~256 ~64 ~66 ~260 ~66 ~66 dirt
fill ~256 ~67 ~66 ~260 ~67 ~66 grass_block
fill ~261 ~60 ~66 ~271 ~62 ~66 stone
fill ~261 ~63 ~66 ~271 ~65 ~66 dirt
fill ~261 ~66 ~66 ~271 ~66 ~66 grass_block
fill ~256 ~60 ~67 ~261 ~63 ~67 stone
fill ~256 ~64 ~67 ~261 ~66 ~67 dirt
fill ~256 ~67 ~67 ~261 ~67 ~67 grass_block
fill ~262 ~60 ~67 ~271 ~62 ~67 stone
fill ~262 ~63 ~67 ~271 ~65 ~67 dirt
fill ~262 ~66 ~67 ~271 ~66 ~67 grass_block
fill ~256 ~60 ~68 ~262 ~63 ~68 stone
fill ~256 ~64 ~68 ~262 ~66 ~68 dirt
fill ~256 ~67 ~68 ~262 ~67 ~68 grass_block
fill ~263 ~60 ~68 ~271 ~62 ~68 stone
fill ~263 ~63 ~68 ~271 ~65 ~68 dirt
fill ~263 ~66 ~68 ~271 ~66 ~68 grass_block
fill ~256 ~60 ~69 ~263 ~63 ~69 stone
fill ~256 ~64 ~69 ~263 ~66 ~69 dirt
fill ~256 ~67 ~69 ~263 ~67 ~69 grass_block
fill ~264 ~60 ~69 ~271 ~62 ~69 stone
fill ~264 ~63 ~69 ~271 ~65 ~69 dirt
fill ~264 ~66 ~69 ~271 ~66 ~69 grass_block
fill ~256 ~60 ~70 ~262 ~63 ~70 stone
fill ~256 ~64 ~70 ~262 ~66 ~70 dirt
fill ~256 ~67 ~70 ~262 ~67 ~70 grass_block
fill ~263 ~60 ~70 ~271 ~62 ~70 stone
fill ~263 ~63 ~70 ~271 ~65 ~70 dirt
fill ~263 ~66 ~70 ~271 ~66 ~70 grass_block
fill ~256 ~60 ~71 ~261 ~63 ~71 stone
fill ~256 ~64 ~71 ~261 ~66 ~71 dirt
fill ~256 ~67 ~71 ~261 ~67 ~71 grass_block
fill ~262 ~60 ~71 ~271 ~62 ~71 stone
fill ~262 ~63 ~71 ~271 ~65 ~71 dirt
fill ~262 ~66 ~71 ~271 ~66 ~71 grass_block
fill ~256 ~60 ~72 ~262 ~63 ~72 stone
fill ~256 ~64 ~72 ~262 ~66 ~72 dirt
fill ~256 ~67 ~72 ~262 ~67 ~72 grass_block
fill ~263 ~60 ~72 ~266 ~62 ~72 stone
fill ~263 ~63 ~72 ~266 ~65 ~72 dirt
fill ~263 ~66 ~72 ~266 ~66 ~72 grass_block
fill ~267 ~60 ~72 ~268 ~63 ~72 stone
fill ~267 ~64 ~72 ~268 ~66 ~72 dirt
fill ~267 ~67 ~72 ~268 ~67 ~72 grass_block
fill ~269 ~60 ~72 ~271 ~62 ~72 stone
fill ~269 ~63 ~72 ~271 ~65 ~72 dirt
fill ~269 ~66 ~72 ~271 ~66 ~72 grass_block
fill ~256 ~60 ~73 ~256 ~63 ~73 stone
fill ~256 ~64 ~73 ~256 ~66 ~73 dirt
fill ~256 ~67 ~73 ~256 ~67 ~73 grass_block
fill ~257 ~60 ~73 ~257 ~62 ~73 stone
fill ~257 ~63 ~73 ~257 ~65 ~73 dirt
fill ~257 ~66 ~73 ~257 ~66 ~73 grass_block
fill ~258 ~60 ~73 ~258 ~63 ~73 stone
fill ~258 ~64 ~73 ~258 ~66 ~73 dirt
fill ~258 ~67 ~73 ~258 ~67 ~73 grass_block
fill ~259 ~60 ~73 ~264 ~62 ~73 stone
fill ~259 ~63 ~73 ~264 ~65 ~73 dirt
fill ~259 ~66 ~73 ~264 ~66 ~73 grass_block
fill ~265 ~60 ~73 ~265 ~63 ~73 stone
fill ~265 ~64 ~73 ~265 ~66 ~73 dirt
fill ~265 ~67 ~73 ~265 ~67 ~73 grass_block
fill ~266 ~60 ~73 ~266 ~62 ~73 stone
fill ~266 ~63 ~73 ~266 ~65 ~73 dirt
fill ~266 ~66 ~73 ~266 ~66 ~73 grass_block
fill ~267 ~60 ~73 ~271 ~63 ~73 stone
fill ~267 ~64 ~73 ~271 ~66 ~73 dirt
fill ~267 ~67 ~73 ~271 ~67 ~73 grass_block
fill ~256 ~60 ~74 ~261 ~63 ~74 stone
fill ~256 ~64 ~74 ~261 ~66 ~74 dirt
fill ~256 ~67 ~74 ~261 ~67 ~74 grass_block
fill ~262 ~60 ~74 ~263 ~62 ~74 stone
fill ~262 ~63 ~74 ~263 ~65 ~74 dirt
fill ~262 ~66 ~74 ~263 ~66 ~74 grass_block
fill ~264 ~60 ~74 ~265 ~63 ~74 stone
fill ~264 ~64 ~74 ~265 ~66 ~74 dirt
fill ~264 ~67 ~74 ~265 ~67 ~74 grass_block
fill ~266 ~60 ~74 ~266 ~62 ~74 stone
fill ~266 ~63 ~74 ~266 ~65 ~74 dirt
fill ~266 ~66 ~74 ~266 ~66 ~74 grass_block
fill ~267 ~60 ~74 ~268 ~63 ~74 stone
fill ~267 ~64 ~74 ~268 ~66 ~74 dirt
fill ~267 ~67 ~74 ~268 ~67 ~74 grass_block
fill ~269 ~60 ~74 ~271 ~62 ~74 stone
fill ~269 ~63 ~74 ~271 ~65 ~74 dirt
fill ~269 ~66 ~74 ~271 ~66 ~74 grass_block
fill ~256 ~60 ~75 ~263 ~63 ~75 stone
fill ~256 ~64 ~75 ~263 ~66 ~75 dirt
fill ~256 ~67 ~75 ~263 ~67 ~75 grass_block
fill ~264 ~60 ~75 ~271 ~62 ~75 stone
fill ~264 ~63 ~75 ~271 ~65 ~75 dirt
fill ~264 ~66 ~75 ~271 ~66 ~75 grass_block
fill ~256 ~60 ~76 ~264 ~63 ~76 stone
fill ~256 ~64 ~76 ~264 ~66 ~76 dirt
fill ~256 ~67 ~76 ~264 ~67 ~76 grass_block
fill ~265 ~60 ~76 ~271 ~62 ~76 stone
fill ~265 ~63 ~76 ~271 ~65 ~76 dirt
fill ~265 ~66 ~76 ~271 ~66 ~76 grass_block
fill ~256 ~60 ~77 ~257 ~63 ~77 stone
fill ~256 ~64 ~77 ~257 ~66 ~77 dirt
fill ~256 ~67 ~77 ~257 ~67 ~77 grass_block
fill ~258 ~60 ~77 ~259 ~64 ~77 stone
fill ~258 ~65 ~77 ~259 ~67 ~77 dirt
fill ~258 ~68 ~77 ~259 ~68 ~77 grass_block
fill ~260 ~60 ~77 ~267 ~63 ~77 stone
fill ~260 ~64 ~77 ~267 ~66 ~77 dirt
fill ~260 ~67 ~77 ~267 ~67 ~77 grass_block
fill ~268 ~60 ~77 ~271 ~62 ~77 stone
fill ~268 ~63 ~77 ~271 ~65 ~77 dirt
fill ~268 ~66 ~77 ~271 ~66 ~77 grass_block
fill ~256 ~60 ~78 ~262 ~64 ~78 stone
fill ~256 ~65 ~78 ~262 ~67 ~78 dirt
fill ~256 ~68 ~78 ~262 ~68 ~78 grass_block
fill ~263 ~60 ~78 ~267 ~63 ~78 stone
fill ~263 ~64 ~78 ~267 ~66 ~78 dirt
fill ~263 ~67 ~78 ~267 ~67 ~78 grass_block
fill ~268 ~60 ~78 ~271 ~62 ~78 stone
fill ~268 ~63 ~78 ~271 ~65 ~78 dirt
fill ~268 ~66 ~78 ~271 ~66 ~78 grass_block
fill ~256 ~60 ~79 ~261 ~64 ~79 stone
fill ~256 ~65 ~79 ~261 ~67 ~79 dirt
fill ~256 ~68 ~79 ~261 ~68 ~79 grass_block
fill ~262 ~60 ~79 ~266 ~63 ~79 stone
fill ~262 ~64 ~79 ~266 ~66 ~79 dirt
fill ~262 ~67 ~79 ~266 ~67 ~79 grass_block
fill ~267 ~60 ~79 ~270 ~62 ~79 stone
fill ~267 ~63 ~79 ~270 ~65 ~79 dirt
fill ~267 ~66 ~79 ~270 ~66 ~79 grass_block
fill ~271 ~60 ~79 ~271 ~63 ~79 stone
fill ~271 ~64 ~79 ~271 ~66 ~79 dirt
fill ~271 ~67 ~79 ~271 ~67 ~79 grass_block