fill ~416 ~60 ~96 ~419 ~63 ~96 stone
fill ~416 ~64 ~96 ~419 ~66 ~96 dirt
fill ~416 ~67 ~96 ~419 ~67 ~96 grass_block
fill ~420 ~60 ~96 ~422 ~62 ~96 stone
fill ~420 ~63 ~96 ~422 ~65 ~96 dirt
fill ~420 ~66 ~96 ~422 ~66 ~96 grass_block
fill ~423 ~60 ~96 ~431 ~61 ~96 stone
fill ~423 ~62 ~96 ~431 ~64 ~96 dirt
fill ~423 ~65 ~96 ~431 ~65 ~96 grass_block
fill ~416 ~60 ~97 ~418 ~63 ~97 stone
fill ~416 ~64 ~97 ~418 ~66 ~97 dirt
fill ~416 ~67 ~97 ~418 ~67 ~97 grass_block
fill ~419 ~60 ~97 ~422 ~62 ~97 stone
fill ~419 ~63 ~97 ~422 ~65 ~97 dirt
fill ~419 ~66 ~97 ~422 ~66 ~97 grass_block
fill ~423 ~60 ~97 ~431 ~61 ~97 stone
fill ~423 ~62 ~97 ~431 ~64 ~97 dirt
fill ~423 ~65 ~97 ~431 ~65 ~97 grass_block
fill ~416 ~60 ~98 ~417 ~63 ~98 stone
fill ~416 ~64 ~98 ~417 ~66 ~98 dirt
fill ~416 ~67 ~98 ~417 ~67 ~98 grass_block
fill ~418 ~60 ~98 ~426 ~62 ~98 stone
fill ~418 ~63 ~98 ~426 ~65 ~98 dirt
fill ~418 ~66 ~98 ~426 ~66 ~98 grass_block
fill ~427 ~60 ~98 ~427 ~63 ~98 stone
fill ~427 ~64 ~98 ~427 ~66 ~98 dirt
fill ~427 ~67 ~98 ~427 ~67 ~98 grass_block
fill ~428 ~60 ~98 ~430 ~62 ~98 stone
fill ~428 ~63 ~98 ~430 ~65 ~98 dirt
fill ~428 ~66 ~98 ~430 ~66 ~98 grass_block
fill ~431 ~60 ~98 ~431 ~61 ~98 stone
fill ~431 ~62 ~98 ~431 ~64 ~98 dirt
fill ~431 ~65 ~98 ~431 ~65 ~98 grass_block
fill ~416 ~60 ~99 ~420 ~62 ~99 stone
fill ~416 ~63 ~99 ~420 ~65 ~99 dirt
fill ~416 ~66 ~99 ~420 ~66 ~99 grass_block
fill ~421 ~60 ~99 ~424 ~63 ~99 stone
fill ~421 ~64 ~99 ~424 ~66 ~99 dirt
fill ~421 ~67 ~99 ~424 ~67 ~99 grass_block
fill ~425 ~60 ~99 ~425 ~62 ~99 stone
fill ~425 ~63 ~99 ~425 ~65 ~99 dirt
fill ~425 ~66 ~99 ~425 ~66 ~99 grass_block
fill ~426 ~60 ~99 ~429 ~63 ~99 stone
fill ~426 ~64 ~99 ~429 ~66 ~99 dirt
fill ~426 ~67 ~99 ~429 ~67 ~99 grass_block
fill ~430 ~60 ~99 ~431 ~62 ~99 stone
fill ~430 ~63 ~99 ~431 ~65 ~99 dirt
fill ~430 ~66 ~99 ~431 ~66 ~99 grass_block
fill ~416 ~60 ~100 ~418 ~63 ~100 stone
fill ~416 ~64 ~100 ~418 ~66 ~100 dirt
fill ~416 ~67 ~100 ~418 ~67 ~100 grass_block
fill ~419 ~60 ~100 ~419 ~62 ~100 stone
fill ~419 ~63 ~100 ~419 ~65 ~100 dirt
fill ~419 ~66 ~100 ~419 ~66 ~100 grass_block
fill ~420 ~60 ~100 ~420 ~63 ~100 stone
fill ~420 ~64 ~100 ~420 ~66 ~100 dirt
fill ~420 ~67 ~100 ~420 ~67 ~100 grass_block
fill ~421 ~60 ~100 ~423 ~64 ~100 stone
fill ~421 ~65 ~100 ~423 ~67 ~100 dirt
fill ~421 ~68 ~100 ~423 ~68 ~100 grass_block
fill ~424 ~60 ~100 ~426 ~63 ~100 stone
fill ~424 ~64 ~100 ~426 ~66 ~100 dirt
fill ~424 ~67 ~100 ~426 ~67 ~100 grass_block
fill ~427 ~60 ~100 ~428 ~64 ~100 stone
fill ~427 ~65 ~100 ~428 ~67 ~100 dirt
fill ~427 ~68 ~100 ~428 ~68 ~100 grass_block
fill ~429 ~60 ~100 ~430 ~63 ~100 stone
fill ~429 ~64 ~100 ~430 ~66 ~100 dirt
fill ~429 ~67 ~100 ~430 ~67 ~100 grass_block
fill ~431 ~60 ~100 ~431 ~62 ~100 stone
fill ~431 ~63 ~100 ~431 ~65 ~100 dirt
fill ~431 ~66 ~100 ~431 ~66 ~100 grass_block
fill ~416 ~60 ~101 ~416 ~64 ~101 stone
fill ~416 ~65 ~101 ~416 ~67 ~101 dirt
fill ~416 ~68 ~101 ~416 ~68 ~101 grass_block
fill ~417 ~60 ~101 ~420 ~63 ~101 stone
fill ~417 ~64 ~101 ~420 ~66 ~101 dirt
fill ~417 ~67 ~101 ~420 ~67 ~101 grass_block
fill ~421 ~60 ~101 ~429 ~64 ~101 stone
fill ~421 ~65 ~101 ~429 ~67 ~101 dirt
fill ~421 ~68 ~101 ~429 ~68 ~101 grass_block
fill ~430 ~60 ~101 ~431 ~63 ~101 stone
fill ~430 ~64 ~101 ~431 ~66 ~101 dirt
fill ~430 ~67 ~101 ~431 ~67 ~101 grass_block
fill ~416 ~60 ~102 ~417 ~64 ~102 stone
fill ~416 ~65 ~102 ~417 ~67 ~102 dirt
fill ~416 ~68 ~102 ~417 ~68 ~102 grass_block
fill ~418 ~60 ~102 ~420 ~63 ~102 stone
fill ~418 ~64 ~102 ~420 ~66 ~102 dirt
fill ~418 ~67 ~102 ~420 ~67 ~102 grass_block
fill ~421 ~60 ~102 ~422 ~64 ~102 stone
fill ~421 ~65 ~102 ~422 ~67 ~102 dirt
fill ~421 ~68 ~102 ~422 ~68 ~102 grass_block
fill ~423 ~60 ~102 ~423 ~65 ~102 stone
fill ~423 ~66 ~102 ~423 ~68 ~102 dirt
fill ~423 ~69 ~102 ~423 ~69 ~102 grass_block
fill ~424 ~60 ~102 ~430 ~64 ~102 stone
fill ~424 ~65 ~102 ~430 ~67 ~102 dirt
fill ~424 ~68 ~102 ~430 ~68 ~102 grass_block
fill ~431 ~60 ~102 ~431 ~63 ~102 stone
fill ~431 ~64 ~102 ~431 ~66 ~102 dirt
fill ~431 ~67 ~102 ~431 ~67 ~102 grass_block
fill ~416 ~60 ~103 ~418 ~64 ~103 stone
fill ~416 ~65 ~103 ~418 ~67 ~103 dirt
fill ~416 ~68 ~103 ~418 ~68 ~103 grass_block
fill ~419 ~60 ~103 ~419 ~63 ~103 stone
fill ~419 ~64 ~103 ~419 ~66 ~103 dirt
fill ~419 ~67 ~103 ~419 ~67 ~103 grass_block
fill ~420 ~60 ~103 ~422 ~64 ~103 stone
fill ~420 ~65 ~103 ~422 ~67 ~103 dirt
fill ~420 ~68 ~103 ~422 ~68 ~103 grass_block
fill ~423 ~60 ~103 ~425 ~65 ~103 stone
fill ~423 ~66 ~103 ~425 ~68 ~103 dirt
fill ~423 ~69 ~103 ~425 ~69 ~103 grass_block
fill ~426 ~60 ~103 ~431 ~64 ~103 stone
fill ~426 ~65 ~103 ~431 ~67 ~103 dirt
fill ~426 ~68 ~103 ~431 ~68 ~103 grass_block
fill ~416 ~60 ~104 ~416 ~65 ~104 stone
fill ~416 ~66 ~104 ~416 ~68 ~104 dirt
fill ~416 ~69 ~104 ~416 ~69 ~104 grass_block
fill ~417 ~60 ~104 ~422 ~64 ~104 stone
fill ~417 ~65 ~104 ~422 ~67 ~104 dirt
fill ~417 ~68 ~104 ~422 ~68 ~104 grass_block
fill ~423 ~60 ~104 ~428 ~65 ~104 stone
fill ~423 ~66 ~104 ~428 ~68 ~104 dirt
fill ~423 ~69 ~104 ~428 ~69 ~104 grass_block
fill ~429 ~60 ~104 ~431 ~64 ~104 stone
fill ~429 ~65 ~104 ~431 ~67 ~104 dirt
fill ~429 ~68 ~104 ~431 ~68 ~104 grass_block
fill ~416 ~60 ~105 ~416 ~65 ~105 stone
fill ~416 ~66 ~105 ~416 ~68 ~105 dirt
fill ~416 ~69 ~105 ~416 ~69 ~105 grass_block
fill ~417 ~60 ~105 ~423 ~64 ~105 stone
fill ~417 ~65 ~105 ~423 ~67 ~105 dirt
fill ~417 ~68 ~105 ~423 ~68 ~105 grass_block
fill ~424 ~60 ~105 ~429 ~65 ~105 stone
fill ~424 ~66 ~105 ~429 ~68 ~105 dirt
fill ~424 ~69 ~105 ~429 ~69 ~105 grass_block
fill ~430 ~60 ~105 ~431 ~64 ~105 stone
fill ~430 ~65 ~105 ~431 ~67 ~105 dirt
fill ~430 ~68 ~105 ~431 ~68 ~105 grass_block
fill ~416 ~60 ~106 ~423 ~64 ~106 stone
fill ~416 ~65 ~106 ~423 ~67 ~106 dirt
fill ~416 ~68 ~106 ~423 ~68 ~106 grass_block
fill ~424 ~60 ~106 ~430 ~65 ~106 stone
fill ~424 ~66 ~106 ~430 ~68 ~106 dirt
fill ~424 ~69 ~106 ~430 ~69 ~106 grass_block
fill ~431 ~60 ~106 ~431 ~64 ~106 stone
fill ~431 ~65 ~106 ~431 ~67 ~106 dirt
fill ~431 ~68 ~106 ~431 ~68 ~106 grass_block
fill ~416 ~60 ~107 ~425 ~64 ~107 stone
fill ~416 ~65 ~107 ~425 ~67 ~107 dirt
fill ~416 ~68 ~107 ~425 ~68 ~107 grass_block
fill ~426 ~60 ~107 ~431 ~65 ~107 stone
fill ~426 ~66 ~107 ~431 ~68 ~107 dirt
fill ~426 ~69 ~107 ~431 ~69 ~107 grass_block
fill ~416 ~60 ~108 ~427 ~64 ~108 stone
fill ~416 ~65 ~108 ~427 ~67 ~108 dirt
fill ~416 ~68 ~108 ~427 ~68 ~108 grass_block
fill ~428 ~60 ~108 ~431 ~65 ~108 stone
fill ~428 ~66 ~108 ~431 ~68 ~108 dirt
fill ~428 ~69 ~108 ~431 ~69 ~108 grass_block
fill ~416 ~60 ~109 ~418 ~64 ~109 stone
fill ~416 ~65 ~109 ~418 ~67 ~109 dirt
fill ~416 ~68 ~109 ~418 ~68 ~109 grass_block
fill ~419 ~60 ~109 ~422 ~63 ~109 stone
fill ~419 ~64 ~109 ~422 ~66 ~109 dirt
fill ~419 ~67 ~109 ~422 ~67 ~109 grass_block
fill ~423 ~60 ~109 ~428 ~64 ~109 stone
fill ~423 ~65 ~109 ~428 ~67 ~109 dirt
fill ~423 ~68 ~109 ~428 ~68 ~109 grass_block
fill ~429 ~60 ~109 ~431 ~65 ~109 stone
fill ~429 ~66 ~109 ~431 ~68 ~109 dirt
fill ~429 ~69 ~109 ~431 ~69 ~109 grass_block
fill ~416 ~60 ~110 ~416 ~64 ~110 stone
fill ~416 ~65 ~110 ~416 ~67 ~110 dirt
fill ~416 ~68 ~110 ~416 ~68 ~110 grass_block
fill ~417 ~60 ~110 ~423 ~63 ~110 stone
fill ~417 ~64 ~110 ~423 ~66 ~110 dirt
fill ~417 ~67 ~110 ~423 ~67 ~110 grass_block
fill ~424 ~60 ~110 ~428 ~64 ~110 stone
fill ~424 ~65 ~110 ~428 ~67 ~110 dirt
fill ~424 ~68 ~110 ~428 ~68 ~110 grass_block
fill ~429 ~60 ~110 ~431 ~65 ~110 stone
fill ~429 ~66 ~110 ~431 ~68 ~110 dirt
fill ~429 ~69 ~110 ~431 ~69 ~110 grass_block
fill ~416 ~60 ~111 ~423 ~63 ~111 stone
fill ~416 ~64 ~111 ~423 ~66 ~111 dirt
fill ~416 ~67 ~111 ~423 ~67 ~111 grass_block
fill ~424 ~60 ~111 ~430 ~64 ~111 stone
fill ~424 ~65 ~111 ~430 ~67 ~111 dirt
fill ~424 ~68 ~111 ~430 ~68 ~111 grass_block
fill ~431 ~60 ~111 ~431 ~65 ~111 stone
fill ~431 ~66 ~111 ~431 ~68 ~111 dirt
fill ~431 ~69 ~111 ~431 ~69 ~111 grass_block