fill ~384 ~60 ~112 ~395 ~63 ~112 stone
fill ~384 ~64 ~112 ~395 ~66 ~112 dirt
fill ~384 ~67 ~112 ~395 ~67 ~112 grass_block
fill ~396 ~60 ~112 ~396 ~62 ~112 stone
fill ~396 ~63 ~112 ~396 ~65 ~112 dirt
fill ~396 ~66 ~112 ~396 ~66 ~112 grass_block
fill ~397 ~60 ~112 ~399 ~63 ~112 stone
fill ~397 ~64 ~112 ~399 ~66 ~112 dirt
fill ~397 ~67 ~112 ~399 ~67 ~112 grass_block
fill ~384 ~60 ~113 ~394 ~63 ~113 stone
fill ~384 ~64 ~113 ~394 ~66 ~113 dirt
fill ~384 ~67 ~113 ~394 ~67 ~113 grass_block
fill ~395 ~60 ~113 ~396 ~62 ~113 stone
fill ~395 ~63 ~113 ~396 ~65 ~113 dirt
fill ~395 ~66 ~113 ~396 ~66 ~113 grass_block
fill ~397 ~60 ~113 ~399 ~63 ~113 stone
fill ~397 ~64 ~113 ~399 ~66 ~113 dirt
fill ~397 ~67 ~113 ~399 ~67 ~113 grass_block
fill ~384 ~60 ~114 ~392 ~63 ~114 stone
fill ~384 ~64 ~114 ~392 ~66 ~114 dirt
fill ~384 ~67 ~114 ~392 ~67 ~114 grass_block
fill ~393 ~60 ~114 ~396 ~62 ~114 stone
fill ~393 ~63 ~114 ~396 ~65 ~114 dirt
fill ~393 ~66 ~114 ~396 ~66 ~114 grass_block
fill ~397 ~60 ~114 ~398 ~63 ~114 stone
fill ~397 ~64 ~114 ~398 ~66 ~114 dirt
fill ~397 ~67 ~114 ~398 ~67 ~114 grass_block
fill ~399 ~60 ~114 ~399 ~64 ~114 stone
fill ~399 ~65 ~114 ~399 ~67 ~114 dirt
fill ~399 ~68 ~114 ~399 ~68 ~114 grass_block
fill ~384 ~60 ~115 ~384 ~62 ~115 stone
fill ~384 ~63 ~115 ~384 ~65 ~115 dirt
fill ~384 ~66 ~115 ~384 ~66 ~115 grass_block
fill ~385 ~60 ~115 ~391 ~63 ~115 stone
fill ~385 ~64 ~115 ~391 ~66 ~115 dirt
fill ~385 ~67 ~115 ~391 ~67 ~115 grass_block
fill ~392 ~60 ~115 ~395 ~62 ~115 stone
fill ~392 ~63 ~115 ~395 ~65 ~115 dirt
fill ~392 ~66 ~115 ~395 ~66 ~115 grass_block
fill ~396 ~60 ~115 ~398 ~63 ~115 stone
fill ~396 ~64 ~115 ~398 ~66 ~115 dirt
fill ~396 ~67 ~115 ~398 ~67 ~115 grass_block
fill ~399 ~60 ~115 ~399 ~64 ~115 stone
fill ~399 ~65 ~115 ~399 ~67 ~115 dirt
fill ~399 ~68 ~115 ~399 ~68 ~115 grass_block
fill ~384 ~60 ~116 ~384 ~62 ~116 stone
fill ~384 ~63 ~116 ~384 ~65 ~116 dirt
fill ~384 ~66 ~116 ~384 ~66 ~116 grass_block
fill ~385 ~60 ~116 ~389 ~63 ~116 stone
fill ~385 ~64 ~116 ~389 ~66 ~116 dirt
fill ~385 ~67 ~116 ~389 ~67 ~116 grass_block
fill ~390 ~60 ~116 ~395 ~62 ~116 stone
fill ~390 ~63 ~116 ~395 ~65 ~116 dirt
fill ~390 ~66 ~116 ~395 ~66 ~116 grass_block
fill ~396 ~60 ~116 ~398 ~63 ~116 stone
fill ~396 ~64 ~116 ~398 ~66 ~116 dirt
fill ~396 ~67 ~116 ~398 ~67 ~116 grass_block
fill ~399 ~60 ~116 ~399 ~64 ~116 stone
fill ~399 ~65 ~116 ~399 ~67 ~116 dirt
fill ~399 ~68 ~116 ~399 ~68 ~116 grass_block
fill ~384 ~60 ~117 ~385 ~62 ~117 stone
fill ~384 ~63 ~117 ~385 ~65 ~117 dirt
fill ~384 ~66 ~117 ~385 ~66 ~117 grass_block
fill ~386 ~60 ~117 ~387 ~63 ~117 stone
fill ~386 ~64 ~117 ~387 ~66 ~117 dirt
fill ~386 ~67 ~117 ~387 ~67 ~117 grass_block
fill ~388 ~60 ~117 ~394 ~62 ~117 stone
fill ~388 ~63 ~117 ~394 ~65 ~117 dirt
fill ~388 ~66 ~117 ~394 ~66 ~117 grass_block
fill ~395 ~60 ~117 ~398 ~63 ~117 stone
fill ~395 ~64 ~117 ~398 ~66 ~117 dirt
fill ~395 ~67 ~117 ~398 ~67 ~117 grass_block
fill ~399 ~60 ~117 ~399 ~64 ~117 stone
fill ~399 ~65 ~117 ~399 ~67 ~117 dirt
fill ~399 ~68 ~117 ~399 ~68 ~117 grass_block
fill ~384 ~60 ~118 ~395 ~62 ~118 stone
fill ~384 ~63 ~118 ~395 ~65 ~118 dirt
fill ~384 ~66 ~118 ~395 ~66 ~118 grass_block
fill ~396 ~60 ~118 ~399 ~63 ~118 stone
fill ~396 ~64 ~118 ~399 ~66 ~118 dirt
fill ~396 ~67 ~118 ~399 ~67 ~118 grass_block
fill ~384 ~60 ~119 ~396 ~62 ~119 stone
fill ~384 ~63 ~119 ~396 ~65 ~119 dirt
fill ~384 ~66 ~119 ~396 ~66 ~119 grass_block
fill ~397 ~60 ~119 ~399 ~63 ~119 stone
fill ~397 ~64 ~119 ~399 ~66 ~119 dirt
fill ~397 ~67 ~119 ~399 ~67 ~119 grass_block
fill ~384 ~60 ~120 ~394 ~62 ~120 stone
fill ~384 ~63 ~120 ~394 ~65 ~120 dirt
fill ~384 ~66 ~120 ~394 ~66 ~120 grass_block
fill ~395 ~60 ~120 ~399 ~63 ~120 stone
fill ~395 ~64 ~120 ~399 ~66 ~120 dirt
fill ~395 ~67 ~120 ~399 ~67 ~120 grass_block
fill ~384 ~60 ~121 ~384 ~62 ~121 stone
fill ~384 ~63 ~121 ~384 ~65 ~121 dirt
fill ~384 ~66 ~121 ~384 ~66 ~121 grass_block
fill ~385 ~60 ~121 ~385 ~61 ~121 stone
fill ~385 ~62 ~121 ~385 ~64 ~121 dirt
fill ~385 ~65 ~121 ~385 ~65 ~121 grass_block
fill ~386 ~60 ~121 ~394 ~62 ~121 stone
fill ~386 ~63 ~121 ~394 ~65 ~121 dirt
fill ~386 ~66 ~121 ~394 ~66 ~121 grass_block
fill ~395 ~60 ~121 ~396 ~63 ~121 stone
fill ~395 ~64 ~121 ~396 ~66 ~121 dirt
fill ~395 ~67 ~121 ~396 ~67 ~121 grass_block
fill ~397 ~60 ~121 ~397 ~64 ~121 stone
fill ~397 ~65 ~121 ~397 ~67 ~121 dirt
fill ~397 ~68 ~121 ~397 ~68 ~121 grass_block
fill ~398 ~60 ~121 ~399 ~63 ~121 stone
fill ~398 ~64 ~121 ~399 ~66 ~121 dirt
fill ~398 ~67 ~121 ~399 ~67 ~121 grass_block
fill ~384 ~60 ~122 ~384 ~62 ~122 stone
fill ~384 ~63 ~122 ~384 ~65 ~122 dirt
fill ~384 ~66 ~122 ~384 ~66 ~122 grass_block
fill ~385 ~60 ~122 ~385 ~61 ~122 stone
fill ~385 ~62 ~122 ~385 ~64 ~122 dirt
fill ~385 ~65 ~122 ~385 ~65 ~122 grass_block
fill ~386 ~60 ~122 ~393 ~62 ~122 stone
fill ~386 ~63 ~122 ~393 ~65 ~122 dirt
fill ~386 ~66 ~122 ~393 ~66 ~122 grass_block
fill ~394 ~60 ~122 ~396 ~63 ~122 stone
fill ~394 ~64 ~122 ~396 ~66 ~122 dirt
fill ~394 ~67 ~122 ~396 ~67 ~122 grass_block
fill ~397 ~60 ~122 ~398 ~64 ~122 stone
fill ~397 ~65 ~122 ~398 ~67 ~122 dirt
fill ~397 ~68 ~122 ~398 ~68 ~122 grass_block
fill ~399 ~60 ~122 ~399 ~63 ~122 stone
fill ~399 ~64 ~122 ~399 ~66 ~122 dirt
fill ~399 ~67 ~122 ~399 ~67 ~122 grass_block
fill ~384 ~60 ~123 ~385 ~62 ~123 stone
fill ~384 ~63 ~123 ~385 ~65 ~123 dirt
fill ~384 ~66 ~123 ~385 ~66 ~123 grass_block
fill ~386 ~60 ~123 ~386 ~61 ~123 stone
fill ~386 ~62 ~123 ~386 ~64 ~123 dirt
fill ~386 ~65 ~123 ~386 ~65 ~123 grass_block
fill ~387 ~60 ~123 ~387 ~62 ~123 stone
fill ~387 ~63 ~123 ~387 ~65 ~123 dirt
fill ~387 ~66 ~123 ~387 ~66 ~123 grass_block
fill ~388 ~60 ~123 ~392 ~61 ~123 stone
fill ~388 ~62 ~123 ~392 ~64 ~123 dirt
fill ~388 ~65 ~123 ~392 ~65 ~123 grass_block
fill ~393 ~60 ~123 ~393 ~62 ~123 stone
fill ~393 ~63 ~123 ~393 ~65 ~123 dirt
fill ~393 ~66 ~123 ~393 ~66 ~123 grass_block
fill ~394 ~60 ~123 ~396 ~63 ~123 stone
fill ~394 ~64 ~123 ~396 ~66 ~123 dirt
fill ~394 ~67 ~123 ~396 ~67 ~123 grass_block
fill ~397 ~60 ~123 ~399 ~64 ~123 stone
fill ~397 ~65 ~123 ~399 ~67 ~123 dirt
fill ~397 ~68 ~123 ~399 ~68 ~123 grass_block
fill ~384 ~60 ~124 ~385 ~62 ~124 stone
fill ~384 ~63 ~124 ~385 ~65 ~124 dirt
fill ~384 ~66 ~124 ~385 ~66 ~124 grass_block
fill ~386 ~60 ~124 ~391 ~61 ~124 stone
fill ~386 ~62 ~124 ~391 ~64 ~124 dirt
fill ~386 ~65 ~124 ~391 ~65 ~124 grass_block
fill ~392 ~60 ~124 ~393 ~62 ~124 stone
fill ~392 ~63 ~124 ~393 ~65 ~124 dirt
fill ~392 ~66 ~124 ~393 ~66 ~124 grass_block
fill ~394 ~60 ~124 ~397 ~63 ~124 stone
fill ~394 ~64 ~124 ~397 ~66 ~124 dirt
fill ~394 ~67 ~124 ~397 ~67 ~124 grass_block
fill ~398 ~60 ~124 ~399 ~64 ~124 stone
fill ~398 ~65 ~124 ~399 ~67 ~124 dirt
fill ~398 ~68 ~124 ~399 ~68 ~124 grass_block
fill ~384 ~60 ~125 ~385 ~62 ~125 stone
fill ~384 ~63 ~125 ~385 ~65 ~125 dirt
fill ~384 ~66 ~125 ~385 ~66 ~125 grass_block
fill ~386 ~60 ~125 ~391 ~61 ~125 stone
fill ~386 ~62 ~125 ~391 ~64 ~125 dirt
fill ~386 ~65 ~125 ~391 ~65 ~125 grass_block
fill ~392 ~60 ~125 ~395 ~62 ~125 stone
fill ~392 ~63 ~125 ~395 ~65 ~125 dirt
fill ~392 ~66 ~125 ~395 ~66 ~125 grass_block
fill ~396 ~60 ~125 ~398 ~63 ~125 stone
fill ~396 ~64 ~125 ~398 ~66 ~125 dirt
fill ~396 ~67 ~125 ~398 ~67 ~125 grass_block
fill ~399 ~60 ~125 ~399 ~64 ~125 stone
fill ~399 ~65 ~125 ~399 ~67 ~125 dirt
fill ~399 ~68 ~125 ~399 ~68 ~125 grass_block
fill ~384 ~60 ~126 ~385 ~62 ~126 stone
fill ~384 ~63 ~126 ~385 ~65 ~126 dirt
fill ~384 ~66 ~126 ~385 ~66 ~126 grass_block
fill ~386 ~60 ~126 ~389 ~61 ~126 stone
fill ~386 ~62 ~126 ~389 ~64 ~126 dirt
fill ~386 ~65 ~126 ~389 ~65 ~126 grass_block
fill ~390 ~60 ~126 ~395 ~62 ~126 stone
fill ~390 ~63 ~126 ~395 ~65 ~126 dirt
fill ~390 ~66 ~126 ~395 ~66 ~126 grass_block
fill ~396 ~60 ~126 ~397 ~63 ~126 stone
fill ~396 ~64 ~126 ~397 ~66 ~126 dirt
fill ~396 ~67 ~126 ~397 ~67 ~126 grass_block
fill ~398 ~60 ~126 ~399 ~64 ~126 stone
fill ~398 ~65 ~126 ~399 ~67 ~126 dirt
fill ~398 ~68 ~126 ~399 ~68 ~126 grass_block
fill ~384 ~60 ~127 ~384 ~62 ~127 stone
fill ~384 ~63 ~127 ~384 ~65 ~127 dirt
fill ~384 ~66 ~127 ~384 ~66 ~127 grass_block
fill ~385 ~60 ~127 ~389 ~61 ~127 stone
fill ~385 ~62 ~127 ~389 ~64 ~127 dirt
fill ~385 ~65 ~127 ~389 ~65 ~127 grass_block
fill ~390 ~60 ~127 ~390 ~62 ~127 stone
fill ~390 ~63 ~127 ~390 ~65 ~127 dirt
fill ~390 ~66 ~127 ~390 ~66 ~127 grass_block
fill ~391 ~60 ~127 ~392 ~63 ~127 stone
fill ~391 ~64 ~127 ~392 ~66 ~127 dirt
fill ~391 ~67 ~127 ~392 ~67 ~127 grass_block
fill ~393 ~60 ~127 ~395 ~62 ~127 stone
fill ~393 ~63 ~127 ~395 ~65 ~127 dirt
fill ~393 ~66 ~127 ~395 ~66 ~127 grass_block
fill ~396 ~60 ~127 ~397 ~63 ~127 stone
fill ~396 ~64 ~127 ~397 ~66 ~127 dirt
fill ~396 ~67 ~127 ~397 ~67 ~127 grass_block
fill ~398 ~60 ~127 ~399 ~64 ~127 stone
fill ~398 ~65 ~127 ~399 ~67 ~127 dirt
fill ~398 ~68 ~127 ~399 ~68 ~127 grass_block