fill ~176 ~60 ~96 ~177 ~63 ~96 stone
fill ~176 ~64 ~96 ~177 ~66 ~96 dirt
fill ~176 ~67 ~96 ~177 ~67 ~96 grass_block
fill ~178 ~60 ~96 ~178 ~62 ~96 stone
fill ~178 ~63 ~96 ~178 ~65 ~96 dirt
fill ~178 ~66 ~96 ~178 ~66 ~96 grass_block
fill ~179 ~60 ~96 ~180 ~63 ~96 stone
fill ~179 ~64 ~96 ~180 ~66 ~96 dirt
fill ~179 ~67 ~96 ~180 ~67 ~96 grass_block
fill ~181 ~60 ~96 ~182 ~64 ~96 stone
fill ~181 ~65 ~96 ~182 ~67 ~96 dirt
fill ~181 ~68 ~96 ~182 ~68 ~96 grass_block
fill ~183 ~60 ~96 ~191 ~63 ~96 stone
fill ~183 ~64 ~96 ~191 ~66 ~96 dirt
fill ~183 ~67 ~96 ~191 ~67 ~96 grass_block
fill ~176 ~60 ~97 ~177 ~63 ~97 stone
fill ~176 ~64 ~97 ~177 ~66 ~97 dirt
fill ~176 ~67 ~97 ~177 ~67 ~97 grass_block
fill ~178 ~60 ~97 ~179 ~62 ~97 stone
fill ~178 ~63 ~97 ~179 ~65 ~97 dirt
fill ~178 ~66 ~97 ~179 ~66 ~97 grass_block
fill ~180 ~60 ~97 ~181 ~63 ~97 stone
fill ~180 ~64 ~97 ~181 ~66 ~97 dirt
fill ~180 ~67 ~97 ~181 ~67 ~97 grass_block
fill ~182 ~60 ~97 ~182 ~64 ~97 stone
fill ~182 ~65 ~97 ~182 ~67 ~97 dirt
fill ~182 ~68 ~97 ~182 ~68 ~97 grass_block
fill ~183 ~60 ~97 ~187 ~63 ~97 stone
fill ~183 ~64 ~97 ~187 ~66 ~97 dirt
fill ~183 ~67 ~97 ~187 ~67 ~97 grass_block
fill ~188 ~60 ~97 ~188 ~62 ~97 stone
fill ~188 ~63 ~97 ~188 ~65 ~97 dirt
fill ~188 ~66 ~97 ~188 ~66 ~97 grass_block
fill ~189 ~60 ~97 ~191 ~63 ~97 stone
fill ~189 ~64 ~97 ~191 ~66 ~97 dirt
fill ~189 ~67 ~97 ~191 ~67 ~97 grass_block
fill ~176 ~60 ~98 ~178 ~63 ~98 stone
fill ~176 ~64 ~98 ~178 ~66 ~98 dirt
fill ~176 ~67 ~98 ~178 ~67 ~98 grass_block
fill ~179 ~60 ~98 ~180 ~62 ~98 stone
fill ~179 ~63 ~98 ~180 ~65 ~98 dirt
fill ~179 ~66 ~98 ~180 ~66 ~98 grass_block
fill ~181 ~60 ~98 ~187 ~63 ~98 stone
fill ~181 ~64 ~98 ~187 ~66 ~98 dirt
fill ~181 ~67 ~98 ~187 ~67 ~98 grass_block
fill ~188 ~60 ~98 ~188 ~62 ~98 stone
fill ~188 ~63 ~98 ~188 ~65 ~98 dirt
fill ~188 ~66 ~98 ~188 ~66 ~98 grass_block
fill ~189 ~60 ~98 ~191 ~63 ~98 stone
fill ~189 ~64 ~98 ~191 ~66 ~98 dirt
fill ~189 ~67 ~98 ~191 ~67 ~98 grass_block
fill ~176 ~60 ~99 ~178 ~63 ~99 stone
fill ~176 ~64 ~99 ~178 ~66 ~99 dirt
fill ~176 ~67 ~99 ~178 ~67 ~99 grass_block
fill ~179 ~60 ~99 ~180 ~62 ~99 stone
fill ~179 ~63 ~99 ~180 ~65 ~99 dirt
fill ~179 ~66 ~99 ~180 ~66 ~99 grass_block
fill ~181 ~60 ~99 ~191 ~63 ~99 stone
fill ~181 ~64 ~99 ~191 ~66 ~99 dirt
fill ~181 ~67 ~99 ~191 ~67 ~99 grass_block
fill ~176 ~60 ~100 ~176 ~64 ~100 stone
fill ~176 ~65 ~100 ~176 ~67 ~100 dirt
fill ~176 ~68 ~100 ~176 ~68 ~100 grass_block
fill ~177 ~60 ~100 ~179 ~63 ~100 stone
fill ~177 ~64 ~100 ~179 ~66 ~100 dirt
fill ~177 ~67 ~100 ~179 ~67 ~100 grass_block
fill ~180 ~60 ~100 ~182 ~62 ~100 stone
fill ~180 ~63 ~100 ~182 ~65 ~100 dirt
fill ~180 ~66 ~100 ~182 ~66 ~100 grass_block
fill ~183 ~60 ~100 ~191 ~63 ~100 stone
fill ~183 ~64 ~100 ~191 ~66 ~100 dirt
fill ~183 ~67 ~100 ~191 ~67 ~100 grass_block
fill ~176 ~60 ~101 ~176 ~64 ~101 stone
fill ~176 ~65 ~101 ~176 ~67 ~101 dirt
fill ~176 ~68 ~101 ~176 ~68 ~101 grass_block
fill ~177 ~60 ~101 ~180 ~63 ~101 stone
fill ~177 ~64 ~101 ~180 ~66 ~101 dirt
fill ~177 ~67 ~101 ~180 ~67 ~101 grass_block
fill ~181 ~60 ~101 ~183 ~62 ~101 stone
fill ~181 ~63 ~101 ~183 ~65 ~101 dirt
fill ~181 ~66 ~101 ~183 ~66 ~101 grass_block
fill ~184 ~60 ~101 ~187 ~63 ~101 stone
fill ~184 ~64 ~101 ~187 ~66 ~101 dirt
fill ~184 ~67 ~101 ~187 ~67 ~101 grass_block
fill ~188 ~60 ~101 ~189 ~62 ~101 stone
fill ~188 ~63 ~101 ~189 ~65 ~101 dirt
fill ~188 ~66 ~101 ~189 ~66 ~101 grass_block
fill ~190 ~60 ~101 ~191 ~63 ~101 stone
fill ~190 ~64 ~101 ~191 ~66 ~101 dirt
fill ~190 ~67 ~101 ~191 ~67 ~101 grass_block
fill ~176 ~60 ~102 ~177 ~64 ~102 stone
fill ~176 ~65 ~102 ~177 ~67 ~102 dirt
fill ~176 ~68 ~102 ~177 ~68 ~102 grass_block
fill ~178 ~60 ~102 ~181 ~63 ~102 stone
fill ~178 ~64 ~102 ~181 ~66 ~102 dirt
fill ~178 ~67 ~102 ~181 ~67 ~102 grass_block
fill ~182 ~60 ~102 ~183 ~62 ~102 stone
fill ~182 ~63 ~102 ~183 ~65 ~102 dirt
fill ~182 ~66 ~102 ~183 ~66 ~102 grass_block
fill ~184 ~60 ~102 ~187 ~63 ~102 stone
fill ~184 ~64 ~102 ~187 ~66 ~102 dirt
fill ~184 ~67 ~102 ~187 ~67 ~102 grass_block
fill ~188 ~60 ~102 ~190 ~62 ~102 stone
fill ~188 ~63 ~102 ~190 ~65 ~102 dirt
fill ~188 ~66 ~102 ~190 ~66 ~102 grass_block
fill ~191 ~60 ~102 ~191 ~63 ~102 stone
fill ~191 ~64 ~102 ~191 ~66 ~102 dirt
fill ~191 ~67 ~102 ~191 ~67 ~102 grass_block
fill ~176 ~60 ~103 ~178 ~64 ~103 stone
fill ~176 ~65 ~103 ~178 ~67 ~103 dirt
fill ~176 ~68 ~103 ~178 ~68 ~103 grass_block
fill ~179 ~60 ~103 ~182 ~63 ~103 stone
fill ~179 ~64 ~103 ~182 ~66 ~103 dirt
fill ~179 ~67 ~103 ~182 ~67 ~103 grass_block
fill ~183 ~60 ~103 ~184 ~62 ~103 stone
fill ~183 ~63 ~103 ~184 ~65 ~103 dirt
fill ~183 ~66 ~103 ~184 ~66 ~103 grass_block
fill ~185 ~60 ~103 ~187 ~63 ~103 stone
fill ~185 ~64 ~103 ~187 ~66 ~103 dirt
fill ~185 ~67 ~103 ~187 ~67 ~103 grass_block
fill ~188 ~60 ~103 ~191 ~62 ~103 stone
fill ~188 ~63 ~103 ~191 ~65 ~103 dirt
fill ~188 ~66 ~103 ~191 ~66 ~103 grass_block
fill ~176 ~60 ~104 ~176 ~65 ~104 stone
fill ~176 ~66 ~104 ~176 ~68 ~104 dirt
fill ~176 ~69 ~104 ~176 ~69 ~104 grass_block
fill ~177 ~60 ~104 ~179 ~64 ~104 stone
fill ~177 ~65 ~104 ~179 ~67 ~104 dirt
fill ~177 ~68 ~104 ~179 ~68 ~104 grass_block
fill ~180 ~60 ~104 ~182 ~63 ~104 stone
fill ~180 ~64 ~104 ~182 ~66 ~104 dirt
fill ~180 ~67 ~104 ~182 ~67 ~104 grass_block
fill ~183 ~60 ~104 ~185 ~62 ~104 stone
fill ~183 ~63 ~104 ~185 ~65 ~104 dirt
fill ~183 ~66 ~104 ~185 ~66 ~104 grass_block
fill ~186 ~60 ~104 ~188 ~63 ~104 stone
fill ~186 ~64 ~104 ~188 ~66 ~104 dirt
fill ~186 ~67 ~104 ~188 ~67 ~104 grass_block
fill ~189 ~60 ~104 ~191 ~62 ~104 stone
fill ~189 ~63 ~104 ~191 ~65 ~104 dirt
fill ~189 ~66 ~104 ~191 ~66 ~104 grass_block
fill ~176 ~60 ~105 ~176 ~65 ~105 stone
fill ~176 ~66 ~105 ~176 ~68 ~105 dirt
fill ~176 ~69 ~105 ~176 ~69 ~105 grass_block
fill ~177 ~60 ~105 ~180 ~64 ~105 stone
fill ~177 ~65 ~105 ~180 ~67 ~105 dirt
fill ~177 ~68 ~105 ~180 ~68 ~105 grass_block
fill ~181 ~60 ~105 ~183 ~63 ~105 stone
fill ~181 ~64 ~105 ~183 ~66 ~105 dirt
fill ~181 ~67 ~105 ~183 ~67 ~105 grass_block
fill ~184 ~60 ~105 ~186 ~62 ~105 stone
fill ~184 ~63 ~105 ~186 ~65 ~105 dirt
fill ~184 ~66 ~105 ~186 ~66 ~105 grass_block
fill ~187 ~60 ~105 ~188 ~63 ~105 stone
fill ~187 ~64 ~105 ~188 ~66 ~105 dirt
fill ~187 ~67 ~105 ~188 ~67 ~105 grass_block
fill ~189 ~60 ~105 ~191 ~62 ~105 stone
fill ~189 ~63 ~105 ~191 ~65 ~105 dirt
fill ~189 ~66 ~105 ~191 ~66 ~105 grass_block
fill ~176 ~60 ~106 ~176 ~65 ~106 stone
fill ~176 ~66 ~106 ~176 ~68 ~106 dirt
fill ~176 ~69 ~106 ~176 ~69 ~106 grass_block
fill ~177 ~60 ~106 ~180 ~64 ~106 stone
fill ~177 ~65 ~106 ~180 ~67 ~106 dirt
fill ~177 ~68 ~106 ~180 ~68 ~106 grass_block
fill ~181 ~60 ~106 ~184 ~63 ~106 stone
fill ~181 ~64 ~106 ~184 ~66 ~106 dirt
fill ~181 ~67 ~106 ~184 ~67 ~106 grass_block
fill ~185 ~60 ~106 ~191 ~62 ~106 stone
fill ~185 ~63 ~106 ~191 ~65 ~106 dirt
fill ~185 ~66 ~106 ~191 ~66 ~106 grass_block
fill ~176 ~60 ~107 ~177 ~65 ~107 stone
fill ~176 ~66 ~107 ~177 ~68 ~107 dirt
fill ~176 ~69 ~107 ~177 ~69 ~107 grass_block
fill ~178 ~60 ~107 ~181 ~64 ~107 stone
fill ~178 ~65 ~107 ~181 ~67 ~107 dirt
fill ~178 ~68 ~107 ~181 ~68 ~107 grass_block
fill ~182 ~60 ~107 ~184 ~63 ~107 stone
fill ~182 ~64 ~107 ~184 ~66 ~107 dirt
fill ~182 ~67 ~107 ~184 ~67 ~107 grass_block
fill ~185 ~60 ~107 ~191 ~62 ~107 stone
fill ~185 ~63 ~107 ~191 ~65 ~107 dirt
fill ~185 ~66 ~107 ~191 ~66 ~107 grass_block
fill ~176 ~60 ~108 ~177 ~65 ~108 stone
fill ~176 ~66 ~108 ~177 ~68 ~108 dirt
fill ~176 ~69 ~108 ~177 ~69 ~108 grass_block
fill ~178 ~60 ~108 ~182 ~64 ~108 stone
fill ~178 ~65 ~108 ~182 ~67 ~108 dirt
fill ~178 ~68 ~108 ~182 ~68 ~108 grass_block
fill ~183 ~60 ~108 ~185 ~63 ~108 stone
fill ~183 ~64 ~108 ~185 ~66 ~108 dirt
fill ~183 ~67 ~108 ~185 ~67 ~108 grass_block
fill ~186 ~60 ~108 ~190 ~62 ~108 stone
fill ~186 ~63 ~108 ~190 ~65 ~108 dirt
fill ~186 ~66 ~108 ~190 ~66 ~108 grass_block
fill ~191 ~60 ~108 ~191 ~63 ~108 stone
fill ~191 ~64 ~108 ~191 ~66 ~108 dirt
fill ~191 ~67 ~108 ~191 ~67 ~108 grass_block
fill ~176 ~60 ~109 ~176 ~64 ~109 stone
fill ~176 ~65 ~109 ~176 ~67 ~109 dirt
fill ~176 ~68 ~109 ~176 ~68 ~109 grass_block
fill ~177 ~60 ~109 ~179 ~65 ~109 stone
fill ~177 ~66 ~109 ~179 ~68 ~109 dirt
fill ~177 ~69 ~109 ~179 ~69 ~109 grass_block
fill ~180 ~60 ~109 ~182 ~64 ~109 stone
fill ~180 ~65 ~109 ~182 ~67 ~109 dirt
fill ~180 ~68 ~109 ~182 ~68 ~109 grass_block
fill ~183 ~60 ~109 ~186 ~63 ~109 stone
fill ~183 ~64 ~109 ~186 ~66 ~109 dirt
fill ~183 ~67 ~109 ~186 ~67 ~109 grass_block
fill ~187 ~60 ~109 ~191 ~62 ~109 stone
fill ~187 ~63 ~109 ~191 ~65 ~109 dirt
fill ~187 ~66 ~109 ~191 ~66 ~109 grass_block
fill ~176 ~60 ~110 ~183 ~64 ~110 stone
fill ~176 ~65 ~110 ~183 ~67 ~110 dirt
fill ~176 ~68 ~110 ~183 ~68 ~110 grass_block
fill ~184 ~60 ~110 ~187 ~63 ~110 stone
fill ~184 ~64 ~110 ~187 ~66 ~110 dirt
fill ~184 ~67 ~110 ~187 ~67 ~110 grass_block
fill ~188 ~60 ~110 ~191 ~62 ~110 stone
fill ~188 ~63 ~110 ~191 ~65 ~110 dirt
fill ~188 ~66 ~110 ~191 ~66 ~110 grass_block
fill ~176 ~60 ~111 ~182 ~64 ~111 stone
fill ~176 ~65 ~111 ~182 ~67 ~111 dirt
fill ~176 ~68 ~111 ~182 ~68 ~111 grass_block
fill ~183 ~60 ~111 ~188 ~63 ~111 stone
fill ~183 ~64 ~111 ~188 ~66 ~111 dirt
fill ~183 ~67 ~111 ~188 ~67 ~111 grass_block
fill ~189 ~60 ~111 ~191 ~62 ~111 stone
fill ~189 ~63 ~111 ~191 ~65 ~111 dirt
fill ~189 ~66 ~111 ~191 ~66 ~111 grass_block