fill ~112 ~60 ~16 ~114 ~66 ~16 stone
fill ~112 ~67 ~16 ~114 ~69 ~16 dirt
fill ~112 ~70 ~16 ~114 ~70 ~16 grass_block
fill ~115 ~60 ~16 ~117 ~65 ~16 stone
fill ~115 ~66 ~16 ~117 ~68 ~16 dirt
fill ~115 ~69 ~16 ~117 ~69 ~16 grass_block
fill ~118 ~60 ~16 ~118 ~64 ~16 stone
fill ~118 ~65 ~16 ~118 ~67 ~16 dirt
fill ~118 ~68 ~16 ~118 ~68 ~16 grass_block
fill ~119 ~60 ~16 ~120 ~65 ~16 stone
fill ~119 ~66 ~16 ~120 ~68 ~16 dirt
fill ~119 ~69 ~16 ~120 ~69 ~16 grass_block
fill ~121 ~60 ~16 ~126 ~64 ~16 stone
fill ~121 ~65 ~16 ~126 ~67 ~16 dirt
fill ~121 ~68 ~16 ~126 ~68 ~16 grass_block
fill ~127 ~60 ~16 ~127 ~65 ~16 stone
fill ~127 ~66 ~16 ~127 ~68 ~16 dirt
fill ~127 ~69 ~16 ~127 ~69 ~16 grass_block
fill ~112 ~60 ~17 ~112 ~67 ~17 stone
fill ~112 ~68 ~17 ~112 ~70 ~17 dirt
fill ~112 ~71 ~17 ~112 ~71 ~17 grass_block
fill ~113 ~60 ~17 ~115 ~66 ~17 stone
fill ~113 ~67 ~17 ~115 ~69 ~17 dirt
fill ~113 ~70 ~17 ~115 ~70 ~17 grass_block
fill ~116 ~60 ~17 ~121 ~65 ~17 stone
fill ~116 ~66 ~17 ~121 ~68 ~17 dirt
fill ~116 ~69 ~17 ~121 ~69 ~17 grass_block
fill ~122 ~60 ~17 ~126 ~64 ~17 stone
fill ~122 ~65 ~17 ~126 ~67 ~17 dirt
fill ~122 ~68 ~17 ~126 ~68 ~17 grass_block
fill ~127 ~60 ~17 ~127 ~65 ~17 stone
fill ~127 ~66 ~17 ~127 ~68 ~17 dirt
fill ~127 ~69 ~17 ~127 ~69 ~17 grass_block
fill ~112 ~60 ~18 ~113 ~67 ~18 stone
fill ~112 ~68 ~18 ~113 ~70 ~18 dirt
fill ~112 ~71 ~18 ~113 ~71 ~18 grass_block
fill ~114 ~60 ~18 ~116 ~66 ~18 stone
fill ~114 ~67 ~18 ~116 ~69 ~18 dirt
fill ~114 ~70 ~18 ~116 ~70 ~18 grass_block
fill ~117 ~60 ~18 ~121 ~65 ~18 stone
fill ~117 ~66 ~18 ~121 ~68 ~18 dirt
fill ~117 ~69 ~18 ~121 ~69 ~18 grass_block
fill ~122 ~60 ~18 ~125 ~64 ~18 stone
fill ~122 ~65 ~18 ~125 ~67 ~18 dirt
fill ~122 ~68 ~18 ~125 ~68 ~18 grass_block
fill ~126 ~60 ~18 ~127 ~65 ~18 stone
fill ~126 ~66 ~18 ~127 ~68 ~18 dirt
fill ~126 ~69 ~18 ~127 ~69 ~18 grass_block
fill ~112 ~60 ~19 ~114 ~67 ~19 stone
fill ~112 ~68 ~19 ~114 ~70 ~19 dirt
fill ~112 ~71 ~19 ~114 ~71 ~19 grass_block
fill ~115 ~60 ~19 ~117 ~66 ~19 stone
fill ~115 ~67 ~19 ~117 ~69 ~19 dirt
fill ~115 ~70 ~19 ~117 ~70 ~19 grass_block
fill ~118 ~60 ~19 ~121 ~65 ~19 stone
fill ~118 ~66 ~19 ~121 ~68 ~19 dirt
fill ~118 ~69 ~19 ~121 ~69 ~19 grass_block
fill ~122 ~60 ~19 ~124 ~64 ~19 stone
fill ~122 ~65 ~19 ~124 ~67 ~19 dirt
fill ~122 ~68 ~19 ~124 ~68 ~19 grass_block
fill ~125 ~60 ~19 ~127 ~65 ~19 stone
fill ~125 ~66 ~19 ~127 ~68 ~19 dirt
fill ~125 ~69 ~19 ~127 ~69 ~19 grass_block
fill ~112 ~60 ~20 ~112 ~68 ~20 stone
fill ~112 ~69 ~20 ~112 ~71 ~20 dirt
fill ~112 ~72 ~20 ~112 ~72 ~20 grass_block
fill ~113 ~60 ~20 ~115 ~67 ~20 stone
fill ~113 ~68 ~20 ~115 ~70 ~20 dirt
fill ~113 ~71 ~20 ~115 ~71 ~20 grass_block
fill ~116 ~60 ~20 ~117 ~66 ~20 stone
fill ~116 ~67 ~20 ~117 ~69 ~20 dirt
fill ~116 ~70 ~20 ~117 ~70 ~20 grass_block
fill ~118 ~60 ~20 ~127 ~65 ~20 stone
fill ~118 ~66 ~20 ~127 ~68 ~20 dirt
fill ~118 ~69 ~20 ~127 ~69 ~20 grass_block
fill ~112 ~60 ~21 ~113 ~68 ~21 stone
fill ~112 ~69 ~21 ~113 ~71 ~21 dirt
fill ~112 ~72 ~21 ~113 ~72 ~21 grass_block
fill ~114 ~60 ~21 ~115 ~67 ~21 stone
fill ~114 ~68 ~21 ~115 ~70 ~21 dirt
fill ~114 ~71 ~21 ~115 ~71 ~21 grass_block
fill ~116 ~60 ~21 ~117 ~66 ~21 stone
fill ~116 ~67 ~21 ~117 ~69 ~21 dirt
fill ~116 ~70 ~21 ~117 ~70 ~21 grass_block
fill ~118 ~60 ~21 ~122 ~65 ~21 stone
fill ~118 ~66 ~21 ~122 ~68 ~21 dirt
fill ~118 ~69 ~21 ~122 ~69 ~21 grass_block
fill ~123 ~60 ~21 ~126 ~66 ~21 stone
fill ~123 ~67 ~21 ~126 ~69 ~21 dirt
fill ~123 ~70 ~21 ~126 ~70 ~21 grass_block
fill ~127 ~60 ~21 ~127 ~65 ~21 stone
fill ~127 ~66 ~21 ~127 ~68 ~21 dirt
fill ~127 ~69 ~21 ~127 ~69 ~21 grass_block
fill ~112 ~60 ~22 ~113 ~68 ~22 stone
fill ~112 ~69 ~22 ~113 ~71 ~22 dirt
fill ~112 ~72 ~22 ~113 ~72 ~22 grass_block
fill ~114 ~60 ~22 ~116 ~67 ~22 stone
fill ~114 ~68 ~22 ~116 ~70 ~22 dirt
fill ~114 ~71 ~22 ~116 ~71 ~22 grass_block
fill ~117 ~60 ~22 ~118 ~66 ~22 stone
fill ~117 ~67 ~22 ~118 ~69 ~22 dirt
fill ~117 ~70 ~22 ~118 ~70 ~22 grass_block
fill ~119 ~60 ~22 ~119 ~65 ~22 stone
fill ~119 ~66 ~22 ~119 ~68 ~22 dirt
fill ~119 ~69 ~22 ~119 ~69 ~22 grass_block
fill ~120 ~60 ~22 ~127 ~66 ~22 stone
fill ~120 ~67 ~22 ~127 ~69 ~22 dirt
fill ~120 ~70 ~22 ~127 ~70 ~22 grass_block
fill ~112 ~60 ~23 ~114 ~68 ~23 stone
fill ~112 ~69 ~23 ~114 ~71 ~23 dirt
fill ~112 ~72 ~23 ~114 ~72 ~23 grass_block
fill ~115 ~60 ~23 ~116 ~67 ~23 stone
fill ~115 ~68 ~23 ~116 ~70 ~23 dirt
fill ~115 ~71 ~23 ~116 ~71 ~23 grass_block
fill ~117 ~60 ~23 ~120 ~66 ~23 stone
fill ~117 ~67 ~23 ~120 ~69 ~23 dirt
fill ~117 ~70 ~23 ~120 ~70 ~23 grass_block
fill ~121 ~60 ~23 ~122 ~67 ~23 stone
fill ~121 ~68 ~23 ~122 ~70 ~23 dirt
fill ~121 ~71 ~23 ~122 ~71 ~23 grass_block
fill ~123 ~60 ~23 ~126 ~66 ~23 stone
fill ~123 ~67 ~23 ~126 ~69 ~23 dirt
fill ~123 ~70 ~23 ~126 ~70 ~23 grass_block
fill ~127 ~60 ~23 ~127 ~65 ~23 stone
fill ~127 ~66 ~23 ~127 ~68 ~23 dirt
fill ~127 ~69 ~23 ~127 ~69 ~23 grass_block
fill ~112 ~60 ~24 ~115 ~68 ~24 stone
fill ~112 ~69 ~24 ~115 ~71 ~24 dirt
fill ~112 ~72 ~24 ~115 ~72 ~24 grass_block
fill ~116 ~60 ~24 ~123 ~67 ~24 stone
fill ~116 ~68 ~24 ~123 ~70 ~24 dirt
fill ~116 ~71 ~24 ~123 ~71 ~24 grass_block
fill ~124 ~60 ~24 ~126 ~66 ~24 stone
fill ~124 ~67 ~24 ~126 ~69 ~24 dirt
fill ~124 ~70 ~24 ~126 ~70 ~24 grass_block
fill ~127 ~60 ~24 ~127 ~65 ~24 stone
fill ~127 ~66 ~24 ~127 ~68 ~24 dirt
fill ~127 ~69 ~24 ~127 ~69 ~24 grass_block
fill ~112 ~60 ~25 ~117 ~68 ~25 stone
fill ~112 ~69 ~25 ~117 ~71 ~25 dirt
fill ~112 ~72 ~25 ~117 ~72 ~25 grass_block
fill ~118 ~60 ~25 ~120 ~67 ~25 stone
fill ~118 ~68 ~25 ~120 ~70 ~25 dirt
fill ~118 ~71 ~25 ~120 ~71 ~25 grass_block
fill ~121 ~60 ~25 ~121 ~68 ~25 stone
fill ~121 ~69 ~25 ~121 ~71 ~25 dirt
fill ~121 ~72 ~25 ~121 ~72 ~25 grass_block
fill ~122 ~60 ~25 ~124 ~67 ~25 stone
fill ~122 ~68 ~25 ~124 ~70 ~25 dirt
fill ~122 ~71 ~25 ~124 ~71 ~25 grass_block
fill ~125 ~60 ~25 ~126 ~66 ~25 stone
fill ~125 ~67 ~25 ~126 ~69 ~25 dirt
fill ~125 ~70 ~25 ~126 ~70 ~25 grass_block
fill ~127 ~60 ~25 ~127 ~65 ~25 stone
fill ~127 ~66 ~25 ~127 ~68 ~25 dirt
fill ~127 ~69 ~25 ~127 ~69 ~25 grass_block
fill ~112 ~60 ~26 ~122 ~68 ~26 stone
fill ~112 ~69 ~26 ~122 ~71 ~26 dirt
fill ~112 ~72 ~26 ~122 ~72 ~26 grass_block
fill ~123 ~60 ~26 ~124 ~67 ~26 stone
fill ~123 ~68 ~26 ~124 ~70 ~26 dirt
fill ~123 ~71 ~26 ~124 ~71 ~26 grass_block
fill ~125 ~60 ~26 ~125 ~66 ~26 stone
fill ~125 ~67 ~26 ~125 ~69 ~26 dirt
fill ~125 ~70 ~26 ~125 ~70 ~26 grass_block
fill ~126 ~60 ~26 ~127 ~65 ~26 stone
fill ~126 ~66 ~26 ~127 ~68 ~26 dirt
fill ~126 ~69 ~26 ~127 ~69 ~26 grass_block
fill ~112 ~60 ~27 ~122 ~68 ~27 stone
fill ~112 ~69 ~27 ~122 ~71 ~27 dirt
fill ~112 ~72 ~27 ~122 ~72 ~27 grass_block
fill ~123 ~60 ~27 ~124 ~67 ~27 stone
fill ~123 ~68 ~27 ~124 ~70 ~27 dirt
fill ~123 ~71 ~27 ~124 ~71 ~27 grass_block
fill ~125 ~60 ~27 ~127 ~66 ~27 stone
fill ~125 ~67 ~27 ~127 ~69 ~27 dirt
fill ~125 ~70 ~27 ~127 ~70 ~27 grass_block
fill ~112 ~60 ~28 ~123 ~68 ~28 stone
fill ~112 ~69 ~28 ~123 ~71 ~28 dirt
fill ~112 ~72 ~28 ~123 ~72 ~28 grass_block
fill ~124 ~60 ~28 ~126 ~67 ~28 stone
fill ~124 ~68 ~28 ~126 ~70 ~28 dirt
fill ~124 ~71 ~28 ~126 ~71 ~28 grass_block
fill ~127 ~60 ~28 ~127 ~66 ~28 stone
fill ~127 ~67 ~28 ~127 ~69 ~28 dirt
fill ~127 ~70 ~28 ~127 ~70 ~28 grass_block
fill ~112 ~60 ~29 ~113 ~67 ~29 stone
fill ~112 ~68 ~29 ~113 ~70 ~29 dirt
fill ~112 ~71 ~29 ~113 ~71 ~29 grass_block
fill ~114 ~60 ~29 ~125 ~68 ~29 stone
fill ~114 ~69 ~29 ~125 ~71 ~29 dirt
fill ~114 ~72 ~29 ~125 ~72 ~29 grass_block
fill ~126 ~60 ~29 ~127 ~67 ~29 stone
fill ~126 ~68 ~29 ~127 ~70 ~29 dirt
fill ~126 ~71 ~29 ~127 ~71 ~29 grass_block
fill ~112 ~60 ~30 ~113 ~67 ~30 stone
fill ~112 ~68 ~30 ~113 ~70 ~30 dirt
fill ~112 ~71 ~30 ~113 ~71 ~30 grass_block
fill ~114 ~60 ~30 ~126 ~68 ~30 stone
fill ~114 ~69 ~30 ~126 ~71 ~30 dirt
fill ~114 ~72 ~30 ~126 ~72 ~30 grass_block
fill ~127 ~60 ~30 ~127 ~67 ~30 stone
fill ~127 ~68 ~30 ~127 ~70 ~30 dirt
fill ~127 ~71 ~30 ~127 ~71 ~30 grass_block
fill ~112 ~60 ~31 ~113 ~67 ~31 stone
fill ~112 ~68 ~31 ~113 ~70 ~31 dirt
fill ~112 ~71 ~31 ~113 ~71 ~31 grass_block
fill ~114 ~60 ~31 ~127 ~68 ~31 stone
fill ~114 ~69 ~31 ~127 ~71 ~31 dirt
fill ~114 ~72 ~31 ~127 ~72 ~31 grass_block