fill ~208 ~60 ~32 ~223 ~61 ~32 stone
fill ~208 ~62 ~32 ~223 ~64 ~32 dirt
fill ~208 ~65 ~32 ~223 ~65 ~32 grass_block
fill ~208 ~60 ~33 ~223 ~61 ~33 stone
fill ~208 ~62 ~33 ~223 ~64 ~33 dirt
fill ~208 ~65 ~33 ~223 ~65 ~33 grass_block
fill ~208 ~60 ~34 ~223 ~61 ~34 stone
fill ~208 ~62 ~34 ~223 ~64 ~34 dirt
fill ~208 ~65 ~34 ~223 ~65 ~34 grass_block
fill ~208 ~60 ~35 ~223 ~61 ~35 stone
fill ~208 ~62 ~35 ~223 ~64 ~35 dirt
fill ~208 ~65 ~35 ~223 ~65 ~35 grass_block
fill ~208 ~60 ~36 ~208 ~62 ~36 stone
fill ~208 ~63 ~36 ~208 ~65 ~36 dirt
fill ~208 ~66 ~36 ~208 ~66 ~36 grass_block
fill ~209 ~60 ~36 ~223 ~61 ~36 stone
fill ~209 ~62 ~36 ~223 ~64 ~36 dirt
fill ~209 ~65 ~36 ~223 ~65 ~36 grass_block
fill ~208 ~60 ~37 ~209 ~62 ~37 stone
fill ~208 ~63 ~37 ~209 ~65 ~37 dirt
fill ~208 ~66 ~37 ~209 ~66 ~37 grass_block
fill ~210 ~60 ~37 ~223 ~61 ~37 stone
fill ~210 ~62 ~37 ~223 ~64 ~37 dirt
fill ~210 ~65 ~37 ~223 ~65 ~37 grass_block
fill ~208 ~60 ~38 ~210 ~62 ~38 stone
fill ~208 ~63 ~38 ~210 ~65 ~38 dirt
fill ~208 ~66 ~38 ~210 ~66 ~38 grass_block
fill ~211 ~60 ~38 ~223 ~61 ~38 stone
fill ~211 ~62 ~38 ~223 ~64 ~38 dirt
fill ~211 ~65 ~38 ~223 ~65 ~38 grass_block
fill ~208 ~60 ~39 ~209 ~63 ~39 stone
fill ~208 ~64 ~39 ~209 ~66 ~39 dirt
fill ~208 ~67 ~39 ~209 ~67 ~39 grass_block
fill ~210 ~60 ~39 ~212 ~62 ~39 stone
fill ~210 ~63 ~39 ~212 ~65 ~39 dirt
fill ~210 ~66 ~39 ~212 ~66 ~39 grass_block
fill ~213 ~60 ~39 ~223 ~61 ~39 stone
fill ~213 ~62 ~39 ~223 ~64 ~39 dirt
fill ~213 ~65 ~39 ~223 ~65 ~39 grass_block
fill ~208 ~60 ~40 ~210 ~63 ~40 stone
fill ~208 ~64 ~40 ~210 ~66 ~40 dirt
fill ~208 ~67 ~40 ~210 ~67 ~40 grass_block
fill ~211 ~60 ~40 ~217 ~62 ~40 stone
fill ~211 ~63 ~40 ~217 ~65 ~40 dirt
fill ~211 ~66 ~40 ~217 ~66 ~40 grass_block
fill ~218 ~60 ~40 ~223 ~61 ~40 stone
fill ~218 ~62 ~40 ~223 ~64 ~40 dirt
fill ~218 ~65 ~40 ~223 ~65 ~40 grass_block
fill ~208 ~60 ~41 ~208 ~64 ~41 stone
fill ~208 ~65 ~41 ~208 ~67 ~41 dirt
fill ~208 ~68 ~41 ~208 ~68 ~41 grass_block
fill ~209 ~60 ~41 ~212 ~63 ~41 stone
fill ~209 ~64 ~41 ~212 ~66 ~41 dirt
fill ~209 ~67 ~41 ~212 ~67 ~41 grass_block
fill ~213 ~60 ~41 ~219 ~62 ~41 stone
fill ~213 ~63 ~41 ~219 ~65 ~41 dirt
fill ~213 ~66 ~41 ~219 ~66 ~41 grass_block
fill ~220 ~60 ~41 ~223 ~61 ~41 stone
fill ~220 ~62 ~41 ~223 ~64 ~41 dirt
fill ~220 ~65 ~41 ~223 ~65 ~41 grass_block
fill ~208 ~60 ~42 ~209 ~64 ~42 stone
fill ~208 ~65 ~42 ~209 ~67 ~42 dirt
fill ~208 ~68 ~42 ~209 ~68 ~42 grass_block
fill ~210 ~60 ~42 ~215 ~63 ~42 stone
fill ~210 ~64 ~42 ~215 ~66 ~42 dirt
fill ~210 ~67 ~42 ~215 ~67 ~42 grass_block
fill ~216 ~60 ~42 ~223 ~62 ~42 stone
fill ~216 ~63 ~42 ~223 ~65 ~42 dirt
fill ~216 ~66 ~42 ~223 ~66 ~42 grass_block
fill ~208 ~60 ~43 ~210 ~64 ~43 stone
fill ~208 ~65 ~43 ~210 ~67 ~43 dirt
fill ~208 ~68 ~43 ~210 ~68 ~43 grass_block
fill ~211 ~60 ~43 ~218 ~63 ~43 stone
fill ~211 ~64 ~43 ~218 ~66 ~43 dirt
fill ~211 ~67 ~43 ~218 ~67 ~43 grass_block
fill ~219 ~60 ~43 ~223 ~62 ~43 stone
fill ~219 ~63 ~43 ~223 ~65 ~43 dirt
fill ~219 ~66 ~43 ~223 ~66 ~43 grass_block
fill ~208 ~60 ~44 ~211 ~64 ~44 stone
fill ~208 ~65 ~44 ~211 ~67 ~44 dirt
fill ~208 ~68 ~44 ~211 ~68 ~44 grass_block
fill ~212 ~60 ~44 ~218 ~63 ~44 stone
fill ~212 ~64 ~44 ~218 ~66 ~44 dirt
fill ~212 ~67 ~44 ~218 ~67 ~44 grass_block
fill ~219 ~60 ~44 ~220 ~62 ~44 stone
fill ~219 ~63 ~44 ~220 ~65 ~44 dirt
fill ~219 ~66 ~44 ~220 ~66 ~44 grass_block
fill ~221 ~60 ~44 ~221 ~63 ~44 stone
fill ~221 ~64 ~44 ~221 ~66 ~44 dirt
fill ~221 ~67 ~44 ~221 ~67 ~44 grass_block
fill ~222 ~60 ~44 ~223 ~62 ~44 stone
fill ~222 ~63 ~44 ~223 ~65 ~44 dirt
fill ~222 ~66 ~44 ~223 ~66 ~44 grass_block
fill ~208 ~60 ~45 ~211 ~64 ~45 stone
fill ~208 ~65 ~45 ~211 ~67 ~45 dirt
fill ~208 ~68 ~45 ~211 ~68 ~45 grass_block
fill ~212 ~60 ~45 ~223 ~63 ~45 stone
fill ~212 ~64 ~45 ~223 ~66 ~45 dirt
fill ~212 ~67 ~45 ~223 ~67 ~45 grass_block
fill ~208 ~60 ~46 ~212 ~64 ~46 stone
fill ~208 ~65 ~46 ~212 ~67 ~46 dirt
fill ~208 ~68 ~46 ~212 ~68 ~46 grass_block
fill ~213 ~60 ~46 ~223 ~63 ~46 stone
fill ~213 ~64 ~46 ~223 ~66 ~46 dirt
fill ~213 ~67 ~46 ~223 ~67 ~46 grass_block
fill ~208 ~60 ~47 ~213 ~64 ~47 stone
fill ~208 ~65 ~47 ~213 ~67 ~47 dirt
fill ~208 ~68 ~47 ~213 ~68 ~47 grass_block
fill ~214 ~60 ~47 ~223 ~63 ~47 stone
fill ~214 ~64 ~47 ~223 ~66 ~47 dirt
fill ~214 ~67 ~47 ~223 ~67 ~47 grass_block