fill ~160 ~60 ~0 ~174 ~61 ~0 stone
fill ~160 ~62 ~0 ~174 ~64 ~0 dirt
fill ~160 ~65 ~0 ~174 ~65 ~0 grass_block
fill ~175 ~60 ~0 ~175 ~62 ~0 stone
fill ~175 ~63 ~0 ~175 ~65 ~0 dirt
fill ~175 ~66 ~0 ~175 ~66 ~0 grass_block
fill ~160 ~60 ~1 ~175 ~61 ~1 stone
fill ~160 ~62 ~1 ~175 ~64 ~1 dirt
fill ~160 ~65 ~1 ~175 ~65 ~1 grass_block
fill ~160 ~60 ~2 ~175 ~61 ~2 stone
fill ~160 ~62 ~2 ~175 ~64 ~2 dirt
fill ~160 ~65 ~2 ~175 ~65 ~2 grass_block
fill ~160 ~60 ~3 ~175 ~61 ~3 stone
fill ~160 ~62 ~3 ~175 ~64 ~3 dirt
fill ~160 ~65 ~3 ~175 ~65 ~3 grass_block
fill ~160 ~60 ~4 ~175 ~61 ~4 stone
fill ~160 ~62 ~4 ~175 ~64 ~4 dirt
fill ~160 ~65 ~4 ~175 ~65 ~4 grass_block
fill ~160 ~60 ~5 ~175 ~61 ~5 stone
fill ~160 ~62 ~5 ~175 ~64 ~5 dirt
fill ~160 ~65 ~5 ~175 ~65 ~5 grass_block
fill ~160 ~60 ~6 ~175 ~61 ~6 stone
fill ~160 ~62 ~6 ~175 ~64 ~6 dirt
fill ~160 ~65 ~6 ~175 ~65 ~6 grass_block
fill ~160 ~60 ~7 ~162 ~62 ~7 stone
fill ~160 ~63 ~7 ~162 ~65 ~7 dirt
fill ~160 ~66 ~7 ~162 ~66 ~7 grass_block
fill ~163 ~60 ~7 ~175 ~61 ~7 stone
fill ~163 ~62 ~7 ~175 ~64 ~7 dirt
fill ~163 ~65 ~7 ~175 ~65 ~7 grass_block
fill ~160 ~60 ~8 ~160 ~63 ~8 stone
fill ~160 ~64 ~8 ~160 ~66 ~8 dirt
fill ~160 ~67 ~8 ~160 ~67 ~8 grass_block
fill ~161 ~60 ~8 ~166 ~62 ~8 stone
fill ~161 ~63 ~8 ~166 ~65 ~8 dirt
fill ~161 ~66 ~8 ~166 ~66 ~8 grass_block
fill ~167 ~60 ~8 ~175 ~61 ~8 stone
fill ~167 ~62 ~8 ~175 ~64 ~8 dirt
fill ~167 ~65 ~8 ~175 ~65 ~8 grass_block
fill ~160 ~60 ~9 ~160 ~63 ~9 stone
fill ~160 ~64 ~9 ~160 ~66 ~9 dirt
fill ~160 ~67 ~9 ~160 ~67 ~9 grass_block
fill ~161 ~60 ~9 ~169 ~62 ~9 stone
fill ~161 ~63 ~9 ~169 ~65 ~9 dirt
fill ~161 ~66 ~9 ~169 ~66 ~9 grass_block
fill ~170 ~60 ~9 ~175 ~61 ~9 stone
fill ~170 ~62 ~9 ~175 ~64 ~9 dirt
fill ~170 ~65 ~9 ~175 ~65 ~9 grass_block
fill ~160 ~60 ~10 ~171 ~62 ~10 stone
fill ~160 ~63 ~10 ~171 ~65 ~10 dirt
fill ~160 ~66 ~10 ~171 ~66 ~10 grass_block
fill ~172 ~60 ~10 ~175 ~61 ~10 stone
fill ~172 ~62 ~10 ~175 ~64 ~10 dirt
fill ~172 ~65 ~10 ~175 ~65 ~10 grass_block
fill ~160 ~60 ~11 ~165 ~63 ~11 stone
fill ~160 ~64 ~11 ~165 ~66 ~11 dirt
fill ~160 ~67 ~11 ~165 ~67 ~11 grass_block
fill ~166 ~60 ~11 ~173 ~62 ~11 stone
fill ~166 ~63 ~11 ~173 ~65 ~11 dirt
fill ~166 ~66 ~11 ~173 ~66 ~11 grass_block
fill ~174 ~60 ~11 ~175 ~61 ~11 stone
fill ~174 ~62 ~11 ~175 ~64 ~11 dirt
fill ~174 ~65 ~11 ~175 ~65 ~11 grass_block
fill ~160 ~60 ~12 ~166 ~63 ~12 stone
fill ~160 ~64 ~12 ~166 ~66 ~12 dirt
fill ~160 ~67 ~12 ~166 ~67 ~12 grass_block
fill ~167 ~60 ~12 ~174 ~62 ~12 stone
fill ~167 ~63 ~12 ~174 ~65 ~12 dirt
fill ~167 ~66 ~12 ~174 ~66 ~12 grass_block
fill ~175 ~60 ~12 ~175 ~61 ~12 stone
fill ~175 ~62 ~12 ~175 ~64 ~12 dirt
fill ~175 ~65 ~12 ~175 ~65 ~12 grass_block
fill ~160 ~60 ~13 ~167 ~63 ~13 stone
fill ~160 ~64 ~13 ~167 ~66 ~13 dirt
fill ~160 ~67 ~13 ~167 ~67 ~13 grass_block
fill ~168 ~60 ~13 ~175 ~62 ~13 stone
fill ~168 ~63 ~13 ~175 ~65 ~13 dirt
fill ~168 ~66 ~13 ~175 ~66 ~13 grass_block
fill ~160 ~60 ~14 ~167 ~63 ~14 stone
fill ~160 ~64 ~14 ~167 ~66 ~14 dirt
fill ~160 ~67 ~14 ~167 ~67 ~14 grass_block
fill ~168 ~60 ~14 ~175 ~62 ~14 stone
fill ~168 ~63 ~14 ~175 ~65 ~14 dirt
fill ~168 ~66 ~14 ~175 ~66 ~14 grass_block
fill ~160 ~60 ~15 ~166 ~63 ~15 stone
fill ~160 ~64 ~15 ~166 ~66 ~15 dirt
fill ~160 ~67 ~15 ~166 ~67 ~15 grass_block
fill ~167 ~60 ~15 ~175 ~62 ~15 stone
fill ~167 ~63 ~15 ~175 ~65 ~15 dirt
fill ~167 ~66 ~15 ~175 ~66 ~15 grass_block