fill ~272 ~60 ~112 ~283 ~64 ~112 stone
fill ~272 ~65 ~112 ~283 ~67 ~112 dirt
fill ~272 ~68 ~112 ~283 ~68 ~112 grass_block
fill ~284 ~60 ~112 ~287 ~65 ~112 stone
fill ~284 ~66 ~112 ~287 ~68 ~112 dirt
fill ~284 ~69 ~112 ~287 ~69 ~112 grass_block
fill ~272 ~60 ~113 ~277 ~64 ~113 stone
fill ~272 ~65 ~113 ~277 ~67 ~113 dirt
fill ~272 ~68 ~113 ~277 ~68 ~113 grass_block
fill ~278 ~60 ~113 ~279 ~63 ~113 stone
fill ~278 ~64 ~113 ~279 ~66 ~113 dirt
fill ~278 ~67 ~113 ~279 ~67 ~113 grass_block
fill ~280 ~60 ~113 ~282 ~64 ~113 stone
fill ~280 ~65 ~113 ~282 ~67 ~113 dirt
fill ~280 ~68 ~113 ~282 ~68 ~113 grass_block
fill ~283 ~60 ~113 ~287 ~65 ~113 stone
fill ~283 ~66 ~113 ~287 ~68 ~113 dirt
fill ~283 ~69 ~113 ~287 ~69 ~113 grass_block
fill ~272 ~60 ~114 ~276 ~64 ~114 stone
fill ~272 ~65 ~114 ~276 ~67 ~114 dirt
fill ~272 ~68 ~114 ~276 ~68 ~114 grass_block
fill ~277 ~60 ~114 ~279 ~63 ~114 stone
fill ~277 ~64 ~114 ~279 ~66 ~114 dirt
fill ~277 ~67 ~114 ~279 ~67 ~114 grass_block
fill ~280 ~60 ~114 ~282 ~64 ~114 stone
fill ~280 ~65 ~114 ~282 ~67 ~114 dirt
fill ~280 ~68 ~114 ~282 ~68 ~114 grass_block
fill ~283 ~60 ~114 ~287 ~65 ~114 stone
fill ~283 ~66 ~114 ~287 ~68 ~114 dirt
fill ~283 ~69 ~114 ~287 ~69 ~114 grass_block
fill ~272 ~60 ~115 ~275 ~64 ~115 stone
fill ~272 ~65 ~115 ~275 ~67 ~115 dirt
fill ~272 ~68 ~115 ~275 ~68 ~115 grass_block
fill ~276 ~60 ~115 ~280 ~63 ~115 stone
fill ~276 ~64 ~115 ~280 ~66 ~115 dirt
fill ~276 ~67 ~115 ~280 ~67 ~115 grass_block
fill ~281 ~60 ~115 ~282 ~64 ~115 stone
fill ~281 ~65 ~115 ~282 ~67 ~115 dirt
fill ~281 ~68 ~115 ~282 ~68 ~115 grass_block
fill ~283 ~60 ~115 ~287 ~65 ~115 stone
fill ~283 ~66 ~115 ~287 ~68 ~115 dirt
fill ~283 ~69 ~115 ~287 ~69 ~115 grass_block
fill ~272 ~60 ~116 ~273 ~63 ~116 stone
fill ~272 ~64 ~116 ~273 ~66 ~116 dirt
fill ~272 ~67 ~116 ~273 ~67 ~116 grass_block
fill ~274 ~60 ~116 ~274 ~64 ~116 stone
fill ~274 ~65 ~116 ~274 ~67 ~116 dirt
fill ~274 ~68 ~116 ~274 ~68 ~116 grass_block
fill ~275 ~60 ~116 ~280 ~63 ~116 stone
fill ~275 ~64 ~116 ~280 ~66 ~116 dirt
fill ~275 ~67 ~116 ~280 ~67 ~116 grass_block
fill ~281 ~60 ~116 ~283 ~64 ~116 stone
fill ~281 ~65 ~116 ~283 ~67 ~116 dirt
fill ~281 ~68 ~116 ~283 ~68 ~116 grass_block
fill ~284 ~60 ~116 ~287 ~65 ~116 stone
fill ~284 ~66 ~116 ~287 ~68 ~116 dirt
fill ~284 ~69 ~116 ~287 ~69 ~116 grass_block
fill ~272 ~60 ~117 ~281 ~63 ~117 stone
fill ~272 ~64 ~117 ~281 ~66 ~117 dirt
fill ~272 ~67 ~117 ~281 ~67 ~117 grass_block
fill ~282 ~60 ~117 ~283 ~64 ~117 stone
fill ~282 ~65 ~117 ~283 ~67 ~117 dirt
fill ~282 ~68 ~117 ~283 ~68 ~117 grass_block
fill ~284 ~60 ~117 ~287 ~65 ~117 stone
fill ~284 ~66 ~117 ~287 ~68 ~117 dirt
fill ~284 ~69 ~117 ~287 ~69 ~117 grass_block
fill ~272 ~60 ~118 ~282 ~63 ~118 stone
fill ~272 ~64 ~118 ~282 ~66 ~118 dirt
fill ~272 ~67 ~118 ~282 ~67 ~118 grass_block
fill ~283 ~60 ~118 ~284 ~64 ~118 stone
fill ~283 ~65 ~118 ~284 ~67 ~118 dirt
fill ~283 ~68 ~118 ~284 ~68 ~118 grass_block
fill ~285 ~60 ~118 ~287 ~65 ~118 stone
fill ~285 ~66 ~118 ~287 ~68 ~118 dirt
fill ~285 ~69 ~118 ~287 ~69 ~118 grass_block
fill ~272 ~60 ~119 ~275 ~63 ~119 stone
fill ~272 ~64 ~119 ~275 ~66 ~119 dirt
fill ~272 ~67 ~119 ~275 ~67 ~119 grass_block
fill ~276 ~60 ~119 ~276 ~62 ~119 stone
fill ~276 ~63 ~119 ~276 ~65 ~119 dirt
fill ~276 ~66 ~119 ~276 ~66 ~119 grass_block
fill ~277 ~60 ~119 ~279 ~63 ~119 stone
fill ~277 ~64 ~119 ~279 ~66 ~119 dirt
fill ~277 ~67 ~119 ~279 ~67 ~119 grass_block
fill ~280 ~60 ~119 ~284 ~64 ~119 stone
fill ~280 ~65 ~119 ~284 ~67 ~119 dirt
fill ~280 ~68 ~119 ~284 ~68 ~119 grass_block
fill ~285 ~60 ~119 ~287 ~65 ~119 stone
fill ~285 ~66 ~119 ~287 ~68 ~119 dirt
fill ~285 ~69 ~119 ~287 ~69 ~119 grass_block
fill ~272 ~60 ~120 ~273 ~63 ~120 stone
fill ~272 ~64 ~120 ~273 ~66 ~120 dirt
fill ~272 ~67 ~120 ~273 ~67 ~120 grass_block
fill ~274 ~60 ~120 ~275 ~62 ~120 stone
fill ~274 ~63 ~120 ~275 ~65 ~120 dirt
fill ~274 ~66 ~120 ~275 ~66 ~120 grass_block
fill ~276 ~60 ~120 ~278 ~63 ~120 stone
fill ~276 ~64 ~120 ~278 ~66 ~120 dirt
fill ~276 ~67 ~120 ~278 ~67 ~120 grass_block
fill ~279 ~60 ~120 ~285 ~64 ~120 stone
fill ~279 ~65 ~120 ~285 ~67 ~120 dirt
fill ~279 ~68 ~120 ~285 ~68 ~120 grass_block
fill ~286 ~60 ~120 ~287 ~65 ~120 stone
fill ~286 ~66 ~120 ~287 ~68 ~120 dirt
fill ~286 ~69 ~120 ~287 ~69 ~120 grass_block
fill ~272 ~60 ~121 ~275 ~62 ~121 stone
fill ~272 ~63 ~121 ~275 ~65 ~121 dirt
fill ~272 ~66 ~121 ~275 ~66 ~121 grass_block
fill ~276 ~60 ~121 ~278 ~63 ~121 stone
fill ~276 ~64 ~121 ~278 ~66 ~121 dirt
fill ~276 ~67 ~121 ~278 ~67 ~121 grass_block
fill ~279 ~60 ~121 ~280 ~64 ~121 stone
fill ~279 ~65 ~121 ~280 ~67 ~121 dirt
fill ~279 ~68 ~121 ~280 ~68 ~121 grass_block
fill ~281 ~60 ~121 ~287 ~65 ~121 stone
fill ~281 ~66 ~121 ~287 ~68 ~121 dirt
fill ~281 ~69 ~121 ~287 ~69 ~121 grass_block
fill ~272 ~60 ~122 ~275 ~62 ~122 stone
fill ~272 ~63 ~122 ~275 ~65 ~122 dirt
fill ~272 ~66 ~122 ~275 ~66 ~122 grass_block
fill ~276 ~60 ~122 ~278 ~63 ~122 stone
fill ~276 ~64 ~122 ~278 ~66 ~122 dirt
fill ~276 ~67 ~122 ~278 ~67 ~122 grass_block
fill ~279 ~60 ~122 ~280 ~64 ~122 stone
fill ~279 ~65 ~122 ~280 ~67 ~122 dirt
fill ~279 ~68 ~122 ~280 ~68 ~122 grass_block
fill ~281 ~60 ~122 ~287 ~65 ~122 stone
fill ~281 ~66 ~122 ~287 ~68 ~122 dirt
fill ~281 ~69 ~122 ~287 ~69 ~122 grass_block
fill ~272 ~60 ~123 ~275 ~62 ~123 stone
fill ~272 ~63 ~123 ~275 ~65 ~123 dirt
fill ~272 ~66 ~123 ~275 ~66 ~123 grass_block
fill ~276 ~60 ~123 ~278 ~63 ~123 stone
fill ~276 ~64 ~123 ~278 ~66 ~123 dirt
fill ~276 ~67 ~123 ~278 ~67 ~123 grass_block
fill ~279 ~60 ~123 ~280 ~64 ~123 stone
fill ~279 ~65 ~123 ~280 ~67 ~123 dirt
fill ~279 ~68 ~123 ~280 ~68 ~123 grass_block
fill ~281 ~60 ~123 ~287 ~65 ~123 stone
fill ~281 ~66 ~123 ~287 ~68 ~123 dirt
fill ~281 ~69 ~123 ~287 ~69 ~123 grass_block
fill ~272 ~60 ~124 ~275 ~62 ~124 stone
fill ~272 ~63 ~124 ~275 ~65 ~124 dirt
fill ~272 ~66 ~124 ~275 ~66 ~124 grass_block
fill ~276 ~60 ~124 ~277 ~63 ~124 stone
fill ~276 ~64 ~124 ~277 ~66 ~124 dirt
fill ~276 ~67 ~124 ~277 ~67 ~124 grass_block
fill ~278 ~60 ~124 ~280 ~64 ~124 stone
fill ~278 ~65 ~124 ~280 ~67 ~124 dirt
fill ~278 ~68 ~124 ~280 ~68 ~124 grass_block
fill ~281 ~60 ~124 ~284 ~65 ~124 stone
fill ~281 ~66 ~124 ~284 ~68 ~124 dirt
fill ~281 ~69 ~124 ~284 ~69 ~124 grass_block
fill ~285 ~60 ~124 ~287 ~66 ~124 stone
fill ~285 ~67 ~124 ~287 ~69 ~124 dirt
fill ~285 ~70 ~124 ~287 ~70 ~124 grass_block
fill ~272 ~60 ~125 ~274 ~62 ~125 stone
fill ~272 ~63 ~125 ~274 ~65 ~125 dirt
fill ~272 ~66 ~125 ~274 ~66 ~125 grass_block
fill ~275 ~60 ~125 ~277 ~63 ~125 stone
fill ~275 ~64 ~125 ~277 ~66 ~125 dirt
fill ~275 ~67 ~125 ~277 ~67 ~125 grass_block
fill ~278 ~60 ~125 ~281 ~64 ~125 stone
fill ~278 ~65 ~125 ~281 ~67 ~125 dirt
fill ~278 ~68 ~125 ~281 ~68 ~125 grass_block
fill ~282 ~60 ~125 ~284 ~65 ~125 stone
fill ~282 ~66 ~125 ~284 ~68 ~125 dirt
fill ~282 ~69 ~125 ~284 ~69 ~125 grass_block
fill ~285 ~60 ~125 ~287 ~66 ~125 stone
fill ~285 ~67 ~125 ~287 ~69 ~125 dirt
fill ~285 ~70 ~125 ~287 ~70 ~125 grass_block
fill ~272 ~60 ~126 ~274 ~62 ~126 stone
fill ~272 ~63 ~126 ~274 ~65 ~126 dirt
fill ~272 ~66 ~126 ~274 ~66 ~126 grass_block
fill ~275 ~60 ~126 ~277 ~63 ~126 stone
fill ~275 ~64 ~126 ~277 ~66 ~126 dirt
fill ~275 ~67 ~126 ~277 ~67 ~126 grass_block
fill ~278 ~60 ~126 ~281 ~64 ~126 stone
fill ~278 ~65 ~126 ~281 ~67 ~126 dirt
fill ~278 ~68 ~126 ~281 ~68 ~126 grass_block
fill ~282 ~60 ~126 ~285 ~65 ~126 stone
fill ~282 ~66 ~126 ~285 ~68 ~126 dirt
fill ~282 ~69 ~126 ~285 ~69 ~126 grass_block
fill ~286 ~60 ~126 ~287 ~66 ~126 stone
fill ~286 ~67 ~126 ~287 ~69 ~126 dirt
fill ~286 ~70 ~126 ~287 ~70 ~126 grass_block
fill ~272 ~60 ~127 ~274 ~62 ~127 stone
fill ~272 ~63 ~127 ~274 ~65 ~127 dirt
fill ~272 ~66 ~127 ~274 ~66 ~127 grass_block
fill ~275 ~60 ~127 ~277 ~63 ~127 stone
fill ~275 ~64 ~127 ~277 ~66 ~127 dirt
fill ~275 ~67 ~127 ~277 ~67 ~127 grass_block
fill ~278 ~60 ~127 ~282 ~64 ~127 stone
fill ~278 ~65 ~127 ~282 ~67 ~127 dirt
fill ~278 ~68 ~127 ~282 ~68 ~127 grass_block
fill ~283 ~60 ~127 ~286 ~65 ~127 stone
fill ~283 ~66 ~127 ~286 ~68 ~127 dirt
fill ~283 ~69 ~127 ~286 ~69 ~127 grass_block
fill ~287 ~60 ~127 ~287 ~66 ~127 stone
fill ~287 ~67 ~127 ~287 ~69 ~127 dirt
fill ~287 ~70 ~127 ~287 ~70 ~127 grass_block