fill ~368 ~60 ~48 ~369 ~66 ~48 stone
fill ~368 ~67 ~48 ~369 ~69 ~48 dirt
fill ~368 ~70 ~48 ~369 ~70 ~48 grass_block
fill ~370 ~60 ~48 ~373 ~65 ~48 stone
fill ~370 ~66 ~48 ~373 ~68 ~48 dirt
fill ~370 ~69 ~48 ~373 ~69 ~48 grass_block
fill ~374 ~60 ~48 ~376 ~64 ~48 stone
fill ~374 ~65 ~48 ~376 ~67 ~48 dirt
fill ~374 ~68 ~48 ~376 ~68 ~48 grass_block
fill ~377 ~60 ~48 ~381 ~63 ~48 stone
fill ~377 ~64 ~48 ~381 ~66 ~48 dirt
fill ~377 ~67 ~48 ~381 ~67 ~48 grass_block
fill ~382 ~60 ~48 ~383 ~64 ~48 stone
fill ~382 ~65 ~48 ~383 ~67 ~48 dirt
fill ~382 ~68 ~48 ~383 ~68 ~48 grass_block
fill ~368 ~60 ~49 ~369 ~66 ~49 stone
fill ~368 ~67 ~49 ~369 ~69 ~49 dirt
fill ~368 ~70 ~49 ~369 ~70 ~49 grass_block
fill ~370 ~60 ~49 ~374 ~65 ~49 stone
fill ~370 ~66 ~49 ~374 ~68 ~49 dirt
fill ~370 ~69 ~49 ~374 ~69 ~49 grass_block
fill ~375 ~60 ~49 ~376 ~64 ~49 stone
fill ~375 ~65 ~49 ~376 ~67 ~49 dirt
fill ~375 ~68 ~49 ~376 ~68 ~49 grass_block
fill ~377 ~60 ~49 ~382 ~63 ~49 stone
fill ~377 ~64 ~49 ~382 ~66 ~49 dirt
fill ~377 ~67 ~49 ~382 ~67 ~49 grass_block
fill ~383 ~60 ~49 ~383 ~64 ~49 stone
fill ~383 ~65 ~49 ~383 ~67 ~49 dirt
fill ~383 ~68 ~49 ~383 ~68 ~49 grass_block
fill ~368 ~60 ~50 ~374 ~65 ~50 stone
fill ~368 ~66 ~50 ~374 ~68 ~50 dirt
fill ~368 ~69 ~50 ~374 ~69 ~50 grass_block
fill ~375 ~60 ~50 ~376 ~64 ~50 stone
fill ~375 ~65 ~50 ~376 ~67 ~50 dirt
fill ~375 ~68 ~50 ~376 ~68 ~50 grass_block
fill ~377 ~60 ~50 ~383 ~63 ~50 stone
fill ~377 ~64 ~50 ~383 ~66 ~50 dirt
fill ~377 ~67 ~50 ~383 ~67 ~50 grass_block
fill ~368 ~60 ~51 ~369 ~65 ~51 stone
fill ~368 ~66 ~51 ~369 ~68 ~51 dirt
fill ~368 ~69 ~51 ~369 ~69 ~51 grass_block
fill ~370 ~60 ~51 ~371 ~64 ~51 stone
fill ~370 ~65 ~51 ~371 ~67 ~51 dirt
fill ~370 ~68 ~51 ~371 ~68 ~51 grass_block
fill ~372 ~60 ~51 ~375 ~65 ~51 stone
fill ~372 ~66 ~51 ~375 ~68 ~51 dirt
fill ~372 ~69 ~51 ~375 ~69 ~51 grass_block
fill ~376 ~60 ~51 ~378 ~64 ~51 stone
fill ~376 ~65 ~51 ~378 ~67 ~51 dirt
fill ~376 ~68 ~51 ~378 ~68 ~51 grass_block
fill ~379 ~60 ~51 ~383 ~63 ~51 stone
fill ~379 ~64 ~51 ~383 ~66 ~51 dirt
fill ~379 ~67 ~51 ~383 ~67 ~51 grass_block
fill ~368 ~60 ~52 ~371 ~64 ~52 stone
fill ~368 ~65 ~52 ~371 ~67 ~52 dirt
fill ~368 ~68 ~52 ~371 ~68 ~52 grass_block
fill ~372 ~60 ~52 ~376 ~65 ~52 stone
fill ~372 ~66 ~52 ~376 ~68 ~52 dirt
fill ~372 ~69 ~52 ~376 ~69 ~52 grass_block
fill ~377 ~60 ~52 ~379 ~64 ~52 stone
fill ~377 ~65 ~52 ~379 ~67 ~52 dirt
fill ~377 ~68 ~52 ~379 ~68 ~52 grass_block
fill ~380 ~60 ~52 ~383 ~63 ~52 stone
fill ~380 ~64 ~52 ~383 ~66 ~52 dirt
fill ~380 ~67 ~52 ~383 ~67 ~52 grass_block
fill ~368 ~60 ~53 ~372 ~64 ~53 stone
fill ~368 ~65 ~53 ~372 ~67 ~53 dirt
fill ~368 ~68 ~53 ~372 ~68 ~53 grass_block
fill ~373 ~60 ~53 ~376 ~65 ~53 stone
fill ~373 ~66 ~53 ~376 ~68 ~53 dirt
fill ~373 ~69 ~53 ~376 ~69 ~53 grass_block
fill ~377 ~60 ~53 ~379 ~64 ~53 stone
fill ~377 ~65 ~53 ~379 ~67 ~53 dirt
fill ~377 ~68 ~53 ~379 ~68 ~53 grass_block
fill ~380 ~60 ~53 ~383 ~63 ~53 stone
fill ~380 ~64 ~53 ~383 ~66 ~53 dirt
fill ~380 ~67 ~53 ~383 ~67 ~53 grass_block
fill ~368 ~60 ~54 ~371 ~64 ~54 stone
fill ~368 ~65 ~54 ~371 ~67 ~54 dirt
fill ~368 ~68 ~54 ~371 ~68 ~54 grass_block
fill ~372 ~60 ~54 ~377 ~65 ~54 stone
fill ~372 ~66 ~54 ~377 ~68 ~54 dirt
fill ~372 ~69 ~54 ~377 ~69 ~54 grass_block
fill ~378 ~60 ~54 ~379 ~64 ~54 stone
fill ~378 ~65 ~54 ~379 ~67 ~54 dirt
fill ~378 ~68 ~54 ~379 ~68 ~54 grass_block
fill ~380 ~60 ~54 ~382 ~63 ~54 stone
fill ~380 ~64 ~54 ~382 ~66 ~54 dirt
fill ~380 ~67 ~54 ~382 ~67 ~54 grass_block
fill ~383 ~60 ~54 ~383 ~62 ~54 stone
fill ~383 ~63 ~54 ~383 ~65 ~54 dirt
fill ~383 ~66 ~54 ~383 ~66 ~54 grass_block
fill ~368 ~60 ~55 ~368 ~64 ~55 stone
fill ~368 ~65 ~55 ~368 ~67 ~55 dirt
fill ~368 ~68 ~55 ~368 ~68 ~55 grass_block
fill ~369 ~60 ~55 ~369 ~63 ~55 stone
fill ~369 ~64 ~55 ~369 ~66 ~55 dirt
fill ~369 ~67 ~55 ~369 ~67 ~55 grass_block
fill ~370 ~60 ~55 ~371 ~64 ~55 stone
fill ~370 ~65 ~55 ~371 ~67 ~55 dirt
fill ~370 ~68 ~55 ~371 ~68 ~55 grass_block
fill ~372 ~60 ~55 ~377 ~65 ~55 stone
fill ~372 ~66 ~55 ~377 ~68 ~55 dirt
fill ~372 ~69 ~55 ~377 ~69 ~55 grass_block
fill ~378 ~60 ~55 ~381 ~64 ~55 stone
fill ~378 ~65 ~55 ~381 ~67 ~55 dirt
fill ~378 ~68 ~55 ~381 ~68 ~55 grass_block
fill ~382 ~60 ~55 ~383 ~63 ~55 stone
fill ~382 ~64 ~55 ~383 ~66 ~55 dirt
fill ~382 ~67 ~55 ~383 ~67 ~55 grass_block
fill ~368 ~60 ~56 ~368 ~64 ~56 stone
fill ~368 ~65 ~56 ~368 ~67 ~56 dirt
fill ~368 ~68 ~56 ~368 ~68 ~56 grass_block
fill ~369 ~60 ~56 ~369 ~63 ~56 stone
fill ~369 ~64 ~56 ~369 ~66 ~56 dirt
fill ~369 ~67 ~56 ~369 ~67 ~56 grass_block
fill ~370 ~60 ~56 ~371 ~64 ~56 stone
fill ~370 ~65 ~56 ~371 ~67 ~56 dirt
fill ~370 ~68 ~56 ~371 ~68 ~56 grass_block
fill ~372 ~60 ~56 ~378 ~65 ~56 stone
fill ~372 ~66 ~56 ~378 ~68 ~56 dirt
fill ~372 ~69 ~56 ~378 ~69 ~56 grass_block
fill ~379 ~60 ~56 ~381 ~64 ~56 stone
fill ~379 ~65 ~56 ~381 ~67 ~56 dirt
fill ~379 ~68 ~56 ~381 ~68 ~56 grass_block
fill ~382 ~60 ~56 ~383 ~63 ~56 stone
fill ~382 ~64 ~56 ~383 ~66 ~56 dirt
fill ~382 ~67 ~56 ~383 ~67 ~56 grass_block
fill ~368 ~60 ~57 ~369 ~63 ~57 stone
fill ~368 ~64 ~57 ~369 ~66 ~57 dirt
fill ~368 ~67 ~57 ~369 ~67 ~57 grass_block
fill ~370 ~60 ~57 ~372 ~64 ~57 stone
fill ~370 ~65 ~57 ~372 ~67 ~57 dirt
fill ~370 ~68 ~57 ~372 ~68 ~57 grass_block
fill ~373 ~60 ~57 ~379 ~65 ~57 stone
fill ~373 ~66 ~57 ~379 ~68 ~57 dirt
fill ~373 ~69 ~57 ~379 ~69 ~57 grass_block
fill ~380 ~60 ~57 ~382 ~64 ~57 stone
fill ~380 ~65 ~57 ~382 ~67 ~57 dirt
fill ~380 ~68 ~57 ~382 ~68 ~57 grass_block
fill ~383 ~60 ~57 ~383 ~63 ~57 stone
fill ~383 ~64 ~57 ~383 ~66 ~57 dirt
fill ~383 ~67 ~57 ~383 ~67 ~57 grass_block
fill ~368 ~60 ~58 ~369 ~63 ~58 stone
fill ~368 ~64 ~58 ~369 ~66 ~58 dirt
fill ~368 ~67 ~58 ~369 ~67 ~58 grass_block
fill ~370 ~60 ~58 ~372 ~64 ~58 stone
fill ~370 ~65 ~58 ~372 ~67 ~58 dirt
fill ~370 ~68 ~58 ~372 ~68 ~58 grass_block
fill ~373 ~60 ~58 ~380 ~65 ~58 stone
fill ~373 ~66 ~58 ~380 ~68 ~58 dirt
fill ~373 ~69 ~58 ~380 ~69 ~58 grass_block
fill ~381 ~60 ~58 ~383 ~64 ~58 stone
fill ~381 ~65 ~58 ~383 ~67 ~58 dirt
fill ~381 ~68 ~58 ~383 ~68 ~58 grass_block
fill ~368 ~60 ~59 ~369 ~63 ~59 stone
fill ~368 ~64 ~59 ~369 ~66 ~59 dirt
fill ~368 ~67 ~59 ~369 ~67 ~59 grass_block
fill ~370 ~60 ~59 ~373 ~64 ~59 stone
fill ~370 ~65 ~59 ~373 ~67 ~59 dirt
fill ~370 ~68 ~59 ~373 ~68 ~59 grass_block
fill ~374 ~60 ~59 ~375 ~65 ~59 stone
fill ~374 ~66 ~59 ~375 ~68 ~59 dirt
fill ~374 ~69 ~59 ~375 ~69 ~59 grass_block
fill ~376 ~60 ~59 ~377 ~64 ~59 stone
fill ~376 ~65 ~59 ~377 ~67 ~59 dirt
fill ~376 ~68 ~59 ~377 ~68 ~59 grass_block
fill ~378 ~60 ~59 ~381 ~65 ~59 stone
fill ~378 ~66 ~59 ~381 ~68 ~59 dirt
fill ~378 ~69 ~59 ~381 ~69 ~59 grass_block
fill ~382 ~60 ~59 ~383 ~64 ~59 stone
fill ~382 ~65 ~59 ~383 ~67 ~59 dirt
fill ~382 ~68 ~59 ~383 ~68 ~59 grass_block
fill ~368 ~60 ~60 ~369 ~63 ~60 stone
fill ~368 ~64 ~60 ~369 ~66 ~60 dirt
fill ~368 ~67 ~60 ~369 ~67 ~60 grass_block
fill ~370 ~60 ~60 ~378 ~64 ~60 stone
fill ~370 ~65 ~60 ~378 ~67 ~60 dirt
fill ~370 ~68 ~60 ~378 ~68 ~60 grass_block
fill ~379 ~60 ~60 ~382 ~65 ~60 stone
fill ~379 ~66 ~60 ~382 ~68 ~60 dirt
fill ~379 ~69 ~60 ~382 ~69 ~60 grass_block
fill ~383 ~60 ~60 ~383 ~64 ~60 stone
fill ~383 ~65 ~60 ~383 ~67 ~60 dirt
fill ~383 ~68 ~60 ~383 ~68 ~60 grass_block
fill ~368 ~60 ~61 ~370 ~63 ~61 stone
fill ~368 ~64 ~61 ~370 ~66 ~61 dirt
fill ~368 ~67 ~61 ~370 ~67 ~61 grass_block
fill ~371 ~60 ~61 ~383 ~64 ~61 stone
fill ~371 ~65 ~61 ~383 ~67 ~61 dirt
fill ~371 ~68 ~61 ~383 ~68 ~61 grass_block
fill ~368 ~60 ~62 ~370 ~63 ~62 stone
fill ~368 ~64 ~62 ~370 ~66 ~62 dirt
fill ~368 ~67 ~62 ~370 ~67 ~62 grass_block
fill ~371 ~60 ~62 ~374 ~64 ~62 stone
fill ~371 ~65 ~62 ~374 ~67 ~62 dirt
fill ~371 ~68 ~62 ~374 ~68 ~62 grass_block
fill ~375 ~60 ~62 ~377 ~63 ~62 stone
fill ~375 ~64 ~62 ~377 ~66 ~62 dirt
fill ~375 ~67 ~62 ~377 ~67 ~62 grass_block
fill ~378 ~60 ~62 ~382 ~64 ~62 stone
fill ~378 ~65 ~62 ~382 ~67 ~62 dirt
fill ~378 ~68 ~62 ~382 ~68 ~62 grass_block
fill ~383 ~60 ~62 ~383 ~65 ~62 stone
fill ~383 ~66 ~62 ~383 ~68 ~62 dirt
fill ~383 ~69 ~62 ~383 ~69 ~62 grass_block
fill ~368 ~60 ~63 ~371 ~63 ~63 stone
fill ~368 ~64 ~63 ~371 ~66 ~63 dirt
fill ~368 ~67 ~63 ~371 ~67 ~63 grass_block
fill ~372 ~60 ~63 ~373 ~64 ~63 stone
fill ~372 ~65 ~63 ~373 ~67 ~63 dirt
fill ~372 ~68 ~63 ~373 ~68 ~63 grass_block
fill ~374 ~60 ~63 ~380 ~63 ~63 stone
fill ~374 ~64 ~63 ~380 ~66 ~63 dirt
fill ~374 ~67 ~63 ~380 ~67 ~63 grass_block
fill ~381 ~60 ~63 ~383 ~64 ~63 stone
fill ~381 ~65 ~63 ~383 ~67 ~63 dirt
fill ~381 ~68 ~63 ~383 ~68 ~63 grass_block