fill ~384 ~60 ~0 ~385 ~64 ~0 stone
fill ~384 ~65 ~0 ~385 ~67 ~0 dirt
fill ~384 ~68 ~0 ~385 ~68 ~0 grass_block
fill ~386 ~60 ~0 ~388 ~63 ~0 stone
fill ~386 ~64 ~0 ~388 ~66 ~0 dirt
fill ~386 ~67 ~0 ~388 ~67 ~0 grass_block
fill ~389 ~60 ~0 ~392 ~62 ~0 stone
fill ~389 ~63 ~0 ~392 ~65 ~0 dirt
fill ~389 ~66 ~0 ~392 ~66 ~0 grass_block
fill ~393 ~60 ~0 ~396 ~63 ~0 stone
fill ~393 ~64 ~0 ~396 ~66 ~0 dirt
fill ~393 ~67 ~0 ~396 ~67 ~0 grass_block
fill ~397 ~60 ~0 ~399 ~64 ~0 stone
fill ~397 ~65 ~0 ~399 ~67 ~0 dirt
fill ~397 ~68 ~0 ~399 ~68 ~0 grass_block
fill ~384 ~60 ~1 ~386 ~64 ~1 stone
fill ~384 ~65 ~1 ~386 ~67 ~1 dirt
fill ~384 ~68 ~1 ~386 ~68 ~1 grass_block
fill ~387 ~60 ~1 ~389 ~63 ~1 stone
fill ~387 ~64 ~1 ~389 ~66 ~1 dirt
fill ~387 ~67 ~1 ~389 ~67 ~1 grass_block
fill ~390 ~60 ~1 ~393 ~62 ~1 stone
fill ~390 ~63 ~1 ~393 ~65 ~1 dirt
fill ~390 ~66 ~1 ~393 ~66 ~1 grass_block
fill ~394 ~60 ~1 ~397 ~63 ~1 stone
fill ~394 ~64 ~1 ~397 ~66 ~1 dirt
fill ~394 ~67 ~1 ~397 ~67 ~1 grass_block
fill ~398 ~60 ~1 ~399 ~64 ~1 stone
fill ~398 ~65 ~1 ~399 ~67 ~1 dirt
fill ~398 ~68 ~1 ~399 ~68 ~1 grass_block
fill ~384 ~60 ~2 ~387 ~64 ~2 stone
fill ~384 ~65 ~2 ~387 ~67 ~2 dirt
fill ~384 ~68 ~2 ~387 ~68 ~2 grass_block
fill ~388 ~60 ~2 ~390 ~63 ~2 stone
fill ~388 ~64 ~2 ~390 ~66 ~2 dirt
fill ~388 ~67 ~2 ~390 ~67 ~2 grass_block
fill ~391 ~60 ~2 ~394 ~62 ~2 stone
fill ~391 ~63 ~2 ~394 ~65 ~2 dirt
fill ~391 ~66 ~2 ~394 ~66 ~2 grass_block
fill ~395 ~60 ~2 ~398 ~63 ~2 stone
fill ~395 ~64 ~2 ~398 ~66 ~2 dirt
fill ~395 ~67 ~2 ~398 ~67 ~2 grass_block
fill ~399 ~60 ~2 ~399 ~64 ~2 stone
fill ~399 ~65 ~2 ~399 ~67 ~2 dirt
fill ~399 ~68 ~2 ~399 ~68 ~2 grass_block
fill ~384 ~60 ~3 ~384 ~65 ~3 stone
fill ~384 ~66 ~3 ~384 ~68 ~3 dirt
fill ~384 ~69 ~3 ~384 ~69 ~3 grass_block
fill ~385 ~60 ~3 ~387 ~64 ~3 stone
fill ~385 ~65 ~3 ~387 ~67 ~3 dirt
fill ~385 ~68 ~3 ~387 ~68 ~3 grass_block
fill ~388 ~60 ~3 ~391 ~63 ~3 stone
fill ~388 ~64 ~3 ~391 ~66 ~3 dirt
fill ~388 ~67 ~3 ~391 ~67 ~3 grass_block
fill ~392 ~60 ~3 ~396 ~62 ~3 stone
fill ~392 ~63 ~3 ~396 ~65 ~3 dirt
fill ~392 ~66 ~3 ~396 ~66 ~3 grass_block
fill ~397 ~60 ~3 ~399 ~63 ~3 stone
fill ~397 ~64 ~3 ~399 ~66 ~3 dirt
fill ~397 ~67 ~3 ~399 ~67 ~3 grass_block
fill ~384 ~60 ~4 ~385 ~65 ~4 stone
fill ~384 ~66 ~4 ~385 ~68 ~4 dirt
fill ~384 ~69 ~4 ~385 ~69 ~4 grass_block
fill ~386 ~60 ~4 ~389 ~64 ~4 stone
fill ~386 ~65 ~4 ~389 ~67 ~4 dirt
fill ~386 ~68 ~4 ~389 ~68 ~4 grass_block
fill ~390 ~60 ~4 ~392 ~63 ~4 stone
fill ~390 ~64 ~4 ~392 ~66 ~4 dirt
fill ~390 ~67 ~4 ~392 ~67 ~4 grass_block
fill ~393 ~60 ~4 ~397 ~62 ~4 stone
fill ~393 ~63 ~4 ~397 ~65 ~4 dirt
fill ~393 ~66 ~4 ~397 ~66 ~4 grass_block
fill ~398 ~60 ~4 ~399 ~63 ~4 stone
fill ~398 ~64 ~4 ~399 ~66 ~4 dirt
fill ~398 ~67 ~4 ~399 ~67 ~4 grass_block
fill ~384 ~60 ~5 ~386 ~65 ~5 stone
fill ~384 ~66 ~5 ~386 ~68 ~5 dirt
fill ~384 ~69 ~5 ~386 ~69 ~5 grass_block
fill ~387 ~60 ~5 ~390 ~64 ~5 stone
fill ~387 ~65 ~5 ~390 ~67 ~5 dirt
fill ~387 ~68 ~5 ~390 ~68 ~5 grass_block
fill ~391 ~60 ~5 ~393 ~63 ~5 stone
fill ~391 ~64 ~5 ~393 ~66 ~5 dirt
fill ~391 ~67 ~5 ~393 ~67 ~5 grass_block
fill ~394 ~60 ~5 ~397 ~62 ~5 stone
fill ~394 ~63 ~5 ~397 ~65 ~5 dirt
fill ~394 ~66 ~5 ~397 ~66 ~5 grass_block
fill ~398 ~60 ~5 ~399 ~63 ~5 stone
fill ~398 ~64 ~5 ~399 ~66 ~5 dirt
fill ~398 ~67 ~5 ~399 ~67 ~5 grass_block
fill ~384 ~60 ~6 ~387 ~65 ~6 stone
fill ~384 ~66 ~6 ~387 ~68 ~6 dirt
fill ~384 ~69 ~6 ~387 ~69 ~6 grass_block
fill ~388 ~60 ~6 ~390 ~64 ~6 stone
fill ~388 ~65 ~6 ~390 ~67 ~6 dirt
fill ~388 ~68 ~6 ~390 ~68 ~6 grass_block
fill ~391 ~60 ~6 ~394 ~63 ~6 stone
fill ~391 ~64 ~6 ~394 ~66 ~6 dirt
fill ~391 ~67 ~6 ~394 ~67 ~6 grass_block
fill ~395 ~60 ~6 ~398 ~62 ~6 stone
fill ~395 ~63 ~6 ~398 ~65 ~6 dirt
fill ~395 ~66 ~6 ~398 ~66 ~6 grass_block
fill ~399 ~60 ~6 ~399 ~63 ~6 stone
fill ~399 ~64 ~6 ~399 ~66 ~6 dirt
fill ~399 ~67 ~6 ~399 ~67 ~6 grass_block
fill ~384 ~60 ~7 ~388 ~65 ~7 stone
fill ~384 ~66 ~7 ~388 ~68 ~7 dirt
fill ~384 ~69 ~7 ~388 ~69 ~7 grass_block
fill ~389 ~60 ~7 ~391 ~64 ~7 stone
fill ~389 ~65 ~7 ~391 ~67 ~7 dirt
fill ~389 ~68 ~7 ~391 ~68 ~7 grass_block
fill ~392 ~60 ~7 ~395 ~63 ~7 stone
fill ~392 ~64 ~7 ~395 ~66 ~7 dirt
fill ~392 ~67 ~7 ~395 ~67 ~7 grass_block
fill ~396 ~60 ~7 ~399 ~62 ~7 stone
fill ~396 ~63 ~7 ~399 ~65 ~7 dirt
fill ~396 ~66 ~7 ~399 ~66 ~7 grass_block
fill ~384 ~60 ~8 ~392 ~64 ~8 stone
fill ~384 ~65 ~8 ~392 ~67 ~8 dirt
fill ~384 ~68 ~8 ~392 ~68 ~8 grass_block
fill ~393 ~60 ~8 ~395 ~63 ~8 stone
fill ~393 ~64 ~8 ~395 ~66 ~8 dirt
fill ~393 ~67 ~8 ~395 ~67 ~8 grass_block
fill ~396 ~60 ~8 ~399 ~62 ~8 stone
fill ~396 ~63 ~8 ~399 ~65 ~8 dirt
fill ~396 ~66 ~8 ~399 ~66 ~8 grass_block
fill ~384 ~60 ~9 ~393 ~64 ~9 stone
fill ~384 ~65 ~9 ~393 ~67 ~9 dirt
fill ~384 ~68 ~9 ~393 ~68 ~9 grass_block
fill ~394 ~60 ~9 ~396 ~63 ~9 stone
fill ~394 ~64 ~9 ~396 ~66 ~9 dirt
fill ~394 ~67 ~9 ~396 ~67 ~9 grass_block
fill ~397 ~60 ~9 ~399 ~62 ~9 stone
fill ~397 ~63 ~9 ~399 ~65 ~9 dirt
fill ~397 ~66 ~9 ~399 ~66 ~9 grass_block
fill ~384 ~60 ~10 ~394 ~64 ~10 stone
fill ~384 ~65 ~10 ~394 ~67 ~10 dirt
fill ~384 ~68 ~10 ~394 ~68 ~10 grass_block
fill ~395 ~60 ~10 ~397 ~63 ~10 stone
fill ~395 ~64 ~10 ~397 ~66 ~10 dirt
fill ~395 ~67 ~10 ~397 ~67 ~10 grass_block
fill ~398 ~60 ~10 ~399 ~62 ~10 stone
fill ~398 ~63 ~10 ~399 ~65 ~10 dirt
fill ~398 ~66 ~10 ~399 ~66 ~10 grass_block
fill ~384 ~60 ~11 ~389 ~63 ~11 stone
fill ~384 ~64 ~11 ~389 ~66 ~11 dirt
fill ~384 ~67 ~11 ~389 ~67 ~11 grass_block
fill ~390 ~60 ~11 ~394 ~64 ~11 stone
fill ~390 ~65 ~11 ~394 ~67 ~11 dirt
fill ~390 ~68 ~11 ~394 ~68 ~11 grass_block
fill ~395 ~60 ~11 ~398 ~63 ~11 stone
fill ~395 ~64 ~11 ~398 ~66 ~11 dirt
fill ~395 ~67 ~11 ~398 ~67 ~11 grass_block
fill ~399 ~60 ~11 ~399 ~62 ~11 stone
fill ~399 ~63 ~11 ~399 ~65 ~11 dirt
fill ~399 ~66 ~11 ~399 ~66 ~11 grass_block
fill ~384 ~60 ~12 ~398 ~63 ~12 stone
fill ~384 ~64 ~12 ~398 ~66 ~12 dirt
fill ~384 ~67 ~12 ~398 ~67 ~12 grass_block
fill ~399 ~60 ~12 ~399 ~62 ~12 stone
fill ~399 ~63 ~12 ~399 ~65 ~12 dirt
fill ~399 ~66 ~12 ~399 ~66 ~12 grass_block
fill ~384 ~60 ~13 ~399 ~63 ~13 stone
fill ~384 ~64 ~13 ~399 ~66 ~13 dirt
fill ~384 ~67 ~13 ~399 ~67 ~13 grass_block
fill ~384 ~60 ~14 ~387 ~63 ~14 stone
fill ~384 ~64 ~14 ~387 ~66 ~14 dirt
fill ~384 ~67 ~14 ~387 ~67 ~14 grass_block
fill ~388 ~60 ~14 ~389 ~62 ~14 stone
fill ~388 ~63 ~14 ~389 ~65 ~14 dirt
fill ~388 ~66 ~14 ~389 ~66 ~14 grass_block
fill ~390 ~60 ~14 ~399 ~63 ~14 stone
fill ~390 ~64 ~14 ~399 ~66 ~14 dirt
fill ~390 ~67 ~14 ~399 ~67 ~14 grass_block
fill ~384 ~60 ~15 ~384 ~62 ~15 stone
fill ~384 ~63 ~15 ~384 ~65 ~15 dirt
fill ~384 ~66 ~15 ~384 ~66 ~15 grass_block
fill ~385 ~60 ~15 ~385 ~63 ~15 stone
fill ~385 ~64 ~15 ~385 ~66 ~15 dirt
fill ~385 ~67 ~15 ~385 ~67 ~15 grass_block
fill ~386 ~60 ~15 ~394 ~62 ~15 stone
fill ~386 ~63 ~15 ~394 ~65 ~15 dirt
fill ~386 ~66 ~15 ~394 ~66 ~15 grass_block
fill ~395 ~60 ~15 ~399 ~63 ~15 stone
fill ~395 ~64 ~15 ~399 ~66 ~15 dirt
fill ~395 ~67 ~15 ~399 ~67 ~15 grass_block