fill ~336 ~60 ~16 ~350 ~64 ~16 stone
fill ~336 ~65 ~16 ~350 ~67 ~16 dirt
fill ~336 ~68 ~16 ~350 ~68 ~16 grass_block
fill ~351 ~60 ~16 ~351 ~63 ~16 stone
fill ~351 ~64 ~16 ~351 ~66 ~16 dirt
fill ~351 ~67 ~16 ~351 ~67 ~16 grass_block
fill ~336 ~60 ~17 ~336 ~65 ~17 stone
fill ~336 ~66 ~17 ~336 ~68 ~17 dirt
fill ~336 ~69 ~17 ~336 ~69 ~17 grass_block
fill ~337 ~60 ~17 ~340 ~64 ~17 stone
fill ~337 ~65 ~17 ~340 ~67 ~17 dirt
fill ~337 ~68 ~17 ~340 ~68 ~17 grass_block
fill ~341 ~60 ~17 ~346 ~65 ~17 stone
fill ~341 ~66 ~17 ~346 ~68 ~17 dirt
fill ~341 ~69 ~17 ~346 ~69 ~17 grass_block
fill ~347 ~60 ~17 ~350 ~64 ~17 stone
fill ~347 ~65 ~17 ~350 ~67 ~17 dirt
fill ~347 ~68 ~17 ~350 ~68 ~17 grass_block
fill ~351 ~60 ~17 ~351 ~63 ~17 stone
fill ~351 ~64 ~17 ~351 ~66 ~17 dirt
fill ~351 ~67 ~17 ~351 ~67 ~17 grass_block
fill ~336 ~60 ~18 ~336 ~65 ~18 stone
fill ~336 ~66 ~18 ~336 ~68 ~18 dirt
fill ~336 ~69 ~18 ~336 ~69 ~18 grass_block
fill ~337 ~60 ~18 ~338 ~64 ~18 stone
fill ~337 ~65 ~18 ~338 ~67 ~18 dirt
fill ~337 ~68 ~18 ~338 ~68 ~18 grass_block
fill ~339 ~60 ~18 ~347 ~65 ~18 stone
fill ~339 ~66 ~18 ~347 ~68 ~18 dirt
fill ~339 ~69 ~18 ~347 ~69 ~18 grass_block
fill ~348 ~60 ~18 ~350 ~64 ~18 stone
fill ~348 ~65 ~18 ~350 ~67 ~18 dirt
fill ~348 ~68 ~18 ~350 ~68 ~18 grass_block
fill ~351 ~60 ~18 ~351 ~63 ~18 stone
fill ~351 ~64 ~18 ~351 ~66 ~18 dirt
fill ~351 ~67 ~18 ~351 ~67 ~18 grass_block
fill ~336 ~60 ~19 ~347 ~65 ~19 stone
fill ~336 ~66 ~19 ~347 ~68 ~19 dirt
fill ~336 ~69 ~19 ~347 ~69 ~19 grass_block
fill ~348 ~60 ~19 ~351 ~64 ~19 stone
fill ~348 ~65 ~19 ~351 ~67 ~19 dirt
fill ~348 ~68 ~19 ~351 ~68 ~19 grass_block
fill ~336 ~60 ~20 ~343 ~65 ~20 stone
fill ~336 ~66 ~20 ~343 ~68 ~20 dirt
fill ~336 ~69 ~20 ~343 ~69 ~20 grass_block
fill ~344 ~60 ~20 ~345 ~66 ~20 stone
fill ~344 ~67 ~20 ~345 ~69 ~20 dirt
fill ~344 ~70 ~20 ~345 ~70 ~20 grass_block
fill ~346 ~60 ~20 ~350 ~65 ~20 stone
fill ~346 ~66 ~20 ~350 ~68 ~20 dirt
fill ~346 ~69 ~20 ~350 ~69 ~20 grass_block
fill ~351 ~60 ~20 ~351 ~64 ~20 stone
fill ~351 ~65 ~20 ~351 ~67 ~20 dirt
fill ~351 ~68 ~20 ~351 ~68 ~20 grass_block
fill ~336 ~60 ~21 ~342 ~65 ~21 stone
fill ~336 ~66 ~21 ~342 ~68 ~21 dirt
fill ~336 ~69 ~21 ~342 ~69 ~21 grass_block
fill ~343 ~60 ~21 ~344 ~66 ~21 stone
fill ~343 ~67 ~21 ~344 ~69 ~21 dirt
fill ~343 ~70 ~21 ~344 ~70 ~21 grass_block
fill ~345 ~60 ~21 ~351 ~65 ~21 stone
fill ~345 ~66 ~21 ~351 ~68 ~21 dirt
fill ~345 ~69 ~21 ~351 ~69 ~21 grass_block
fill ~336 ~60 ~22 ~351 ~65 ~22 stone
fill ~336 ~66 ~22 ~351 ~68 ~22 dirt
fill ~336 ~69 ~22 ~351 ~69 ~22 grass_block
fill ~336 ~60 ~23 ~345 ~65 ~23 stone
fill ~336 ~66 ~23 ~345 ~68 ~23 dirt
fill ~336 ~69 ~23 ~345 ~69 ~23 grass_block
fill ~346 ~60 ~23 ~348 ~64 ~23 stone
fill ~346 ~65 ~23 ~348 ~67 ~23 dirt
fill ~346 ~68 ~23 ~348 ~68 ~23 grass_block
fill ~349 ~60 ~23 ~351 ~65 ~23 stone
fill ~349 ~66 ~23 ~351 ~68 ~23 dirt
fill ~349 ~69 ~23 ~351 ~69 ~23 grass_block
fill ~336 ~60 ~24 ~337 ~65 ~24 stone
fill ~336 ~66 ~24 ~337 ~68 ~24 dirt
fill ~336 ~69 ~24 ~337 ~69 ~24 grass_block
fill ~338 ~60 ~24 ~338 ~64 ~24 stone
fill ~338 ~65 ~24 ~338 ~67 ~24 dirt
fill ~338 ~68 ~24 ~338 ~68 ~24 grass_block
fill ~339 ~60 ~24 ~343 ~65 ~24 stone
fill ~339 ~66 ~24 ~343 ~68 ~24 dirt
fill ~339 ~69 ~24 ~343 ~69 ~24 grass_block
fill ~344 ~60 ~24 ~348 ~64 ~24 stone
fill ~344 ~65 ~24 ~348 ~67 ~24 dirt
fill ~344 ~68 ~24 ~348 ~68 ~24 grass_block
fill ~349 ~60 ~24 ~351 ~65 ~24 stone
fill ~349 ~66 ~24 ~351 ~68 ~24 dirt
fill ~349 ~69 ~24 ~351 ~69 ~24 grass_block
fill ~336 ~60 ~25 ~336 ~65 ~25 stone
fill ~336 ~66 ~25 ~336 ~68 ~25 dirt
fill ~336 ~69 ~25 ~336 ~69 ~25 grass_block
fill ~337 ~60 ~25 ~340 ~64 ~25 stone
fill ~337 ~65 ~25 ~340 ~67 ~25 dirt
fill ~337 ~68 ~25 ~340 ~68 ~25 grass_block
fill ~341 ~60 ~25 ~341 ~65 ~25 stone
fill ~341 ~66 ~25 ~341 ~68 ~25 dirt
fill ~341 ~69 ~25 ~341 ~69 ~25 grass_block
fill ~342 ~60 ~25 ~347 ~64 ~25 stone
fill ~342 ~65 ~25 ~347 ~67 ~25 dirt
fill ~342 ~68 ~25 ~347 ~68 ~25 grass_block
fill ~348 ~60 ~25 ~351 ~65 ~25 stone
fill ~348 ~66 ~25 ~351 ~68 ~25 dirt
fill ~348 ~69 ~25 ~351 ~69 ~25 grass_block
fill ~336 ~60 ~26 ~336 ~65 ~26 stone
fill ~336 ~66 ~26 ~336 ~68 ~26 dirt
fill ~336 ~69 ~26 ~336 ~69 ~26 grass_block
fill ~337 ~60 ~26 ~343 ~64 ~26 stone
fill ~337 ~65 ~26 ~343 ~67 ~26 dirt
fill ~337 ~68 ~26 ~343 ~68 ~26 grass_block
fill ~344 ~60 ~26 ~345 ~63 ~26 stone
fill ~344 ~64 ~26 ~345 ~66 ~26 dirt
fill ~344 ~67 ~26 ~345 ~67 ~26 grass_block
fill ~346 ~60 ~26 ~347 ~64 ~26 stone
fill ~346 ~65 ~26 ~347 ~67 ~26 dirt
fill ~346 ~68 ~26 ~347 ~68 ~26 grass_block
fill ~348 ~60 ~26 ~351 ~65 ~26 stone
fill ~348 ~66 ~26 ~351 ~68 ~26 dirt
fill ~348 ~69 ~26 ~351 ~69 ~26 grass_block
fill ~336 ~60 ~27 ~336 ~65 ~27 stone
fill ~336 ~66 ~27 ~336 ~68 ~27 dirt
fill ~336 ~69 ~27 ~336 ~69 ~27 grass_block
fill ~337 ~60 ~27 ~339 ~64 ~27 stone
fill ~337 ~65 ~27 ~339 ~67 ~27 dirt
fill ~337 ~68 ~27 ~339 ~68 ~27 grass_block
fill ~340 ~60 ~27 ~341 ~63 ~27 stone
fill ~340 ~64 ~27 ~341 ~66 ~27 dirt
fill ~340 ~67 ~27 ~341 ~67 ~27 grass_block
fill ~342 ~60 ~27 ~342 ~64 ~27 stone
fill ~342 ~65 ~27 ~342 ~67 ~27 dirt
fill ~342 ~68 ~27 ~342 ~68 ~27 grass_block
fill ~343 ~60 ~27 ~344 ~63 ~27 stone
fill ~343 ~64 ~27 ~344 ~66 ~27 dirt
fill ~343 ~67 ~27 ~344 ~67 ~27 grass_block
fill ~345 ~60 ~27 ~347 ~64 ~27 stone
fill ~345 ~65 ~27 ~347 ~67 ~27 dirt
fill ~345 ~68 ~27 ~347 ~68 ~27 grass_block
fill ~348 ~60 ~27 ~351 ~65 ~27 stone
fill ~348 ~66 ~27 ~351 ~68 ~27 dirt
fill ~348 ~69 ~27 ~351 ~69 ~27 grass_block
fill ~336 ~60 ~28 ~336 ~65 ~28 stone
fill ~336 ~66 ~28 ~336 ~68 ~28 dirt
fill ~336 ~69 ~28 ~336 ~69 ~28 grass_block
fill ~337 ~60 ~28 ~339 ~64 ~28 stone
fill ~337 ~65 ~28 ~339 ~67 ~28 dirt
fill ~337 ~68 ~28 ~339 ~68 ~28 grass_block
fill ~340 ~60 ~28 ~343 ~63 ~28 stone
fill ~340 ~64 ~28 ~343 ~66 ~28 dirt
fill ~340 ~67 ~28 ~343 ~67 ~28 grass_block
fill ~344 ~60 ~28 ~346 ~64 ~28 stone
fill ~344 ~65 ~28 ~346 ~67 ~28 dirt
fill ~344 ~68 ~28 ~346 ~68 ~28 grass_block
fill ~347 ~60 ~28 ~351 ~65 ~28 stone
fill ~347 ~66 ~28 ~351 ~68 ~28 dirt
fill ~347 ~69 ~28 ~351 ~69 ~28 grass_block
fill ~336 ~60 ~29 ~338 ~64 ~29 stone
fill ~336 ~65 ~29 ~338 ~67 ~29 dirt
fill ~336 ~68 ~29 ~338 ~68 ~29 grass_block
fill ~339 ~60 ~29 ~343 ~63 ~29 stone
fill ~339 ~64 ~29 ~343 ~66 ~29 dirt
fill ~339 ~67 ~29 ~343 ~67 ~29 grass_block
fill ~344 ~60 ~29 ~346 ~64 ~29 stone
fill ~344 ~65 ~29 ~346 ~67 ~29 dirt
fill ~344 ~68 ~29 ~346 ~68 ~29 grass_block
fill ~347 ~60 ~29 ~350 ~65 ~29 stone
fill ~347 ~66 ~29 ~350 ~68 ~29 dirt
fill ~347 ~69 ~29 ~350 ~69 ~29 grass_block
fill ~351 ~60 ~29 ~351 ~64 ~29 stone
fill ~351 ~65 ~29 ~351 ~67 ~29 dirt
fill ~351 ~68 ~29 ~351 ~68 ~29 grass_block
fill ~336 ~60 ~30 ~338 ~64 ~30 stone
fill ~336 ~65 ~30 ~338 ~67 ~30 dirt
fill ~336 ~68 ~30 ~338 ~68 ~30 grass_block
fill ~339 ~60 ~30 ~343 ~63 ~30 stone
fill ~339 ~64 ~30 ~343 ~66 ~30 dirt
fill ~339 ~67 ~30 ~343 ~67 ~30 grass_block
fill ~344 ~60 ~30 ~346 ~64 ~30 stone
fill ~344 ~65 ~30 ~346 ~67 ~30 dirt
fill ~344 ~68 ~30 ~346 ~68 ~30 grass_block
fill ~347 ~60 ~30 ~349 ~65 ~30 stone
fill ~347 ~66 ~30 ~349 ~68 ~30 dirt
fill ~347 ~69 ~30 ~349 ~69 ~30 grass_block
fill ~350 ~60 ~30 ~351 ~64 ~30 stone
fill ~350 ~65 ~30 ~351 ~67 ~30 dirt
fill ~350 ~68 ~30 ~351 ~68 ~30 grass_block
fill ~336 ~60 ~31 ~338 ~64 ~31 stone
fill ~336 ~65 ~31 ~338 ~67 ~31 dirt
fill ~336 ~68 ~31 ~338 ~68 ~31 grass_block
fill ~339 ~60 ~31 ~343 ~63 ~31 stone
fill ~339 ~64 ~31 ~343 ~66 ~31 dirt
fill ~339 ~67 ~31 ~343 ~67 ~31 grass_block
fill ~344 ~60 ~31 ~351 ~64 ~31 stone
fill ~344 ~65 ~31 ~351 ~67 ~31 dirt
fill ~344 ~68 ~31 ~351 ~68 ~31 grass_block