fill ~160 ~60 ~128 ~161 ~64 ~128 stone
fill ~160 ~65 ~128 ~161 ~67 ~128 dirt
fill ~160 ~68 ~128 ~161 ~68 ~128 grass_block
fill ~162 ~60 ~128 ~166 ~63 ~128 stone
fill ~162 ~64 ~128 ~166 ~66 ~128 dirt
fill ~162 ~67 ~128 ~166 ~67 ~128 grass_block
fill ~167 ~60 ~128 ~169 ~64 ~128 stone
fill ~167 ~65 ~128 ~169 ~67 ~128 dirt
fill ~167 ~68 ~128 ~169 ~68 ~128 grass_block
fill ~170 ~60 ~128 ~174 ~65 ~128 stone
fill ~170 ~66 ~128 ~174 ~68 ~128 dirt
fill ~170 ~69 ~128 ~174 ~69 ~128 grass_block
fill ~175 ~60 ~128 ~175 ~64 ~128 stone
fill ~175 ~65 ~128 ~175 ~67 ~128 dirt
fill ~175 ~68 ~128 ~175 ~68 ~128 grass_block
fill ~160 ~60 ~129 ~160 ~64 ~129 stone
fill ~160 ~65 ~129 ~160 ~67 ~129 dirt
fill ~160 ~68 ~129 ~160 ~68 ~129 grass_block
fill ~161 ~60 ~129 ~164 ~63 ~129 stone
fill ~161 ~64 ~129 ~164 ~66 ~129 dirt
fill ~161 ~67 ~129 ~164 ~67 ~129 grass_block
fill ~165 ~60 ~129 ~165 ~64 ~129 stone
fill ~165 ~65 ~129 ~165 ~67 ~129 dirt
fill ~165 ~68 ~129 ~165 ~68 ~129 grass_block
fill ~166 ~60 ~129 ~167 ~63 ~129 stone
fill ~166 ~64 ~129 ~167 ~66 ~129 dirt
fill ~166 ~67 ~129 ~167 ~67 ~129 grass_block
fill ~168 ~60 ~129 ~169 ~64 ~129 stone
fill ~168 ~65 ~129 ~169 ~67 ~129 dirt
fill ~168 ~68 ~129 ~169 ~68 ~129 grass_block
fill ~170 ~60 ~129 ~174 ~65 ~129 stone
fill ~170 ~66 ~129 ~174 ~68 ~129 dirt
fill ~170 ~69 ~129 ~174 ~69 ~129 grass_block
fill ~175 ~60 ~129 ~175 ~64 ~129 stone
fill ~175 ~65 ~129 ~175 ~67 ~129 dirt
fill ~175 ~68 ~129 ~175 ~68 ~129 grass_block
fill ~160 ~60 ~130 ~163 ~63 ~130 stone
fill ~160 ~64 ~130 ~163 ~66 ~130 dirt
fill ~160 ~67 ~130 ~163 ~67 ~130 grass_block
fill ~164 ~60 ~130 ~170 ~64 ~130 stone
fill ~164 ~65 ~130 ~170 ~67 ~130 dirt
fill ~164 ~68 ~130 ~170 ~68 ~130 grass_block
fill ~171 ~60 ~130 ~175 ~65 ~130 stone
fill ~171 ~66 ~130 ~175 ~68 ~130 dirt
fill ~171 ~69 ~130 ~175 ~69 ~130 grass_block
fill ~160 ~60 ~131 ~162 ~63 ~131 stone
fill ~160 ~64 ~131 ~162 ~66 ~131 dirt
fill ~160 ~67 ~131 ~162 ~67 ~131 grass_block
fill ~163 ~60 ~131 ~164 ~64 ~131 stone
fill ~163 ~65 ~131 ~164 ~67 ~131 dirt
fill ~163 ~68 ~131 ~164 ~68 ~131 grass_block
fill ~165 ~60 ~131 ~166 ~65 ~131 stone
fill ~165 ~66 ~131 ~166 ~68 ~131 dirt
fill ~165 ~69 ~131 ~166 ~69 ~131 grass_block
fill ~167 ~60 ~131 ~170 ~64 ~131 stone
fill ~167 ~65 ~131 ~170 ~67 ~131 dirt
fill ~167 ~68 ~131 ~170 ~68 ~131 grass_block
fill ~171 ~60 ~131 ~175 ~65 ~131 stone
fill ~171 ~66 ~131 ~175 ~68 ~131 dirt
fill ~171 ~69 ~131 ~175 ~69 ~131 grass_block
fill ~160 ~60 ~132 ~161 ~63 ~132 stone
fill ~160 ~64 ~132 ~161 ~66 ~132 dirt
fill ~160 ~67 ~132 ~161 ~67 ~132 grass_block
fill ~162 ~60 ~132 ~163 ~64 ~132 stone
fill ~162 ~65 ~132 ~163 ~67 ~132 dirt
fill ~162 ~68 ~132 ~163 ~68 ~132 grass_block
fill ~164 ~60 ~132 ~174 ~65 ~132 stone
fill ~164 ~66 ~132 ~174 ~68 ~132 dirt
fill ~164 ~69 ~132 ~174 ~69 ~132 grass_block
fill ~175 ~60 ~132 ~175 ~64 ~132 stone
fill ~175 ~65 ~132 ~175 ~67 ~132 dirt
fill ~175 ~68 ~132 ~175 ~68 ~132 grass_block
fill ~160 ~60 ~133 ~161 ~63 ~133 stone
fill ~160 ~64 ~133 ~161 ~66 ~133 dirt
fill ~160 ~67 ~133 ~161 ~67 ~133 grass_block
fill ~162 ~60 ~133 ~163 ~64 ~133 stone
fill ~162 ~65 ~133 ~163 ~67 ~133 dirt
fill ~162 ~68 ~133 ~163 ~68 ~133 grass_block
fill ~164 ~60 ~133 ~175 ~65 ~133 stone
fill ~164 ~66 ~133 ~175 ~68 ~133 dirt
fill ~164 ~69 ~133 ~175 ~69 ~133 grass_block
fill ~160 ~60 ~134 ~161 ~63 ~134 stone
fill ~160 ~64 ~134 ~161 ~66 ~134 dirt
fill ~160 ~67 ~134 ~161 ~67 ~134 grass_block
fill ~162 ~60 ~134 ~163 ~64 ~134 stone
fill ~162 ~65 ~134 ~163 ~67 ~134 dirt
fill ~162 ~68 ~134 ~163 ~68 ~134 grass_block
fill ~164 ~60 ~134 ~165 ~65 ~134 stone
fill ~164 ~66 ~134 ~165 ~68 ~134 dirt
fill ~164 ~69 ~134 ~165 ~69 ~134 grass_block
fill ~166 ~60 ~134 ~167 ~66 ~134 stone
fill ~166 ~67 ~134 ~167 ~69 ~134 dirt
fill ~166 ~70 ~134 ~167 ~70 ~134 grass_block
fill ~168 ~60 ~134 ~174 ~65 ~134 stone
fill ~168 ~66 ~134 ~174 ~68 ~134 dirt
fill ~168 ~69 ~134 ~174 ~69 ~134 grass_block
fill ~175 ~60 ~134 ~175 ~64 ~134 stone
fill ~175 ~65 ~134 ~175 ~67 ~134 dirt
fill ~175 ~68 ~134 ~175 ~68 ~134 grass_block
fill ~160 ~60 ~135 ~163 ~64 ~135 stone
fill ~160 ~65 ~135 ~163 ~67 ~135 dirt
fill ~160 ~68 ~135 ~163 ~68 ~135 grass_block
fill ~164 ~60 ~135 ~165 ~65 ~135 stone
fill ~164 ~66 ~135 ~165 ~68 ~135 dirt
fill ~164 ~69 ~135 ~165 ~69 ~135 grass_block
fill ~166 ~60 ~135 ~168 ~66 ~135 stone
fill ~166 ~67 ~135 ~168 ~69 ~135 dirt
fill ~166 ~70 ~135 ~168 ~70 ~135 grass_block
fill ~169 ~60 ~135 ~174 ~65 ~135 stone
fill ~169 ~66 ~135 ~174 ~68 ~135 dirt
fill ~169 ~69 ~135 ~174 ~69 ~135 grass_block
fill ~175 ~60 ~135 ~175 ~64 ~135 stone
fill ~175 ~65 ~135 ~175 ~67 ~135 dirt
fill ~175 ~68 ~135 ~175 ~68 ~135 grass_block
fill ~160 ~60 ~136 ~163 ~64 ~136 stone
fill ~160 ~65 ~136 ~163 ~67 ~136 dirt
fill ~160 ~68 ~136 ~163 ~68 ~136 grass_block
fill ~164 ~60 ~136 ~165 ~65 ~136 stone
fill ~164 ~66 ~136 ~165 ~68 ~136 dirt
fill ~164 ~69 ~136 ~165 ~69 ~136 grass_block
fill ~166 ~60 ~136 ~168 ~66 ~136 stone
fill ~166 ~67 ~136 ~168 ~69 ~136 dirt
fill ~166 ~70 ~136 ~168 ~70 ~136 grass_block
fill ~169 ~60 ~136 ~173 ~65 ~136 stone
fill ~169 ~66 ~136 ~173 ~68 ~136 dirt
fill ~169 ~69 ~136 ~173 ~69 ~136 grass_block
fill ~174 ~60 ~136 ~175 ~64 ~136 stone
fill ~174 ~65 ~136 ~175 ~67 ~136 dirt
fill ~174 ~68 ~136 ~175 ~68 ~136 grass_block
fill ~160 ~60 ~137 ~163 ~64 ~137 stone
fill ~160 ~65 ~137 ~163 ~67 ~137 dirt
fill ~160 ~68 ~137 ~163 ~68 ~137 grass_block
fill ~164 ~60 ~137 ~165 ~65 ~137 stone
fill ~164 ~66 ~137 ~165 ~68 ~137 dirt
fill ~164 ~69 ~137 ~165 ~69 ~137 grass_block
fill ~166 ~60 ~137 ~168 ~66 ~137 stone
fill ~166 ~67 ~137 ~168 ~69 ~137 dirt
fill ~166 ~70 ~137 ~168 ~70 ~137 grass_block
fill ~169 ~60 ~137 ~171 ~65 ~137 stone
fill ~169 ~66 ~137 ~171 ~68 ~137 dirt
fill ~169 ~69 ~137 ~171 ~69 ~137 grass_block
fill ~172 ~60 ~137 ~175 ~64 ~137 stone
fill ~172 ~65 ~137 ~175 ~67 ~137 dirt
fill ~172 ~68 ~137 ~175 ~68 ~137 grass_block
fill ~160 ~60 ~138 ~162 ~64 ~138 stone
fill ~160 ~65 ~138 ~162 ~67 ~138 dirt
fill ~160 ~68 ~138 ~162 ~68 ~138 grass_block
fill ~163 ~60 ~138 ~165 ~65 ~138 stone
fill ~163 ~66 ~138 ~165 ~68 ~138 dirt
fill ~163 ~69 ~138 ~165 ~69 ~138 grass_block
fill ~166 ~60 ~138 ~169 ~66 ~138 stone
fill ~166 ~67 ~138 ~169 ~69 ~138 dirt
fill ~166 ~70 ~138 ~169 ~70 ~138 grass_block
fill ~170 ~60 ~138 ~171 ~65 ~138 stone
fill ~170 ~66 ~138 ~171 ~68 ~138 dirt
fill ~170 ~69 ~138 ~171 ~69 ~138 grass_block
fill ~172 ~60 ~138 ~174 ~64 ~138 stone
fill ~172 ~65 ~138 ~174 ~67 ~138 dirt
fill ~172 ~68 ~138 ~174 ~68 ~138 grass_block
fill ~175 ~60 ~138 ~175 ~63 ~138 stone
fill ~175 ~64 ~138 ~175 ~66 ~138 dirt
fill ~175 ~67 ~138 ~175 ~67 ~138 grass_block
fill ~160 ~60 ~139 ~162 ~64 ~139 stone
fill ~160 ~65 ~139 ~162 ~67 ~139 dirt
fill ~160 ~68 ~139 ~162 ~68 ~139 grass_block
fill ~163 ~60 ~139 ~164 ~65 ~139 stone
fill ~163 ~66 ~139 ~164 ~68 ~139 dirt
fill ~163 ~69 ~139 ~164 ~69 ~139 grass_block
fill ~165 ~60 ~139 ~169 ~66 ~139 stone
fill ~165 ~67 ~139 ~169 ~69 ~139 dirt
fill ~165 ~70 ~139 ~169 ~70 ~139 grass_block
fill ~170 ~60 ~139 ~173 ~65 ~139 stone
fill ~170 ~66 ~139 ~173 ~68 ~139 dirt
fill ~170 ~69 ~139 ~173 ~69 ~139 grass_block
fill ~174 ~60 ~139 ~175 ~64 ~139 stone
fill ~174 ~65 ~139 ~175 ~67 ~139 dirt
fill ~174 ~68 ~139 ~175 ~68 ~139 grass_block
fill ~160 ~60 ~140 ~164 ~65 ~140 stone
fill ~160 ~66 ~140 ~164 ~68 ~140 dirt
fill ~160 ~69 ~140 ~164 ~69 ~140 grass_block
fill ~165 ~60 ~140 ~170 ~66 ~140 stone
fill ~165 ~67 ~140 ~170 ~69 ~140 dirt
fill ~165 ~70 ~140 ~170 ~70 ~140 grass_block
fill ~171 ~60 ~140 ~174 ~65 ~140 stone
fill ~171 ~66 ~140 ~174 ~68 ~140 dirt
fill ~171 ~69 ~140 ~174 ~69 ~140 grass_block
fill ~175 ~60 ~140 ~175 ~64 ~140 stone
fill ~175 ~65 ~140 ~175 ~67 ~140 dirt
fill ~175 ~68 ~140 ~175 ~68 ~140 grass_block
fill ~160 ~60 ~141 ~161 ~65 ~141 stone
fill ~160 ~66 ~141 ~161 ~68 ~141 dirt
fill ~160 ~69 ~141 ~161 ~69 ~141 grass_block
fill ~162 ~60 ~141 ~171 ~66 ~141 stone
fill ~162 ~67 ~141 ~171 ~69 ~141 dirt
fill ~162 ~70 ~141 ~171 ~70 ~141 grass_block
fill ~172 ~60 ~141 ~175 ~65 ~141 stone
fill ~172 ~66 ~141 ~175 ~68 ~141 dirt
fill ~172 ~69 ~141 ~175 ~69 ~141 grass_block
fill ~160 ~60 ~142 ~172 ~66 ~142 stone
fill ~160 ~67 ~142 ~172 ~69 ~142 dirt
fill ~160 ~70 ~142 ~172 ~70 ~142 grass_block
fill ~173 ~60 ~142 ~175 ~65 ~142 stone
fill ~173 ~66 ~142 ~175 ~68 ~142 dirt
fill ~173 ~69 ~142 ~175 ~69 ~142 grass_block
fill ~160 ~60 ~143 ~172 ~66 ~143 stone
fill ~160 ~67 ~143 ~172 ~69 ~143 dirt
fill ~160 ~70 ~143 ~172 ~70 ~143 grass_block
fill ~173 ~60 ~143 ~175 ~65 ~143 stone
fill ~173 ~66 ~143 ~175 ~68 ~143 dirt
fill ~173 ~69 ~143 ~175 ~69 ~143 grass_block