fill ~384 ~60 ~64 ~385 ~65 ~64 stone
fill ~384 ~66 ~64 ~385 ~68 ~64 dirt
fill ~384 ~69 ~64 ~385 ~69 ~64 grass_block
fill ~386 ~60 ~64 ~388 ~64 ~64 stone
fill ~386 ~65 ~64 ~388 ~67 ~64 dirt
fill ~386 ~68 ~64 ~388 ~68 ~64 grass_block
fill ~389 ~60 ~64 ~390 ~63 ~64 stone
fill ~389 ~64 ~64 ~390 ~66 ~64 dirt
fill ~389 ~67 ~64 ~390 ~67 ~64 grass_block
fill ~391 ~60 ~64 ~394 ~62 ~64 stone
fill ~391 ~63 ~64 ~394 ~65 ~64 dirt
fill ~391 ~66 ~64 ~394 ~66 ~64 grass_block
fill ~395 ~60 ~64 ~396 ~63 ~64 stone
fill ~395 ~64 ~64 ~396 ~66 ~64 dirt
fill ~395 ~67 ~64 ~396 ~67 ~64 grass_block
fill ~397 ~60 ~64 ~398 ~64 ~64 stone
fill ~397 ~65 ~64 ~398 ~67 ~64 dirt
fill ~397 ~68 ~64 ~398 ~68 ~64 grass_block
fill ~399 ~60 ~64 ~399 ~63 ~64 stone
fill ~399 ~64 ~64 ~399 ~66 ~64 dirt
fill ~399 ~67 ~64 ~399 ~67 ~64 grass_block
fill ~384 ~60 ~65 ~386 ~65 ~65 stone
fill ~384 ~66 ~65 ~386 ~68 ~65 dirt
fill ~384 ~69 ~65 ~386 ~69 ~65 grass_block
fill ~387 ~60 ~65 ~389 ~64 ~65 stone
fill ~387 ~65 ~65 ~389 ~67 ~65 dirt
fill ~387 ~68 ~65 ~389 ~68 ~65 grass_block
fill ~390 ~60 ~65 ~391 ~63 ~65 stone
fill ~390 ~64 ~65 ~391 ~66 ~65 dirt
fill ~390 ~67 ~65 ~391 ~67 ~65 grass_block
fill ~392 ~60 ~65 ~395 ~62 ~65 stone
fill ~392 ~63 ~65 ~395 ~65 ~65 dirt
fill ~392 ~66 ~65 ~395 ~66 ~65 grass_block
fill ~396 ~60 ~65 ~399 ~63 ~65 stone
fill ~396 ~64 ~65 ~399 ~66 ~65 dirt
fill ~396 ~67 ~65 ~399 ~67 ~65 grass_block
fill ~384 ~60 ~66 ~387 ~65 ~66 stone
fill ~384 ~66 ~66 ~387 ~68 ~66 dirt
fill ~384 ~69 ~66 ~387 ~69 ~66 grass_block
fill ~388 ~60 ~66 ~390 ~64 ~66 stone
fill ~388 ~65 ~66 ~390 ~67 ~66 dirt
fill ~388 ~68 ~66 ~390 ~68 ~66 grass_block
fill ~391 ~60 ~66 ~392 ~63 ~66 stone
fill ~391 ~64 ~66 ~392 ~66 ~66 dirt
fill ~391 ~67 ~66 ~392 ~67 ~66 grass_block
fill ~393 ~60 ~66 ~396 ~62 ~66 stone
fill ~393 ~63 ~66 ~396 ~65 ~66 dirt
fill ~393 ~66 ~66 ~396 ~66 ~66 grass_block
fill ~397 ~60 ~66 ~399 ~63 ~66 stone
fill ~397 ~64 ~66 ~399 ~66 ~66 dirt
fill ~397 ~67 ~66 ~399 ~67 ~66 grass_block
fill ~384 ~60 ~67 ~384 ~66 ~67 stone
fill ~384 ~67 ~67 ~384 ~69 ~67 dirt
fill ~384 ~70 ~67 ~384 ~70 ~67 grass_block
fill ~385 ~60 ~67 ~387 ~65 ~67 stone
fill ~385 ~66 ~67 ~387 ~68 ~67 dirt
fill ~385 ~69 ~67 ~387 ~69 ~67 grass_block
fill ~388 ~60 ~67 ~391 ~64 ~67 stone
fill ~388 ~65 ~67 ~391 ~67 ~67 dirt
fill ~388 ~68 ~67 ~391 ~68 ~67 grass_block
fill ~392 ~60 ~67 ~392 ~63 ~67 stone
fill ~392 ~64 ~67 ~392 ~66 ~67 dirt
fill ~392 ~67 ~67 ~392 ~67 ~67 grass_block
fill ~393 ~60 ~67 ~397 ~62 ~67 stone
fill ~393 ~63 ~67 ~397 ~65 ~67 dirt
fill ~393 ~66 ~67 ~397 ~66 ~67 grass_block
fill ~398 ~60 ~67 ~399 ~63 ~67 stone
fill ~398 ~64 ~67 ~399 ~66 ~67 dirt
fill ~398 ~67 ~67 ~399 ~67 ~67 grass_block
fill ~384 ~60 ~68 ~388 ~65 ~68 stone
fill ~384 ~66 ~68 ~388 ~68 ~68 dirt
fill ~384 ~69 ~68 ~388 ~69 ~68 grass_block
fill ~389 ~60 ~68 ~392 ~64 ~68 stone
fill ~389 ~65 ~68 ~392 ~67 ~68 dirt
fill ~389 ~68 ~68 ~392 ~68 ~68 grass_block
fill ~393 ~60 ~68 ~393 ~63 ~68 stone
fill ~393 ~64 ~68 ~393 ~66 ~68 dirt
fill ~393 ~67 ~68 ~393 ~67 ~68 grass_block
fill ~394 ~60 ~68 ~398 ~62 ~68 stone
fill ~394 ~63 ~68 ~398 ~65 ~68 dirt
fill ~394 ~66 ~68 ~398 ~66 ~68 grass_block
fill ~399 ~60 ~68 ~399 ~63 ~68 stone
fill ~399 ~64 ~68 ~399 ~66 ~68 dirt
fill ~399 ~67 ~68 ~399 ~67 ~68 grass_block
fill ~384 ~60 ~69 ~390 ~65 ~69 stone
fill ~384 ~66 ~69 ~390 ~68 ~69 dirt
fill ~384 ~69 ~69 ~390 ~69 ~69 grass_block
fill ~391 ~60 ~69 ~392 ~64 ~69 stone
fill ~391 ~65 ~69 ~392 ~67 ~69 dirt
fill ~391 ~68 ~69 ~392 ~68 ~69 grass_block
fill ~393 ~60 ~69 ~395 ~63 ~69 stone
fill ~393 ~64 ~69 ~395 ~66 ~69 dirt
fill ~393 ~67 ~69 ~395 ~67 ~69 grass_block
fill ~396 ~60 ~69 ~399 ~62 ~69 stone
fill ~396 ~63 ~69 ~399 ~65 ~69 dirt
fill ~396 ~66 ~69 ~399 ~66 ~69 grass_block
fill ~384 ~60 ~70 ~390 ~65 ~70 stone
fill ~384 ~66 ~70 ~390 ~68 ~70 dirt
fill ~384 ~69 ~70 ~390 ~69 ~70 grass_block
fill ~391 ~60 ~70 ~393 ~64 ~70 stone
fill ~391 ~65 ~70 ~393 ~67 ~70 dirt
fill ~391 ~68 ~70 ~393 ~68 ~70 grass_block
fill ~394 ~60 ~70 ~395 ~63 ~70 stone
fill ~394 ~64 ~70 ~395 ~66 ~70 dirt
fill ~394 ~67 ~70 ~395 ~67 ~70 grass_block
fill ~396 ~60 ~70 ~399 ~62 ~70 stone
fill ~396 ~63 ~70 ~399 ~65 ~70 dirt
fill ~396 ~66 ~70 ~399 ~66 ~70 grass_block
fill ~384 ~60 ~71 ~391 ~65 ~71 stone
fill ~384 ~66 ~71 ~391 ~68 ~71 dirt
fill ~384 ~69 ~71 ~391 ~69 ~71 grass_block
fill ~392 ~60 ~71 ~394 ~64 ~71 stone
fill ~392 ~65 ~71 ~394 ~67 ~71 dirt
fill ~392 ~68 ~71 ~394 ~68 ~71 grass_block
fill ~395 ~60 ~71 ~397 ~63 ~71 stone
fill ~395 ~64 ~71 ~397 ~66 ~71 dirt
fill ~395 ~67 ~71 ~397 ~67 ~71 grass_block
fill ~398 ~60 ~71 ~399 ~62 ~71 stone
fill ~398 ~63 ~71 ~399 ~65 ~71 dirt
fill ~398 ~66 ~71 ~399 ~66 ~71 grass_block
fill ~384 ~60 ~72 ~386 ~64 ~72 stone
fill ~384 ~65 ~72 ~386 ~67 ~72 dirt
fill ~384 ~68 ~72 ~386 ~68 ~72 grass_block
fill ~387 ~60 ~72 ~392 ~65 ~72 stone
fill ~387 ~66 ~72 ~392 ~68 ~72 dirt
fill ~387 ~69 ~72 ~392 ~69 ~72 grass_block
fill ~393 ~60 ~72 ~395 ~64 ~72 stone
fill ~393 ~65 ~72 ~395 ~67 ~72 dirt
fill ~393 ~68 ~72 ~395 ~68 ~72 grass_block
fill ~396 ~60 ~72 ~398 ~63 ~72 stone
fill ~396 ~64 ~72 ~398 ~66 ~72 dirt
fill ~396 ~67 ~72 ~398 ~67 ~72 grass_block
fill ~399 ~60 ~72 ~399 ~62 ~72 stone
fill ~399 ~63 ~72 ~399 ~65 ~72 dirt
fill ~399 ~66 ~72 ~399 ~66 ~72 grass_block
fill ~384 ~60 ~73 ~388 ~64 ~73 stone
fill ~384 ~65 ~73 ~388 ~67 ~73 dirt
fill ~384 ~68 ~73 ~388 ~68 ~73 grass_block
fill ~389 ~60 ~73 ~393 ~65 ~73 stone
fill ~389 ~66 ~73 ~393 ~68 ~73 dirt
fill ~389 ~69 ~73 ~393 ~69 ~73 grass_block
fill ~394 ~60 ~73 ~396 ~64 ~73 stone
fill ~394 ~65 ~73 ~396 ~67 ~73 dirt
fill ~394 ~68 ~73 ~396 ~68 ~73 grass_block
fill ~397 ~60 ~73 ~398 ~63 ~73 stone
fill ~397 ~64 ~73 ~398 ~66 ~73 dirt
fill ~397 ~67 ~73 ~398 ~67 ~73 grass_block
fill ~399 ~60 ~73 ~399 ~62 ~73 stone
fill ~399 ~63 ~73 ~399 ~65 ~73 dirt
fill ~399 ~66 ~73 ~399 ~66 ~73 grass_block
fill ~384 ~60 ~74 ~390 ~64 ~74 stone
fill ~384 ~65 ~74 ~390 ~67 ~74 dirt
fill ~384 ~68 ~74 ~390 ~68 ~74 grass_block
fill ~391 ~60 ~74 ~393 ~65 ~74 stone
fill ~391 ~66 ~74 ~393 ~68 ~74 dirt
fill ~391 ~69 ~74 ~393 ~69 ~74 grass_block
fill ~394 ~60 ~74 ~397 ~64 ~74 stone
fill ~394 ~65 ~74 ~397 ~67 ~74 dirt
fill ~394 ~68 ~74 ~397 ~68 ~74 grass_block
fill ~398 ~60 ~74 ~399 ~63 ~74 stone
fill ~398 ~64 ~74 ~399 ~66 ~74 dirt
fill ~398 ~67 ~74 ~399 ~67 ~74 grass_block
fill ~384 ~60 ~75 ~385 ~64 ~75 stone
fill ~384 ~65 ~75 ~385 ~67 ~75 dirt
fill ~384 ~68 ~75 ~385 ~68 ~75 grass_block
fill ~386 ~60 ~75 ~388 ~63 ~75 stone
fill ~386 ~64 ~75 ~388 ~66 ~75 dirt
fill ~386 ~67 ~75 ~388 ~67 ~75 grass_block
fill ~389 ~60 ~75 ~398 ~64 ~75 stone
fill ~389 ~65 ~75 ~398 ~67 ~75 dirt
fill ~389 ~68 ~75 ~398 ~68 ~75 grass_block
fill ~399 ~60 ~75 ~399 ~63 ~75 stone
fill ~399 ~64 ~75 ~399 ~66 ~75 dirt
fill ~399 ~67 ~75 ~399 ~67 ~75 grass_block
fill ~384 ~60 ~76 ~390 ~63 ~76 stone
fill ~384 ~64 ~76 ~390 ~66 ~76 dirt
fill ~384 ~67 ~76 ~390 ~67 ~76 grass_block
fill ~391 ~60 ~76 ~398 ~64 ~76 stone
fill ~391 ~65 ~76 ~398 ~67 ~76 dirt
fill ~391 ~68 ~76 ~398 ~68 ~76 grass_block
fill ~399 ~60 ~76 ~399 ~63 ~76 stone
fill ~399 ~64 ~76 ~399 ~66 ~76 dirt
fill ~399 ~67 ~76 ~399 ~67 ~76 grass_block
fill ~384 ~60 ~77 ~392 ~63 ~77 stone
fill ~384 ~64 ~77 ~392 ~66 ~77 dirt
fill ~384 ~67 ~77 ~392 ~67 ~77 grass_block
fill ~393 ~60 ~77 ~399 ~64 ~77 stone
fill ~393 ~65 ~77 ~399 ~67 ~77 dirt
fill ~393 ~68 ~77 ~399 ~68 ~77 grass_block
fill ~384 ~60 ~78 ~386 ~63 ~78 stone
fill ~384 ~64 ~78 ~386 ~66 ~78 dirt
fill ~384 ~67 ~78 ~386 ~67 ~78 grass_block
fill ~387 ~60 ~78 ~387 ~62 ~78 stone
fill ~387 ~63 ~78 ~387 ~65 ~78 dirt
fill ~387 ~66 ~78 ~387 ~66 ~78 grass_block
fill ~388 ~60 ~78 ~398 ~63 ~78 stone
fill ~388 ~64 ~78 ~398 ~66 ~78 dirt
fill ~388 ~67 ~78 ~398 ~67 ~78 grass_block
fill ~399 ~60 ~78 ~399 ~64 ~78 stone
fill ~399 ~65 ~78 ~399 ~67 ~78 dirt
fill ~399 ~68 ~78 ~399 ~68 ~78 grass_block
fill ~384 ~60 ~79 ~384 ~62 ~79 stone
fill ~384 ~63 ~79 ~384 ~65 ~79 dirt
fill ~384 ~66 ~79 ~384 ~66 ~79 grass_block
fill ~385 ~60 ~79 ~385 ~63 ~79 stone
fill ~385 ~64 ~79 ~385 ~66 ~79 dirt
fill ~385 ~67 ~79 ~385 ~67 ~79 grass_block
fill ~386 ~60 ~79 ~387 ~62 ~79 stone
fill ~386 ~63 ~79 ~387 ~65 ~79 dirt
fill ~386 ~66 ~79 ~387 ~66 ~79 grass_block
fill ~388 ~60 ~79 ~399 ~63 ~79 stone
fill ~388 ~64 ~79 ~399 ~66 ~79 dirt
fill ~388 ~67 ~79 ~399 ~67 ~79 grass_block