fill ~352 ~60 ~128 ~353 ~61 ~128 stone
fill ~352 ~62 ~128 ~353 ~64 ~128 dirt
fill ~352 ~65 ~128 ~353 ~65 ~128 grass_block
fill ~354 ~60 ~128 ~363 ~60 ~128 stone
fill ~354 ~61 ~128 ~363 ~63 ~128 dirt
fill ~354 ~64 ~128 ~363 ~64 ~128 grass_block
fill ~364 ~60 ~128 ~367 ~61 ~128 stone
fill ~364 ~62 ~128 ~367 ~64 ~128 dirt
fill ~364 ~65 ~128 ~367 ~65 ~128 grass_block
fill ~352 ~60 ~129 ~355 ~61 ~129 stone
fill ~352 ~62 ~129 ~355 ~64 ~129 dirt
fill ~352 ~65 ~129 ~355 ~65 ~129 grass_block
fill ~356 ~60 ~129 ~364 ~60 ~129 stone
fill ~356 ~61 ~129 ~364 ~63 ~129 dirt
fill ~356 ~64 ~129 ~364 ~64 ~129 grass_block
fill ~365 ~60 ~129 ~367 ~61 ~129 stone
fill ~365 ~62 ~129 ~367 ~64 ~129 dirt
fill ~365 ~65 ~129 ~367 ~65 ~129 grass_block
fill ~352 ~60 ~130 ~359 ~61 ~130 stone
fill ~352 ~62 ~130 ~359 ~64 ~130 dirt
fill ~352 ~65 ~130 ~359 ~65 ~130 grass_block
fill ~360 ~60 ~130 ~366 ~60 ~130 stone
fill ~360 ~61 ~130 ~366 ~63 ~130 dirt
fill ~360 ~64 ~130 ~366 ~64 ~130 grass_block
fill ~367 ~60 ~130 ~367 ~61 ~130 stone
fill ~367 ~62 ~130 ~367 ~64 ~130 dirt
fill ~367 ~65 ~130 ~367 ~65 ~130 grass_block
fill ~352 ~60 ~131 ~355 ~61 ~131 stone
fill ~352 ~62 ~131 ~355 ~64 ~131 dirt
fill ~352 ~65 ~131 ~355 ~65 ~131 grass_block
fill ~356 ~60 ~131 ~357 ~60 ~131 stone
fill ~356 ~61 ~131 ~357 ~63 ~131 dirt
fill ~356 ~64 ~131 ~357 ~64 ~131 grass_block
fill ~358 ~60 ~131 ~359 ~61 ~131 stone
fill ~358 ~62 ~131 ~359 ~64 ~131 dirt
fill ~358 ~65 ~131 ~359 ~65 ~131 grass_block
fill ~360 ~60 ~131 ~367 ~60 ~131 stone
fill ~360 ~61 ~131 ~367 ~63 ~131 dirt
fill ~360 ~64 ~131 ~367 ~64 ~131 grass_block
fill ~352 ~60 ~132 ~361 ~61 ~132 stone
fill ~352 ~62 ~132 ~361 ~64 ~132 dirt
fill ~352 ~65 ~132 ~361 ~65 ~132 grass_block
fill ~362 ~60 ~132 ~367 ~60 ~132 stone
fill ~362 ~61 ~132 ~367 ~63 ~132 dirt
fill ~362 ~64 ~132 ~367 ~64 ~132 grass_block
fill ~352 ~60 ~133 ~363 ~61 ~133 stone
fill ~352 ~62 ~133 ~363 ~64 ~133 dirt
fill ~352 ~65 ~133 ~363 ~65 ~133 grass_block
fill ~364 ~60 ~133 ~367 ~60 ~133 stone
fill ~364 ~61 ~133 ~367 ~63 ~133 dirt
fill ~364 ~64 ~133 ~367 ~64 ~133 grass_block
fill ~352 ~60 ~134 ~359 ~62 ~134 stone
fill ~352 ~63 ~134 ~359 ~65 ~134 dirt
fill ~352 ~66 ~134 ~359 ~66 ~134 grass_block
fill ~360 ~60 ~134 ~364 ~61 ~134 stone
fill ~360 ~62 ~134 ~364 ~64 ~134 dirt
fill ~360 ~65 ~134 ~364 ~65 ~134 grass_block
fill ~365 ~60 ~134 ~367 ~60 ~134 stone
fill ~365 ~61 ~134 ~367 ~63 ~134 dirt
fill ~365 ~64 ~134 ~367 ~64 ~134 grass_block
fill ~352 ~60 ~135 ~362 ~62 ~135 stone
fill ~352 ~63 ~135 ~362 ~65 ~135 dirt
fill ~352 ~66 ~135 ~362 ~66 ~135 grass_block
fill ~363 ~60 ~135 ~366 ~61 ~135 stone
fill ~363 ~62 ~135 ~366 ~64 ~135 dirt
fill ~363 ~65 ~135 ~366 ~65 ~135 grass_block
fill ~367 ~60 ~135 ~367 ~60 ~135 stone
fill ~367 ~61 ~135 ~367 ~63 ~135 dirt
fill ~367 ~64 ~135 ~367 ~64 ~135 grass_block
fill ~352 ~60 ~136 ~364 ~62 ~136 stone
fill ~352 ~63 ~136 ~364 ~65 ~136 dirt
fill ~352 ~66 ~136 ~364 ~66 ~136 grass_block
fill ~365 ~60 ~136 ~367 ~61 ~136 stone
fill ~365 ~62 ~136 ~367 ~64 ~136 dirt
fill ~365 ~65 ~136 ~367 ~65 ~136 grass_block
fill ~352 ~60 ~137 ~352 ~63 ~137 stone
fill ~352 ~64 ~137 ~352 ~66 ~137 dirt
fill ~352 ~67 ~137 ~352 ~67 ~137 grass_block
fill ~353 ~60 ~137 ~366 ~62 ~137 stone
fill ~353 ~63 ~137 ~366 ~65 ~137 dirt
fill ~353 ~66 ~137 ~366 ~66 ~137 grass_block
fill ~367 ~60 ~137 ~367 ~61 ~137 stone
fill ~367 ~62 ~137 ~367 ~64 ~137 dirt
fill ~367 ~65 ~137 ~367 ~65 ~137 grass_block
fill ~352 ~60 ~138 ~352 ~63 ~138 stone
fill ~352 ~64 ~138 ~352 ~66 ~138 dirt
fill ~352 ~67 ~138 ~352 ~67 ~138 grass_block
fill ~353 ~60 ~138 ~367 ~62 ~138 stone
fill ~353 ~63 ~138 ~367 ~65 ~138 dirt
fill ~353 ~66 ~138 ~367 ~66 ~138 grass_block
fill ~352 ~60 ~139 ~352 ~63 ~139 stone
fill ~352 ~64 ~139 ~352 ~66 ~139 dirt
fill ~352 ~67 ~139 ~352 ~67 ~139 grass_block
fill ~353 ~60 ~139 ~354 ~62 ~139 stone
fill ~353 ~63 ~139 ~354 ~65 ~139 dirt
fill ~353 ~66 ~139 ~354 ~66 ~139 grass_block
fill ~355 ~60 ~139 ~355 ~63 ~139 stone
fill ~355 ~64 ~139 ~355 ~66 ~139 dirt
fill ~355 ~67 ~139 ~355 ~67 ~139 grass_block
fill ~356 ~60 ~139 ~367 ~62 ~139 stone
fill ~356 ~63 ~139 ~367 ~65 ~139 dirt
fill ~356 ~66 ~139 ~367 ~66 ~139 grass_block
fill ~352 ~60 ~140 ~359 ~62 ~140 stone
fill ~352 ~63 ~140 ~359 ~65 ~140 dirt
fill ~352 ~66 ~140 ~359 ~66 ~140 grass_block
fill ~360 ~60 ~140 ~360 ~63 ~140 stone
fill ~360 ~64 ~140 ~360 ~66 ~140 dirt
fill ~360 ~67 ~140 ~360 ~67 ~140 grass_block
fill ~361 ~60 ~140 ~367 ~62 ~140 stone
fill ~361 ~63 ~140 ~367 ~65 ~140 dirt
fill ~361 ~66 ~140 ~367 ~66 ~140 grass_block
fill ~352 ~60 ~141 ~367 ~62 ~141 stone
fill ~352 ~63 ~141 ~367 ~65 ~141 dirt
fill ~352 ~66 ~141 ~367 ~66 ~141 grass_block
fill ~352 ~60 ~142 ~352 ~62 ~142 stone
fill ~352 ~63 ~142 ~352 ~65 ~142 dirt
fill ~352 ~66 ~142 ~352 ~66 ~142 grass_block
fill ~353 ~60 ~142 ~353 ~63 ~142 stone
fill ~353 ~64 ~142 ~353 ~66 ~142 dirt
fill ~353 ~67 ~142 ~353 ~67 ~142 grass_block
fill ~354 ~60 ~142 ~367 ~62 ~142 stone
fill ~354 ~63 ~142 ~367 ~65 ~142 dirt
fill ~354 ~66 ~142 ~367 ~66 ~142 grass_block
fill ~352 ~60 ~143 ~352 ~63 ~143 stone
fill ~352 ~64 ~143 ~352 ~66 ~143 dirt
fill ~352 ~67 ~143 ~352 ~67 ~143 grass_block
fill ~353 ~60 ~143 ~367 ~62 ~143 stone
fill ~353 ~63 ~143 ~367 ~65 ~143 dirt
fill ~353 ~66 ~143 ~367 ~66 ~143 grass_block