fill ~128 ~60 ~0 ~139 ~62 ~0 stone
fill ~128 ~63 ~0 ~139 ~65 ~0 dirt
fill ~128 ~66 ~0 ~139 ~66 ~0 grass_block
fill ~140 ~60 ~0 ~143 ~61 ~0 stone
fill ~140 ~62 ~0 ~143 ~64 ~0 dirt
fill ~140 ~65 ~0 ~143 ~65 ~0 grass_block
fill ~128 ~60 ~1 ~129 ~63 ~1 stone
fill ~128 ~64 ~1 ~129 ~66 ~1 dirt
fill ~128 ~67 ~1 ~129 ~67 ~1 grass_block
fill ~130 ~60 ~1 ~142 ~62 ~1 stone
fill ~130 ~63 ~1 ~142 ~65 ~1 dirt
fill ~130 ~66 ~1 ~142 ~66 ~1 grass_block
fill ~143 ~60 ~1 ~143 ~61 ~1 stone
fill ~143 ~62 ~1 ~143 ~64 ~1 dirt
fill ~143 ~65 ~1 ~143 ~65 ~1 grass_block
fill ~128 ~60 ~2 ~141 ~63 ~2 stone
fill ~128 ~64 ~2 ~141 ~66 ~2 dirt
fill ~128 ~67 ~2 ~141 ~67 ~2 grass_block
fill ~142 ~60 ~2 ~143 ~62 ~2 stone
fill ~142 ~63 ~2 ~143 ~65 ~2 dirt
fill ~142 ~66 ~2 ~143 ~66 ~2 grass_block
fill ~128 ~60 ~3 ~129 ~64 ~3 stone
fill ~128 ~65 ~3 ~129 ~67 ~3 dirt
fill ~128 ~68 ~3 ~129 ~68 ~3 grass_block
fill ~130 ~60 ~3 ~133 ~63 ~3 stone
fill ~130 ~64 ~3 ~133 ~66 ~3 dirt
fill ~130 ~67 ~3 ~133 ~67 ~3 grass_block
fill ~134 ~60 ~3 ~139 ~64 ~3 stone
fill ~134 ~65 ~3 ~139 ~67 ~3 dirt
fill ~134 ~68 ~3 ~139 ~68 ~3 grass_block
fill ~140 ~60 ~3 ~142 ~63 ~3 stone
fill ~140 ~64 ~3 ~142 ~66 ~3 dirt
fill ~140 ~67 ~3 ~142 ~67 ~3 grass_block
fill ~143 ~60 ~3 ~143 ~62 ~3 stone
fill ~143 ~63 ~3 ~143 ~65 ~3 dirt
fill ~143 ~66 ~3 ~143 ~66 ~3 grass_block
fill ~128 ~60 ~4 ~131 ~65 ~4 stone
fill ~128 ~66 ~4 ~131 ~68 ~4 dirt
fill ~128 ~69 ~4 ~131 ~69 ~4 grass_block
fill ~132 ~60 ~4 ~133 ~64 ~4 stone
fill ~132 ~65 ~4 ~133 ~67 ~4 dirt
fill ~132 ~68 ~4 ~133 ~68 ~4 grass_block
fill ~134 ~60 ~4 ~137 ~65 ~4 stone
fill ~134 ~66 ~4 ~137 ~68 ~4 dirt
fill ~134 ~69 ~4 ~137 ~69 ~4 grass_block
fill ~138 ~60 ~4 ~140 ~64 ~4 stone
fill ~138 ~65 ~4 ~140 ~67 ~4 dirt
fill ~138 ~68 ~4 ~140 ~68 ~4 grass_block
fill ~141 ~60 ~4 ~143 ~63 ~4 stone
fill ~141 ~64 ~4 ~143 ~66 ~4 dirt
fill ~141 ~67 ~4 ~143 ~67 ~4 grass_block
fill ~128 ~60 ~5 ~139 ~65 ~5 stone
fill ~128 ~66 ~5 ~139 ~68 ~5 dirt
fill ~128 ~69 ~5 ~139 ~69 ~5 grass_block
fill ~140 ~60 ~5 ~143 ~64 ~5 stone
fill ~140 ~65 ~5 ~143 ~67 ~5 dirt
fill ~140 ~68 ~5 ~143 ~68 ~5 grass_block
fill ~128 ~60 ~6 ~143 ~65 ~6 stone
fill ~128 ~66 ~6 ~143 ~68 ~6 dirt
fill ~128 ~69 ~6 ~143 ~69 ~6 grass_block
fill ~128 ~60 ~7 ~131 ~64 ~7 stone
fill ~128 ~65 ~7 ~131 ~67 ~7 dirt
fill ~128 ~68 ~7 ~131 ~68 ~7 grass_block
fill ~132 ~60 ~7 ~143 ~65 ~7 stone
fill ~132 ~66 ~7 ~143 ~68 ~7 dirt
fill ~132 ~69 ~7 ~143 ~69 ~7 grass_block
fill ~128 ~60 ~8 ~133 ~64 ~8 stone
fill ~128 ~65 ~8 ~133 ~67 ~8 dirt
fill ~128 ~68 ~8 ~133 ~68 ~8 grass_block
fill ~134 ~60 ~8 ~143 ~65 ~8 stone
fill ~134 ~66 ~8 ~143 ~68 ~8 dirt
fill ~134 ~69 ~8 ~143 ~69 ~8 grass_block
fill ~128 ~60 ~9 ~135 ~64 ~9 stone
fill ~128 ~65 ~9 ~135 ~67 ~9 dirt
fill ~128 ~68 ~9 ~135 ~68 ~9 grass_block
fill ~136 ~60 ~9 ~143 ~65 ~9 stone
fill ~136 ~66 ~9 ~143 ~68 ~9 dirt
fill ~136 ~69 ~9 ~143 ~69 ~9 grass_block
fill ~128 ~60 ~10 ~139 ~64 ~10 stone
fill ~128 ~65 ~10 ~139 ~67 ~10 dirt
fill ~128 ~68 ~10 ~139 ~68 ~10 grass_block
fill ~140 ~60 ~10 ~143 ~65 ~10 stone
fill ~140 ~66 ~10 ~143 ~68 ~10 dirt
fill ~140 ~69 ~10 ~143 ~69 ~10 grass_block
fill ~128 ~60 ~11 ~142 ~64 ~11 stone
fill ~128 ~65 ~11 ~142 ~67 ~11 dirt
fill ~128 ~68 ~11 ~142 ~68 ~11 grass_block
fill ~143 ~60 ~11 ~143 ~65 ~11 stone
fill ~143 ~66 ~11 ~143 ~68 ~11 dirt
fill ~143 ~69 ~11 ~143 ~69 ~11 grass_block
fill ~128 ~60 ~12 ~133 ~63 ~12 stone
fill ~128 ~64 ~12 ~133 ~66 ~12 dirt
fill ~128 ~67 ~12 ~133 ~67 ~12 grass_block
fill ~134 ~60 ~12 ~143 ~64 ~12 stone
fill ~134 ~65 ~12 ~143 ~67 ~12 dirt
fill ~134 ~68 ~12 ~143 ~68 ~12 grass_block
fill ~128 ~60 ~13 ~137 ~63 ~13 stone
fill ~128 ~64 ~13 ~137 ~66 ~13 dirt
fill ~128 ~67 ~13 ~137 ~67 ~13 grass_block
fill ~138 ~60 ~13 ~143 ~64 ~13 stone
fill ~138 ~65 ~13 ~143 ~67 ~13 dirt
fill ~138 ~68 ~13 ~143 ~68 ~13 grass_block
fill ~128 ~60 ~14 ~128 ~64 ~14 stone
fill ~128 ~65 ~14 ~128 ~67 ~14 dirt
fill ~128 ~68 ~14 ~128 ~68 ~14 grass_block
fill ~129 ~60 ~14 ~139 ~63 ~14 stone
fill ~129 ~64 ~14 ~139 ~66 ~14 dirt
fill ~129 ~67 ~14 ~139 ~67 ~14 grass_block
fill ~140 ~60 ~14 ~143 ~64 ~14 stone
fill ~140 ~65 ~14 ~143 ~67 ~14 dirt
fill ~140 ~68 ~14 ~143 ~68 ~14 grass_block
fill ~128 ~60 ~15 ~128 ~65 ~15 stone
fill ~128 ~66 ~15 ~128 ~68 ~15 dirt
fill ~128 ~69 ~15 ~128 ~69 ~15 grass_block
fill ~129 ~60 ~15 ~133 ~64 ~15 stone
fill ~129 ~65 ~15 ~133 ~67 ~15 dirt
fill ~129 ~68 ~15 ~133 ~68 ~15 grass_block
fill ~134 ~60 ~15 ~141 ~63 ~15 stone
fill ~134 ~64 ~15 ~141 ~66 ~15 dirt
fill ~134 ~67 ~15 ~141 ~67 ~15 grass_block
fill ~142 ~60 ~15 ~143 ~64 ~15 stone
fill ~142 ~65 ~15 ~143 ~67 ~15 dirt
fill ~142 ~68 ~15 ~143 ~68 ~15 grass_block