fill ~48 ~60 ~16 ~50 ~64 ~16 stone
fill ~48 ~65 ~16 ~50 ~67 ~16 dirt
fill ~48 ~68 ~16 ~50 ~68 ~16 grass_block
fill ~51 ~60 ~16 ~55 ~63 ~16 stone
fill ~51 ~64 ~16 ~55 ~66 ~16 dirt
fill ~51 ~67 ~16 ~55 ~67 ~16 grass_block
fill ~56 ~60 ~16 ~60 ~64 ~16 stone
fill ~56 ~65 ~16 ~60 ~67 ~16 dirt
fill ~56 ~68 ~16 ~60 ~68 ~16 grass_block
fill ~61 ~60 ~16 ~63 ~65 ~16 stone
fill ~61 ~66 ~16 ~63 ~68 ~16 dirt
fill ~61 ~69 ~16 ~63 ~69 ~16 grass_block
fill ~48 ~60 ~17 ~51 ~64 ~17 stone
fill ~48 ~65 ~17 ~51 ~67 ~17 dirt
fill ~48 ~68 ~17 ~51 ~68 ~17 grass_block
fill ~52 ~60 ~17 ~56 ~63 ~17 stone
fill ~52 ~64 ~17 ~56 ~66 ~17 dirt
fill ~52 ~67 ~17 ~56 ~67 ~17 grass_block
fill ~57 ~60 ~17 ~62 ~64 ~17 stone
fill ~57 ~65 ~17 ~62 ~67 ~17 dirt
fill ~57 ~68 ~17 ~62 ~68 ~17 grass_block
fill ~63 ~60 ~17 ~63 ~65 ~17 stone
fill ~63 ~66 ~17 ~63 ~68 ~17 dirt
fill ~63 ~69 ~17 ~63 ~69 ~17 grass_block
fill ~48 ~60 ~18 ~49 ~65 ~18 stone
fill ~48 ~66 ~18 ~49 ~68 ~18 dirt
fill ~48 ~69 ~18 ~49 ~69 ~18 grass_block
fill ~50 ~60 ~18 ~52 ~64 ~18 stone
fill ~50 ~65 ~18 ~52 ~67 ~18 dirt
fill ~50 ~68 ~18 ~52 ~68 ~18 grass_block
fill ~53 ~60 ~18 ~58 ~63 ~18 stone
fill ~53 ~64 ~18 ~58 ~66 ~18 dirt
fill ~53 ~67 ~18 ~58 ~67 ~18 grass_block
fill ~59 ~60 ~18 ~63 ~64 ~18 stone
fill ~59 ~65 ~18 ~63 ~67 ~18 dirt
fill ~59 ~68 ~18 ~63 ~68 ~18 grass_block
fill ~48 ~60 ~19 ~50 ~65 ~19 stone
fill ~48 ~66 ~19 ~50 ~68 ~19 dirt
fill ~48 ~69 ~19 ~50 ~69 ~19 grass_block
fill ~51 ~60 ~19 ~53 ~64 ~19 stone
fill ~51 ~65 ~19 ~53 ~67 ~19 dirt
fill ~51 ~68 ~19 ~53 ~68 ~19 grass_block
fill ~54 ~60 ~19 ~60 ~63 ~19 stone
fill ~54 ~64 ~19 ~60 ~66 ~19 dirt
fill ~54 ~67 ~19 ~60 ~67 ~19 grass_block
fill ~61 ~60 ~19 ~63 ~64 ~19 stone
fill ~61 ~65 ~19 ~63 ~67 ~19 dirt
fill ~61 ~68 ~19 ~63 ~68 ~19 grass_block
fill ~48 ~60 ~20 ~48 ~66 ~20 stone
fill ~48 ~67 ~20 ~48 ~69 ~20 dirt
fill ~48 ~70 ~20 ~48 ~70 ~20 grass_block
fill ~49 ~60 ~20 ~51 ~65 ~20 stone
fill ~49 ~66 ~20 ~51 ~68 ~20 dirt
fill ~49 ~69 ~20 ~51 ~69 ~20 grass_block
fill ~52 ~60 ~20 ~54 ~64 ~20 stone
fill ~52 ~65 ~20 ~54 ~67 ~20 dirt
fill ~52 ~68 ~20 ~54 ~68 ~20 grass_block
fill ~55 ~60 ~20 ~62 ~63 ~20 stone
fill ~55 ~64 ~20 ~62 ~66 ~20 dirt
fill ~55 ~67 ~20 ~62 ~67 ~20 grass_block
fill ~63 ~60 ~20 ~63 ~64 ~20 stone
fill ~63 ~65 ~20 ~63 ~67 ~20 dirt
fill ~63 ~68 ~20 ~63 ~68 ~20 grass_block
fill ~48 ~60 ~21 ~48 ~67 ~21 stone
fill ~48 ~68 ~21 ~48 ~70 ~21 dirt
fill ~48 ~71 ~21 ~48 ~71 ~21 grass_block
fill ~49 ~60 ~21 ~49 ~66 ~21 stone
fill ~49 ~67 ~21 ~49 ~69 ~21 dirt
fill ~49 ~70 ~21 ~49 ~70 ~21 grass_block
fill ~50 ~60 ~21 ~52 ~65 ~21 stone
fill ~50 ~66 ~21 ~52 ~68 ~21 dirt
fill ~50 ~69 ~21 ~52 ~69 ~21 grass_block
fill ~53 ~60 ~21 ~56 ~64 ~21 stone
fill ~53 ~65 ~21 ~56 ~67 ~21 dirt
fill ~53 ~68 ~21 ~56 ~68 ~21 grass_block
fill ~57 ~60 ~21 ~63 ~63 ~21 stone
fill ~57 ~64 ~21 ~63 ~66 ~21 dirt
fill ~57 ~67 ~21 ~63 ~67 ~21 grass_block
fill ~48 ~60 ~22 ~48 ~67 ~22 stone
fill ~48 ~68 ~22 ~48 ~70 ~22 dirt
fill ~48 ~71 ~22 ~48 ~71 ~22 grass_block
fill ~49 ~60 ~22 ~51 ~66 ~22 stone
fill ~49 ~67 ~22 ~51 ~69 ~22 dirt
fill ~49 ~70 ~22 ~51 ~70 ~22 grass_block
fill ~52 ~60 ~22 ~54 ~65 ~22 stone
fill ~52 ~66 ~22 ~54 ~68 ~22 dirt
fill ~52 ~69 ~22 ~54 ~69 ~22 grass_block
fill ~55 ~60 ~22 ~58 ~64 ~22 stone
fill ~55 ~65 ~22 ~58 ~67 ~22 dirt
fill ~55 ~68 ~22 ~58 ~68 ~22 grass_block
fill ~59 ~60 ~22 ~63 ~63 ~22 stone
fill ~59 ~64 ~22 ~63 ~66 ~22 dirt
fill ~59 ~67 ~22 ~63 ~67 ~22 grass_block
fill ~48 ~60 ~23 ~51 ~67 ~23 stone
fill ~48 ~68 ~23 ~51 ~70 ~23 dirt
fill ~48 ~71 ~23 ~51 ~71 ~23 grass_block
fill ~52 ~60 ~23 ~53 ~66 ~23 stone
fill ~52 ~67 ~23 ~53 ~69 ~23 dirt
fill ~52 ~70 ~23 ~53 ~70 ~23 grass_block
fill ~54 ~60 ~23 ~56 ~65 ~23 stone
fill ~54 ~66 ~23 ~56 ~68 ~23 dirt
fill ~54 ~69 ~23 ~56 ~69 ~23 grass_block
fill ~57 ~60 ~23 ~58 ~64 ~23 stone
fill ~57 ~65 ~23 ~58 ~67 ~23 dirt
fill ~57 ~68 ~23 ~58 ~68 ~23 grass_block
fill ~59 ~60 ~23 ~63 ~63 ~23 stone
fill ~59 ~64 ~23 ~63 ~66 ~23 dirt
fill ~59 ~67 ~23 ~63 ~67 ~23 grass_block
fill ~48 ~60 ~24 ~49 ~68 ~24 stone
fill ~48 ~69 ~24 ~49 ~71 ~24 dirt
fill ~48 ~72 ~24 ~49 ~72 ~24 grass_block
fill ~50 ~60 ~24 ~52 ~67 ~24 stone
fill ~50 ~68 ~24 ~52 ~70 ~24 dirt
fill ~50 ~71 ~24 ~52 ~71 ~24 grass_block
fill ~53 ~60 ~24 ~54 ~66 ~24 stone
fill ~53 ~67 ~24 ~54 ~69 ~24 dirt
fill ~53 ~70 ~24 ~54 ~70 ~24 grass_block
fill ~55 ~60 ~24 ~56 ~65 ~24 stone
fill ~55 ~66 ~24 ~56 ~68 ~24 dirt
fill ~55 ~69 ~24 ~56 ~69 ~24 grass_block
fill ~57 ~60 ~24 ~61 ~64 ~24 stone
fill ~57 ~65 ~24 ~61 ~67 ~24 dirt
fill ~57 ~68 ~24 ~61 ~68 ~24 grass_block
fill ~62 ~60 ~24 ~63 ~63 ~24 stone
fill ~62 ~64 ~24 ~63 ~66 ~24 dirt
fill ~62 ~67 ~24 ~63 ~67 ~24 grass_block
fill ~48 ~60 ~25 ~51 ~68 ~25 stone
fill ~48 ~69 ~25 ~51 ~71 ~25 dirt
fill ~48 ~72 ~25 ~51 ~72 ~25 grass_block
fill ~52 ~60 ~25 ~53 ~67 ~25 stone
fill ~52 ~68 ~25 ~53 ~70 ~25 dirt
fill ~52 ~71 ~25 ~53 ~71 ~25 grass_block
fill ~54 ~60 ~25 ~56 ~66 ~25 stone
fill ~54 ~67 ~25 ~56 ~69 ~25 dirt
fill ~54 ~70 ~25 ~56 ~70 ~25 grass_block
fill ~57 ~60 ~25 ~59 ~65 ~25 stone
fill ~57 ~66 ~25 ~59 ~68 ~25 dirt
fill ~57 ~69 ~25 ~59 ~69 ~25 grass_block
fill ~60 ~60 ~25 ~63 ~64 ~25 stone
fill ~60 ~65 ~25 ~63 ~67 ~25 dirt
fill ~60 ~68 ~25 ~63 ~68 ~25 grass_block
fill ~48 ~60 ~26 ~48 ~67 ~26 stone
fill ~48 ~68 ~26 ~48 ~70 ~26 dirt
fill ~48 ~71 ~26 ~48 ~71 ~26 grass_block
fill ~49 ~60 ~26 ~52 ~68 ~26 stone
fill ~49 ~69 ~26 ~52 ~71 ~26 dirt
fill ~49 ~72 ~26 ~52 ~72 ~26 grass_block
fill ~53 ~60 ~26 ~55 ~67 ~26 stone
fill ~53 ~68 ~26 ~55 ~70 ~26 dirt
fill ~53 ~71 ~26 ~55 ~71 ~26 grass_block
fill ~56 ~60 ~26 ~57 ~66 ~26 stone
fill ~56 ~67 ~26 ~57 ~69 ~26 dirt
fill ~56 ~70 ~26 ~57 ~70 ~26 grass_block
fill ~58 ~60 ~26 ~59 ~65 ~26 stone
fill ~58 ~66 ~26 ~59 ~68 ~26 dirt
fill ~58 ~69 ~26 ~59 ~69 ~26 grass_block
fill ~60 ~60 ~26 ~63 ~64 ~26 stone
fill ~60 ~65 ~26 ~63 ~67 ~26 dirt
fill ~60 ~68 ~26 ~63 ~68 ~26 grass_block
fill ~48 ~60 ~27 ~48 ~67 ~27 stone
fill ~48 ~68 ~27 ~48 ~70 ~27 dirt
fill ~48 ~71 ~27 ~48 ~71 ~27 grass_block
fill ~49 ~60 ~27 ~54 ~68 ~27 stone
fill ~49 ~69 ~27 ~54 ~71 ~27 dirt
fill ~49 ~72 ~27 ~54 ~72 ~27 grass_block
fill ~55 ~60 ~27 ~56 ~67 ~27 stone
fill ~55 ~68 ~27 ~56 ~70 ~27 dirt
fill ~55 ~71 ~27 ~56 ~71 ~27 grass_block
fill ~57 ~60 ~27 ~58 ~66 ~27 stone
fill ~57 ~67 ~27 ~58 ~69 ~27 dirt
fill ~57 ~70 ~27 ~58 ~70 ~27 grass_block
fill ~59 ~60 ~27 ~62 ~65 ~27 stone
fill ~59 ~66 ~27 ~62 ~68 ~27 dirt
fill ~59 ~69 ~27 ~62 ~69 ~27 grass_block
fill ~63 ~60 ~27 ~63 ~64 ~27 stone
fill ~63 ~65 ~27 ~63 ~67 ~27 dirt
fill ~63 ~68 ~27 ~63 ~68 ~27 grass_block
fill ~48 ~60 ~28 ~49 ~67 ~28 stone
fill ~48 ~68 ~28 ~49 ~70 ~28 dirt
fill ~48 ~71 ~28 ~49 ~71 ~28 grass_block
fill ~50 ~60 ~28 ~55 ~68 ~28 stone
fill ~50 ~69 ~28 ~55 ~71 ~28 dirt
fill ~50 ~72 ~28 ~55 ~72 ~28 grass_block
fill ~56 ~60 ~28 ~58 ~67 ~28 stone
fill ~56 ~68 ~28 ~58 ~70 ~28 dirt
fill ~56 ~71 ~28 ~58 ~71 ~28 grass_block
fill ~59 ~60 ~28 ~61 ~66 ~28 stone
fill ~59 ~67 ~28 ~61 ~69 ~28 dirt
fill ~59 ~70 ~28 ~61 ~70 ~28 grass_block
fill ~62 ~60 ~28 ~63 ~65 ~28 stone
fill ~62 ~66 ~28 ~63 ~68 ~28 dirt
fill ~62 ~69 ~28 ~63 ~69 ~28 grass_block
fill ~48 ~60 ~29 ~48 ~66 ~29 stone
fill ~48 ~67 ~29 ~48 ~69 ~29 dirt
fill ~48 ~70 ~29 ~48 ~70 ~29 grass_block
fill ~49 ~60 ~29 ~52 ~67 ~29 stone
fill ~49 ~68 ~29 ~52 ~70 ~29 dirt
fill ~49 ~71 ~29 ~52 ~71 ~29 grass_block
fill ~53 ~60 ~29 ~56 ~68 ~29 stone
fill ~53 ~69 ~29 ~56 ~71 ~29 dirt
fill ~53 ~72 ~29 ~56 ~72 ~29 grass_block
fill ~57 ~60 ~29 ~59 ~67 ~29 stone
fill ~57 ~68 ~29 ~59 ~70 ~29 dirt
fill ~57 ~71 ~29 ~59 ~71 ~29 grass_block
fill ~60 ~60 ~29 ~61 ~66 ~29 stone
fill ~60 ~67 ~29 ~61 ~69 ~29 dirt
fill ~60 ~70 ~29 ~61 ~70 ~29 grass_block
fill ~62 ~60 ~29 ~63 ~65 ~29 stone
fill ~62 ~66 ~29 ~63 ~68 ~29 dirt
fill ~62 ~69 ~29 ~63 ~69 ~29 grass_block
fill ~48 ~60 ~30 ~49 ~66 ~30 stone
fill ~48 ~67 ~30 ~49 ~69 ~30 dirt
fill ~48 ~70 ~30 ~49 ~70 ~30 grass_block
fill ~50 ~60 ~30 ~54 ~67 ~30 stone
fill ~50 ~68 ~30 ~54 ~70 ~30 dirt
fill ~50 ~71 ~30 ~54 ~71 ~30 grass_block
fill ~55 ~60 ~30 ~57 ~68 ~30 stone
fill ~55 ~69 ~30 ~57 ~71 ~30 dirt
fill ~55 ~72 ~30 ~57 ~72 ~30 grass_block
fill ~58 ~60 ~30 ~60 ~67 ~30 stone
fill ~58 ~68 ~30 ~60 ~70 ~30 dirt
fill ~58 ~71 ~30 ~60 ~71 ~30 grass_block
fill ~61 ~60 ~30 ~62 ~66 ~30 stone
fill ~61 ~67 ~30 ~62 ~69 ~30 dirt
fill ~61 ~70 ~30 ~62 ~70 ~30 grass_block
fill ~63 ~60 ~30 ~63 ~65 ~30 stone
fill ~63 ~66 ~30 ~63 ~68 ~30 dirt
fill ~63 ~69 ~30 ~63 ~69 ~30 grass_block
fill ~48 ~60 ~31 ~53 ~66 ~31 stone
fill ~48 ~67 ~31 ~53 ~69 ~31 dirt
fill ~48 ~70 ~31 ~53 ~70 ~31 grass_block
fill ~54 ~60 ~31 ~55 ~67 ~31 stone
fill ~54 ~68 ~31 ~55 ~70 ~31 dirt
fill ~54 ~71 ~31 ~55 ~71 ~31 grass_block
fill ~56 ~60 ~31 ~58 ~68 ~31 stone
fill ~56 ~69 ~31 ~58 ~71 ~31 dirt
fill ~56 ~72 ~31 ~58 ~72 ~31 grass_block
fill ~59 ~60 ~31 ~61 ~67 ~31 stone
fill ~59 ~68 ~31 ~61 ~70 ~31 dirt
fill ~59 ~71 ~31 ~61 ~71 ~31 grass_block
fill ~62 ~60 ~31 ~63 ~66 ~31 stone
fill ~62 ~67 ~31 ~63 ~69 ~31 dirt
fill ~62 ~70 ~31 ~63 ~70 ~31 grass_block