fill ~288 ~60 ~48 ~290 ~61 ~48 stone
fill ~288 ~62 ~48 ~290 ~64 ~48 dirt
fill ~288 ~65 ~48 ~290 ~65 ~48 grass_block
fill ~291 ~60 ~48 ~295 ~62 ~48 stone
fill ~291 ~63 ~48 ~295 ~65 ~48 dirt
fill ~291 ~66 ~48 ~295 ~66 ~48 grass_block
fill ~296 ~60 ~48 ~297 ~63 ~48 stone
fill ~296 ~64 ~48 ~297 ~66 ~48 dirt
fill ~296 ~67 ~48 ~297 ~67 ~48 grass_block
fill ~298 ~60 ~48 ~301 ~64 ~48 stone
fill ~298 ~65 ~48 ~301 ~67 ~48 dirt
fill ~298 ~68 ~48 ~301 ~68 ~48 grass_block
fill ~302 ~60 ~48 ~303 ~63 ~48 stone
fill ~302 ~64 ~48 ~303 ~66 ~48 dirt
fill ~302 ~67 ~48 ~303 ~67 ~48 grass_block
fill ~288 ~60 ~49 ~291 ~61 ~49 stone
fill ~288 ~62 ~49 ~291 ~64 ~49 dirt
fill ~288 ~65 ~49 ~291 ~65 ~49 grass_block
fill ~292 ~60 ~49 ~292 ~62 ~49 stone
fill ~292 ~63 ~49 ~292 ~65 ~49 dirt
fill ~292 ~66 ~49 ~292 ~66 ~49 grass_block
fill ~293 ~60 ~49 ~298 ~63 ~49 stone
fill ~293 ~64 ~49 ~298 ~66 ~49 dirt
fill ~293 ~67 ~49 ~298 ~67 ~49 grass_block
fill ~299 ~60 ~49 ~301 ~64 ~49 stone
fill ~299 ~65 ~49 ~301 ~67 ~49 dirt
fill ~299 ~68 ~49 ~301 ~68 ~49 grass_block
fill ~302 ~60 ~49 ~303 ~63 ~49 stone
fill ~302 ~64 ~49 ~303 ~66 ~49 dirt
fill ~302 ~67 ~49 ~303 ~67 ~49 grass_block
fill ~288 ~60 ~50 ~290 ~61 ~50 stone
fill ~288 ~62 ~50 ~290 ~64 ~50 dirt
fill ~288 ~65 ~50 ~290 ~65 ~50 grass_block
fill ~291 ~60 ~50 ~292 ~62 ~50 stone
fill ~291 ~63 ~50 ~292 ~65 ~50 dirt
fill ~291 ~66 ~50 ~292 ~66 ~50 grass_block
fill ~293 ~60 ~50 ~298 ~63 ~50 stone
fill ~293 ~64 ~50 ~298 ~66 ~50 dirt
fill ~293 ~67 ~50 ~298 ~67 ~50 grass_block
fill ~299 ~60 ~50 ~301 ~64 ~50 stone
fill ~299 ~65 ~50 ~301 ~67 ~50 dirt
fill ~299 ~68 ~50 ~301 ~68 ~50 grass_block
fill ~302 ~60 ~50 ~303 ~63 ~50 stone
fill ~302 ~64 ~50 ~303 ~66 ~50 dirt
fill ~302 ~67 ~50 ~303 ~67 ~50 grass_block
fill ~288 ~60 ~51 ~291 ~61 ~51 stone
fill ~288 ~62 ~51 ~291 ~64 ~51 dirt
fill ~288 ~65 ~51 ~291 ~65 ~51 grass_block
fill ~292 ~60 ~51 ~293 ~62 ~51 stone
fill ~292 ~63 ~51 ~293 ~65 ~51 dirt
fill ~292 ~66 ~51 ~293 ~66 ~51 grass_block
fill ~294 ~60 ~51 ~298 ~63 ~51 stone
fill ~294 ~64 ~51 ~298 ~66 ~51 dirt
fill ~294 ~67 ~51 ~298 ~67 ~51 grass_block
fill ~299 ~60 ~51 ~301 ~64 ~51 stone
fill ~299 ~65 ~51 ~301 ~67 ~51 dirt
fill ~299 ~68 ~51 ~301 ~68 ~51 grass_block
fill ~302 ~60 ~51 ~303 ~63 ~51 stone
fill ~302 ~64 ~51 ~303 ~66 ~51 dirt
fill ~302 ~67 ~51 ~303 ~67 ~51 grass_block
fill ~288 ~60 ~52 ~290 ~61 ~52 stone
fill ~288 ~62 ~52 ~290 ~64 ~52 dirt
fill ~288 ~65 ~52 ~290 ~65 ~52 grass_block
fill ~291 ~60 ~52 ~294 ~62 ~52 stone
fill ~291 ~63 ~52 ~294 ~65 ~52 dirt
fill ~291 ~66 ~52 ~294 ~66 ~52 grass_block
fill ~295 ~60 ~52 ~297 ~63 ~52 stone
fill ~295 ~64 ~52 ~297 ~66 ~52 dirt
fill ~295 ~67 ~52 ~297 ~67 ~52 grass_block
fill ~298 ~60 ~52 ~302 ~64 ~52 stone
fill ~298 ~65 ~52 ~302 ~67 ~52 dirt
fill ~298 ~68 ~52 ~302 ~68 ~52 grass_block
fill ~303 ~60 ~52 ~303 ~63 ~52 stone
fill ~303 ~64 ~52 ~303 ~66 ~52 dirt
fill ~303 ~67 ~52 ~303 ~67 ~52 grass_block
fill ~288 ~60 ~53 ~290 ~61 ~53 stone
fill ~288 ~62 ~53 ~290 ~64 ~53 dirt
fill ~288 ~65 ~53 ~290 ~65 ~53 grass_block
fill ~291 ~60 ~53 ~294 ~62 ~53 stone
fill ~291 ~63 ~53 ~294 ~65 ~53 dirt
fill ~291 ~66 ~53 ~294 ~66 ~53 grass_block
fill ~295 ~60 ~53 ~297 ~63 ~53 stone
fill ~295 ~64 ~53 ~297 ~66 ~53 dirt
fill ~295 ~67 ~53 ~297 ~67 ~53 grass_block
fill ~298 ~60 ~53 ~300 ~64 ~53 stone
fill ~298 ~65 ~53 ~300 ~67 ~53 dirt
fill ~298 ~68 ~53 ~300 ~68 ~53 grass_block
fill ~301 ~60 ~53 ~303 ~63 ~53 stone
fill ~301 ~64 ~53 ~303 ~66 ~53 dirt
fill ~301 ~67 ~53 ~303 ~67 ~53 grass_block
fill ~288 ~60 ~54 ~291 ~61 ~54 stone
fill ~288 ~62 ~54 ~291 ~64 ~54 dirt
fill ~288 ~65 ~54 ~291 ~65 ~54 grass_block
fill ~292 ~60 ~54 ~294 ~62 ~54 stone
fill ~292 ~63 ~54 ~294 ~65 ~54 dirt
fill ~292 ~66 ~54 ~294 ~66 ~54 grass_block
fill ~295 ~60 ~54 ~298 ~63 ~54 stone
fill ~295 ~64 ~54 ~298 ~66 ~54 dirt
fill ~295 ~67 ~54 ~298 ~67 ~54 grass_block
fill ~299 ~60 ~54 ~300 ~64 ~54 stone
fill ~299 ~65 ~54 ~300 ~67 ~54 dirt
fill ~299 ~68 ~54 ~300 ~68 ~54 grass_block
fill ~301 ~60 ~54 ~303 ~63 ~54 stone
fill ~301 ~64 ~54 ~303 ~66 ~54 dirt
fill ~301 ~67 ~54 ~303 ~67 ~54 grass_block
fill ~288 ~60 ~55 ~291 ~61 ~55 stone
fill ~288 ~62 ~55 ~291 ~64 ~55 dirt
fill ~288 ~65 ~55 ~291 ~65 ~55 grass_block
fill ~292 ~60 ~55 ~294 ~62 ~55 stone
fill ~292 ~63 ~55 ~294 ~65 ~55 dirt
fill ~292 ~66 ~55 ~294 ~66 ~55 grass_block
fill ~295 ~60 ~55 ~298 ~63 ~55 stone
fill ~295 ~64 ~55 ~298 ~66 ~55 dirt
fill ~295 ~67 ~55 ~298 ~67 ~55 grass_block
fill ~299 ~60 ~55 ~300 ~64 ~55 stone
fill ~299 ~65 ~55 ~300 ~67 ~55 dirt
fill ~299 ~68 ~55 ~300 ~68 ~55 grass_block
fill ~301 ~60 ~55 ~303 ~63 ~55 stone
fill ~301 ~64 ~55 ~303 ~66 ~55 dirt
fill ~301 ~67 ~55 ~303 ~67 ~55 grass_block
fill ~288 ~60 ~56 ~292 ~61 ~56 stone
fill ~288 ~62 ~56 ~292 ~64 ~56 dirt
fill ~288 ~65 ~56 ~292 ~65 ~56 grass_block
fill ~293 ~60 ~56 ~295 ~62 ~56 stone
fill ~293 ~63 ~56 ~295 ~65 ~56 dirt
fill ~293 ~66 ~56 ~295 ~66 ~56 grass_block
fill ~296 ~60 ~56 ~303 ~63 ~56 stone
fill ~296 ~64 ~56 ~303 ~66 ~56 dirt
fill ~296 ~67 ~56 ~303 ~67 ~56 grass_block
fill ~288 ~60 ~57 ~292 ~61 ~57 stone
fill ~288 ~62 ~57 ~292 ~64 ~57 dirt
fill ~288 ~65 ~57 ~292 ~65 ~57 grass_block
fill ~293 ~60 ~57 ~296 ~62 ~57 stone
fill ~293 ~63 ~57 ~296 ~65 ~57 dirt
fill ~293 ~66 ~57 ~296 ~66 ~57 grass_block
fill ~297 ~60 ~57 ~303 ~63 ~57 stone
fill ~297 ~64 ~57 ~303 ~66 ~57 dirt
fill ~297 ~67 ~57 ~303 ~67 ~57 grass_block
fill ~288 ~60 ~58 ~293 ~61 ~58 stone
fill ~288 ~62 ~58 ~293 ~64 ~58 dirt
fill ~288 ~65 ~58 ~293 ~65 ~58 grass_block
fill ~294 ~60 ~58 ~296 ~62 ~58 stone
fill ~294 ~63 ~58 ~296 ~65 ~58 dirt
fill ~294 ~66 ~58 ~296 ~66 ~58 grass_block
fill ~297 ~60 ~58 ~303 ~63 ~58 stone
fill ~297 ~64 ~58 ~303 ~66 ~58 dirt
fill ~297 ~67 ~58 ~303 ~67 ~58 grass_block
fill ~288 ~60 ~59 ~293 ~61 ~59 stone
fill ~288 ~62 ~59 ~293 ~64 ~59 dirt
fill ~288 ~65 ~59 ~293 ~65 ~59 grass_block
fill ~294 ~60 ~59 ~297 ~62 ~59 stone
fill ~294 ~63 ~59 ~297 ~65 ~59 dirt
fill ~294 ~66 ~59 ~297 ~66 ~59 grass_block
fill ~298 ~60 ~59 ~303 ~63 ~59 stone
fill ~298 ~64 ~59 ~303 ~66 ~59 dirt
fill ~298 ~67 ~59 ~303 ~67 ~59 grass_block
fill ~288 ~60 ~60 ~294 ~61 ~60 stone
fill ~288 ~62 ~60 ~294 ~64 ~60 dirt
fill ~288 ~65 ~60 ~294 ~65 ~60 grass_block
fill ~295 ~60 ~60 ~297 ~62 ~60 stone
fill ~295 ~63 ~60 ~297 ~65 ~60 dirt
fill ~295 ~66 ~60 ~297 ~66 ~60 grass_block
fill ~298 ~60 ~60 ~303 ~63 ~60 stone
fill ~298 ~64 ~60 ~303 ~66 ~60 dirt
fill ~298 ~67 ~60 ~303 ~67 ~60 grass_block
fill ~288 ~60 ~61 ~295 ~61 ~61 stone
fill ~288 ~62 ~61 ~295 ~64 ~61 dirt
fill ~288 ~65 ~61 ~295 ~65 ~61 grass_block
fill ~296 ~60 ~61 ~298 ~62 ~61 stone
fill ~296 ~63 ~61 ~298 ~65 ~61 dirt
fill ~296 ~66 ~61 ~298 ~66 ~61 grass_block
fill ~299 ~60 ~61 ~303 ~63 ~61 stone
fill ~299 ~64 ~61 ~303 ~66 ~61 dirt
fill ~299 ~67 ~61 ~303 ~67 ~61 grass_block
fill ~288 ~60 ~62 ~295 ~61 ~62 stone
fill ~288 ~62 ~62 ~295 ~64 ~62 dirt
fill ~288 ~65 ~62 ~295 ~65 ~62 grass_block
fill ~296 ~60 ~62 ~299 ~62 ~62 stone
fill ~296 ~63 ~62 ~299 ~65 ~62 dirt
fill ~296 ~66 ~62 ~299 ~66 ~62 grass_block
fill ~300 ~60 ~62 ~303 ~63 ~62 stone
fill ~300 ~64 ~62 ~303 ~66 ~62 dirt
fill ~300 ~67 ~62 ~303 ~67 ~62 grass_block
fill ~288 ~60 ~63 ~296 ~61 ~63 stone
fill ~288 ~62 ~63 ~296 ~64 ~63 dirt
fill ~288 ~65 ~63 ~296 ~65 ~63 grass_block
fill ~297 ~60 ~63 ~300 ~62 ~63 stone
fill ~297 ~63 ~63 ~300 ~65 ~63 dirt
fill ~297 ~66 ~63 ~300 ~66 ~63 grass_block
fill ~301 ~60 ~63 ~303 ~63 ~63 stone
fill ~301 ~64 ~63 ~303 ~66 ~63 dirt
fill ~301 ~67 ~63 ~303 ~67 ~63 grass_block