fill ~240 ~60 ~80 ~244 ~66 ~80 stone
fill ~240 ~67 ~80 ~244 ~69 ~80 dirt
fill ~240 ~70 ~80 ~244 ~70 ~80 grass_block
fill ~245 ~60 ~80 ~251 ~65 ~80 stone
fill ~245 ~66 ~80 ~251 ~68 ~80 dirt
fill ~245 ~69 ~80 ~251 ~69 ~80 grass_block
fill ~252 ~60 ~80 ~255 ~64 ~80 stone
fill ~252 ~65 ~80 ~255 ~67 ~80 dirt
fill ~252 ~68 ~80 ~255 ~68 ~80 grass_block
fill ~240 ~60 ~81 ~247 ~66 ~81 stone
fill ~240 ~67 ~81 ~247 ~69 ~81 dirt
fill ~240 ~70 ~81 ~247 ~70 ~81 grass_block
fill ~248 ~60 ~81 ~251 ~65 ~81 stone
fill ~248 ~66 ~81 ~251 ~68 ~81 dirt
fill ~248 ~69 ~81 ~251 ~69 ~81 grass_block
fill ~252 ~60 ~81 ~252 ~64 ~81 stone
fill ~252 ~65 ~81 ~252 ~67 ~81 dirt
fill ~252 ~68 ~81 ~252 ~68 ~81 grass_block
fill ~253 ~60 ~81 ~255 ~65 ~81 stone
fill ~253 ~66 ~81 ~255 ~68 ~81 dirt
fill ~253 ~69 ~81 ~255 ~69 ~81 grass_block
fill ~240 ~60 ~82 ~247 ~66 ~82 stone
fill ~240 ~67 ~82 ~247 ~69 ~82 dirt
fill ~240 ~70 ~82 ~247 ~70 ~82 grass_block
fill ~248 ~60 ~82 ~255 ~65 ~82 stone
fill ~248 ~66 ~82 ~255 ~68 ~82 dirt
fill ~248 ~69 ~82 ~255 ~69 ~82 grass_block
fill ~240 ~60 ~83 ~248 ~66 ~83 stone
fill ~240 ~67 ~83 ~248 ~69 ~83 dirt
fill ~240 ~70 ~83 ~248 ~70 ~83 grass_block
fill ~249 ~60 ~83 ~255 ~65 ~83 stone
fill ~249 ~66 ~83 ~255 ~68 ~83 dirt
fill ~249 ~69 ~83 ~255 ~69 ~83 grass_block
fill ~240 ~60 ~84 ~249 ~66 ~84 stone
fill ~240 ~67 ~84 ~249 ~69 ~84 dirt
fill ~240 ~70 ~84 ~249 ~70 ~84 grass_block
fill ~250 ~60 ~84 ~255 ~65 ~84 stone
fill ~250 ~66 ~84 ~255 ~68 ~84 dirt
fill ~250 ~69 ~84 ~255 ~69 ~84 grass_block
fill ~240 ~60 ~85 ~249 ~66 ~85 stone
fill ~240 ~67 ~85 ~249 ~69 ~85 dirt
fill ~240 ~70 ~85 ~249 ~70 ~85 grass_block
fill ~250 ~60 ~85 ~255 ~65 ~85 stone
fill ~250 ~66 ~85 ~255 ~68 ~85 dirt
fill ~250 ~69 ~85 ~255 ~69 ~85 grass_block
fill ~240 ~60 ~86 ~242 ~65 ~86 stone
fill ~240 ~66 ~86 ~242 ~68 ~86 dirt
fill ~240 ~69 ~86 ~242 ~69 ~86 grass_block
fill ~243 ~60 ~86 ~252 ~66 ~86 stone
fill ~243 ~67 ~86 ~252 ~69 ~86 dirt
fill ~243 ~70 ~86 ~252 ~70 ~86 grass_block
fill ~253 ~60 ~86 ~255 ~65 ~86 stone
fill ~253 ~66 ~86 ~255 ~68 ~86 dirt
fill ~253 ~69 ~86 ~255 ~69 ~86 grass_block
fill ~240 ~60 ~87 ~240 ~64 ~87 stone
fill ~240 ~65 ~87 ~240 ~67 ~87 dirt
fill ~240 ~68 ~87 ~240 ~68 ~87 grass_block
fill ~241 ~60 ~87 ~243 ~65 ~87 stone
fill ~241 ~66 ~87 ~243 ~68 ~87 dirt
fill ~241 ~69 ~87 ~243 ~69 ~87 grass_block
fill ~244 ~60 ~87 ~252 ~66 ~87 stone
fill ~244 ~67 ~87 ~252 ~69 ~87 dirt
fill ~244 ~70 ~87 ~252 ~70 ~87 grass_block
fill ~253 ~60 ~87 ~255 ~65 ~87 stone
fill ~253 ~66 ~87 ~255 ~68 ~87 dirt
fill ~253 ~69 ~87 ~255 ~69 ~87 grass_block
fill ~240 ~60 ~88 ~241 ~64 ~88 stone
fill ~240 ~65 ~88 ~241 ~67 ~88 dirt
fill ~240 ~68 ~88 ~241 ~68 ~88 grass_block
fill ~242 ~60 ~88 ~245 ~65 ~88 stone
fill ~242 ~66 ~88 ~245 ~68 ~88 dirt
fill ~242 ~69 ~88 ~245 ~69 ~88 grass_block
fill ~246 ~60 ~88 ~251 ~66 ~88 stone
fill ~246 ~67 ~88 ~251 ~69 ~88 dirt
fill ~246 ~70 ~88 ~251 ~70 ~88 grass_block
fill ~252 ~60 ~88 ~252 ~65 ~88 stone
fill ~252 ~66 ~88 ~252 ~68 ~88 dirt
fill ~252 ~69 ~88 ~252 ~69 ~88 grass_block
fill ~253 ~60 ~88 ~254 ~66 ~88 stone
fill ~253 ~67 ~88 ~254 ~69 ~88 dirt
fill ~253 ~70 ~88 ~254 ~70 ~88 grass_block
fill ~255 ~60 ~88 ~255 ~65 ~88 stone
fill ~255 ~66 ~88 ~255 ~68 ~88 dirt
fill ~255 ~69 ~88 ~255 ~69 ~88 grass_block
fill ~240 ~60 ~89 ~243 ~64 ~89 stone
fill ~240 ~65 ~89 ~243 ~67 ~89 dirt
fill ~240 ~68 ~89 ~243 ~68 ~89 grass_block
fill ~244 ~60 ~89 ~247 ~65 ~89 stone
fill ~244 ~66 ~89 ~247 ~68 ~89 dirt
fill ~244 ~69 ~89 ~247 ~69 ~89 grass_block
fill ~248 ~60 ~89 ~249 ~66 ~89 stone
fill ~248 ~67 ~89 ~249 ~69 ~89 dirt
fill ~248 ~70 ~89 ~249 ~70 ~89 grass_block
fill ~250 ~60 ~89 ~255 ~65 ~89 stone
fill ~250 ~66 ~89 ~255 ~68 ~89 dirt
fill ~250 ~69 ~89 ~255 ~69 ~89 grass_block
fill ~240 ~60 ~90 ~241 ~64 ~90 stone
fill ~240 ~65 ~90 ~241 ~67 ~90 dirt
fill ~240 ~68 ~90 ~241 ~68 ~90 grass_block
fill ~242 ~60 ~90 ~242 ~63 ~90 stone
fill ~242 ~64 ~90 ~242 ~66 ~90 dirt
fill ~242 ~67 ~90 ~242 ~67 ~90 grass_block
fill ~243 ~60 ~90 ~245 ~64 ~90 stone
fill ~243 ~65 ~90 ~245 ~67 ~90 dirt
fill ~243 ~68 ~90 ~245 ~68 ~90 grass_block
fill ~246 ~60 ~90 ~252 ~65 ~90 stone
fill ~246 ~66 ~90 ~252 ~68 ~90 dirt
fill ~246 ~69 ~90 ~252 ~69 ~90 grass_block
fill ~253 ~60 ~90 ~253 ~64 ~90 stone
fill ~253 ~65 ~90 ~253 ~67 ~90 dirt
fill ~253 ~68 ~90 ~253 ~68 ~90 grass_block
fill ~254 ~60 ~90 ~255 ~65 ~90 stone
fill ~254 ~66 ~90 ~255 ~68 ~90 dirt
fill ~254 ~69 ~90 ~255 ~69 ~90 grass_block
fill ~240 ~60 ~91 ~241 ~64 ~91 stone
fill ~240 ~65 ~91 ~241 ~67 ~91 dirt
fill ~240 ~68 ~91 ~241 ~68 ~91 grass_block
fill ~242 ~60 ~91 ~243 ~63 ~91 stone
fill ~242 ~64 ~91 ~243 ~66 ~91 dirt
fill ~242 ~67 ~91 ~243 ~67 ~91 grass_block
fill ~244 ~60 ~91 ~246 ~64 ~91 stone
fill ~244 ~65 ~91 ~246 ~67 ~91 dirt
fill ~244 ~68 ~91 ~246 ~68 ~91 grass_block
fill ~247 ~60 ~91 ~250 ~65 ~91 stone
fill ~247 ~66 ~91 ~250 ~68 ~91 dirt
fill ~247 ~69 ~91 ~250 ~69 ~91 grass_block
fill ~251 ~60 ~91 ~255 ~64 ~91 stone
fill ~251 ~65 ~91 ~255 ~67 ~91 dirt
fill ~251 ~68 ~91 ~255 ~68 ~91 grass_block
fill ~240 ~60 ~92 ~242 ~64 ~92 stone
fill ~240 ~65 ~92 ~242 ~67 ~92 dirt
fill ~240 ~68 ~92 ~242 ~68 ~92 grass_block
fill ~243 ~60 ~92 ~245 ~63 ~92 stone
fill ~243 ~64 ~92 ~245 ~66 ~92 dirt
fill ~243 ~67 ~92 ~245 ~67 ~92 grass_block
fill ~246 ~60 ~92 ~248 ~64 ~92 stone
fill ~246 ~65 ~92 ~248 ~67 ~92 dirt
fill ~246 ~68 ~92 ~248 ~68 ~92 grass_block
fill ~249 ~60 ~92 ~250 ~65 ~92 stone
fill ~249 ~66 ~92 ~250 ~68 ~92 dirt
fill ~249 ~69 ~92 ~250 ~69 ~92 grass_block
fill ~251 ~60 ~92 ~255 ~64 ~92 stone
fill ~251 ~65 ~92 ~255 ~67 ~92 dirt
fill ~251 ~68 ~92 ~255 ~68 ~92 grass_block
fill ~240 ~60 ~93 ~240 ~65 ~93 stone
fill ~240 ~66 ~93 ~240 ~68 ~93 dirt
fill ~240 ~69 ~93 ~240 ~69 ~93 grass_block
fill ~241 ~60 ~93 ~243 ~64 ~93 stone
fill ~241 ~65 ~93 ~243 ~67 ~93 dirt
fill ~241 ~68 ~93 ~243 ~68 ~93 grass_block
fill ~244 ~60 ~93 ~246 ~63 ~93 stone
fill ~244 ~64 ~93 ~246 ~66 ~93 dirt
fill ~244 ~67 ~93 ~246 ~67 ~93 grass_block
fill ~247 ~60 ~93 ~251 ~64 ~93 stone
fill ~247 ~65 ~93 ~251 ~67 ~93 dirt
fill ~247 ~68 ~93 ~251 ~68 ~93 grass_block
fill ~252 ~60 ~93 ~253 ~63 ~93 stone
fill ~252 ~64 ~93 ~253 ~66 ~93 dirt
fill ~252 ~67 ~93 ~253 ~67 ~93 grass_block
fill ~254 ~60 ~93 ~255 ~64 ~93 stone
fill ~254 ~65 ~93 ~255 ~67 ~93 dirt
fill ~254 ~68 ~93 ~255 ~68 ~93 grass_block
fill ~240 ~60 ~94 ~241 ~65 ~94 stone
fill ~240 ~66 ~94 ~241 ~68 ~94 dirt
fill ~240 ~69 ~94 ~241 ~69 ~94 grass_block
fill ~242 ~60 ~94 ~244 ~64 ~94 stone
fill ~242 ~65 ~94 ~244 ~67 ~94 dirt
fill ~242 ~68 ~94 ~244 ~68 ~94 grass_block
fill ~245 ~60 ~94 ~247 ~63 ~94 stone
fill ~245 ~64 ~94 ~247 ~66 ~94 dirt
fill ~245 ~67 ~94 ~247 ~67 ~94 grass_block
fill ~248 ~60 ~94 ~250 ~64 ~94 stone
fill ~248 ~65 ~94 ~250 ~67 ~94 dirt
fill ~248 ~68 ~94 ~250 ~68 ~94 grass_block
fill ~251 ~60 ~94 ~253 ~63 ~94 stone
fill ~251 ~64 ~94 ~253 ~66 ~94 dirt
fill ~251 ~67 ~94 ~253 ~67 ~94 grass_block
fill ~254 ~60 ~94 ~255 ~64 ~94 stone
fill ~254 ~65 ~94 ~255 ~67 ~94 dirt
fill ~254 ~68 ~94 ~255 ~68 ~94 grass_block
fill ~240 ~60 ~95 ~241 ~65 ~95 stone
fill ~240 ~66 ~95 ~241 ~68 ~95 dirt
fill ~240 ~69 ~95 ~241 ~69 ~95 grass_block
fill ~242 ~60 ~95 ~244 ~64 ~95 stone
fill ~242 ~65 ~95 ~244 ~67 ~95 dirt
fill ~242 ~68 ~95 ~244 ~68 ~95 grass_block
fill ~245 ~60 ~95 ~254 ~63 ~95 stone
fill ~245 ~64 ~95 ~254 ~66 ~95 dirt
fill ~245 ~67 ~95 ~254 ~67 ~95 grass_block
fill ~255 ~60 ~95 ~255 ~64 ~95 stone
fill ~255 ~65 ~95 ~255 ~67 ~95 dirt
fill ~255 ~68 ~95 ~255 ~68 ~95 grass_block