fill ~160 ~60 ~32 ~161 ~63 ~32 stone
fill ~160 ~64 ~32 ~161 ~66 ~32 dirt
fill ~160 ~67 ~32 ~161 ~67 ~32 grass_block
fill ~162 ~60 ~32 ~163 ~64 ~32 stone
fill ~162 ~65 ~32 ~163 ~67 ~32 dirt
fill ~162 ~68 ~32 ~163 ~68 ~32 grass_block
fill ~164 ~60 ~32 ~167 ~65 ~32 stone
fill ~164 ~66 ~32 ~167 ~68 ~32 dirt
fill ~164 ~69 ~32 ~167 ~69 ~32 grass_block
fill ~168 ~60 ~32 ~171 ~64 ~32 stone
fill ~168 ~65 ~32 ~171 ~67 ~32 dirt
fill ~168 ~68 ~32 ~171 ~68 ~32 grass_block
fill ~172 ~60 ~32 ~175 ~65 ~32 stone
fill ~172 ~66 ~32 ~175 ~68 ~32 dirt
fill ~172 ~69 ~32 ~175 ~69 ~32 grass_block
fill ~160 ~60 ~33 ~162 ~63 ~33 stone
fill ~160 ~64 ~33 ~162 ~66 ~33 dirt
fill ~160 ~67 ~33 ~162 ~67 ~33 grass_block
fill ~163 ~60 ~33 ~164 ~64 ~33 stone
fill ~163 ~65 ~33 ~164 ~67 ~33 dirt
fill ~163 ~68 ~33 ~164 ~68 ~33 grass_block
fill ~165 ~60 ~33 ~169 ~65 ~33 stone
fill ~165 ~66 ~33 ~169 ~68 ~33 dirt
fill ~165 ~69 ~33 ~169 ~69 ~33 grass_block
fill ~170 ~60 ~33 ~171 ~64 ~33 stone
fill ~170 ~65 ~33 ~171 ~67 ~33 dirt
fill ~170 ~68 ~33 ~171 ~68 ~33 grass_block
fill ~172 ~60 ~33 ~175 ~65 ~33 stone
fill ~172 ~66 ~33 ~175 ~68 ~33 dirt
fill ~172 ~69 ~33 ~175 ~69 ~33 grass_block
fill ~160 ~60 ~34 ~160 ~63 ~34 stone
fill ~160 ~64 ~34 ~160 ~66 ~34 dirt
fill ~160 ~67 ~34 ~160 ~67 ~34 grass_block
fill ~161 ~60 ~34 ~162 ~64 ~34 stone
fill ~161 ~65 ~34 ~162 ~67 ~34 dirt
fill ~161 ~68 ~34 ~162 ~68 ~34 grass_block
fill ~163 ~60 ~34 ~163 ~63 ~34 stone
fill ~163 ~64 ~34 ~163 ~66 ~34 dirt
fill ~163 ~67 ~34 ~163 ~67 ~34 grass_block
fill ~164 ~60 ~34 ~165 ~64 ~34 stone
fill ~164 ~65 ~34 ~165 ~67 ~34 dirt
fill ~164 ~68 ~34 ~165 ~68 ~34 grass_block
fill ~166 ~60 ~34 ~175 ~65 ~34 stone
fill ~166 ~66 ~34 ~175 ~68 ~34 dirt
fill ~166 ~69 ~34 ~175 ~69 ~34 grass_block
fill ~160 ~60 ~35 ~166 ~64 ~35 stone
fill ~160 ~65 ~35 ~166 ~67 ~35 dirt
fill ~160 ~68 ~35 ~166 ~68 ~35 grass_block
fill ~167 ~60 ~35 ~175 ~65 ~35 stone
fill ~167 ~66 ~35 ~175 ~68 ~35 dirt
fill ~167 ~69 ~35 ~175 ~69 ~35 grass_block
fill ~160 ~60 ~36 ~160 ~64 ~36 stone
fill ~160 ~65 ~36 ~160 ~67 ~36 dirt
fill ~160 ~68 ~36 ~160 ~68 ~36 grass_block
fill ~161 ~60 ~36 ~161 ~65 ~36 stone
fill ~161 ~66 ~36 ~161 ~68 ~36 dirt
fill ~161 ~69 ~36 ~161 ~69 ~36 grass_block
fill ~162 ~60 ~36 ~166 ~64 ~36 stone
fill ~162 ~65 ~36 ~166 ~67 ~36 dirt
fill ~162 ~68 ~36 ~166 ~68 ~36 grass_block
fill ~167 ~60 ~36 ~175 ~65 ~36 stone
fill ~167 ~66 ~36 ~175 ~68 ~36 dirt
fill ~167 ~69 ~36 ~175 ~69 ~36 grass_block
fill ~160 ~60 ~37 ~160 ~64 ~37 stone
fill ~160 ~65 ~37 ~160 ~67 ~37 dirt
fill ~160 ~68 ~37 ~160 ~68 ~37 grass_block
fill ~161 ~60 ~37 ~163 ~65 ~37 stone
fill ~161 ~66 ~37 ~163 ~68 ~37 dirt
fill ~161 ~69 ~37 ~163 ~69 ~37 grass_block
fill ~164 ~60 ~37 ~166 ~64 ~37 stone
fill ~164 ~65 ~37 ~166 ~67 ~37 dirt
fill ~164 ~68 ~37 ~166 ~68 ~37 grass_block
fill ~167 ~60 ~37 ~175 ~65 ~37 stone
fill ~167 ~66 ~37 ~175 ~68 ~37 dirt
fill ~167 ~69 ~37 ~175 ~69 ~37 grass_block
fill ~160 ~60 ~38 ~161 ~65 ~38 stone
fill ~160 ~66 ~38 ~161 ~68 ~38 dirt
fill ~160 ~69 ~38 ~161 ~69 ~38 grass_block
fill ~162 ~60 ~38 ~162 ~66 ~38 stone
fill ~162 ~67 ~38 ~162 ~69 ~38 dirt
fill ~162 ~70 ~38 ~162 ~70 ~38 grass_block
fill ~163 ~60 ~38 ~175 ~65 ~38 stone
fill ~163 ~66 ~38 ~175 ~68 ~38 dirt
fill ~163 ~69 ~38 ~175 ~69 ~38 grass_block
fill ~160 ~60 ~39 ~161 ~65 ~39 stone
fill ~160 ~66 ~39 ~161 ~68 ~39 dirt
fill ~160 ~69 ~39 ~161 ~69 ~39 grass_block
fill ~162 ~60 ~39 ~163 ~66 ~39 stone
fill ~162 ~67 ~39 ~163 ~69 ~39 dirt
fill ~162 ~70 ~39 ~163 ~70 ~39 grass_block
fill ~164 ~60 ~39 ~175 ~65 ~39 stone
fill ~164 ~66 ~39 ~175 ~68 ~39 dirt
fill ~164 ~69 ~39 ~175 ~69 ~39 grass_block
fill ~160 ~60 ~40 ~161 ~65 ~40 stone
fill ~160 ~66 ~40 ~161 ~68 ~40 dirt
fill ~160 ~69 ~40 ~161 ~69 ~40 grass_block
fill ~162 ~60 ~40 ~169 ~66 ~40 stone
fill ~162 ~67 ~40 ~169 ~69 ~40 dirt
fill ~162 ~70 ~40 ~169 ~70 ~40 grass_block
fill ~170 ~60 ~40 ~175 ~65 ~40 stone
fill ~170 ~66 ~40 ~175 ~68 ~40 dirt
fill ~170 ~69 ~40 ~175 ~69 ~40 grass_block
fill ~160 ~60 ~41 ~160 ~65 ~41 stone
fill ~160 ~66 ~41 ~160 ~68 ~41 dirt
fill ~160 ~69 ~41 ~160 ~69 ~41 grass_block
fill ~161 ~60 ~41 ~172 ~66 ~41 stone
fill ~161 ~67 ~41 ~172 ~69 ~41 dirt
fill ~161 ~70 ~41 ~172 ~70 ~41 grass_block
fill ~173 ~60 ~41 ~175 ~65 ~41 stone
fill ~173 ~66 ~41 ~175 ~68 ~41 dirt
fill ~173 ~69 ~41 ~175 ~69 ~41 grass_block
fill ~160 ~60 ~42 ~161 ~66 ~42 stone
fill ~160 ~67 ~42 ~161 ~69 ~42 dirt
fill ~160 ~70 ~42 ~161 ~70 ~42 grass_block
fill ~162 ~60 ~42 ~165 ~67 ~42 stone
fill ~162 ~68 ~42 ~165 ~70 ~42 dirt
fill ~162 ~71 ~42 ~165 ~71 ~42 grass_block
fill ~166 ~60 ~42 ~172 ~66 ~42 stone
fill ~166 ~67 ~42 ~172 ~69 ~42 dirt
fill ~166 ~70 ~42 ~172 ~70 ~42 grass_block
fill ~173 ~60 ~42 ~175 ~65 ~42 stone
fill ~173 ~66 ~42 ~175 ~68 ~42 dirt
fill ~173 ~69 ~42 ~175 ~69 ~42 grass_block
fill ~160 ~60 ~43 ~160 ~66 ~43 stone
fill ~160 ~67 ~43 ~160 ~69 ~43 dirt
fill ~160 ~70 ~43 ~160 ~70 ~43 grass_block
fill ~161 ~60 ~43 ~166 ~67 ~43 stone
fill ~161 ~68 ~43 ~166 ~70 ~43 dirt
fill ~161 ~71 ~43 ~166 ~71 ~43 grass_block
fill ~167 ~60 ~43 ~172 ~66 ~43 stone
fill ~167 ~67 ~43 ~172 ~69 ~43 dirt
fill ~167 ~70 ~43 ~172 ~70 ~43 grass_block
fill ~173 ~60 ~43 ~175 ~65 ~43 stone
fill ~173 ~66 ~43 ~175 ~68 ~43 dirt
fill ~173 ~69 ~43 ~175 ~69 ~43 grass_block
fill ~160 ~60 ~44 ~160 ~66 ~44 stone
fill ~160 ~67 ~44 ~160 ~69 ~44 dirt
fill ~160 ~70 ~44 ~160 ~70 ~44 grass_block
fill ~161 ~60 ~44 ~166 ~67 ~44 stone
fill ~161 ~68 ~44 ~166 ~70 ~44 dirt
fill ~161 ~71 ~44 ~166 ~71 ~44 grass_block
fill ~167 ~60 ~44 ~171 ~66 ~44 stone
fill ~167 ~67 ~44 ~171 ~69 ~44 dirt
fill ~167 ~70 ~44 ~171 ~70 ~44 grass_block
fill ~172 ~60 ~44 ~175 ~65 ~44 stone
fill ~172 ~66 ~44 ~175 ~68 ~44 dirt
fill ~172 ~69 ~44 ~175 ~69 ~44 grass_block
fill ~160 ~60 ~45 ~166 ~67 ~45 stone
fill ~160 ~68 ~45 ~166 ~70 ~45 dirt
fill ~160 ~71 ~45 ~166 ~71 ~45 grass_block
fill ~167 ~60 ~45 ~171 ~66 ~45 stone
fill ~167 ~67 ~45 ~171 ~69 ~45 dirt
fill ~167 ~70 ~45 ~171 ~70 ~45 grass_block
fill ~172 ~60 ~45 ~175 ~65 ~45 stone
fill ~172 ~66 ~45 ~175 ~68 ~45 dirt
fill ~172 ~69 ~45 ~175 ~69 ~45 grass_block
fill ~160 ~60 ~46 ~166 ~67 ~46 stone
fill ~160 ~68 ~46 ~166 ~70 ~46 dirt
fill ~160 ~71 ~46 ~166 ~71 ~46 grass_block
fill ~167 ~60 ~46 ~170 ~66 ~46 stone
fill ~167 ~67 ~46 ~170 ~69 ~46 dirt
fill ~167 ~70 ~46 ~170 ~70 ~46 grass_block
fill ~171 ~60 ~46 ~173 ~65 ~46 stone
fill ~171 ~66 ~46 ~173 ~68 ~46 dirt
fill ~171 ~69 ~46 ~173 ~69 ~46 grass_block
fill ~174 ~60 ~46 ~175 ~66 ~46 stone
fill ~174 ~67 ~46 ~175 ~69 ~46 dirt
fill ~174 ~70 ~46 ~175 ~70 ~46 grass_block
fill ~160 ~60 ~47 ~166 ~67 ~47 stone
fill ~160 ~68 ~47 ~166 ~70 ~47 dirt
fill ~160 ~71 ~47 ~166 ~71 ~47 grass_block
fill ~167 ~60 ~47 ~175 ~66 ~47 stone
fill ~167 ~67 ~47 ~175 ~69 ~47 dirt
fill ~167 ~70 ~47 ~175 ~70 ~47 grass_block