fill ~464 ~60 ~16 ~467 ~65 ~16 stone
fill ~464 ~66 ~16 ~467 ~68 ~16 dirt
fill ~464 ~69 ~16 ~467 ~69 ~16 grass_block
fill ~468 ~60 ~16 ~469 ~66 ~16 stone
fill ~468 ~67 ~16 ~469 ~69 ~16 dirt
fill ~468 ~70 ~16 ~469 ~70 ~16 grass_block
fill ~464 ~60 ~17 ~467 ~65 ~17 stone
fill ~464 ~66 ~17 ~467 ~68 ~17 dirt
fill ~464 ~69 ~17 ~467 ~69 ~17 grass_block
fill ~468 ~60 ~17 ~469 ~66 ~17 stone
fill ~468 ~67 ~17 ~469 ~69 ~17 dirt
fill ~468 ~70 ~17 ~469 ~70 ~17 grass_block
fill ~464 ~60 ~18 ~467 ~65 ~18 stone
fill ~464 ~66 ~18 ~467 ~68 ~18 dirt
fill ~464 ~69 ~18 ~467 ~69 ~18 grass_block
fill ~468 ~60 ~18 ~469 ~66 ~18 stone
fill ~468 ~67 ~18 ~469 ~69 ~18 dirt
fill ~468 ~70 ~18 ~469 ~70 ~18 grass_block
fill ~464 ~60 ~19 ~469 ~65 ~19 stone
fill ~464 ~66 ~19 ~469 ~68 ~19 dirt
fill ~464 ~69 ~19 ~469 ~69 ~19 grass_block
fill ~464 ~60 ~20 ~464 ~64 ~20 stone
fill ~464 ~65 ~20 ~464 ~67 ~20 dirt
fill ~464 ~68 ~20 ~464 ~68 ~20 grass_block
fill ~465 ~60 ~20 ~469 ~65 ~20 stone
fill ~465 ~66 ~20 ~469 ~68 ~20 dirt
fill ~465 ~69 ~20 ~469 ~69 ~20 grass_block
fill ~464 ~60 ~21 ~466 ~64 ~21 stone
fill ~464 ~65 ~21 ~466 ~67 ~21 dirt
fill ~464 ~68 ~21 ~466 ~68 ~21 grass_block
fill ~467 ~60 ~21 ~469 ~65 ~21 stone
fill ~467 ~66 ~21 ~469 ~68 ~21 dirt
fill ~467 ~69 ~21 ~469 ~69 ~21 grass_block
fill ~464 ~60 ~22 ~468 ~64 ~22 stone
fill ~464 ~65 ~22 ~468 ~67 ~22 dirt
fill ~464 ~68 ~22 ~468 ~68 ~22 grass_block
fill ~469 ~60 ~22 ~469 ~65 ~22 stone
fill ~469 ~66 ~22 ~469 ~68 ~22 dirt
fill ~469 ~69 ~22 ~469 ~69 ~22 grass_block
fill ~464 ~60 ~23 ~469 ~64 ~23 stone
fill ~464 ~65 ~23 ~469 ~67 ~23 dirt
fill ~464 ~68 ~23 ~469 ~68 ~23 grass_block
fill ~464 ~60 ~24 ~466 ~63 ~24 stone
fill ~464 ~64 ~24 ~466 ~66 ~24 dirt
fill ~464 ~67 ~24 ~466 ~67 ~24 grass_block
fill ~467 ~60 ~24 ~469 ~64 ~24 stone
fill ~467 ~65 ~24 ~469 ~67 ~24 dirt
fill ~467 ~68 ~24 ~469 ~68 ~24 grass_block
fill ~464 ~60 ~25 ~466 ~63 ~25 stone
fill ~464 ~64 ~25 ~466 ~66 ~25 dirt
fill ~464 ~67 ~25 ~466 ~67 ~25 grass_block
fill ~467 ~60 ~25 ~469 ~64 ~25 stone
fill ~467 ~65 ~25 ~469 ~67 ~25 dirt
fill ~467 ~68 ~25 ~469 ~68 ~25 grass_block
fill ~464 ~60 ~26 ~467 ~63 ~26 stone
fill ~464 ~64 ~26 ~467 ~66 ~26 dirt
fill ~464 ~67 ~26 ~467 ~67 ~26 grass_block
fill ~468 ~60 ~26 ~469 ~64 ~26 stone
fill ~468 ~65 ~26 ~469 ~67 ~26 dirt
fill ~468 ~68 ~26 ~469 ~68 ~26 grass_block
fill ~464 ~60 ~27 ~468 ~63 ~27 stone
fill ~464 ~64 ~27 ~468 ~66 ~27 dirt
fill ~464 ~67 ~27 ~468 ~67 ~27 grass_block
fill ~469 ~60 ~27 ~469 ~64 ~27 stone
fill ~469 ~65 ~27 ~469 ~67 ~27 dirt
fill ~469 ~68 ~27 ~469 ~68 ~27 grass_block
fill ~464 ~60 ~28 ~469 ~63 ~28 stone
fill ~464 ~64 ~28 ~469 ~66 ~28 dirt
fill ~464 ~67 ~28 ~469 ~67 ~28 grass_block
fill ~464 ~60 ~29 ~469 ~63 ~29 stone
fill ~464 ~64 ~29 ~469 ~66 ~29 dirt
fill ~464 ~67 ~29 ~469 ~67 ~29 grass_block
fill ~464 ~60 ~30 ~466 ~63 ~30 stone
fill ~464 ~64 ~30 ~466 ~66 ~30 dirt
fill ~464 ~67 ~30 ~466 ~67 ~30 grass_block
fill ~467 ~60 ~30 ~468 ~62 ~30 stone
fill ~467 ~63 ~30 ~468 ~65 ~30 dirt
fill ~467 ~66 ~30 ~468 ~66 ~30 grass_block
fill ~469 ~60 ~30 ~469 ~63 ~30 stone
fill ~469 ~64 ~30 ~469 ~66 ~30 dirt
fill ~469 ~67 ~30 ~469 ~67 ~30 grass_block
fill ~464 ~60 ~31 ~464 ~63 ~31 stone
fill ~464 ~64 ~31 ~464 ~66 ~31 dirt
fill ~464 ~67 ~31 ~464 ~67 ~31 grass_block
fill ~465 ~60 ~31 ~469 ~62 ~31 stone
fill ~465 ~63 ~31 ~469 ~65 ~31 dirt
fill ~465 ~66 ~31 ~469 ~66 ~31 grass_block